Workbook

Sheet Total
A1: Site Name | B1: Day | C1: Month | D1: Year | E1: Total Electricity Kwh | F1: Electricity Tariff ($/Kwh) | G1: Natural Gas (m3) | H1: Natural Gas $/m3 | I1: Water Utility Supply (m3) m3 | J1: Water Utility Supply (m3) $/m3 | K1: District Energy Cooling RTH | L1: District Energy Cooling $/RTH | M1: Room Nights | N1: Total Guests
A2: Pearl Rotana Capital Centre | B2: 1 | C2: 3 | D2: 2023 | E2: =Submetering!E2+Submetering!F2+Submetering!G2 -> 15740 | F2: 0.2 | G2: =Submetering!I2+Submetering!J2 -> 25 | H2: 12.61 | I2: =Submetering!H2 -> 79 | J2: 7.84 | K2: =Submetering!K2 -> 6539.935 | L2: 1.14 | M2: ='Mar 2023'!AD5*315 -> 235.998
A3: Pearl Rotana Capital Centre | B3: =B2+1 -> 2 | C3: 3 | D3: 2023 | E3: =Submetering!E3+Submetering!F3+Submetering!G3 -> 16086 | F3: 0.2 | G3: =Submetering!I3+Submetering!J3 -> 29 | H3: 12.61 | I3: =Submetering!H3 -> 101 | J3: 7.84 | K3: =Submetering!K3 -> 6824.28 | L3: 1.14 | M3: ='Mar 2023'!AD6*315 -> 257.0085
A4: Pearl Rotana Capital Centre | B4: =B3+1 -> 3 | C4: 3 | D4: 2023 | E4: =Submetering!E4+Submetering!F4+Submetering!G4 -> 16145 | F4: 0.2 | G4: =Submetering!I4+Submetering!J4 -> 30 | H4: 12.61 | I4: =Submetering!H4 -> 97 | J4: 7.84 | K4: =Submetering!K4 -> 6824.28 | L4: 1.14 | M4: ='Mar 2023'!AD7*315 -> 315
A5: Pearl Rotana Capital Centre | B5: =B4+1 -> 4 | C5: 3 | D5: 2023 | E5: =Submetering!E5+Submetering!F5+Submetering!G5 -> 16352 | F5: 0.2 | G5: =Submetering!I5+Submetering!J5 -> 28 | H5: 12.61 | I5: =Submetering!H5 -> 96 | J5: 7.84 | K5: =Submetering!K5 -> 6824.28 | L5: 1.14 | M5: ='Mar 2023'!AD8*315 -> 315
A6: Pearl Rotana Capital Centre | B6: =B5+1 -> 5 | C6: 3 | D6: 2023 | E6: =Submetering!E6+Submetering!F6+Submetering!G6 -> 15573 | F6: 0.2 | G6: =Submetering!I6+Submetering!J6 -> 26 | H6: 12.61 | I6: =Submetering!H6 -> 126 | J6: 7.84 | K6: =Submetering!K6 -> 6255.59 | L6: 1.14 | M6: ='Mar 2023'!AD9*315 -> 285.9885
A7: Pearl Rotana Capital Centre | B7: =B6+1 -> 6 | C7: 3 | D7: 2023 | E7: =Submetering!E7+Submetering!F7+Submetering!G7 -> 16431 | F7: 0.2 | G7: =Submetering!I7+Submetering!J7 -> 28 | H7: 12.61 | I7: =Submetering!H7 -> 93 | J7: 7.84 | K7: =Submetering!K7 -> 6255.59 | L7: 1.14 | M7: ='Mar 2023'!AD10*315 -> 246.015
A8: Pearl Rotana Capital Centre | B8: =B7+1 -> 7 | C8: 3 | D8: 2023 | E8: =Submetering!E8+Submetering!F8+Submetering!G8 -> 15717 | F8: 0.2 | G8: =Submetering!I8+Submetering!J8 -> 27 | H8: 12.61 | I8: =Submetering!H8 -> 108 | J8: 7.84 | K8: =Submetering!K8 -> 5971.245 | L8: 1.14 | M8: ='Mar 2023'!AD11*315 -> 253.9845
A9: Pearl Rotana Capital Centre | B9: =B8+1 -> 8 | C9: 3 | D9: 2023 | E9: =Submetering!E9+Submetering!F9+Submetering!G9 -> 16114 | F9: 0.2 | G9: =Submetering!I9+Submetering!J9 -> 28 | H9: 12.61 | I9: =Submetering!H9 -> 92 | J9: 7.84 | K9: =Submetering!K9 -> 6539.935 | L9: 1.14 | M9: ='Mar 2023'!AD12*315 -> 253.008
A10: Pearl Rotana Capital Centre | B10: =B9+1 -> 9 | C10: 3 | D10: 2023 | E10: =Submetering!E10+Submetering!F10+Submetering!G10 -> 16308 | F10: 0.2 | G10: =Submetering!I10+Submetering!J10 -> 33 | H10: 12.61 | I10: =Submetering!H10 -> 89 | J10: 7.84 | K10: =Submetering!K10 -> 6539.935 | L10: 1.14 | M10: ='Mar 2023'!AD13*315 -> 219.996
A11: Pearl Rotana Capital Centre | B11: =B10+1 -> 10 | C11: 3 | D11: 2023 | E11: =Submetering!E11+Submetering!F11+Submetering!G11 -> 16082 | F11: 0.2 | G11: =Submetering!I11+Submetering!J11 -> 29 | H11: 12.61 | I11: =Submetering!H11 -> 90 | J11: 7.84 | K11: =Submetering!K11 -> 6539.935 | L11: 1.14 | M11: ='Mar 2023'!AD14*315 -> 211.995
A12: Pearl Rotana Capital Centre | B12: =B11+1 -> 11 | C12: 3 | D12: 2023 | E12: =Submetering!E12+Submetering!F12+Submetering!G12 -> 15602 | F12: 0.2 | G12: =Submetering!I12+Submetering!J12 -> 26 | H12: 12.61 | I12: =Submetering!H12 -> 94 | J12: 7.84 | K12: =Submetering!K12 -> 6539.935 | L12: 1.14 | M12: ='Mar 2023'!AD15*315 -> 213.003
A13: Pearl Rotana Capital Centre | B13: =B12+1 -> 12 | C13: 3 | D13: 2023 | E13: =Submetering!E13+Submetering!F13+Submetering!G13 -> 15391 | F13: 0.2 | G13: =Submetering!I13+Submetering!J13 -> 26 | H13: 12.61 | I13: =Submetering!H13 -> 103 | J13: 7.84 | K13: =Submetering!K13 -> 6539.935 | L13: 1.14 | M13: ='Mar 2023'!AD16*315 -> 215.9955
A14: Pearl Rotana Capital Centre | B14: =B13+1 -> 13 | C14: 3 | D14: 2023 | E14: =Submetering!E14+Submetering!F14+Submetering!G14 -> 15959 | F14: 0.2 | G14: =Submetering!I14+Submetering!J14 -> 28 | H14: 12.61 | I14: =Submetering!H14 -> 103 | J14: 7.84 | K14: =Submetering!K14 -> 6824.28 | L14: 1.14 | M14: ='Mar 2023'!AD17*315 -> 269.01
... A32: Pearl Rotana Capital Centre | B32: =B31+1 -> 31 | C32: 3 | D32: 2023 | E32: =Submetering!E32+Submetering!F32+Submetering!G32 -> 15087 | F32: 2.2 | G32: =Submetering!I32+Submetering!J32 -> 29 | H32: 12.61 | I32: =Submetering!H32 -> 69 | J32: 7.84 | K32: =Submetering!K32 -> 5686.9 | L32: 1.14 | M32: ='Mar 2023'!AD35*315 -> 113.9985

Sheet Submetering
A1: Site Name | B1: Day | C1: Month | D1: Year | E1: MDB#2 | F1: MDB#3 | G1: MDB#1 Façade | H1: Water | I1: Gas Meter#1 GF Kitchen | J1: Gas Meter#2 1st floor Kitchen | K1: District Cooling | L1: District Cooling ETS | M1: Water Main Kitchen | N1: Room Nights | O1: Total Guests
A2: Pearl Rotana Capital Centre | B2: 1 | C2: 3 | D2: 2023 | E2: ='Mar 2023'!C5 -> 7814 | F2: ='Mar 2023'!E5 -> 7814 | G2: ='Mar 2023'!G5 -> 112 | H2: ='Mar 2023'!K5 -> 79 | I2: ='Mar 2023'!N5 -> 16 | J2: ='Mar 2023'!P5 -> 9 | K2: ='Mar 2023'!X5 -> 6539.935 | L2: ='Mar 2023'!AC5 -> 7008 | M2: ='Mar 2023'!AP5 -> 0 | N2: ='Mar 2023'!AD5*315 -> 235.998
A3: Pearl Rotana Capital Centre | B3: =B2+1 -> 2 | C3: 3 | D3: 2023 | E3: ='Mar 2023'!C6 -> 8287 | F3: ='Mar 2023'!E6 -> 7684 | G3: ='Mar 2023'!G6 -> 115 | H3: ='Mar 2023'!K6 -> 101 | I3: ='Mar 2023'!N6 -> 17 | J3: ='Mar 2023'!P6 -> 12 | K3: ='Mar 2023'!X6 -> 6824.28 | L3: ='Mar 2023'!AC6 -> 7095 | M3: ='Mar 2023'!AP6 -> 0 | N3: ='Mar 2023'!AD6*315 -> 257.0085
A4: Pearl Rotana Capital Centre | B4: =B3+1 -> 3 | C4: 3 | D4: 2023 | E4: ='Mar 2023'!C7 -> 8411 | F4: ='Mar 2023'!E7 -> 7613 | G4: ='Mar 2023'!G7 -> 121 | H4: ='Mar 2023'!K7 -> 97 | I4: ='Mar 2023'!N7 -> 18 | J4: ='Mar 2023'!P7 -> 12 | K4: ='Mar 2023'!X7 -> 6824.28 | L4: ='Mar 2023'!AC7 -> 7406 | M4: ='Mar 2023'!AP7 -> 0 | N4: ='Mar 2023'!AD7*315 -> 315
A5: Pearl Rotana Capital Centre | B5: =B4+1 -> 4 | C5: 3 | D5: 2023 | E5: ='Mar 2023'!C8 -> 8595 | F5: ='Mar 2023'!E8 -> 7644 | G5: ='Mar 2023'!G8 -> 113 | H5: ='Mar 2023'!K8 -> 96 | I5: ='Mar 2023'!N8 -> 17 | J5: ='Mar 2023'!P8 -> 11 | K5: ='Mar 2023'!X8 -> 6824.28 | L5: ='Mar 2023'!AC8 -> 6608 | M5: ='Mar 2023'!AP8 -> 0 | N5: ='Mar 2023'!AD8*315 -> 315
A6: Pearl Rotana Capital Centre | B6: =B5+1 -> 5 | C6: 3 | D6: 2023 | E6: ='Mar 2023'!C9 -> 8013 | F6: ='Mar 2023'!E9 -> 7433 | G6: ='Mar 2023'!G9 -> 127 | H6: ='Mar 2023'!K9 -> 126 | I6: ='Mar 2023'!N9 -> 16 | J6: ='Mar 2023'!P9 -> 10 | K6: ='Mar 2023'!X9 -> 6255.59 | L6: ='Mar 2023'!AC9 -> 6085 | M6: ='Mar 2023'!AP9 -> 0 | N6: ='Mar 2023'!AD9*315 -> 285.9885
A7: Pearl Rotana Capital Centre | B7: =B6+1 -> 6 | C7: 3 | D7: 2023 | E7: ='Mar 2023'!C10 -> 8618 | F7: ='Mar 2023'!E10 -> 7683 | G7: ='Mar 2023'!G10 -> 130 | H7: ='Mar 2023'!K10 -> 93 | I7: ='Mar 2023'!N10 -> 16 | J7: ='Mar 2023'!P10 -> 12 | K7: ='Mar 2023'!X10 -> 6255.59 | L7: ='Mar 2023'!AC10 -> 6814 | M7: ='Mar 2023'!AP10 -> 0 | N7: ='Mar 2023'!AD10*315 -> 246.015
A8: Pearl Rotana Capital Centre | B8: =B7+1 -> 7 | C8: 3 | D8: 2023 | E8: ='Mar 2023'!C11 -> 8234 | F8: ='Mar 2023'!E11 -> 7360 | G8: ='Mar 2023'!G11 -> 123 | H8: ='Mar 2023'!K11 -> 108 | I8: ='Mar 2023'!N11 -> 15 | J8: ='Mar 2023'!P11 -> 12 | K8: ='Mar 2023'!X11 -> 5971.245 | L8: ='Mar 2023'!AC11 -> 6566 | M8: ='Mar 2023'!AP11 -> 0 | N8: ='Mar 2023'!AD11*315 -> 253.9845
A9: Pearl Rotana Capital Centre | B9: =B8+1 -> 8 | C9: 3 | D9: 2023 | E9: ='Mar 2023'!C12 -> 8433 | F9: ='Mar 2023'!E12 -> 7563 | G9: ='Mar 2023'!G12 -> 118 | H9: ='Mar 2023'!K12 -> 92 | I9: ='Mar 2023'!N12 -> 16 | J9: ='Mar 2023'!P12 -> 12 | K9: ='Mar 2023'!X12 -> 6539.935 | L9: ='Mar 2023'!AC12 -> 6978 | M9: ='Mar 2023'!AP12 -> 0 | N9: ='Mar 2023'!AD12*315 -> 253.008
A10: Pearl Rotana Capital Centre | B10: =B9+1 -> 9 | C10: 3 | D10: 2023 | E10: ='Mar 2023'!C13 -> 8357 | F10: ='Mar 2023'!E13 -> 7823 | G10: ='Mar 2023'!G13 -> 128 | H10: ='Mar 2023'!K13 -> 89 | I10: ='Mar 2023'!N13 -> 17 | J10: ='Mar 2023'!P13 -> 16 | K10: ='Mar 2023'!X13 -> 6539.935 | L10: ='Mar 2023'!AC13 -> 7113 | M10: ='Mar 2023'!AP13 -> 0 | N10: ='Mar 2023'!AD13*315 -> 219.996
A11: Pearl Rotana Capital Centre | B11: =B10+1 -> 10 | C11: 3 | D11: 2023 | E11: ='Mar 2023'!C14 -> 8199 | F11: ='Mar 2023'!E14 -> 7756 | G11: ='Mar 2023'!G14 -> 127 | H11: ='Mar 2023'!K14 -> 90 | I11: ='Mar 2023'!N14 -> 16 | J11: ='Mar 2023'!P14 -> 13 | K11: ='Mar 2023'!X14 -> 6539.935 | L11: ='Mar 2023'!AC14 -> 7097 | M11: ='Mar 2023'!AP14 -> 0 | N11: ='Mar 2023'!AD14*315 -> 211.995
A12: Pearl Rotana Capital Centre | B12: =B11+1 -> 11 | C12: 3 | D12: 2023 | E12: ='Mar 2023'!C15 -> 8249 | F12: ='Mar 2023'!E15 -> 7226 | G12: ='Mar 2023'!G15 -> 127 | H12: ='Mar 2023'!K15 -> 94 | I12: ='Mar 2023'!N15 -> 17 | J12: ='Mar 2023'!P15 -> 9 | K12: ='Mar 2023'!X15 -> 6539.935 | L12: ='Mar 2023'!AC15 -> 6808 | M12: ='Mar 2023'!AP15 -> 0 | N12: ='Mar 2023'!AD15*315 -> 213.003
A13: Pearl Rotana Capital Centre | B13: =B12+1 -> 12 | C13: 3 | D13: 2023 | E13: ='Mar 2023'!C16 -> 8146 | F13: ='Mar 2023'!E16 -> 7117 | G13: ='Mar 2023'!G16 -> 128 | H13: ='Mar 2023'!K16 -> 103 | I13: ='Mar 2023'!N16 -> 15 | J13: ='Mar 2023'!P16 -> 11 | K13: ='Mar 2023'!X16 -> 6539.935 | L13: ='Mar 2023'!AC16 -> 6732 | M13: ='Mar 2023'!AP16 -> 0 | N13: ='Mar 2023'!AD16*315 -> 215.9955
A14: Pearl Rotana Capital Centre | B14: =B13+1 -> 13 | C14: 3 | D14: 2023 | E14: ='Mar 2023'!C17 -> 8144 | F14: ='Mar 2023'!E17 -> 7699 | G14: ='Mar 2023'!G17 -> 116 | H14: ='Mar 2023'!K17 -> 103 | I14: ='Mar 2023'!N17 -> 15 | J14: ='Mar 2023'!P17 -> 13 | K14: ='Mar 2023'!X17 -> 6824.28 | L14: ='Mar 2023'!AC17 -> 7260 | M14: ='Mar 2023'!AP17 -> 0 | N14: ='Mar 2023'!AD17*315 -> 269.01
... A32: Pearl Rotana Capital Centre | B32: =B31+1 -> 31 | C32: 3 | D32: 2023 | E32: ='Mar 2023'!C35 -> 7847 | F32: ='Mar 2023'!E35 -> 7119 | G32: ='Mar 2023'!G35 -> 121 | H32: ='Mar 2023'!K35 -> 69 | I32: ='Mar 2023'!N35 -> 17 | J32: ='Mar 2023'!P35 -> 12 | K32: ='Mar 2023'!X35 -> 5686.9 | L32: ='Mar 2023'!AC35 -> 6050 | M32: ='Mar 2023'!AP35 -> 0 | N32: ='Mar 2023'!AD35*315 -> 113.9985

Sheet Mar 2023
A1: PEARL ROTANA CAPITAL CENTRE UTILITIES CONSUMPTION MARCH 2023
A2: DATE | B2: Electricity | J2: Water | M2: SNG Gas | V2: District Cooling | AD2: Additional Info
B3: MDB #2 | D3: MDB #3 | F3: MDB #1 Façade | H3: Total ELE Cons. KW | I3: Electricity AED | J3: Hotel Reading | K3: Water Cons. M3 | L3: Water AED | M3: Gas Meter #1 G Floor Kitchen | O3: Gas Meter #2 1st Floor Kitchen | Q3: Total Gas Cons. M3 | R3: PRS Meter Reading | S3: PRS Meter Cons. M3 | T3: Meter factor (1.05570) | U3: Gas AED | V3: Hotel BTU Meter Energy Reading | W3: District Cooling Cons. MWH | X3: District Cooling Cons. Ton Hour | Y3: District Cooling Cons. AED | Z3: District Cooling Fixed Charge | AA3: District Cooling Total AED | AB3: ETS Energy Meter Reading | AD3: Hotel Occupancy % | AE3: Adl. & Chl.
B4: Reading | C4: Cons. | D4: Reading | E4: Cons. | F4: Reading | G4: Cons. | M4: Reading | N4: Cons. | O4: Reading | P4: Cons.
A5: 44986 | B5: 15790229 | C5: 7814 | D5: 17031258 | E5: 7814 | F5: 403487 | G5: 112 | H5: =C5+E5+G5 -> 15740 | I5: =H5*0.2 -> 3148 | J5: 39527 | K5: 79 | L5: =K5*7.84 -> 619.36 | M5: 27925 | N5: 16 | O5: 15138 | P5: 9 | Q5: =N5+P5 -> 25 | R5: 39426 | S5: 24 | T5: =S5*1.0557 -> 25.3368 | U5: =IF(ISBLANK(M5),"0",T5*11.05+209.677) -> 489.64864 | V5: 55710 | W5: 23 | X5: =IF(ISBLANK(V5),"0 ",W5*284.345) -> 6539.935 | Y5: =X5*0.3435 -> 2246.4677 | Z5: =IF(ISBLANK(V5),"0",1570*1487.37/12/31*0.65) -> 4080.2717 | AA5: =Y5+Z5 -> 6326.7394 | AB5: 2267571 | AC5: 7008 | AD5: 0.7492 | AE5: 300
A6: 44987 | B6: 15798516 | C6: =IF(ISBLANK(B6),"0",B6-B5) -> 8287 | D6: 17038942 | E6: =IF(ISBLANK(D6),"0",D6-D5) -> 7684 | F6: 403602 | G6: =IF(ISBLANK(F6),"0",F6-F5) -> 115 | H6: =C6+E6+G6 -> 16086 | I6: =H6*0.2 -> 3217.2 | J6: 39628 | K6: =IF(ISBLANK(J6),"0",J6-J5) -> 101 | L6: =K6*7.84 -> 791.84 | M6: 27942 | N6: =IF(ISBLANK(M6),"0",M6-M5) -> 17 | O6: 15150 | P6: =IF(ISBLANK(O6),"0",O6-O5) -> 12 | Q6: =N6+P6 -> 29 | R6: 39453 | S6: =IF(ISBLANK(R6),"0",R6-R5) -> 27 | T6: =S6*1.0557 -> 28.5039 | U6: =IF(ISBLANK(M6),"0",T6*11.05+209.677) -> 524.6451 | V6: 55734 | W6: =IF(ISBLANK(V6)," ",V6-V5) -> 24 | X6: =IF(ISBLANK(V6),"0 ",W6*284.345) -> 6824.28 | Y6: =X6*0.3435 -> 2344.1402 | Z6: =IF(ISBLANK(V6),"0",1570*1487.37/12/31*0.65) -> 4080.2717 | AA6: =Y6+Z6 -> 6424.4119 | AB6: 2274666 | AC6: =IF(ISBLANK(AB6)," ",AB6-AB5) -> 7095 | AD6: 0.8159 | AE6: 346
A7: 44988 | B7: 15806927 | C7: =IF(ISBLANK(B7),"0",B7-B6) -> 8411 | D7: 17046555 | E7: =IF(ISBLANK(D7),"0",D7-D6) -> 7613 | F7: 403723 | G7: =IF(ISBLANK(F7),"0",F7-F6) -> 121 | H7: =C7+E7+G7 -> 16145 | I7: =H7*0.2 -> 3229 | J7: 39725 | K7: =IF(ISBLANK(J7),"0",J7-J6) -> 97 | L7: =K7*7.84 -> 760.48 | M7: 27960 | N7: =IF(ISBLANK(M7),"0",M7-M6) -> 18 | O7: 15162 | P7: =IF(ISBLANK(O7),"0",O7-O6) -> 12 | Q7: =N7+P7 -> 30 | R7: 39481 | S7: =IF(ISBLANK(R7),"0",R7-R6) -> 28 | T7: =S7*1.0557 -> 29.5596 | U7: =IF(ISBLANK(M7),"0",T7*11.05+209.677) -> 536.31058 | V7: 55758 | W7: =IF(ISBLANK(V7)," ",V7-V6) -> 24 | X7: =IF(ISBLANK(V7),"0 ",W7*284.345) -> 6824.28 | Y7: =X7*0.3435 -> 2344.1402 | Z7: =IF(ISBLANK(V7),"0",1570*1487.37/12/31*0.65) -> 4080.2717 | AA7: =Y7+Z7 -> 6424.4119 | AB7: 2282072 | AC7: =IF(ISBLANK(AB7)," ",AB7-AB6) -> 7406 | AD7: 1 | AE7: 426
A8: 44989 | B8: 15815522 | C8: =IF(ISBLANK(B8),"0",B8-B7) -> 8595 | D8: 17054199 | E8: =IF(ISBLANK(D8),"0",D8-D7) -> 7644 | F8: 403836 | G8: =IF(ISBLANK(F8),"0",F8-F7) -> 113 | H8: =C8+E8+G8 -> 16352 | I8: =H8*0.2 -> 3270.4 | J8: 39821 | K8: =IF(ISBLANK(J8),"0",J8-J7) -> 96 | L8: =K8*7.84 -> 752.64 | M8: 27977 | N8: =IF(ISBLANK(M8),"0",M8-M7) -> 17 | O8: 15173 | P8: =IF(ISBLANK(O8),"0",O8-O7) -> 11 | Q8: =N8+P8 -> 28 | R8: 39509 | S8: =IF(ISBLANK(R8),"0",R8-R7) -> 28 | T8: =S8*1.0557 -> 29.5596 | U8: =IF(ISBLANK(M8),"0",T8*11.05+209.677) -> 536.31058 | V8: 55782 | W8: =IF(ISBLANK(V8)," ",V8-V7) -> 24 | X8: =IF(ISBLANK(V8),"0 ",W8*284.345) -> 6824.28 | Y8: =X8*0.3435 -> 2344.1402 | Z8: =IF(ISBLANK(V8),"0",1570*1487.37/12/31*0.65) -> 4080.2717 | AA8: =Y8+Z8 -> 6424.4119 | AB8: 2288680 | AC8: =IF(ISBLANK(AB8)," ",AB8-AB7) -> 6608 | AD8: 1 | AE8: 423
A9: 44990 | B9: 15823535 | C9: =IF(ISBLANK(B9),"0",B9-B8) -> 8013 | D9: 17061632 | E9: =IF(ISBLANK(D9),"0",D9-D8) -> 7433 | F9: 403963 | G9: =IF(ISBLANK(F9),"0",F9-F8) -> 127 | H9: =C9+E9+G9 -> 15573 | I9: =H9*0.2 -> 3114.6 | J9: 39947 | K9: =IF(ISBLANK(J9),"0",J9-J8) -> 126 | L9: =K9*7.84 -> 987.84 | M9: 27993 | N9: =IF(ISBLANK(M9),"0",M9-M8) -> 16 | O9: 15183 | P9: =IF(ISBLANK(O9),"0",O9-O8) -> 10 | Q9: =N9+P9 -> 26 | R9: 39534 | S9: =IF(ISBLANK(R9),"0",R9-R8) -> 25 | T9: =S9*1.0557 -> 26.3925 | U9: =IF(ISBLANK(M9),"0",T9*11.05+209.677) -> 501.31412 | V9: 55804 | W9: =IF(ISBLANK(V9)," ",V9-V8) -> 22 | X9: =IF(ISBLANK(V9),"0 ",W9*284.345) -> 6255.59 | Y9: =X9*0.3435 -> 2148.7952 | Z9: =IF(ISBLANK(V9),"0",1570*1487.37/12/31*0.65) -> 4080.2717 | AA9: =Y9+Z9 -> 6229.0669 | AB9: 2294765 | AC9: =IF(ISBLANK(AB9)," ",AB9-AB8) -> 6085 | AD9: 0.9079 | AE9: 369
A10: 44991 | B10: 15832153 | C10: =IF(ISBLANK(B10),"0",B10-B9) -> 8618 | D10: 17069315 | E10: =IF(ISBLANK(D10),"0",D10-D9) -> 7683 | F10: 404093 | G10: =IF(ISBLANK(F10),"0",F10-F9) -> 130 | H10: =C10+E10+G10 -> 16431 | I10: =H10*0.2 -> 3286.2 | J10: 40040 | K10: =IF(ISBLANK(J10),"0",J10-J9) -> 93 | L10: =K10*7.84 -> 729.12 | M10: 28009 | N10: =IF(ISBLANK(M10),"0",M10-M9) -> 16 | O10: 15195 | P10: =IF(ISBLANK(O10),"0",O10-O9) -> 12 | Q10: =N10+P10 -> 28 | R10: 39561 | S10: =IF(ISBLANK(R10),"0",R10-R9) -> 27 | T10: =S10*1.0557 -> 28.5039 | U10: =IF(ISBLANK(M10),"0",T10*11.05+209.677) -> 524.6451 | V10: 55826 | W10: =IF(ISBLANK(V10)," ",V10-V9) -> 22 | X10: =IF(ISBLANK(V10),"0 ",W10*284.345) -> 6255.59 | Y10: =X10*0.3435 -> 2148.7952 | Z10: =IF(ISBLANK(V10),"0",1570*1487.37/12/31*0.65) -> 4080.2717 | AA10: =Y10+Z10 -> 6229.0669 | AB10: 2301579 | AC10: =IF(ISBLANK(AB10)," ",AB10-AB9) -> 6814 | AD10: 0.781 | AE10: 323
A11: 44992 | B11: 15840387 | C11: =IF(ISBLANK(B11),"0",B11-B10) -> 8234 | D11: 17076675 | E11: =IF(ISBLANK(D11),"0",D11-D10) -> 7360 | F11: 404216 | G11: =IF(ISBLANK(F11),"0",F11-F10) -> 123 | H11: =C11+E11+G11 -> 15717 | I11: =H11*0.2 -> 3143.4 | J11: 40148 | K11: =IF(ISBLANK(J11),"0",J11-J10) -> 108 | L11: =K11*7.84 -> 846.72 | M11: 28024 | N11: =IF(ISBLANK(M11),"0",M11-M10) -> 15 | O11: 15207 | P11: =IF(ISBLANK(O11),"0",O11-O10) -> 12 | Q11: =N11+P11 -> 27 | R11: 39587 | S11: =IF(ISBLANK(R11),"0",R11-R10) -> 26 | T11: =S11*1.0557 -> 27.4482 | U11: =IF(ISBLANK(M11),"0",T11*11.05+209.677) -> 512.97961 | V11: 55847 | W11: =IF(ISBLANK(V11)," ",V11-V10) -> 21 | X11: =IF(ISBLANK(V11),"0 ",W11*284.345) -> 5971.245 | Y11: =X11*0.3435 -> 2051.1227 | Z11: =IF(ISBLANK(V11),"0",1570*1487.37/12/31*0.65) -> 4080.2717 | AA11: =Y11+Z11 -> 6131.3944 | AB11: 2308145 | AC11: =IF(ISBLANK(AB11)," ",AB11-AB10) -> 6566 | AD11: 0.8063 | AE11: 330
A12: 44993 | B12: 15848820 | C12: =IF(ISBLANK(B12),"0",B12-B11) -> 8433 | D12: 17084238 | E12: =IF(ISBLANK(D12),"0",D12-D11) -> 7563 | F12: 404334 | G12: =IF(ISBLANK(F12),"0",F12-F11) -> 118 | H12: =C12+E12+G12 -> 16114 | I12: =H12*0.2 -> 3222.8 | J12: 40240 | K12: =IF(ISBLANK(J12),"0",J12-J11) -> 92 | L12: =K12*7.84 -> 721.28 | M12: 28040 | N12: =IF(ISBLANK(M12),"0",M12-M11) -> 16 | O12: 15219 | P12: =IF(ISBLANK(O12),"0",O12-O11) -> 12 | Q12: =N12+P12 -> 28 | R12: 39614 | S12: =IF(ISBLANK(R12),"0",R12-R11) -> 27 | T12: =S12*1.0557 -> 28.5039 | U12: =IF(ISBLANK(M12),"0",T12*11.05+209.677) -> 524.6451 | V12: 55870 | W12: =IF(ISBLANK(V12)," ",V12-V11) -> 23 | X12: =IF(ISBLANK(V12),"0 ",W12*284.345) -> 6539.935 | Y12: =X12*0.3435 -> 2246.4677 | Z12: =IF(ISBLANK(V12),"0",1570*1487.37/12/31*0.65) -> 4080.2717 | AA12: =Y12+Z12 -> 6326.7394 | AB12: 2315123 | AC12: =IF(ISBLANK(AB12)," ",AB12-AB11) -> 6978 | AD12: 0.8032 | AE12: 336
A13: 44994 | B13: 15857177 | C13: =IF(ISBLANK(B13),"0",B13-B12) -> 8357 | D13: 17092061 | E13: =IF(ISBLANK(D13),"0",D13-D12) -> 7823 | F13: 404462 | G13: =IF(ISBLANK(F13),"0",F13-F12) -> 128 | H13: =C13+E13+G13 -> 16308 | I13: =H13*0.2 -> 3261.6 | J13: 40329 | K13: =IF(ISBLANK(J13),"0",J13-J12) -> 89 | L13: =K13*7.84 -> 697.76 | M13: 28057 | N13: =IF(ISBLANK(M13),"0",M13-M12) -> 17 | O13: 15235 | P13: =IF(ISBLANK(O13),"0",O13-O12) -> 16 | Q13: =N13+P13 -> 33 | R13: 39646 | S13: =IF(ISBLANK(R13),"0",R13-R12) -> 32 | T13: =S13*1.0557 -> 33.7824 | U13: =IF(ISBLANK(M13),"0",T13*11.05+209.677) -> 582.97252 | V13: 55893 | W13: =IF(ISBLANK(V13)," ",V13-V12) -> 23 | X13: =IF(ISBLANK(V13),"0 ",W13*284.345) -> 6539.935 | Y13: =X13*0.3435 -> 2246.4677 | Z13: =IF(ISBLANK(V13),"0",1570*1487.37/12/31*0.65) -> 4080.2717 | AA13: =Y13+Z13 -> 6326.7394 | AB13: 2322236 | AC13: =IF(ISBLANK(AB13)," ",AB13-AB12) -> 7113 | AD13: 0.6984 | AE13: 295
A14: 44995 | B14: 15865376 | C14: =IF(ISBLANK(B14),"0",B14-B13) -> 8199 | D14: 17099817 | E14: =IF(ISBLANK(D14),"0",D14-D13) -> 7756 | F14: 404589 | G14: =IF(ISBLANK(F14),"0",F14-F13) -> 127 | H14: =C14+E14+G14 -> 16082 | I14: =H14*0.2 -> 3216.4 | J14: 40419 | K14: =IF(ISBLANK(J14),"0",J14-J13) -> 90 | L14: =K14*7.84 -> 705.6 | M14: 28073 | N14: =IF(ISBLANK(M14),"0",M14-M13) -> 16 | O14: 15248 | P14: =IF(ISBLANK(O14),"0",O14-O13) -> 13 | Q14: =N14+P14 -> 29 | R14: 39675 | S14: =IF(ISBLANK(R14),"0",R14-R13) -> 29 | T14: =S14*1.0557 -> 30.6153 | U14: =IF(ISBLANK(M14),"0",T14*11.05+209.677) -> 547.97607 | V14: 55916 | W14: =IF(ISBLANK(V14)," ",V14-V13) -> 23 | X14: =IF(ISBLANK(V14),"0 ",W14*284.345) -> 6539.935 | Y14: =X14*0.3435 -> 2246.4677 | Z14: =IF(ISBLANK(V14),"0",1570*1487.37/12/31*0.65) -> 4080.2717 | AA14: =Y14+Z14 -> 6326.7394 | AB14: 2329333 | AC14: =IF(ISBLANK(AB14)," ",AB14-AB13) -> 7097 | AD14: 0.673 | AE14: 316
A15: 44996 | B15: 15873625 | C15: =IF(ISBLANK(B15),"0",B15-B14) -> 8249 | D15: 17107043 | E15: =IF(ISBLANK(D15),"0",D15-D14) -> 7226 | F15: 404716 | G15: =IF(ISBLANK(F15),"0",F15-F14) -> 127 | H15: =C15+E15+G15 -> 15602 | I15: =H15*0.2 -> 3120.4 | J15: 40513 | K15: =IF(ISBLANK(J15),"0",J15-J14) -> 94 | L15: =K15*7.84 -> 736.96 | M15: 28090 | N15: =IF(ISBLANK(M15),"0",M15-M14) -> 17 | O15: 15257 | P15: =IF(ISBLANK(O15),"0",O15-O14) -> 9 | Q15: =N15+P15 -> 26 | R15: 39700 | S15: =IF(ISBLANK(R15),"0",R15-R14) -> 25 | T15: =S15*1.0557 -> 26.3925 | U15: =IF(ISBLANK(M15),"0",T15*11.05+209.677) -> 501.31412 | V15: 55939 | W15: =IF(ISBLANK(V15)," ",V15-V14) -> 23 | X15: =IF(ISBLANK(V15),"0 ",W15*284.345) -> 6539.935 | Y15: =X15*0.3435 -> 2246.4677 | Z15: =IF(ISBLANK(V15),"0",1570*1487.37/12/31*0.65) -> 4080.2717 | AA15: =Y15+Z15 -> 6326.7394 | AB15: 2336141 | AC15: =IF(ISBLANK(AB15)," ",AB15-AB14) -> 6808 | AD15: 0.6762 | AE15: 309
A16: 44997 | B16: 15881771 | C16: =IF(ISBLANK(B16),"0",B16-B15) -> 8146 | D16: 17114160 | E16: =IF(ISBLANK(D16),"0",D16-D15) -> 7117 | F16: 404844 | G16: =IF(ISBLANK(F16),"0",F16-F15) -> 128 | H16: =C16+E16+G16 -> 15391 | I16: =H16*0.2 -> 3078.2 | J16: 40616 | K16: =IF(ISBLANK(J16),"0",J16-J15) -> 103 | L16: =K16*7.84 -> 807.52 | M16: 28105 | N16: =IF(ISBLANK(M16),"0",M16-M15) -> 15 | O16: 15268 | P16: =IF(ISBLANK(O16),"0",O16-O15) -> 11 | Q16: =N16+P16 -> 26 | R16: 39725 | S16: =IF(ISBLANK(R16),"0",R16-R15) -> 25 | T16: =S16*1.0557 -> 26.3925 | U16: =IF(ISBLANK(M16),"0",T16*11.05+209.677) -> 501.31412 | V16: 55962 | W16: =IF(ISBLANK(V16)," ",V16-V15) -> 23 | X16: =IF(ISBLANK(V16),"0 ",W16*284.345) -> 6539.935 | Y16: =X16*0.3435 -> 2246.4677 | Z16: =IF(ISBLANK(V16),"0",1570*1487.37/12/31*0.65) -> 4080.2717 | AA16: =Y16+Z16 -> 6326.7394 | AB16: 2342873 | AC16: =IF(ISBLANK(AB16)," ",AB16-AB15) -> 6732 | AD16: 0.6857 | AE16: 298
A17: 44998 | B17: 15889915 | C17: =IF(ISBLANK(B17),"0",B17-B16) -> 8144 | D17: 17121859 | E17: =IF(ISBLANK(D17),"0",D17-D16) -> 7699 | F17: 404960 | G17: =IF(ISBLANK(F17),"0",F17-F16) -> 116 | H17: =C17+E17+G17 -> 15959 | I17: =H17*0.2 -> 3191.8 | J17: 40719 | K17: =IF(ISBLANK(J17),"0",J17-J16) -> 103 | L17: =K17*7.84 -> 807.52 | M17: 28120 | N17: =IF(ISBLANK(M17),"0",M17-M16) -> 15 | O17: 15281 | P17: =IF(ISBLANK(O17),"0",O17-O16) -> 13 | Q17: =N17+P17 -> 28 | R17: 39751 | S17: =IF(ISBLANK(R17),"0",R17-R16) -> 26 | T17: =S17*1.0557 -> 27.4482 | U17: =IF(ISBLANK(M17),"0",T17*11.05+209.677) -> 512.97961 | V17: 55986 | W17: =IF(ISBLANK(V17)," ",V17-V16) -> 24 | X17: =IF(ISBLANK(V17),"0 ",W17*284.345) -> 6824.28 | Y17: =X17*0.3435 -> 2344.1402 | Z17: =IF(ISBLANK(V17),"0",1570*1487.37/12/31*0.65) -> 4080.2717 | AA17: =Y17+Z17 -> 6424.4119 | AB17: 2350133 | AC17: =IF(ISBLANK(AB17)," ",AB17-AB16) -> 7260 | AD17: 0.854 | AE17: 357
... A35: 45016 | B35: 16033407 | C35: =IF(ISBLANK(B35),"0",B35-B34) -> 7847 | D35: 17256333 | E35: =IF(ISBLANK(D35),"0",D35-D34) -> 7119 | F35: 407173 | G35: =IF(ISBLANK(F35),"0",F35-F34) -> 121 | H35: =C35+E35+G35 -> 15087 | I35: =H35*0.2 -> 3017.4 | J35: 42302 | K35: =IF(ISBLANK(J35),"0",J35-J34) -> 69 | L35: =K35*7.84 -> 540.96 | M35: 28411 | N35: =IF(ISBLANK(M35),"0",M35-M34) -> 17 | O35: 15507 | P35: =IF(ISBLANK(O35),"0",O35-O34) -> 12 | Q35: =N35+P35 -> 29 | R35: 40251 | S35: =IF(ISBLANK(R35),"0",R35-R34) -> 28 | T35: =S35*1.0557 -> 29.5596 | U35: =IF(ISBLANK(M35),"0",T35*11.05+209.677) -> 536.31058 | V35: 56371 | W35: =IF(ISBLANK(V35)," ",V35-V34) -> 20 | X35: =IF(ISBLANK(V35),"0 ",W35*284.345) -> 5686.9 | Y35: =X35*0.3435 -> 1953.4502 | Z35: =IF(ISBLANK(V35),"0",1570*1487.37/12/31*0.65) -> 4080.2717 | AA35: =Y35+Z35 -> 6033.7219 | AB35: 2466746 | AC35: =IF(ISBLANK(AB35)," ",AB35-AB34) -> 6050 | AD35: 0.3619 | AE35: 156
C36: =SUM(C5:C35) -> 250992 | E36: =SUM(E5:E35) -> 232889 | G36: =SUM(G5:G35) -> 3798 | H36: =SUM(H5:H35) -> 487679 | I36: =H36*0.2 -> 97535.8 | K36: =SUM(K5:K35) -> 2854 | L36: =K36*7.84 -> 22375.36 | N36: =SUM(N5:N35) -> 502 | P36: =SUM(P5:P35) -> 378 | Q36: =SUM(Q5:Q35) -> 880 | S36: =SUM(S5:S35) -> 849 | T36: =SUM(T5:T35) -> 896.2893 | U36: =SUM(U5:U35) -> 16403.984 | W36: =SUM(W5:W35) -> 684 | X36: =SUM(X5:X35) -> 194491.98 | Y36: =SUM(Y5:Y35) -> 66807.995 | Z36: =SUM(Z5:Z35) -> 126488.42 | AA36: =SUM(AA5:AA35) -> 193296.42 | AC36: =SUM(AC5:AC35) -> 206183 | AD36: =AVERAGE(AD5:AD35) -> 0.64106129 | AE36: =SUM(AE5:AE35) -> 8360
V37: AVT Charges should be Zero in the DC invoice - Please notify if not
B38: Electricity | D38: AED | G38: KW | J38: Water | L38: AED | M38: M3 | O38: Gas | R38: AED | T38: M3 | V38: Chilled Water | X38: AED | Z38: Ton Hour
B39: Actual March 2023 | D39: =I36 -> 97535.8 | G39: =D39/0.2 -> 487679 | J39: =B39 -> Actual March 2023 | L39: =L36 -> 22375.36 | M39: =K36 -> 2854 | O39: =B39 -> Actual March 2023 | R39: =U36 -> 16403.984 | T39: =T36 -> 896.2893 | V39: =B39 -> Actual March 2023 | X39: =AA36 -> 193296.42 | Z39: =X36 -> 194491.98 | AD39: =AC36 -> 206183 | AE39: =AD39-X36 -> 11691.02
B40: Budget March 2023 | D40: 99603 | G40: =D40/0.2 -> 498015 | J40: =B40 -> Budget March 2023 | L40: 23170.114 | M40: =L40/7.84 -> 2955.3717 | O40: =B40 -> Budget March 2023 | R40: 16700.062 | T40: =(R40-6500)/11.05/1.0557 -> 874.37961 | V40: =B40 -> Budget March 2023 | X40: 192191.15 | Z40: =AG40/0.3435 -> 191276.56 | AG40: =X40-126487.65 -> 65703.5 | AH40: CHW Consumption Charges (Budgeted 2023 MTD)
B41: Actual March 2022 | D41: 99341.8 | G41: =D41/0.2 -> 496709 | J41: =B41 -> Actual March 2022 | L41: 20062.56 | M41: =L41/7.84 -> 2559 | O41: =B41 -> Actual March 2022 | R41: 13408.61 | T41: =(R41-6500)/9.05/1.0557 -> 723.10535 | V41: =B41 -> Actual March 2022 | X41: 182068.16 | Z41: =AG41/0.3428 -> 176328.53 | AG41: =X41-121622.74 -> 60445.42 | AH41: CHW Consumption Charges (Actual 2022 MTD)
B42: Actual YTD 2023 | D42: =D39+183274.8 -> 280810.6 | G42: =D42/0.2 -> 1404053 | J42: =B42 -> Actual YTD 2023 | L42: =L39+40666.08 -> 63041.44 | M42: =L42/7.84 -> 8041 | O42: =B42 -> Actual YTD 2023 | R42: =R39+31442.88 -> 47846.864 | T42: =(R42-6500*3)/11.05/1.0557 -> 2429.9773 | V42: =B42 -> Actual YTD 2023 | X42: =X39+353402.19 -> 546698.61 | Z42: =AG42/0.3435 -> 486857.81 | AG42: =X42-AG46 -> 167235.66 | AH42: CHW Consumption Charges (Actual 2023 YTD)
B43: Budget YTD 2023 | D43: 285277 | G43: =D43/0.2 -> 1426385 | J43: =B43 -> Budget YTD 2023 | L43: 60979 | M43: =L43/7.84 -> 7777.9337 | O43: =B43 -> Budget YTD 2023 | R43: 48289 | T43: =(R43-6500*3)/11.05/1.0557 -> 2467.8785 | V43: =B43 -> Budget YTD 2023 | X43: 538991 | Z43: =AG43/0.3435 -> 464419.36 | AG43: =X43-AG46 -> 159528.05 | AH43: CHW Consumption Charges (Budgeted 2023 YTD)
B44: Actual YTD 2022 | D44: 285695.2 | G44: =D44/0.2 -> 1428476 | J44: =B44 -> Actual YTD 2022 | L44: 58572.64 | M44: =L44/7.84 -> 7471 | O44: =B44 -> Actual YTD 2022 | R44: 43454.83 | T44: =(R44-6500*3)/9.05/1.0557 -> 2507.2867 | V44: =B44 -> Actual YTD 2022 | X44: 513911.95 | Z44: =AG44/0.3428 -> 434783.34 | AG44: =X44-AG47 -> 149043.73 | AH44: CHW Consumption Charges (Actual 2022 YTD)
G45: 44986 | I45: =TODAY() -> 45373 | J45: 31
A46: Monthly Budget | D46: Daily Budget | I46: MTD Average | N46: MTD Budget | U46: MTD Actual | AG46: =126487.65*3 -> 379462.95 | AH46: CHW Fixed Charges YTD 2023
A47: Electricity | B47: =D40 -> 99603 | D47: Electricity | G47: =B47/31 -> 3213 | I47: Electricity | L47: =I36/J45 -> 3146.3161 | N47: Electricity | R47: =G47*J45 -> 99603 | U47: Electricity | W47: =I36 -> 97535.8 | Y47: =R47-W47 -> 2067.2 | AG47: =121622.74*3 -> 364868.22 | AH47: CHW Fixed Charges YTD 2022
A48: Water | B48: =L40 -> 23170.114 | D48: Water | G48: =B48/31 -> 747.42303 | I48: Water | L48: =L36/J45 -> 721.78581 | N48: Water | R48: =G48*J45 -> 23170.114 | U48: Water | W48: =L36 -> 22375.36 | Y48: =R48-W48 -> 794.7538
A49: Gas | B49: =R40 -> 16700.062 | D49: Gas | G49: =B49/31 -> 538.71169 | I49: Gas | L49: =U36/J45 -> 529.16077 | N49: Gas | R49: =G49*J45 -> 16700.062 | U49: Gas | W49: =U36 -> 16403.984 | Y49: =R49-W49 -> 296.07852
A50: Chilled Water | B50: =X40 -> 192191.15 | D50: Chilled Water | G50: =B50/31 -> 6199.7145 | I50: Chilled Water | L50: =AA36/J45 -> 6235.3684 | N50: Chilled Water | R50: =G50*J45 -> 192191.15 | U50: Chilled Water | W50: =AA36 -> 193296.42 | Y50: =R50-W50 -> -1105.2692
B51: =SUM(B47:B50) -> 331664.33 | R51: =SUM(R47:S50) -> 331664.33 | W51: =SUM(W47:X50) -> 329611.56 | Y51: =R51-W51 -> 2052.7631
B52: =B51*X52 -> 2052.7631 | X52: =1-(W51/R51) -> 0.0061892793
A54: Actual Last Year | D54: Average Daily Consumption Last Year | I54: MTD Average Last Year | N54: MTD Actual | U54: MTD Actual Vs Last Year | Z54: MTD Fcst | AA54: YTD Fcst | AD54: MTD Saving Fcst Vs LY | AE54: YTD Saving Fcst Vs LY
A55: Electricity | B55: =D41 -> 99341.8 | D55: Electricity | G55: =B55/31 -> 3204.5742 | I55: Electricity | L55: =G55*J45 -> 99341.8 | N55: Electricity | R55: =W47 -> 97535.8 | U55: Electricity | W55: =L55-R55 -> 1806 | Z55: =L47*31 -> 97535.8 | AA55: =Z55 -> 97535.8 | AD55: =D41-Z55 -> 1806 | AE55: =D44-AA55 -> 188159.4
A56: Water | B56: =L41 -> 20062.56 | D56: Water | G56: =B56/31 -> 647.17935 | I56: Water | L56: =G56*J45 -> 20062.56 | N56: Water | R56: =W48 -> 22375.36 | U56: Water | W56: =L56-R56 -> -2312.8 | Z56: =L48*31 -> 22375.36 | AA56: =Z56 -> 22375.36 | AD56: =L41-Z56 -> -2312.8 | AE56: =L44-AA56 -> 36197.28
A57: Gas | B57: =R41 -> 13408.61 | D57: Gas | G57: =B57/31 -> 432.53581 | I57: Gas | L57: =G57*J45 -> 13408.61 | N57: Gas | R57: =W49 -> 16403.984 | U57: Gas | W57: =L57-R57 -> -2995.3738 | Z57: =L49*31 -> 16403.984 | AA57: =Z57 -> 16403.984 | AD57: =R41-Z57 -> -2995.3738 | AE57: =R44-AA57 -> 27050.846
A58: Chilled Water | B58: =X41 -> 182068.16 | D58: Chilled Water | G58: =B58/31 -> 5873.1665 | I58: Chilled Water | L58: =G58*J45 -> 182068.16 | N58: Chilled Water | R58: =W50 -> 193296.42 | U58: Chilled Water | W58: =L58-R58 -> -11228.259 | Z58: =L50*31 -> 193296.42 | AA58: =Z58 -> 193296.42 | AD58: =X41-Z58 -> -11228.259 | AE58: =Z44-AA58 -> 241486.92
...
