Workbook

Sheet Total
A1: Site Name | B1: Day | C1: Month | D1: Year | E1: Total Electricity Kwh | F1: Electricity Tariff ($/Kwh) | G1: Water Utility Supply (m3) m3 | H1: Water Utility Supply (m3) $/m3 | I1: LPG (Liters) | J1: LPG $/Liters | K1: District Energy Cooling RTH | L1: District Energy Cooling $/RTH | M1: Room Nights | N1: Cooling Degree Day
A2: Beach Rotana Abu Dhabi | B2: 1 | C2: 3 | D2: 2024 | E2: =IF((Elect!D8+Elect!F8+Elect!H8+Elect!J8+Elect!L8+Elect!N8+Elect!R8+Elect!T8+Elect!V8+Elect!X8)<0,"0",Elect!D8+Elect!F8+Elect!H8+Elect!J8+Elect!L8+Elect!N8+Elect!R8+Elect!T8+Elect!V8+Elect!X8) -> 35578 | F2: 0.439 | G2: =IF((Water!C8+Water!E8+Water!G8+Water!K8+Water!M8+Water!O8+Water!Q8)<0,"0",Water!C8+Water!E8+Water!G8+Water!K8+Water!M8+Water!O8+Water!Q8) -> 550 | H2: =2.1*0.5 -> 1.05 | I2: =IF((Gas!B8+Gas!E8+Gas!G8+Gas!I8+Gas!K8+Gas!M8+Gas!O8+Gas!Q8+Gas!S8+Gas!U8)<0,"0",Gas!B8+Gas!E8+Gas!G8+Gas!I8+Gas!K8+Gas!M8+Gas!O8+Gas!Q8+Gas!S8+Gas!U8) -> 1275 | J2: =2.1*0.5 -> 1.05 | K2: ='Chilled Water'!D4+'Chilled Water'!G4+'Chilled Water'!J4+'Chilled Water'!M4 -> 576 | L2: ='[1]MTD Utility Sheet'!F4/K2 -> 11.127396 | M2: =Elect!B8 -> 0 | N2: 4.9
A3: Beach Rotana Abu Dhabi | B3: =B2+1 -> 2 | C3: 3 | D3: 2024 | E3: =IF((Elect!D9+Elect!F9+Elect!H9+Elect!J9+Elect!L9+Elect!N9+Elect!R9+Elect!T9+Elect!V9+Elect!X9)<0,"0",Elect!D9+Elect!F9+Elect!H9+Elect!J9+Elect!L9+Elect!N9+Elect!R9+Elect!T9+Elect!V9+Elect!X9) -> 34164 | F3: 0.439 | G3: =IF((Water!C9+Water!E9+Water!G9+Water!K9+Water!M9+Water!O9+Water!Q9)<0,"0",Water!C9+Water!E9+Water!G9+Water!K9+Water!M9+Water!O9+Water!Q9) -> 511 | H3: =2.1*0.5 -> 1.05 | I3: =IF((Gas!B9+Gas!E9+Gas!G9+Gas!I9+Gas!K9+Gas!M9+Gas!O9+Gas!Q9+Gas!S9+Gas!U9)<0,"0",Gas!B9+Gas!E9+Gas!G9+Gas!I9+Gas!K9+Gas!M9+Gas!O9+Gas!Q9+Gas!S9+Gas!U9) -> 76 | J3: =2.1*0.5 -> 1.05 | K3: ='Chilled Water'!D5+'Chilled Water'!G5+'Chilled Water'!J5+'Chilled Water'!M5 -> 3543 | L3: ='[1]MTD Utility Sheet'!F5/K3 -> 1.755357 | M3: =Elect!B9 -> 0 | N3: 5
A4: Beach Rotana Abu Dhabi | B4: =B3+1 -> 3 | C4: 3 | D4: 2024 | E4: =IF((Elect!D10+Elect!F10+Elect!H10+Elect!J10+Elect!L10+Elect!N10+Elect!R10+Elect!T10+Elect!V10+Elect!X10)<0,"0",Elect!D10+Elect!F10+Elect!H10+Elect!J10+Elect!L10+Elect!N10+Elect!R10+Elect!T10+Elect!V10+Elect!X10) -> 34097 | F4: 0.439 | G4: =IF((Water!C10+Water!E10+Water!G10+Water!K10+Water!M10+Water!O10+Water!Q10)<0,"0",Water!C10+Water!E10+Water!G10+Water!K10+Water!M10+Water!O10+Water!Q10) -> 464 | H4: =2.1*0.5 -> 1.05 | I4: =IF((Gas!B10+Gas!E10+Gas!G10+Gas!I10+Gas!K10+Gas!M10+Gas!O10+Gas!Q10+Gas!S10+Gas!U10)<0,"0",Gas!B10+Gas!E10+Gas!G10+Gas!I10+Gas!K10+Gas!M10+Gas!O10+Gas!Q10+Gas!S10+Gas!U10) -> 73 | J4: =2.1*0.5 -> 1.05 | K4: ='Chilled Water'!D6+'Chilled Water'!G6+'Chilled Water'!J6+'Chilled Water'!M6 -> 3671 | L4: ='[1]MTD Utility Sheet'!F6/K4 -> 1.8072106 | M4: =Elect!B10 -> 0 | N4: 5.1
A5: Beach Rotana Abu Dhabi | B5: =B4+1 -> 4 | C5: 3 | D5: 2024 | E5: =IF((Elect!D11+Elect!F11+Elect!H11+Elect!J11+Elect!L11+Elect!N11+Elect!R11+Elect!T11+Elect!V11+Elect!X11)<0,"0",Elect!D11+Elect!F11+Elect!H11+Elect!J11+Elect!L11+Elect!N11+Elect!R11+Elect!T11+Elect!V11+Elect!X11) -> 34211 | F5: 0.439 | G5: =IF((Water!C11+Water!E11+Water!G11+Water!K11+Water!M11+Water!O11+Water!Q11)<0,"0",Water!C11+Water!E11+Water!G11+Water!K11+Water!M11+Water!O11+Water!Q11) -> 498 | H5: =2.1*0.5 -> 1.05 | I5: =IF((Gas!B11+Gas!E11+Gas!G11+Gas!I11+Gas!K11+Gas!M11+Gas!O11+Gas!Q11+Gas!S11+Gas!U11)<0,"0",Gas!B11+Gas!E11+Gas!G11+Gas!I11+Gas!K11+Gas!M11+Gas!O11+Gas!Q11+Gas!S11+Gas!U11) -> 74 | J5: =2.1*0.5 -> 1.05 | K5: ='Chilled Water'!D7+'Chilled Water'!G7+'Chilled Water'!J7+'Chilled Water'!M7 -> 3504 | L5: ='[1]MTD Utility Sheet'!F7/K5 -> 1.7623716 | M5: =Elect!B11 -> 0 | N5: 3.8
A6: Beach Rotana Abu Dhabi | B6: =B5+1 -> 5 | C6: 3 | D6: 2024 | E6: =IF((Elect!D12+Elect!F12+Elect!H12+Elect!J12+Elect!L12+Elect!N12+Elect!R12+Elect!T12+Elect!V12+Elect!X12)<0,"0",Elect!D12+Elect!F12+Elect!H12+Elect!J12+Elect!L12+Elect!N12+Elect!R12+Elect!T12+Elect!V12+Elect!X12) -> 35774 | F6: 0.439 | G6: =IF((Water!C12+Water!E12+Water!G12+Water!K12+Water!M12+Water!O12+Water!Q12)<0,"0",Water!C12+Water!E12+Water!G12+Water!K12+Water!M12+Water!O12+Water!Q12) -> 546 | H6: =2.1*0.5 -> 1.05 | I6: =IF((Gas!B12+Gas!E12+Gas!G12+Gas!I12+Gas!K12+Gas!M12+Gas!O12+Gas!Q12+Gas!S12+Gas!U12)<0,"0",Gas!B12+Gas!E12+Gas!G12+Gas!I12+Gas!K12+Gas!M12+Gas!O12+Gas!Q12+Gas!S12+Gas!U12) -> 72 | J6: =2.1*0.5 -> 1.05 | K6: ='Chilled Water'!D8+'Chilled Water'!G8+'Chilled Water'!J8+'Chilled Water'!M8 -> 3420 | L6: ='[1]MTD Utility Sheet'!F8/K6 -> 1.816886 | M6: =Elect!B12 -> 0 | N6: 4.1
A7: Beach Rotana Abu Dhabi | B7: =B6+1 -> 6 | C7: 3 | D7: 2024 | E7: =IF((Elect!D13+Elect!F13+Elect!H13+Elect!J13+Elect!L13+Elect!N13+Elect!R13+Elect!T13+Elect!V13+Elect!X13)<0,"0",Elect!D13+Elect!F13+Elect!H13+Elect!J13+Elect!L13+Elect!N13+Elect!R13+Elect!T13+Elect!V13+Elect!X13) -> 35146 | F7: 0.439 | G7: =IF((Water!C13+Water!E13+Water!G13+Water!K13+Water!M13+Water!O13+Water!Q13)<0,"0",Water!C13+Water!E13+Water!G13+Water!K13+Water!M13+Water!O13+Water!Q13) -> 460 | H7: =2.1*0.5 -> 1.05 | I7: =IF((Gas!B13+Gas!E13+Gas!G13+Gas!I13+Gas!K13+Gas!M13+Gas!O13+Gas!Q13+Gas!S13+Gas!U13)<0,"0",Gas!B13+Gas!E13+Gas!G13+Gas!I13+Gas!K13+Gas!M13+Gas!O13+Gas!Q13+Gas!S13+Gas!U13) -> 79 | J7: =2.1*0.5 -> 1.05 | K7: ='Chilled Water'!D9+'Chilled Water'!G9+'Chilled Water'!J9+'Chilled Water'!M9 -> 3604 | L7: ='[1]MTD Utility Sheet'!F9/K7 -> 1.7352858 | M7: =Elect!B13 -> 0 | N7: 4.3
A8: Beach Rotana Abu Dhabi | B8: =B7+1 -> 7 | C8: 3 | D8: 2024 | E8: =IF((Elect!D14+Elect!F14+Elect!H14+Elect!J14+Elect!L14+Elect!N14+Elect!R14+Elect!T14+Elect!V14+Elect!X14)<0,"0",Elect!D14+Elect!F14+Elect!H14+Elect!J14+Elect!L14+Elect!N14+Elect!R14+Elect!T14+Elect!V14+Elect!X14) -> 35292 | F8: 0.439 | G8: =IF((Water!C14+Water!E14+Water!G14+Water!K14+Water!M14+Water!O14+Water!Q14)<0,"0",Water!C14+Water!E14+Water!G14+Water!K14+Water!M14+Water!O14+Water!Q14) -> 530 | H8: =2.1*0.5 -> 1.05 | I8: =IF((Gas!B14+Gas!E14+Gas!G14+Gas!I14+Gas!K14+Gas!M14+Gas!O14+Gas!Q14+Gas!S14+Gas!U14)<0,"0",Gas!B14+Gas!E14+Gas!G14+Gas!I14+Gas!K14+Gas!M14+Gas!O14+Gas!Q14+Gas!S14+Gas!U14) -> 88 | J8: =2.1*0.5 -> 1.05 | K8: ='Chilled Water'!D10+'Chilled Water'!G10+'Chilled Water'!J10+'Chilled Water'!M10 -> 3649 | L8: ='[1]MTD Utility Sheet'!F10/K8 -> 1.6151768 | M8: =Elect!B14 -> 0 | N8: 4.6
A9: Beach Rotana Abu Dhabi | B9: =B8+1 -> 8 | C9: 3 | D9: 2024 | E9: =IF((Elect!D15+Elect!F15+Elect!H15+Elect!J15+Elect!L15+Elect!N15+Elect!R15+Elect!T15+Elect!V15+Elect!X15)<0,"0",Elect!D15+Elect!F15+Elect!H15+Elect!J15+Elect!L15+Elect!N15+Elect!R15+Elect!T15+Elect!V15+Elect!X15) -> 34626 | F9: 0.439 | G9: =IF((Water!C15+Water!E15+Water!G15+Water!K15+Water!M15+Water!O15+Water!Q15)<0,"0",Water!C15+Water!E15+Water!G15+Water!K15+Water!M15+Water!O15+Water!Q15) -> 550 | H9: =2.1*0.5 -> 1.05 | I9: =IF((Gas!B15+Gas!E15+Gas!G15+Gas!I15+Gas!K15+Gas!M15+Gas!O15+Gas!Q15+Gas!S15+Gas!U15)<0,"0",Gas!B15+Gas!E15+Gas!G15+Gas!I15+Gas!K15+Gas!M15+Gas!O15+Gas!Q15+Gas!S15+Gas!U15) -> 89 | J9: =2.1*0.5 -> 1.05 | K9: ='Chilled Water'!D11+'Chilled Water'!G11+'Chilled Water'!J11+'Chilled Water'!M11 -> 3584 | L9: ='[1]MTD Utility Sheet'!F11/K9 -> 1.7306864 | M9: =Elect!B15 -> 0 | N9: 6
A10: Beach Rotana Abu Dhabi | B10: =B9+1 -> 9 | C10: 3 | D10: 2024 | E10: =IF((Elect!D16+Elect!F16+Elect!H16+Elect!J16+Elect!L16+Elect!N16+Elect!R16+Elect!T16+Elect!V16+Elect!X16)<0,"0",Elect!D16+Elect!F16+Elect!H16+Elect!J16+Elect!L16+Elect!N16+Elect!R16+Elect!T16+Elect!V16+Elect!X16) -> 38992 | F10: 0.439 | G10: =IF((Water!C16+Water!E16+Water!G16+Water!K16+Water!M16+Water!O16+Water!Q16)<0,"0",Water!C16+Water!E16+Water!G16+Water!K16+Water!M16+Water!O16+Water!Q16) -> 477 | H10: =2.1*0.5 -> 1.05 | I10: =IF((Gas!B16+Gas!E16+Gas!G16+Gas!I16+Gas!K16+Gas!M16+Gas!O16+Gas!Q16+Gas!S16+Gas!U16)<0,"0",Gas!B16+Gas!E16+Gas!G16+Gas!I16+Gas!K16+Gas!M16+Gas!O16+Gas!Q16+Gas!S16+Gas!U16) -> 94 | J10: =2.1*0.5 -> 1.05 | K10: ='Chilled Water'!D12+'Chilled Water'!G12+'Chilled Water'!J12+'Chilled Water'!M12 -> 3861 | L10: ='[1]MTD Utility Sheet'!F12/K10 -> 1.6230951 | M10: =Elect!B16 -> 0 | N10: 8
A11: Beach Rotana Abu Dhabi | B11: =B10+1 -> 10 | C11: 3 | D11: 2024 | E11: =IF((Elect!D17+Elect!F17+Elect!H17+Elect!J17+Elect!L17+Elect!N17+Elect!R17+Elect!T17+Elect!V17+Elect!X17)<0,"0",Elect!D17+Elect!F17+Elect!H17+Elect!J17+Elect!L17+Elect!N17+Elect!R17+Elect!T17+Elect!V17+Elect!X17) -> 36513 | F11: 0.439 | G11: =IF((Water!C17+Water!E17+Water!G17+Water!K17+Water!M17+Water!O17+Water!Q17)<0,"0",Water!C17+Water!E17+Water!G17+Water!K17+Water!M17+Water!O17+Water!Q17) -> 466 | H11: =2.1*0.5 -> 1.05 | I11: =IF((Gas!B17+Gas!E17+Gas!G17+Gas!I17+Gas!K17+Gas!M17+Gas!O17+Gas!Q17+Gas!S17+Gas!U17)<0,"0",Gas!B17+Gas!E17+Gas!G17+Gas!I17+Gas!K17+Gas!M17+Gas!O17+Gas!Q17+Gas!S17+Gas!U17) -> 75 | J11: =2.1*0.5 -> 1.05 | K11: ='Chilled Water'!D13+'Chilled Water'!G13+'Chilled Water'!J13+'Chilled Water'!M13 -> 3718 | L11: ='[1]MTD Utility Sheet'!F13/K11 -> 1.7278133 | M11: =Elect!B17 -> 0 | N11: 8.2
A12: Beach Rotana Abu Dhabi | B12: =B11+1 -> 11 | C12: 3 | D12: 2024 | E12: =IF((Elect!D18+Elect!F18+Elect!H18+Elect!J18+Elect!L18+Elect!N18+Elect!R18+Elect!T18+Elect!V18+Elect!X18)<0,"0",Elect!D18+Elect!F18+Elect!H18+Elect!J18+Elect!L18+Elect!N18+Elect!R18+Elect!T18+Elect!V18+Elect!X18) -> 35616 | F12: 0.439 | G12: =IF((Water!C18+Water!E18+Water!G18+Water!K18+Water!M18+Water!O18+Water!Q18)<0,"0",Water!C18+Water!E18+Water!G18+Water!K18+Water!M18+Water!O18+Water!Q18) -> 480 | H12: =2.1*0.5 -> 1.05 | I12: =IF((Gas!B18+Gas!E18+Gas!G18+Gas!I18+Gas!K18+Gas!M18+Gas!O18+Gas!Q18+Gas!S18+Gas!U18)<0,"0",Gas!B18+Gas!E18+Gas!G18+Gas!I18+Gas!K18+Gas!M18+Gas!O18+Gas!Q18+Gas!S18+Gas!U18) -> 1677 | J12: =2.1*0.5 -> 1.05 | K12: ='Chilled Water'!D14+'Chilled Water'!G14+'Chilled Water'!J14+'Chilled Water'!M14 -> 3503 | L12: ='[1]MTD Utility Sheet'!F14/K12 -> 1.7947131 | M12: =Elect!B18 -> 0 | N12: 8.3
A13: Beach Rotana Abu Dhabi | B13: =B12+1 -> 12 | C13: 3 | D13: 2024 | E13: =IF((Elect!D19+Elect!F19+Elect!H19+Elect!J19+Elect!L19+Elect!N19+Elect!R19+Elect!T19+Elect!V19+Elect!X19)<0,"0",Elect!D19+Elect!F19+Elect!H19+Elect!J19+Elect!L19+Elect!N19+Elect!R19+Elect!T19+Elect!V19+Elect!X19) -> 35814 | F13: 0.439 | G13: =IF((Water!C19+Water!E19+Water!G19+Water!K19+Water!M19+Water!O19+Water!Q19)<0,"0",Water!C19+Water!E19+Water!G19+Water!K19+Water!M19+Water!O19+Water!Q19) -> 476 | H13: =2.1*0.5 -> 1.05 | I13: =IF((Gas!B19+Gas!E19+Gas!G19+Gas!I19+Gas!K19+Gas!M19+Gas!O19+Gas!Q19+Gas!S19+Gas!U19)<0,"0",Gas!B19+Gas!E19+Gas!G19+Gas!I19+Gas!K19+Gas!M19+Gas!O19+Gas!Q19+Gas!S19+Gas!U19) -> 76 | J13: =2.1*0.5 -> 1.05 | K13: ='Chilled Water'!D15+'Chilled Water'!G15+'Chilled Water'!J15+'Chilled Water'!M15 -> 3892 | L13: ='[1]MTD Utility Sheet'!F15/K13 -> 1.6214414 | M13: =Elect!B19 -> 0 | N13: 8.7
A14: Beach Rotana Abu Dhabi | B14: =B13+1 -> 13 | C14: 3 | D14: 2024 | E14: =IF((Elect!D20+Elect!F20+Elect!H20+Elect!J20+Elect!L20+Elect!N20+Elect!R20+Elect!T20+Elect!V20+Elect!X20)<0,"0",Elect!D20+Elect!F20+Elect!H20+Elect!J20+Elect!L20+Elect!N20+Elect!R20+Elect!T20+Elect!V20+Elect!X20) -> 0 | F14: 0.439 | G14: =IF((Water!C20+Water!E20+Water!G20+Water!K20+Water!M20+Water!O20+Water!Q20)<0,"0",Water!C20+Water!E20+Water!G20+Water!K20+Water!M20+Water!O20+Water!Q20) -> 0 | H14: =2.1*0.5 -> 1.05 | I14: =IF((Gas!B20+Gas!E20+Gas!G20+Gas!I20+Gas!K20+Gas!M20+Gas!O20+Gas!Q20+Gas!S20+Gas!U20)<0,"0",Gas!B20+Gas!E20+Gas!G20+Gas!I20+Gas!K20+Gas!M20+Gas!O20+Gas!Q20+Gas!S20+Gas!U20) -> 0 | J14: =2.1*0.5 -> 1.05 | K14: ='Chilled Water'!D16+'Chilled Water'!G16+'Chilled Water'!J16+'Chilled Water'!M16 -> -40525 | L14: ='[1]MTD Utility Sheet'!F16/K14 -> -0.15793313 | M14: =Elect!B20 -> 0 | N14: 7.9
... A32: Beach Rotana Abu Dhabi | B32: =B31+1 -> 31 | C32: 3 | D32: 2024 | E32: =IF((Elect!D38+Elect!F38+Elect!H38+Elect!J38+Elect!L38+Elect!N38+Elect!R38+Elect!T38+Elect!V38+Elect!X38)<0,"0",Elect!D38+Elect!F38+Elect!H38+Elect!J38+Elect!L38+Elect!N38+Elect!R38+Elect!T38+Elect!V38+Elect!X38) -> 0 | F32: 0.439 | G32: =IF((Water!C38+Water!E38+Water!G38+Water!K38+Water!M38+Water!O38+Water!Q38)<0,"0",Water!C38+Water!E38+Water!G38+Water!K38+Water!M38+Water!O38+Water!Q38) -> 0 | H32: =2.1*0.5 -> 1.05 | I32: =IF((Gas!B38+Gas!E38+Gas!G38+Gas!I38+Gas!K38+Gas!M38+Gas!O38+Gas!Q38+Gas!S38+Gas!U38)<0,"0",Gas!B38+Gas!E38+Gas!G38+Gas!I38+Gas!K38+Gas!M38+Gas!O38+Gas!Q38+Gas!S38+Gas!U38) -> 0 | J32: =2.1*0.5 -> 1.05 | K32: ='Chilled Water'!D34+'Chilled Water'!G34+'Chilled Water'!J34+'Chilled Water'!M34 -> 0 | L32: ='[1]MTD Utility Sheet'!F34/K32 -> #DIV/0! | M32: =Elect!B38 -> 0 | N32: 3.5

Sheet Submetering
A1: Site Name | B1: Day | C1: Month | D1: Year | E1: Beach wing Meter 1 | F1: Beach wing Meter 2 | G1: Beach wing Meter 3 | H1: Bayview | I1: Ballroom | J1: Tower - Grand Lobby | K1: Tower - Hotel | L1: Tower - Restaurant | M1: Tennis Court | N1: Diving Center | O1: Hotel Appartments | P1: Room Nights
A2: Beach Rotana Abu Dhabi | B2: 1 | C2: 3 | D2: 2024 | E2: =Elect!D8 -> 3774 | F2: =Elect!F8 -> 4097 | G2: =Elect!H8 -> 9721 | H2: =Elect!J8 -> 2194 | I2: =Elect!L8 -> 3260 | J2: =Elect!N8 -> 1180 | K2: =Elect!P8 -> 6190 | L2: =Elect!R8 -> 6660 | M2: =Elect!T8 -> 45 | N2: =Elect!V8 -> 0 | O2: =Elect!X8 -> 4647 | P2: =Elect!B8 -> 0
A3: Beach Rotana Abu Dhabi | B3: =B2+1 -> 2 | C3: 3 | D3: 2024 | E3: =Elect!D9 -> 2727 | F3: =Elect!F9 -> 3992 | G3: =Elect!H9 -> 10541 | H3: =Elect!J9 -> 2236 | I3: =Elect!L9 -> 3120 | J3: =Elect!N9 -> 1190 | K3: =Elect!P9 -> 6506 | L3: =Elect!R9 -> 6280 | M3: =Elect!T9 -> 39 | N3: =Elect!V9 -> 0 | O3: =Elect!X9 -> 4039 | P3: =Elect!B9 -> 0
A4: Beach Rotana Abu Dhabi | B4: =B3+1 -> 3 | C4: 3 | D4: 2024 | E4: =Elect!D10 -> 5968 | F4: =Elect!F10 -> 3773 | G4: =Elect!H10 -> 7324 | H4: =Elect!J10 -> 2285 | I4: =Elect!L10 -> 3180 | J4: =Elect!N10 -> 1130 | K4: =Elect!P10 -> 6675 | L4: =Elect!R10 -> 6340 | M4: =Elect!T10 -> 33 | N4: =Elect!V10 -> 0 | O4: =Elect!X10 -> 4064 | P4: =Elect!B10 -> 0
A5: Beach Rotana Abu Dhabi | B5: =B4+1 -> 4 | C5: 3 | D5: 2024 | E5: =Elect!D11 -> 4066 | F5: =Elect!F11 -> 3716 | G5: =Elect!H11 -> 8642 | H5: =Elect!J11 -> 2329 | I5: =Elect!L11 -> 3030 | J5: =Elect!N11 -> 1060 | K5: =Elect!P11 -> 6542 | L5: =Elect!R11 -> 6010 | M5: =Elect!T11 -> 35 | N5: =Elect!V11 -> 0 | O5: =Elect!X11 -> 5323 | P5: =Elect!B11 -> 0
A6: Beach Rotana Abu Dhabi | B6: =B5+1 -> 5 | C6: 3 | D6: 2024 | E6: =Elect!D12 -> 6362 | F6: =Elect!F12 -> 4964 | G6: =Elect!H12 -> 7342 | H6: =Elect!J12 -> 2321 | I6: =Elect!L12 -> 3010 | J6: =Elect!N12 -> 1150 | K6: =Elect!P12 -> 6336 | L6: =Elect!R12 -> 6360 | M6: =Elect!T12 -> 65 | N6: =Elect!V12 -> 0 | O6: =Elect!X12 -> 4200 | P6: =Elect!B12 -> 0
A7: Beach Rotana Abu Dhabi | B7: =B6+1 -> 6 | C7: 3 | D7: 2024 | E7: =Elect!D13 -> 3565 | F7: =Elect!F13 -> 3566 | G7: =Elect!H13 -> 10911 | H7: =Elect!J13 -> 2301 | I7: =Elect!L13 -> 3060 | J7: =Elect!N13 -> 1130 | K7: =Elect!P13 -> 6247 | L7: =Elect!R13 -> 6530 | M7: =Elect!T13 -> 31 | N7: =Elect!V13 -> 0 | O7: =Elect!X13 -> 4052 | P7: =Elect!B13 -> 0
A8: Beach Rotana Abu Dhabi | B8: =B7+1 -> 7 | C8: 3 | D8: 2024 | E8: =Elect!D14 -> 6386 | F8: =Elect!F14 -> 3729 | G8: =Elect!H14 -> 7755 | H8: =Elect!J14 -> 2319 | I8: =Elect!L14 -> 3070 | J8: =Elect!N14 -> 1160 | K8: =Elect!P14 -> 6390 | L8: =Elect!R14 -> 6670 | M8: =Elect!T14 -> 35 | N8: =Elect!V14 -> 0 | O8: =Elect!X14 -> 4168 | P8: =Elect!B14 -> 0
A9: Beach Rotana Abu Dhabi | B9: =B8+1 -> 8 | C9: 3 | D9: 2024 | E9: =Elect!D15 -> 3793 | F9: =Elect!F15 -> 6945 | G9: =Elect!H15 -> 6128 | H9: =Elect!J15 -> 2285 | I9: =Elect!L15 -> 3100 | J9: =Elect!N15 -> 1170 | K9: =Elect!P15 -> 6384 | L9: =Elect!R15 -> 7070 | M9: =Elect!T15 -> 59 | N9: =Elect!V15 -> 0 | O9: =Elect!X15 -> 4076 | P9: =Elect!B15 -> 0
A10: Beach Rotana Abu Dhabi | B10: =B9+1 -> 9 | C10: 3 | D10: 2024 | E10: =Elect!D16 -> 7401 | F10: =Elect!F16 -> 4614 | G10: =Elect!H16 -> 8499 | H10: =Elect!J16 -> 2207 | I10: =Elect!L16 -> 3440 | J10: =Elect!N16 -> 1170 | K10: =Elect!P16 -> 5778 | L10: =Elect!R16 -> 7450 | M10: =Elect!T16 -> 46 | N10: =Elect!V16 -> 0 | O10: =Elect!X16 -> 4165 | P10: =Elect!B16 -> 0
A11: Beach Rotana Abu Dhabi | B11: =B10+1 -> 10 | C11: 3 | D11: 2024 | E11: =Elect!D17 -> 3442 | F11: =Elect!F17 -> 3904 | G11: =Elect!H17 -> 11834 | H11: =Elect!J17 -> 2008 | I11: =Elect!L17 -> 3260 | J11: =Elect!N17 -> 1150 | K11: =Elect!P17 -> 5514 | L11: =Elect!R17 -> 6750 | M11: =Elect!T17 -> 8 | N11: =Elect!V17 -> 0 | O11: =Elect!X17 -> 4157 | P11: =Elect!B17 -> 0
A12: Beach Rotana Abu Dhabi | B12: =B11+1 -> 11 | C12: 3 | D12: 2024 | E12: =Elect!D18 -> 7906 | F12: =Elect!F18 -> 3731 | G12: =Elect!H18 -> 6516 | H12: =Elect!J18 -> 2168 | I12: =Elect!L18 -> 3220 | J12: =Elect!N18 -> 1140 | K12: =Elect!P18 -> 6029 | L12: =Elect!R18 -> 6750 | M12: =Elect!T18 -> 45 | N12: =Elect!V18 -> 0 | O12: =Elect!X18 -> 4140 | P12: =Elect!B18 -> 0
A13: Beach Rotana Abu Dhabi | B13: =B12+1 -> 12 | C13: 3 | D13: 2024 | E13: =Elect!D19 -> 8396 | F13: =Elect!F19 -> 3606 | G13: =Elect!H19 -> 6974 | H13: =Elect!J19 -> 2282 | I13: =Elect!L19 -> 3090 | J13: =Elect!N19 -> 1110 | K13: =Elect!P19 -> 5934 | L13: =Elect!R19 -> 6130 | M13: =Elect!T19 -> 51 | N13: =Elect!V19 -> 0 | O13: =Elect!X19 -> 4175 | P13: =Elect!B19 -> 0
A14: Beach Rotana Abu Dhabi | B14: =B13+1 -> 13 | C14: 3 | D14: 2024 | E14: =Elect!D20 -> -1452705 | F14: =Elect!F20 -> -32489058 | G14: =Elect!H20 -> -48264287 | H14: =Elect!J20 -> -2295740 | I14: =Elect!L20 -> -9681200 | J14: =Elect!N20 -> -5926210 | K14: =Elect!P20 -> -379773 | L14: =Elect!R20 -> -4934540 | M14: =Elect!T20 -> -53344 | N14: =Elect!V20 -> 0 | O14: =Elect!X20 -> -9364241 | P14: =Elect!B20 -> 0
... A32: Beach Rotana Abu Dhabi | B32: =B31+1 -> 31 | C32: 3 | D32: 2024 | E32: =Elect!D38 -> 0 | F32: =Elect!F38 -> 0 | G32: =Elect!H38 -> 0 | H32: =Elect!J38 -> 0 | I32: =Elect!L38 -> 0 | J32: =Elect!N38 -> 0 | K32: =Elect!P38 -> 0 | L32: =Elect!R38 -> 0 | M32: =Elect!T38 -> 0 | N32: =Elect!V38 -> 0 | O32: =Elect!X38 -> 0 | P32: =Elect!B38 -> 0

Sheet Elect
A1: BEACH ROTANA ABUDHABI
A2: DAILY ELECTRICITY METER READING
A3: For Month of March 2024
A5: Date | C5: BEACH WING | I5: Bay View Restaurant | K5: Ballroom | M5: TOWER WING | S5: Tennis Court | U5: Diving Center | W5: HOTEL APARTMENTS
B6: OCCUPANCY | C6: Meter 1 | E6: Meter 2 | G6: Meter 3 | M6: Grand Lobby | O6: Hotel | Q6: Restaurants
C7: R | D7: C | E7: R | F7: C | G7: R | H7: C | I7: R | J7: C | K7: R | L7: C | M7: R | N7: C | O7: R | P7: C | Q7: R | R7: C | S7: R | T7: C | U7: R | V7: C | W7: R | X7: C
A8: 45352 | C8: 1392693 | D8: =C8-1388919 -> 3774 | E8: 32442518 | F8: =E8-32438421 -> 4097 | G8: 48171821 | H8: =G8-48162100 -> 9721 | I8: 2270999 | J8: =I8-2268805 -> 2194 | K8: 9646620 | L8: =K8-9643360 -> 3260 | M8: 5913650 | N8: =M8-5912470 -> 1180 | O8: 311438 | P8: =O8-305248 -> 6190 | Q8: 4862200 | R8: =Q8-4855540 -> 6660 | S8: 52897 | T8: =S8-52852 -> 45 | U8: 33955 | V8: =U8-33955 -> 0 | W8: 9317682 | X8: =W8-9313035 -> 4647
A9: 45353 | C9: 1395420 | D9: =C9-C8 -> 2727 | E9: 32446510 | F9: =E9-E8 -> 3992 | G9: 48182362 | H9: =G9-G8 -> 10541 | I9: 2273235 | J9: =I9-I8 -> 2236 | K9: 9649740 | L9: =K9-K8 -> 3120 | M9: 5914840 | N9: =M9-M8 -> 1190 | O9: 317944 | P9: =O9-O8 -> 6506 | Q9: 4868480 | R9: =Q9-Q8 -> 6280 | S9: 52936 | T9: =S9-S8 -> 39 | U9: 33955 | V9: =U9-U8 -> 0 | W9: 9321721 | X9: =W9-W8 -> 4039
A10: 45354 | C10: 1401388 | D10: =C10-C9 -> 5968 | E10: 32450283 | F10: =E10-E9 -> 3773 | G10: 48189686 | H10: =G10-G9 -> 7324 | I10: 2275520 | J10: =I10-I9 -> 2285 | K10: 9652920 | L10: =K10-K9 -> 3180 | M10: 5915970 | N10: =M10-M9 -> 1130 | O10: 324619 | P10: =O10-O9 -> 6675 | Q10: 4874820 | R10: =Q10-Q9 -> 6340 | S10: 52969 | T10: =S10-S9 -> 33 | U10: 33955 | V10: =U10-U9 -> 0 | W10: 9325785 | X10: =W10-W9 -> 4064
A11: 45355 | C11: 1405454 | D11: =C11-C10 -> 4066 | E11: 32453999 | F11: =E11-E10 -> 3716 | G11: 48198328 | H11: =G11-G10 -> 8642 | I11: 2277849 | J11: =I11-I10 -> 2329 | K11: 9655950 | L11: =K11-K10 -> 3030 | M11: 5917030 | N11: =M11-M10 -> 1060 | O11: 331161 | P11: =O11-O10 -> 6542 | Q11: 4880830 | R11: =Q11-Q10 -> 6010 | S11: 53004 | T11: =S11-S10 -> 35 | U11: 33955 | V11: =U11-U10 -> 0 | W11: 9331108 | X11: =W11-W10 -> 5323
A12: 45356 | C12: 1411816 | D12: =C12-C11 -> 6362 | E12: 32458963 | F12: =E12-E11 -> 4964 | G12: 48205670 | H12: =G12-G11 -> 7342 | I12: 2280170 | J12: =I12-I11 -> 2321 | K12: 9658960 | L12: =K12-K11 -> 3010 | M12: 5918180 | N12: =M12-M11 -> 1150 | O12: 337497 | P12: =O12-O11 -> 6336 | Q12: 4887190 | R12: =Q12-Q11 -> 6360 | S12: 53069 | T12: =S12-S11 -> 65 | U12: 33955 | V12: =U12-U11 -> 0 | W12: 9335308 | X12: =W12-W11 -> 4200
A13: 45357 | C13: 1415381 | D13: =C13-C12 -> 3565 | E13: 32462529 | F13: =E13-E12 -> 3566 | G13: 48216581 | H13: =G13-G12 -> 10911 | I13: 2282471 | J13: =I13-I12 -> 2301 | K13: 9662020 | L13: =K13-K12 -> 3060 | M13: 5919310 | N13: =M13-M12 -> 1130 | O13: 343744 | P13: =O13-O12 -> 6247 | Q13: 4893720 | R13: =Q13-Q12 -> 6530 | S13: 53100 | T13: =S13-S12 -> 31 | U13: 33955 | V13: =U13-U12 -> 0 | W13: 9339360 | X13: =W13-W12 -> 4052
A14: 45358 | C14: 1421767 | D14: =C14-C13 -> 6386 | E14: 32466258 | F14: =E14-E13 -> 3729 | G14: 48224336 | H14: =G14-G13 -> 7755 | I14: 2284790 | J14: =I14-I13 -> 2319 | K14: 9665090 | L14: =K14-K13 -> 3070 | M14: 5920470 | N14: =M14-M13 -> 1160 | O14: 350134 | P14: =O14-O13 -> 6390 | Q14: 4900390 | R14: =Q14-Q13 -> 6670 | S14: 53135 | T14: =S14-S13 -> 35 | U14: 33955 | V14: =U14-U13 -> 0 | W14: 9343528 | X14: =W14-W13 -> 4168
A15: 45359 | C15: 1425560 | D15: =C15-C14 -> 3793 | E15: 32473203 | F15: =E15-E14 -> 6945 | G15: 48230464 | H15: =G15-G14 -> 6128 | I15: 2287075 | J15: =I15-I14 -> 2285 | K15: 9668190 | L15: =K15-K14 -> 3100 | M15: 5921640 | N15: =M15-M14 -> 1170 | O15: 356518 | P15: =O15-O14 -> 6384 | Q15: 4907460 | R15: =Q15-Q14 -> 7070 | S15: 53194 | T15: =S15-S14 -> 59 | U15: 33955 | V15: =U15-U14 -> 0 | W15: 9347604 | X15: =W15-W14 -> 4076
A16: 45360 | C16: 1432961 | D16: =C16-C15 -> 7401 | E16: 32477817 | F16: =E16-E15 -> 4614 | G16: 48238963 | H16: =G16-G15 -> 8499 | I16: 2289282 | J16: =I16-I15 -> 2207 | K16: 9671630 | L16: =K16-K15 -> 3440 | M16: 5922810 | N16: =M16-M15 -> 1170 | O16: 362296 | P16: =O16-O15 -> 5778 | Q16: 4914910 | R16: =Q16-Q15 -> 7450 | S16: 53240 | T16: =S16-S15 -> 46 | U16: 33955 | V16: =U16-U15 -> 0 | W16: 9351769 | X16: =W16-W15 -> 4165
A17: 45361 | C17: 1436403 | D17: =C17-C16 -> 3442 | E17: 32481721 | F17: =E17-E16 -> 3904 | G17: 48250797 | H17: =G17-G16 -> 11834 | I17: 2291290 | J17: =I17-I16 -> 2008 | K17: 9674890 | L17: =K17-K16 -> 3260 | M17: 5923960 | N17: =M17-M16 -> 1150 | O17: 367810 | P17: =O17-O16 -> 5514 | Q17: 4921660 | R17: =Q17-Q16 -> 6750 | S17: 53248 | T17: =S17-S16 -> 8 | U17: 33955 | V17: =U17-U16 -> 0 | W17: 9355926 | X17: =W17-W16 -> 4157
A18: 45362 | C18: 1444309 | D18: =C18-C17 -> 7906 | E18: 32485452 | F18: =E18-E17 -> 3731 | G18: 48257313 | H18: =G18-G17 -> 6516 | I18: 2293458 | J18: =I18-I17 -> 2168 | K18: 9678110 | L18: =K18-K17 -> 3220 | M18: 5925100 | N18: =M18-M17 -> 1140 | O18: 373839 | P18: =O18-O17 -> 6029 | Q18: 4928410 | R18: =Q18-Q17 -> 6750 | S18: 53293 | T18: =S18-S17 -> 45 | U18: 33955 | V18: =U18-U17 -> 0 | W18: 9360066 | X18: =W18-W17 -> 4140
A19: 45363 | C19: 1452705 | D19: =C19-C18 -> 8396 | E19: 32489058 | F19: =E19-E18 -> 3606 | G19: 48264287 | H19: =G19-G18 -> 6974 | I19: 2295740 | J19: =I19-I18 -> 2282 | K19: 9681200 | L19: =K19-K18 -> 3090 | M19: 5926210 | N19: =M19-M18 -> 1110 | O19: 379773 | P19: =O19-O18 -> 5934 | Q19: 4934540 | R19: =Q19-Q18 -> 6130 | S19: 53344 | T19: =S19-S18 -> 51 | U19: 33955 | V19: =U19-U18 -> 0 | W19: 9364241 | X19: =W19-W18 -> 4175
A20: 45364 | D20: =C20-C19 -> -1452705 | F20: =E20-E19 -> -32489058 | H20: =G20-G19 -> -48264287 | J20: =I20-I19 -> -2295740 | L20: =K20-K19 -> -9681200 | N20: =M20-M19 -> -5926210 | P20: =O20-O19 -> -379773 | R20: =Q20-Q19 -> -4934540 | T20: =S20-S19 -> -53344 | U20: 33955 | V20: =U20-U19 -> 0 | X20: =W20-W19 -> -9364241
A21: 45365 | D21: =C21-C20 -> 0 | F21: =E21-E20 -> 0 | H21: =G21-G20 -> 0 | J21: =I21-I20 -> 0 | L21: =K21-K20 -> 0 | N21: =M21-M20 -> 0 | P21: =O21-O20 -> 0 | R21: =Q21-Q20 -> 0 | T21: =S21-S20 -> 0 | U21: 33955 | V21: =U21-U20 -> 0 | X21: =W21-W20 -> 0
A22: 45366 | D22: =C22-C21 -> 0 | F22: =E22-E21 -> 0 | H22: =G22-G21 -> 0 | J22: =I22-I21 -> 0 | L22: =K22-K21 -> 0 | N22: =M22-M21 -> 0 | P22: =O22-O21 -> 0 | R22: =Q22-Q21 -> 0 | T22: =S22-S21 -> 0 | U22: 33955 | V22: =U22-U21 -> 0 | X22: =W22-W21 -> 0
A23: 45367 | D23: =C23-C22 -> 0 | F23: =E23-E22 -> 0 | H23: =G23-G22 -> 0 | J23: =I23-I22 -> 0 | L23: =K23-K22 -> 0 | N23: =M23-M22 -> 0 | P23: =O23-O22 -> 0 | R23: =Q23-Q22 -> 0 | T23: =S23-S22 -> 0 | U23: 33955 | V23: =U23-U22 -> 0 | X23: =W23-W22 -> 0
A24: 45368 | D24: =C24-C23 -> 0 | F24: =E24-E23 -> 0 | H24: =G24-G23 -> 0 | J24: =I24-I23 -> 0 | L24: =K24-K23 -> 0 | N24: =M24-M23 -> 0 | P24: =O24-O23 -> 0 | R24: =Q24-Q23 -> 0 | T24: =S24-S23 -> 0 | U24: 33955 | V24: =U24-U23 -> 0 | X24: =W24-W23 -> 0
A25: 45369 | D25: =C25-C24 -> 0 | F25: =E25-E24 -> 0 | H25: =G25-G24 -> 0 | J25: =I25-I24 -> 0 | L25: =K25-K24 -> 0 | N25: =M25-M24 -> 0 | P25: =O25-O24 -> 0 | R25: =Q25-Q24 -> 0 | T25: =S25-S24 -> 0 | U25: 33955 | V25: =U25-U24 -> 0 | X25: =W25-W24 -> 0
A26: 45370 | D26: =C26-C25 -> 0 | F26: =E26-E25 -> 0 | H26: =G26-G25 -> 0 | J26: =I26-I25 -> 0 | L26: =K26-K25 -> 0 | N26: =M26-M25 -> 0 | P26: =O26-O25 -> 0 | R26: =Q26-Q25 -> 0 | T26: =S26-S25 -> 0 | U26: 33955 | V26: =U26-U25 -> 0 | X26: =W26-W25 -> 0
A27: 45371 | D27: =C27-C26 -> 0 | F27: =E27-E26 -> 0 | H27: =G27-G26 -> 0 | J27: =I27-I26 -> 0 | L27: =K27-K26 -> 0 | N27: =M27-M26 -> 0 | P27: =O27-O26 -> 0 | R27: =Q27-Q26 -> 0 | T27: =S27-S26 -> 0 | U27: 33955 | V27: =U27-U26 -> 0 | X27: =W27-W26 -> 0
A28: 45372 | D28: =C28-C27 -> 0 | F28: =E28-E27 -> 0 | H28: =G28-G27 -> 0 | J28: =I28-I27 -> 0 | L28: =K28-K27 -> 0 | N28: =M28-M27 -> 0 | P28: =O28-O27 -> 0 | R28: =Q28-Q27 -> 0 | T28: =S28-S27 -> 0 | U28: 33955 | V28: =U28-U27 -> 0 | X28: =W28-W27 -> 0
A29: 45373 | D29: =C29-C28 -> 0 | F29: =E29-E28 -> 0 | H29: =G29-G28 -> 0 | J29: =I29-I28 -> 0 | L29: =K29-K28 -> 0 | N29: =M29-M28 -> 0 | P29: =O29-O28 -> 0 | R29: =Q29-Q28 -> 0 | T29: =S29-S28 -> 0 | U29: 33955 | V29: =U29-U28 -> 0 | X29: =W29-W28 -> 0
A30: 45374 | D30: =C30-C29 -> 0 | F30: =E30-E29 -> 0 | H30: =G30-G29 -> 0 | J30: =I30-I29 -> 0 | L30: =K30-K29 -> 0 | N30: =M30-M29 -> 0 | P30: =O30-O29 -> 0 | R30: =Q30-Q29 -> 0 | T30: =S30-S29 -> 0 | U30: 33955 | V30: =U30-U29 -> 0 | X30: =W30-W29 -> 0
A31: 45375 | D31: =C31-C30 -> 0 | F31: =E31-E30 -> 0 | H31: =G31-G30 -> 0 | J31: =I31-I30 -> 0 | L31: =K31-K30 -> 0 | N31: =M31-M30 -> 0 | P31: =O31-O30 -> 0 | R31: =Q31-Q30 -> 0 | T31: =S31-S30 -> 0 | U31: 33955 | V31: =U31-U30 -> 0 | X31: =W31-W30 -> 0
... A38: 45382 | D38: =C38-C37 -> 0 | F38: =E38-E37 -> 0 | H38: =G38-G37 -> 0 | J38: =I38-I37 -> 0 | L38: =K38-K37 -> 0 | N38: =M38-M37 -> 0 | P38: =O38-O37 -> 0 | R38: =Q38-Q37 -> 0 | T38: =S38-S37 -> 0 | U38: 33955 | V38: =U38-U37 -> 0 | X38: =W38-W37 -> 0
A39: Total | D39: =SUM(D8:D38) -> -1388919 | F39: =SUM(F3:F38) -> -32438421 | H39: =SUM(H8:H38) -> -48162100 | J39: =SUM(J8:J38) -> -2268805 | L39: =SUM(L8:L38) -> -9643360 | N39: =SUM(N8:N38) -> -5912470 | P39: =SUM(P8:P38) -> -305248 | R39: =SUM(R8:R38) -> -4855540 | T39: =SUM(T8:T38) -> -52852 | V39: =SUM(V8:V38) -> 0 | X39: =SUM(X8:X38) -> -9313035
A42: R - Reading
A43: C - Consumption
A45: Note: Hotel meter reset to 0 on 12th January 2024

Sheet Water
A1: BEACH ROTANA ABUDHABI
A2: DAILY WATER METER READING
A3: For Month of March 2024
A5: Date | B5: BEACH WING | F5: BAYVIEW | J5: TOWER WING | P5: APARTMENT M3 | R5: LAUNDRY
B6: Meter 1 | D6: Irrigation | F6: Rest. & Kitchen | H6: Chilled Water | J6: Meter 1 (M3) | L6: Meter 2 (M3) | N6: Banquet Kit. & Rest.
B7: R | C7: C | D7: R | E7: C | F7: R | G7: C | H7: R | I7: C | J7: R | K7: C | L7: R | M7: C | N7: R | O7: C | P7: R | Q7: C | R7: R | S7: C
A8: 45352 | B8: 192798 | C8: =B8-192629 -> 169 | D8: 380105 | E8: =D8-380039 -> 66 | F8: 91335 | G8: =F8-91192 -> 143 | J8: 376834 | K8: =J8-376834 -> 0 | L8: 102044 | M8: =L8-102002 -> 42 | N8: 81700 | O8: =N8-81620 -> 80 | P8: 178564 | Q8: =P8-178514 -> 50 | S8: =R8-23357 -> -23357
A9: 45353 | B9: 192964 | C9: =B9-B8 -> 166 | D9: 380129 | E9: =D9-D8 -> 24 | F9: 91455 | G9: =F9-F8 -> 120 | J9: 376834 | K9: =J9-J8 -> 0 | L9: 102092 | M9: =L9-L8 -> 48 | N9: 81790 | O9: =N9-N8 -> 90 | P9: 178627 | Q9: =P9-P8 -> 63
A10: 45354 | B10: 193132 | C10: =B10-B9 -> 168 | D10: 380129 | E10: =D10-D9 -> 0 | F10: 91583 | G10: =F10-F9 -> 128 | J10: 376834 | K10: =J10-J9 -> 0 | L10: 102135 | M10: =L10-L9 -> 43 | N10: 81880 | O10: =N10-N9 -> 90 | P10: 178662 | Q10: =P10-P9 -> 35
A11: 45355 | B11: 193306 | C11: =B11-B10 -> 174 | D11: 380130 | E11: =D11-D10 -> 1 | F11: 91721 | G11: =F11-F10 -> 138 | J11: 376834 | K11: =J11-J10 -> 0 | L11: 102180 | M11: =L11-L10 -> 45 | N11: 81970 | O11: =N11-N10 -> 90 | P11: 178712 | Q11: =P11-P10 -> 50
A12: 45356 | B12: 193483 | C12: =B12-B11 -> 177 | D12: 380183 | E12: =D12-D11 -> 53 | F12: 91842 | G12: =F12-F11 -> 121 | J12: 376834 | K12: =J12-J11 -> 0 | L12: 102226 | M12: =L12-L11 -> 46 | N12: 82070 | O12: =N12-N11 -> 100 | P12: 178761 | Q12: =P12-P11 -> 49
A13: 45357 | B13: 193646 | C13: =B13-B12 -> 163 | D13: 380183 | E13: =D13-D12 -> 0 | F13: 91958 | G13: =F13-F12 -> 116 | J13: 376834 | K13: =J13-J12 -> 0 | L13: 102279 | M13: =L13-L12 -> 53 | N13: 82150 | O13: =N13-N12 -> 80 | P13: 178809 | Q13: =P13-P12 -> 48
A14: 45358 | B14: 193852 | C14: =B14-B13 -> 206 | D14: 380197 | E14: =D14-D13 -> 14 | F14: 92070 | G14: =F14-F13 -> 112 | J14: 376834 | K14: =J14-J13 -> 0 | L14: 102328 | M14: =L14-L13 -> 49 | N14: 82250 | O14: =N14-N13 -> 100 | P14: 178858 | Q14: =P14-P13 -> 49
A15: 45359 | B15: 194038 | C15: =B15-B14 -> 186 | D15: 380238 | E15: =D15-D14 -> 41 | F15: 92197 | G15: =F15-F14 -> 127 | J15: 376834 | K15: =J15-J14 -> 0 | L15: 102376 | M15: =L15-L14 -> 48 | N15: 82350 | O15: =N15-N14 -> 100 | P15: 178906 | Q15: =P15-P14 -> 48
A16: 45360 | B16: 194218 | C16: =B16-B15 -> 180 | D16: 380238 | E16: =D16-D15 -> 0 | F16: 92318 | G16: =F16-F15 -> 121 | J16: 376834 | K16: =J16-J15 -> 0 | L16: 102424 | M16: =L16-L15 -> 48 | N16: 82430 | O16: =N16-N15 -> 80 | P16: 178954 | Q16: =P16-P15 -> 48
A17: 45361 | B17: 194387 | C17: =B17-B16 -> 169 | D17: 380238 | E17: =D17-D16 -> 0 | F17: 92385 | G17: =F17-F16 -> 67 | J17: 376834 | K17: =J17-J16 -> 0 | L17: 102468 | M17: =L17-L16 -> 44 | N17: 82570 | O17: =N17-N16 -> 140 | P17: 179000 | Q17: =P17-P16 -> 46
A18: 45362 | B18: 194557 | C18: =B18-B17 -> 170 | D18: 380238 | E18: =D18-D17 -> 0 | F18: 92510 | G18: =F18-F17 -> 125 | J18: 376834 | K18: =J18-J17 -> 0 | L18: 102514 | M18: =L18-L17 -> 46 | N18: 82660 | O18: =N18-N17 -> 90 | P18: 179049 | Q18: =P18-P17 -> 49
A19: 45363 | B19: 194719 | C19: =B19-B18 -> 162 | D19: 380238 | E19: =D19-D18 -> 0 | F19: 92635 | G19: =F19-F18 -> 125 | J19: 376834 | K19: =J19-J18 -> 0 | L19: 102553 | M19: =L19-L18 -> 39 | N19: 82750 | O19: =N19-N18 -> 90 | P19: 179109 | Q19: =P19-P18 -> 60
A20: 45364 | C20: =B20-B19 -> -194719 | E20: =D20-D19 -> -380238 | G20: =F20-F19 -> -92635 | J20: 376834 | K20: =J20-J19 -> 0 | M20: =L20-L19 -> -102553 | O20: =N20-N19 -> -82750 | Q20: =P20-P19 -> -179109
A21: 45365 | C21: =B21-B20 -> 0 | E21: =D21-D20 -> 0 | G21: =F21-F20 -> 0 | J21: 376834 | K21: =J21-J20 -> 0 | M21: =L21-L20 -> 0 | O21: =N21-N20 -> 0 | Q21: =P21-P20 -> 0
A22: 45366 | C22: =B22-B21 -> 0 | E22: =D22-D21 -> 0 | G22: =F22-F21 -> 0 | J22: 376834 | K22: =J22-J21 -> 0 | M22: =L22-L21 -> 0 | O22: =N22-N21 -> 0 | Q22: =P22-P21 -> 0
A23: 45367 | C23: =B23-B22 -> 0 | E23: =D23-D22 -> 0 | G23: =F23-F22 -> 0 | J23: 376834 | K23: =J23-J22 -> 0 | M23: =L23-L22 -> 0 | O23: =N23-N22 -> 0 | Q23: =P23-P22 -> 0 | S23: 0
A24: 45368 | C24: =B24-B23 -> 0 | E24: =D24-D23 -> 0 | G24: =F24-F23 -> 0 | J24: 376834 | K24: =J24-J23 -> 0 | M24: =L24-L23 -> 0 | O24: =N24-N23 -> 0 | Q24: =P24-P23 -> 0 | S24: =R24-R23 -> 0
A25: 45369 | C25: =B25-B24 -> 0 | E25: =D25-D24 -> 0 | G25: =F25-F24 -> 0 | J25: 376834 | K25: =J25-J24 -> 0 | M25: =L25-L24 -> 0 | O25: =N25-N24 -> 0 | Q25: =P25-P24 -> 0 | S25: =R25-R24 -> 0
A26: 45370 | C26: =B26-B25 -> 0 | E26: =D26-D25 -> 0 | G26: =F26-F25 -> 0 | J26: 376834 | K26: =J26-J25 -> 0 | M26: =L26-L25 -> 0 | O26: =N26-N25 -> 0 | Q26: =P26-P25 -> 0 | S26: =R26-R25 -> 0
A27: 45371 | C27: =B27-B26 -> 0 | E27: =D27-D26 -> 0 | G27: =F27-F26 -> 0 | J27: 376834 | K27: =J27-J26 -> 0 | M27: =L27-L26 -> 0 | O27: =N27-N26 -> 0 | Q27: =P27-P26 -> 0 | S27: =R27-R26 -> 0
A28: 45372 | C28: =B28-B27 -> 0 | E28: =D28-D27 -> 0 | G28: =F28-F27 -> 0 | J28: 376834 | K28: =J28-J27 -> 0 | M28: =L28-L27 -> 0 | O28: =N28-N27 -> 0 | Q28: =P28-P27 -> 0 | S28: =R28-R27 -> 0
A29: 45373 | C29: =B29-B28 -> 0 | E29: =D29-D28 -> 0 | G29: =F29-F28 -> 0 | J29: 376834 | K29: =J29-J28 -> 0 | M29: =L29-L28 -> 0 | O29: =N29-N28 -> 0 | Q29: =P29-P28 -> 0 | S29: =R29-R28 -> 0
A30: 45374 | C30: =B30-B29 -> 0 | E30: =D30-D29 -> 0 | G30: =F30-F29 -> 0 | J30: 376834 | K30: =J30-J29 -> 0 | M30: =L30-L29 -> 0 | O30: =N30-N29 -> 0 | Q30: =P30-P29 -> 0 | S30: =R30-R29 -> 0
A31: 45375 | C31: =B31-B30 -> 0 | E31: =D31-D30 -> 0 | G31: =F31-F30 -> 0 | J31: 376834 | K31: =J31-J30 -> 0 | M31: =L31-L30 -> 0 | O31: =N31-N30 -> 0 | Q31: =P31-P30 -> 0 | S31: =R31-R30 -> 0
A32: 45376 | C32: =B32-B31 -> 0 | E32: =D32-D31 -> 0 | G32: =F32-F31 -> 0 | J32: 376834 | K32: =J32-J31 -> 0 | M32: =L32-L31 -> 0 | O32: =N32-N31 -> 0 | Q32: =P32-P31 -> 0 | S32: =R32-R31 -> 0
A33: 45377 | C33: =B33-B32 -> 0 | E33: =D33-D32 -> 0 | G33: =F33-F32 -> 0 | J33: 376834 | K33: =J33-J32 -> 0 | M33: =L33-L32 -> 0 | O33: =N33-N32 -> 0 | Q33: =P33-P32 -> 0
A34: 45378 | C34: =B34-B33 -> 0 | E34: =D34-D33 -> 0 | G34: =F34-F33 -> 0 | J34: 376834 | K34: =J34-J33 -> 0 | M34: =L34-L33 -> 0 | O34: =N34-N33 -> 0 | Q34: =P34-P33 -> 0
A35: 45379 | C35: =B35-B34 -> 0 | E35: =D35-D34 -> 0 | G35: =F35-F34 -> 0 | J35: 376834 | K35: =J35-J34 -> 0 | M35: =L35-L34 -> 0 | O35: =N35-N34 -> 0 | Q35: =P35-P34 -> 0
A36: 45380 | C36: =B36-B35 -> 0 | E36: =D36-D35 -> 0 | G36: =F36-F35 -> 0 | J36: 376834 | K36: =J36-J35 -> 0 | M36: =L36-L35 -> 0 | O36: =N36-N35 -> 0 | Q36: =P36-P35 -> 0
A37: 45381 | C37: =B37-B36 -> 0 | E37: =D37-D36 -> 0 | G37: =F37-F36 -> 0 | J37: 376834 | K37: =J37-J36 -> 0 | M37: =L37-L36 -> 0 | O37: =N37-N36 -> 0 | Q37: =P37-P36 -> 0
A38: 45382 | C38: =B38-B37 -> 0 | E38: =D38-D37 -> 0 | G38: =F38-F37 -> 0 | J38: 376834 | K38: =J38-J37 -> 0 | M38: =L38-L37 -> 0 | O38: =N38-N37 -> 0 | Q38: =P38-P37 -> 0
A39: Total | C39: =SUM(C8:C38) -> -192629 | E39: =SUM(E8:E38) -> -380039 | G39: =SUM(G8:G38) -> -91192 | I39: =SUM(I8:I36) -> 0 | K39: =SUM(K8:K35) -> 0 | M39: =SUM(M8:M38) -> -102002 | O39: =SUM(O8:O38) -> -81620 | Q39: =SUM(Q8:Q38) -> -178514 | S39: =SUM(S10:S36) -> 0
A41: R - Reading
A42: C - Consumption
...

Sheet Gas
A1: BEACH ROTANA ABUDHABI
A2: DAILY GAS METER READING
A3: For Month of March 2024
A5: Date | B5: Beach Wing Kitchen | D5: Banquet Kitchen | F5: Room Service Kitchen | H5: Pregos | J5: Rodeo Grill | L5: Bay View Restaurant | N5: Indigo Restaurant | P5: Finz Restaurant | R5: Apartment | T5: Beach Wing Laundry
B6: Qty./Ltrs | C6: Amt. | D6: R | E6: C | F6: R | G6: C | H6: R | I6: C | J6: R | K6: C | L6: R | M6: C | N6: R | O6: C | P6: R | Q6: C | R6: R | S6: C | T6: Qty./Ltrs | U6: Amt.
A8: 45352 | B8: 1200 | C8: =B8*0 -> 0 | D8: 38916 | E8: =D8-38896 -> 20 | F8: 49452 | G8: =F8-49440 -> 12 | H8: 72681 | I8: =H8-72664 -> 17 | J8: 17278 | K8: =J8-17276 -> 2 | L8: 29625 | M8: =L8-29622 -> 3 | N8: 9449 | O8: =N8-9442 -> 7 | P8: 42956 | Q8: =P8-42942 -> 14 | R8: 15964 | S8: =R8-15964 -> 0 | U8: =T8*1.66 -> 0
A9: 45353 | C9: =B9*1.55 -> 0 | D9: 38929 | E9: =D9-D8 -> 13 | F9: 49465 | G9: =F9-F8 -> 13 | H9: 72699 | I9: =H9-H8 -> 18 | J9: 17281 | K9: =J9-J8 -> 3 | L9: 29628 | M9: =L9-L8 -> 3 | N9: 9457 | O9: =N9-N8 -> 8 | P9: 42973 | Q9: =P9-P8 -> 17 | R9: 15965 | S9: =R9-R8 -> 1 | U9: =T9*2.17 -> 0
A10: 45354 | C10: =B10*1.76 -> 0 | D10: 38940 | E10: =D10-D9 -> 11 | F10: 49477 | G10: =F10-F9 -> 12 | H10: 72717 | I10: =H10-H9 -> 18 | J10: 17284 | K10: =J10-J9 -> 3 | L10: 29633 | M10: =L10-L9 -> 5 | N10: 9466 | O10: =N10-N9 -> 9 | P10: 42988 | Q10: =P10-P9 -> 15 | R10: 15965 | S10: =R10-R9 -> 0 | U10: =T10*2.29 -> 0
A11: 45355 | C11: =B11*1.35 -> 0 | D11: 38952 | E11: =D11-D10 -> 12 | F11: 49490 | G11: =F11-F10 -> 13 | H11: 72735 | I11: =H11-H10 -> 18 | J11: 17287 | K11: =J11-J10 -> 3 | L11: 29638 | M11: =L11-L10 -> 5 | N11: 9474 | O11: =N11-N10 -> 8 | P11: 43003 | Q11: =P11-P10 -> 15 | R11: 15965 | S11: =R11-R10 -> 0 | U11: =T11*2.37 -> 0
A12: 45356 | C12: =B12*1.71 -> 0 | D12: 38963 | E12: =D12-D11 -> 11 | F12: 49501 | G12: =F12-F11 -> 11 | H12: 72753 | I12: =H12-H11 -> 18 | J12: 17292 | K12: =J12-J11 -> 5 | L12: 29641 | M12: =L12-L11 -> 3 | N12: 9480 | O12: =N12-N11 -> 6 | P12: 43020 | Q12: =P12-P11 -> 17 | R12: 15966 | S12: =R12-R11 -> 1 | U12: =T12*1.73 -> 0
A13: 45357 | C13: =B13*1.95 -> 0 | D13: 38980 | E13: =D13-D12 -> 17 | F13: 49512 | G13: =F13-F12 -> 11 | H13: 72772 | I13: =H13-H12 -> 19 | J13: 17297 | K13: =J13-J12 -> 5 | L13: 29645 | M13: =L13-L12 -> 4 | N13: 9487 | O13: =N13-N12 -> 7 | P13: 43036 | Q13: =P13-P12 -> 16 | R13: 15966 | S13: =R13-R12 -> 0 | U13: =T13*2.29 -> 0
A14: 45358 | C14: =B14*1.18 -> 0 | D14: 39007 | E14: =D14-D13 -> 27 | F14: 49524 | G14: =F14-F13 -> 12 | H14: 72791 | I14: =H14-H13 -> 19 | J14: 17299 | K14: =J14-J13 -> 2 | L14: 29650 | M14: =L14-L13 -> 5 | N14: 9494 | O14: =N14-N13 -> 7 | P14: 43052 | Q14: =P14-P13 -> 16 | R14: 15966 | S14: =R14-R13 -> 0 | U14: =T14*2.37 -> 0
A15: 45359 | C15: =B15*0 -> 0 | D15: 39034 | E15: =D15-D14 -> 27 | F15: 49537 | G15: =F15-F14 -> 13 | H15: 72810 | I15: =H15-H14 -> 19 | J15: 17302 | K15: =J15-J14 -> 3 | L15: 29654 | M15: =L15-L14 -> 4 | N15: 9501 | O15: =N15-N14 -> 7 | P15: 43068 | Q15: =P15-P14 -> 16 | R15: 15966 | S15: =R15-R14 -> 0 | U15: =T15*1.97 -> 0
A16: 45360 | C16: =B16*1.31 -> 0 | D16: 39064 | E16: =D16-D15 -> 30 | F16: 49552 | G16: =F16-F15 -> 15 | H16: 72829 | I16: =H16-H15 -> 19 | J16: 17306 | K16: =J16-J15 -> 4 | L16: 29658 | M16: =L16-L15 -> 4 | N16: 9507 | O16: =N16-N15 -> 6 | P16: 43084 | Q16: =P16-P15 -> 16 | R16: 15966 | S16: =R16-R15 -> 0 | U16: =T16*1.25 -> 0
A17: 45361 | C17: =B17*1.72 -> 0 | D17: 39080 | E17: =D17-D16 -> 16 | F17: 49565 | G17: =F17-F16 -> 13 | H17: 72847 | I17: =H17-H16 -> 18 | J17: 17310 | K17: =J17-J16 -> 4 | L17: 29660 | M17: =L17-L16 -> 2 | N17: 9515 | O17: =N17-N16 -> 8 | P17: 43097 | Q17: =P17-P16 -> 13 | R17: 15967 | S17: =R17-R16 -> 1 | U17: =T17*2.29 -> 0
A18: 45362 | B18: 1600 | C18: =B18*0 -> 0 | D18: 39095 | E18: =D18-D17 -> 15 | F18: 49577 | G18: =F18-F17 -> 12 | H18: 72865 | I18: =H18-H17 -> 18 | J18: 17313 | K18: =J18-J17 -> 3 | L18: 29665 | M18: =L18-L17 -> 5 | N18: 9523 | O18: =N18-N17 -> 8 | P18: 43113 | Q18: =P18-P17 -> 16 | R18: 15967 | S18: =R18-R17 -> 0 | U18: =T18*2.37 -> 0
A19: 45363 | C19: =B19*1.67 -> 0 | D19: 39117 | E19: =D19-D18 -> 22 | F19: 49589 | G19: =F19-F18 -> 12 | H19: 72883 | I19: =H19-H18 -> 18 | J19: 17316 | K19: =J19-J18 -> 3 | L19: 29668 | M19: =L19-L18 -> 3 | N19: 9529 | O19: =N19-N18 -> 6 | P19: 43125 | Q19: =P19-P18 -> 12 | R19: 15967 | S19: =R19-R18 -> 0 | U19: =T19*1.46 -> 0
A20: 45364 | C20: =B20*1.54 -> 0 | E20: =D20-D19 -> -39117 | G20: =F20-F19 -> -49589 | I20: =H20-H19 -> -72883 | K20: =J20-J19 -> -17316 | M20: =L20-L19 -> -29668 | O20: =N20-N19 -> -9529 | Q20: =P20-P19 -> -43125 | S20: =R20-R19 -> -15967 | U20: =T20*2.37 -> 0
A21: 45365 | C21: =B21*1.92 -> 0 | E21: =D21-D20 -> 0 | G21: =F21-F20 -> 0 | I21: =H21-H20 -> 0 | K21: =J21-J20 -> 0 | M21: =L21-L20 -> 0 | O21: =N21-N20 -> 0 | Q21: =P21-P20 -> 0 | S21: =R21-R20 -> 0 | U21: =T21*1.97 -> 0
A22: 45366 | C22: =B22*2.1 -> 0 | E22: =D22-D21 -> 0 | G22: =F22-F21 -> 0 | I22: =H22-H21 -> 0 | K22: =J22-J21 -> 0 | M22: =L22-L21 -> 0 | O22: =N22-N21 -> 0 | Q22: =P22-P21 -> 0 | S22: =R22-R21 -> 0 | U22: =T22*2.1 -> 0
A23: 45367 | C23: =B23*1.31 -> 0 | E23: =D23-D22 -> 0 | G23: =F23-F22 -> 0 | I23: =H23-H22 -> 0 | K23: =J23-J22 -> 0 | M23: =L23-L22 -> 0 | O23: =N23-N22 -> 0 | Q23: =P23-P22 -> 0 | S23: =R23-R22 -> 0 | U23: =T23*1.82 -> 0
A24: 45368 | C24: =B24*1.94 -> 0 | E24: =D24-D23 -> 0 | G24: =F24-F23 -> 0 | I24: =H24-H23 -> 0 | K24: =J24-J23 -> 0 | M24: =L24-L23 -> 0 | O24: =N24-N23 -> 0 | Q24: =P24-P23 -> 0 | S24: =R24-R23 -> 0 | U24: =T24*2.29 -> 0
A25: 45369 | C25: =B25*2.37 -> 0 | E25: =D25-D24 -> 0 | G25: =F25-F24 -> 0 | I25: =H25-H24 -> 0 | K25: =J25-J24 -> 0 | M25: =L25-L24 -> 0 | O25: =N25-N24 -> 0 | Q25: =P25-P24 -> 0 | S25: =R25-R24 -> 0 | U25: =T25*2.37 -> 0
A26: 45370 | C26: =B26*1.54 -> 0 | E26: =D26-D25 -> 0 | G26: =F26-F25 -> 0 | I26: =H26-H25 -> 0 | K26: =J26-J25 -> 0 | M26: =L26-L25 -> 0 | O26: =N26-N25 -> 0 | Q26: =P26-P25 -> 0 | S26: =R26-R25 -> 0 | U26: =T26*1.66 -> 0
A27: 45371 | C27: =B27*1.72 -> 0 | E27: =D27-D26 -> 0 | G27: =F27-F26 -> 0 | I27: =H27-H26 -> 0 | K27: =J27-J26 -> 0 | M27: =L27-L26 -> 0 | O27: =N27-N26 -> 0 | Q27: =P27-P26 -> 0 | S27: =R27-R26 -> 0 | U27: =T27*1.94 -> 0
A28: 45372 | C28: =B28*1.69 -> 0 | E28: =D28-D27 -> 0 | G28: =F28-F27 -> 0 | I28: =H28-H27 -> 0 | K28: =J28-J27 -> 0 | M28: =L28-L27 -> 0 | O28: =N28-N27 -> 0 | Q28: =P28-P27 -> 0 | S28: =R28-R27 -> 0 | U28: =T28*2.29 -> 0
A29: 45373 | C29: =B29*1.55 -> 0 | E29: =D29-D28 -> 0 | G29: =F29-F28 -> 0 | I29: =H29-H28 -> 0 | K29: =J29-J28 -> 0 | M29: =L29-L28 -> 0 | O29: =N29-N28 -> 0 | Q29: =P29-P28 -> 0 | S29: =R29-R28 -> 0 | U29: =T29*2.37 -> 0
A30: 45374 | C30: =B30*1.35 -> 0 | E30: =D30-D29 -> 0 | G30: =F30-F29 -> 0 | I30: =H30-H29 -> 0 | K30: =J30-J29 -> 0 | M30: =L30-L29 -> 0 | O30: =N30-N29 -> 0 | Q30: =P30-P29 -> 0 | S30: =R30-R29 -> 0 | U30: =T30*2 -> 0
A31: 45375 | C31: =B31*1.66 -> 0 | E31: =D31-D30 -> 0 | G31: =F31-F30 -> 0 | I31: =H31-H30 -> 0 | K31: =J31-J30 -> 0 | M31: =L31-L30 -> 0 | O31: =N31-N30 -> 0 | Q31: =P31-P30 -> 0 | S31: =R31-R30 -> 0 | U31: =T31*2.29 -> 0
A32: 45376 | C32: =B32*0 -> 0 | E32: =D32-D31 -> 0 | G32: =F32-F31 -> 0 | I32: =H32-H31 -> 0 | K32: =J32-J31 -> 0 | M32: =L32-L31 -> 0 | O32: =N32-N31 -> 0 | Q32: =P32-P31 -> 0 | S32: =R32-R31 -> 0 | U32: =T32*2.37 -> 0
A33: 45377 | C33: =B33*1.94 -> 0 | E33: =D33-D32 -> 0 | G33: =F33-F32 -> 0 | I33: =H33-H32 -> 0 | K33: =J33-J32 -> 0 | M33: =L33-L32 -> 0 | O33: =N33-N32 -> 0 | Q33: =P33-P32 -> 0 | S33: =R33-R32 -> 0 | U33: =T33*1.94 -> 0
A34: 45378 | C34: =B34*1.95 -> 0 | E34: =D34-D33 -> 0 | G34: =F34-F33 -> 0 | I34: =H34-H33 -> 0 | K34: =J34-J33 -> 0 | M34: =L34-L33 -> 0 | O34: =N34-N33 -> 0 | Q34: =P34-P33 -> 0 | S34: =R34-R33 -> 0 | U34: =T34*0 -> 0
A35: 45379 | C35: =B35*1.57 -> 0 | E35: =D35-D34 -> 0 | G35: =F35-F34 -> 0 | I35: =H35-H34 -> 0 | K35: =J35-J34 -> 0 | M35: =L35-L34 -> 0 | O35: =N35-N34 -> 0 | Q35: =P35-P34 -> 0 | S35: =R35-R34 -> 0 | U35: =T35*1.57 -> 0
A36: 45380 | C36: =B36*1.66 -> 0 | E36: =D36-D35 -> 0 | G36: =F36-F35 -> 0 | I36: =H36-H35 -> 0 | K36: =J36-J35 -> 0 | M36: =L36-L35 -> 0 | O36: =N36-N35 -> 0 | Q36: =P36-P35 -> 0 | S36: =R36-R35 -> 0 | U36: =T36*1.57 -> 0
A37: 45381 | C37: =B37*1.66 -> 0 | E37: =D37-D36 -> 0 | G37: =F37-F36 -> 0 | I37: =H37-H36 -> 0 | K37: =J37-J36 -> 0 | M37: =L37-L36 -> 0 | O37: =N37-N36 -> 0 | Q37: =P37-P36 -> 0 | S37: =R37-R36 -> 0 | U37: =T37*1.57 -> 0
A38: 45382 | C38: =B38*1.66 -> 0 | E38: =D38-D37 -> 0 | G38: =F38-F37 -> 0 | I38: =H38-H37 -> 0 | K38: =J38-J37 -> 0 | M38: =L38-L37 -> 0 | O38: =N38-N37 -> 0 | Q38: =P38-P37 -> 0 | S38: =R38-R37 -> 0
A39: Total | B39: =SUM(B8:B38) -> 2800 | C39: =SUM(C8:C38) -> 0 | E39: =SUM(E8:E38) -> -38896 | G39: =SUM(G8:G38) -> -49440 | I39: =SUM(I8:I38) -> -72664 | K39: =SUM(K8:K38) -> -17276 | M39: =SUM(M8:M38) -> -29622 | O39: =SUM(O8:O38) -> -9442 | Q39: =SUM(Q8:Q38) -> -42942 | S39: =SUM(S8:S38) -> -15964 | T39: =SUM(T8:T37) -> 0 | U39: =SUM(U8:U37) -> 0
A41: R - Reading
A42: C - Consumption

Sheet Chilled Water
A1: SECONDARY PUMP (CHILLED WATER READING) - March 2024
B2: Hotel Apartment | E2: Hotel Tower | H2: Package 3 & 4 | K2: Beach Front
B3: Previous | C3: Present | D3: Consumption | E3: Previous | F3: Present | G3: Consumption | H3: Previous | I3: Present | J3: Consumption | K3: Previous | L3: Present | M3: Consumption
A4: 45352 | B4: 0 | C4: 55 | D4: =C4-B4 -> 55 | E4: 0 | F4: 204 | G4: =F4-E4 -> 204 | H4: 0 | I4: 269 | J4: =I4-H4 -> 269 | K4: 0 | L4: 48 | M4: =L4-K4 -> 48
A5: 45353 | B5: =C4 -> 55 | C5: 444 | D5: =C5-B5 -> 389 | E5: =F4 -> 204 | F5: 1473 | G5: =F5-E5 -> 1269 | H5: =I4 -> 269 | I5: 1868 | J5: =I5-H5 -> 1599 | K5: =L4 -> 48 | L5: 334 | M5: =L5-K5 -> 286
A6: 45354 | B6: =C5 -> 444 | C6: 844 | D6: =C6-B6 -> 400 | E6: =F5 -> 1473 | F6: 2700 | G6: =F6-E6 -> 1227 | H6: =I5 -> 1868 | I6: 3605 | J6: =I6-H6 -> 1737 | K6: =L5 -> 334 | L6: 641 | M6: =L6-K6 -> 307
A7: 45355 | B7: =C6 -> 844 | C7: 1243 | D7: =C7-B7 -> 399 | E7: =F6 -> 2700 | F7: 3890 | G7: =F7-E7 -> 1190 | H7: =I6 -> 3605 | I7: 5212 | J7: =I7-H7 -> 1607 | K7: =L6 -> 641 | L7: 949 | M7: =L7-K7 -> 308
A8: 45356 | B8: =C7 -> 1243 | C8: 1638 | D8: =C8-B8 -> 395 | E8: =F7 -> 3890 | F8: 5026 | G8: =F8-E8 -> 1136 | H8: =I7 -> 5212 | I8: 6837 | J8: =I8-H8 -> 1625 | K8: =L7 -> 949 | L8: 1213 | M8: =L8-K8 -> 264
A9: 45357 | B9: =C8 -> 1638 | C9: 2055 | D9: =C9-B9 -> 417 | E9: =F8 -> 5026 | F9: 6216 | G9: =F9-E9 -> 1190 | H9: =I8 -> 6837 | I9: 8529 | J9: =I9-H9 -> 1692 | K9: =L8 -> 1213 | L9: 1518 | M9: =L9-K9 -> 305
A10: 45358 | B10: =C9 -> 2055 | C10: 2437 | D10: =C10-B10 -> 382 | E10: =F9 -> 6216 | F10: 7400 | G10: =F10-E10 -> 1184 | H10: =I9 -> 8529 | I10: 10288 | J10: =I10-H10 -> 1759 | K10: =L9 -> 1518 | L10: 1842 | M10: =L10-K10 -> 324
A11: 45359 | B11: =C10 -> 2437 | C11: 2843 | D11: =C11-B11 -> 406 | E11: =F10 -> 7400 | F11: 8607 | G11: =F11-E11 -> 1207 | H11: =I10 -> 10288 | I11: 11990 | J11: =I11-H11 -> 1702 | K11: =L10 -> 1842 | L11: 2111 | M11: =L11-K11 -> 269
A12: 45360 | B12: =C11 -> 2843 | C12: 3291 | D12: =C12-B12 -> 448 | E12: =F11 -> 8607 | F12: 9665 | G12: =F12-E12 -> 1058 | H12: =I11 -> 11990 | I12: 14101 | J12: =I12-H12 -> 2111 | K12: =L11 -> 2111 | L12: 2355 | M12: =L12-K12 -> 244
A13: 45361 | B13: =C12 -> 3291 | C13: 3747 | D13: =C13-B13 -> 456 | E13: =F12 -> 9665 | F13: 10762 | G13: =F13-E13 -> 1097 | H13: =I12 -> 14101 | I13: 15953 | J13: =I13-H13 -> 1852 | K13: =L12 -> 2355 | L13: 2668 | M13: =L13-K13 -> 313
A14: 45362 | B14: =C13 -> 3747 | C14: 4170 | D14: =C14-B14 -> 423 | E14: =F13 -> 10762 | F14: 11926 | G14: =F14-E14 -> 1164 | H14: =I13 -> 15953 | I14: 17636 | J14: =I14-H14 -> 1683 | K14: =L13 -> 2668 | L14: 2901 | M14: =L14-K14 -> 233
A15: 45363 | B15: =C14 -> 4170 | C15: 4649 | D15: =C15-B15 -> 479 | E15: =F14 -> 11926 | F15: 13302 | G15: =F15-E15 -> 1376 | H15: =I14 -> 17636 | I15: 19314 | J15: =I15-H15 -> 1678 | K15: =L14 -> 2901 | L15: 3260 | M15: =L15-K15 -> 359
A16: 45364 | B16: =C15 -> 4649 | D16: =C16-B16 -> -4649 | E16: =F15 -> 13302 | G16: =F16-E16 -> -13302 | H16: =I15 -> 19314 | J16: =I16-H16 -> -19314 | K16: =L15 -> 3260 | M16: =L16-K16 -> -3260
A17: 45365 | B17: =C16 -> 0 | D17: =C17-B17 -> 0 | E17: =F16 -> 0 | G17: =F17-E17 -> 0 | H17: =I16 -> 0 | J17: =I17-H17 -> 0 | K17: =L16 -> 0 | M17: =L17-K17 -> 0
A18: 45366 | B18: =C17 -> 0 | D18: =C18-B18 -> 0 | E18: =F17 -> 0 | G18: =F18-E18 -> 0 | H18: =I17 -> 0 | J18: =I18-H18 -> 0 | K18: =L17 -> 0 | M18: =L18-K18 -> 0
A19: 45367 | B19: =C18 -> 0 | D19: =C19-B19 -> 0 | E19: =F18 -> 0 | G19: =F19-E19 -> 0 | H19: =I18 -> 0 | J19: =I19-H19 -> 0 | K19: =L18 -> 0 | M19: =L19-K19 -> 0
A20: 45368 | B20: =C19 -> 0 | D20: =C20-B20 -> 0 | E20: =F19 -> 0 | G20: =F20-E20 -> 0 | H20: =I19 -> 0 | J20: =I20-H20 -> 0 | K20: =L19 -> 0 | M20: =L20-K20 -> 0
A21: 45369 | B21: =C20 -> 0 | D21: =C21-B21 -> 0 | E21: =F20 -> 0 | G21: =F21-E21 -> 0 | H21: =I20 -> 0 | J21: =I21-H21 -> 0 | K21: =L20 -> 0 | M21: =L21-K21 -> 0
A22: 45370 | B22: =C21 -> 0 | D22: =C22-B22 -> 0 | E22: =F21 -> 0 | G22: =F22-E22 -> 0 | H22: =I21 -> 0 | J22: =I22-H22 -> 0 | K22: =L21 -> 0 | M22: =L22-K22 -> 0
A23: 45371 | B23: =C22 -> 0 | D23: =C23-B23 -> 0 | E23: =F22 -> 0 | G23: =F23-E23 -> 0 | H23: =I22 -> 0 | J23: =I23-H23 -> 0 | K23: =L22 -> 0 | M23: =L23-K23 -> 0
A24: 45372 | B24: =C23 -> 0 | D24: =C24-B24 -> 0 | E24: =F23 -> 0 | G24: =F24-E24 -> 0 | H24: =I23 -> 0 | J24: =I24-H24 -> 0 | K24: =L23 -> 0 | M24: =L24-K24 -> 0
A25: 45373 | B25: =C24 -> 0 | D25: =C25-B25 -> 0 | E25: =F24 -> 0 | G25: =F25-E25 -> 0 | H25: =I24 -> 0 | J25: =I25-H25 -> 0 | K25: =L24 -> 0 | M25: =L25-K25 -> 0
A26: 45374 | B26: =C25 -> 0 | D26: =C26-B26 -> 0 | E26: =F25 -> 0 | G26: =F26-E26 -> 0 | H26: =I25 -> 0 | J26: =I26-H26 -> 0 | K26: =L25 -> 0 | M26: =L26-K26 -> 0
A27: 45375 | B27: =C26 -> 0 | D27: =C27-B27 -> 0 | E27: =F26 -> 0 | G27: =F27-E27 -> 0 | H27: =I26 -> 0 | J27: =I27-H27 -> 0 | K27: =L26 -> 0 | M27: =L27-K27 -> 0
... A34: 45382 | B34: =C33 -> 0 | D34: =C34-B34 -> 0 | E34: =F33 -> 0 | G34: =F34-E34 -> 0 | H34: =I33 -> 0 | J34: =I34-H34 -> 0 | K34: =L33 -> 0 | M34: =L34-K34 -> 0
A35: Total BRAD Reading | B35: =SUM(D4:D34) -> 0 | E35: =SUM(G4:G34) -> 0 | H35: =SUM(J4:J34) -> 0 | K35: =SUM(M4:M34) -> 0
B36: =SUM(B35:M35) -> 0
