Workbook

Sheet Total
A1: Site Name | B1: Day | C1: Month | D1: Year | E1: Total Electricity Kwh | F1: Electricity Tariff ($/Kwh) | G1: Water Utility Supply (m3) m3 | H1: Water Utility Supply (m3) $/m3 | I1: LPG (Liters) | J1: LPG $/Liters | K1: District Energy Cooling RTH | L1: District Energy Cooling $/RTH | M1: Room Nights
A2: Beach Rotana Residences Abu Dhabi | B2: 1 | C2: 5 | D2: 2024 | E2: =IF((Elect!D9+Elect!H9+Elect!J9)<0,"0",Elect!D9+Elect!H9+Elect!J9) -> 10685 | F2: 0.2 | G2: =IF(Water!C11<0,"0",Water!C11) -> 100 | H2: 7.84 | I2: =IF((Gas!C9+Gas!G9)<0,"0",Gas!C9+Gas!G9) -> 50 | J2: 9.75 | K2: =IF(('Chilled Water'!C4+'Chilled Water'!E4)<0,"0",'Chilled Water'!C4+'Chilled Water'!E4) -> 10199 | L2: 0.33 | M2: =Elect!B9 -> 318
A3: Beach Rotana Residences Abu Dhabi | B3: =B2+1 -> 2 | C3: 5 | D3: 2024 | E3: =IF((Elect!D10+Elect!H10+Elect!J10)<0,"0",Elect!D10+Elect!H10+Elect!J10) -> 10094 | F3: 0.2 | G3: =IF(Water!C12<0,"0",Water!C12) -> 103 | H3: 7.84 | I3: =IF((Gas!C10+Gas!G10)<0,"0",Gas!C10+Gas!G10) -> 1 | J3: 9.75 | K3: =IF(('Chilled Water'!C5+'Chilled Water'!E5)<0,"0",'Chilled Water'!C5+'Chilled Water'!E5) -> 9305 | L3: 0.33 | M3: =Elect!B10 -> 320
A4: Beach Rotana Residences Abu Dhabi | B4: =B3+1 -> 3 | C4: 5 | D4: 2024 | E4: =IF((Elect!D11+Elect!H11+Elect!J11)<0,"0",Elect!D11+Elect!H11+Elect!J11) -> 9973 | F4: 0.2 | G4: =IF(Water!C13<0,"0",Water!C13) -> 105 | H4: 7.84 | I4: =IF((Gas!C11+Gas!G11)<0,"0",Gas!C11+Gas!G11) -> 128 | J4: 9.75 | K4: =IF(('Chilled Water'!C6+'Chilled Water'!E6)<0,"0",'Chilled Water'!C6+'Chilled Water'!E6) -> 8774 | L4: 0.33 | M4: =Elect!B11 -> 317
A5: Beach Rotana Residences Abu Dhabi | B5: =B4+1 -> 4 | C5: 5 | D5: 2024 | E5: =IF((Elect!D12+Elect!H12+Elect!J12)<0,"0",Elect!D12+Elect!H12+Elect!J12) -> 10157 | F5: 0.2 | G5: =IF(Water!C14<0,"0",Water!C14) -> 105 | H5: 7.84 | I5: =IF((Gas!C12+Gas!G12)<0,"0",Gas!C12+Gas!G12) -> 66 | J5: 9.75 | K5: =IF(('Chilled Water'!C7+'Chilled Water'!E7)<0,"0",'Chilled Water'!C7+'Chilled Water'!E7) -> 10003 | L5: 0.33 | M5: =Elect!B12 -> 311
A6: Beach Rotana Residences Abu Dhabi | B6: =B5+1 -> 5 | C6: 5 | D6: 2024 | E6: =IF((Elect!D13+Elect!H13+Elect!J13)<0,"0",Elect!D13+Elect!H13+Elect!J13) -> 10740 | F6: 0.2 | G6: =IF(Water!C15<0,"0",Water!C15) -> 114 | H6: 7.84 | I6: =IF((Gas!C13+Gas!G13)<0,"0",Gas!C13+Gas!G13) -> 68 | J6: 9.75 | K6: =IF(('Chilled Water'!C8+'Chilled Water'!E8)<0,"0",'Chilled Water'!C8+'Chilled Water'!E8) -> 9786 | L6: 0.33 | M6: =Elect!B13 -> 307
A7: Beach Rotana Residences Abu Dhabi | B7: =B6+1 -> 6 | C7: 5 | D7: 2024 | E7: =IF((Elect!D14+Elect!H14+Elect!J14)<0,"0",Elect!D14+Elect!H14+Elect!J14) -> 11148 | F7: 0.2 | G7: =IF(Water!C16<0,"0",Water!C16) -> 117 | H7: 7.84 | I7: =IF((Gas!C14+Gas!G14)<0,"0",Gas!C14+Gas!G14) -> 44 | J7: 9.75 | K7: =IF(('Chilled Water'!C9+'Chilled Water'!E9)<0,"0",'Chilled Water'!C9+'Chilled Water'!E9) -> 9901 | L7: 0.33 | M7: =Elect!B14 -> 312
A8: Beach Rotana Residences Abu Dhabi | B8: =B7+1 -> 7 | C8: 5 | D8: 2024 | E8: =IF((Elect!D15+Elect!H15+Elect!J15)<0,"0",Elect!D15+Elect!H15+Elect!J15) -> 11137 | F8: 0.2 | G8: =IF(Water!C17<0,"0",Water!C17) -> 218 | H8: 7.84 | I8: =IF((Gas!C15+Gas!G15)<0,"0",Gas!C15+Gas!G15) -> 36 | J8: 9.75 | K8: =IF(('Chilled Water'!C10+'Chilled Water'!E10)<0,"0",'Chilled Water'!C10+'Chilled Water'!E10) -> 10019 | L8: 0.33 | M8: =Elect!B15 -> 314
A9: Beach Rotana Residences Abu Dhabi | B9: =B8+1 -> 8 | C9: 5 | D9: 2024 | E9: =IF((Elect!D16+Elect!H16+Elect!J16)<0,"0",Elect!D16+Elect!H16+Elect!J16) -> 11295 | F9: 0.2 | G9: =IF(Water!C18<0,"0",Water!C18) -> 101 | H9: 7.84 | I9: =IF((Gas!C16+Gas!G16)<0,"0",Gas!C16+Gas!G16) -> 74 | J9: 9.75 | K9: =IF(('Chilled Water'!C11+'Chilled Water'!E11)<0,"0",'Chilled Water'!C11+'Chilled Water'!E11) -> 10892 | L9: 0.33 | M9: =Elect!B16 -> 314
A10: Beach Rotana Residences Abu Dhabi | B10: =B9+1 -> 9 | C10: 5 | D10: 2024 | E10: =IF((Elect!D17+Elect!H17+Elect!J17)<0,"0",Elect!D17+Elect!H17+Elect!J17) -> 11220 | F10: 0.2 | G10: =IF(Water!C19<0,"0",Water!C19) -> 106 | H10: 7.84 | I10: =IF((Gas!C17+Gas!G17)<0,"0",Gas!C17+Gas!G17) -> 66 | J10: 9.75 | K10: =IF(('Chilled Water'!C12+'Chilled Water'!E12)<0,"0",'Chilled Water'!C12+'Chilled Water'!E12) -> 10152 | L10: 0.33 | M10: =Elect!B17 -> 316
A11: Beach Rotana Residences Abu Dhabi | B11: =B10+1 -> 10 | C11: 5 | D11: 2024 | E11: =IF((Elect!D18+Elect!H18+Elect!J18)<0,"0",Elect!D18+Elect!H18+Elect!J18) -> 11278 | F11: 0.2 | G11: =IF(Water!C20<0,"0",Water!C20) -> 0 | H11: 7.84 | I11: =IF((Gas!C18+Gas!G18)<0,"0",Gas!C18+Gas!G18) -> 69 | J11: 9.75 | K11: =IF(('Chilled Water'!C13+'Chilled Water'!E13)<0,"0",'Chilled Water'!C13+'Chilled Water'!E13) -> 10171 | L11: 0.33 | M11: =Elect!B18 -> 305
A12: Beach Rotana Residences Abu Dhabi | B12: =B11+1 -> 11 | C12: 5 | D12: 2024 | E12: =IF((Elect!D19+Elect!H19+Elect!J19)<0,"0",Elect!D19+Elect!H19+Elect!J19) -> 11403 | F12: 0.2 | G12: =IF(Water!C21<0,"0",Water!C21) -> 0 | H12: 7.84 | I12: =IF((Gas!C19+Gas!G19)<0,"0",Gas!C19+Gas!G19) -> 76 | J12: 9.75 | K12: =IF(('Chilled Water'!C14+'Chilled Water'!E14)<0,"0",'Chilled Water'!C14+'Chilled Water'!E14) -> 9908 | L12: 0.33 | M12: =Elect!B19 -> 304
A13: Beach Rotana Residences Abu Dhabi | B13: =B12+1 -> 12 | C13: 5 | D13: 2024 | E13: =IF((Elect!D20+Elect!H20+Elect!J20)<0,"0",Elect!D20+Elect!H20+Elect!J20) -> 0 | F13: 0.2 | G13: =IF(Water!C22<0,"0",Water!C22) -> 0 | H13: 7.84 | I13: =IF((Gas!C20+Gas!G20)<0,"0",Gas!C20+Gas!G20) -> 0 | J13: 9.75 | K13: =IF(('Chilled Water'!C15+'Chilled Water'!E15)<0,"0",'Chilled Water'!C15+'Chilled Water'!E15) -> 0 | L13: 0.33 | M13: =Elect!B20 -> 0
A14: Beach Rotana Residences Abu Dhabi | B14: =B13+1 -> 13 | C14: 5 | D14: 2024 | E14: =IF((Elect!D21+Elect!H21+Elect!J21)<0,"0",Elect!D21+Elect!H21+Elect!J21) -> 0 | F14: 0.2 | G14: =IF(Water!C23<0,"0",Water!C23) -> 0 | H14: 7.84 | I14: =IF((Gas!C21+Gas!G21)<0,"0",Gas!C21+Gas!G21) -> 0 | J14: 9.75 | K14: =IF(('Chilled Water'!C16+'Chilled Water'!E16)<0,"0",'Chilled Water'!C16+'Chilled Water'!E16) -> 0 | L14: 0.33 | M14: =Elect!B21 -> 0
... A28: Beach Rotana Residences Abu Dhabi | B28: =B27+1 -> 27 | C28: 5 | D28: 2024 | E28: =IF((Elect!D35+Elect!H35+Elect!J35)<0,"0",Elect!D35+Elect!H35+Elect!J35) -> 0 | F28: 0.2 | G28: =IF(Water!C37<0,"0",Water!C37) -> 0 | H28: 7.84 | I28: =IF((Gas!C35+Gas!G35)<0,"0",Gas!C35+Gas!G35) -> 0 | J28: 9.75 | K28: =IF(('Chilled Water'!C30+'Chilled Water'!E30)<0,"0",'Chilled Water'!C30+'Chilled Water'!E30) -> 0 | L28: 0.33 | M28: =Elect!B35 -> 0
A29: Beach Rotana Residences Abu Dhabi | B29: =B28+1 -> 28 | C29: 5 | D29: 2024 | E29: =IF((Elect!D36+Elect!H36+Elect!J36)<0,"0",Elect!D36+Elect!H36+Elect!J36) -> 0 | F29: 0.2 | G29: =IF(Water!C39<0,"0",Water!C39) -> 0 | H29: 7.84 | I29: =IF((Gas!C36+Gas!G36)<0,"0",Gas!C36+Gas!G36) -> 0 | J29: 9.75 | K29: =IF(('Chilled Water'!C31+'Chilled Water'!E31)<0,"0",'Chilled Water'!C31+'Chilled Water'!E31) -> 0 | L29: 0.33 | M29: =Elect!B36 -> 0
A30: Beach Rotana Residences Abu Dhabi | B30: =B29+1 -> 29 | C30: 5 | D30: 2024 | E30: =IF((Elect!D37+Elect!H37+Elect!J37)<0,"0",Elect!D37+Elect!H37+Elect!J37) -> 0 | F30: 0.2 | G30: =IF(Water!C40<0,"0",Water!C40) -> 0 | H30: 7.84 | I30: =IF((Gas!C37+Gas!G37)<0,"0",Gas!C37+Gas!G37) -> 0 | J30: 9.75 | K30: =IF(('Chilled Water'!C32+'Chilled Water'!E32)<0,"0",'Chilled Water'!C32+'Chilled Water'!E32) -> 0 | L30: 0.33 | M30: =Elect!B37 -> 0
A31: Beach Rotana Residences Abu Dhabi | B31: =B30+1 -> 30 | C31: 5 | D31: 2024 | E31: =IF((Elect!D39+Elect!H39+Elect!J39)<0,"0",Elect!D39+Elect!H39+Elect!J39) -> 0 | F31: 0.2 | G31: =IF(Water!C41<0,"0",Water!C41) -> 0 | H31: 7.84 | I31: =IF((Gas!C39+Gas!G39)<0,"0",Gas!C39+Gas!G39) -> 0 | J31: 9.75 | K31: =IF(('Chilled Water'!C33+'Chilled Water'!E33)<0,"0",'Chilled Water'!C33+'Chilled Water'!E33) -> 0 | L31: 0.33 | M31: =Elect!B39 -> 0
A32: Beach Rotana Residences Abu Dhabi | B32: =B31+1 -> 31 | C32: 5 | D32: 2024 | E32: =IF((Elect!#REF!+Elect!#REF!+Elect!#REF!)<0,"0",Elect!#REF!+Elect!#REF!+Elect!#REF!) -> #REF! | F32: 0.2 | G32: =IF(Water!C42<0,"0",Water!C42) -> 0 | H32: 7.84 | I32: =IF((Gas!C40+Gas!G40)<0,"0",Gas!C40+Gas!G40) -> 0 | J32: 9.75 | K32: =IF(('Chilled Water'!C34+'Chilled Water'!E34)<0,"0",'Chilled Water'!C34+'Chilled Water'!E34) -> 0 | L32: 0.33 | M32: =Elect!#REF! -> #REF!

Sheet Elect
A1: BEACH ROTANA HOTEL ABU DHABI
A2: DAILY ELECTRICITY METER READING
A3: For the Month of May 2024
A5: Date | C5: BEACH ROTANA RESIDENCES | E5: LAUNDRY | G5: BEACH ROTANA RESIDENCES | I5: BEACH ROTANA RESIDENCES
B6: Room Night | C6: Meter 1 (kWh) - MDB8 | G6: Meter 2 (kWh) - MDB9 | I6: Meter 3 (kWh) - MDB11
C7: Electricity | G7: Electricity | I7: Electricity
C8: R | D8: C | E8: R | F8: C | G8: R | H8: C | I8: R | J8: C
A9: 45413 | B9: 318 | C9: 4275930 | D9: =C9-4273954 -> 1976 | G9: 7233422 | H9: =G9-7228995 -> 4427 | I9: 9346433 | J9: =I9-9342151 -> 4282
A10: 45414 | B10: 320 | C10: 4277813 | D10: =C10-C9 -> 1883 | G10: 7237494 | H10: =G10-G9 -> 4072 | I10: 9350572 | J10: =I10-I9 -> 4139
A11: 45415 | B11: 317 | C11: 4279904 | D11: =C11-C10 -> 2091 | F11: =E11-36689 -> -36689 | G11: 7240983 | H11: =G11-G10 -> 3489 | I11: 9354965 | J11: =I11-I10 -> 4393
A12: 45416 | B12: 311 | C12: 4281857 | D12: =C12-C11 -> 1953 | F12: =E12-E11 -> 0 | G12: 7244976 | H12: =G12-G11 -> 3993 | I12: 9359176 | J12: =I12-I11 -> 4211
A13: 45417 | B13: 307 | C13: 4283925 | D13: =C13-C12 -> 2068 | F13: =E13-E12 -> 0 | G13: 7249344 | H13: =G13-G12 -> 4368 | I13: 9363480 | J13: =I13-I12 -> 4304
A14: 45418 | B14: 312 | C14: 4285969 | D14: =C14-C13 -> 2044 | F14: =E14-E13 -> 0 | G14: 7254215 | H14: =G14-G13 -> 4871 | I14: 9367713 | J14: =I14-I13 -> 4233
A15: 45419 | B15: 314 | C15: 4287926 | D15: =C15-C14 -> 1957 | F15: =E15-E14 -> 0 | G15: 7259242 | H15: =G15-G14 -> 5027 | I15: 9371866 | J15: =I15-I14 -> 4153
A16: 45420 | B16: 314 | C16: 4289896 | D16: =C16-C15 -> 1970 | F16: =E16-E15 -> 0 | G16: 7264282 | H16: =G16-G15 -> 5040 | I16: 9376151 | J16: =I16-I15 -> 4285
A17: 45421 | B17: 316 | C17: 4291851 | D17: =C17-C16 -> 1955 | F17: =E17-E16 -> 0 | G17: 7269266 | H17: =G17-G16 -> 4984 | I17: 9380432 | J17: =I17-I16 -> 4281
A18: 45422 | B18: 305 | C18: 4293845 | D18: =C18-C17 -> 1994 | F18: =E18-E17 -> 0 | G18: 7274268 | H18: =G18-G17 -> 5002 | I18: 9384714 | J18: =I18-I17 -> 4282
A19: 45423 | B19: 304 | C19: 4295852 | D19: =C19-C18 -> 2007 | F19: =E19-E18 -> 0 | G19: 7279411 | H19: =G19-G18 -> 5143 | I19: 9388967 | J19: =I19-I18 -> 4253
A20: 45424 | D20: =C20-C19 -> -4295852 | F20: =E20-E19 -> 0 | H20: =G20-G19 -> -7279411 | J20: =I20-I19 -> -9388967
A21: 45425 | D21: =C21-C20 -> 0 | F21: =E21-E20 -> 0 | H21: =G21-G20 -> 0 | J21: =I21-I20 -> 0
A22: 45426 | D22: =C22-C21 -> 0 | F22: =E22-E21 -> 0 | H22: =G22-G21 -> 0 | J22: =I22-I21 -> 0
A23: 45427 | D23: =C23-C22 -> 0 | F23: =E23-E22 -> 0 | H23: =G23-G22 -> 0 | J23: =I23-I22 -> 0
A24: 45428 | D24: =C24-C23 -> 0 | F24: 0 | H24: =G24-G23 -> 0 | J24: =I24-I23 -> 0
A25: 45429 | D25: =C25-C24 -> 0 | F25: =E25-E24 -> 0 | H25: =G25-G24 -> 0 | J25: =I25-I24 -> 0
A26: 45430 | D26: =C26-C25 -> 0 | F26: =E26-E25 -> 0 | H26: =G26-G25 -> 0 | J26: =I26-I25 -> 0
A27: 45431 | D27: =C27-C26 -> 0 | F27: =E27-E26 -> 0 | H27: =G27-G26 -> 0 | J27: =I27-I26 -> 0
A28: 45432 | D28: =C28-C27 -> 0 | F28: =E28-E27 -> 0 | H28: =G28-G27 -> 0 | J28: =I28-I27 -> 0
A29: 45433 | D29: =C29-C28 -> 0 | F29: =E29-E28 -> 0 | H29: =G29-G28 -> 0 | J29: =I29-I28 -> 0
A30: 45434 | D30: =C30-C29 -> 0 | F30: =E30-E29 -> 0 | H30: =G30-G29 -> 0 | J30: =I30-I29 -> 0
A31: 45435 | D31: =C31-C30 -> 0 | F31: =E31-E30 -> 0 | H31: =G31-G30 -> 0 | J31: =I31-I30 -> 0
A32: 45436 | D32: =C32-C31 -> 0 | F32: =E32-E31 -> 0 | H32: =G32-G31 -> 0 | J32: =I32-I31 -> 0
A33: 45437 | D33: =C33-C32 -> 0 | F33: =E33-E32 -> 0 | H33: =G33-G32 -> 0 | J33: =I33-I32 -> 0
A34: 45438 | D34: =C34-C33 -> 0 | H34: =G34-G33 -> 0 | J34: =I34-I33 -> 0
A35: 45439 | D35: =C35-C34 -> 0 | H35: =G35-G34 -> 0 | J35: =I35-I34 -> 0
A36: 45440 | D36: =C36-C35 -> 0 | H36: =G36-G35 -> 0 | J36: =I36-I35 -> 0
A37: 45441 | D37: =C37-C36 -> 0 | H37: =G37-G36 -> 0 | J37: =I37-I36 -> 0
A38: 45442 | D38: =C38-C36 -> 0 | H38: =G38-G36 -> 0 | J38: =I38-I36 -> 0
A39: 45443 | D39: =C39-C37 -> 0 | H39: =G39-G37 -> 0 | J39: =I39-I37 -> 0
A40: Total Reading | D40: =SUM(D9:D39) -> -4273954 | F40: =SUM(F11:F37) -> -36689 | H40: =SUM(H9:H39) -> -7228995 | J40: =SUM(J9:J39) -> -9342151
C41: =D40+H40+J40 -> -20845100
...

Sheet Water
A1: BEACH ROTANA HOTEL ABUDHABI
A2: DAILY WATER METER READING
A3: For the Month of May 2024
A5: Date | B5: BEACH ROTANA RESIDENCES | D5: LAUNDRY
B6: Water - M³
B8: R | C8: C | D8: R | E8: C
A9: 45413 | B9: 186709 | C9: =B9-186628 -> 81
A10: 45414 | B10: 186813 | C10: =B10-B9 -> 104
A11: 45415 | B11: 186913 | C11: =B11-B10 -> 100 | E11: =D11-36689 -> -36689
A12: 45416 | B12: 187016 | C12: =B12-B11 -> 103 | E12: =D12-D11 -> 0
A13: 45417 | B13: 187121 | C13: =B13-B12 -> 105 | E13: =D13-D12 -> 0
A14: 45418 | B14: 187226 | C14: =B14-B13 -> 105 | E14: =D14-D13 -> 0
A15: 45419 | B15: 187340 | C15: =B15-B14 -> 114 | E15: =D15-D14 -> 0
A16: 45420 | B16: 187457 | C16: =B16-B15 -> 117 | E16: =D16-D15 -> 0
A17: 45421 | B17: 187675 | C17: =B17-B16 -> 218 | E17: =D17-D16 -> 0
A18: 45422 | B18: 187776 | C18: =B18-B17 -> 101 | E18: =D18-D17 -> 0
A19: 45423 | B19: 187882 | C19: =B19-B18 -> 106 | E19: =D19-D18 -> 0
A20: 45424 | C20: =B20-B19 -> -187882 | E20: =D20-D19 -> 0
A21: 45425 | C21: =B21-B20 -> 0 | E21: =D21-D20 -> 0
A22: 45426 | C22: =B22-B21 -> 0 | E22: =D22-D21 -> 0
A23: 45427 | C23: =B23-B22 -> 0 | E23: =D23-D22 -> 0
A24: 45428 | C24: =B24-B23 -> 0 | E24: 0
A25: 45429 | C25: =B25-B24 -> 0 | E25: =D25-D24 -> 0
A26: 45430 | C26: =B26-B25 -> 0 | E26: =D26-D25 -> 0
A27: 45431 | C27: =B27-B26 -> 0 | E27: =D27-D26 -> 0
A28: 45432 | C28: =B28-B27 -> 0 | E28: =D28-D27 -> 0
A29: 45433 | C29: =B29-B28 -> 0 | E29: =D29-D28 -> 0
A30: 45434 | C30: =B30-B29 -> 0 | E30: =D30-D29 -> 0
A31: 45435 | C31: =B31-B30 -> 0 | E31: =D31-D30 -> 0
A32: 45436 | C32: =B32-B31 -> 0 | E32: =D32-D31 -> 0
A33: 45437 | C33: =B33-B32 -> 0 | E33: =D33-D32 -> 0
A34: 45438 | C34: =B34-B33 -> 0
A35: 45439 | C35: =B35-B34 -> 0
A36: 45440 | C36: =B36-B35 -> 0
A37: 45441 | C37: =B37-B36 -> 0
A38: 45442 | C38: =B38-B36 -> 0 | E38: =D38-D32 -> 0
A39: 45443 | C39: =B39-B37 -> 0 | E39: =D39-D33 -> 0
A40: Total Reading
C41: =SUM(C9:C40) -> -186628 | E41: =SUM(E11:E39) -> -36689
A42: R - Reading
...

Sheet Gas
A1: BEACH ROTANA HOTEL ABU DHABI
A2: DAILY ELECTRICITY METER READING
A3: For the Month of May 2024
A5: Date | B5: BEACH ROTANA RESIDENCES | D5: LAUNDRY | F5: BEACH ROTANA RESIDENCES
B6: Penthouse (Boiler) - M³ | F6: Kitchen - M³
B7: Gas | F7: Gas
B8: R | C8: C | D8: R | E8: C | F8: R | G8: C
A9: 45413 | B9: 109842 | C9: =B9-109794 -> 48 | F9: 21007 | G9: =F9-21005 -> 2
A10: 45414 | B10: 109842 | C10: =B10-B9 -> 0 | F10: 21008 | G10: =F10-F9 -> 1
A11: 45415 | B11: 109968 | C11: =B11-B10 -> 126 | E11: =D11-36689 -> -36689 | F11: 21010 | G11: =F11-F10 -> 2
A12: 45416 | B12: 110033 | C12: =B12-B11 -> 65 | E12: =D12-D11 -> 0 | F12: 21011 | G12: =F12-F11 -> 1
A13: 45417 | B13: 110099 | C13: =B13-B12 -> 66 | E13: =D13-D12 -> 0 | F13: 21013 | G13: =F13-F12 -> 2
A14: 45418 | B14: 110141 | C14: =B14-B13 -> 42 | E14: =D14-D13 -> 0 | F14: 21015 | G14: =F14-F13 -> 2
A15: 45419 | B15: 110174 | C15: =B15-B14 -> 33 | E15: =D15-D14 -> 0 | F15: 21018 | G15: =F15-F14 -> 3
A16: 45420 | B16: 110247 | C16: =B16-B15 -> 73 | E16: =D16-D15 -> 0 | F16: 21019 | G16: =F16-F15 -> 1
A17: 45421 | B17: 110312 | C17: =B17-B16 -> 65 | E17: =D17-D16 -> 0 | F17: 21020 | G17: =F17-F16 -> 1
A18: 45422 | B18: 110379 | C18: =B18-B17 -> 67 | E18: =D18-D17 -> 0 | F18: 21022 | G18: =F18-F17 -> 2
A19: 45423 | B19: 110453 | C19: =B19-B18 -> 74 | E19: =D19-D18 -> 0 | F19: 21024 | G19: =F19-F18 -> 2
A20: 45424 | C20: =B20-B19 -> -110453 | E20: =D20-D19 -> 0 | G20: =F20-F19 -> -21024
A21: 45425 | C21: =B21-B20 -> 0 | E21: =D21-D20 -> 0 | G21: =F21-F20 -> 0
A22: 45426 | C22: =B22-B21 -> 0 | E22: =D22-D21 -> 0 | G22: =F22-F21 -> 0
A23: 45427 | C23: =B23-B22 -> 0 | E23: =D23-D22 -> 0 | G23: =F23-F22 -> 0
A24: 45428 | C24: =B24-B23 -> 0 | E24: 0 | G24: =F24-F23 -> 0
A25: 45429 | C25: =B25-B24 -> 0 | E25: =D25-D24 -> 0 | G25: =F25-F24 -> 0
A26: 45430 | C26: =B26-B25 -> 0 | E26: =D26-D25 -> 0 | G26: =F26-F25 -> 0
A27: 45431 | C27: =B27-B26 -> 0 | E27: =D27-D26 -> 0 | G27: =F27-F26 -> 0
A28: 45432 | C28: =B28-B27 -> 0 | E28: =D28-D27 -> 0 | G28: =F28-F27 -> 0
A29: 45433 | C29: =B29-B28 -> 0 | E29: =D29-D28 -> 0 | G29: =F29-F28 -> 0
A30: 45434 | C30: =B30-B29 -> 0 | E30: =D30-D29 -> 0 | G30: =F30-F29 -> 0
A31: 45435 | C31: =B31-B30 -> 0 | E31: =D31-D30 -> 0 | G31: =F31-F30 -> 0
A32: 45436 | C32: =B32-B31 -> 0 | E32: =D32-D31 -> 0 | G32: =F32-F31 -> 0
A33: 45437 | C33: =B33-B32 -> 0 | E33: =D33-D32 -> 0 | G33: =F33-F32 -> 0
A34: 45438 | C34: =B34-B33 -> 0 | G34: =F34-F33 -> 0
A35: 45439 | C35: =B35-B34 -> 0 | G35: =F35-F34 -> 0
A36: 45440 | C36: =B36-B35 -> 0 | G36: =F36-F35 -> 0
A37: 45441 | C37: =B37-B36 -> 0 | G37: =F37-F36 -> 0
A38: 45442 | C38: =B38-B37 -> 0 | G38: =F38-F37 -> 0
A39: 45443 | C39: =B39-B37 -> 0 | G39: =F39-F37 -> 0
A40: Total Reading
C41: =SUM(C9:C40) -> -109794 | E41: =SUM(E11:E37) -> -36689 | G41: =SUM(G9:G40) -> -21005
...

Sheet Chilled Water
A1: SECONDARY PUMP (CHILLED WATER READING) May 2024
A2: Date | B2: Meter 1 | D2: Meter 2
B3: R | C3: C | D3: R | E3: C
A4: 45413 | B4: 2273896 | C4: =B4-2272417 -> 1479 | D4: 13759993 | E4: =D4-13751273 -> 8720
A5: 45414 | B5: 2275266 | C5: =B5-B4 -> 1370 | D5: 13767928 | E5: =D5-D4 -> 7935
A6: 45415 | B6: 2276619 | C6: =B6-B5 -> 1353 | D6: 13775349 | E6: =D6-D5 -> 7421
A7: 45416 | B7: 2278053 | C7: =B7-B6 -> 1434 | D7: 13783918 | E7: =D7-D6 -> 8569
A8: 45417 | B8: 2279443 | C8: =B8-B7 -> 1390 | D8: 13792314 | E8: =D8-D7 -> 8396
A9: 45418 | B9: 2280849 | C9: =B9-B8 -> 1406 | D9: 13800809 | E9: =D9-D8 -> 8495
A10: 45419 | B10: 2282289 | C10: =B10-B9 -> 1440 | D10: 13809388 | E10: =D10-D9 -> 8579
A11: 45420 | B11: 2283840 | C11: =B11-B10 -> 1551 | D11: 13818729 | E11: =D11-D10 -> 9341
A12: 45421 | B12: 2285301 | C12: =B12-B11 -> 1461 | D12: 13827420 | E12: =D12-D11 -> 8691
A13: 45422 | B13: 2286754 | C13: =B13-B12 -> 1453 | D13: 13836138 | E13: =D13-D12 -> 8718
A14: 45423 | B14: 2288173 | C14: =B14-B13 -> 1419 | D14: 13844627 | E14: =D14-D13 -> 8489
A15: 45424 | C15: =B15-B14 -> -2288173 | E15: =D15-D14 -> -13844627
A16: 45425 | C16: =B16-B15 -> 0 | E16: =D16-D15 -> 0
A17: 45426 | C17: =B17-B16 -> 0 | E17: =D17-D16 -> 0
A18: 45427 | C18: =B18-B17 -> 0 | E18: =D18-D17 -> 0
A19: 45428 | C19: =B19-B18 -> 0 | E19: =D19-D18 -> 0
A20: 45429 | C20: =B20-B19 -> 0 | E20: =D20-D19 -> 0
A21: 45430 | C21: =B21-B20 -> 0 | E21: =D21-D20 -> 0
A22: 45431 | C22: =B22-B21 -> 0 | E22: =D22-D21 -> 0
A23: 45432 | C23: =B23-B22 -> 0 | E23: =D23-D22 -> 0
A24: 45433 | C24: =B24-B23 -> 0 | E24: =D24-D23 -> 0
A25: 45434 | C25: =B25-B24 -> 0 | E25: =D25-D24 -> 0
A26: 45435 | C26: =B26-B25 -> 0 | E26: =D26-D25 -> 0
... A34: 45443 | C34: =B34-B33 -> 0 | E34: =D34-D33 -> 0
A35: Total BRR Reading | B35: =SUM(C4:C34) -> -2272417 | D35: =SUM(E4:E34) -> -13751273
A36: Grand Total | B36: =B35+D35 -> -16023690

Sheet Cost 
B1: Consumption of Electricity,Water & L.P. Gas
B2: For the Month of September 2017
B4: Electricity charges
C5: Kwh
B6: Location | C6: Meter reading | E6: Consumption and amount
C7: from | D7: to | E7: Mul. Units | F7: Factor | G7: Cons.Units | H7: Rate | I7: Amount (AED)
B8: Beach Wing - Meter No.1 | C8: 8800732 | D8: 9177927 | E8: =+D8-C8 -> 377195 | F8: 1 | G8: =+F8*E8 -> 377195 | H8: 0.2 | I8: =G8*H8 -> 75439
B9: Beach Wing - Meter No.2 | C9: 17584845 | D9: 17917016 | E9: =+D9-C9 -> 332171 | F9: 1 | G9: =+F9*E9 -> 332171 | H9: 0.2 | I9: =G9*H9 -> 66434.2
B10: Beach Wing - Meter No.3 | C10: 26995657 | D10: 27436051 | E10: =+D10-C10 -> 440394 | F10: 1 | G10: =+F10*E10 -> 440394 | H10: 0.2 | I10: =G10*H10 -> 88078.8
B11: Total Electricity charges | G11: =SUM(G8:G10) -> 1149760 | I11: =SUM(I8:I10) -> 229952
B14: Domestic Water Charges
C15: M3
B16: Location | C16: Meter reading | E16: Consumption and amount
C17: from | D17: to | E17: Mul. Units | F17: Factor | G17: Cons.Units | H17: Rate | I17: Amount (AED)
B18: Laundry | C18: 526949 | D18: 531926 | E18: =+D18-C18 -> 4977 | F18: 1 | G18: =F18*E18 -> 4977 | H18: 7.84 | I18: =H18*E18 -> 39019.68
B19: Boiler | E19: =+D19-C19 -> 0 | F19: 1 | G19: =F19*E19 -> 0 | H19: 7.84 | I19: =H19*E19 -> 0
B20: Total Domestic Water Charges | E20: =SUM(E18:E19) -> 4977 | G20: =SUM(G18:G19) -> 4977 | I20: =SUM(I18:I19) -> 39019.68
B23: Chilled Water Charges
C24: M3
B25: Location | C25: Meter reading | E25: Consumption and amount
C26: from | D26: to | E26: Mul. Units | F26: Factor | G26: Cons.Units | H26: Rate | I26: Amount (AED)
B27: AHU L1 | C27: 526949 | D27: 531926 | E27: =+D27-C27 -> 4977 | F27: 1 | G27: =F27*E27 -> 4977 | H27: 7.84 | I27: =H27*E27 -> 39019.68
B28: AHU L2 | E28: =+D28-C28 -> 0 | F28: 1 | G28: =F28*E28 -> 0 | H28: 7.84 | I28: =H28*E28 -> 0
B29: AHU L3 | E29: =+D29-C29 -> 0 | F29: 1 | G29: =F29*E29 -> 0 | H29: 7.84 | I29: =H29*E29 -> 0
B30: AHU L4 | E30: =+D30-C30 -> 0 | F30: 1 | G30: =F30*E30 -> 0 | H30: 7.84 | I30: =H30*E30 -> 0
B31: Total Chilled Water Charges | E31: =SUM(E27:E30) -> 4977 | G31: =SUM(G27:G30) -> 4977 | I31: =SUM(I27:I30) -> 39019.68
B34: LPG Gas
C35: Liters
B36: Location | C36: Meter reading | E36: Consumption and amount
C37: from | D37: to | E37: Mul. Units | F37: Factor | G37: Cons.Units | H37: Rate | I37: Amount (AED)
B38: Laundry (Liters) | E38: 17300 | F38: 1 | G38: =+F38*E38 -> 17300 | H38: 1.28 | I38: =+G38*H38 -> 22144
