Workbook

Sheet TOTAL
A1: Site Name | B1: Day | C1: Month | D1: Year | E1: Total Electricity Kwh | F1: Electricity Tariff ($/Kwh) | G1: LPG (Liters) | H1: LPG $/Liters | I1: Water Utility Supply (m3) m3 | J1: Water Utility Supply (m3) $/m3 | K1: District Energy Cooling RTH | L1: District Energy Cooling $/RTH | M1: Room Nights | N1: Total Guests
A2: Amwaj Rotana - Jumeirah Beach | B2: 1 | C2: 3 | D2: 2024 | E2: ='MTD Utility Sheet'!G4/0.439 -> 15137.608 | F2: 0.439 | G2: =('MTD Utility Sheet'!I4/1.82)/0.5 -> 488 | H2: =1.82*0.5 -> 0.91 | I2: ='MTD Utility Sheet'!H4/12.38 -> 219.77383 | J2: 12.38 | K2: =IF(('MTD Utility Sheet'!F4-2866)<0,"0",('MTD Utility Sheet'!F4-2866)/(0.568+0.075)) -> 3056.7652 | L2: ='MTD Utility Sheet'!F4/K2 -> 1.5805925 | M2: ='MTD Utility Sheet'!B4*301 -> 301
A3: Amwaj Rotana - Jumeirah Beach | B3: =B2+1 -> 2 | C3: 3 | D3: 2024 | E3: ='MTD Utility Sheet'!G5/0.439 -> 14160.979 | F3: 0.439 | G3: =('MTD Utility Sheet'!I5/1.82)/0.5 -> 390.3956 | H3: =1.82*0.5 -> 0.91 | I3: ='MTD Utility Sheet'!H5/12.38 -> 188.85299 | J3: 12.38 | K3: =IF(('MTD Utility Sheet'!F5-2866)<0,"0",('MTD Utility Sheet'!F5-2866)/(0.568+0.075)) -> 2786.6252 | L3: ='MTD Utility Sheet'!F5/K3 -> 1.6714842 | M3: ='MTD Utility Sheet'!B5*301 -> 300.0067
A4: Amwaj Rotana - Jumeirah Beach | B4: =B3+1 -> 3 | C4: 3 | D4: 2024 | E4: ='MTD Utility Sheet'!G6/0.439 -> 14160.979 | F4: 0.439 | G4: =('MTD Utility Sheet'!I6/1.82)/0.5 -> 585.6044 | H4: =1.82*0.5 -> 0.91 | I4: ='MTD Utility Sheet'!H6/12.38 -> 212.31018 | J4: 12.38 | K4: =IF(('MTD Utility Sheet'!F6-2866)<0,"0",('MTD Utility Sheet'!F6-2866)/(0.568+0.075)) -> 2894.6812 | L4: ='MTD Utility Sheet'!F6/K4 -> 1.6330918 | M4: ='MTD Utility Sheet'!B6*301 -> 300.0067
A5: Amwaj Rotana - Jumeirah Beach | B5: =B4+1 -> 4 | C5: 3 | D5: 2024 | E5: ='MTD Utility Sheet'!G7/0.439 -> 14160.979 | F5: 0.439 | G5: =('MTD Utility Sheet'!I7/1.82)/0.5 -> 488 | H5: =1.82*0.5 -> 0.91 | I5: ='MTD Utility Sheet'!H7/12.38 -> 202.71405 | J5: 12.38 | K5: =IF(('MTD Utility Sheet'!F7-2866)<0,"0",('MTD Utility Sheet'!F7-2866)/(0.568+0.075)) -> 3272.8616 | L5: ='MTD Utility Sheet'!F7/K5 -> 1.5186863 | M5: ='MTD Utility Sheet'!B7*301 -> 301
A6: Amwaj Rotana - Jumeirah Beach | B6: =B5+1 -> 5 | C6: 3 | D6: 2024 | E6: ='MTD Utility Sheet'!G8/0.439 -> 14160.979 | F6: 0.439 | G6: =('MTD Utility Sheet'!I8/1.82)/0.5 -> 488 | H6: =1.82*0.5 -> 0.91 | I6: ='MTD Utility Sheet'!H8/12.38 -> 202.71405 | J6: 12.38 | K6: =IF(('MTD Utility Sheet'!F8-2866)<0,"0",('MTD Utility Sheet'!F8-2866)/(0.568+0.075)) -> 4248.196 | L6: ='MTD Utility Sheet'!F8/K6 -> 1.3176393 | M6: ='MTD Utility Sheet'!B8*301 -> 297.99
A7: Amwaj Rotana - Jumeirah Beach | B7: =B6+1 -> 6 | C7: 3 | D7: 2024 | E7: ='MTD Utility Sheet'!G9/0.439 -> 14649.294 | F7: 0.439 | G7: =('MTD Utility Sheet'!I9/1.82)/0.5 -> 488 | H7: =1.82*0.5 -> 0.91 | I7: ='MTD Utility Sheet'!H9/12.38 -> 229.36995 | J7: 12.38 | K7: =IF(('MTD Utility Sheet'!F9-2866)<0,"0",('MTD Utility Sheet'!F9-2866)/(0.568+0.075)) -> 3656.7341 | L7: ='MTD Utility Sheet'!F9/K7 -> 1.4267595 | M7: ='MTD Utility Sheet'!B9*301 -> 301
A8: Amwaj Rotana - Jumeirah Beach | B8: =B7+1 -> 7 | C8: 3 | D8: 2024 | E8: ='MTD Utility Sheet'!G10/0.439 -> 14160.979 | F8: 0.439 | G8: =('MTD Utility Sheet'!I10/1.82)/0.5 -> 390.3956 | H8: =1.82*0.5 -> 0.91 | I8: ='MTD Utility Sheet'!H10/12.38 -> 203.78029 | J8: 12.38 | K8: =IF(('MTD Utility Sheet'!F10-2866)<0,"0",('MTD Utility Sheet'!F10-2866)/(0.568+0.075)) -> 3804.6034 | L8: ='MTD Utility Sheet'!F10/K8 -> 1.396298 | M8: ='MTD Utility Sheet'!B10*301 -> 299.0134
A9: Amwaj Rotana - Jumeirah Beach | B9: =B8+1 -> 8 | C9: 3 | D9: 2024 | E9: ='MTD Utility Sheet'!G11/0.439 -> 14649.294 | F9: 0.439 | G9: =('MTD Utility Sheet'!I11/1.82)/0.5 -> 390.3956 | H9: =1.82*0.5 -> 0.91 | I9: ='MTD Utility Sheet'!H11/12.38 -> 220.84006 | J9: 12.38 | K9: =IF(('MTD Utility Sheet'!F11-2866)<0,"0",('MTD Utility Sheet'!F11-2866)/(0.568+0.075)) -> 4788.4603 | L9: ='MTD Utility Sheet'!F11/K9 -> 1.2415222 | M9: ='MTD Utility Sheet'!B11*301 -> 297.99
A10: Amwaj Rotana - Jumeirah Beach | B10: =B9+1 -> 9 | C10: 3 | D10: 2024 | E10: ='MTD Utility Sheet'!G12/0.439 -> 15137.608 | F10: 0.439 | G10: =('MTD Utility Sheet'!I12/1.82)/0.5 -> 439.1978 | H10: =1.82*0.5 -> 0.91 | I10: ='MTD Utility Sheet'!H12/12.38 -> 188.85299 | J10: 12.38 | K10: =IF(('MTD Utility Sheet'!F12-2866)<0,"0",('MTD Utility Sheet'!F12-2866)/(0.568+0.075)) -> 4020.7154 | L10: ='MTD Utility Sheet'!F12/K10 -> 1.3558085 | M10: ='MTD Utility Sheet'!B12*301 -> 290.0135
A11: Amwaj Rotana - Jumeirah Beach | B11: =B10+1 -> 10 | C11: 3 | D11: 2024 | E11: ='MTD Utility Sheet'!G13/0.439 -> 14649.294 | F11: 0.439 | G11: =('MTD Utility Sheet'!I13/1.82)/0.5 -> 390.3956 | H11: =1.82*0.5 -> 0.91 | I11: ='MTD Utility Sheet'!H13/12.38 -> 176.05816 | J11: 12.38 | K11: =IF(('MTD Utility Sheet'!F13-2866)<0,"0",('MTD Utility Sheet'!F13-2866)/(0.568+0.075)) -> 3963.8414 | L11: ='MTD Utility Sheet'!F13/K11 -> 1.366036 | M11: ='MTD Utility Sheet'!B13*301 -> 255.0072
A12: Amwaj Rotana - Jumeirah Beach | B12: =B11+1 -> 11 | C12: 3 | D12: 2024 | E12: ='MTD Utility Sheet'!G14/0.439 -> 13672.665 | F12: 0.439 | G12: =('MTD Utility Sheet'!I14/1.82)/0.5 -> 488 | H12: =1.82*0.5 -> 0.91 | I12: ='MTD Utility Sheet'!H14/12.38 -> 158.99838 | J12: 12.38 | K12: =IF(('MTD Utility Sheet'!F14-2866)<0,"0",('MTD Utility Sheet'!F14-2866)/(0.568+0.075)) -> 3966.6874 | L12: ='MTD Utility Sheet'!F14/K12 -> 1.3655172 | M12: ='MTD Utility Sheet'!B14*301 -> 229.964
A13: Amwaj Rotana - Jumeirah Beach | B13: =B12+1 -> 12 | C13: 3 | D13: 2024 | E13: ='MTD Utility Sheet'!G15/0.439 -> 14649.294 | F13: 0.439 | G13: =('MTD Utility Sheet'!I15/1.82)/0.5 -> 488 | H13: =1.82*0.5 -> 0.91 | I13: ='MTD Utility Sheet'!H15/12.38 -> 160.06462 | J13: 12.38 | K13: =IF(('MTD Utility Sheet'!F15-2866)<0,"0",('MTD Utility Sheet'!F15-2866)/(0.568+0.075)) -> 4026.3919 | L13: ='MTD Utility Sheet'!F15/K13 -> 1.3548035 | M13: ='MTD Utility Sheet'!B15*301 -> 219.9708
A14: Amwaj Rotana - Jumeirah Beach | B14: =B13+1 -> 13 | C14: 3 | D14: 2024 | E14: ='MTD Utility Sheet'!G16/0.439 -> 13184.374 | F14: 0.439 | G14: =('MTD Utility Sheet'!I16/1.82)/0.5 -> 341.6044 | H14: =1.82*0.5 -> 0.91 | I14: ='MTD Utility Sheet'!H16/12.38 -> 163.26333 | J14: 12.38 | K14: =IF(('MTD Utility Sheet'!F16-2866)<0,"0",('MTD Utility Sheet'!F16-2866)/(0.568+0.075)) -> 3830.2022 | L14: ='MTD Utility Sheet'!F16/K14 -> 1.3912634 | M14: ='MTD Utility Sheet'!B16*301 -> 215.9976
... A32: Amwaj Rotana - Jumeirah Beach | B32: =B31+1 -> 31 | C32: 3 | D32: 2026 | E32: ='MTD Utility Sheet'!G34/0.439 -> 15137.608 | F32: 0.439 | G32: =('MTD Utility Sheet'!I34/1.82)/0.5 -> 585.6044 | H32: =1.82*0.5 -> 0.91 | I32: ='MTD Utility Sheet'!H34/12.38 -> 213.37641 | J32: 12.38 | K32: =IF(('MTD Utility Sheet'!F34-2866)<0,"0",('MTD Utility Sheet'!F34-2866)/(0.568+0.075)) -> 5957.1384 | L32: ='MTD Utility Sheet'!F34/K32 -> 1.1241035 | M32: ='MTD Utility Sheet'!B34*301 -> 280.9233

Sheet MTD Utility Sheet
A1: Daily Utilities March 2024
B3: Occ % | C3: Out. Temp at 2PM | D3: RH % | E3: F&B Covers | F3: Chilled water | G3: Electricity | H3: Water | I3: LPG | J3: Total
A4: 1 | B4: 1 | C4: 23.50c | D4: 0.661 | E4: 1393 | F4: 4831.5 | G4: 6645.41 | H4: 2720.8 | I4: 444.08 | J4: =SUM(F4+G4+H4+I4) -> 14641.79
A5: 2 | B5: 0.9967 | C5: 21.0c | D5: 0.74 | E5: 1573 | F5: 4657.8 | G5: 6216.67 | H5: 2338 | I5: 355.26 | J5: =SUM(F5+G5+H5+I5) -> 13567.73
A6: 3 | B6: 0.9967 | C6: 21.20c | D6: 0.71 | E6: 1274 | F6: 4727.28 | G6: 6216.67 | H6: 2628.4 | I6: 532.9 | J6: =SUM(F6+G6+H6+I6) -> 14105.25
A7: 4 | B7: 1 | C7: 24.54c | D7: 0.7 | E7: 1170 | F7: 4970.45 | G7: 6216.67 | H7: 2509.6 | I7: 444.08 | J7: =SUM(F7+G7+H7+I7) -> 14140.8
A8: 5 | B8: 0.99 | C8: 24.82c | D8: 0.72 | E8: 1126 | F8: 5597.59 | G8: 6216.67 | H8: 2509.6 | I8: 444.08 | J8: =SUM(F8+G8+H8+I8) -> 14767.94
A9: 6 | B9: 1 | C9: 24.23c | D9: 0.6705 | E9: 1358 | F9: 5217.28 | G9: 6431.04 | H9: 2839.6 | I9: 444.08 | J9: =SUM(F9+G9+H9+I9) -> 14932
A10: 7 | B10: 0.9934 | C10: 23.0c | D10: 0.88 | E10: 1421 | F10: 5312.36 | G10: 6216.67 | H10: 2522.8 | I10: 355.26 | J10: =SUM(F10+G10+H10+I10) -> 14407.09
A11: 8 | B11: 0.99 | C11: 23.50c | D11: 0.84 | E11: 1385 | F11: 5944.98 | G11: 6431.04 | H11: 2734 | I11: 355.26 | J11: =SUM(F11+G11+H11+I11) -> 15465.28
A12: 9 | B12: 0.9635 | C12: 21.0c | D12: 0.85 | E12: 1442 | F12: 5451.32 | G12: 6645.41 | H12: 2338 | I12: 399.67 | J12: =SUM(F12+G12+H12+I12) -> 14834.4
A13: 10 | B13: 0.8472 | C13: 21.0c | D13: 0.99 | E13: 1270 | F13: 5414.75 | G13: 6431.04 | H13: 2179.6 | I13: 355.26 | J13: =SUM(F13+G13+H13+I13) -> 14380.65
A14: 11 | B14: 0.764 | C14: 25.8c | D14: 0.86 | E14: 1133 | F14: 5416.58 | G14: 6002.3 | H14: 1968.4 | I14: 444.08 | J14: =SUM(F14+G14+H14+I14) -> 13831.36
A15: 12 | B15: 0.7308 | C15: 26.0c | D15: 0.78 | E15: 1087 | F15: 5454.97 | G15: 6431.04 | H15: 1981.6 | I15: 444.08 | J15: =SUM(F15+G15+H15+I15) -> 14311.69
... A34: 31 | B34: 0.9333 | C34: 26.0c | D34: 0.84 | E34: 1563 | F34: 6696.44 | G34: 6645.41 | H34: 2641.6 | I34: 532.9 | J34: =SUM(F34+G34+H34+I34) -> 16516.35
A35: Total Cost | F35: =SUM(F4:F34) -> 184844.61 | G35: =SUM(G4:G34) -> 197218.55 | H35: =SUM(H4:H34) -> 75355.6 | I35: =SUM(I4:I34) -> 13099.49 | J35: =SUM(J4:J34) -> 470518.25
A36: Total Units | B36: =AVERAGE(B4:B34) -> 0.88660323 | C36: =AVERAGE(C4:C34) -> #DIV/0! | D36: =AVERAGE(D4:D34) -> 0.79553226 | E36: =SUM(E4:E34) -> 41820 | F36: =F35*0.38 -> 70240.952 | G36: =G35/12.9 -> 15288.26 | H36: =H35/0.92 -> 81908.261 | I36: =I35/1.76 -> 7442.892

Sheet March-31
A1: Daily Utilities Consumption
A2: 31.3.2024
A3: District Cooling
A4: Previous Reading MWh | B4: 60688.01 | C4: Current Reading MWh | D4: 60708.96 | E4: Consumption MWH | F4: =D4-B4 -> 20.95 | G4: Consumption RTH | H4: =F4*284.35 -> 5957.1325
A5: Cost Calculation
A6: Total Cost (0.568/rth) | D6: =H4*0.568 -> 3383.6513
A7: Total Fuel Surchage Cost (0.075/rth) | D7: =H4*0.075 -> 446.78494
A8: Chilled Water Demand (2,866 AED/Day) | D8: 2866
A9: Grand Total Exc. VAT | D9: =SUM(D6:H8) -> 6696.4362
A10: Electrical
A11: MDB-G1 (39299675-8) | C11: Previous Reading KWH | D11: 41353 | E11: Current Reading KWH | F11: 41360 | G11: Consumption KWH | H11: =F11-D11 -> 7
A12: MDB-G2 (39299676-6) | C12: Previous Reading KWH | D12: 68446 | E12: Current Reading KWH | F12: 68459 | G12: Consumption KWH | H12: =F12-D12 -> 13
A13: MDB-G3 (39299677-4) | C13: Previous Reading KWH | D13: 69736 | E13: Current Reading KWH | F13: 69747 | G13: Consumption KWH | H13: =F13-D13 -> 11
A14: Total Consumption KWH | H14: =SUM(H11:H13) -> 31
A15: Total Consumption * Multiplication Factor (487.20) | H15: =H14*487.2 -> 15103.2
A16: Cost Calculation
A17: 0-2000 kwh @ 0.230 /KWH | D17: 460
A18: 2000-4000 kwh @ 0.280 /KWH | D18: 560
A19: 4000-6000 kwh @ 0.320 /KWH | D19: 640
A20: 6000 & above @ 0.380 /KWH | D20: =H15*0.38 -> 5739.216
A21: Fuel Surcharge @ 0.060 /KWH | D21: =H15*0.06 -> 906.192
A22: Grand Total Exc. VAT | D22: =D20+D21 -> 6645.408
A23: WATER
A24: Previous Reading | B24: 257058 | C24: Present Reading | D24: 257271 | E24: Consumption m3 | F24: =D24-B24 -> 213 | G24: Consumption IG | H24: =F24*220 -> 46860
A25: Cost calculation
A26: 0-10000 @ 0.035 / IG | D26: 350
A27: 10000-20000 @ 0.04 / IG | D27: 400
A28: 20000 & above @ 0.046 / IG | D28: =(H24-20000)*0.046 -> 1235.56
A29: Fuel Surcharge @ 0.004 / IG | D29: =H24*0.004 -> 187.44
A30: Sewerage Fees | D30: =H24*0.01 -> 468.6
A31: Grand Total Exc. VAT | D31: =SUM(D26:H30) -> 2641.6
A32: LPG Gas
A33: Tank 1 (1% = 48 liters) | C33: Previous Reading % | D33: 52 | E33: Current Reading % | F33: 40 | G33: Consumption Liters | H33: =(D33-F33)*48.8 -> 585.6
A34: Tank 2 (1% = 48 liters) | C34: Previous Reading % | D34: 80 | E34: Current Reading % | F34: 80 | G34: Consumption Liters | H34: =(D34-F34)*48.8 -> 0
A35: Total Cost (@ 1.82 AED/Liter) | H35: =((H34+H33)*1.82)*0.5 -> 532.896
A36: Total Utilities | H36: =H35+D22+D9+D31 -> 16516.34

Sheet March-30
A1: Daily Utilities Consumption
A2: 30.3.2024
A3: District Cooling
A4: Previous Reading MWh | B4: 60670.58 | C4: Current Reading MWh | D4: 60688.01 | E4: Consumption MWH | F4: =D4-B4 -> 17.43 | G4: Consumption RTH | H4: =F4*284.35 -> 4956.2205
A5: Cost Calculation
A6: Total Cost (0.568/rth) | D6: =H4*0.568 -> 2815.1332
A7: Total Fuel Surchage Cost (0.075/rth) | D7: =H4*0.075 -> 371.71654
A8: Chilled Water Demand (2,866 AED/Day) | D8: 2866
A9: Grand Total Exc. VAT | D9: =SUM(D6:H8) -> 6052.8498
A10: Electrical
A11: MDB-G1 (39299675-8) | C11: Previous Reading KWH | D11: 41346 | E11: Current Reading KWH | F11: 41353 | G11: Consumption KWH | H11: =F11-D11 -> 7
A12: MDB-G2 (39299676-6) | C12: Previous Reading KWH | D12: 68433 | E12: Current Reading KWH | F12: 68446 | G12: Consumption KWH | H12: =F12-D12 -> 13
A13: MDB-G3 (39299677-4) | C13: Previous Reading KWH | D13: 69727 | E13: Current Reading KWH | F13: 69736 | G13: Consumption KWH | H13: =F13-D13 -> 9
A14: Total Consumption KWH | H14: =SUM(H11:H13) -> 29
A15: Total Consumption * Multiplication Factor (487.20) | H15: =H14*487.2 -> 14128.8
A16: Cost Calculation
A17: 0-2000 kwh @ 0.230 /KWH | D17: 460
A18: 2000-4000 kwh @ 0.280 /KWH | D18: 560
A19: 4000-6000 kwh @ 0.320 /KWH | D19: 640
A20: 6000 & above @ 0.380 /KWH | D20: =H15*0.38 -> 5368.944
A21: Fuel Surcharge @ 0.060 /KWH | D21: =H15*0.06 -> 847.728
A22: Grand Total Exc. VAT | D22: =D20+D21 -> 6216.672
A23: WATER
A24: Previous Reading | B24: 256851 | C24: Present Reading | D24: 257058 | E24: Consumption m3 | F24: =D24-B24 -> 207 | G24: Consumption IG | H24: =F24*220 -> 45540
A25: Cost calculation
A26: 0-10000 @ 0.035 / IG | D26: 350
A27: 10000-20000 @ 0.04 / IG | D27: 400
A28: 20000 & above @ 0.046 / IG | D28: =(H24-20000)*0.046 -> 1174.84
A29: Fuel Surcharge @ 0.004 / IG | D29: =H24*0.004 -> 182.16
A30: Sewerage Fees | D30: =H24*0.01 -> 455.4
A31: Grand Total Exc. VAT | D31: =SUM(D26:H30) -> 2562.4
A32: LPG Gas
A33: Tank 1 (1% = 48 liters) | C33: Previous Reading % | D33: 63 | E33: Current Reading % | F33: 52 | G33: Consumption Liters | H33: =(D33-F33)*48.8 -> 536.8
A34: Tank 2 (1% = 48 liters) | C34: Previous Reading % | D34: 80 | E34: Current Reading % | F34: 80 | G34: Consumption Liters | H34: =(D34-F34)*48.8 -> 0
A35: Total Cost (@ 1.82 AED/Liter) | H35: =((H34+H33)*1.82)*0.5 -> 488.488
A36: Total Utilities | H36: =H35+D22+D9+D31 -> 15320.41

Sheet March-29
A1: Daily Utilities Consumption
A2: 29.3.2024
A3: District Cooling
A4: Previous Reading MWh | B4: 60655.23 | C4: Current Reading MWh | D4: 60670.58 | E4: Consumption MWH | F4: =D4-B4 -> 15.35 | G4: Consumption RTH | H4: =F4*284.35 -> 4364.7725
A5: Cost Calculation
A6: Total Cost (0.568/rth) | D6: =H4*0.568 -> 2479.1908
A7: Total Fuel Surchage Cost (0.075/rth) | D7: =H4*0.075 -> 327.35794
A8: Chilled Water Demand (2,866 AED/Day) | D8: 2866
A9: Grand Total Exc. VAT | D9: =SUM(D6:H8) -> 5672.5487
A10: Electrical
A11: MDB-G1 (39299675-8) | C11: Previous Reading KWH | D11: 41339 | E11: Current Reading KWH | F11: 41346 | G11: Consumption KWH | H11: =F11-D11 -> 7
A12: MDB-G2 (39299676-6) | C12: Previous Reading KWH | D12: 68420 | E12: Current Reading KWH | F12: 68433 | G12: Consumption KWH | H12: =F12-D12 -> 13
A13: MDB-G3 (39299677-4) | C13: Previous Reading KWH | D13: 69717 | E13: Current Reading KWH | F13: 69727 | G13: Consumption KWH | H13: =F13-D13 -> 10
A14: Total Consumption KWH | H14: =SUM(H11:H13) -> 30
A15: Total Consumption * Multiplication Factor (487.20) | H15: =H14*487.2 -> 14616
A16: Cost Calculation
A17: 0-2000 kwh @ 0.230 /KWH | D17: 460
A18: 2000-4000 kwh @ 0.280 /KWH | D18: 560
A19: 4000-6000 kwh @ 0.320 /KWH | D19: 640
A20: 6000 & above @ 0.380 /KWH | D20: =H15*0.38 -> 5554.08
A21: Fuel Surcharge @ 0.060 /KWH | D21: =H15*0.06 -> 876.96
A22: Grand Total Exc. VAT | D22: =D20+D21 -> 6431.04
A23: WATER
A24: Previous Reading | B24: 256626 | C24: Present Reading | D24: 256851 | E24: Consumption m3 | F24: =D24-B24 -> 225 | G24: Consumption IG | H24: =F24*220 -> 49500
A25: Cost calculation
A26: 0-10000 @ 0.035 / IG | D26: 350
A27: 10000-20000 @ 0.04 / IG | D27: 400
A28: 20000 & above @ 0.046 / IG | D28: =(H24-20000)*0.046 -> 1357
A29: Fuel Surcharge @ 0.004 / IG | D29: =H24*0.004 -> 198
A30: Sewerage Fees | D30: =H24*0.01 -> 495
A31: Grand Total Exc. VAT | D31: =SUM(D26:H30) -> 2800
A32: LPG Gas
A33: Tank 1 (1% = 48 liters) | C33: Previous Reading % | D33: 74 | E33: Current Reading % | F33: 63 | G33: Consumption Liters | H33: =(D33-F33)*48.8 -> 536.8
A34: Tank 2 (1% = 48 liters) | C34: Previous Reading % | D34: 80 | E34: Current Reading % | F34: 80 | G34: Consumption Liters | H34: =(D34-F34)*48.8 -> 0
A35: Total Cost (@ 1.82 AED/Liter) | H35: =((H34+H33)*1.82)*0.5 -> 488.488
A36: Total Utilities | H36: =H35+D22+D9+D31 -> 15392.077

Sheet March-28
A1: Daily Utilities Consumption
A2: 28.3.2024
A3: District Cooling
A4: Previous Reading MWh | B4: 60640.04 | C4: Current Reading MWh | D4: 60655.23 | E4: Consumption MWH | F4: =D4-B4 -> 15.19 | G4: Consumption RTH | H4: =F4*284.35 -> 4319.2765
A5: Cost Calculation
A6: Total Cost (0.568/rth) | D6: =H4*0.568 -> 2453.3491
A7: Total Fuel Surchage Cost (0.075/rth) | D7: =H4*0.075 -> 323.94574
A8: Chilled Water Demand (2,866 AED/Day) | D8: 2866
A9: Grand Total Exc. VAT | D9: =SUM(D6:H8) -> 5643.2948
A10: Electrical
A11: MDB-G1 (39299675-8) | C11: Previous Reading KWH | D11: 41332 | E11: Current Reading KWH | F11: 41339 | G11: Consumption KWH | H11: =F11-D11 -> 7
A12: MDB-G2 (39299676-6) | C12: Previous Reading KWH | D12: 68407 | E12: Current Reading KWH | F12: 68420 | G12: Consumption KWH | H12: =F12-D12 -> 13
A13: MDB-G3 (39299677-4) | C13: Previous Reading KWH | D13: 69707 | E13: Current Reading KWH | F13: 69717 | G13: Consumption KWH | H13: =F13-D13 -> 10
A14: Total Consumption KWH | H14: =SUM(H11:H13) -> 30
A15: Total Consumption * Multiplication Factor (487.20) | H15: =H14*487.2 -> 14616
A16: Cost Calculation
A17: 0-2000 kwh @ 0.230 /KWH | D17: 460
A18: 2000-4000 kwh @ 0.280 /KWH | D18: 560
A19: 4000-6000 kwh @ 0.320 /KWH | D19: 640
A20: 6000 & above @ 0.380 /KWH | D20: =H15*0.38 -> 5554.08
A21: Fuel Surcharge @ 0.060 /KWH | D21: =H15*0.06 -> 876.96
A22: Grand Total Exc. VAT | D22: =D20+D21 -> 6431.04
A23: WATER
A24: Previous Reading | B24: 256423 | C24: Present Reading | D24: 256626 | E24: Consumption m3 | F24: =D24-B24 -> 203 | G24: Consumption IG | H24: =F24*220 -> 44660
A25: Cost calculation
A26: 0-10000 @ 0.035 / IG | D26: 350
A27: 10000-20000 @ 0.04 / IG | D27: 400
A28: 20000 & above @ 0.046 / IG | D28: =(H24-20000)*0.046 -> 1134.36
A29: Fuel Surcharge @ 0.004 / IG | D29: =H24*0.004 -> 178.64
A30: Sewerage Fees | D30: =H24*0.01 -> 446.6
A31: Grand Total Exc. VAT | D31: =SUM(D26:H30) -> 2509.6
A32: LPG Gas
A33: Tank 1 (1% = 48 liters) | C33: Previous Reading % | D33: 85 | E33: Current Reading % | F33: 74 | G33: Consumption Liters | H33: =(D33-F33)*48.8 -> 536.8
A34: Tank 2 (1% = 48 liters) | C34: Previous Reading % | D34: 80 | E34: Current Reading % | F34: 80 | G34: Consumption Liters | H34: =(D34-F34)*48.8 -> 0
A35: Total Cost (@ 1.82 AED/Liter) | H35: =((H34+H33)*1.82)*0.5 -> 488.488
A36: Total Utilities | H36: =H35+D22+D9+D31 -> 15072.423

Sheet March-27
A1: Daily Utilities Consumption
A2: 27.3.2024
A3: District Cooling
A4: Previous Reading MWh | B4: 60624.87 | C4: Current Reading MWh | D4: 60640.04 | E4: Consumption MWH | F4: =D4-B4 -> 15.17 | G4: Consumption RTH | H4: =F4*284.35 -> 4313.5895
A5: Cost Calculation
A6: Total Cost (0.568/rth) | D6: =H4*0.568 -> 2450.1188
A7: Total Fuel Surchage Cost (0.075/rth) | D7: =H4*0.075 -> 323.51921
A8: Chilled Water Demand (2,866 AED/Day) | D8: 2866
A9: Grand Total Exc. VAT | D9: =SUM(D6:H8) -> 5639.638
A10: Electrical
A11: MDB-G1 (39299675-8) | C11: Previous Reading KWH | D11: 41326 | E11: Current Reading KWH | F11: 41332 | G11: Consumption KWH | H11: =F11-D11 -> 6
A12: MDB-G2 (39299676-6) | C12: Previous Reading KWH | D12: 68393 | E12: Current Reading KWH | F12: 68407 | G12: Consumption KWH | H12: =F12-D12 -> 14
A13: MDB-G3 (39299677-4) | C13: Previous Reading KWH | D13: 69697 | E13: Current Reading KWH | F13: 69707 | G13: Consumption KWH | H13: =F13-D13 -> 10
A14: Total Consumption KWH | H14: =SUM(H11:H13) -> 30
A15: Total Consumption * Multiplication Factor (487.20) | H15: =H14*487.2 -> 14616
A16: Cost Calculation
A17: 0-2000 kwh @ 0.230 /KWH | D17: 460
A18: 2000-4000 kwh @ 0.280 /KWH | D18: 560
A19: 4000-6000 kwh @ 0.320 /KWH | D19: 640
A20: 6000 & above @ 0.380 /KWH | D20: =H15*0.38 -> 5554.08
A21: Fuel Surcharge @ 0.060 /KWH | D21: =H15*0.06 -> 876.96
A22: Grand Total Exc. VAT | D22: =D20+D21 -> 6431.04
A23: WATER
A24: Previous Reading | B24: 256223 | C24: Present Reading | D24: 256423 | E24: Consumption m3 | F24: =D24-B24 -> 200 | G24: Consumption IG | H24: =F24*220 -> 44000
A25: Cost calculation
A26: 0-10000 @ 0.035 / IG | D26: 350
A27: 10000-20000 @ 0.04 / IG | D27: 400
A28: 20000 & above @ 0.046 / IG | D28: =(H24-20000)*0.046 -> 1104
A29: Fuel Surcharge @ 0.004 / IG | D29: =H24*0.004 -> 176
A30: Sewerage Fees | D30: =H24*0.01 -> 440
A31: Grand Total Exc. VAT | D31: =SUM(D26:H30) -> 2470
A32: LPG Gas
A33: Tank 1 (1% = 48 liters) | C33: Previous Reading % | D33: 80 | E33: Current Reading % | F33: 69 | G33: Consumption Liters | H33: =(D33-F33)*48.8 -> 536.8
A34: Tank 2 (1% = 48 liters) | C34: Previous Reading % | D34: 20 | E34: Current Reading % | F34: 20 | G34: Consumption Liters | H34: =(D34-F34)*48.8 -> 0
A35: Total Cost (@ 1.82 AED/Liter) | H35: =((H34+H33)*1.82)*0.5 -> 488.488
A36: Total Utilities | H36: =H35+D22+D9+D31 -> 15029.166

Sheet March-26
A1: Daily Utilities Consumption
A2: 26.3.2024
A3: District Cooling
A4: Previous Reading MWh | B4: 60604.53 | C4: Current Reading MWh | D4: 60624.87 | E4: Consumption MWH | F4: =D4-B4 -> 20.34 | G4: Consumption RTH | H4: =F4*284.35 -> 5783.679
A5: Cost Calculation
A6: Total Cost (0.568/rth) | D6: =H4*0.568 -> 3285.1297
A7: Total Fuel Surchage Cost (0.075/rth) | D7: =H4*0.075 -> 433.77593
A8: Chilled Water Demand (2,866 AED/Day) | D8: 2866
A9: Grand Total Exc. VAT | D9: =SUM(D6:H8) -> 6584.9056
A10: Electrical
A11: MDB-G1 (39299675-8) | C11: Previous Reading KWH | D11: 41319 | E11: Current Reading KWH | F11: 41326 | G11: Consumption KWH | H11: =F11-D11 -> 7
A12: MDB-G2 (39299676-6) | C12: Previous Reading KWH | D12: 68380 | E12: Current Reading KWH | F12: 68393 | G12: Consumption KWH | H12: =F12-D12 -> 13
A13: MDB-G3 (39299677-4) | C13: Previous Reading KWH | D13: 69686 | E13: Current Reading KWH | F13: 69697 | G13: Consumption KWH | H13: =F13-D13 -> 11
A14: Total Consumption KWH | H14: =SUM(H11:H13) -> 31
A15: Total Consumption * Multiplication Factor (487.20) | H15: =H14*487.2 -> 15103.2
A16: Cost Calculation
A17: 0-2000 kwh @ 0.230 /KWH | D17: 460
A18: 2000-4000 kwh @ 0.280 /KWH | D18: 560
A19: 4000-6000 kwh @ 0.320 /KWH | D19: 640
A20: 6000 & above @ 0.380 /KWH | D20: =H15*0.38 -> 5739.216
A21: Fuel Surcharge @ 0.060 /KWH | D21: =H15*0.06 -> 906.192
A22: Grand Total Exc. VAT | D22: =D20+D21 -> 6645.408
A23: WATER
A24: Previous Reading | B24: 256020 | C24: Present Reading | D24: 256223 | E24: Consumption m3 | F24: =D24-B24 -> 203 | G24: Consumption IG | H24: =F24*220 -> 44660
A25: Cost calculation
A26: 0-10000 @ 0.035 / IG | D26: 350
A27: 10000-20000 @ 0.04 / IG | D27: 400
A28: 20000 & above @ 0.046 / IG | D28: =(H24-20000)*0.046 -> 1134.36
A29: Fuel Surcharge @ 0.004 / IG | D29: =H24*0.004 -> 178.64
A30: Sewerage Fees | D30: =H24*0.01 -> 446.6
A31: Grand Total Exc. VAT | D31: =SUM(D26:H30) -> 2509.6
A32: LPG Gas
A33: Tank 1 (1% = 48 liters) | C33: Previous Reading % | D33: 80 | E33: Current Reading % | F33: 80 | G33: Consumption Liters | H33: =(D33-F33)*48.8 -> 0
A34: Tank 2 (1% = 48 liters) | C34: Previous Reading % | D34: 32 | E34: Current Reading % | F34: 20 | G34: Consumption Liters | H34: =(D34-F34)*48.8 -> 585.6
A35: Total Cost (@ 1.82 AED/Liter) | H35: =((H34+H33)*1.82)*0.5 -> 532.896
A36: Total Utilities | H36: =H35+D22+D9+D31 -> 16272.81

Sheet March-25
A1: Daily Utilities Consumption
A2: 25.3.2024
A3: District Cooling
A4: Previous Reading MWh | B4: 60581.7 | C4: Current Reading MWh | D4: 60604.53 | E4: Consumption MWH | F4: =D4-B4 -> 22.83 | G4: Consumption RTH | H4: =F4*284.35 -> 6491.7105
A5: Cost Calculation
A6: Total Cost (0.568/rth) | D6: =H4*0.568 -> 3687.2916
A7: Total Fuel Surchage Cost (0.075/rth) | D7: =H4*0.075 -> 486.87829
A8: Chilled Water Demand (2,866 AED/Day) | D8: 2866
A9: Grand Total Exc. VAT | D9: =SUM(D6:H8) -> 7040.1699
A10: Electrical
A11: MDB-G1 (39299675-8) | C11: Previous Reading KWH | D11: 41312 | E11: Current Reading KWH | F11: 41319 | G11: Consumption KWH | H11: =F11-D11 -> 7
A12: MDB-G2 (39299676-6) | C12: Previous Reading KWH | D12: 68367 | E12: Current Reading KWH | F12: 68380 | G12: Consumption KWH | H12: =F12-D12 -> 13
A13: MDB-G3 (39299677-4) | C13: Previous Reading KWH | D13: 69676 | E13: Current Reading KWH | F13: 69686 | G13: Consumption KWH | H13: =F13-D13 -> 10
A14: Total Consumption KWH | H14: =SUM(H11:H13) -> 30
A15: Total Consumption * Multiplication Factor (487.20) | H15: =H14*487.2 -> 14616
A16: Cost Calculation
A17: 0-2000 kwh @ 0.230 /KWH | D17: 460
A18: 2000-4000 kwh @ 0.280 /KWH | D18: 560
A19: 4000-6000 kwh @ 0.320 /KWH | D19: 640
A20: 6000 & above @ 0.380 /KWH | D20: =H15*0.38 -> 5554.08
A21: Fuel Surcharge @ 0.060 /KWH | D21: =H15*0.06 -> 876.96
A22: Grand Total Exc. VAT | D22: =D20+D21 -> 6431.04
A23: WATER
A24: Previous Reading | B24: 255807 | C24: Present Reading | D24: 256020 | E24: Consumption m3 | F24: =D24-B24 -> 213 | G24: Consumption IG | H24: =F24*220 -> 46860
A25: Cost calculation
A26: 0-10000 @ 0.035 / IG | D26: 350
A27: 10000-20000 @ 0.04 / IG | D27: 400
A28: 20000 & above @ 0.046 / IG | D28: =(H24-20000)*0.046 -> 1235.56
A29: Fuel Surcharge @ 0.004 / IG | D29: =H24*0.004 -> 187.44
A30: Sewerage Fees | D30: =H24*0.01 -> 468.6
A31: Grand Total Exc. VAT | D31: =SUM(D26:H30) -> 2641.6
A32: LPG Gas
A33: Tank 1 (1% = 48 liters) | C33: Previous Reading % | D33: 80 | E33: Current Reading % | F33: 80 | G33: Consumption Liters | H33: =(D33-F33)*48.8 -> 0
A34: Tank 2 (1% = 48 liters) | C34: Previous Reading % | D34: 40 | E34: Current Reading % | F34: 32 | G34: Consumption Liters | H34: =(D34-F34)*48.8 -> 390.4
A35: Total Cost (@ 1.82 AED/Liter) | H35: =((H34+H33)*1.82)*0.5 -> 355.264
A36: Total Utilities | H36: =H35+D22+D9+D31 -> 16468.074

Sheet March-24
A1: Daily Utilities Consumption
A2: 24.3.2024
A3: District Cooling
A4: Previous Reading MWh | B4: 60558.88 | C4: Current Reading MWh | D4: 60581.7 | E4: Consumption MWH | F4: =D4-B4 -> 22.82 | G4: Consumption RTH | H4: =F4*284.35 -> 6488.867
A5: Cost Calculation
A6: Total Cost (0.568/rth) | D6: =H4*0.568 -> 3685.6765
A7: Total Fuel Surchage Cost (0.075/rth) | D7: =H4*0.075 -> 486.66502
A8: Chilled Water Demand (2,866 AED/Day) | D8: 2866
A9: Grand Total Exc. VAT | D9: =SUM(D6:H8) -> 7038.3415
A10: Electrical
A11: MDB-G1 (39299675-8) | C11: Previous Reading KWH | D11: 41305 | E11: Current Reading KWH | F11: 41312 | G11: Consumption KWH | H11: =F11-D11 -> 7
A12: MDB-G2 (39299676-6) | C12: Previous Reading KWH | D12: 68354 | E12: Current Reading KWH | F12: 68367 | G12: Consumption KWH | H12: =F12-D12 -> 13
A13: MDB-G3 (39299677-4) | C13: Previous Reading KWH | D13: 69666 | E13: Current Reading KWH | F13: 69676 | G13: Consumption KWH | H13: =F13-D13 -> 10
A14: Total Consumption KWH | H14: =SUM(H11:H13) -> 30
A15: Total Consumption * Multiplication Factor (487.20) | H15: =H14*487.2 -> 14616
A16: Cost Calculation
A17: 0-2000 kwh @ 0.230 /KWH | D17: 460
A18: 2000-4000 kwh @ 0.280 /KWH | D18: 560
A19: 4000-6000 kwh @ 0.320 /KWH | D19: 640
A20: 6000 & above @ 0.380 /KWH | D20: =H15*0.38 -> 5554.08
A21: Fuel Surcharge @ 0.060 /KWH | D21: =H15*0.06 -> 876.96
A22: Grand Total Exc. VAT | D22: =D20+D21 -> 6431.04
A23: WATER
A24: Previous Reading | B24: 255587 | C24: Present Reading | D24: 255807 | E24: Consumption m3 | F24: =D24-B24 -> 220 | G24: Consumption IG | H24: =F24*220 -> 48400
A25: Cost calculation
A26: 0-10000 @ 0.035 / IG | D26: 350
A27: 10000-20000 @ 0.04 / IG | D27: 400
A28: 20000 & above @ 0.046 / IG | D28: =(H24-20000)*0.046 -> 1306.4
A29: Fuel Surcharge @ 0.004 / IG | D29: =H24*0.004 -> 193.6
A30: Sewerage Fees | D30: =H24*0.01 -> 484
A31: Grand Total Exc. VAT | D31: =SUM(D26:H30) -> 2734
A32: LPG Gas
A33: Tank 1 (1% = 48 liters) | C33: Previous Reading % | D33: 80 | E33: Current Reading % | F33: 80 | G33: Consumption Liters | H33: =(D33-F33)*48.8 -> 0
A34: Tank 2 (1% = 48 liters) | C34: Previous Reading % | D34: 52 | E34: Current Reading % | F34: 40 | G34: Consumption Liters | H34: =(D34-F34)*48.8 -> 585.6
A35: Total Cost (@ 1.82 AED/Liter) | H35: =((H34+H33)*1.82)*0.5 -> 532.896
A36: Total Utilities | H36: =H35+D22+D9+D31 -> 16736.277

Sheet March-23
A1: Daily Utilities Consumption
A2: 23.3.2024
A3: District Cooling
A4: Previous Reading MWh | B4: 60536.78 | C4: Current Reading MWh | D4: 60558.88 | E4: Consumption MWH | F4: =D4-B4 -> 22.1 | G4: Consumption RTH | H4: =F4*284.35 -> 6284.135
A5: Cost Calculation
A6: Total Cost (0.568/rth) | D6: =H4*0.568 -> 3569.3887
A7: Total Fuel Surchage Cost (0.075/rth) | D7: =H4*0.075 -> 471.31012
A8: Chilled Water Demand (2,866 AED/Day) | D8: 2866
A9: Grand Total Exc. VAT | D9: =SUM(D6:H8) -> 6906.6988
A10: Electrical
A11: MDB-G1 (39299675-8) | C11: Previous Reading KWH | D11: 41298 | E11: Current Reading KWH | F11: 41305 | G11: Consumption KWH | H11: =F11-D11 -> 7
A12: MDB-G2 (39299676-6) | C12: Previous Reading KWH | D12: 68341 | E12: Current Reading KWH | F12: 68354 | G12: Consumption KWH | H12: =F12-D12 -> 13
A13: MDB-G3 (39299677-4) | C13: Previous Reading KWH | D13: 69655 | E13: Current Reading KWH | F13: 69666 | G13: Consumption KWH | H13: =F13-D13 -> 11
A14: Total Consumption KWH | H14: =SUM(H11:H13) -> 31
A15: Total Consumption * Multiplication Factor (487.20) | H15: =H14*487.2 -> 15103.2
A16: Cost Calculation
A17: 0-2000 kwh @ 0.230 /KWH | D17: 460
A18: 2000-4000 kwh @ 0.280 /KWH | D18: 560
A19: 4000-6000 kwh @ 0.320 /KWH | D19: 640
A20: 6000 & above @ 0.380 /KWH | D20: =H15*0.38 -> 5739.216
A21: Fuel Surcharge @ 0.060 /KWH | D21: =H15*0.06 -> 906.192
A22: Grand Total Exc. VAT | D22: =D20+D21 -> 6645.408
A23: WATER
A24: Previous Reading | B24: 255387 | C24: Present Reading | D24: 255587 | E24: Consumption m3 | F24: =D24-B24 -> 200 | G24: Consumption IG | H24: =F24*220 -> 44000
A25: Cost calculation
A26: 0-10000 @ 0.035 / IG | D26: 350
A27: 10000-20000 @ 0.04 / IG | D27: 400
A28: 20000 & above @ 0.046 / IG | D28: =(H24-20000)*0.046 -> 1104
A29: Fuel Surcharge @ 0.004 / IG | D29: =H24*0.004 -> 176
A30: Sewerage Fees | D30: =H24*0.01 -> 440
A31: Grand Total Exc. VAT | D31: =SUM(D26:H30) -> 2470
A32: LPG Gas
A33: Tank 1 (1% = 48 liters) | C33: Previous Reading % | D33: 80 | E33: Current Reading % | F33: 80 | G33: Consumption Liters | H33: =(D33-F33)*48.8 -> 0
A34: Tank 2 (1% = 48 liters) | C34: Previous Reading % | D34: 61 | E34: Current Reading % | F34: 52 | G34: Consumption Liters | H34: =(D34-F34)*48.8 -> 439.2
A35: Total Cost (@ 1.82 AED/Liter) | H35: =((H34+H33)*1.82)*0.5 -> 399.672
A36: Total Utilities | H36: =H35+D22+D9+D31 -> 16421.779

Sheet March-22
A1: Daily Utilities Consumption
A2: 22.3.2024
A3: District Cooling
A4: Previous Reading MWh | B4: 60515.3 | C4: Current Reading MWh | D4: 60536.78 | E4: Consumption MWH | F4: =D4-B4 -> 21.48 | G4: Consumption RTH | H4: =F4*284.35 -> 6107.838
A5: Cost Calculation
A6: Total Cost (0.568/rth) | D6: =H4*0.568 -> 3469.252
A7: Total Fuel Surchage Cost (0.075/rth) | D7: =H4*0.075 -> 458.08785
A8: Chilled Water Demand (2,866 AED/Day) | D8: 2866
A9: Grand Total Exc. VAT | D9: =SUM(D6:H8) -> 6793.3398
A10: Electrical
A11: MDB-G1 (39299675-8) | C11: Previous Reading KWH | D11: 41292 | E11: Current Reading KWH | F11: 41298 | G11: Consumption KWH | H11: =F11-D11 -> 6
A12: MDB-G2 (39299676-6) | C12: Previous Reading KWH | D12: 68328 | E12: Current Reading KWH | F12: 68341 | G12: Consumption KWH | H12: =F12-D12 -> 13
A13: MDB-G3 (39299677-4) | C13: Previous Reading KWH | D13: 69645 | E13: Current Reading KWH | F13: 69655 | G13: Consumption KWH | H13: =F13-D13 -> 10
A14: Total Consumption KWH | H14: =SUM(H11:H13) -> 29
A15: Total Consumption * Multiplication Factor (487.20) | H15: =H14*487.2 -> 14128.8
A16: Cost Calculation
A17: 0-2000 kwh @ 0.230 /KWH | D17: 460
A18: 2000-4000 kwh @ 0.280 /KWH | D18: 560
A19: 4000-6000 kwh @ 0.320 /KWH | D19: 640
A20: 6000 & above @ 0.380 /KWH | D20: =H15*0.38 -> 5368.944
A21: Fuel Surcharge @ 0.060 /KWH | D21: =H15*0.06 -> 847.728
A22: Grand Total Exc. VAT | D22: =D20+D21 -> 6216.672
A23: WATER
A24: Previous Reading | B24: 255177 | C24: Present Reading | D24: 255387 | E24: Consumption m3 | F24: =D24-B24 -> 210 | G24: Consumption IG | H24: =F24*220 -> 46200
A25: Cost calculation
A26: 0-10000 @ 0.035 / IG | D26: 350
A27: 10000-20000 @ 0.04 / IG | D27: 400
A28: 20000 & above @ 0.046 / IG | D28: =(H24-20000)*0.046 -> 1205.2
A29: Fuel Surcharge @ 0.004 / IG | D29: =H24*0.004 -> 184.8
A30: Sewerage Fees | D30: =H24*0.01 -> 462
A31: Grand Total Exc. VAT | D31: =SUM(D26:H30) -> 2602
A32: LPG Gas
A33: Tank 1 (1% = 48 liters) | C33: Previous Reading % | D33: 80 | E33: Current Reading % | F33: 80 | G33: Consumption Liters | H33: =(D33-F33)*48.8 -> 0
A34: Tank 2 (1% = 48 liters) | C34: Previous Reading % | D34: 71 | E34: Current Reading % | F34: 61 | G34: Consumption Liters | H34: =(D34-F34)*48.8 -> 488
A35: Total Cost (@ 1.82 AED/Liter) | H35: =((H34+H33)*1.82)*0.5 -> 444.08
A36: Total Utilities | H36: =H35+D22+D9+D31 -> 16056.092

Sheet March-21
A1: Daily Utilities Consumption
A2: 21.3.2024
A3: District Cooling
A4: Previous Reading MWh | B4: 60492.24 | C4: Current Reading MWh | D4: 60515.3 | E4: Consumption MWH | F4: =D4-B4 -> 23.06 | G4: Consumption RTH | H4: =F4*284.35 -> 6557.111
A5: Cost Calculation
A6: Total Cost (0.568/rth) | D6: =H4*0.568 -> 3724.439
A7: Total Fuel Surchage Cost (0.075/rth) | D7: =H4*0.075 -> 491.78333
A8: Chilled Water Demand (2,866 AED/Day) | D8: 2866
A9: Grand Total Exc. VAT | D9: =SUM(D6:H8) -> 7082.2224
A10: Electrical
A11: MDB-G1 (39299675-8) | C11: Previous Reading KWH | D11: 41285 | E11: Current Reading KWH | F11: 41292 | G11: Consumption KWH | H11: =F11-D11 -> 7
A12: MDB-G2 (39299676-6) | C12: Previous Reading KWH | D12: 68315 | E12: Current Reading KWH | F12: 68328 | G12: Consumption KWH | H12: =F12-D12 -> 13
A13: MDB-G3 (39299677-4) | C13: Previous Reading KWH | D13: 69635 | E13: Current Reading KWH | F13: 69645 | G13: Consumption KWH | H13: =F13-D13 -> 10
A14: Total Consumption KWH | H14: =SUM(H11:H13) -> 30
A15: Total Consumption * Multiplication Factor (487.20) | H15: =H14*487.2 -> 14616
A16: Cost Calculation
A17: 0-2000 kwh @ 0.230 /KWH | D17: 460
A18: 2000-4000 kwh @ 0.280 /KWH | D18: 560
A19: 4000-6000 kwh @ 0.320 /KWH | D19: 640
A20: 6000 & above @ 0.380 /KWH | D20: =H15*0.38 -> 5554.08
A21: Fuel Surcharge @ 0.060 /KWH | D21: =H15*0.06 -> 876.96
A22: Grand Total Exc. VAT | D22: =D20+D21 -> 6431.04
A23: WATER
A24: Previous Reading | B24: 254976 | C24: Present Reading | D24: 255177 | E24: Consumption m3 | F24: =D24-B24 -> 201 | G24: Consumption IG | H24: =F24*220 -> 44220
A25: Cost calculation
A26: 0-10000 @ 0.035 / IG | D26: 350
A27: 10000-20000 @ 0.04 / IG | D27: 400
A28: 20000 & above @ 0.046 / IG | D28: =(H24-20000)*0.046 -> 1114.12
A29: Fuel Surcharge @ 0.004 / IG | D29: =H24*0.004 -> 176.88
A30: Sewerage Fees | D30: =H24*0.01 -> 442.2
A31: Grand Total Exc. VAT | D31: =SUM(D26:H30) -> 2483.2
A32: LPG Gas
A33: Tank 1 (1% = 48 liters) | C33: Previous Reading % | D33: 23 | E33: Current Reading % | F33: 23 | G33: Consumption Liters | H33: =(D33-F33)*48.8 -> 0
A34: Tank 2 (1% = 48 liters) | C34: Previous Reading % | D34: 80 | E34: Current Reading % | F34: 71 | G34: Consumption Liters | H34: =(D34-F34)*48.8 -> 439.2
A35: Total Cost (@ 1.82 AED/Liter) | H35: =((H34+H33)*1.82)*0.5 -> 399.672
A36: Total Utilities | H36: =H35+D22+D9+D31 -> 16396.134

Sheet March-20
A1: Daily Utilities Consumption
A2: 20.3.2024
A3: District Cooling
A4: Previous Reading MWh | B4: 60470.39 | C4: Current Reading MWh | D4: 60492.24 | E4: Consumption MWH | F4: =D4-B4 -> 21.85 | G4: Consumption RTH | H4: =F4*284.35 -> 6213.0475
A5: Cost Calculation
A6: Total Cost (0.568/rth) | D6: =H4*0.568 -> 3529.011
A7: Total Fuel Surchage Cost (0.075/rth) | D7: =H4*0.075 -> 465.97856
A8: Chilled Water Demand (2,866 AED/Day) | D8: 2866
A9: Grand Total Exc. VAT | D9: =SUM(D6:H8) -> 6860.9895
A10: Electrical
A11: MDB-G1 (39299675-8) | C11: Previous Reading KWH | D11: 41278 | E11: Current Reading KWH | F11: 41285 | G11: Consumption KWH | H11: =F11-D11 -> 7
A12: MDB-G2 (39299676-6) | C12: Previous Reading KWH | D12: 68302 | E12: Current Reading KWH | F12: 68315 | G12: Consumption KWH | H12: =F12-D12 -> 13
A13: MDB-G3 (39299677-4) | C13: Previous Reading KWH | D13: 69626 | E13: Current Reading KWH | F13: 69635 | G13: Consumption KWH | H13: =F13-D13 -> 9
A14: Total Consumption KWH | H14: =SUM(H11:H13) -> 29
A15: Total Consumption * Multiplication Factor (487.20) | H15: =H14*487.2 -> 14128.8
A16: Cost Calculation
A17: 0-2000 kwh @ 0.230 /KWH | D17: 460
A18: 2000-4000 kwh @ 0.280 /KWH | D18: 560
A19: 4000-6000 kwh @ 0.320 /KWH | D19: 640
A20: 6000 & above @ 0.380 /KWH | D20: =H15*0.38 -> 5368.944
A21: Fuel Surcharge @ 0.060 /KWH | D21: =H15*0.06 -> 847.728
A22: Grand Total Exc. VAT | D22: =D20+D21 -> 6216.672
A23: WATER
A24: Previous Reading | B24: 254782 | C24: Present Reading | D24: 254976 | E24: Consumption m3 | F24: =D24-B24 -> 194 | G24: Consumption IG | H24: =F24*220 -> 42680
A25: Cost calculation
A26: 0-10000 @ 0.035 / IG | D26: 350
A27: 10000-20000 @ 0.04 / IG | D27: 400
A28: 20000 & above @ 0.046 / IG | D28: =(H24-20000)*0.046 -> 1043.28
A29: Fuel Surcharge @ 0.004 / IG | D29: =H24*0.004 -> 170.72
A30: Sewerage Fees | D30: =H24*0.01 -> 426.8
A31: Grand Total Exc. VAT | D31: =SUM(D26:H30) -> 2390.8
A32: LPG Gas
A33: Tank 1 (1% = 48 liters) | C33: Previous Reading % | D33: 32 | E33: Current Reading % | F33: 23 | G33: Consumption Liters | H33: =(D33-F33)*48.8 -> 439.2
A34: Tank 2 (1% = 48 liters) | C34: Previous Reading % | D34: 80 | E34: Current Reading % | F34: 80 | G34: Consumption Liters | H34: =(D34-F34)*48.8 -> 0
A35: Total Cost (@ 1.82 AED/Liter) | H35: =((H34+H33)*1.82)*0.5 -> 399.672
A36: Total Utilities | H36: =H35+D22+D9+D31 -> 15868.134

Sheet March-19
A1: Daily Utilities Consumption
A2: 19.3.2024
A3: District Cooling
A4: Previous Reading MWh | B4: 60448.64 | C4: Current Reading MWh | D4: 60470.39 | E4: Consumption MWH | F4: =D4-B4 -> 21.75 | G4: Consumption RTH | H4: =F4*284.35 -> 6184.6125
A5: Cost Calculation
A6: Total Cost (0.568/rth) | D6: =H4*0.568 -> 3512.8599
A7: Total Fuel Surchage Cost (0.075/rth) | D7: =H4*0.075 -> 463.84594
A8: Chilled Water Demand (2,866 AED/Day) | D8: 2866
A9: Grand Total Exc. VAT | D9: =SUM(D6:H8) -> 6842.7058
A10: Electrical
A11: MDB-G1 (39299675-8) | C11: Previous Reading KWH | D11: 41271 | E11: Current Reading KWH | F11: 41278 | G11: Consumption KWH | H11: =F11-D11 -> 7
A12: MDB-G2 (39299676-6) | C12: Previous Reading KWH | D12: 68290 | E12: Current Reading KWH | F12: 68302 | G12: Consumption KWH | H12: =F12-D12 -> 12
A13: MDB-G3 (39299677-4) | C13: Previous Reading KWH | D13: 69615 | E13: Current Reading KWH | F13: 69626 | G13: Consumption KWH | H13: =F13-D13 -> 11
A14: Total Consumption KWH | H14: =SUM(H11:H13) -> 30
A15: Total Consumption * Multiplication Factor (487.20) | H15: =H14*487.2 -> 14616
A16: Cost Calculation
A17: 0-2000 kwh @ 0.230 /KWH | D17: 460
A18: 2000-4000 kwh @ 0.280 /KWH | D18: 560
A19: 4000-6000 kwh @ 0.320 /KWH | D19: 640
A20: 6000 & above @ 0.380 /KWH | D20: =H15*0.38 -> 5554.08
A21: Fuel Surcharge @ 0.060 /KWH | D21: =H15*0.06 -> 876.96
A22: Grand Total Exc. VAT | D22: =D20+D21 -> 6431.04
A23: WATER
A24: Previous Reading | B24: 254584 | C24: Present Reading | D24: 254782 | E24: Consumption m3 | F24: =D24-B24 -> 198 | G24: Consumption IG | H24: =F24*220 -> 43560
A25: Cost calculation
A26: 0-10000 @ 0.035 / IG | D26: 350
A27: 10000-20000 @ 0.04 / IG | D27: 400
A28: 20000 & above @ 0.046 / IG | D28: =(H24-20000)*0.046 -> 1083.76
A29: Fuel Surcharge @ 0.004 / IG | D29: =H24*0.004 -> 174.24
A30: Sewerage Fees | D30: =H24*0.01 -> 435.6
A31: Grand Total Exc. VAT | D31: =SUM(D26:H30) -> 2443.6
A32: LPG Gas
A33: Tank 1 (1% = 48 liters) | C33: Previous Reading % | D33: 40 | E33: Current Reading % | F33: 32 | G33: Consumption Liters | H33: =(D33-F33)*48.8 -> 390.4
A34: Tank 2 (1% = 48 liters) | C34: Previous Reading % | D34: 80 | E34: Current Reading % | F34: 80 | G34: Consumption Liters | H34: =(D34-F34)*48.8 -> 0
A35: Total Cost (@ 1.82 AED/Liter) | H35: =((H34+H33)*1.82)*0.5 -> 355.264
A36: Total Utilities | H36: =H35+D22+D9+D31 -> 16072.61

Sheet March-18
A1: Daily Utilities Consumption
A2: 18.3.2024
A3: District Cooling
A4: Previous Reading MWh | B4: 60426.95 | C4: Current Reading MWh | D4: 60448.64 | E4: Consumption MWH | F4: =D4-B4 -> 21.69 | G4: Consumption RTH | H4: =F4*284.35 -> 6167.5515
A5: Cost Calculation
A6: Total Cost (0.568/rth) | D6: =H4*0.568 -> 3503.1693
A7: Total Fuel Surchage Cost (0.075/rth) | D7: =H4*0.075 -> 462.56636
A8: Chilled Water Demand (2,866 AED/Day) | D8: 2866
A9: Grand Total Exc. VAT | D9: =SUM(D6:H8) -> 6831.7356
A10: Electrical
A11: MDB-G1 (39299675-8) | C11: Previous Reading KWH | D11: 41265 | E11: Current Reading KWH | F11: 41271 | G11: Consumption KWH | H11: =F11-D11 -> 6
A12: MDB-G2 (39299676-6) | C12: Previous Reading KWH | D12: 68278 | E12: Current Reading KWH | F12: 68290 | G12: Consumption KWH | H12: =F12-D12 -> 12
A13: MDB-G3 (39299677-4) | C13: Previous Reading KWH | D13: 69605 | E13: Current Reading KWH | F13: 69615 | G13: Consumption KWH | H13: =F13-D13 -> 10
A14: Total Consumption KWH | H14: =SUM(H11:H13) -> 28
A15: Total Consumption * Multiplication Factor (487.20) | H15: =H14*487.2 -> 13641.6
A16: Cost Calculation
A17: 0-2000 kwh @ 0.230 /KWH | D17: 460
A18: 2000-4000 kwh @ 0.280 /KWH | D18: 560
A19: 4000-6000 kwh @ 0.320 /KWH | D19: 640
A20: 6000 & above @ 0.380 /KWH | D20: =H15*0.38 -> 5183.808
A21: Fuel Surcharge @ 0.060 /KWH | D21: =H15*0.06 -> 818.496
A22: Grand Total Exc. VAT | D22: =D20+D21 -> 6002.304
A23: WATER
A24: Previous Reading | B24: 254410 | C24: Present Reading | D24: 254584 | E24: Consumption m3 | F24: =D24-B24 -> 174 | G24: Consumption IG | H24: =F24*220 -> 38280
A25: Cost calculation
A26: 0-10000 @ 0.035 / IG | D26: 350
A27: 10000-20000 @ 0.04 / IG | D27: 400
A28: 20000 & above @ 0.046 / IG | D28: =(H24-20000)*0.046 -> 840.88
A29: Fuel Surcharge @ 0.004 / IG | D29: =H24*0.004 -> 153.12
A30: Sewerage Fees | D30: =H24*0.01 -> 382.8
A31: Grand Total Exc. VAT | D31: =SUM(D26:H30) -> 2126.8
A32: LPG Gas
A33: Tank 1 (1% = 48 liters) | C33: Previous Reading % | D33: 48 | E33: Current Reading % | F33: 40 | G33: Consumption Liters | H33: =(D33-F33)*48.8 -> 390.4
A34: Tank 2 (1% = 48 liters) | C34: Previous Reading % | D34: 80 | E34: Current Reading % | F34: 80 | G34: Consumption Liters | H34: =(D34-F34)*48.8 -> 0
A35: Total Cost (@ 1.82 AED/Liter) | H35: =((H34+H33)*1.82)*0.5 -> 355.264
A36: Total Utilities | H36: =H35+D22+D9+D31 -> 15316.104

Sheet March-17
A1: Daily Utilities Consumption
A2: 17.3.2024
A3: District Cooling
A4: Previous Reading MWh | B4: 60405.86 | C4: Current Reading MWh | D4: 60426.95 | E4: Consumption MWH | F4: =D4-B4 -> 21.09 | G4: Consumption RTH | H4: =F4*284.35 -> 5996.9415
A5: Cost Calculation
A6: Total Cost (0.568/rth) | D6: =H4*0.568 -> 3406.2628
A7: Total Fuel Surchage Cost (0.075/rth) | D7: =H4*0.075 -> 449.77061
A8: Chilled Water Demand (2,866 AED/Day) | D8: 2866
A9: Grand Total Exc. VAT | D9: =SUM(D6:H8) -> 6722.0334
A10: Electrical
A11: MDB-G1 (39299675-8) | C11: Previous Reading KWH | D11: 41258 | E11: Current Reading KWH | F11: 41265 | G11: Consumption KWH | H11: =F11-D11 -> 7
A12: MDB-G2 (39299676-6) | C12: Previous Reading KWH | D12: 68265 | E12: Current Reading KWH | F12: 68278 | G12: Consumption KWH | H12: =F12-D12 -> 13
A13: MDB-G3 (39299677-4) | C13: Previous Reading KWH | D13: 69594 | E13: Current Reading KWH | F13: 69605 | G13: Consumption KWH | H13: =F13-D13 -> 11
A14: Total Consumption KWH | H14: =SUM(H11:H13) -> 31
A15: Total Consumption * Multiplication Factor (487.20) | H15: =H14*487.2 -> 15103.2
A16: Cost Calculation
A17: 0-2000 kwh @ 0.230 /KWH | D17: 460
A18: 2000-4000 kwh @ 0.280 /KWH | D18: 560
A19: 4000-6000 kwh @ 0.320 /KWH | D19: 640
A20: 6000 & above @ 0.380 /KWH | D20: =H15*0.38 -> 5739.216
A21: Fuel Surcharge @ 0.060 /KWH | D21: =H15*0.06 -> 906.192
A22: Grand Total Exc. VAT | D22: =D20+D21 -> 6645.408
A23: WATER
A24: Previous Reading | B24: 254224 | C24: Present Reading | D24: 254410 | E24: Consumption m3 | F24: =D24-B24 -> 186 | G24: Consumption IG | H24: =F24*220 -> 40920
A25: Cost calculation
A26: 0-10000 @ 0.035 / IG | D26: 350
A27: 10000-20000 @ 0.04 / IG | D27: 400
A28: 20000 & above @ 0.046 / IG | D28: =(H24-20000)*0.046 -> 962.32
A29: Fuel Surcharge @ 0.004 / IG | D29: =H24*0.004 -> 163.68
A30: Sewerage Fees | D30: =H24*0.01 -> 409.2
A31: Grand Total Exc. VAT | D31: =SUM(D26:H30) -> 2285.2
A32: LPG Gas
A33: Tank 1 (1% = 48 liters) | C33: Previous Reading % | D33: 58 | E33: Current Reading % | F33: 48 | G33: Consumption Liters | H33: =(D33-F33)*48.8 -> 488
A34: Tank 2 (1% = 48 liters) | C34: Previous Reading % | D34: 80 | E34: Current Reading % | F34: 80 | G34: Consumption Liters | H34: =(D34-F34)*48.8 -> 0
A35: Total Cost (@ 1.82 AED/Liter) | H35: =((H34+H33)*1.82)*0.5 -> 444.08
A36: Total Utilities | H36: =H35+D22+D9+D31 -> 16096.721

Sheet March-16
A1: Daily Utilities Consumption
A2: 16.3.2024
A3: District Cooling
A4: Previous Reading MWh | B4: 60387.74 | C4: Current Reading MWh | D4: 60405.86 | E4: Consumption MWH | F4: =D4-B4 -> 18.12 | G4: Consumption RTH | H4: =F4*284.35 -> 5152.422
A5: Cost Calculation
A6: Total Cost (0.568/rth) | D6: =H4*0.568 -> 2926.5757
A7: Total Fuel Surchage Cost (0.075/rth) | D7: =H4*0.075 -> 386.43165
A8: Chilled Water Demand (2,866 AED/Day) | D8: 2866
A9: Grand Total Exc. VAT | D9: =SUM(D6:H8) -> 6179.0073
A10: Electrical
A11: MDB-G1 (39299675-8) | C11: Previous Reading KWH | D11: 41251 | E11: Current Reading KWH | F11: 41258 | G11: Consumption KWH | H11: =F11-D11 -> 7
A12: MDB-G2 (39299676-6) | C12: Previous Reading KWH | D12: 68252 | E12: Current Reading KWH | F12: 68265 | G12: Consumption KWH | H12: =F12-D12 -> 13
A13: MDB-G3 (39299677-4) | C13: Previous Reading KWH | D13: 69584 | E13: Current Reading KWH | F13: 69594 | G13: Consumption KWH | H13: =F13-D13 -> 10
A14: Total Consumption KWH | H14: =SUM(H11:H13) -> 30
A15: Total Consumption * Multiplication Factor (487.20) | H15: =H14*487.2 -> 14616
A16: Cost Calculation
A17: 0-2000 kwh @ 0.230 /KWH | D17: 460
A18: 2000-4000 kwh @ 0.280 /KWH | D18: 560
A19: 4000-6000 kwh @ 0.320 /KWH | D19: 640
A20: 6000 & above @ 0.380 /KWH | D20: =H15*0.38 -> 5554.08
A21: Fuel Surcharge @ 0.060 /KWH | D21: =H15*0.06 -> 876.96
A22: Grand Total Exc. VAT | D22: =D20+D21 -> 6431.04
A23: WATER
A24: Previous Reading | B24: 254043 | C24: Present Reading | D24: 254224 | E24: Consumption m3 | F24: =D24-B24 -> 181 | G24: Consumption IG | H24: =F24*220 -> 39820
A25: Cost calculation
A26: 0-10000 @ 0.035 / IG | D26: 350
A27: 10000-20000 @ 0.04 / IG | D27: 400
A28: 20000 & above @ 0.046 / IG | D28: =(H24-20000)*0.046 -> 911.72
A29: Fuel Surcharge @ 0.004 / IG | D29: =H24*0.004 -> 159.28
A30: Sewerage Fees | D30: =H24*0.01 -> 398.2
A31: Grand Total Exc. VAT | D31: =SUM(D26:H30) -> 2219.2
A32: LPG Gas
A33: Tank 1 (1% = 48 liters) | C33: Previous Reading % | D33: 66 | E33: Current Reading % | F33: 58 | G33: Consumption Liters | H33: =(D33-F33)*48.8 -> 390.4
A34: Tank 2 (1% = 48 liters) | C34: Previous Reading % | D34: 80 | E34: Current Reading % | F34: 80 | G34: Consumption Liters | H34: =(D34-F34)*48.8 -> 0
A35: Total Cost (@ 1.82 AED/Liter) | H35: =((H34+H33)*1.82)*0.5 -> 355.264
A36: Total Utilities | H36: =H35+D22+D9+D31 -> 15184.511

Sheet March-15
A1: Daily Utilities Consumption
A2: 15.3.2024
A3: District Cooling
A4: Previous Reading MWh | B4: 60370.76 | C4: Current Reading MWh | D4: 60387.74 | E4: Consumption MWH | F4: =D4-B4 -> 16.98 | G4: Consumption RTH | H4: =F4*284.35 -> 4828.263
A5: Cost Calculation
A6: Total Cost (0.568/rth) | D6: =H4*0.568 -> 2742.4534
A7: Total Fuel Surchage Cost (0.075/rth) | D7: =H4*0.075 -> 362.11972
A8: Chilled Water Demand (2,866 AED/Day) | D8: 2866
A9: Grand Total Exc. VAT | D9: =SUM(D6:H8) -> 5970.5731
A10: Electrical
A11: MDB-G1 (39299675-8) | C11: Previous Reading KWH | D11: 41245 | E11: Current Reading KWH | F11: 41251 | G11: Consumption KWH | H11: =F11-D11 -> 6
A12: MDB-G2 (39299676-6) | C12: Previous Reading KWH | D12: 68239 | E12: Current Reading KWH | F12: 68252 | G12: Consumption KWH | H12: =F12-D12 -> 13
A13: MDB-G3 (39299677-4) | C13: Previous Reading KWH | D13: 69573 | E13: Current Reading KWH | F13: 69584 | G13: Consumption KWH | H13: =F13-D13 -> 11
A14: Total Consumption KWH | H14: =SUM(H11:H13) -> 30
A15: Total Consumption * Multiplication Factor (487.20) | H15: =H14*487.2 -> 14616
A16: Cost Calculation
A17: 0-2000 kwh @ 0.230 /KWH | D17: 460
A18: 2000-4000 kwh @ 0.280 /KWH | D18: 560
A19: 4000-6000 kwh @ 0.320 /KWH | D19: 640
A20: 6000 & above @ 0.380 /KWH | D20: =H15*0.38 -> 5554.08
A21: Fuel Surcharge @ 0.060 /KWH | D21: =H15*0.06 -> 876.96
A22: Grand Total Exc. VAT | D22: =D20+D21 -> 6431.04
A23: WATER
A24: Previous Reading | B24: 253855 | C24: Present Reading | D24: 254043 | E24: Consumption m3 | F24: =D24-B24 -> 188 | G24: Consumption IG | H24: =F24*220 -> 41360
A25: Cost calculation
A26: 0-10000 @ 0.035 / IG | D26: 350
A27: 10000-20000 @ 0.04 / IG | D27: 400
A28: 20000 & above @ 0.046 / IG | D28: =(H24-20000)*0.046 -> 982.56
A29: Fuel Surcharge @ 0.004 / IG | D29: =H24*0.004 -> 165.44
A30: Sewerage Fees | D30: =H24*0.01 -> 413.6
A31: Grand Total Exc. VAT | D31: =SUM(D26:H30) -> 2311.6
A32: LPG Gas
A33: Tank 1 (1% = 48 liters) | C33: Previous Reading % | D33: 75 | E33: Current Reading % | F33: 66 | G33: Consumption Liters | H33: =(D33-F33)*48.8 -> 439.2
A34: Tank 2 (1% = 48 liters) | C34: Previous Reading % | D34: 80 | E34: Current Reading % | F34: 80 | G34: Consumption Liters | H34: =(D34-F34)*48.8 -> 0
A35: Total Cost (@ 1.82 AED/Liter) | H35: =((H34+H33)*1.82)*0.5 -> 399.672
A36: Total Utilities | H36: =H35+D22+D9+D31 -> 15112.885

Sheet March-14
A1: Daily Utilities Consumption
A2: 14.3.2024
A3: District Cooling
A4: Previous Reading MWh | B4: 60353.83 | C4: Current Reading MWh | D4: 60370.76 | E4: Consumption MWH | F4: =D4-B4 -> 16.93 | G4: Consumption RTH | H4: =F4*284.35 -> 4814.0455
A5: Cost Calculation
A6: Total Cost (0.568/rth) | D6: =H4*0.568 -> 2734.3778
A7: Total Fuel Surchage Cost (0.075/rth) | D7: =H4*0.075 -> 361.05341
A8: Chilled Water Demand (2,866 AED/Day) | D8: 2866
A9: Grand Total Exc. VAT | D9: =SUM(D6:H8) -> 5961.4313
A10: Electrical
A11: MDB-G1 (39299675-8) | C11: Previous Reading KWH | D11: 41238 | E11: Current Reading KWH | F11: 41245 | G11: Consumption KWH | H11: =F11-D11 -> 7
A12: MDB-G2 (39299676-6) | C12: Previous Reading KWH | D12: 68227 | E12: Current Reading KWH | F12: 68239 | G12: Consumption KWH | H12: =F12-D12 -> 12
A13: MDB-G3 (39299677-4) | C13: Previous Reading KWH | D13: 69563 | E13: Current Reading KWH | F13: 69573 | G13: Consumption KWH | H13: =F13-D13 -> 10
A14: Total Consumption KWH | H14: =SUM(H11:H13) -> 29
A15: Total Consumption * Multiplication Factor (487.20) | H15: =H14*487.2 -> 14128.8
A16: Cost Calculation
A17: 0-2000 kwh @ 0.230 /KWH | D17: 460
A18: 2000-4000 kwh @ 0.280 /KWH | D18: 560
A19: 4000-6000 kwh @ 0.320 /KWH | D19: 640
A20: 6000 & above @ 0.380 /KWH | D20: =H15*0.38 -> 5368.944
A21: Fuel Surcharge @ 0.060 /KWH | D21: =H15*0.06 -> 847.728
A22: Grand Total Exc. VAT | D22: =D20+D21 -> 6216.672
A23: WATER
A24: Previous Reading | B24: 253701 | C24: Present Reading | D24: 253855 | E24: Consumption m3 | F24: =D24-B24 -> 154 | G24: Consumption IG | H24: =F24*220 -> 33880
A25: Cost calculation
A26: 0-10000 @ 0.035 / IG | D26: 350
A27: 10000-20000 @ 0.04 / IG | D27: 400
A28: 20000 & above @ 0.046 / IG | D28: =(H24-20000)*0.046 -> 638.48
A29: Fuel Surcharge @ 0.004 / IG | D29: =H24*0.004 -> 135.52
A30: Sewerage Fees | D30: =H24*0.01 -> 338.8
A31: Grand Total Exc. VAT | D31: =SUM(D26:H30) -> 1862.8
A32: LPG Gas
A33: Tank 1 (1% = 48 liters) | C33: Previous Reading % | D33: 82 | E33: Current Reading % | F33: 75 | G33: Consumption Liters | H33: =(D33-F33)*48.8 -> 341.6
A34: Tank 2 (1% = 48 liters) | C34: Previous Reading % | D34: 80 | E34: Current Reading % | F34: 80 | G34: Consumption Liters | H34: =(D34-F34)*48.8 -> 0
A35: Total Cost (@ 1.82 AED/Liter) | H35: =((H34+H33)*1.82)*0.5 -> 310.856
A36: Total Utilities | H36: =H35+D22+D9+D31 -> 14351.759

Sheet March-13
A1: Daily Utilities Consumption
A2: 13.3.2024
A3: District Cooling
A4: Previous Reading MWh | B4: 60340.36 | C4: Current Reading MWh | D4: 60353.83 | E4: Consumption MWH | F4: =D4-B4 -> 13.47 | G4: Consumption RTH | H4: =F4*284.35 -> 3830.1945
A5: Cost Calculation
A6: Total Cost (0.568/rth) | D6: =H4*0.568 -> 2175.5505
A7: Total Fuel Surchage Cost (0.075/rth) | D7: =H4*0.075 -> 287.26459
A8: Chilled Water Demand (2,866 AED/Day) | D8: 2866
A9: Grand Total Exc. VAT | D9: =SUM(D6:H8) -> 5328.8151
A10: Electrical
A11: MDB-G1 (39299675-8) | C11: Previous Reading KWH | D11: 41232 | E11: Current Reading KWH | F11: 41238 | G11: Consumption KWH | H11: =F11-D11 -> 6
A12: MDB-G2 (39299676-6) | C12: Previous Reading KWH | D12: 68215 | E12: Current Reading KWH | F12: 68227 | G12: Consumption KWH | H12: =F12-D12 -> 12
A13: MDB-G3 (39299677-4) | C13: Previous Reading KWH | D13: 69554 | E13: Current Reading KWH | F13: 69563 | G13: Consumption KWH | H13: =F13-D13 -> 9
A14: Total Consumption KWH | H14: =SUM(H11:H13) -> 27
A15: Total Consumption * Multiplication Factor (487.20) | H15: =H14*487.2 -> 13154.4
A16: Cost Calculation
A17: 0-2000 kwh @ 0.230 /KWH | D17: 460
A18: 2000-4000 kwh @ 0.280 /KWH | D18: 560
A19: 4000-6000 kwh @ 0.320 /KWH | D19: 640
A20: 6000 & above @ 0.380 /KWH | D20: =H15*0.38 -> 4998.672
A21: Fuel Surcharge @ 0.060 /KWH | D21: =H15*0.06 -> 789.264
A22: Grand Total Exc. VAT | D22: =D20+D21 -> 5787.936
A23: WATER
A24: Previous Reading | B24: 253535 | C24: Present Reading | D24: 253701 | E24: Consumption m3 | F24: =D24-B24 -> 166 | G24: Consumption IG | H24: =F24*220 -> 36520
A25: Cost calculation
A26: 0-10000 @ 0.035 / IG | D26: 350
A27: 10000-20000 @ 0.04 / IG | D27: 400
A28: 20000 & above @ 0.046 / IG | D28: =(H24-20000)*0.046 -> 759.92
A29: Fuel Surcharge @ 0.004 / IG | D29: =H24*0.004 -> 146.08
A30: Sewerage Fees | D30: =H24*0.01 -> 365.2
A31: Grand Total Exc. VAT | D31: =SUM(D26:H30) -> 2021.2
A32: LPG Gas
A33: Tank 1 (1% = 48 liters) | C33: Previous Reading % | D33: 35 | E33: Current Reading % | F33: 28 | G33: Consumption Liters | H33: =(D33-F33)*48.8 -> 341.6
A34: Tank 2 (1% = 48 liters) | C34: Previous Reading % | D34: 80 | E34: Current Reading % | F34: 80 | G34: Consumption Liters | H34: =(D34-F34)*48.8 -> 0
A35: Total Cost (@ 1.82 AED/Liter) | H35: =((H34+H33)*1.82)*0.5 -> 310.856
A36: Total Utilities | H36: =H35+D22+D9+D31 -> 13448.807

Sheet March-12
A1: Daily Utilities Consumption
A2: 12.3.2024
A3: District Cooling
A4: Previous Reading MWh | B4: 60326.2 | C4: Current Reading MWh | D4: 60340.36 | E4: Consumption MWH | F4: =D4-B4 -> 14.16 | G4: Consumption RTH | H4: =F4*284.35 -> 4026.396
A5: Cost Calculation
A6: Total Cost (0.568/rth) | D6: =H4*0.568 -> 2286.9929
A7: Total Fuel Surchage Cost (0.075/rth) | D7: =H4*0.075 -> 301.9797
A8: Chilled Water Demand (2,866 AED/Day) | D8: 2866
A9: Grand Total Exc. VAT | D9: =SUM(D6:H8) -> 5454.9726
A10: Electrical
A11: MDB-G1 (39299675-8) | C11: Previous Reading KWH | D11: 41225 | E11: Current Reading KWH | F11: 41232 | G11: Consumption KWH | H11: =F11-D11 -> 7
A12: MDB-G2 (39299676-6) | C12: Previous Reading KWH | D12: 68202 | E12: Current Reading KWH | F12: 68215 | G12: Consumption KWH | H12: =F12-D12 -> 13
A13: MDB-G3 (39299677-4) | C13: Previous Reading KWH | D13: 69544 | E13: Current Reading KWH | F13: 69554 | G13: Consumption KWH | H13: =F13-D13 -> 10
A14: Total Consumption KWH | H14: =SUM(H11:H13) -> 30
A15: Total Consumption * Multiplication Factor (487.20) | H15: =H14*487.2 -> 14616
A16: Cost Calculation
A17: 0-2000 kwh @ 0.230 /KWH | D17: 460
A18: 2000-4000 kwh @ 0.280 /KWH | D18: 560
A19: 4000-6000 kwh @ 0.320 /KWH | D19: 640
A20: 6000 & above @ 0.380 /KWH | D20: =H15*0.38 -> 5554.08
A21: Fuel Surcharge @ 0.060 /KWH | D21: =H15*0.06 -> 876.96
A22: Grand Total Exc. VAT | D22: =D20+D21 -> 6431.04
A23: WATER
A24: Previous Reading | B24: 253372 | C24: Present Reading | D24: 253535 | E24: Consumption m3 | F24: =D24-B24 -> 163 | G24: Consumption IG | H24: =F24*220 -> 35860
A25: Cost calculation
A26: 0-10000 @ 0.035 / IG | D26: 350
A27: 10000-20000 @ 0.04 / IG | D27: 400
A28: 20000 & above @ 0.046 / IG | D28: =(H24-20000)*0.046 -> 729.56
A29: Fuel Surcharge @ 0.004 / IG | D29: =H24*0.004 -> 143.44
A30: Sewerage Fees | D30: =H24*0.01 -> 358.6
A31: Grand Total Exc. VAT | D31: =SUM(D26:H30) -> 1981.6
A32: LPG Gas
A33: Tank 1 (1% = 48 liters) | C33: Previous Reading % | D33: 45 | E33: Current Reading % | F33: 35 | G33: Consumption Liters | H33: =(D33-F33)*48.8 -> 488
A34: Tank 2 (1% = 48 liters) | C34: Previous Reading % | D34: 80 | E34: Current Reading % | F34: 80 | G34: Consumption Liters | H34: =(D34-F34)*48.8 -> 0
A35: Total Cost (@ 1.82 AED/Liter) | H35: =((H34+H33)*1.82)*0.5 -> 444.08
A36: Total Utilities | H36: =H35+D22+D9+D31 -> 14311.693

Sheet March-11
A1: Daily Utilities Consumption
A2: 11.3.2024
A3: District Cooling
A4: Previous Reading MWh | B4: 60312.25 | C4: Current Reading MWh | D4: 60326.2 | E4: Consumption MWH | F4: =D4-B4 -> 13.95 | G4: Consumption RTH | H4: =F4*284.35 -> 3966.6825
A5: Cost Calculation
A6: Total Cost (0.568/rth) | D6: =H4*0.568 -> 2253.0757
A7: Total Fuel Surchage Cost (0.075/rth) | D7: =H4*0.075 -> 297.50119
A8: Chilled Water Demand (2,866 AED/Day) | D8: 2866
A9: Grand Total Exc. VAT | D9: =SUM(D6:H8) -> 5416.5768
A10: Electrical
A11: MDB-G1 (39299675-8) | C11: Previous Reading KWH | D11: 41219 | E11: Current Reading KWH | F11: 41225 | G11: Consumption KWH | H11: =F11-D11 -> 6
A12: MDB-G2 (39299676-6) | C12: Previous Reading KWH | D12: 68190 | E12: Current Reading KWH | F12: 68202 | G12: Consumption KWH | H12: =F12-D12 -> 12
A13: MDB-G3 (39299677-4) | C13: Previous Reading KWH | D13: 69534 | E13: Current Reading KWH | F13: 69544 | G13: Consumption KWH | H13: =F13-D13 -> 10
A14: Total Consumption KWH | H14: =SUM(H11:H13) -> 28
A15: Total Consumption * Multiplication Factor (487.20) | H15: =H14*487.2 -> 13641.6
A16: Cost Calculation
A17: 0-2000 kwh @ 0.230 /KWH | D17: 460
A18: 2000-4000 kwh @ 0.280 /KWH | D18: 560
A19: 4000-6000 kwh @ 0.320 /KWH | D19: 640
A20: 6000 & above @ 0.380 /KWH | D20: =H15*0.38 -> 5183.808
A21: Fuel Surcharge @ 0.060 /KWH | D21: =H15*0.06 -> 818.496
A22: Grand Total Exc. VAT | D22: =D20+D21 -> 6002.304
A23: WATER
A24: Previous Reading | B24: 253210 | C24: Present Reading | D24: 253372 | E24: Consumption m3 | F24: =D24-B24 -> 162 | G24: Consumption IG | H24: =F24*220 -> 35640
A25: Cost calculation
A26: 0-10000 @ 0.035 / IG | D26: 350
A27: 10000-20000 @ 0.04 / IG | D27: 400
A28: 20000 & above @ 0.046 / IG | D28: =(H24-20000)*0.046 -> 719.44
A29: Fuel Surcharge @ 0.004 / IG | D29: =H24*0.004 -> 142.56
A30: Sewerage Fees | D30: =H24*0.01 -> 356.4
A31: Grand Total Exc. VAT | D31: =SUM(D26:H30) -> 1968.4
A32: LPG Gas
A33: Tank 1 (1% = 48 liters) | C33: Previous Reading % | D33: 55 | E33: Current Reading % | F33: 45 | G33: Consumption Liters | H33: =(D33-F33)*48.8 -> 488
A34: Tank 2 (1% = 48 liters) | C34: Previous Reading % | D34: 80 | E34: Current Reading % | F34: 80 | G34: Consumption Liters | H34: =(D34-F34)*48.8 -> 0
A35: Total Cost (@ 1.82 AED/Liter) | H35: =((H34+H33)*1.82)*0.5 -> 444.08
A36: Total Utilities | H36: =H35+D22+D9+D31 -> 13831.361

Sheet March-10
