Workbook

Sheet Total
A1: Site Name | B1: Day | C1: Month | D1: Year | E1: Total Electricity Kwh | F1: Electricity Tariff ($/Kwh) | G1: Natural Gas (m3) | H1: Natural Gas $/m3 | I1: Water Utility Supply (m3) m3 | J1: Water Utility Supply (m3) $/m3 | K1: District Energy Cooling RTH | L1: District Energy Cooling $/RTH | M1: Room Nights | N1: Total Guests
A2: Pearl Rotana Capital Centre | B2: 1 | C2: 5 | D2: 2023 | E2: =Submetering!E2+Submetering!F2+Submetering!G2 -> 14863 | F2: 0.2 | G2: =Submetering!I2+Submetering!J2 -> 28 | H2: 12.61 | I2: =Submetering!H2 -> 80 | J2: 7.84 | K2: =Submetering!K2 -> 7108.625 | L2: 1.14 | M2: ='may 23'!AD5*315 -> 222.012
A3: Pearl Rotana Capital Centre | B3: =B2+1 -> 2 | C3: 5 | D3: 2023 | E3: =Submetering!E3+Submetering!F3+Submetering!G3 -> 14969 | F3: 0.2 | G3: =Submetering!I3+Submetering!J3 -> 26 | H3: 12.61 | I3: =Submetering!H3 -> 94 | J3: 7.84 | K3: =Submetering!K3 -> 7961.66 | L3: 1.14 | M3: ='may 23'!AD6*315 -> 234.0135
A4: Pearl Rotana Capital Centre | B4: =B3+1 -> 3 | C4: 5 | D4: 2023 | E4: =Submetering!E4+Submetering!F4+Submetering!G4 -> 16164 | F4: 0.2 | G4: =Submetering!I4+Submetering!J4 -> 30 | H4: 12.61 | I4: =Submetering!H4 -> 101 | J4: 7.84 | K4: =Submetering!K4 -> 7961.66 | L4: 1.14 | M4: ='may 23'!AD7*315 -> 226.989
A5: Pearl Rotana Capital Centre | B5: =B4+1 -> 4 | C5: 5 | D5: 2023 | E5: =Submetering!E5+Submetering!F5+Submetering!G5 -> 15629 | F5: 0.2 | G5: =Submetering!I5+Submetering!J5 -> 29 | H5: 12.61 | I5: =Submetering!H5 -> 109 | J5: 7.84 | K5: =Submetering!K5 -> 6255.59 | L5: 1.14 | M5: ='may 23'!AD8*315 -> 206.9865
A6: Pearl Rotana Capital Centre | B6: =B5+1 -> 5 | C6: 5 | D6: 2023 | E6: =Submetering!E6+Submetering!F6+Submetering!G6 -> 16692 | F6: 0.2 | G6: =Submetering!I6+Submetering!J6 -> 31 | H6: 12.61 | I6: =Submetering!H6 -> 148 | J6: 7.84 | K6: =Submetering!K6 -> 9099.04 | L6: 1.14 | M6: ='may 23'!AD9*315 -> 182.007
A7: Pearl Rotana Capital Centre | B7: =B6+1 -> 6 | C7: 5 | D7: 2023 | E7: =Submetering!E7+Submetering!F7+Submetering!G7 -> 15545 | F7: 0.2 | G7: =Submetering!I7+Submetering!J7 -> 29 | H7: 12.61 | I7: =Submetering!H7 -> 97 | J7: 7.84 | K7: =Submetering!K7 -> 7677.315 | L7: 1.14 | M7: ='may 23'!AD10*315 -> 215.964
A8: Pearl Rotana Capital Centre | B8: =B7+1 -> 7 | C8: 5 | D8: 2023 | E8: =Submetering!E8+Submetering!F8+Submetering!G8 -> 15410 | F8: 0.2 | G8: =Submetering!I8+Submetering!J8 -> 28 | H8: 12.61 | I8: =Submetering!H8 -> 109 | J8: 7.84 | K8: =Submetering!K8 -> 7961.66 | L8: 1.14 | M8: ='may 23'!AD11*315 -> 273.0105
A9: Pearl Rotana Capital Centre | B9: =B8+1 -> 8 | C9: 5 | D9: 2023 | E9: =Submetering!E9+Submetering!F9+Submetering!G9 -> 15764 | F9: 0.2 | G9: =Submetering!I9+Submetering!J9 -> 30 | H9: 12.61 | I9: =Submetering!H9 -> 94 | J9: 7.84 | K9: =Submetering!K9 -> 7677.315 | L9: 1.14 | M9: ='may 23'!AD12*315 -> 315
A10: Pearl Rotana Capital Centre | B10: =B9+1 -> 9 | C10: 5 | D10: 2023 | E10: =Submetering!E10+Submetering!F10+Submetering!G10 -> 15629 | F10: 0.2 | G10: =Submetering!I10+Submetering!J10 -> 31 | H10: 12.61 | I10: =Submetering!H10 -> 101 | J10: 7.84 | K10: =Submetering!K10 -> 7677.315 | L10: 1.14 | M10: ='may 23'!AD13*315 -> 315
A11: Pearl Rotana Capital Centre | B11: =B10+1 -> 10 | C11: 5 | D11: 2023 | E11: =Submetering!E11+Submetering!F11+Submetering!G11 -> 15700 | F11: 0.2 | G11: =Submetering!I11+Submetering!J11 -> 30 | H11: 12.61 | I11: =Submetering!H11 -> 87 | J11: 7.84 | K11: =Submetering!K11 -> 7961.66 | L11: 1.14 | M11: ='may 23'!AD14*315 -> 218.988
A12: Pearl Rotana Capital Centre | B12: =B11+1 -> 11 | C12: 5 | D12: 2023 | E12: =Submetering!E12+Submetering!F12+Submetering!G12 -> 15562 | F12: 0.2 | G12: =Submetering!I12+Submetering!J12 -> 33 | H12: 12.61 | I12: =Submetering!H12 -> 91 | J12: 7.84 | K12: =Submetering!K12 -> 7392.97 | L12: 1.14 | M12: ='may 23'!AD15*315 -> 163.8
A13: Pearl Rotana Capital Centre | B13: =B12+1 -> 12 | C13: 5 | D13: 2023 | E13: =Submetering!E13+Submetering!F13+Submetering!G13 -> 15031 | F13: 0.2 | G13: =Submetering!I13+Submetering!J13 -> 32 | H13: 12.61 | I13: =Submetering!H13 -> 81 | J13: 7.84 | K13: =Submetering!K13 -> 7961.66 | L13: 1.14 | M13: ='may 23'!AD16*315 -> 140.994
A14: Pearl Rotana Capital Centre | B14: =B13+1 -> 13 | C14: 5 | D14: 2023 | E14: =Submetering!E14+Submetering!F14+Submetering!G14 -> 14772 | F14: 0.2 | G14: =Submetering!I14+Submetering!J14 -> 29 | H14: 12.61 | I14: =Submetering!H14 -> 70 | J14: 7.84 | K14: =Submetering!K14 -> 8530.35 | L14: 1.14 | M14: ='may 23'!AD17*315 -> 144.9945
... A32: Pearl Rotana Capital Centre | B32: =B31+1 -> 31 | C32: 5 | D32: 2023 | E32: =Submetering!E32+Submetering!F32+Submetering!G32 -> 15988 | F32: 2.2 | G32: =Submetering!I32+Submetering!J32 -> 28 | H32: 12.61 | I32: =Submetering!H32 -> 95 | J32: 7.84 | K32: =Submetering!K32 -> 10805.11 | L32: 1.14 | M32: ='may 23'!AD35*315 -> 198.9855

Sheet Submetering
A1: Site Name | B1: Day | C1: Month | D1: Year | E1: MDB#2 | F1: MDB#3 | G1: MDB#1 Façade | H1: Water | I1: Gas Meter#1 GF Kitchen | J1: Gas Meter#2 1st floor Kitchen | K1: District Cooling | L1: District Cooling ETS | M1: Water Main Kitchen | N1: Room Nights | O1: Total Guests
A2: Pearl Rotana Capital Centre | B2: 1 | C2: 5 | D2: 2023 | E2: ='may 23'!C5 -> 7674 | F2: ='may 23'!E5 -> 7077 | G2: ='may 23'!G5 -> 112 | H2: ='may 23'!K5 -> 80 | I2: ='may 23'!N5 -> 16 | J2: ='may 23'!P5 -> 12 | K2: ='may 23'!X5 -> 7108.625 | L2: ='may 23'!AC5 -> 8038 | M2: ='may 23'!AP5 -> 0 | N2: ='may 23'!AD5*315 -> 222.012
A3: Pearl Rotana Capital Centre | B3: =B2+1 -> 2 | C3: 5 | D3: 2023 | E3: ='may 23'!C6 -> 7803 | F3: ='may 23'!E6 -> 7055 | G3: ='may 23'!G6 -> 111 | H3: ='may 23'!K6 -> 94 | I3: ='may 23'!N6 -> 17 | J3: ='may 23'!P6 -> 9 | K3: ='may 23'!X6 -> 7961.66 | L3: ='may 23'!AC6 -> 8850 | M3: ='may 23'!AP6 -> 0 | N3: ='may 23'!AD6*315 -> 234.0135
A4: Pearl Rotana Capital Centre | B4: =B3+1 -> 3 | C4: 5 | D4: 2023 | E4: ='may 23'!C7 -> 8540 | F4: ='may 23'!E7 -> 7515 | G4: ='may 23'!G7 -> 109 | H4: ='may 23'!K7 -> 101 | I4: ='may 23'!N7 -> 18 | J4: ='may 23'!P7 -> 12 | K4: ='may 23'!X7 -> 7961.66 | L4: ='may 23'!AC7 -> 8621 | M4: ='may 23'!AP7 -> 0 | N4: ='may 23'!AD7*315 -> 226.989
A5: Pearl Rotana Capital Centre | B5: =B4+1 -> 4 | C5: 5 | D5: 2023 | E5: ='may 23'!C8 -> 8127 | F5: ='may 23'!E8 -> 7374 | G5: ='may 23'!G8 -> 128 | H5: ='may 23'!K8 -> 109 | I5: ='may 23'!N8 -> 18 | J5: ='may 23'!P8 -> 11 | K5: ='may 23'!X8 -> 6255.59 | L5: ='may 23'!AC8 -> 8424 | M5: ='may 23'!AP8 -> 0 | N5: ='may 23'!AD8*315 -> 206.9865
A6: Pearl Rotana Capital Centre | B6: =B5+1 -> 5 | C6: 5 | D6: 2023 | E6: ='may 23'!C9 -> 8888 | F6: ='may 23'!E9 -> 7711 | G6: ='may 23'!G9 -> 93 | H6: ='may 23'!K9 -> 148 | I6: ='may 23'!N9 -> 18 | J6: ='may 23'!P9 -> 13 | K6: ='may 23'!X9 -> 9099.04 | L6: ='may 23'!AC9 -> 8500 | M6: ='may 23'!AP9 -> 0 | N6: ='may 23'!AD9*315 -> 182.007
A7: Pearl Rotana Capital Centre | B7: =B6+1 -> 6 | C7: 5 | D7: 2023 | E7: ='may 23'!C10 -> 8197 | F7: ='may 23'!E10 -> 7239 | G7: ='may 23'!G10 -> 109 | H7: ='may 23'!K10 -> 97 | I7: ='may 23'!N10 -> 18 | J7: ='may 23'!P10 -> 11 | K7: ='may 23'!X10 -> 7677.315 | L7: ='may 23'!AC10 -> 8166 | M7: ='may 23'!AP10 -> 0 | N7: ='may 23'!AD10*315 -> 215.964
A8: Pearl Rotana Capital Centre | B8: =B7+1 -> 7 | C8: 5 | D8: 2023 | E8: ='may 23'!C11 -> 7984 | F8: ='may 23'!E11 -> 7317 | G8: ='may 23'!G11 -> 109 | H8: ='may 23'!K11 -> 109 | I8: ='may 23'!N11 -> 18 | J8: ='may 23'!P11 -> 10 | K8: ='may 23'!X11 -> 7961.66 | L8: ='may 23'!AC11 -> 8571 | M8: ='may 23'!AP11 -> 0 | N8: ='may 23'!AD11*315 -> 273.0105
A9: Pearl Rotana Capital Centre | B9: =B8+1 -> 8 | C9: 5 | D9: 2023 | E9: ='may 23'!C12 -> 8304 | F9: ='may 23'!E12 -> 7346 | G9: ='may 23'!G12 -> 114 | H9: ='may 23'!K12 -> 94 | I9: ='may 23'!N12 -> 19 | J9: ='may 23'!P12 -> 11 | K9: ='may 23'!X12 -> 7677.315 | L9: ='may 23'!AC12 -> 8705 | M9: ='may 23'!AP12 -> 0 | N9: ='may 23'!AD12*315 -> 315
A10: Pearl Rotana Capital Centre | B10: =B9+1 -> 9 | C10: 5 | D10: 2023 | E10: ='may 23'!C13 -> 8166 | F10: ='may 23'!E13 -> 7348 | G10: ='may 23'!G13 -> 115 | H10: ='may 23'!K13 -> 101 | I10: ='may 23'!N13 -> 18 | J10: ='may 23'!P13 -> 13 | K10: ='may 23'!X13 -> 7677.315 | L10: ='may 23'!AC13 -> 8746 | M10: ='may 23'!AP13 -> 0 | N10: ='may 23'!AD13*315 -> 315
A11: Pearl Rotana Capital Centre | B11: =B10+1 -> 10 | C11: 5 | D11: 2023 | E11: ='may 23'!C14 -> 8113 | F11: ='may 23'!E14 -> 7474 | G11: ='may 23'!G14 -> 113 | H11: ='may 23'!K14 -> 87 | I11: ='may 23'!N14 -> 19 | J11: ='may 23'!P14 -> 11 | K11: ='may 23'!X14 -> 7961.66 | L11: ='may 23'!AC14 -> 9010 | M11: ='may 23'!AP14 -> 0 | N11: ='may 23'!AD14*315 -> 218.988
A12: Pearl Rotana Capital Centre | B12: =B11+1 -> 11 | C12: 5 | D12: 2023 | E12: ='may 23'!C15 -> 8099 | F12: ='may 23'!E15 -> 7349 | G12: ='may 23'!G15 -> 114 | H12: ='may 23'!K15 -> 91 | I12: ='may 23'!N15 -> 18 | J12: ='may 23'!P15 -> 15 | K12: ='may 23'!X15 -> 7392.97 | L12: ='may 23'!AC15 -> 8520 | M12: ='may 23'!AP15 -> 0 | N12: ='may 23'!AD15*315 -> 163.8
A13: Pearl Rotana Capital Centre | B13: =B12+1 -> 12 | C13: 5 | D13: 2023 | E13: ='may 23'!C16 -> 7923 | F13: ='may 23'!E16 -> 6993 | G13: ='may 23'!G16 -> 115 | H13: ='may 23'!K16 -> 81 | I13: ='may 23'!N16 -> 20 | J13: ='may 23'!P16 -> 12 | K13: ='may 23'!X16 -> 7961.66 | L13: ='may 23'!AC16 -> 8809 | M13: ='may 23'!AP16 -> 0 | N13: ='may 23'!AD16*315 -> 140.994
A14: Pearl Rotana Capital Centre | B14: =B13+1 -> 13 | C14: 5 | D14: 2023 | E14: ='may 23'!C17 -> 7781 | F14: ='may 23'!E17 -> 6877 | G14: ='may 23'!G17 -> 114 | H14: ='may 23'!K17 -> 70 | I14: ='may 23'!N17 -> 19 | J14: ='may 23'!P17 -> 10 | K14: ='may 23'!X17 -> 8530.35 | L14: ='may 23'!AC17 -> 9300 | M14: ='may 23'!AP17 -> 0 | N14: ='may 23'!AD17*315 -> 144.9945
... A32: Pearl Rotana Capital Centre | B32: =B31+1 -> 31 | C32: 5 | D32: 2023 | E32: ='may 23'!C35 -> 8214 | F32: ='may 23'!E35 -> 7670 | G32: ='may 23'!G35 -> 104 | H32: ='may 23'!K35 -> 95 | I32: ='may 23'!N35 -> 18 | J32: ='may 23'!P35 -> 10 | K32: ='may 23'!X35 -> 10805.11 | L32: ='may 23'!AC35 -> 12284 | M32: ='may 23'!AP35 -> 0 | N32: ='may 23'!AD35*315 -> 198.9855

Sheet may 23
A1: PEARL ROTANA CAPITAL CENTRE UTILITIES CONSUMPTION MAY 2023
A2: DATE | B2: Electricity | J2: Water | M2: SNG Gas | V2: District Cooling | AD2: Additional Info
B3: MDB #2 | D3: MDB #3 | F3: MDB #1 Façade | H3: Total ELE Cons. KW | I3: Electricity AED | J3: Hotel Reading | K3: Water Cons. M3 | L3: Water AED | M3: Gas Meter #1 G Floor Kitchen | O3: Gas Meter #2 1st Floor Kitchen | Q3: Total Gas Cons. M3 | R3: PRS Meter Reading | S3: PRS Meter Cons. M3 | T3: Meter factor (1.05570) | U3: Gas AED | V3: Hotel BTU Meter Energy Reading | W3: District Cooling Cons. MWH | X3: District Cooling Cons. Ton Hour | Y3: District Cooling Cons. AED | Z3: District Cooling Fixed Charge | AA3: District Cooling Total AED | AB3: ETS Energy Meter Reading | AD3: Hotel Occupancy % | AE3: Adl. & Chl.
B4: Reading | C4: Cons. | D4: Reading | E4: Cons. | F4: Reading | G4: Cons. | M4: Reading | N4: Cons. | O4: Reading | P4: Cons.
A5: 45047 | B5: 16273359 | C5: 7674 | D5: 17470804 | E5: 7077 | F5: 410787 | G5: 112 | H5: =C5+E5+G5 -> 14863 | I5: =H5*0.2 -> 2972.6 | J5: 45167 | K5: 80 | L5: =K5*7.84 -> 627.2 | M5: 28926 | N5: 16 | O5: 15867 | P5: 12 | Q5: =N5+P5 -> 28 | R5: 41101 | S5: 29 | T5: =S5*1.0557 -> 30.6153 | U5: =IF(ISBLANK(M5),"0",T5*11.05+209.6774) -> 547.97647 | V5: 57069 | W5: 25 | X5: =IF(ISBLANK(V5),"0 ",W5*284.345) -> 7108.625 | Y5: =X5*0.3435 -> 2441.8127 | Z5: =IF(ISBLANK(V5),"0",1570*1487.37/12/31*0.65) -> 4080.2717 | AA5: =Y5+Z5 -> 6522.0844 | AB5: 2680415 | AC5: 8038 | AD5: 0.7048 | AE5: 285
A6: 45048 | B6: 16281162 | C6: =IF(ISBLANK(B6),"0",B6-B5) -> 7803 | D6: 17477859 | E6: =IF(ISBLANK(D6),"0",D6-D5) -> 7055 | F6: 410898 | G6: =IF(ISBLANK(F6),"0",F6-F5) -> 111 | H6: =C6+E6+G6 -> 14969 | I6: =H6*0.2 -> 2993.8 | J6: 45261 | K6: =IF(ISBLANK(J6),"0",J6-J5) -> 94 | L6: =K6*7.84 -> 736.96 | M6: 28943 | N6: =IF(ISBLANK(M6),"0",M6-M5) -> 17 | O6: 15876 | P6: =IF(ISBLANK(O6),"0",O6-O5) -> 9 | Q6: =N6+P6 -> 26 | R6: 41126 | S6: =IF(ISBLANK(R6),"0",R6-R5) -> 25 | T6: =S6*1.0557 -> 26.3925 | U6: =IF(ISBLANK(M6),"0",T6*11.05+209.6774) -> 501.31453 | V6: 57097 | W6: =IF(ISBLANK(V6)," ",V6-V5) -> 28 | X6: =IF(ISBLANK(V6),"0 ",W6*284.345) -> 7961.66 | Y6: =X6*0.3435 -> 2734.8302 | Z6: =IF(ISBLANK(V6),"0",1570*1487.37/12/31*0.65) -> 4080.2717 | AA6: =Y6+Z6 -> 6815.1019 | AB6: 2689265 | AC6: =IF(ISBLANK(AB6)," ",AB6-AB5) -> 8850 | AD6: 0.7429 | AE6: 283
A7: 45049 | B7: 16289702 | C7: =IF(ISBLANK(B7),"0",B7-B6) -> 8540 | D7: 17485374 | E7: =IF(ISBLANK(D7),"0",D7-D6) -> 7515 | F7: 411007 | G7: =IF(ISBLANK(F7),"0",F7-F6) -> 109 | H7: =C7+E7+G7 -> 16164 | I7: =H7*0.2 -> 3232.8 | J7: 45362 | K7: =IF(ISBLANK(J7),"0",J7-J6) -> 101 | L7: =K7*7.84 -> 791.84 | M7: 28961 | N7: =IF(ISBLANK(M7),"0",M7-M6) -> 18 | O7: 15888 | P7: =IF(ISBLANK(O7),"0",O7-O6) -> 12 | Q7: =N7+P7 -> 30 | R7: 41155 | S7: =IF(ISBLANK(R7),"0",R7-R6) -> 29 | T7: =S7*1.0557 -> 30.6153 | U7: =IF(ISBLANK(M7),"0",T7*11.05+209.6774) -> 547.97647 | V7: 57125 | W7: =IF(ISBLANK(V7)," ",V7-V6) -> 28 | X7: =IF(ISBLANK(V7),"0 ",W7*284.345) -> 7961.66 | Y7: =X7*0.3435 -> 2734.8302 | Z7: =IF(ISBLANK(V7),"0",1570*1487.37/12/31*0.65) -> 4080.2717 | AA7: =Y7+Z7 -> 6815.1019 | AB7: 2697886 | AC7: =IF(ISBLANK(AB7)," ",AB7-AB6) -> 8621 | AD7: 0.7206 | AE7: 283
A8: 45050 | B8: 16297829 | C8: =IF(ISBLANK(B8),"0",B8-B7) -> 8127 | D8: 17492748 | E8: =IF(ISBLANK(D8),"0",D8-D7) -> 7374 | F8: 411135 | G8: =IF(ISBLANK(F8),"0",F8-F7) -> 128 | H8: =C8+E8+G8 -> 15629 | I8: =H8*0.2 -> 3125.8 | J8: 45471 | K8: =IF(ISBLANK(J8),"0",J8-J7) -> 109 | L8: =K8*7.84 -> 854.56 | M8: 28979 | N8: =IF(ISBLANK(M8),"0",M8-M7) -> 18 | O8: 15899 | P8: =IF(ISBLANK(O8),"0",O8-O7) -> 11 | Q8: =N8+P8 -> 29 | R8: 41184 | S8: =IF(ISBLANK(R8),"0",R8-R7) -> 29 | T8: =S8*1.0557 -> 30.6153 | U8: =IF(ISBLANK(M8),"0",T8*11.05+209.6774) -> 547.97647 | V8: 57147 | W8: =IF(ISBLANK(V8)," ",V8-V7) -> 22 | X8: =IF(ISBLANK(V8),"0 ",W8*284.345) -> 6255.59 | Y8: =X8*0.3435 -> 2148.7952 | Z8: =IF(ISBLANK(V8),"0",1570*1487.37/12/31*0.65) -> 4080.2717 | AA8: =Y8+Z8 -> 6229.0669 | AB8: 2706310 | AC8: =IF(ISBLANK(AB8)," ",AB8-AB7) -> 8424 | AD8: 0.6571 | AE8: 271
A9: 45051 | B9: 16306717 | C9: =IF(ISBLANK(B9),"0",B9-B8) -> 8888 | D9: 17500459 | E9: =IF(ISBLANK(D9),"0",D9-D8) -> 7711 | F9: 411228 | G9: =IF(ISBLANK(F9),"0",F9-F8) -> 93 | H9: =C9+E9+G9 -> 16692 | I9: =H9*0.2 -> 3338.4 | J9: 45619 | K9: =IF(ISBLANK(J9),"0",J9-J8) -> 148 | L9: =K9*7.84 -> 1160.32 | M9: 28997 | N9: =IF(ISBLANK(M9),"0",M9-M8) -> 18 | O9: 15912 | P9: =IF(ISBLANK(O9),"0",O9-O8) -> 13 | Q9: =N9+P9 -> 31 | R9: 41214 | S9: =IF(ISBLANK(R9),"0",R9-R8) -> 30 | T9: =S9*1.0557 -> 31.671 | U9: =IF(ISBLANK(M9),"0",T9*11.05+209.6774) -> 559.64195 | V9: 57179 | W9: =IF(ISBLANK(V9)," ",V9-V8) -> 32 | X9: =IF(ISBLANK(V9),"0 ",W9*284.345) -> 9099.04 | Y9: =X9*0.3435 -> 3125.5202 | Z9: =IF(ISBLANK(V9),"0",1570*1487.37/12/31*0.65) -> 4080.2717 | AA9: =Y9+Z9 -> 7205.792 | AB9: 2714810 | AC9: =IF(ISBLANK(AB9)," ",AB9-AB8) -> 8500 | AD9: 0.5778 | AE9: 178
A10: 45052 | B10: 16314914 | C10: =IF(ISBLANK(B10),"0",B10-B9) -> 8197 | D10: 17507698 | E10: =IF(ISBLANK(D10),"0",D10-D9) -> 7239 | F10: 411337 | G10: =IF(ISBLANK(F10),"0",F10-F9) -> 109 | H10: =C10+E10+G10 -> 15545 | I10: =H10*0.2 -> 3109 | J10: 45716 | K10: =IF(ISBLANK(J10),"0",J10-J9) -> 97 | L10: =K10*7.84 -> 760.48 | M10: 29015 | N10: =IF(ISBLANK(M10),"0",M10-M9) -> 18 | O10: 15923 | P10: =IF(ISBLANK(O10),"0",O10-O9) -> 11 | Q10: =N10+P10 -> 29 | R10: 41242 | S10: =IF(ISBLANK(R10),"0",R10-R9) -> 28 | T10: =S10*1.0557 -> 29.5596 | U10: =IF(ISBLANK(M10),"0",T10*11.05+209.6774) -> 536.31098 | V10: 57206 | W10: =IF(ISBLANK(V10)," ",V10-V9) -> 27 | X10: =IF(ISBLANK(V10),"0 ",W10*284.345) -> 7677.315 | Y10: =X10*0.3435 -> 2637.1577 | Z10: =IF(ISBLANK(V10),"0",1570*1487.37/12/31*0.65) -> 4080.2717 | AA10: =Y10+Z10 -> 6717.4294 | AB10: 2722976 | AC10: =IF(ISBLANK(AB10)," ",AB10-AB9) -> 8166 | AD10: 0.6856 | AE10: 281
A11: 45053 | B11: 16322898 | C11: =IF(ISBLANK(B11),"0",B11-B10) -> 7984 | D11: 17515015 | E11: =IF(ISBLANK(D11),"0",D11-D10) -> 7317 | F11: 411446 | G11: =IF(ISBLANK(F11),"0",F11-F10) -> 109 | H11: =C11+E11+G11 -> 15410 | I11: =H11*0.2 -> 3082 | J11: 45825 | K11: =IF(ISBLANK(J11),"0",J11-J10) -> 109 | L11: =K11*7.84 -> 854.56 | M11: 29033 | N11: =IF(ISBLANK(M11),"0",M11-M10) -> 18 | O11: 15933 | P11: =IF(ISBLANK(O11),"0",O11-O10) -> 10 | Q11: =N11+P11 -> 28 | R11: 41270 | S11: =IF(ISBLANK(R11),"0",R11-R10) -> 28 | T11: =S11*1.0557 -> 29.5596 | U11: =IF(ISBLANK(M11),"0",T11*11.05+209.6774) -> 536.31098 | V11: 57234 | W11: =IF(ISBLANK(V11)," ",V11-V10) -> 28 | X11: =IF(ISBLANK(V11),"0 ",W11*284.345) -> 7961.66 | Y11: =X11*0.3435 -> 2734.8302 | Z11: =IF(ISBLANK(V11),"0",1570*1487.37/12/31*0.65) -> 4080.2717 | AA11: =Y11+Z11 -> 6815.1019 | AB11: 2731547 | AC11: =IF(ISBLANK(AB11)," ",AB11-AB10) -> 8571 | AD11: 0.8667 | AE11: 315
A12: 45054 | B12: 16331202 | C12: =IF(ISBLANK(B12),"0",B12-B11) -> 8304 | D12: 17522361 | E12: =IF(ISBLANK(D12),"0",D12-D11) -> 7346 | F12: 411560 | G12: =IF(ISBLANK(F12),"0",F12-F11) -> 114 | H12: =C12+E12+G12 -> 15764 | I12: =H12*0.2 -> 3152.8 | J12: 45919 | K12: =IF(ISBLANK(J12),"0",J12-J11) -> 94 | L12: =K12*7.84 -> 736.96 | M12: 29052 | N12: =IF(ISBLANK(M12),"0",M12-M11) -> 19 | O12: 15944 | P12: =IF(ISBLANK(O12),"0",O12-O11) -> 11 | Q12: =N12+P12 -> 30 | R12: 41300 | S12: =IF(ISBLANK(R12),"0",R12-R11) -> 30 | T12: =S12*1.0557 -> 31.671 | U12: =IF(ISBLANK(M12),"0",T12*11.05+209.6774) -> 559.64195 | V12: 57261 | W12: =IF(ISBLANK(V12)," ",V12-V11) -> 27 | X12: =IF(ISBLANK(V12),"0 ",W12*284.345) -> 7677.315 | Y12: =X12*0.3435 -> 2637.1577 | Z12: =IF(ISBLANK(V12),"0",1570*1487.37/12/31*0.65) -> 4080.2717 | AA12: =Y12+Z12 -> 6717.4294 | AB12: 2740252 | AC12: =IF(ISBLANK(AB12)," ",AB12-AB11) -> 8705 | AD12: 1 | AE12: 354
A13: 45055 | B13: 16339368 | C13: =IF(ISBLANK(B13),"0",B13-B12) -> 8166 | D13: 17529709 | E13: =IF(ISBLANK(D13),"0",D13-D12) -> 7348 | F13: 411675 | G13: =IF(ISBLANK(F13),"0",F13-F12) -> 115 | H13: =C13+E13+G13 -> 15629 | I13: =H13*0.2 -> 3125.8 | J13: 46020 | K13: =IF(ISBLANK(J13),"0",J13-J12) -> 101 | L13: =K13*7.84 -> 791.84 | M13: 29070 | N13: =IF(ISBLANK(M13),"0",M13-M12) -> 18 | O13: 15957 | P13: =IF(ISBLANK(O13),"0",O13-O12) -> 13 | Q13: =N13+P13 -> 31 | R13: 41331 | S13: =IF(ISBLANK(R13),"0",R13-R12) -> 31 | T13: =S13*1.0557 -> 32.7267 | U13: =IF(ISBLANK(M13),"0",T13*11.05+209.6774) -> 571.30744 | V13: 57288 | W13: =IF(ISBLANK(V13)," ",V13-V12) -> 27 | X13: =IF(ISBLANK(V13),"0 ",W13*284.345) -> 7677.315 | Y13: =X13*0.3435 -> 2637.1577 | Z13: =IF(ISBLANK(V13),"0",1570*1487.37/12/31*0.65) -> 4080.2717 | AA13: =Y13+Z13 -> 6717.4294 | AB13: 2748998 | AC13: =IF(ISBLANK(AB13)," ",AB13-AB12) -> 8746 | AD13: 1 | AE13: 357
A14: 45056 | B14: 16347481 | C14: =IF(ISBLANK(B14),"0",B14-B13) -> 8113 | D14: 17537183 | E14: =IF(ISBLANK(D14),"0",D14-D13) -> 7474 | F14: 411788 | G14: =IF(ISBLANK(F14),"0",F14-F13) -> 113 | H14: =C14+E14+G14 -> 15700 | I14: =H14*0.2 -> 3140 | J14: 46107 | K14: =IF(ISBLANK(J14),"0",J14-J13) -> 87 | L14: =K14*7.84 -> 682.08 | M14: 29089 | N14: =IF(ISBLANK(M14),"0",M14-M13) -> 19 | O14: 15968 | P14: =IF(ISBLANK(O14),"0",O14-O13) -> 11 | Q14: =N14+P14 -> 30 | R14: 41360 | S14: =IF(ISBLANK(R14),"0",R14-R13) -> 29 | T14: =S14*1.0557 -> 30.6153 | U14: =IF(ISBLANK(M14),"0",T14*11.05+209.6774) -> 547.97647 | V14: 57316 | W14: =IF(ISBLANK(V14)," ",V14-V13) -> 28 | X14: =IF(ISBLANK(V14),"0 ",W14*284.345) -> 7961.66 | Y14: =X14*0.3435 -> 2734.8302 | Z14: =IF(ISBLANK(V14),"0",1570*1487.37/12/31*0.65) -> 4080.2717 | AA14: =Y14+Z14 -> 6815.1019 | AB14: 2758008 | AC14: =IF(ISBLANK(AB14)," ",AB14-AB13) -> 9010 | AD14: 0.6952 | AE14: 248
A15: 45057 | B15: 16355580 | C15: =IF(ISBLANK(B15),"0",B15-B14) -> 8099 | D15: 17544532 | E15: =IF(ISBLANK(D15),"0",D15-D14) -> 7349 | F15: 411902 | G15: =IF(ISBLANK(F15),"0",F15-F14) -> 114 | H15: =C15+E15+G15 -> 15562 | I15: =H15*0.2 -> 3112.4 | J15: 46198 | K15: =IF(ISBLANK(J15),"0",J15-J14) -> 91 | L15: =K15*7.84 -> 713.44 | M15: 29107 | N15: =IF(ISBLANK(M15),"0",M15-M14) -> 18 | O15: 15983 | P15: =IF(ISBLANK(O15),"0",O15-O14) -> 15 | Q15: =N15+P15 -> 33 | R15: 41393 | S15: =IF(ISBLANK(R15),"0",R15-R14) -> 33 | T15: =S15*1.0557 -> 34.8381 | U15: =IF(ISBLANK(M15),"0",T15*11.05+209.6774) -> 594.63841 | V15: 57342 | W15: =IF(ISBLANK(V15)," ",V15-V14) -> 26 | X15: =IF(ISBLANK(V15),"0 ",W15*284.345) -> 7392.97 | Y15: =X15*0.3435 -> 2539.4852 | Z15: =IF(ISBLANK(V15),"0",1570*1487.37/12/31*0.65) -> 4080.2717 | AA15: =Y15+Z15 -> 6619.7569 | AB15: 2766528 | AC15: =IF(ISBLANK(AB15)," ",AB15-AB14) -> 8520 | AD15: 0.52 | AE15: 199
A16: 45058 | B16: 16363503 | C16: =IF(ISBLANK(B16),"0",B16-B15) -> 7923 | D16: 17551525 | E16: =IF(ISBLANK(D16),"0",D16-D15) -> 6993 | F16: 412017 | G16: =IF(ISBLANK(F16),"0",F16-F15) -> 115 | H16: =C16+E16+G16 -> 15031 | I16: =H16*0.2 -> 3006.2 | J16: 46279 | K16: =IF(ISBLANK(J16),"0",J16-J15) -> 81 | L16: =K16*7.84 -> 635.04 | M16: 29127 | N16: =IF(ISBLANK(M16),"0",M16-M15) -> 20 | O16: 15995 | P16: =IF(ISBLANK(O16),"0",O16-O15) -> 12 | Q16: =N16+P16 -> 32 | R16: 41425 | S16: =IF(ISBLANK(R16),"0",R16-R15) -> 32 | T16: =S16*1.0557 -> 33.7824 | U16: =IF(ISBLANK(M16),"0",T16*11.05+209.6774) -> 582.97292 | V16: 57370 | W16: =IF(ISBLANK(V16)," ",V16-V15) -> 28 | X16: =IF(ISBLANK(V16),"0 ",W16*284.345) -> 7961.66 | Y16: =X16*0.3435 -> 2734.8302 | Z16: =IF(ISBLANK(V16),"0",1570*1487.37/12/31*0.65) -> 4080.2717 | AA16: =Y16+Z16 -> 6815.1019 | AB16: 2775337 | AC16: =IF(ISBLANK(AB16)," ",AB16-AB15) -> 8809 | AD16: 0.4476 | AE16: 184
A17: 45059 | B17: 16371284 | C17: =IF(ISBLANK(B17),"0",B17-B16) -> 7781 | D17: 17558402 | E17: =IF(ISBLANK(D17),"0",D17-D16) -> 6877 | F17: 412131 | G17: =IF(ISBLANK(F17),"0",F17-F16) -> 114 | H17: =C17+E17+G17 -> 14772 | I17: =H17*0.2 -> 2954.4 | J17: 46349 | K17: =IF(ISBLANK(J17),"0",J17-J16) -> 70 | L17: =K17*7.84 -> 548.8 | M17: 29146 | N17: =IF(ISBLANK(M17),"0",M17-M16) -> 19 | O17: 16005 | P17: =IF(ISBLANK(O17),"0",O17-O16) -> 10 | Q17: =N17+P17 -> 29 | R17: 41454 | S17: =IF(ISBLANK(R17),"0",R17-R16) -> 29 | T17: =S17*1.0557 -> 30.6153 | U17: =IF(ISBLANK(M17),"0",T17*11.05+209.6774) -> 547.97647 | V17: 57400 | W17: =IF(ISBLANK(V17)," ",V17-V16) -> 30 | X17: =IF(ISBLANK(V17),"0 ",W17*284.345) -> 8530.35 | Y17: =X17*0.3435 -> 2930.1752 | Z17: =IF(ISBLANK(V17),"0",1570*1487.37/12/31*0.65) -> 4080.2717 | AA17: =Y17+Z17 -> 7010.447 | AB17: 2784637 | AC17: =IF(ISBLANK(AB17)," ",AB17-AB16) -> 9300 | AD17: 0.4603 | AE17: 180
... A20: 45062 | B20: 16395671 | C20: =IF(ISBLANK(B20),"0",B20-B19) -> 8393 | D20: 17580216 | E20: =IF(ISBLANK(D20),"0",D20-D19) -> 7422 | F20: 412472 | G20: =IF(ISBLANK(F20),"0",F20-F19) -> 115 | H20: =C20+E20+G20 -> 15930 | I20: =H20*0.2 -> 3186 | J20: 46601 | K20: =IF(ISBLANK(J20),"0",J20-J19) -> 84 | L20: =K20*7.84 -> 658.56 | M20: 29203 | N20: =IF(ISBLANK(M20),"0",M20-M19) -> 19 | O20: 16044 | P20: =IF(ISBLANK(O20),"0",O20-O19) -> 15 | Q20: =N20+P20 -> 34 | R20: 41549 | S20: =IF(ISBLANK(R20),"0",R20-R19) -> 33 | T20: =S20*1.0557 -> 34.8381 | U20: =IF(ISBLANK(M20),"0",T20*11.05+209.6774) -> 594.63841 | V20: 57490 | W20: =IF(ISBLANK(V20)," ",V20-V19) -> 31 | X20: =IF(ISBLANK(V20),"0 ",W20*284.345) -> 8814.695 | Y20: =X20*0.3435 -> 3027.8477 | Z20: =IF(ISBLANK(V20),"0",1570*1487.37/12/31*0.65) -> 4080.2717 | AA20: =Y20+Z20 -> 7108.1195 | AB20: 2813316 | AC20: =IF(ISBLANK(AB20)," ",AB20-AB19) -> 9798 | AD20: 0.8794 | AE20: 291
A21: 45063 | B21: 16403808 | C21: =IF(ISBLANK(B21),"0",B21-B20) -> 8137 | D21: 17587482 | E21: =IF(ISBLANK(D21),"0",D21-D20) -> 7266 | F21: 412588 | G21: =IF(ISBLANK(F21),"0",F21-F20) -> 116 | H21: =C21+E21+G21 -> 15519 | I21: =H21*0.2 -> 3103.8 | J21: 46697 | K21: =IF(ISBLANK(J21),"0",J21-J20) -> 96 | L21: =K21*7.84 -> 752.64 | M21: 29220 | N21: =IF(ISBLANK(M21),"0",M21-M20) -> 17 | O21: 16061 | P21: =IF(ISBLANK(O21),"0",O21-O20) -> 17 | Q21: =N21+P21 -> 34 | R21: 41583 | S21: =IF(ISBLANK(R21),"0",R21-R20) -> 34 | T21: =S21*1.0557 -> 35.8938 | U21: =IF(ISBLANK(M21),"0",T21*11.05+209.6774) -> 606.30389 | V21: 57520 | W21: =IF(ISBLANK(V21)," ",V21-V20) -> 30 | X21: =IF(ISBLANK(V21),"0 ",W21*284.345) -> 8530.35 | Y21: =X21*0.3435 -> 2930.1752 | Z21: =IF(ISBLANK(V21),"0",1570*1487.37/12/31*0.65) -> 4080.2717 | AA21: =Y21+Z21 -> 7010.447 | AB21: 2823518 | AC21: 10202 | AD21: 0.7778 | AE21: 260
A22: 45064 | B22: 16411865 | C22: =IF(ISBLANK(B22),"0",B22-B21) -> 8057 | D22: 17594939 | E22: =IF(ISBLANK(D22),"0",D22-D21) -> 7457 | F22: 412700 | G22: 112 | H22: =C22+E22+G22 -> 15626 | I22: =H22*0.2 -> 3125.2 | J22: 46780 | K22: =IF(ISBLANK(J22),"0",J22-J21) -> 83 | L22: =K22*7.84 -> 650.72 | M22: 29238 | N22: =IF(ISBLANK(M22),"0",M22-M21) -> 18 | O22: 16075 | P22: =IF(ISBLANK(O22),"0",O22-O21) -> 14 | Q22: =N22+P22 -> 32 | R22: 41615 | S22: =IF(ISBLANK(R22),"0",R22-R21) -> 32 | T22: =S22*1.0557 -> 33.7824 | U22: =IF(ISBLANK(M22),"0",T22*11.05+209.6774) -> 582.97292 | V22: 57550 | W22: =IF(ISBLANK(V22)," ",V22-V21) -> 30 | X22: =IF(ISBLANK(V22),"0 ",W22*284.345) -> 8530.35 | Y22: =X22*0.3435 -> 2930.1752 | Z22: =IF(ISBLANK(V22),"0",1570*1487.37/12/31*0.65) -> 4080.2717 | AA22: =Y22+Z22 -> 7010.447 | AB22: 2832637 | AC22: =IF(ISBLANK(AB22)," ",AB22-AB21) -> 9119 | AD22: 0.7778 | AE22: 260
A23: 45065 | B23: 16419749 | C23: =IF(ISBLANK(B23),"0",B23-B22) -> 7884 | D23: 17602154 | E23: =IF(ISBLANK(D23),"0",D23-D22) -> 7215 | F23: 412812 | G23: =IF(ISBLANK(F23),"0",F23-F22) -> 112 | H23: =C23+E23+G23 -> 15211 | I23: =H23*0.2 -> 3042.2 | J23: 46863 | K23: =IF(ISBLANK(J23),"0",J23-J22) -> 83 | L23: =K23*7.84 -> 650.72 | M23: 29256 | N23: =IF(ISBLANK(M23),"0",M23-M22) -> 18 | O23: 16087 | P23: =IF(ISBLANK(O23),"0",O23-O22) -> 12 | Q23: =N23+P23 -> 30 | R23: 41645 | S23: =IF(ISBLANK(R23),"0",R23-R22) -> 30 | T23: =S23*1.0557 -> 31.671 | U23: =IF(ISBLANK(M23),"0",T23*11.05+209.6774) -> 559.64195 | V23: 57580 | W23: =IF(ISBLANK(V23)," ",V23-V22) -> 30 | X23: =IF(ISBLANK(V23),"0 ",W23*284.345) -> 8530.35 | Y23: =X23*0.3435 -> 2930.1752 | Z23: =IF(ISBLANK(V23),"0",1570*1487.37/12/31*0.65) -> 4080.2717 | AA23: =Y23+Z23 -> 7010.447 | AB23: 2842392 | AC23: =IF(ISBLANK(AB23)," ",AB23-AB22) -> 9755 | AD23: 0.5143 | AE23: 204
A24: 45066 | B24: 16427913 | C24: =IF(ISBLANK(B24),"0",B24-B23) -> 8164 | D24: 17609602 | E24: =IF(ISBLANK(D24),"0",D24-D23) -> 7448 | F24: 412920 | G24: 108 | H24: =C24+E24+G24 -> 15720 | I24: =H24*0.2 -> 3144 | J24: 46944 | K24: =IF(ISBLANK(J24),"0",J24-J23) -> 81 | L24: =K24*7.84 -> 635.04 | M24: 29274 | N24: =IF(ISBLANK(M24),"0",M24-M23) -> 18 | O24: 16097 | P24: =IF(ISBLANK(O24),"0",O24-O23) -> 10 | Q24: =N24+P24 -> 28 | R24: 41674 | S24: =IF(ISBLANK(R24),"0",R24-R23) -> 29 | T24: =S24*1.0557 -> 30.6153 | U24: =IF(ISBLANK(M24),"0",T24*11.05+209.6774) -> 547.97647 | V24: 57612 | W24: =IF(ISBLANK(V24)," ",V24-V23) -> 32 | X24: =IF(ISBLANK(V24),"0 ",W24*284.345) -> 9099.04 | Y24: =X24*0.3435 -> 3125.5202 | Z24: =IF(ISBLANK(V24),"0",1570*1487.37/12/31*0.65) -> 4080.2717 | AA24: =Y24+Z24 -> 7205.792 | AB24: 2852062 | AC24: =IF(ISBLANK(AB24)," ",AB24-AB23) -> 9670 | AD24: 0.5524 | AE24: 224
A25: 45067 | B25: 16435909 | C25: =IF(ISBLANK(B25),"0",B25-B24) -> 7996 | D25: 17617096 | E25: =IF(ISBLANK(D25),"0",D25-D24) -> 7494 | F25: 413031 | G25: =IF(ISBLANK(F25),"0",F25-F24) -> 111 | H25: =C25+E25+G25 -> 15601 | I25: =H25*0.2 -> 3120.2 | J25: 47033 | K25: =IF(ISBLANK(J25),"0",J25-J24) -> 89 | L25: =K25*7.84 -> 697.76 | M25: 29290 | N25: =IF(ISBLANK(M25),"0",M25-M24) -> 16 | O25: 16110 | P25: =IF(ISBLANK(O25),"0",O25-O24) -> 13 | Q25: =N25+P25 -> 29 | R25: 41698 | S25: =IF(ISBLANK(R25),"0",R25-R24) -> 24 | T25: =S25*1.0557 -> 25.3368 | U25: =IF(ISBLANK(M25),"0",T25*11.05+209.6774) -> 489.64904 | V25: 57642 | W25: =IF(ISBLANK(V25)," ",V25-V24) -> 30 | X25: =IF(ISBLANK(V25),"0 ",W25*284.345) -> 8530.35 | Y25: =X25*0.3435 -> 2930.1752 | Z25: =IF(ISBLANK(V25),"0",1570*1487.37/12/31*0.65) -> 4080.2717 | AA25: =Y25+Z25 -> 7010.447 | AB25: 2861761 | AC25: =IF(ISBLANK(AB25)," ",AB25-AB24) -> 9699 | AD25: 0.7048 | AE25: 251
A26: 45068 | B26: 16443900 | C26: =IF(ISBLANK(B26),"0",B26-B25) -> 7991 | D26: 17624689 | E26: =IF(ISBLANK(D26),"0",D26-D25) -> 7593 | F26: 413144 | G26: =IF(ISBLANK(F26),"0",F26-F25) -> 113 | H26: =C26+E26+G26 -> 15697 | I26: =H26*0.2 -> 3139.4 | J26: 47104 | K26: =IF(ISBLANK(J26),"0",J26-J25) -> 71 | L26: =K26*7.84 -> 556.64 | M26: 29307 | N26: =IF(ISBLANK(M26),"0",M26-M25) -> 17 | O26: 16123 | P26: =IF(ISBLANK(O26),"0",O26-O25) -> 13 | Q26: =N26+P26 -> 30 | R26: 41728 | S26: =IF(ISBLANK(R26),"0",R26-R25) -> 30 | T26: =S26*1.0557 -> 31.671 | U26: =IF(ISBLANK(M26),"0",T26*11.05+209.6774) -> 559.64195 | V26: 57674 | W26: =IF(ISBLANK(V26)," ",V26-V25) -> 32 | X26: =IF(ISBLANK(V26),"0 ",W26*284.345) -> 9099.04 | Y26: =X26*0.3435 -> 3125.5202 | Z26: =IF(ISBLANK(V26),"0",1570*1487.37/12/31*0.65) -> 4080.2717 | AA26: =Y26+Z26 -> 7205.792 | AB26: 2872154 | AC26: =IF(ISBLANK(AB26)," ",AB26-AB25) -> 10393 | AD26: 0.8286 | AE26: 293
A27: 45069 | B27: 16452018 | C27: =IF(ISBLANK(B27),"0",B27-B26) -> 8118 | D27: 17632270 | E27: =IF(ISBLANK(D27),"0",D27-D26) -> 7581 | F27: 413258 | G27: =IF(ISBLANK(F27),"0",F27-F26) -> 114 | H27: =C27+E27+G27 -> 15813 | I27: =H27*0.2 -> 3162.6 | J27: 47193 | K27: =IF(ISBLANK(J27),"0",J27-J26) -> 89 | L27: =K27*7.84 -> 697.76 | M27: 29325 | N27: =IF(ISBLANK(M27),"0",M27-M26) -> 18 | O27: 16138 | P27: =IF(ISBLANK(O27),"0",O27-O26) -> 15 | Q27: =N27+P27 -> 33 | R27: 41761 | S27: =IF(ISBLANK(R27),"0",R27-R26) -> 33 | T27: =S27*1.0557 -> 34.8381 | U27: =IF(ISBLANK(M27),"0",T27*11.05+209.6774) -> 594.63841 | V27: 57706 | W27: =IF(ISBLANK(V27)," ",V27-V26) -> 32 | X27: =IF(ISBLANK(V27),"0 ",W27*284.345) -> 9099.04 | Y27: =X27*0.3435 -> 3125.5202 | Z27: =IF(ISBLANK(V27),"0",1570*1487.37/12/31*0.65) -> 4080.2717 | AA27: =Y27+Z27 -> 7205.792 | AB27: 2882708 | AC27: =IF(ISBLANK(AB27)," ",AB27-AB26) -> 10554 | AD27: 0.9556 | AE27: 346
A28: 45070 | B28: 16460091 | C28: =IF(ISBLANK(B28),"0",B28-B27) -> 8073 | D28: 17639886 | E28: =IF(ISBLANK(D28),"0",D28-D27) -> 7616 | F28: 413371 | G28: =IF(ISBLANK(F28),"0",F28-F27) -> 113 | H28: =C28+E28+G28 -> 15802 | I28: =H28*0.2 -> 3160.4 | J28: 47290 | K28: =IF(ISBLANK(J28),"0",J28-J27) -> 97 | L28: =K28*7.84 -> 760.48 | M28: 29343 | N28: =IF(ISBLANK(M28),"0",M28-M27) -> 18 | O28: 16156 | P28: =IF(ISBLANK(O28),"0",O28-O27) -> 18 | Q28: =N28+P28 -> 36 | R28: 41796 | S28: =IF(ISBLANK(R28),"0",R28-R27) -> 35 | T28: =S28*1.0557 -> 36.9495 | U28: =IF(ISBLANK(M28),"0",T28*11.05+209.6774) -> 617.96938 | V28: 57737 | W28: =IF(ISBLANK(V28)," ",V28-V27) -> 31 | X28: =IF(ISBLANK(V28),"0 ",W28*284.345) -> 8814.695 | Y28: =X28*0.3435 -> 3027.8477 | Z28: =IF(ISBLANK(V28),"0",1570*1487.37/12/31*0.65) -> 4080.2717 | AA28: =Y28+Z28 -> 7108.1195 | AB28: 2892940 | AC28: =IF(ISBLANK(AB28)," ",AB28-AB27) -> 10232 | AD28: 0.946 | AE28: 338
A29: 45071 | B29: 16468451 | C29: =IF(ISBLANK(B29),"0",B29-B28) -> 8360 | D29: 17647769 | E29: =IF(ISBLANK(D29),"0",D29-D28) -> 7883 | F29: 413484 | G29: =IF(ISBLANK(F29),"0",F29-F28) -> 113 | H29: =C29+E29+G29 -> 16356 | I29: =H29*0.2 -> 3271.2 | J29: 47395 | K29: =IF(ISBLANK(J29),"0",J29-J28) -> 105 | L29: =K29*7.84 -> 823.2 | M29: 29361 | N29: =IF(ISBLANK(M29),"0",M29-M28) -> 18 | O29: 16170 | P29: =IF(ISBLANK(O29),"0",O29-O28) -> 14 | Q29: =N29+P29 -> 32 | R29: 41828 | S29: =IF(ISBLANK(R29),"0",R29-R28) -> 32 | T29: =S29*1.0557 -> 33.7824 | U29: =IF(ISBLANK(M29),"0",T29*11.05+209.6774) -> 582.97292 | V29: 57769 | W29: =IF(ISBLANK(V29)," ",V29-V28) -> 32 | X29: =IF(ISBLANK(V29),"0 ",W29*284.345) -> 9099.04 | Y29: =X29*0.3435 -> 3125.5202 | Z29: =IF(ISBLANK(V29),"0",1570*1487.37/12/31*0.65) -> 4080.2717 | AA29: =Y29+Z29 -> 7205.792 | AB29: 2903504 | AC29: =IF(ISBLANK(AB29)," ",AB29-AB28) -> 10564 | AD29: 0.9778 | AE29: 354
A30: 45072 | B30: 16476651 | C30: =IF(ISBLANK(B30),"0",B30-B29) -> 8200 | D30: 17655445 | E30: =IF(ISBLANK(D30),"0",D30-D29) -> 7676 | F30: 413598 | G30: =IF(ISBLANK(F30),"0",F30-F29) -> 114 | H30: =C30+E30+G30 -> 15990 | I30: =H30*0.2 -> 3198 | J30: 47494 | K30: =IF(ISBLANK(J30),"0",J30-J29) -> 99 | L30: =K30*7.84 -> 776.16 | M30: 29380 | N30: =IF(ISBLANK(M30),"0",M30-M29) -> 19 | O30: 16184 | P30: =IF(ISBLANK(O30),"0",O30-O29) -> 14 | Q30: =N30+P30 -> 33 | R30: 41862 | S30: =IF(ISBLANK(R30),"0",R30-R29) -> 34 | T30: =S30*1.0557 -> 35.8938 | U30: =IF(ISBLANK(M30),"0",T30*11.05+209.6774) -> 606.30389 | V30: 57802 | W30: =IF(ISBLANK(V30)," ",V30-V29) -> 33 | X30: =IF(ISBLANK(V30),"0 ",W30*284.345) -> 9383.385 | Y30: =X30*0.3435 -> 3223.1927 | Z30: =IF(ISBLANK(V30),"0",1570*1487.37/12/31*0.65) -> 4080.2717 | AA30: =Y30+Z30 -> 7303.4645 | AB30: 2913858 | AC30: =IF(ISBLANK(AB30)," ",AB30-AB29) -> 10354 | AD30: 0.8 | AE30: 215
A31: 45073 | B31: 16484912 | C31: =IF(ISBLANK(B31),"0",B31-B30) -> 8261 | D31: 17663194 | E31: =IF(ISBLANK(D31),"0",D31-D30) -> 7749 | F31: 413715 | G31: =IF(ISBLANK(F31),"0",F31-F30) -> 117 | H31: =C31+E31+G31 -> 16127 | I31: =H31*0.2 -> 3225.4 | J31: 47596 | K31: =IF(ISBLANK(J31),"0",J31-J30) -> 102 | L31: =K31*7.84 -> 799.68 | M31: 29398 | N31: =IF(ISBLANK(M31),"0",M31-M30) -> 18 | O31: 16199 | P31: =IF(ISBLANK(O31),"0",O31-O30) -> 15 | Q31: =N31+P31 -> 33 | R31: 41895 | S31: =IF(ISBLANK(R31),"0",R31-R30) -> 33 | T31: =S31*1.0557 -> 34.8381 | U31: =IF(ISBLANK(M31),"0",T31*11.05+209.6774) -> 594.63841 | V31: 57835 | W31: =IF(ISBLANK(V31)," ",V31-V30) -> 33 | X31: =IF(ISBLANK(V31),"0 ",W31*284.345) -> 9383.385 | Y31: =X31*0.3435 -> 3223.1927 | Z31: =IF(ISBLANK(V31),"0",1570*1487.37/12/31*0.65) -> 4080.2717 | AA31: =Y31+Z31 -> 7303.4645 | AB31: 2924320 | AC31: =IF(ISBLANK(AB31)," ",AB31-AB30) -> 10462 | AD31: 0.8606 | AE31: 334
A32: 45074 | B32: 16493026 | C32: =IF(ISBLANK(B32),"0",B32-B31) -> 8114 | D32: 17670761 | E32: =IF(ISBLANK(D32),"0",D32-D31) -> 7567 | F32: 413822 | G32: =IF(ISBLANK(F32),"0",F32-F31) -> 107 | H32: =C32+E32+G32 -> 15788 | I32: =H32*0.2 -> 3157.6 | J32: 47696 | K32: =IF(ISBLANK(J32),"0",J32-J31) -> 100 | L32: =K32*7.84 -> 784 | M32: 29416 | N32: =IF(ISBLANK(M32),"0",M32-M31) -> 18 | O32: 16212 | P32: =IF(ISBLANK(O32),"0",O32-O31) -> 13 | Q32: =N32+P32 -> 31 | R32: 41925 | S32: =IF(ISBLANK(R32),"0",R32-R31) -> 30 | T32: =S32*1.0557 -> 31.671 | U32: =IF(ISBLANK(M32),"0",T32*11.05+209.6774) -> 559.64195 | V32: 57869 | W32: =IF(ISBLANK(V32)," ",V32-V31) -> 34 | X32: =IF(ISBLANK(V32),"0 ",W32*284.345) -> 9667.73 | Y32: =X32*0.3435 -> 3320.8653 | Z32: =IF(ISBLANK(V32),"0",1570*1487.37/12/31*0.65) -> 4080.2717 | AA32: =Y32+Z32 -> 7401.137 | AB32: 2934286 | AC32: =IF(ISBLANK(AB32)," ",AB32-AB31) -> 9966 | AD32: 0.819 | AE32: 323
A33: 45075 | B33: 16501213 | C33: =IF(ISBLANK(B33),"0",B33-B32) -> 8187 | D33: 17678482 | E33: =IF(ISBLANK(D33),"0",D33-D32) -> 7721 | F33: 413929 | G33: =IF(ISBLANK(F33),"0",F33-F32) -> 107 | H33: =C33+E33+G33 -> 16015 | I33: =H33*0.2 -> 3203 | J33: 47790 | K33: =IF(ISBLANK(J33),"0",J33-J32) -> 94 | L33: =K33*7.84 -> 736.96 | M33: 29435 | N33: =IF(ISBLANK(M33),"0",M33-M32) -> 19 | O33: 16225 | P33: =IF(ISBLANK(O33),"0",O33-O32) -> 13 | Q33: =N33+P33 -> 32 | R33: 41957 | S33: =IF(ISBLANK(R33),"0",R33-R32) -> 32 | T33: =S33*1.0557 -> 33.7824 | U33: =IF(ISBLANK(M33),"0",T33*11.05+209.6774) -> 582.97292 | V33: 57900 | W33: =IF(ISBLANK(V33)," ",V33-V32) -> 31 | X33: =IF(ISBLANK(V33),"0 ",W33*284.345) -> 8814.695 | Y33: =X33*0.3435 -> 3027.8477 | Z33: =IF(ISBLANK(V33),"0",1570*1487.37/12/31*0.65) -> 4080.2717 | AA33: =Y33+Z33 -> 7108.1195 | AB33: 2945286 | AC33: =IF(ISBLANK(AB33)," ",AB33-AB32) -> 11000 | AD33: 0.7492 | AE33: 295
A34: 45076 | B34: 16509383 | C34: 8170 | D34: 17686054 | E34: =IF(ISBLANK(D34),"0",D34-D33) -> 7572 | F34: 414036 | G34: =IF(ISBLANK(F34),"0",F34-F33) -> 107 | H34: =C34+E34+G34 -> 15849 | I34: =H34*0.2 -> 3169.8 | J34: 47878 | K34: =IF(ISBLANK(J34),"0",J34-J33) -> 88 | L34: =K34*7.84 -> 689.92 | M34: 29453 | N34: =IF(ISBLANK(M34),"0",M34-M33) -> 18 | O34: 16238 | P34: =IF(ISBLANK(O34),"0",O34-O33) -> 13 | Q34: =N34+P34 -> 31 | R34: 41989 | S34: =IF(ISBLANK(R34),"0",R34-R33) -> 32 | T34: =S34*1.0557 -> 33.7824 | U34: =IF(ISBLANK(M34),"0",T34*11.05+209.6774) -> 582.97292 | V34: 57938 | W34: =IF(ISBLANK(V34)," ",V34-V33) -> 38 | X34: =IF(ISBLANK(V34),"0 ",W34*284.345) -> 10805.11 | Y34: =X34*0.3435 -> 3711.5553 | Z34: =IF(ISBLANK(V34),"0",1570*1487.37/12/31*0.65) -> 4080.2717 | AA34: =Y34+Z34 -> 7791.827 | AB34: 2957515 | AC34: =IF(ISBLANK(AB34)," ",AB34-AB33) -> 12229 | AD34: 0.781 | AE34: 307
A35: 45077 | B35: 16517597 | C35: =IF(ISBLANK(B35),"0",B35-B34) -> 8214 | D35: 17693724 | E35: =IF(ISBLANK(D35),"0",D35-D34) -> 7670 | F35: 414140 | G35: =IF(ISBLANK(F35),"0",F35-F34) -> 104 | H35: =C35+E35+G35 -> 15988 | I35: =H35*0.2 -> 3197.6 | J35: 47973 | K35: =IF(ISBLANK(J35),"0",J35-J34) -> 95 | L35: =K35*7.84 -> 744.8 | M35: 29471 | N35: =IF(ISBLANK(M35),"0",M35-M34) -> 18 | O35: 16248 | P35: =IF(ISBLANK(O35),"0",O35-O34) -> 10 | Q35: =N35+P35 -> 28 | R35: 42017 | S35: =IF(ISBLANK(R35),"0",R35-R34) -> 28 | T35: =S35*1.0557 -> 29.5596 | U35: =IF(ISBLANK(M35),"0",T35*11.05+209.6774) -> 536.31098 | V35: 57976 | W35: =IF(ISBLANK(V35)," ",V35-V34) -> 38 | X35: =IF(ISBLANK(V35),"0 ",W35*284.345) -> 10805.11 | Y35: =X35*0.3435 -> 3711.5553 | Z35: =IF(ISBLANK(V35),"0",1570*1487.37/12/31*0.65) -> 4080.2717 | AA35: =Y35+Z35 -> 7791.827 | AB35: 2969799 | AC35: =IF(ISBLANK(AB35)," ",AB35-AB34) -> 12284 | AD35: 0.6317 | AE35: 241
C36: =SUM(C5:C35) -> 251912 | E36: =SUM(E5:E35) -> 229997 | G36: =SUM(G5:G35) -> 3465 | H36: =SUM(H5:H35) -> 485374 | I36: =H36*0.2 -> 97074.8 | K36: =SUM(K5:K35) -> 2886 | L36: =K36*7.84 -> 22626.24 | N36: =SUM(N5:N35) -> 561 | P36: =SUM(P5:P35) -> 393 | Q36: =SUM(Q5:Q35) -> 954 | S36: =SUM(S5:S35) -> 945 | T36: =SUM(T5:T35) -> 997.6365 | U36: =SUM(U5:U35) -> 17523.883 | W36: =SUM(W5:W35) -> 932 | X36: =SUM(X5:X35) -> 265009.54 | Y36: =SUM(Y5:Y35) -> 91030.777 | Z36: =SUM(Z5:Z35) -> 126488.42 | AA36: =SUM(AA5:AA35) -> 217519.2 | AC36: =SUM(AC5:AC35) -> 297422 | AD36: =AVERAGE(AD5:AD35) -> 0.75380323 | AE36: =SUM(AE5:AE35) -> 8527
V37: AVT Charges should be Zero in the DC invoice - Please notify if not
B38: Electricity | D38: AED | G38: KW | J38: Water | L38: AED | M38: M3 | O38: Gas | R38: AED | T38: M3 | V38: Chilled Water | X38: AED | Z38: Ton Hour
B39: Actual May 2023 | D39: =I36 -> 97074.8 | G39: =D39/0.2 -> 485374 | J39: =B39 -> Actual May 2023 | L39: =L36 -> 22626.24 | M39: =K36 -> 2886 | O39: =B39 -> Actual May 2023 | R39: =U36 -> 17523.883 | T39: =T36 -> 997.6365 | V39: =B39 -> Actual May 2023 | X39: =AA36 -> 217519.2 | Z39: =X36 -> 265009.54 | AD39: =AC36 -> 297422 | AE39: =AD39-X36 -> 32412.46
B40: Budget May 2023 | D40: 97405.875 | G40: =D40/0.2 -> 487029.38 | J40: =B40 -> Budget May 2023 | L40: 22754.13 | M40: =L40/7.84 -> 2902.3125 | O40: =B40 -> Budget May 2023 | R40: 18049.513 | T40: =(R40-6500)/11.05 -> 1045.2048 | V40: =B40 -> Budget May 2023 | X40: 208877.22 | Z40: =AG40/0.3435 -> 239853.19 | AG40: =X40-126487.65 -> 82389.571 | AH40: CHW Consumption Charges (Budgeted 2023 MTD)
B41: Actual May 2022 | D41: 96266 | G41: =D41/0.2 -> 481330 | J41: =B41 -> Actual May 2022 | L41: 21388 | M41: =L41/7.84 -> 2728.0612 | O41: =B41 -> Actual May 2022 | R41: 17215.34 | T41: =(R41-6500)/11.05 -> 969.71403 | V41: =B41 -> Actual May 2022 | X41: 199844.26 | Z41: =AG41/0.3428 -> 228184.13 | AG41: =X41-121622.74 -> 78221.52 | AH41: CHW Consumption Charges (Actual 2022 MTD)
B42: Actual YTD 2023 | D42: =D39+369445.4 -> 466520.2 | G42: =D42/0.2 -> 2332601 | J42: =B42 -> Actual YTD 2023 | L42: =L39+84875.84 -> 107502.08 | M42: =L42/7.84 -> 13712 | O42: =B42 -> Actual YTD 2023 | R42: =R39+64267.32 -> 81791.203 | T42: =(R42-6500*5)/11.05 -> 4460.7423 | V42: =B42 -> Actual YTD 2023 | X42: =X39+712572.77 -> 930091.97 | Z42: =AG42/0.3435 -> 866531.94 | AG42: =X42-AG46 -> 297653.72 | AH42: CHW Consumption Charges (Actual 2023 YTD)
...
