Workbook

Sheet Total
A1: Site Name | B1: Day | C1: Month | D1: Year | E1: Total Electricity Kwh | F1: Electricity Tariff ($/Kwh) | G1: Natural Gas (m3) | H1: Natural Gas $/m3 | I1: Water Utility Supply (m3) m3 | J1: Water Utility Supply (m3) $/m3 | K1: District Energy Cooling RTH | L1: District Energy Cooling $/RTH | M1: Room Nights | N1: Total Guests
A2: Pearl Rotana Capital Centre | B2: 1 | C2: 3 | D2: 2024 | E2: =Submetering!E2+Submetering!F2+Submetering!G2 -> 14062 | F2: 0.2 | G2: ='Mar 2024'!T5 -> 35.8938 | H2: 17.295121 | I2: ='Mar 2024'!K5 -> 105 | J2: 7.84 | K2: ='Mar 2024'!X5 -> 3980.83 | L2: 1.4101717 | M2: ='Mar 2024'!AD5*315 -> 234.0135
A3: Pearl Rotana Capital Centre | B3: =B2+1 -> 2 | C3: 3 | D3: 2024 | E3: =Submetering!E3+Submetering!F3+Submetering!G3 -> 14707 | F3: 0.2 | G3: ='Mar 2024'!T6 -> 35.8938 | H3: 17.295121 | I3: ='Mar 2024'!K6 -> 102 | J3: 7.84 | K3: ='Mar 2024'!X6 -> 4265.175 | L3: 1.3391069 | M3: ='Mar 2024'!AD6*315 -> 194.0085
A4: Pearl Rotana Capital Centre | B4: =B3+1 -> 3 | C4: 3 | D4: 2024 | E4: =Submetering!E4+Submetering!F4+Submetering!G4 -> 14190 | F4: 0.2 | G4: ='Mar 2024'!T7 -> 32.7267 | H4: 17.295121 | I4: ='Mar 2024'!K7 -> 109 | J4: 7.84 | K4: ='Mar 2024'!X7 -> 4265.175 | L4: 1.3391069 | M4: ='Mar 2024'!AD7*315 -> 257.985
A5: Pearl Rotana Capital Centre | B5: =B4+1 -> 4 | C5: 3 | D5: 2024 | E5: =Submetering!E5+Submetering!F5+Submetering!G5 -> 14386 | F5: 0.2 | G5: ='Mar 2024'!T8 -> 33.7824 | H5: 17.295121 | I5: ='Mar 2024'!K8 -> 97 | J5: 7.84 | K5: ='Mar 2024'!X8 -> 4549.52 | L5: 1.2769252 | M5: ='Mar 2024'!AD8*315 -> 270.9945
A6: Pearl Rotana Capital Centre | B6: =B5+1 -> 5 | C6: 3 | D6: 2024 | E6: =Submetering!E6+Submetering!F6+Submetering!G6 -> 14388 | F6: 0.2 | G6: ='Mar 2024'!T9 -> 31.671 | H6: 17.295121 | I6: ='Mar 2024'!K9 -> 84 | J6: 7.84 | K6: ='Mar 2024'!X9 -> 5402.555 | L6: 1.1296528 | M6: ='Mar 2024'!AD9*315 -> 309.015
A7: Pearl Rotana Capital Centre | B7: =B6+1 -> 6 | C7: 3 | D7: 2024 | E7: =Submetering!E7+Submetering!F7+Submetering!G7 -> 14445 | F7: 0.2 | G7: ='Mar 2024'!T10 -> 29.5596 | H7: 17.295121 | I7: ='Mar 2024'!K10 -> 100 | J7: 7.84 | K7: ='Mar 2024'!X10 -> 5118.21 | L7: 1.1732891 | M7: ='Mar 2024'!AD10*315 -> 297.0135
A8: Pearl Rotana Capital Centre | B8: =B7+1 -> 7 | C8: 3 | D8: 2024 | E8: =Submetering!E8+Submetering!F8+Submetering!G8 -> 14195 | F8: 0.2 | G8: ='Mar 2024'!T11 -> 33.7824 | H8: 17.295121 | I8: ='Mar 2024'!K11 -> 88 | J8: 7.84 | K8: ='Mar 2024'!X11 -> 5118.21 | L8: 1.1732891 | M8: ='Mar 2024'!AD11*315 -> 273.0105
A9: Pearl Rotana Capital Centre | B9: =B8+1 -> 8 | C9: 3 | D9: 2024 | E9: =Submetering!E9+Submetering!F9+Submetering!G9 -> 13748 | F9: 0.2 | G9: ='Mar 2024'!T12 -> 33.7824 | H9: 17.295121 | I9: ='Mar 2024'!K12 -> 105 | J9: 7.84 | K9: ='Mar 2024'!X12 -> 5686.9 | L9: 1.0903802 | M9: ='Mar 2024'!AD12*315 -> 252
A10: Pearl Rotana Capital Centre | B10: =B9+1 -> 9 | C10: 3 | D10: 2024 | E10: =Submetering!E10+Submetering!F10+Submetering!G10 -> 13629 | F10: 0.2 | G10: ='Mar 2024'!T13 -> 32.7267 | H10: 17.295121 | I10: ='Mar 2024'!K13 -> 107 | J10: 7.84 | K10: ='Mar 2024'!X13 -> 5118.21 | L10: 1.1732891 | M10: ='Mar 2024'!AD13*315 -> 246.015
A11: Pearl Rotana Capital Centre | B11: =B10+1 -> 10 | C11: 3 | D11: 2024 | E11: =Submetering!E11+Submetering!F11+Submetering!G11 -> 14165 | F11: 0.2 | G11: ='Mar 2024'!T14 -> 31.671 | H11: 17.295121 | I11: ='Mar 2024'!K14 -> 111 | J11: 7.84 | K11: ='Mar 2024'!X14 -> 5686.9 | L11: 1.0903802 | M11: ='Mar 2024'!AD14*315 -> 199.9935
A12: Pearl Rotana Capital Centre | B12: =B11+1 -> 11 | C12: 3 | D12: 2024 | E12: =Submetering!E12+Submetering!F12+Submetering!G12 -> 14668 | F12: 0.2 | G12: ='Mar 2024'!T15 -> 33.7824 | H12: 17.295121 | I12: ='Mar 2024'!K15 -> 61 | J12: 7.84 | K12: ='Mar 2024'!X15 -> 5402.555 | L12: 1.1296528 | M12: ='Mar 2024'!AD15*315 -> 211.995
A13: Pearl Rotana Capital Centre | B13: =B12+1 -> 12 | C13: 3 | D13: 2024 | E13: =Submetering!E13+Submetering!F13+Submetering!G13 -> 14033 | F13: 0.2 | G13: ='Mar 2024'!T16 -> 31.671 | H13: 17.295121 | I13: ='Mar 2024'!K16 -> 86 | J13: 7.84 | K13: ='Mar 2024'!X16 -> 5118.21 | L13: 1.1732891 | M13: ='Mar 2024'!AD16*315 -> 225.0045
A14: Pearl Rotana Capital Centre | B14: =B13+1 -> 13 | C14: 3 | D14: 2024 | E14: =Submetering!E14+Submetering!F14+Submetering!G14 -> 14329 | F14: 0.2 | G14: ='Mar 2024'!T17 -> 30.6153 | H14: 17.295121 | I14: ='Mar 2024'!K17 -> 96 | J14: 7.84 | K14: ='Mar 2024'!X17 -> 5118.21 | L14: 1.1732891 | M14: ='Mar 2024'!AD17*315 -> 257.0085
... A32: Pearl Rotana Capital Centre | B32: =B31+1 -> 31 | C32: 3 | D32: 2024 | E32: =Submetering!E32+Submetering!F32+Submetering!G32 -> 14278 | F32: 0.2 | G32: ='Mar 2024'!T35 -> 34.8381 | H32: 17.295121 | I32: ='Mar 2024'!K35 -> 96 | J32: 7.84 | K32: ='Mar 2024'!X35 -> 5971.245 | L32: 1.0548478 | M32: ='Mar 2024'!AD35*315 -> 223.9965

Sheet Submetering
A1: Site Name | B1: Day | C1: Month | D1: Year | E1: MDB#2 | F1: MDB#3 | G1: MDB#1 Façade | H1: Water | I1: Gas Meter#1 GF Kitchen | J1: Gas Meter#2 1st floor Kitchen | K1: District Cooling | L1: District Cooling ETS | M1: Water Main Kitchen | N1: Room Nights | O1: Total Guests
A2: Pearl Rotana Capital Centre | B2: 1 | C2: 3 | D2: 2024 | E2: ='Mar 2024'!C5 -> 7337 | F2: ='Mar 2024'!E5 -> 6592 | G2: ='Mar 2024'!G5 -> 133 | H2: ='Mar 2024'!K5 -> 105 | I2: ='Mar 2024'!N5 -> 21 | J2: ='Mar 2024'!P5 -> 15 | K2: ='Mar 2024'!X5 -> 3980.83 | L2: ='Mar 2024'!AC5 -> 4673 | M2: ='Mar 2024'!AP5 -> 10 | N2: ='Mar 2024'!AD5*315 -> 234.0135
A3: Pearl Rotana Capital Centre | B3: =B2+1 -> 2 | C3: 3 | D3: 2024 | E3: ='Mar 2024'!C6 -> 7738 | F3: ='Mar 2024'!E6 -> 6833 | G3: ='Mar 2024'!G6 -> 136 | H3: ='Mar 2024'!K6 -> 102 | I3: ='Mar 2024'!N6 -> 21 | J3: ='Mar 2024'!P6 -> 14 | K3: ='Mar 2024'!X6 -> 4265.175 | L3: ='Mar 2024'!AC6 -> 4758 | M3: ='Mar 2024'!AP6 -> 7 | N3: ='Mar 2024'!AD6*315 -> 194.0085
A4: Pearl Rotana Capital Centre | B4: =B3+1 -> 3 | C4: 3 | D4: 2024 | E4: ='Mar 2024'!C7 -> 7538 | F4: ='Mar 2024'!E7 -> 6519 | G4: ='Mar 2024'!G7 -> 133 | H4: ='Mar 2024'!K7 -> 109 | I4: ='Mar 2024'!N7 -> 18 | J4: ='Mar 2024'!P7 -> 14 | K4: ='Mar 2024'!X7 -> 4265.175 | L4: ='Mar 2024'!AC7 -> 4744 | M4: ='Mar 2024'!AP7 -> 7 | N4: ='Mar 2024'!AD7*315 -> 257.985
A5: Pearl Rotana Capital Centre | B5: =B4+1 -> 4 | C5: 3 | D5: 2024 | E5: ='Mar 2024'!C8 -> 7549 | F5: ='Mar 2024'!E8 -> 6703 | G5: ='Mar 2024'!G8 -> 134 | H5: ='Mar 2024'!K8 -> 97 | I5: ='Mar 2024'!N8 -> 19 | J5: ='Mar 2024'!P8 -> 14 | K5: ='Mar 2024'!X8 -> 4549.52 | L5: ='Mar 2024'!AC8 -> 5466 | M5: ='Mar 2024'!AP8 -> 6 | N5: ='Mar 2024'!AD8*315 -> 270.9945
A6: Pearl Rotana Capital Centre | B6: =B5+1 -> 5 | C6: 3 | D6: 2024 | E6: ='Mar 2024'!C9 -> 7501 | F6: ='Mar 2024'!E9 -> 6759 | G6: ='Mar 2024'!G9 -> 128 | H6: ='Mar 2024'!K9 -> 84 | I6: ='Mar 2024'!N9 -> 19 | J6: ='Mar 2024'!P9 -> 13 | K6: ='Mar 2024'!X9 -> 5402.555 | L6: ='Mar 2024'!AC9 -> 6412 | M6: ='Mar 2024'!AP9 -> 8 | N6: ='Mar 2024'!AD9*315 -> 309.015
A7: Pearl Rotana Capital Centre | B7: =B6+1 -> 6 | C7: 3 | D7: 2024 | E7: ='Mar 2024'!C10 -> 7571 | F7: ='Mar 2024'!E10 -> 6742 | G7: ='Mar 2024'!G10 -> 132 | H7: ='Mar 2024'!K10 -> 100 | I7: ='Mar 2024'!N10 -> 18 | J7: ='Mar 2024'!P10 -> 10 | K7: ='Mar 2024'!X10 -> 5118.21 | L7: ='Mar 2024'!AC10 -> 5967 | M7: ='Mar 2024'!AP10 -> 7 | N7: ='Mar 2024'!AD10*315 -> 297.0135
A8: Pearl Rotana Capital Centre | B8: =B7+1 -> 7 | C8: 3 | D8: 2024 | E8: ='Mar 2024'!C11 -> 7706 | F8: ='Mar 2024'!E11 -> 6359 | G8: ='Mar 2024'!G11 -> 130 | H8: ='Mar 2024'!K11 -> 88 | I8: ='Mar 2024'!N11 -> 19 | J8: ='Mar 2024'!P11 -> 15 | K8: ='Mar 2024'!X11 -> 5118.21 | L8: ='Mar 2024'!AC11 -> 6041 | M8: ='Mar 2024'!AP11 -> 8 | N8: ='Mar 2024'!AD11*315 -> 273.0105
A9: Pearl Rotana Capital Centre | B9: =B8+1 -> 8 | C9: 3 | D9: 2024 | E9: ='Mar 2024'!C12 -> 7658 | F9: ='Mar 2024'!E12 -> 5956 | G9: ='Mar 2024'!G12 -> 134 | H9: ='Mar 2024'!K12 -> 105 | I9: ='Mar 2024'!N12 -> 19 | J9: ='Mar 2024'!P12 -> 14 | K9: ='Mar 2024'!X12 -> 5686.9 | L9: ='Mar 2024'!AC12 -> 6705 | M9: ='Mar 2024'!AP12 -> 13 | N9: ='Mar 2024'!AD12*315 -> 252
A10: Pearl Rotana Capital Centre | B10: =B9+1 -> 9 | C10: 3 | D10: 2024 | E10: ='Mar 2024'!C13 -> 7543 | F10: ='Mar 2024'!E13 -> 6086 | G10: ='Mar 2024'!G13 -> 0 | H10: ='Mar 2024'!K13 -> 107 | I10: ='Mar 2024'!N13 -> 20 | J10: ='Mar 2024'!P13 -> 13 | K10: ='Mar 2024'!X13 -> 5118.21 | L10: ='Mar 2024'!AC13 -> 5958 | M10: ='Mar 2024'!AP13 -> 9 | N10: ='Mar 2024'!AD13*315 -> 246.015
A11: Pearl Rotana Capital Centre | B11: =B10+1 -> 10 | C11: 3 | D11: 2024 | E11: ='Mar 2024'!C14 -> 7485 | F11: ='Mar 2024'!E14 -> 6586 | G11: ='Mar 2024'!G14 -> 94 | H11: ='Mar 2024'!K14 -> 111 | I11: ='Mar 2024'!N14 -> 18 | J11: ='Mar 2024'!P14 -> 13 | K11: ='Mar 2024'!X14 -> 5686.9 | L11: ='Mar 2024'!AC14 -> 5940 | M11: ='Mar 2024'!AP14 -> 8 | N11: ='Mar 2024'!AD14*315 -> 199.9935
A12: Pearl Rotana Capital Centre | B12: =B11+1 -> 11 | C12: 3 | D12: 2024 | E12: ='Mar 2024'!C15 -> 7727 | F12: ='Mar 2024'!E15 -> 6812 | G12: ='Mar 2024'!G15 -> 129 | H12: ='Mar 2024'!K15 -> 61 | I12: ='Mar 2024'!N15 -> 18 | J12: ='Mar 2024'!P15 -> 15 | K12: ='Mar 2024'!X15 -> 5402.555 | L12: ='Mar 2024'!AC15 -> 6415 | M12: ='Mar 2024'!AP15 -> 9 | N12: ='Mar 2024'!AD15*315 -> 211.995
A13: Pearl Rotana Capital Centre | B13: =B12+1 -> 12 | C13: 3 | D13: 2024 | E13: ='Mar 2024'!C16 -> 7334 | F13: ='Mar 2024'!E16 -> 6568 | G13: ='Mar 2024'!G16 -> 131 | H13: ='Mar 2024'!K16 -> 86 | I13: ='Mar 2024'!N16 -> 17 | J13: ='Mar 2024'!P16 -> 14 | K13: ='Mar 2024'!X16 -> 5118.21 | L13: ='Mar 2024'!AC16 -> 5787 | M13: ='Mar 2024'!AP16 -> 8 | N13: ='Mar 2024'!AD16*315 -> 225.0045
A14: Pearl Rotana Capital Centre | B14: =B13+1 -> 13 | C14: 3 | D14: 2024 | E14: ='Mar 2024'!C17 -> 7461 | F14: ='Mar 2024'!E17 -> 6738 | G14: ='Mar 2024'!G17 -> 130 | H14: ='Mar 2024'!K17 -> 96 | I14: ='Mar 2024'!N17 -> 16 | J14: ='Mar 2024'!P17 -> 15 | K14: ='Mar 2024'!X17 -> 5118.21 | L14: ='Mar 2024'!AC17 -> 6001 | M14: ='Mar 2024'!AP17 -> 12 | N14: ='Mar 2024'!AD17*315 -> 257.0085
... A32: Pearl Rotana Capital Centre | B32: =B31+1 -> 31 | C32: 3 | D32: 2024 | E32: ='Mar 2024'!C35 -> 7370 | F32: ='Mar 2024'!E35 -> 6775 | G32: ='Mar 2024'!G35 -> 133 | H32: ='Mar 2024'!K35 -> 96 | I32: ='Mar 2024'!N35 -> 18 | J32: ='Mar 2024'!P35 -> 15 | K32: ='Mar 2024'!X35 -> 5971.245 | L32: ='Mar 2024'!AC35 -> 6581 | M32: ='Mar 2024'!AP35 -> 7 | N32: ='Mar 2024'!AD35*315 -> 223.9965

Sheet Mar 2024
A1: PEARL ROTANA CAPITAL CENTRE UTILITIES CONSUMPTION - MARCH 2024
A2: DATE | B2: Electricity | J2: Water | M2: SNG Gas | V2: District Cooling | AD2: Additional Info | AF2: Additional Meter
B3: MDB #2 | D3: MDB #3 | F3: MDB #1 Façade | H3: Total ELE Cons. KW | I3: Electricity AED | J3: Hotel Reading | K3: Water Cons. M3 | L3: Water AED | M3: Gas Meter #1 G Floor Kitchen | O3: Gas Meter #2 1st Floor Kitchen | Q3: Total Gas Cons. M3 | R3: PRS Meter Reading | S3: PRS Meter Cons. M3 | T3: Meter factor (1.05570) | U3: Gas AED | V3: Hotel BTU Meter Energy Reading | W3: District Cooling Cons. MWH | X3: District Cooling Cons. Ton Hour | Y3: District Cooling Cons. AED | Z3: District Cooling Fixed Charge | AA3: District Cooling Total AED | AB3: ETS Energy Meter Reading | AC3: ETS Cons. | AD3: Hotel Occupancy % | AE3: Adl. & Chl. | AF3: Electricity MDB-1 | AI3: Electricity MDB-E | AL3: Electricity-MCC Panel Chilled water Secondary Pumps | AO3: Water - Main kitchen | AR3: Water - Swimming Pool | AU3: Water - Bottling Plant
B4: Reading | C4: Cons. | D4: Reading | E4: Cons. | F4: Reading | G4: Cons. | M4: Reading | N4: Cons. | O4: Reading | P4: Cons. | AF4: Meter Reading | AG4: Cons. KWH | AH4: AED | AI4: Meter Reading | AJ4: Cons. KWH | AK4: AED | AL4: Meter Reading | AM4: Cons. KWH | AN4: AED | AO4: Meter Reading | AP4: Cons. M3 | AQ4: AED | AR4: Meter Reading | AS4: Cons. M3 | AT4: AED | AU4: Meter Reading | AV4: Cons. M3 | AW4: AED
A5: 45352 | B5: 18677916 | C5: 7337 | D5: 19638549 | E5: 6592 | F5: 447817 | G5: 133 | H5: =C5+E5+G5 -> 14062 | I5: =H5*0.2 -> 2812.4 | J5: 75209 | K5: 105 | L5: =K5*7.84 -> 823.2 | M5: 34769 | N5: 21 | O5: 19757 | P5: 15 | Q5: 36 | R5: 50691 | S5: 34 | T5: =S5*1.0557 -> 35.8938 | U5: =IF(ISBLANK(M5),"0",T5*11.05+209.677) -> 606.30349 | V5: 66536 | W5: 14 | X5: =IF(ISBLANK(V5),"0 ",W5*284.345) -> 3980.83 | Y5: =X5*0.3442 -> 1370.2017 | Z5: =IF(ISBLANK(V5),"0",1570*1546.86/12/31*0.65) -> 4243.4694 | AA5: =Y5+Z5 -> 5613.6711 | AB5: 5876453 | AC5: 4673 | AD5: 0.7429 | AE5: 337 | AF5: 13157306 | AG5: 4896 | AH5: =AG5*0.2 -> 979.2 | AI5: 6114379 | AJ5: 2112 | AK5: =AJ5*0.2 -> 422.4 | AL5: 113369 | AM5: 165 | AN5: =AM5*0.2 -> 33 | AO5: 5775 | AP5: 10 | AQ5: =AP5*7.84 -> 78.4 | AR5: 2717 | AS5: 1 | AT5: =AS5*7.84 -> 7.84 | AU5: 83 | AV5: 1 | AW5: =AV5*7.84 -> 7.84
A6: 45353 | B6: 18685654 | C6: =IF(ISBLANK(B6),"0",B6-B5) -> 7738 | D6: 19645382 | E6: =IF(ISBLANK(D6),"0",D6-D5) -> 6833 | F6: 447953 | G6: =IF(ISBLANK(F6),"0",F6-F5) -> 136 | H6: =C6+E6+G6 -> 14707 | I6: =H6*0.2 -> 2941.4 | J6: 75311 | K6: =IF(ISBLANK(J6),"0",J6-J5) -> 102 | L6: =K6*7.84 -> 799.68 | M6: 34790 | N6: =IF(ISBLANK(M6),"0",M6-M5) -> 21 | O6: 19771 | P6: =IF(ISBLANK(O6),"0",O6-O5) -> 14 | Q6: =N6+P6 -> 35 | R6: 50725 | S6: =IF(ISBLANK(R6),"0",R6-R5) -> 34 | T6: =S6*1.0557 -> 35.8938 | U6: =IF(ISBLANK(M6),"0",T6*11.05+209.677) -> 606.30349 | V6: 66551 | W6: =IF(ISBLANK(V6)," ",V6-V5) -> 15 | X6: =IF(ISBLANK(V6),"0 ",W6*284.345) -> 4265.175 | Y6: =X6*0.3442 -> 1468.0732 | Z6: =IF(ISBLANK(V6),"0",1570*1546.86/12/31*0.65) -> 4243.4694 | AA6: =Y6+Z6 -> 5711.5427 | AB6: 5881211 | AC6: =IF(ISBLANK(AB6),"0 ",AB6-AB5) -> 4758 | AD6: 0.6159 | AE6: 289 | AF6: 13161564 | AG6: =IF(ISBLANK(AF6),"0",AF6-AF5) -> 4258 | AH6: =AG6*0.2 -> 851.6 | AI6: 6116452 | AJ6: =IF(ISBLANK(AI6),"0",AI6-AI5) -> 2073 | AK6: =AJ6*0.2 -> 414.6 | AL6: 113544 | AM6: =IF(ISBLANK(AL6),"0",AL6-AL5) -> 175 | AN6: =AM6*0.2 -> 35 | AO6: 5782 | AP6: =IF(ISBLANK(AO6),"0",AO6-AO5) -> 7 | AQ6: =AP6*7.84 -> 54.88 | AR6: 2718 | AS6: =IF(ISBLANK(AR6),"0",AR6-AR5) -> 1 | AT6: =AS6*7.84 -> 7.84 | AU6: 84 | AV6: =IF(ISBLANK(AU6),"0",AU6-AU5) -> 1 | AW6: =AV6*7.84 -> 7.84
A7: 45354 | B7: 18693192 | C7: =IF(ISBLANK(B7),"0",B7-B6) -> 7538 | D7: 19651901 | E7: =IF(ISBLANK(D7),"0",D7-D6) -> 6519 | F7: 448086 | G7: =IF(ISBLANK(F7),"0",F7-F6) -> 133 | H7: =C7+E7+G7 -> 14190 | I7: =H7*0.2 -> 2838 | J7: 75420 | K7: =IF(ISBLANK(J7),"0",J7-J6) -> 109 | L7: =K7*7.84 -> 854.56 | M7: 34808 | N7: =IF(ISBLANK(M7),"0",M7-M6) -> 18 | O7: 19785 | P7: =IF(ISBLANK(O7),"0",O7-O6) -> 14 | Q7: =N7+P7 -> 32 | R7: 50756 | S7: =IF(ISBLANK(R7),"0",R7-R6) -> 31 | T7: =S7*1.0557 -> 32.7267 | U7: =IF(ISBLANK(M7),"0",T7*11.05+209.677) -> 571.30704 | V7: 66566 | W7: =IF(ISBLANK(V7)," ",V7-V6) -> 15 | X7: =IF(ISBLANK(V7),"0 ",W7*284.345) -> 4265.175 | Y7: =X7*0.3442 -> 1468.0732 | Z7: =IF(ISBLANK(V7),"0",1570*1546.86/12/31*0.65) -> 4243.4694 | AA7: =Y7+Z7 -> 5711.5427 | AB7: 5885955 | AC7: =IF(ISBLANK(AB7),"0 ",AB7-AB6) -> 4744 | AD7: 0.819 | AE7: 374 | AF7: 13165810 | AG7: =IF(ISBLANK(AF7),"0",AF7-AF6) -> 4246 | AH7: =AG7*0.2 -> 849.2 | AI7: 6118500 | AJ7: =IF(ISBLANK(AI7),"0",AI7-AI6) -> 2048 | AK7: =AJ7*0.2 -> 409.6 | AL7: 113722 | AM7: =IF(ISBLANK(AL7),"0",AL7-AL6) -> 178 | AN7: =AM7*0.2 -> 35.6 | AO7: 5789 | AP7: =IF(ISBLANK(AO7),"0",AO7-AO6) -> 7 | AQ7: =AP7*7.84 -> 54.88 | AR7: 2720 | AS7: =IF(ISBLANK(AR7),"0",AR7-AR6) -> 2 | AT7: =AS7*7.84 -> 15.68 | AU7: 84 | AV7: =IF(ISBLANK(AU7),"0",AU7-AU6) -> 0 | AW7: =AV7*7.84 -> 0
A8: 45355 | B8: 18700741 | C8: =IF(ISBLANK(B8),"0",B8-B7) -> 7549 | D8: 19658604 | E8: =IF(ISBLANK(D8),"0",D8-D7) -> 6703 | F8: 448220 | G8: =IF(ISBLANK(F8),"0",F8-F7) -> 134 | H8: =C8+E8+G8 -> 14386 | I8: =H8*0.2 -> 2877.2 | J8: 75517 | K8: =IF(ISBLANK(J8),"0",J8-J7) -> 97 | L8: =K8*7.84 -> 760.48 | M8: 34827 | N8: =IF(ISBLANK(M8),"0",M8-M7) -> 19 | O8: 19799 | P8: =IF(ISBLANK(O8),"0",O8-O7) -> 14 | Q8: =N8+P8 -> 33 | R8: 50788 | S8: =IF(ISBLANK(R8),"0",R8-R7) -> 32 | T8: =S8*1.0557 -> 33.7824 | U8: =IF(ISBLANK(M8),"0",T8*11.05+209.677) -> 582.97252 | V8: 66582 | W8: =IF(ISBLANK(V8)," ",V8-V7) -> 16 | X8: =IF(ISBLANK(V8),"0 ",W8*284.345) -> 4549.52 | Y8: =X8*0.3442 -> 1565.9448 | Z8: =IF(ISBLANK(V8),"0",1570*1546.86/12/31*0.65) -> 4243.4694 | AA8: =Y8+Z8 -> 5809.4142 | AB8: 5891421 | AC8: =IF(ISBLANK(AB8),"0 ",AB8-AB7) -> 5466 | AD8: 0.8603 | AE8: 345 | AF8: 13170989 | AG8: =IF(ISBLANK(AF8),"0",AF8-AF7) -> 5179 | AH8: =AG8*0.2 -> 1035.8 | AI8: 6120673 | AJ8: =IF(ISBLANK(AI8),"0",AI8-AI7) -> 2173 | AK8: =AJ8*0.2 -> 434.6 | AL8: 113911 | AM8: =IF(ISBLANK(AL8),"0",AL8-AL7) -> 189 | AN8: =AM8*0.2 -> 37.8 | AO8: 5795 | AP8: =IF(ISBLANK(AO8),"0",AO8-AO7) -> 6 | AQ8: =AP8*7.84 -> 47.04 | AR8: 2721 | AS8: =IF(ISBLANK(AR8),"0",AR8-AR7) -> 1 | AT8: =AS8*7.84 -> 7.84 | AU8: 84 | AV8: =IF(ISBLANK(AU8),"0",AU8-AU7) -> 0 | AW8: =AV8*7.84 -> 0
A9: 45356 | B9: 18708242 | C9: =IF(ISBLANK(B9),"0",B9-B8) -> 7501 | D9: 19665363 | E9: =IF(ISBLANK(D9),"0",D9-D8) -> 6759 | F9: 448348 | G9: =IF(ISBLANK(F9),"0",F9-F8) -> 128 | H9: =C9+E9+G9 -> 14388 | I9: =H9*0.2 -> 2877.6 | J9: 75601 | K9: =IF(ISBLANK(J9),"0",J9-J8) -> 84 | L9: =K9*7.84 -> 658.56 | M9: 34846 | N9: =IF(ISBLANK(M9),"0",M9-M8) -> 19 | O9: 19812 | P9: =IF(ISBLANK(O9),"0",O9-O8) -> 13 | Q9: =N9+P9 -> 32 | R9: 50818 | S9: =IF(ISBLANK(R9),"0",R9-R8) -> 30 | T9: =S9*1.0557 -> 31.671 | U9: =IF(ISBLANK(M9),"0",T9*11.05+209.677) -> 559.64155 | V9: 66601 | W9: =IF(ISBLANK(V9)," ",V9-V8) -> 19 | X9: =IF(ISBLANK(V9),"0 ",W9*284.345) -> 5402.555 | Y9: =X9*0.3442 -> 1859.5594 | Z9: =IF(ISBLANK(V9),"0",1570*1546.86/12/31*0.65) -> 4243.4694 | AA9: =Y9+Z9 -> 6103.0289 | AB9: 5897833 | AC9: =IF(ISBLANK(AB9),"0 ",AB9-AB8) -> 6412 | AD9: 0.981 | AE9: 409 | AF9: 13176180 | AG9: =IF(ISBLANK(AF9),"0",AF9-AF8) -> 5191 | AH9: =AG9*0.2 -> 1038.2 | AI9: 6122874 | AJ9: =IF(ISBLANK(AI9),"0",AI9-AI8) -> 2201 | AK9: =AJ9*0.2 -> 440.2 | AL9: 114152 | AM9: =IF(ISBLANK(AL9),"0",AL9-AL8) -> 241 | AN9: =AM9*0.2 -> 48.2 | AO9: 5803 | AP9: =IF(ISBLANK(AO9),"0",AO9-AO8) -> 8 | AQ9: =AP9*7.84 -> 62.72 | AR9: 2722 | AS9: =IF(ISBLANK(AR9),"0",AR9-AR8) -> 1 | AT9: =AS9*7.84 -> 7.84 | AU9: 84 | AV9: =IF(ISBLANK(AU9),"0",AU9-AU8) -> 0 | AW9: =AV9*7.84 -> 0
A10: 45357 | B10: 18715813 | C10: =IF(ISBLANK(B10),"0",B10-B9) -> 7571 | D10: 19672105 | E10: =IF(ISBLANK(D10),"0",D10-D9) -> 6742 | F10: 448480 | G10: =IF(ISBLANK(F10),"0",F10-F9) -> 132 | H10: =C10+E10+G10 -> 14445 | I10: =H10*0.2 -> 2889 | J10: 75701 | K10: =IF(ISBLANK(J10),"0",J10-J9) -> 100 | L10: =K10*7.84 -> 784 | M10: 34864 | N10: =IF(ISBLANK(M10),"0",M10-M9) -> 18 | O10: 19822 | P10: =IF(ISBLANK(O10),"0",O10-O9) -> 10 | Q10: =N10+P10 -> 28 | R10: 50846 | S10: =IF(ISBLANK(R10),"0",R10-R9) -> 28 | T10: =S10*1.0557 -> 29.5596 | U10: =IF(ISBLANK(M10),"0",T10*11.05+209.677) -> 536.31058 | V10: 66619 | W10: =IF(ISBLANK(V10)," ",V10-V9) -> 18 | X10: =IF(ISBLANK(V10),"0 ",W10*284.345) -> 5118.21 | Y10: =X10*0.3442 -> 1761.6879 | Z10: =IF(ISBLANK(V10),"0",1570*1546.86/12/31*0.65) -> 4243.4694 | AA10: =Y10+Z10 -> 6005.1573 | AB10: 5903800 | AC10: =IF(ISBLANK(AB10),"0 ",AB10-AB9) -> 5967 | AD10: 0.9429 | AE10: 384 | AF10: 13181438 | AG10: =IF(ISBLANK(AF10),"0",AF10-AF9) -> 5258 | AH10: =AG10*0.2 -> 1051.6 | AI10: 6125120 | AJ10: =IF(ISBLANK(AI10),"0",AI10-AI9) -> 2246 | AK10: =AJ10*0.2 -> 449.2 | AL10: 114364 | AM10: =IF(ISBLANK(AL10),"0",AL10-AL9) -> 212 | AN10: =AM10*0.2 -> 42.4 | AO10: 5810 | AP10: =IF(ISBLANK(AO10),"0",AO10-AO9) -> 7 | AQ10: =AP10*7.84 -> 54.88 | AR10: 2722 | AS10: =IF(ISBLANK(AR10),"0",AR10-AR9) -> 0 | AT10: =AS10*7.84 -> 0 | AU10: 84 | AV10: =IF(ISBLANK(AU10),"0",AU10-AU9) -> 0 | AW10: =AV10*7.84 -> 0
A11: 45358 | B11: 18723519 | C11: =IF(ISBLANK(B11),"0",B11-B10) -> 7706 | D11: 19678464 | E11: =IF(ISBLANK(D11),"0",D11-D10) -> 6359 | F11: 448610 | G11: =IF(ISBLANK(F11),"0",F11-F10) -> 130 | H11: =C11+E11+G11 -> 14195 | I11: =H11*0.2 -> 2839 | J11: 75789 | K11: =IF(ISBLANK(J11),"0",J11-J10) -> 88 | L11: =K11*7.84 -> 689.92 | M11: 34883 | N11: =IF(ISBLANK(M11),"0",M11-M10) -> 19 | O11: 19837 | P11: =IF(ISBLANK(O11),"0",O11-O10) -> 15 | Q11: =N11+P11 -> 34 | R11: 50878 | S11: =IF(ISBLANK(R11),"0",R11-R10) -> 32 | T11: =S11*1.0557 -> 33.7824 | U11: =IF(ISBLANK(M11),"0",T11*11.05+209.677) -> 582.97252 | V11: 66637 | W11: =IF(ISBLANK(V11)," ",V11-V10) -> 18 | X11: =IF(ISBLANK(V11),"0 ",W11*284.345) -> 5118.21 | Y11: =X11*0.3442 -> 1761.6879 | Z11: =IF(ISBLANK(V11),"0",1570*1546.86/12/31*0.65) -> 4243.4694 | AA11: =Y11+Z11 -> 6005.1573 | AB11: 5909841 | AC11: =IF(ISBLANK(AB11),"0 ",AB11-AB10) -> 6041 | AD11: 0.8667 | AE11: 378 | AF11: 13186736 | AG11: =IF(ISBLANK(AF11),"0",AF11-AF10) -> 5298 | AH11: =AG11*0.2 -> 1059.6 | AI11: 6127356 | AJ11: =IF(ISBLANK(AI11),"0",AI11-AI10) -> 2236 | AK11: =AJ11*0.2 -> 447.2 | AL11: 114568 | AM11: =IF(ISBLANK(AL11),"0",AL11-AL10) -> 204 | AN11: =AM11*0.2 -> 40.8 | AO11: 5818 | AP11: =IF(ISBLANK(AO11),"0",AO11-AO10) -> 8 | AQ11: =AP11*7.84 -> 62.72 | AR11: 2722 | AS11: =IF(ISBLANK(AR11),"0",AR11-AR10) -> 0 | AT11: =AS11*7.84 -> 0 | AU11: 84 | AV11: =IF(ISBLANK(AU11),"0",AU11-AU10) -> 0 | AW11: =AV11*7.84 -> 0
A12: 45359 | B12: 18731177 | C12: =IF(ISBLANK(B12),"0",B12-B11) -> 7658 | D12: 19684420 | E12: =IF(ISBLANK(D12),"0",D12-D11) -> 5956 | F12: 448744 | G12: =IF(ISBLANK(F12),"0",F12-F11) -> 134 | H12: =C12+E12+G12 -> 13748 | I12: =H12*0.2 -> 2749.6 | J12: 75894 | K12: =IF(ISBLANK(J12),"0",J12-J11) -> 105 | L12: =K12*7.84 -> 823.2 | M12: 34902 | N12: =IF(ISBLANK(M12),"0",M12-M11) -> 19 | O12: 19851 | P12: =IF(ISBLANK(O12),"0",O12-O11) -> 14 | Q12: =N12+P12 -> 33 | R12: 50910 | S12: =IF(ISBLANK(R12),"0",R12-R11) -> 32 | T12: =S12*1.0557 -> 33.7824 | U12: =IF(ISBLANK(M12),"0",T12*11.05+209.677) -> 582.97252 | V12: 66657 | W12: =IF(ISBLANK(V12)," ",V12-V11) -> 20 | X12: =IF(ISBLANK(V12),"0 ",W12*284.345) -> 5686.9 | Y12: =X12*0.3442 -> 1957.431 | Z12: =IF(ISBLANK(V12),"0",1570*1546.86/12/31*0.65) -> 4243.4694 | AA12: =Y12+Z12 -> 6200.9004 | AB12: 5916546 | AC12: =IF(ISBLANK(AB12),"0 ",AB12-AB11) -> 6705 | AD12: 0.8 | AE12: 343 | AF12: 13191812 | AG12: =IF(ISBLANK(AF12),"0",AF12-AF11) -> 5076 | AH12: =AG12*0.2 -> 1015.2 | AI12: 6129544 | AJ12: =IF(ISBLANK(AI12),"0",AI12-AI11) -> 2188 | AK12: =AJ12*0.2 -> 437.6 | AL12: 114816 | AM12: =IF(ISBLANK(AL12),"0",AL12-AL11) -> 248 | AN12: =AM12*0.2 -> 49.6 | AO12: 5831 | AP12: =IF(ISBLANK(AO12),"0",AO12-AO11) -> 13 | AQ12: =AP12*7.84 -> 101.92 | AR12: 2723 | AS12: =IF(ISBLANK(AR12),"0",AR12-AR11) -> 1 | AT12: =AS12*7.84 -> 7.84 | AU12: 85 | AV12: =IF(ISBLANK(AU12),"0",AU12-AU11) -> 1 | AW12: =AV12*7.84 -> 7.84
A13: 45360 | B13: 18738720 | C13: =IF(ISBLANK(B13),"0",B13-B12) -> 7543 | D13: 19690506 | E13: =IF(ISBLANK(D13),"0",D13-D12) -> 6086 | F13: 448744 | G13: =IF(ISBLANK(F13),"0",F13-F12) -> 0 | H13: =C13+E13+G13 -> 13629 | I13: =H13*0.2 -> 2725.8 | J13: 76001 | K13: =IF(ISBLANK(J13),"0",J13-J12) -> 107 | L13: =K13*7.84 -> 838.88 | M13: 34922 | N13: =IF(ISBLANK(M13),"0",M13-M12) -> 20 | O13: 19864 | P13: =IF(ISBLANK(O13),"0",O13-O12) -> 13 | Q13: =N13+P13 -> 33 | R13: 50941 | S13: =IF(ISBLANK(R13),"0",R13-R12) -> 31 | T13: =S13*1.0557 -> 32.7267 | U13: =IF(ISBLANK(M13),"0",T13*11.05+209.677) -> 571.30704 | V13: 66675 | W13: =IF(ISBLANK(V13)," ",V13-V12) -> 18 | X13: =IF(ISBLANK(V13),"0 ",W13*284.345) -> 5118.21 | Y13: =X13*0.3442 -> 1761.6879 | Z13: =IF(ISBLANK(V13),"0",1570*1546.86/12/31*0.65) -> 4243.4694 | AA13: =Y13+Z13 -> 6005.1573 | AB13: 5922504 | AC13: =IF(ISBLANK(AB13),"0 ",AB13-AB12) -> 5958 | AD13: 0.781 | AE13: 336 | AF13: 13195848 | AG13: =IF(ISBLANK(AF13),"0",AF13-AF12) -> 4036 | AH13: =AG13*0.2 -> 807.2 | AI13: 6131609 | AJ13: =IF(ISBLANK(AI13),"0",AI13-AI12) -> 2065 | AK13: =AJ13*0.2 -> 413 | AL13: 115020 | AM13: =IF(ISBLANK(AL13),"0",AL13-AL12) -> 204 | AN13: =AM13*0.2 -> 40.8 | AO13: 5840 | AP13: =IF(ISBLANK(AO13),"0",AO13-AO12) -> 9 | AQ13: =AP13*7.84 -> 70.56 | AR13: 2732 | AS13: =IF(ISBLANK(AR13),"0",AR13-AR12) -> 9 | AT13: =AS13*7.84 -> 70.56 | AU13: 86 | AV13: =IF(ISBLANK(AU13),"0",AU13-AU12) -> 1 | AW13: =AV13*7.84 -> 7.84
A14: 45361 | B14: 18746205 | C14: =IF(ISBLANK(B14),"0",B14-B13) -> 7485 | D14: 19697092 | E14: =IF(ISBLANK(D14),"0",D14-D13) -> 6586 | F14: 448838 | G14: =IF(ISBLANK(F14),"0",F14-F13) -> 94 | H14: =C14+E14+G14 -> 14165 | I14: =H14*0.2 -> 2833 | J14: 76112 | K14: =IF(ISBLANK(J14),"0",J14-J13) -> 111 | L14: =K14*7.84 -> 870.24 | M14: 34940 | N14: =IF(ISBLANK(M14),"0",M14-M13) -> 18 | O14: 19877 | P14: =IF(ISBLANK(O14),"0",O14-O13) -> 13 | Q14: =N14+P14 -> 31 | R14: 50971 | S14: =IF(ISBLANK(R14),"0",R14-R13) -> 30 | T14: =S14*1.0557 -> 31.671 | U14: =IF(ISBLANK(M14),"0",T14*11.05+209.677) -> 559.64155 | V14: 66695 | W14: =IF(ISBLANK(V14)," ",V14-V13) -> 20 | X14: =IF(ISBLANK(V14),"0 ",W14*284.345) -> 5686.9 | Y14: =X14*0.3442 -> 1957.431 | Z14: =IF(ISBLANK(V14),"0",1570*1546.86/12/31*0.65) -> 4243.4694 | AA14: =Y14+Z14 -> 6200.9004 | AB14: 5928444 | AC14: =IF(ISBLANK(AB14),"0 ",AB14-AB13) -> 5940 | AD14: 0.6349 | AE14: 290 | AF14: 13199935 | AG14: =IF(ISBLANK(AF14),"0",AF14-AF13) -> 4087 | AH14: =AG14*0.2 -> 817.4 | AI14: 6133626 | AJ14: =IF(ISBLANK(AI14),"0",AI14-AI13) -> 2017 | AK14: =AJ14*0.2 -> 403.4 | AL14: 115241 | AM14: =IF(ISBLANK(AL14),"0",AL14-AL13) -> 221 | AN14: =AM14*0.2 -> 44.2 | AO14: 5848 | AP14: =IF(ISBLANK(AO14),"0",AO14-AO13) -> 8 | AQ14: =AP14*7.84 -> 62.72 | AR14: 2734 | AS14: =IF(ISBLANK(AR14),"0",AR14-AR13) -> 2 | AT14: =AS14*7.84 -> 15.68 | AU14: 87 | AV14: =IF(ISBLANK(AU14),"0",AU14-AU13) -> 1 | AW14: =AV14*7.84 -> 7.84
A15: 45362 | B15: 18753932 | C15: =IF(ISBLANK(B15),"0",B15-B14) -> 7727 | D15: 19703904 | E15: =IF(ISBLANK(D15),"0",D15-D14) -> 6812 | F15: 448967 | G15: =IF(ISBLANK(F15),"0",F15-F14) -> 129 | H15: =C15+E15+G15 -> 14668 | I15: =H15*0.2 -> 2933.6 | J15: 76173 | K15: =IF(ISBLANK(J15),"0",J15-J14) -> 61 | L15: =K15*7.84 -> 478.24 | M15: 34958 | N15: =IF(ISBLANK(M15),"0",M15-M14) -> 18 | O15: 19892 | P15: =IF(ISBLANK(O15),"0",O15-O14) -> 15 | Q15: =N15+P15 -> 33 | R15: 51003 | S15: =IF(ISBLANK(R15),"0",R15-R14) -> 32 | T15: =S15*1.0557 -> 33.7824 | U15: =IF(ISBLANK(M15),"0",T15*11.05+209.677) -> 582.97252 | V15: 66714 | W15: =IF(ISBLANK(V15)," ",V15-V14) -> 19 | X15: =IF(ISBLANK(V15),"0 ",W15*284.345) -> 5402.555 | Y15: =X15*0.3442 -> 1859.5594 | Z15: =IF(ISBLANK(V15),"0",1570*1546.86/12/31*0.65) -> 4243.4694 | AA15: =Y15+Z15 -> 6103.0289 | AB15: 5934859 | AC15: =IF(ISBLANK(AB15),"0 ",AB15-AB14) -> 6415 | AD15: 0.673 | AE15: 301 | AF15: 13204842 | AG15: =IF(ISBLANK(AF15),"0",AF15-AF14) -> 4907 | AH15: =AG15*0.2 -> 981.4 | AI15: 6135796 | AJ15: =IF(ISBLANK(AI15),"0",AI15-AI14) -> 2170 | AK15: =AJ15*0.2 -> 434 | AL15: 115455 | AM15: =IF(ISBLANK(AL15),"0",AL15-AL14) -> 214 | AN15: =AM15*0.2 -> 42.8 | AO15: 5857 | AP15: =IF(ISBLANK(AO15),"0",AO15-AO14) -> 9 | AQ15: =AP15*7.84 -> 70.56 | AR15: 2734 | AS15: =IF(ISBLANK(AR15),"0",AR15-AR14) -> 0 | AT15: =AS15*7.84 -> 0 | AU15: 88 | AV15: =IF(ISBLANK(AU15),"0",AU15-AU14) -> 1 | AW15: =AV15*7.84 -> 7.84
A16: 45363 | B16: 18761266 | C16: =IF(ISBLANK(B16),"0",B16-B15) -> 7334 | D16: 19710472 | E16: =IF(ISBLANK(D16),"0",D16-D15) -> 6568 | F16: 449098 | G16: =IF(ISBLANK(F16),"0",F16-F15) -> 131 | H16: =C16+E16+G16 -> 14033 | I16: =H16*0.2 -> 2806.6 | J16: 76259 | K16: =IF(ISBLANK(J16),"0",J16-J15) -> 86 | L16: =K16*7.84 -> 674.24 | M16: 34975 | N16: =IF(ISBLANK(M16),"0",M16-M15) -> 17 | O16: 19906 | P16: =IF(ISBLANK(O16),"0",O16-O15) -> 14 | Q16: =N16+P16 -> 31 | R16: 51033 | S16: =IF(ISBLANK(R16),"0",R16-R15) -> 30 | T16: =S16*1.0557 -> 31.671 | U16: =IF(ISBLANK(M16),"0",T16*11.05+209.677) -> 559.64155 | V16: 66732 | W16: =IF(ISBLANK(V16)," ",V16-V15) -> 18 | X16: =IF(ISBLANK(V16),"0 ",W16*284.345) -> 5118.21 | Y16: =X16*0.3442 -> 1761.6879 | Z16: =IF(ISBLANK(V16),"0",1570*1546.86/12/31*0.65) -> 4243.4694 | AA16: =Y16+Z16 -> 6005.1573 | AB16: 5940646 | AC16: =IF(ISBLANK(AB16),"0 ",AB16-AB15) -> 5787 | AD16: 0.7143 | AE16: 301 | AF16: 13209698 | AG16: =IF(ISBLANK(AF16),"0",AF16-AF15) -> 4856 | AH16: =AG16*0.2 -> 971.2 | AI16: 6137890 | AJ16: =IF(ISBLANK(AI16),"0",AI16-AI15) -> 2094 | AK16: =AJ16*0.2 -> 418.8 | AL16: 115652 | AM16: =IF(ISBLANK(AL16),"0",AL16-AL15) -> 197 | AN16: =AM16*0.2 -> 39.4 | AO16: 5865 | AP16: =IF(ISBLANK(AO16),"0",AO16-AO15) -> 8 | AQ16: =AP16*7.84 -> 62.72 | AR16: 2735 | AS16: =IF(ISBLANK(AR16),"0",AR16-AR15) -> 1 | AT16: =AS16*7.84 -> 7.84 | AU16: 88 | AV16: =IF(ISBLANK(AU16),"0",AU16-AU15) -> 0 | AW16: =AV16*7.84 -> 0
A17: 45364 | B17: 18768727 | C17: =IF(ISBLANK(B17),"0",B17-B16) -> 7461 | D17: 19717210 | E17: =IF(ISBLANK(D17),"0",D17-D16) -> 6738 | F17: 449228 | G17: =IF(ISBLANK(F17),"0",F17-F16) -> 130 | H17: =C17+E17+G17 -> 14329 | I17: =H17*0.2 -> 2865.8 | J17: 76355 | K17: =IF(ISBLANK(J17),"0",J17-J16) -> 96 | L17: =K17*7.84 -> 752.64 | M17: 34991 | N17: =IF(ISBLANK(M17),"0",M17-M16) -> 16 | O17: 19921 | P17: =IF(ISBLANK(O17),"0",O17-O16) -> 15 | Q17: =N17+P17 -> 31 | R17: 51062 | S17: =IF(ISBLANK(R17),"0",R17-R16) -> 29 | T17: =S17*1.0557 -> 30.6153 | U17: =IF(ISBLANK(M17),"0",T17*11.05+209.677) -> 547.97607 | V17: 66750 | W17: =IF(ISBLANK(V17)," ",V17-V16) -> 18 | X17: =IF(ISBLANK(V17),"0 ",W17*284.345) -> 5118.21 | Y17: =X17*0.3442 -> 1761.6879 | Z17: =IF(ISBLANK(V17),"0",1570*1546.86/12/31*0.65) -> 4243.4694 | AA17: =Y17+Z17 -> 6005.1573 | AB17: 5946647 | AC17: =IF(ISBLANK(AB17),"0 ",AB17-AB16) -> 6001 | AD17: 0.8159 | AE17: 390 | AF17: 13214652 | AG17: =IF(ISBLANK(AF17),"0",AF17-AF16) -> 4954 | AH17: =AG17*0.2 -> 990.8 | AI17: 6140041 | AJ17: =IF(ISBLANK(AI17),"0",AI17-AI16) -> 2151 | AK17: =AJ17*0.2 -> 430.2 | AL17: 115855 | AM17: =IF(ISBLANK(AL17),"0",AL17-AL16) -> 203 | AN17: =AM17*0.2 -> 40.6 | AO17: 5877 | AP17: =IF(ISBLANK(AO17),"0",AO17-AO16) -> 12 | AQ17: =AP17*7.84 -> 94.08 | AR17: 2736 | AS17: =IF(ISBLANK(AR17),"0",AR17-AR16) -> 1 | AT17: =AS17*7.84 -> 7.84 | AU17: 89 | AV17: =IF(ISBLANK(AU17),"0",AU17-AU16) -> 1 | AW17: =AV17*7.84 -> 7.84
... A35: 45382 | B35: 18905507 | C35: =IF(ISBLANK(B35),"0",B35-B34) -> 7370 | D35: 19839933 | E35: =IF(ISBLANK(D35),"0",D35-D34) -> 6775 | F35: 451579 | G35: =IF(ISBLANK(F35),"0",F35-F34) -> 133 | H35: =C35+E35+G35 -> 14278 | I35: =H35*0.2 -> 2855.6 | J35: 78151 | K35: =IF(ISBLANK(J35),"0",J35-J34) -> 96 | L35: =K35*7.84 -> 752.64 | M35: 35317 | N35: =IF(ISBLANK(M35),"0",M35-M34) -> 18 | O35: 20194 | P35: =IF(ISBLANK(O35),"0",O35-O34) -> 15 | Q35: =N35+P35 -> 33 | R35: 51644 | S35: =IF(ISBLANK(R35),"0",R35-R34) -> 33 | T35: =S35*1.0557 -> 34.8381 | U35: =IF(ISBLANK(M35),"0",T35*11.05+209.677) -> 594.63801 | V35: 67133 | W35: =IF(ISBLANK(V35)," ",V35-V34) -> 21 | X35: =IF(ISBLANK(V35),"0 ",W35*284.345) -> 5971.245 | Y35: =X35*0.3442 -> 2055.3025 | Z35: =IF(ISBLANK(V35),"0",1570*1546.86/12/31*0.65) -> 4243.4694 | AA35: =Y35+Z35 -> 6298.772 | AB35: 6071978 | AC35: =IF(ISBLANK(AB35),"0 ",AB35-AB34) -> 6581 | AD35: 0.7111 | AE35: 332 | AF35: 13299071 | AG35: =IF(ISBLANK(AF35),"0",AF35-AF34) -> 4112 | AH35: =AG35*0.2 -> 822.4 | AI35: 6178017 | AJ35: =IF(ISBLANK(AI35),"0",AI35-AI34) -> 1956 | AK35: =AJ35*0.2 -> 391.2 | AL35: 120132 | AM35: =IF(ISBLANK(AL35),"0",AL35-AL34) -> 225 | AN35: =AM35*0.2 -> 45 | AO35: 6061 | AP35: =IF(ISBLANK(AO35),"0",AO35-AO34) -> 7 | AQ35: =AP35*7.84 -> 54.88 | AR35: 2755 | AS35: =IF(ISBLANK(AR35),"0",AR35-AR34) -> 0 | AT35: =AS35*7.84 -> 0 | AU35: 109 | AV35: =IF(ISBLANK(AU35),"0",AU35-AU34) -> 2 | AW35: =AV35*7.84 -> 15.68
C36: =SUM(C5:C35) -> 234928 | E36: =SUM(E5:E35) -> 207976 | G36: =SUM(G5:G35) -> 3895 | H36: =SUM(H5:H35) -> 446799 | I36: =H36*0.2 -> 89359.8 | K36: =SUM(K5:K35) -> 3047 | L36: =K36*7.84 -> 23888.48 | N36: =SUM(N5:N35) -> 569 | P36: =SUM(P5:P35) -> 452 | Q36: =SUM(Q5:Q35) -> 1021 | S36: =SUM(S5:S35) -> 987 | T36: =SUM(T5:T35) -> 1041.9759 | U36: =SUM(U5:U35) -> 18013.821 | W36: =SUM(W5:W35) -> 611 | X36: =SUM(X5:X35) -> 173734.79 | Y36: =SUM(Y5:Y35) -> 59799.516 | Z36: =SUM(Z5:Z35) -> 131547.55 | AA36: =SUM(AA5:AA35) -> 191347.07 | AC36: =SUM(AC5:AC35) -> 200198 | AD36: =AVERAGE(AD5:AD35) -> 0.78198387 | AE36: =SUM(AE5:AE35) -> 11099 | AG36: =SUM(AG5:AG35) -> 146661 | AH36: =SUM(AH5:AH35) -> 29332.2 | AJ36: =SUM(AJ5:AJ35) -> 65750 | AK36: =SUM(AK5:AK35) -> 13150 | AM36: =SUM(AM5:AM35) -> 6928 | AN36: =SUM(AN5:AN35) -> 1385.6 | AP36: =SUM(AP5:AP35) -> 296 | AQ36: =SUM(AQ5:AQ35) -> 2320.64 | AS36: =SUM(AS5:AS35) -> 39 | AT36: =SUM(AT5:AT35) -> 305.76 | AV36: =SUM(AV5:AV35) -> 27 | AW36: =SUM(AW5:AW35) -> 211.68
V37: AVT Charges should be Zero in the DC invoice - Please notify if not
B38: Electricity | D38: AED | G38: KW | J38: Water | L38: AED | M38: M3 | O38: Gas | R38: AED | T38: M3 | V38: Chilled Water | X38: AED | Z38: Ton Hour | AG38: =131547.55*3 -> 394642.65 | AH38: CHW Fixed Charges YTD 2023
B39: Actual March 2024 | D39: =I36 -> 89359.8 | G39: =D39/0.2 -> 446799 | J39: =B39 -> Actual March 2024 | L39: =L36 -> 23888.48 | M39: =K36 -> 3047 | O39: =B39 -> Actual March 2024 | R39: =U36 -> 18013.821 | T39: =T36 -> 1041.9759 | V39: =B39 -> Actual March 2024 | X39: =AA36 -> 191347.07 | Z39: =X36 -> 173734.79 | AD39: =AC36 -> 200198 | AE39: =AD39-X36 -> 26463.205 | AG39: =126488.42*3 -> 379465.26 | AH39: CHW Fixed Charges YTD 2022
B40: Budget March 2024 | D40: 98626.5 | G40: =D40/0.2 -> 493132.5 | J40: =B40 -> Budget March 2024 | L40: 23584.25 | M40: =L40/7.84 -> 3008.1952 | O40: =B40 -> Budget March 2024 | R40: 17940.87 | T40: =(R40-6500)/11.05 -> 1035.3729 | V40: =B40 -> Budget March 2024 | X40: 193048.33 | Z40: =AG40/0.3442 -> 178677.45 | AG40: =X40-131547.55 -> 61500.78 | AH40: CHW Consumption Charges (Budgeted 2023 MTD)
B41: Actual March 2023 | D41: 97535.8 | G41: =D41/0.2 -> 487679 | J41: =B41 -> Actual March 2023 | L41: 22375.36 | M41: =L41/7.84 -> 2854 | O41: =B41 -> Actual March 2023 | R41: 16247.56 | T41: =(R41-6500)/11.05 -> 882.13213 | V41: =B41 -> Actual March 2023 | X41: 184957.55 | Z41: =AG41/0.3435 -> 170215.81 | AG41: =X41-126488.42 -> 58469.13 | AH41: CHW Consumption Charges (Actual 2022 MTD)
B42: Actual YTD 2024 | D42: =D39 -> 89359.8 | G42: =D42/0.2 -> 446799 | J42: =B42 -> Actual YTD 2024 | L42: =L39 -> 23888.48 | M42: =L42/7.84 -> 3047 | O42: =B42 -> Actual YTD 2024 | R42: =R39 -> 18013.821 | T42: =(R42-6500*3)/11.05 -> -134.49586 | V42: =B42 -> Actual YTD 2024 | X42: =X39 -> 191347.07 | Z42: =AG42/0.3442 -> -590632.14 | AG42: =X42-AG38 -> -203295.58 | AH42: CHW Consumption Charges (Actual 2023 YTD)
B43: Budget YTD 2024 | D43: =D40+187992 -> 286618.5 | G43: =D43/0.2 -> 1433092.5 | J43: =B43 -> Budget YTD 2024 | L43: =L40+49427.56 -> 73011.81 | M43: =L43/7.84 -> 9312.7309 | O43: =B43 -> Budget YTD 2024 | R43: =R40+37105.68 -> 55046.55 | T43: =(R43-6500*3)/11.05 -> 3216.8824 | V43: =B43 -> Budget YTD 2024 | X43: =X40+365536.93 -> 558585.26 | Z43: =AG43/0.3442 -> 476300.44 | AG43: =X43-AG38 -> 163942.61 | AH43: CHW Consumption Charges (Budgeted 2023 YTD)
B44: Actual YTD 2023 | D44: 280810.6 | G44: =D44/0.2 -> 1404053 | J44: =B44 -> Actual YTD 2023 | L44: 63041.44 | M44: =L44/7.84 -> 8041 | O44: =B44 -> Actual YTD 2023 | R44: 48040.97 | T44: =(R44-6500*3)/11.05 -> 2582.8932 | V44: =B44 -> Actual YTD 2023 | X44: 530478.5 | Z44: =AG44/0.3435 -> 439630.98 | AG44: =X44-AG39 -> 151013.24 | AH44: CHW Consumption Charges (Actual 2022 YTD)
H45: 45352 | I45: =TODAY() -> 45426 | J45: =I45-H45 -> 74
A46: Monthly Budget | D46: Daily Budget | I46: MTD Average | N46: MTD Budget | U46: MTD Actual | Z46: YTD Budget | AD46: YTD Actual | AG46: Savings | AH46: Exceeds
A47: Electricity | B47: =D40 -> 98626.5 | D47: Electricity | G47: =B47/31 -> 3181.5 | I47: Electricity | L47: =I36/J45 -> 1207.5649 | N47: Electricity | R47: =G47*J45 -> 235431 | U47: Electricity | W47: =I36 -> 89359.8 | Y47: =R47-W47 -> 146071.2 | Z47: Electricity | AB47: =R47 -> 235431 | AD47: Electricity | AF47: =W47 -> 89359.8 | AG47: =AB47-AF47 -> 146071.2 | AH47: =AF47-AB47 -> -146071.2
A48: Water | B48: =L40 -> 23584.25 | D48: Water | G48: =B48/31 -> 760.78226 | I48: Water | L48: =L36/J45 -> 322.8173 | N48: Water | R48: =G48*J45 -> 56297.887 | U48: Water | W48: =L36 -> 23888.48 | Y48: =R48-W48 -> 32409.407 | Z48: Water | AB48: =R48 -> 56297.887 | AD48: Water | AF48: =W48 -> 23888.48 | AG48: =AB48-AF48 -> 32409.407 | AH48: =AF48-AB48 -> -32409.407
A49: Gas | B49: =R40 -> 17940.87 | D49: Gas | G49: =B49/31 -> 578.73774 | I49: Gas | L49: =U36/J45 -> 243.43001 | N49: Gas | R49: =G49*J45 -> 42826.593 | U49: Gas | W49: =U36 -> 18013.821 | Y49: =R49-W49 -> 24812.772 | Z49: Gas | AB49: =R49 -> 42826.593 | AD49: Gas | AF49: =W49 -> 18013.821 | AG49: =AB49-AF49 -> 24812.772 | AH49: =AF49-AB49 -> -24812.772
A50: Chilled Water | B50: =X40 -> 193048.33 | D50: Chilled Water | G50: =B50/31 -> 6227.3655 | I50: Chilled Water | L50: =AA36/J45 -> 2585.7712 | N50: Chilled Water | R50: =G50*J45 -> 460825.05 | U50: Chilled Water | W50: =AA36 -> 191347.07 | Y50: =R50-W50 -> 269477.98 | Z50: Chilled Water | AB50: =R50 -> 460825.05 | AD50: Chilled Water | AF50: =W50 -> 191347.07 | AG50: =AB50-AF50 -> 269477.98 | AH50: =AF50-AB50 -> -269477.98
B51: =SUM(B47:B50) -> 333199.95 | R51: =SUM(R47:S50) -> 795380.53 | W51: =SUM(W47:X50) -> 322609.17 | Y51: =R51-W51 -> 472771.36 | AA51: Total Energy cost | AB51: =SUM(AB47:AB50) -> 795380.53 | AF51: =SUM(AF47:AF50) -> 322609.17 | AG51: =AB51-AF51 -> 472771.36
B52: =B51*X52 -> 198052.87 | X52: =1-(W51/R51) -> 0.59439644 | AF52: =1-(AF51/AB51) -> 0.59439644
A54: Actual Last Year | D54: Average Daily Consumption Last Year | I54: MTD Average Last Year | N54: MTD Actual | U54: MTD Actual Vs Last Year | Z54: MTD Fcst | AA54: YTD Fcst | AD54: MTD Saving Fcst Vs LY | AE54: YTD Saving Fcst Vs LY
A55: Electricity | B55: =D41 -> 97535.8 | D55: Electricity | G55: =B55/31 -> 3146.3161 | I55: Electricity | N55: Electricity | R55: =W47 -> 89359.8 | U55: Electricity | W55: =L55-R55 -> #VALUE! | Z55: =L47*31 -> 37434.511 | AA55: =Z55 -> 37434.511 | AD55: =D41-Z55 -> 60101.289 | AE55: =D44-AA55 -> 243376.09
A56: Water | B56: =L41 -> 22375.36 | D56: Water | G56: =B56/31 -> 721.78581 | I56: Water | L56: =G56*J45 -> 53412.15 | N56: Water | R56: =W48 -> 23888.48 | U56: Water | W56: =L56-R56 -> 29523.67 | Z56: =L48*31 -> 10007.336 | AA56: =Z56 -> 10007.336 | AD56: =L41-Z56 -> 12368.024 | AE56: =L44-AA56 -> 53034.104
A57: Gas | B57: =R41 -> 16247.56 | D57: Gas | G57: =B57/31 -> 524.11484 | I57: Gas | L57: =G57*J45 -> 38784.498 | N57: Gas | R57: =W49 -> 18013.821 | U57: Gas | W57: =L57-R57 -> 20770.677 | Z57: =L49*31 -> 7546.3303 | AA57: =Z57 -> 7546.3303 | AD57: =R41-Z57 -> 8701.2297 | AE57: =R44-AA57 -> 40494.64
A58: Chilled Water | B58: =X41 -> 184957.55 | D58: Chilled Water | G58: =B58/31 -> 5966.3726 | I58: Chilled Water | L58: =G58*J45 -> 441511.57 | N58: Chilled Water | R58: =W50 -> 191347.07 | U58: Chilled Water | W58: =L58-R58 -> 250164.5 | Z58: =L50*31 -> 80158.907 | AA58: =Z58 -> 80158.907 | AD58: =X41-Z58 -> 104798.64 | AE58: =Z44-AA58 -> 359472.07
...
