Workbook

Sheet TOTAL
A1: Site Name | B1: Day | C1: Month | D1: Year | E1: Total Electricity Kwh | F1: Electricity Tariff ($/Kwh) | G1: LPG (Liters) | H1: LPG $/Liters | I1: Water Utility Supply (m3) m3 | J1: Water Utility Supply (m3) $/m3 | K1: District Energy Cooling RTH | L1: District Energy Cooling $/RTH | M1: Room Nights | N1: Cooling Degree Day
A2: Amwaj Rotana - Jumeirah Beach | B2: 1 | C2: 5 | D2: 2023 | E2: ='MTD Utility Sheet'!G4/0.439 -> 16474.146 | F2: 0.439 | G2: =('MTD Utility Sheet'!I4/2.1)/0.5 -> 585.6 | H2: =2.1*0.5 -> 1.05 | I2: ='MTD Utility Sheet'!H4/12.38 -> 215.50889 | J2: 12.38 | K2: =IF(('MTD Utility Sheet'!F4-2866)<0,"0",('MTD Utility Sheet'!F4-2866)/(0.568+0.075)) -> 5877.776 | L2: ='MTD Utility Sheet'!F4/K2 -> 1.1305994 | M2: ='MTD Utility Sheet'!B4*301 -> 301 | N2: 4.9
A3: Amwaj Rotana - Jumeirah Beach | B3: =B2+1 -> 2 | C3: 5 | D3: 2023 | E3: ='MTD Utility Sheet'!G5/0.439 -> 15137.608 | F3: 0.439 | G3: =('MTD Utility Sheet'!I5/2.1)/0.5 -> 341.5619 | H3: =2.1*0.5 -> 1.05 | I3: ='MTD Utility Sheet'!H5/12.38 -> 206.979 | J3: 12.38 | K3: =IF(('MTD Utility Sheet'!F5-2866)<0,"0",('MTD Utility Sheet'!F5-2866)/(0.568+0.075)) -> 8010.14 | L3: ='MTD Utility Sheet'!F5/K3 -> 1.0007965 | M3: ='MTD Utility Sheet'!B5*301 -> 298.2007 | N3: 5
A4: Amwaj Rotana - Jumeirah Beach | B4: =B3+1 -> 3 | C4: 5 | D4: 2023 | E4: ='MTD Utility Sheet'!G6/0.439 -> 14649.294 | F4: 0.439 | G4: =('MTD Utility Sheet'!I6/2.1)/0.5 -> 488 | H4: =2.1*0.5 -> 1.05 | I4: ='MTD Utility Sheet'!H6/12.38 -> 217.64136 | J4: 12.38 | K4: =IF(('MTD Utility Sheet'!F6-2866)<0,"0",('MTD Utility Sheet'!F6-2866)/(0.568+0.075)) -> 7358.9736 | L4: ='MTD Utility Sheet'!F6/K4 -> 1.0324565 | M4: ='MTD Utility Sheet'!B6*301 -> 289.0503 | N4: 5.1
A5: Amwaj Rotana - Jumeirah Beach | B5: =B4+1 -> 4 | C5: 5 | D5: 2023 | E5: ='MTD Utility Sheet'!G7/0.439 -> 16114.214 | F5: 0.439 | G5: =('MTD Utility Sheet'!I7/2.1)/0.5 -> 488 | H5: =2.1*0.5 -> 1.05 | I5: ='MTD Utility Sheet'!H7/12.38 -> 210.17771 | J5: 12.38 | K5: =IF(('MTD Utility Sheet'!F7-2866)<0,"0",('MTD Utility Sheet'!F7-2866)/(0.568+0.075)) -> 7725.7854 | L5: ='MTD Utility Sheet'!F7/K5 -> 1.0139655 | M5: ='MTD Utility Sheet'!B7*301 -> 298.0803 | N5: 3.8
A6: Amwaj Rotana - Jumeirah Beach | B6: =B5+1 -> 5 | C6: 5 | D6: 2023 | E6: ='MTD Utility Sheet'!G8/0.439 -> 15625.923 | F6: 0.439 | G6: =('MTD Utility Sheet'!I8/2.1)/0.5 -> 488 | H6: =2.1*0.5 -> 1.05 | I6: ='MTD Utility Sheet'!H8/12.38 -> 206.979 | J6: 12.38 | K6: =IF(('MTD Utility Sheet'!F8-2866)<0,"0",('MTD Utility Sheet'!F8-2866)/(0.568+0.075)) -> 7751.3841 | L6: ='MTD Utility Sheet'!F8/K6 -> 1.0127404 | M6: ='MTD Utility Sheet'!B8*301 -> 301.903 | N6: 4.1
A7: Amwaj Rotana - Jumeirah Beach | B7: =B6+1 -> 6 | C7: 5 | D7: 2023 | E7: ='MTD Utility Sheet'!G9/0.439 -> 15137.608 | F7: 0.439 | G7: =('MTD Utility Sheet'!I9/2.1)/0.5 -> 488 | H7: =2.1*0.5 -> 1.05 | I7: ='MTD Utility Sheet'!H9/12.38 -> 214.44265 | J7: 12.38 | K7: =IF(('MTD Utility Sheet'!F9-2866)<0,"0",('MTD Utility Sheet'!F9-2866)/(0.568+0.075)) -> 8061.3219 | L7: ='MTD Utility Sheet'!F9/K7 -> 0.99852482 | M7: ='MTD Utility Sheet'!B9*301 -> 282.94 | N7: 4.3
A8: Amwaj Rotana - Jumeirah Beach | B8: =B7+1 -> 7 | C8: 5 | D8: 2023 | E8: ='MTD Utility Sheet'!G10/0.439 -> 15137.608 | F8: 0.439 | G8: =('MTD Utility Sheet'!I10/2.1)/0.5 -> 390.4 | H8: =2.1*0.5 -> 1.05 | I8: ='MTD Utility Sheet'!H10/12.38 -> 194.18417 | J8: 12.38 | K8: =IF(('MTD Utility Sheet'!F10-2866)<0,"0",('MTD Utility Sheet'!F10-2866)/(0.568+0.075)) -> 8430.9798 | L8: ='MTD Utility Sheet'!F10/K8 -> 0.98293677 | M8: ='MTD Utility Sheet'!B10*301 -> 269.997 | N8: 4.6
A9: Amwaj Rotana - Jumeirah Beach | B9: =B8+1 -> 8 | C9: 5 | D9: 2023 | E9: ='MTD Utility Sheet'!G11/0.439 -> 15137.608 | F9: 0.439 | G9: =('MTD Utility Sheet'!I11/2.1)/0.5 -> 488 | H9: =2.1*0.5 -> 1.05 | I9: ='MTD Utility Sheet'!H11/12.38 -> 216.57512 | J9: 12.38 | K9: =IF(('MTD Utility Sheet'!F11-2866)<0,"0",('MTD Utility Sheet'!F11-2866)/(0.568+0.075)) -> 7478.3981 | L9: ='MTD Utility Sheet'!F11/K9 -> 1.0262372 | M9: ='MTD Utility Sheet'!B11*301 -> 301 | N9: 6
A10: Amwaj Rotana - Jumeirah Beach | B10: =B9+1 -> 9 | C10: 5 | D10: 2023 | E10: ='MTD Utility Sheet'!G12/0.439 -> 14649.294 | F10: 0.439 | G10: =('MTD Utility Sheet'!I12/2.1)/0.5 -> 488 | H10: =2.1*0.5 -> 1.05 | I10: ='MTD Utility Sheet'!H12/12.38 -> 210.17771 | J10: 12.38 | K10: =IF(('MTD Utility Sheet'!F12-2866)<0,"0",('MTD Utility Sheet'!F12-2866)/(0.568+0.075)) -> 6650.9487 | L10: ='MTD Utility Sheet'!F12/K10 -> 1.073916 | M10: ='MTD Utility Sheet'!B12*301 -> 295.883 | N10: 8
A11: Amwaj Rotana - Jumeirah Beach | B11: =B10+1 -> 10 | C11: 5 | D11: 2023 | E11: ='MTD Utility Sheet'!G13/0.439 -> 15625.923 | F11: 0.439 | G11: =('MTD Utility Sheet'!I13/2.1)/0.5 -> 439.2 | H11: =2.1*0.5 -> 1.05 | I11: ='MTD Utility Sheet'!H13/12.38 -> 205.91276 | J11: 12.38 | K11: =IF(('MTD Utility Sheet'!F13-2866)<0,"0",('MTD Utility Sheet'!F13-2866)/(0.568+0.075)) -> 7350.451 | L11: ='MTD Utility Sheet'!F13/K11 -> 1.032908 | M11: ='MTD Utility Sheet'!B13*301 -> 283.843 | N11: 8.2
A12: Amwaj Rotana - Jumeirah Beach | B12: =B11+1 -> 11 | C12: 5 | D12: 2023 | E12: ='MTD Utility Sheet'!G14/0.439 -> 14649.294 | F12: 0.439 | G12: =('MTD Utility Sheet'!I14/2.1)/0.5 -> 488 | H12: =2.1*0.5 -> 1.05 | I12: ='MTD Utility Sheet'!H14/12.38 -> 202.71405 | J12: 12.38 | K12: =IF(('MTD Utility Sheet'!F14-2866)<0,"0",('MTD Utility Sheet'!F14-2866)/(0.568+0.075)) -> 7518.2115 | L12: ='MTD Utility Sheet'!F14/K12 -> 1.0242077 | M12: ='MTD Utility Sheet'!B14*301 -> 301 | N12: 8.3
A13: Amwaj Rotana - Jumeirah Beach | B13: =B12+1 -> 12 | C13: 5 | D13: 2023 | E13: ='MTD Utility Sheet'!G15/0.439 -> 16602.528 | F13: 0.439 | G13: =('MTD Utility Sheet'!I15/2.1)/0.5 -> 488 | H13: =2.1*0.5 -> 1.05 | I13: ='MTD Utility Sheet'!H15/12.38 -> 210.17771 | J13: 12.38 | K13: =IF(('MTD Utility Sheet'!F15-2866)<0,"0",('MTD Utility Sheet'!F15-2866)/(0.568+0.075)) -> 9056.5785 | L13: ='MTD Utility Sheet'!F15/K13 -> 0.95945505 | M13: ='MTD Utility Sheet'!B15*301 -> 301.903 | N13: 8.7
A14: Amwaj Rotana - Jumeirah Beach | B14: =B13+1 -> 13 | C14: 5 | D14: 2023 | E14: ='MTD Utility Sheet'!G16/0.439 -> 16114.214 | F14: 0.439 | G14: =('MTD Utility Sheet'!I16/2.1)/0.5 -> 488 | H14: =2.1*0.5 -> 1.05 | I14: ='MTD Utility Sheet'!H16/12.38 -> 219.77383 | J14: 12.38 | K14: =IF(('MTD Utility Sheet'!F16-2866)<0,"0",('MTD Utility Sheet'!F16-2866)/(0.568+0.075)) -> 9821.4463 | L14: ='MTD Utility Sheet'!F16/K14 -> 0.93481038 | M14: ='MTD Utility Sheet'!B16*301 -> 291.97 | N14: 7.9
... A32: Amwaj Rotana - Jumeirah Beach | B32: =B31+1 -> 31 | C32: 5 | D32: 2023 | E32: ='MTD Utility Sheet'!G34/0.439 -> 16114.214 | F32: 0.439 | G32: =('MTD Utility Sheet'!I34/2.1)/0.5 -> 292.8 | H32: =2.1*0.5 -> 1.05 | I32: ='MTD Utility Sheet'!H34/12.38 -> 212.31018 | J32: 12.38 | K32: =IF(('MTD Utility Sheet'!F34-2866)<0,"0",('MTD Utility Sheet'!F34-2866)/(0.568+0.075)) -> 11143.67 | L32: ='MTD Utility Sheet'!F34/K32 -> 0.90018636 | M32: ='MTD Utility Sheet'!B34*301 -> 291.97 | N32: 3.5

Sheet MTD Utility Sheet
A1: Daily Utilities May 2023
B3: Occ % | C3: Out. Temp at 2PM | D3: RH % | E3: F&B Covers | F3: Chilled water | G3: Electricity | H3: Water | I3: LPG | J3: Total
A4: 1 | B4: 1 | C4: 33.89c | D4: 0.4712 | E4: 1306 | F4: 6645.41 | G4: 7232.15 | H4: 2668 | I4: 614.88 | J4: =SUM(F4:I4) -> 17160.44
A5: 2 | B5: 0.9907 | C5: 32.84c | D5: 0.6609 | E5: 1328 | F5: 8016.52 | G5: 6645.41 | H5: 2562.4 | I5: 358.64 | J5: =SUM(F5:I5) -> 17582.97
A6: 3 | B6: 0.9603 | C6: 31.53c | D6: 0.5848 | E6: 1251 | F6: 7597.82 | G6: 6431.04 | H6: 2694.4 | I6: 512.4 | J6: =SUM(F6:I6) -> 17235.66
A7: 4 | B7: 0.9903 | C7: 25.75c | D7: 0.7607 | E7: 1374 | F7: 7833.68 | G7: 7074.14 | H7: 2602 | I7: 512.4 | J7: =SUM(F7:I7) -> 18022.22
A8: 5 | B8: 1.003 | C8: 30.8c | D8: 0.6847 | E8: 1390 | F8: 7850.14 | G8: 6859.78 | H8: 2562.4 | I8: 512.4 | J8: =SUM(F8:I8) -> 17784.72
A9: 6 | B9: 0.94 | C9: 31.01c | D9: 0.7526 | E9: 1393 | F9: 8049.43 | G9: 6645.41 | H9: 2654.8 | I9: 512.4 | J9: =SUM(F9:I9) -> 17862.04
A10: 7 | B10: 0.897 | C10: 32c | D10: 0.728 | E10: 1269 | F10: 8287.12 | G10: 6645.41 | H10: 2404 | I10: 409.92 | J10: =SUM(F10:I10) -> 17746.45
A11: 8 | B11: 1 | C11: 34.13c | D11: 0.696 | E11: 1212 | F11: 7674.61 | G11: 6645.41 | H11: 2681.2 | I11: 512.4 | J11: =SUM(F11:I11) -> 17513.62
A12: 9 | B12: 0.983 | C12: 35.12c | D12: 0.5082 | E12: 1360 | F12: 7142.56 | G12: 6431.04 | H12: 2602 | I12: 512.4 | J12: =SUM(F12:I12) -> 16688
A13: 10 | B13: 0.943 | C13: 35.65c | D13: 0.4868 | E13: 1369 | F13: 7592.34 | G13: 6859.78 | H13: 2549.2 | I13: 461.16 | J13: =SUM(F13:I13) -> 17462.48
A14: 11 | B14: 1 | C14: 30.0c | D14: 0.76 | E14: 1344 | F14: 7700.21 | G14: 6431.04 | H14: 2509.6 | I14: 512.4 | J14: =SUM(F14:I14) -> 17153.25
A15: 12 | B15: 1.003 | C15: 31.0c | D15: 0.76 | E15: 1594 | F15: 8689.38 | G15: 7288.51 | H15: 2602 | I15: 512.4 | J15: =SUM(F15:I15) -> 19092.29
... A20: 17 | B20: 1 | C20: 35.02c | D20: 0.6805 | E20: 1202 | F20: 8497.3 | G20: 6645.41 | H20: 2456.8 | I20: 512.4 | J20: =SUM(F20:I20) -> 18111.91
A21: 18 | B21: 1 | C21: 34.05 | D21: 0.4822 | E21: 1332 | F21: 8230.44 | G21: 7074.14 | H21: 2456.8 | I21: 512.4 | J21: =SUM(F21:I21) -> 18273.78
A22: 19 | B22: 0.9202 | C22: 30.28c | D22: 0.531 | E22: 1400 | F22: 8091.48 | G22: 6859.78 | H22: 2707.6 | I22: 409.92 | J22: =SUM(F22:I22) -> 18068.78
A23: 20 | B23: 0.9302 | C23: 36.29c | D23: 0.424 | E23: 1340 | F23: 8363.91 | G23: 7074.14 | H23: 2470 | I23: 358.68 | J23: =SUM(F23:I23) -> 18266.73
A24: 21 | B24: 0.9806 | C24: 34.19C | D24: 0.4082 | E24: 1109 | F24: 8552.23 | G24: 7074.14 | H24: 2483.2 | I24: 512.4 | J24: =SUM(F24:I24) -> 18621.97
A25: 22 | B25: 0.9803 | C25: 33.10c | D25: 0.4523 | E25: 1118 | F25: 8343.8 | G25: 6645.41 | H25: 2338 | I25: 512.4 | J25: =SUM(F25:I25) -> 17839.61
A26: 23 | B26: 0.953 | C26: 33.75c | D26: 0.631 | E26: 1093 | F26: 8948.99 | G26: 6645.41 | H26: 2456.8 | I26: 307.44 | J26: =SUM(F26:I26) -> 18358.64
A27: 24 | B27: 0.973 | C27: 34.2c | D27: 0.684 | E27: 1031 | F27: 8755.18 | G27: 6859.78 | H27: 2206 | I27: 461.16 | J27: =SUM(F27:I27) -> 18282.12
A28: 25 | B28: 1.003 | C28: 35.34c | D28: 0.5568 | E28: 1097 | F28: 8713.13 | G28: 6859.78 | H28: 2562.4 | I28: 461.16 | J28: =SUM(F28:I28) -> 18596.47
A29: 26 | B29: 1.003 | C29: 37.13c | D29: 0.6728 | E29: 1276 | F29: 8824.66 | G29: 7074.14 | H29: 2470 | I29: 409.92 | J29: =SUM(F29:I29) -> 18778.72
A30: 27 | B30: 1 | C30: 36.0c | D30: 0.67 | E30: 1296 | F30: 9488.36 | G30: 6859.78 | H30: 2615.2 | I30: 461.16 | J30: =SUM(F30:I30) -> 19424.5
A31: 28 | B31: 0.96 | C31: 37.20c | D31: 0.79 | E31: 1130 | F31: 9512.13 | G31: 7074.14 | H31: 2773.6 | I31: 512.4 | J31: =SUM(F31:I31) -> 19872.27
A32: 29 | B32: 0.977 | C32: 38.20c | D32: 0.8 | E32: 1118 | F32: 9691.31 | G32: 7074.14 | H32: 2522.8 | I32: 461.16 | J32: =SUM(F32:I32) -> 19749.41
A33: 30 | B33: 0.93 | C33: 38.50c | D33: 0.7 | E33: 1073 | F33: 10016.76 | G33: 7288.51 | H33: 2668 | I33: 409.92 | J33: =SUM(F33:I33) -> 20383.19
A34: 31 | B34: 0.97 | C34: 37.0c | D34: 0.79 | E34: 1103 | F34: 10031.38 | G34: 7074.14 | H34: 2628.4 | I34: 307.44 | J34: =SUM(F34:I34) -> 20041.36
A35: Total Cost | F35: =SUM(F4:F34) -> 261581.4 | G35: =SUM(G4:G34) -> 212811.06 | H35: =SUM(H4:H34) -> 78708.4 | I35: =SUM(I4:I34) -> 14552.12 | J35: =SUM(J4:J34) -> 567652.98
A36: Total Units | B36: =AVERAGE(B4:B34) -> 0.97027742 | C36: =AVERAGE(C4:C34) -> 34.05 | D36: =AVERAGE(D4:D34) -> 0.64344194 | E36: =SUM(E4:E34) -> 38896 | F36: =F35*0.38 -> 99400.932 | G36: =G35/12.9 -> 16496.981 | H36: =H35/0.92 -> 85552.609 | I36: =I35/1.76 -> 8268.25

Sheet March-26
A1: Daily Utilities Consumption
A2: 26.3.2024
A3: District Cooling
A4: Previous Reading MWh | B4: 60604.53 | C4: Current Reading MWh | D4: 60624.87 | E4: Consumption MWH | F4: =D4-B4 -> 20.34 | G4: Consumption RTH | H4: =F4*284.35 -> 5783.679
A5: Cost Calculation
A6: Total Cost (0.568/rth) | D6: =H4*0.568 -> 3285.1297
A7: Total Fuel Surchage Cost (0.075/rth) | D7: =H4*0.075 -> 433.77593
A8: Chilled Water Demand (2,866 AED/Day) | D8: 2866
A9: Grand Total Exc. VAT | D9: =SUM(D6:H8) -> 6584.9056
A10: Electrical
A11: MDB-G1 (39299675-8) | C11: Previous Reading KWH | D11: 41319 | E11: Current Reading KWH | F11: 41326 | G11: Consumption KWH | H11: =F11-D11 -> 7
A12: MDB-G2 (39299676-6) | C12: Previous Reading KWH | D12: 68380 | E12: Current Reading KWH | F12: 68393 | G12: Consumption KWH | H12: =F12-D12 -> 13
A13: MDB-G3 (39299677-4) | C13: Previous Reading KWH | D13: 69686 | E13: Current Reading KWH | F13: 69697 | G13: Consumption KWH | H13: =F13-D13 -> 11
A14: Total Consumption KWH | H14: =SUM(H11:H13) -> 31
A15: Total Consumption * Multiplication Factor (487.20) | H15: =H14*487.2 -> 15103.2
A16: Cost Calculation
A17: 0-2000 kwh @ 0.230 /KWH | D17: 460
A18: 2000-4000 kwh @ 0.280 /KWH | D18: 560
A19: 4000-6000 kwh @ 0.320 /KWH | D19: 640
A20: 6000 & above @ 0.380 /KWH | D20: =H15*0.38 -> 5739.216
A21: Fuel Surcharge @ 0.060 /KWH | D21: =H15*0.06 -> 906.192
A22: Grand Total Exc. VAT | D22: =D20+D21 -> 6645.408
A23: WATER
A24: Previous Reading | B24: 256020 | C24: Present Reading | D24: 256223 | E24: Consumption m3 | F24: =D24-B24 -> 203 | G24: Consumption IG | H24: =F24*220 -> 44660
A25: Cost calculation
A26: 0-10000 @ 0.035 / IG | D26: 350
A27: 10000-20000 @ 0.04 / IG | D27: 400
A28: 20000 & above @ 0.046 / IG | D28: =(H24-20000)*0.046 -> 1134.36
A29: Fuel Surcharge @ 0.004 / IG | D29: =H24*0.004 -> 178.64
A30: Sewerage Fees | D30: =H24*0.01 -> 446.6
A31: Grand Total Exc. VAT | D31: =SUM(D26:H30) -> 2509.6
A32: LPG Gas
A33: Tank 1 (1% = 48 liters) | C33: Previous Reading % | D33: 80 | E33: Current Reading % | F33: 80 | G33: Consumption Liters | H33: =(D33-F33)*48.8 -> 0
A34: Tank 2 (1% = 48 liters) | C34: Previous Reading % | D34: 32 | E34: Current Reading % | F34: 20 | G34: Consumption Liters | H34: =(D34-F34)*48.8 -> 585.6
A35: Total Cost (@ 1.82 AED/Liter) | H35: =((H34+H33)*1.82)*0.5 -> 532.896
A36: Total Utilities | H36: =H35+D22+D9+D31 -> 16272.81

Sheet March-25
A1: Daily Utilities Consumption
A2: 25.3.2024
A3: District Cooling
A4: Previous Reading MWh | B4: 60581.7 | C4: Current Reading MWh | D4: 60604.53 | E4: Consumption MWH | F4: =D4-B4 -> 22.83 | G4: Consumption RTH | H4: =F4*284.35 -> 6491.7105
A5: Cost Calculation
A6: Total Cost (0.568/rth) | D6: =H4*0.568 -> 3687.2916
A7: Total Fuel Surchage Cost (0.075/rth) | D7: =H4*0.075 -> 486.87829
A8: Chilled Water Demand (2,866 AED/Day) | D8: 2866
A9: Grand Total Exc. VAT | D9: =SUM(D6:H8) -> 7040.1699
A10: Electrical
A11: MDB-G1 (39299675-8) | C11: Previous Reading KWH | D11: 41312 | E11: Current Reading KWH | F11: 41319 | G11: Consumption KWH | H11: =F11-D11 -> 7
A12: MDB-G2 (39299676-6) | C12: Previous Reading KWH | D12: 68367 | E12: Current Reading KWH | F12: 68380 | G12: Consumption KWH | H12: =F12-D12 -> 13
A13: MDB-G3 (39299677-4) | C13: Previous Reading KWH | D13: 69676 | E13: Current Reading KWH | F13: 69686 | G13: Consumption KWH | H13: =F13-D13 -> 10
A14: Total Consumption KWH | H14: =SUM(H11:H13) -> 30
A15: Total Consumption * Multiplication Factor (487.20) | H15: =H14*487.2 -> 14616
A16: Cost Calculation
A17: 0-2000 kwh @ 0.230 /KWH | D17: 460
A18: 2000-4000 kwh @ 0.280 /KWH | D18: 560
A19: 4000-6000 kwh @ 0.320 /KWH | D19: 640
A20: 6000 & above @ 0.380 /KWH | D20: =H15*0.38 -> 5554.08
A21: Fuel Surcharge @ 0.060 /KWH | D21: =H15*0.06 -> 876.96
A22: Grand Total Exc. VAT | D22: =D20+D21 -> 6431.04
A23: WATER
A24: Previous Reading | B24: 255807 | C24: Present Reading | D24: 256020 | E24: Consumption m3 | F24: =D24-B24 -> 213 | G24: Consumption IG | H24: =F24*220 -> 46860
A25: Cost calculation
A26: 0-10000 @ 0.035 / IG | D26: 350
A27: 10000-20000 @ 0.04 / IG | D27: 400
A28: 20000 & above @ 0.046 / IG | D28: =(H24-20000)*0.046 -> 1235.56
A29: Fuel Surcharge @ 0.004 / IG | D29: =H24*0.004 -> 187.44
A30: Sewerage Fees | D30: =H24*0.01 -> 468.6
A31: Grand Total Exc. VAT | D31: =SUM(D26:H30) -> 2641.6
A32: LPG Gas
A33: Tank 1 (1% = 48 liters) | C33: Previous Reading % | D33: 80 | E33: Current Reading % | F33: 80 | G33: Consumption Liters | H33: =(D33-F33)*48.8 -> 0
A34: Tank 2 (1% = 48 liters) | C34: Previous Reading % | D34: 40 | E34: Current Reading % | F34: 32 | G34: Consumption Liters | H34: =(D34-F34)*48.8 -> 390.4
A35: Total Cost (@ 1.82 AED/Liter) | H35: =((H34+H33)*1.82)*0.5 -> 355.264
A36: Total Utilities | H36: =H35+D22+D9+D31 -> 16468.074

Sheet March-24
A1: Daily Utilities Consumption
A2: 24.3.2024
A3: District Cooling
A4: Previous Reading MWh | B4: 60558.88 | C4: Current Reading MWh | D4: 60581.7 | E4: Consumption MWH | F4: =D4-B4 -> 22.82 | G4: Consumption RTH | H4: =F4*284.35 -> 6488.867
A5: Cost Calculation
A6: Total Cost (0.568/rth) | D6: =H4*0.568 -> 3685.6765
A7: Total Fuel Surchage Cost (0.075/rth) | D7: =H4*0.075 -> 486.66502
A8: Chilled Water Demand (2,866 AED/Day) | D8: 2866
A9: Grand Total Exc. VAT | D9: =SUM(D6:H8) -> 7038.3415
A10: Electrical
A11: MDB-G1 (39299675-8) | C11: Previous Reading KWH | D11: 41305 | E11: Current Reading KWH | F11: 41312 | G11: Consumption KWH | H11: =F11-D11 -> 7
A12: MDB-G2 (39299676-6) | C12: Previous Reading KWH | D12: 68354 | E12: Current Reading KWH | F12: 68367 | G12: Consumption KWH | H12: =F12-D12 -> 13
A13: MDB-G3 (39299677-4) | C13: Previous Reading KWH | D13: 69666 | E13: Current Reading KWH | F13: 69676 | G13: Consumption KWH | H13: =F13-D13 -> 10
A14: Total Consumption KWH | H14: =SUM(H11:H13) -> 30
A15: Total Consumption * Multiplication Factor (487.20) | H15: =H14*487.2 -> 14616
A16: Cost Calculation
A17: 0-2000 kwh @ 0.230 /KWH | D17: 460
A18: 2000-4000 kwh @ 0.280 /KWH | D18: 560
A19: 4000-6000 kwh @ 0.320 /KWH | D19: 640
A20: 6000 & above @ 0.380 /KWH | D20: =H15*0.38 -> 5554.08
A21: Fuel Surcharge @ 0.060 /KWH | D21: =H15*0.06 -> 876.96
A22: Grand Total Exc. VAT | D22: =D20+D21 -> 6431.04
A23: WATER
A24: Previous Reading | B24: 255587 | C24: Present Reading | D24: 255807 | E24: Consumption m3 | F24: =D24-B24 -> 220 | G24: Consumption IG | H24: =F24*220 -> 48400
A25: Cost calculation
A26: 0-10000 @ 0.035 / IG | D26: 350
A27: 10000-20000 @ 0.04 / IG | D27: 400
A28: 20000 & above @ 0.046 / IG | D28: =(H24-20000)*0.046 -> 1306.4
A29: Fuel Surcharge @ 0.004 / IG | D29: =H24*0.004 -> 193.6
A30: Sewerage Fees | D30: =H24*0.01 -> 484
A31: Grand Total Exc. VAT | D31: =SUM(D26:H30) -> 2734
A32: LPG Gas
A33: Tank 1 (1% = 48 liters) | C33: Previous Reading % | D33: 80 | E33: Current Reading % | F33: 80 | G33: Consumption Liters | H33: =(D33-F33)*48.8 -> 0
A34: Tank 2 (1% = 48 liters) | C34: Previous Reading % | D34: 52 | E34: Current Reading % | F34: 40 | G34: Consumption Liters | H34: =(D34-F34)*48.8 -> 585.6
A35: Total Cost (@ 1.82 AED/Liter) | H35: =((H34+H33)*1.82)*0.5 -> 532.896
A36: Total Utilities | H36: =H35+D22+D9+D31 -> 16736.277

Sheet March-23
A1: Daily Utilities Consumption
A2: 23.3.2024
A3: District Cooling
A4: Previous Reading MWh | B4: 60536.78 | C4: Current Reading MWh | D4: 60558.88 | E4: Consumption MWH | F4: =D4-B4 -> 22.1 | G4: Consumption RTH | H4: =F4*284.35 -> 6284.135
A5: Cost Calculation
A6: Total Cost (0.568/rth) | D6: =H4*0.568 -> 3569.3887
A7: Total Fuel Surchage Cost (0.075/rth) | D7: =H4*0.075 -> 471.31012
A8: Chilled Water Demand (2,866 AED/Day) | D8: 2866
A9: Grand Total Exc. VAT | D9: =SUM(D6:H8) -> 6906.6988
A10: Electrical
A11: MDB-G1 (39299675-8) | C11: Previous Reading KWH | D11: 41298 | E11: Current Reading KWH | F11: 41305 | G11: Consumption KWH | H11: =F11-D11 -> 7
A12: MDB-G2 (39299676-6) | C12: Previous Reading KWH | D12: 68341 | E12: Current Reading KWH | F12: 68354 | G12: Consumption KWH | H12: =F12-D12 -> 13
A13: MDB-G3 (39299677-4) | C13: Previous Reading KWH | D13: 69655 | E13: Current Reading KWH | F13: 69666 | G13: Consumption KWH | H13: =F13-D13 -> 11
A14: Total Consumption KWH | H14: =SUM(H11:H13) -> 31
A15: Total Consumption * Multiplication Factor (487.20) | H15: =H14*487.2 -> 15103.2
A16: Cost Calculation
A17: 0-2000 kwh @ 0.230 /KWH | D17: 460
A18: 2000-4000 kwh @ 0.280 /KWH | D18: 560
A19: 4000-6000 kwh @ 0.320 /KWH | D19: 640
A20: 6000 & above @ 0.380 /KWH | D20: =H15*0.38 -> 5739.216
A21: Fuel Surcharge @ 0.060 /KWH | D21: =H15*0.06 -> 906.192
A22: Grand Total Exc. VAT | D22: =D20+D21 -> 6645.408
A23: WATER
A24: Previous Reading | B24: 255387 | C24: Present Reading | D24: 255587 | E24: Consumption m3 | F24: =D24-B24 -> 200 | G24: Consumption IG | H24: =F24*220 -> 44000
A25: Cost calculation
A26: 0-10000 @ 0.035 / IG | D26: 350
A27: 10000-20000 @ 0.04 / IG | D27: 400
A28: 20000 & above @ 0.046 / IG | D28: =(H24-20000)*0.046 -> 1104
A29: Fuel Surcharge @ 0.004 / IG | D29: =H24*0.004 -> 176
A30: Sewerage Fees | D30: =H24*0.01 -> 440
A31: Grand Total Exc. VAT | D31: =SUM(D26:H30) -> 2470
A32: LPG Gas
A33: Tank 1 (1% = 48 liters) | C33: Previous Reading % | D33: 80 | E33: Current Reading % | F33: 80 | G33: Consumption Liters | H33: =(D33-F33)*48.8 -> 0
A34: Tank 2 (1% = 48 liters) | C34: Previous Reading % | D34: 61 | E34: Current Reading % | F34: 52 | G34: Consumption Liters | H34: =(D34-F34)*48.8 -> 439.2
A35: Total Cost (@ 1.82 AED/Liter) | H35: =((H34+H33)*1.82)*0.5 -> 399.672
A36: Total Utilities | H36: =H35+D22+D9+D31 -> 16421.779

Sheet March-22
A1: Daily Utilities Consumption
A2: 22.3.2024
A3: District Cooling
A4: Previous Reading MWh | B4: 60515.3 | C4: Current Reading MWh | D4: 60536.78 | E4: Consumption MWH | F4: =D4-B4 -> 21.48 | G4: Consumption RTH | H4: =F4*284.35 -> 6107.838
A5: Cost Calculation
A6: Total Cost (0.568/rth) | D6: =H4*0.568 -> 3469.252
A7: Total Fuel Surchage Cost (0.075/rth) | D7: =H4*0.075 -> 458.08785
A8: Chilled Water Demand (2,866 AED/Day) | D8: 2866
A9: Grand Total Exc. VAT | D9: =SUM(D6:H8) -> 6793.3398
A10: Electrical
A11: MDB-G1 (39299675-8) | C11: Previous Reading KWH | D11: 41292 | E11: Current Reading KWH | F11: 41298 | G11: Consumption KWH | H11: =F11-D11 -> 6
A12: MDB-G2 (39299676-6) | C12: Previous Reading KWH | D12: 68328 | E12: Current Reading KWH | F12: 68341 | G12: Consumption KWH | H12: =F12-D12 -> 13
A13: MDB-G3 (39299677-4) | C13: Previous Reading KWH | D13: 69645 | E13: Current Reading KWH | F13: 69655 | G13: Consumption KWH | H13: =F13-D13 -> 10
A14: Total Consumption KWH | H14: =SUM(H11:H13) -> 29
A15: Total Consumption * Multiplication Factor (487.20) | H15: =H14*487.2 -> 14128.8
A16: Cost Calculation
A17: 0-2000 kwh @ 0.230 /KWH | D17: 460
A18: 2000-4000 kwh @ 0.280 /KWH | D18: 560
A19: 4000-6000 kwh @ 0.320 /KWH | D19: 640
A20: 6000 & above @ 0.380 /KWH | D20: =H15*0.38 -> 5368.944
A21: Fuel Surcharge @ 0.060 /KWH | D21: =H15*0.06 -> 847.728
A22: Grand Total Exc. VAT | D22: =D20+D21 -> 6216.672
A23: WATER
A24: Previous Reading | B24: 255177 | C24: Present Reading | D24: 255387 | E24: Consumption m3 | F24: =D24-B24 -> 210 | G24: Consumption IG | H24: =F24*220 -> 46200
A25: Cost calculation
A26: 0-10000 @ 0.035 / IG | D26: 350
A27: 10000-20000 @ 0.04 / IG | D27: 400
A28: 20000 & above @ 0.046 / IG | D28: =(H24-20000)*0.046 -> 1205.2
A29: Fuel Surcharge @ 0.004 / IG | D29: =H24*0.004 -> 184.8
A30: Sewerage Fees | D30: =H24*0.01 -> 462
A31: Grand Total Exc. VAT | D31: =SUM(D26:H30) -> 2602
A32: LPG Gas
A33: Tank 1 (1% = 48 liters) | C33: Previous Reading % | D33: 80 | E33: Current Reading % | F33: 80 | G33: Consumption Liters | H33: =(D33-F33)*48.8 -> 0
A34: Tank 2 (1% = 48 liters) | C34: Previous Reading % | D34: 71 | E34: Current Reading % | F34: 61 | G34: Consumption Liters | H34: =(D34-F34)*48.8 -> 488
A35: Total Cost (@ 1.82 AED/Liter) | H35: =((H34+H33)*1.82)*0.5 -> 444.08
A36: Total Utilities | H36: =H35+D22+D9+D31 -> 16056.092

Sheet March-21
A1: Daily Utilities Consumption
A2: 21.3.2024
A3: District Cooling
A4: Previous Reading MWh | B4: 60492.24 | C4: Current Reading MWh | D4: 60515.3 | E4: Consumption MWH | F4: =D4-B4 -> 23.06 | G4: Consumption RTH | H4: =F4*284.35 -> 6557.111
A5: Cost Calculation
A6: Total Cost (0.568/rth) | D6: =H4*0.568 -> 3724.439
A7: Total Fuel Surchage Cost (0.075/rth) | D7: =H4*0.075 -> 491.78333
A8: Chilled Water Demand (2,866 AED/Day) | D8: 2866
A9: Grand Total Exc. VAT | D9: =SUM(D6:H8) -> 7082.2224
A10: Electrical
A11: MDB-G1 (39299675-8) | C11: Previous Reading KWH | D11: 41285 | E11: Current Reading KWH | F11: 41292 | G11: Consumption KWH | H11: =F11-D11 -> 7
A12: MDB-G2 (39299676-6) | C12: Previous Reading KWH | D12: 68315 | E12: Current Reading KWH | F12: 68328 | G12: Consumption KWH | H12: =F12-D12 -> 13
A13: MDB-G3 (39299677-4) | C13: Previous Reading KWH | D13: 69635 | E13: Current Reading KWH | F13: 69645 | G13: Consumption KWH | H13: =F13-D13 -> 10
A14: Total Consumption KWH | H14: =SUM(H11:H13) -> 30
A15: Total Consumption * Multiplication Factor (487.20) | H15: =H14*487.2 -> 14616
A16: Cost Calculation
A17: 0-2000 kwh @ 0.230 /KWH | D17: 460
A18: 2000-4000 kwh @ 0.280 /KWH | D18: 560
A19: 4000-6000 kwh @ 0.320 /KWH | D19: 640
A20: 6000 & above @ 0.380 /KWH | D20: =H15*0.38 -> 5554.08
A21: Fuel Surcharge @ 0.060 /KWH | D21: =H15*0.06 -> 876.96
A22: Grand Total Exc. VAT | D22: =D20+D21 -> 6431.04
A23: WATER
A24: Previous Reading | B24: 254976 | C24: Present Reading | D24: 255177 | E24: Consumption m3 | F24: =D24-B24 -> 201 | G24: Consumption IG | H24: =F24*220 -> 44220
A25: Cost calculation
A26: 0-10000 @ 0.035 / IG | D26: 350
A27: 10000-20000 @ 0.04 / IG | D27: 400
A28: 20000 & above @ 0.046 / IG | D28: =(H24-20000)*0.046 -> 1114.12
A29: Fuel Surcharge @ 0.004 / IG | D29: =H24*0.004 -> 176.88
A30: Sewerage Fees | D30: =H24*0.01 -> 442.2
A31: Grand Total Exc. VAT | D31: =SUM(D26:H30) -> 2483.2
A32: LPG Gas
A33: Tank 1 (1% = 48 liters) | C33: Previous Reading % | D33: 23 | E33: Current Reading % | F33: 23 | G33: Consumption Liters | H33: =(D33-F33)*48.8 -> 0
A34: Tank 2 (1% = 48 liters) | C34: Previous Reading % | D34: 80 | E34: Current Reading % | F34: 71 | G34: Consumption Liters | H34: =(D34-F34)*48.8 -> 439.2
A35: Total Cost (@ 1.82 AED/Liter) | H35: =((H34+H33)*1.82)*0.5 -> 399.672
A36: Total Utilities | H36: =H35+D22+D9+D31 -> 16396.134

Sheet March-20
A1: Daily Utilities Consumption
A2: 20.3.2024
A3: District Cooling
A4: Previous Reading MWh | B4: 60470.39 | C4: Current Reading MWh | D4: 60492.24 | E4: Consumption MWH | F4: =D4-B4 -> 21.85 | G4: Consumption RTH | H4: =F4*284.35 -> 6213.0475
A5: Cost Calculation
A6: Total Cost (0.568/rth) | D6: =H4*0.568 -> 3529.011
A7: Total Fuel Surchage Cost (0.075/rth) | D7: =H4*0.075 -> 465.97856
A8: Chilled Water Demand (2,866 AED/Day) | D8: 2866
A9: Grand Total Exc. VAT | D9: =SUM(D6:H8) -> 6860.9895
A10: Electrical
A11: MDB-G1 (39299675-8) | C11: Previous Reading KWH | D11: 41278 | E11: Current Reading KWH | F11: 41285 | G11: Consumption KWH | H11: =F11-D11 -> 7
A12: MDB-G2 (39299676-6) | C12: Previous Reading KWH | D12: 68302 | E12: Current Reading KWH | F12: 68315 | G12: Consumption KWH | H12: =F12-D12 -> 13
A13: MDB-G3 (39299677-4) | C13: Previous Reading KWH | D13: 69626 | E13: Current Reading KWH | F13: 69635 | G13: Consumption KWH | H13: =F13-D13 -> 9
A14: Total Consumption KWH | H14: =SUM(H11:H13) -> 29
A15: Total Consumption * Multiplication Factor (487.20) | H15: =H14*487.2 -> 14128.8
A16: Cost Calculation
A17: 0-2000 kwh @ 0.230 /KWH | D17: 460
A18: 2000-4000 kwh @ 0.280 /KWH | D18: 560
A19: 4000-6000 kwh @ 0.320 /KWH | D19: 640
A20: 6000 & above @ 0.380 /KWH | D20: =H15*0.38 -> 5368.944
A21: Fuel Surcharge @ 0.060 /KWH | D21: =H15*0.06 -> 847.728
A22: Grand Total Exc. VAT | D22: =D20+D21 -> 6216.672
A23: WATER
A24: Previous Reading | B24: 254782 | C24: Present Reading | D24: 254976 | E24: Consumption m3 | F24: =D24-B24 -> 194 | G24: Consumption IG | H24: =F24*220 -> 42680
A25: Cost calculation
A26: 0-10000 @ 0.035 / IG | D26: 350
A27: 10000-20000 @ 0.04 / IG | D27: 400
A28: 20000 & above @ 0.046 / IG | D28: =(H24-20000)*0.046 -> 1043.28
A29: Fuel Surcharge @ 0.004 / IG | D29: =H24*0.004 -> 170.72
A30: Sewerage Fees | D30: =H24*0.01 -> 426.8
A31: Grand Total Exc. VAT | D31: =SUM(D26:H30) -> 2390.8
A32: LPG Gas
A33: Tank 1 (1% = 48 liters) | C33: Previous Reading % | D33: 32 | E33: Current Reading % | F33: 23 | G33: Consumption Liters | H33: =(D33-F33)*48.8 -> 439.2
A34: Tank 2 (1% = 48 liters) | C34: Previous Reading % | D34: 80 | E34: Current Reading % | F34: 80 | G34: Consumption Liters | H34: =(D34-F34)*48.8 -> 0
A35: Total Cost (@ 1.82 AED/Liter) | H35: =((H34+H33)*1.82)*0.5 -> 399.672
A36: Total Utilities | H36: =H35+D22+D9+D31 -> 15868.134

Sheet March-19
A1: Daily Utilities Consumption
A2: 19.3.2024
A3: District Cooling
A4: Previous Reading MWh | B4: 60448.64 | C4: Current Reading MWh | D4: 60470.39 | E4: Consumption MWH | F4: =D4-B4 -> 21.75 | G4: Consumption RTH | H4: =F4*284.35 -> 6184.6125
A5: Cost Calculation
A6: Total Cost (0.568/rth) | D6: =H4*0.568 -> 3512.8599
A7: Total Fuel Surchage Cost (0.075/rth) | D7: =H4*0.075 -> 463.84594
A8: Chilled Water Demand (2,866 AED/Day) | D8: 2866
A9: Grand Total Exc. VAT | D9: =SUM(D6:H8) -> 6842.7058
A10: Electrical
A11: MDB-G1 (39299675-8) | C11: Previous Reading KWH | D11: 41271 | E11: Current Reading KWH | F11: 41278 | G11: Consumption KWH | H11: =F11-D11 -> 7
A12: MDB-G2 (39299676-6) | C12: Previous Reading KWH | D12: 68290 | E12: Current Reading KWH | F12: 68302 | G12: Consumption KWH | H12: =F12-D12 -> 12
A13: MDB-G3 (39299677-4) | C13: Previous Reading KWH | D13: 69615 | E13: Current Reading KWH | F13: 69626 | G13: Consumption KWH | H13: =F13-D13 -> 11
A14: Total Consumption KWH | H14: =SUM(H11:H13) -> 30
A15: Total Consumption * Multiplication Factor (487.20) | H15: =H14*487.2 -> 14616
A16: Cost Calculation
A17: 0-2000 kwh @ 0.230 /KWH | D17: 460
A18: 2000-4000 kwh @ 0.280 /KWH | D18: 560
A19: 4000-6000 kwh @ 0.320 /KWH | D19: 640
A20: 6000 & above @ 0.380 /KWH | D20: =H15*0.38 -> 5554.08
A21: Fuel Surcharge @ 0.060 /KWH | D21: =H15*0.06 -> 876.96
A22: Grand Total Exc. VAT | D22: =D20+D21 -> 6431.04
A23: WATER
A24: Previous Reading | B24: 254584 | C24: Present Reading | D24: 254782 | E24: Consumption m3 | F24: =D24-B24 -> 198 | G24: Consumption IG | H24: =F24*220 -> 43560
A25: Cost calculation
A26: 0-10000 @ 0.035 / IG | D26: 350
A27: 10000-20000 @ 0.04 / IG | D27: 400
A28: 20000 & above @ 0.046 / IG | D28: =(H24-20000)*0.046 -> 1083.76
A29: Fuel Surcharge @ 0.004 / IG | D29: =H24*0.004 -> 174.24
A30: Sewerage Fees | D30: =H24*0.01 -> 435.6
A31: Grand Total Exc. VAT | D31: =SUM(D26:H30) -> 2443.6
A32: LPG Gas
A33: Tank 1 (1% = 48 liters) | C33: Previous Reading % | D33: 40 | E33: Current Reading % | F33: 32 | G33: Consumption Liters | H33: =(D33-F33)*48.8 -> 390.4
A34: Tank 2 (1% = 48 liters) | C34: Previous Reading % | D34: 80 | E34: Current Reading % | F34: 80 | G34: Consumption Liters | H34: =(D34-F34)*48.8 -> 0
A35: Total Cost (@ 1.82 AED/Liter) | H35: =((H34+H33)*1.82)*0.5 -> 355.264
A36: Total Utilities | H36: =H35+D22+D9+D31 -> 16072.61

Sheet March-18
A1: Daily Utilities Consumption
A2: 18.3.2024
A3: District Cooling
A4: Previous Reading MWh | B4: 60426.95 | C4: Current Reading MWh | D4: 60448.64 | E4: Consumption MWH | F4: =D4-B4 -> 21.69 | G4: Consumption RTH | H4: =F4*284.35 -> 6167.5515
A5: Cost Calculation
A6: Total Cost (0.568/rth) | D6: =H4*0.568 -> 3503.1693
A7: Total Fuel Surchage Cost (0.075/rth) | D7: =H4*0.075 -> 462.56636
A8: Chilled Water Demand (2,866 AED/Day) | D8: 2866
A9: Grand Total Exc. VAT | D9: =SUM(D6:H8) -> 6831.7356
A10: Electrical
A11: MDB-G1 (39299675-8) | C11: Previous Reading KWH | D11: 41265 | E11: Current Reading KWH | F11: 41271 | G11: Consumption KWH | H11: =F11-D11 -> 6
A12: MDB-G2 (39299676-6) | C12: Previous Reading KWH | D12: 68278 | E12: Current Reading KWH | F12: 68290 | G12: Consumption KWH | H12: =F12-D12 -> 12
A13: MDB-G3 (39299677-4) | C13: Previous Reading KWH | D13: 69605 | E13: Current Reading KWH | F13: 69615 | G13: Consumption KWH | H13: =F13-D13 -> 10
A14: Total Consumption KWH | H14: =SUM(H11:H13) -> 28
A15: Total Consumption * Multiplication Factor (487.20) | H15: =H14*487.2 -> 13641.6
A16: Cost Calculation
A17: 0-2000 kwh @ 0.230 /KWH | D17: 460
A18: 2000-4000 kwh @ 0.280 /KWH | D18: 560
A19: 4000-6000 kwh @ 0.320 /KWH | D19: 640
A20: 6000 & above @ 0.380 /KWH | D20: =H15*0.38 -> 5183.808
A21: Fuel Surcharge @ 0.060 /KWH | D21: =H15*0.06 -> 818.496
A22: Grand Total Exc. VAT | D22: =D20+D21 -> 6002.304
A23: WATER
A24: Previous Reading | B24: 254410 | C24: Present Reading | D24: 254584 | E24: Consumption m3 | F24: =D24-B24 -> 174 | G24: Consumption IG | H24: =F24*220 -> 38280
A25: Cost calculation
A26: 0-10000 @ 0.035 / IG | D26: 350
A27: 10000-20000 @ 0.04 / IG | D27: 400
A28: 20000 & above @ 0.046 / IG | D28: =(H24-20000)*0.046 -> 840.88
A29: Fuel Surcharge @ 0.004 / IG | D29: =H24*0.004 -> 153.12
A30: Sewerage Fees | D30: =H24*0.01 -> 382.8
A31: Grand Total Exc. VAT | D31: =SUM(D26:H30) -> 2126.8
A32: LPG Gas
A33: Tank 1 (1% = 48 liters) | C33: Previous Reading % | D33: 48 | E33: Current Reading % | F33: 40 | G33: Consumption Liters | H33: =(D33-F33)*48.8 -> 390.4
A34: Tank 2 (1% = 48 liters) | C34: Previous Reading % | D34: 80 | E34: Current Reading % | F34: 80 | G34: Consumption Liters | H34: =(D34-F34)*48.8 -> 0
A35: Total Cost (@ 1.82 AED/Liter) | H35: =((H34+H33)*1.82)*0.5 -> 355.264
A36: Total Utilities | H36: =H35+D22+D9+D31 -> 15316.104

Sheet March-17
A1: Daily Utilities Consumption
A2: 17.3.2024
A3: District Cooling
A4: Previous Reading MWh | B4: 60405.86 | C4: Current Reading MWh | D4: 60426.95 | E4: Consumption MWH | F4: =D4-B4 -> 21.09 | G4: Consumption RTH | H4: =F4*284.35 -> 5996.9415
A5: Cost Calculation
A6: Total Cost (0.568/rth) | D6: =H4*0.568 -> 3406.2628
A7: Total Fuel Surchage Cost (0.075/rth) | D7: =H4*0.075 -> 449.77061
A8: Chilled Water Demand (2,866 AED/Day) | D8: 2866
A9: Grand Total Exc. VAT | D9: =SUM(D6:H8) -> 6722.0334
A10: Electrical
A11: MDB-G1 (39299675-8) | C11: Previous Reading KWH | D11: 41258 | E11: Current Reading KWH | F11: 41265 | G11: Consumption KWH | H11: =F11-D11 -> 7
A12: MDB-G2 (39299676-6) | C12: Previous Reading KWH | D12: 68265 | E12: Current Reading KWH | F12: 68278 | G12: Consumption KWH | H12: =F12-D12 -> 13
A13: MDB-G3 (39299677-4) | C13: Previous Reading KWH | D13: 69594 | E13: Current Reading KWH | F13: 69605 | G13: Consumption KWH | H13: =F13-D13 -> 11
A14: Total Consumption KWH | H14: =SUM(H11:H13) -> 31
A15: Total Consumption * Multiplication Factor (487.20) | H15: =H14*487.2 -> 15103.2
A16: Cost Calculation
A17: 0-2000 kwh @ 0.230 /KWH | D17: 460
A18: 2000-4000 kwh @ 0.280 /KWH | D18: 560
A19: 4000-6000 kwh @ 0.320 /KWH | D19: 640
A20: 6000 & above @ 0.380 /KWH | D20: =H15*0.38 -> 5739.216
A21: Fuel Surcharge @ 0.060 /KWH | D21: =H15*0.06 -> 906.192
A22: Grand Total Exc. VAT | D22: =D20+D21 -> 6645.408
A23: WATER
A24: Previous Reading | B24: 254224 | C24: Present Reading | D24: 254410 | E24: Consumption m3 | F24: =D24-B24 -> 186 | G24: Consumption IG | H24: =F24*220 -> 40920
A25: Cost calculation
A26: 0-10000 @ 0.035 / IG | D26: 350
A27: 10000-20000 @ 0.04 / IG | D27: 400
A28: 20000 & above @ 0.046 / IG | D28: =(H24-20000)*0.046 -> 962.32
A29: Fuel Surcharge @ 0.004 / IG | D29: =H24*0.004 -> 163.68
A30: Sewerage Fees | D30: =H24*0.01 -> 409.2
A31: Grand Total Exc. VAT | D31: =SUM(D26:H30) -> 2285.2
A32: LPG Gas
A33: Tank 1 (1% = 48 liters) | C33: Previous Reading % | D33: 58 | E33: Current Reading % | F33: 48 | G33: Consumption Liters | H33: =(D33-F33)*48.8 -> 488
A34: Tank 2 (1% = 48 liters) | C34: Previous Reading % | D34: 80 | E34: Current Reading % | F34: 80 | G34: Consumption Liters | H34: =(D34-F34)*48.8 -> 0
A35: Total Cost (@ 1.82 AED/Liter) | H35: =((H34+H33)*1.82)*0.5 -> 444.08
A36: Total Utilities | H36: =H35+D22+D9+D31 -> 16096.721

Sheet March-16
A1: Daily Utilities Consumption
A2: 16.3.2024
A3: District Cooling
A4: Previous Reading MWh | B4: 60387.74 | C4: Current Reading MWh | D4: 60405.86 | E4: Consumption MWH | F4: =D4-B4 -> 18.12 | G4: Consumption RTH | H4: =F4*284.35 -> 5152.422
A5: Cost Calculation
A6: Total Cost (0.568/rth) | D6: =H4*0.568 -> 2926.5757
A7: Total Fuel Surchage Cost (0.075/rth) | D7: =H4*0.075 -> 386.43165
A8: Chilled Water Demand (2,866 AED/Day) | D8: 2866
A9: Grand Total Exc. VAT | D9: =SUM(D6:H8) -> 6179.0073
A10: Electrical
A11: MDB-G1 (39299675-8) | C11: Previous Reading KWH | D11: 41251 | E11: Current Reading KWH | F11: 41258 | G11: Consumption KWH | H11: =F11-D11 -> 7
A12: MDB-G2 (39299676-6) | C12: Previous Reading KWH | D12: 68252 | E12: Current Reading KWH | F12: 68265 | G12: Consumption KWH | H12: =F12-D12 -> 13
A13: MDB-G3 (39299677-4) | C13: Previous Reading KWH | D13: 69584 | E13: Current Reading KWH | F13: 69594 | G13: Consumption KWH | H13: =F13-D13 -> 10
A14: Total Consumption KWH | H14: =SUM(H11:H13) -> 30
A15: Total Consumption * Multiplication Factor (487.20) | H15: =H14*487.2 -> 14616
A16: Cost Calculation
A17: 0-2000 kwh @ 0.230 /KWH | D17: 460
A18: 2000-4000 kwh @ 0.280 /KWH | D18: 560
A19: 4000-6000 kwh @ 0.320 /KWH | D19: 640
A20: 6000 & above @ 0.380 /KWH | D20: =H15*0.38 -> 5554.08
A21: Fuel Surcharge @ 0.060 /KWH | D21: =H15*0.06 -> 876.96
A22: Grand Total Exc. VAT | D22: =D20+D21 -> 6431.04
A23: WATER
A24: Previous Reading | B24: 254043 | C24: Present Reading | D24: 254224 | E24: Consumption m3 | F24: =D24-B24 -> 181 | G24: Consumption IG | H24: =F24*220 -> 39820
A25: Cost calculation
A26: 0-10000 @ 0.035 / IG | D26: 350
A27: 10000-20000 @ 0.04 / IG | D27: 400
A28: 20000 & above @ 0.046 / IG | D28: =(H24-20000)*0.046 -> 911.72
A29: Fuel Surcharge @ 0.004 / IG | D29: =H24*0.004 -> 159.28
A30: Sewerage Fees | D30: =H24*0.01 -> 398.2
A31: Grand Total Exc. VAT | D31: =SUM(D26:H30) -> 2219.2
A32: LPG Gas
A33: Tank 1 (1% = 48 liters) | C33: Previous Reading % | D33: 66 | E33: Current Reading % | F33: 58 | G33: Consumption Liters | H33: =(D33-F33)*48.8 -> 390.4
A34: Tank 2 (1% = 48 liters) | C34: Previous Reading % | D34: 80 | E34: Current Reading % | F34: 80 | G34: Consumption Liters | H34: =(D34-F34)*48.8 -> 0
A35: Total Cost (@ 1.82 AED/Liter) | H35: =((H34+H33)*1.82)*0.5 -> 355.264
A36: Total Utilities | H36: =H35+D22+D9+D31 -> 15184.511

Sheet March-15
A1: Daily Utilities Consumption
A2: 15.3.2024
A3: District Cooling
A4: Previous Reading MWh | B4: 60370.76 | C4: Current Reading MWh | D4: 60387.74 | E4: Consumption MWH | F4: =D4-B4 -> 16.98 | G4: Consumption RTH | H4: =F4*284.35 -> 4828.263
A5: Cost Calculation
A6: Total Cost (0.568/rth) | D6: =H4*0.568 -> 2742.4534
A7: Total Fuel Surchage Cost (0.075/rth) | D7: =H4*0.075 -> 362.11972
A8: Chilled Water Demand (2,866 AED/Day) | D8: 2866
A9: Grand Total Exc. VAT | D9: =SUM(D6:H8) -> 5970.5731
A10: Electrical
A11: MDB-G1 (39299675-8) | C11: Previous Reading KWH | D11: 41245 | E11: Current Reading KWH | F11: 41251 | G11: Consumption KWH | H11: =F11-D11 -> 6
A12: MDB-G2 (39299676-6) | C12: Previous Reading KWH | D12: 68239 | E12: Current Reading KWH | F12: 68252 | G12: Consumption KWH | H12: =F12-D12 -> 13
A13: MDB-G3 (39299677-4) | C13: Previous Reading KWH | D13: 69573 | E13: Current Reading KWH | F13: 69584 | G13: Consumption KWH | H13: =F13-D13 -> 11
A14: Total Consumption KWH | H14: =SUM(H11:H13) -> 30
A15: Total Consumption * Multiplication Factor (487.20) | H15: =H14*487.2 -> 14616
A16: Cost Calculation
A17: 0-2000 kwh @ 0.230 /KWH | D17: 460
A18: 2000-4000 kwh @ 0.280 /KWH | D18: 560
A19: 4000-6000 kwh @ 0.320 /KWH | D19: 640
A20: 6000 & above @ 0.380 /KWH | D20: =H15*0.38 -> 5554.08
A21: Fuel Surcharge @ 0.060 /KWH | D21: =H15*0.06 -> 876.96
A22: Grand Total Exc. VAT | D22: =D20+D21 -> 6431.04
A23: WATER
A24: Previous Reading | B24: 253855 | C24: Present Reading | D24: 254043 | E24: Consumption m3 | F24: =D24-B24 -> 188 | G24: Consumption IG | H24: =F24*220 -> 41360
A25: Cost calculation
A26: 0-10000 @ 0.035 / IG | D26: 350
A27: 10000-20000 @ 0.04 / IG | D27: 400
A28: 20000 & above @ 0.046 / IG | D28: =(H24-20000)*0.046 -> 982.56
A29: Fuel Surcharge @ 0.004 / IG | D29: =H24*0.004 -> 165.44
A30: Sewerage Fees | D30: =H24*0.01 -> 413.6
A31: Grand Total Exc. VAT | D31: =SUM(D26:H30) -> 2311.6
A32: LPG Gas
A33: Tank 1 (1% = 48 liters) | C33: Previous Reading % | D33: 75 | E33: Current Reading % | F33: 66 | G33: Consumption Liters | H33: =(D33-F33)*48.8 -> 439.2
A34: Tank 2 (1% = 48 liters) | C34: Previous Reading % | D34: 80 | E34: Current Reading % | F34: 80 | G34: Consumption Liters | H34: =(D34-F34)*48.8 -> 0
A35: Total Cost (@ 1.82 AED/Liter) | H35: =((H34+H33)*1.82)*0.5 -> 399.672
A36: Total Utilities | H36: =H35+D22+D9+D31 -> 15112.885

Sheet March-14
A1: Daily Utilities Consumption
A2: 14.3.2024
A3: District Cooling
A4: Previous Reading MWh | B4: 60353.83 | C4: Current Reading MWh | D4: 60370.76 | E4: Consumption MWH | F4: =D4-B4 -> 16.93 | G4: Consumption RTH | H4: =F4*284.35 -> 4814.0455
A5: Cost Calculation
A6: Total Cost (0.568/rth) | D6: =H4*0.568 -> 2734.3778
A7: Total Fuel Surchage Cost (0.075/rth) | D7: =H4*0.075 -> 361.05341
A8: Chilled Water Demand (2,866 AED/Day) | D8: 2866
A9: Grand Total Exc. VAT | D9: =SUM(D6:H8) -> 5961.4313
A10: Electrical
A11: MDB-G1 (39299675-8) | C11: Previous Reading KWH | D11: 41238 | E11: Current Reading KWH | F11: 41245 | G11: Consumption KWH | H11: =F11-D11 -> 7
A12: MDB-G2 (39299676-6) | C12: Previous Reading KWH | D12: 68227 | E12: Current Reading KWH | F12: 68239 | G12: Consumption KWH | H12: =F12-D12 -> 12
A13: MDB-G3 (39299677-4) | C13: Previous Reading KWH | D13: 69563 | E13: Current Reading KWH | F13: 69573 | G13: Consumption KWH | H13: =F13-D13 -> 10
A14: Total Consumption KWH | H14: =SUM(H11:H13) -> 29
A15: Total Consumption * Multiplication Factor (487.20) | H15: =H14*487.2 -> 14128.8
A16: Cost Calculation
A17: 0-2000 kwh @ 0.230 /KWH | D17: 460
A18: 2000-4000 kwh @ 0.280 /KWH | D18: 560
A19: 4000-6000 kwh @ 0.320 /KWH | D19: 640
A20: 6000 & above @ 0.380 /KWH | D20: =H15*0.38 -> 5368.944
A21: Fuel Surcharge @ 0.060 /KWH | D21: =H15*0.06 -> 847.728
A22: Grand Total Exc. VAT | D22: =D20+D21 -> 6216.672
A23: WATER
A24: Previous Reading | B24: 253701 | C24: Present Reading | D24: 253855 | E24: Consumption m3 | F24: =D24-B24 -> 154 | G24: Consumption IG | H24: =F24*220 -> 33880
A25: Cost calculation
A26: 0-10000 @ 0.035 / IG | D26: 350
A27: 10000-20000 @ 0.04 / IG | D27: 400
A28: 20000 & above @ 0.046 / IG | D28: =(H24-20000)*0.046 -> 638.48
A29: Fuel Surcharge @ 0.004 / IG | D29: =H24*0.004 -> 135.52
A30: Sewerage Fees | D30: =H24*0.01 -> 338.8
A31: Grand Total Exc. VAT | D31: =SUM(D26:H30) -> 1862.8
A32: LPG Gas
A33: Tank 1 (1% = 48 liters) | C33: Previous Reading % | D33: 82 | E33: Current Reading % | F33: 75 | G33: Consumption Liters | H33: =(D33-F33)*48.8 -> 341.6
A34: Tank 2 (1% = 48 liters) | C34: Previous Reading % | D34: 80 | E34: Current Reading % | F34: 80 | G34: Consumption Liters | H34: =(D34-F34)*48.8 -> 0
A35: Total Cost (@ 1.82 AED/Liter) | H35: =((H34+H33)*1.82)*0.5 -> 310.856
A36: Total Utilities | H36: =H35+D22+D9+D31 -> 14351.759

Sheet March-13
A1: Daily Utilities Consumption
A2: 13.3.2024
A3: District Cooling
A4: Previous Reading MWh | B4: 60340.36 | C4: Current Reading MWh | D4: 60353.83 | E4: Consumption MWH | F4: =D4-B4 -> 13.47 | G4: Consumption RTH | H4: =F4*284.35 -> 3830.1945
A5: Cost Calculation
A6: Total Cost (0.568/rth) | D6: =H4*0.568 -> 2175.5505
A7: Total Fuel Surchage Cost (0.075/rth) | D7: =H4*0.075 -> 287.26459
A8: Chilled Water Demand (2,866 AED/Day) | D8: 2866
A9: Grand Total Exc. VAT | D9: =SUM(D6:H8) -> 5328.8151
A10: Electrical
A11: MDB-G1 (39299675-8) | C11: Previous Reading KWH | D11: 41232 | E11: Current Reading KWH | F11: 41238 | G11: Consumption KWH | H11: =F11-D11 -> 6
A12: MDB-G2 (39299676-6) | C12: Previous Reading KWH | D12: 68215 | E12: Current Reading KWH | F12: 68227 | G12: Consumption KWH | H12: =F12-D12 -> 12
A13: MDB-G3 (39299677-4) | C13: Previous Reading KWH | D13: 69554 | E13: Current Reading KWH | F13: 69563 | G13: Consumption KWH | H13: =F13-D13 -> 9
A14: Total Consumption KWH | H14: =SUM(H11:H13) -> 27
A15: Total Consumption * Multiplication Factor (487.20) | H15: =H14*487.2 -> 13154.4
A16: Cost Calculation
A17: 0-2000 kwh @ 0.230 /KWH | D17: 460
A18: 2000-4000 kwh @ 0.280 /KWH | D18: 560
A19: 4000-6000 kwh @ 0.320 /KWH | D19: 640
A20: 6000 & above @ 0.380 /KWH | D20: =H15*0.38 -> 4998.672
A21: Fuel Surcharge @ 0.060 /KWH | D21: =H15*0.06 -> 789.264
A22: Grand Total Exc. VAT | D22: =D20+D21 -> 5787.936
A23: WATER
A24: Previous Reading | B24: 253535 | C24: Present Reading | D24: 253701 | E24: Consumption m3 | F24: =D24-B24 -> 166 | G24: Consumption IG | H24: =F24*220 -> 36520
A25: Cost calculation
A26: 0-10000 @ 0.035 / IG | D26: 350
A27: 10000-20000 @ 0.04 / IG | D27: 400
A28: 20000 & above @ 0.046 / IG | D28: =(H24-20000)*0.046 -> 759.92
A29: Fuel Surcharge @ 0.004 / IG | D29: =H24*0.004 -> 146.08
A30: Sewerage Fees | D30: =H24*0.01 -> 365.2
A31: Grand Total Exc. VAT | D31: =SUM(D26:H30) -> 2021.2
A32: LPG Gas
A33: Tank 1 (1% = 48 liters) | C33: Previous Reading % | D33: 35 | E33: Current Reading % | F33: 28 | G33: Consumption Liters | H33: =(D33-F33)*48.8 -> 341.6
A34: Tank 2 (1% = 48 liters) | C34: Previous Reading % | D34: 80 | E34: Current Reading % | F34: 80 | G34: Consumption Liters | H34: =(D34-F34)*48.8 -> 0
A35: Total Cost (@ 1.82 AED/Liter) | H35: =((H34+H33)*1.82)*0.5 -> 310.856
A36: Total Utilities | H36: =H35+D22+D9+D31 -> 13448.807

Sheet March-12
A1: Daily Utilities Consumption
A2: 12.3.2024
A3: District Cooling
A4: Previous Reading MWh | B4: 60326.2 | C4: Current Reading MWh | D4: 60340.36 | E4: Consumption MWH | F4: =D4-B4 -> 14.16 | G4: Consumption RTH | H4: =F4*284.35 -> 4026.396
A5: Cost Calculation
A6: Total Cost (0.568/rth) | D6: =H4*0.568 -> 2286.9929
A7: Total Fuel Surchage Cost (0.075/rth) | D7: =H4*0.075 -> 301.9797
A8: Chilled Water Demand (2,866 AED/Day) | D8: 2866
A9: Grand Total Exc. VAT | D9: =SUM(D6:H8) -> 5454.9726
A10: Electrical
A11: MDB-G1 (39299675-8) | C11: Previous Reading KWH | D11: 41225 | E11: Current Reading KWH | F11: 41232 | G11: Consumption KWH | H11: =F11-D11 -> 7
A12: MDB-G2 (39299676-6) | C12: Previous Reading KWH | D12: 68202 | E12: Current Reading KWH | F12: 68215 | G12: Consumption KWH | H12: =F12-D12 -> 13
A13: MDB-G3 (39299677-4) | C13: Previous Reading KWH | D13: 69544 | E13: Current Reading KWH | F13: 69554 | G13: Consumption KWH | H13: =F13-D13 -> 10
A14: Total Consumption KWH | H14: =SUM(H11:H13) -> 30
A15: Total Consumption * Multiplication Factor (487.20) | H15: =H14*487.2 -> 14616
A16: Cost Calculation
A17: 0-2000 kwh @ 0.230 /KWH | D17: 460
A18: 2000-4000 kwh @ 0.280 /KWH | D18: 560
A19: 4000-6000 kwh @ 0.320 /KWH | D19: 640
A20: 6000 & above @ 0.380 /KWH | D20: =H15*0.38 -> 5554.08
A21: Fuel Surcharge @ 0.060 /KWH | D21: =H15*0.06 -> 876.96
A22: Grand Total Exc. VAT | D22: =D20+D21 -> 6431.04
A23: WATER
A24: Previous Reading | B24: 253372 | C24: Present Reading | D24: 253535 | E24: Consumption m3 | F24: =D24-B24 -> 163 | G24: Consumption IG | H24: =F24*220 -> 35860
A25: Cost calculation
A26: 0-10000 @ 0.035 / IG | D26: 350
A27: 10000-20000 @ 0.04 / IG | D27: 400
A28: 20000 & above @ 0.046 / IG | D28: =(H24-20000)*0.046 -> 729.56
A29: Fuel Surcharge @ 0.004 / IG | D29: =H24*0.004 -> 143.44
A30: Sewerage Fees | D30: =H24*0.01 -> 358.6
A31: Grand Total Exc. VAT | D31: =SUM(D26:H30) -> 1981.6
A32: LPG Gas
A33: Tank 1 (1% = 48 liters) | C33: Previous Reading % | D33: 45 | E33: Current Reading % | F33: 35 | G33: Consumption Liters | H33: =(D33-F33)*48.8 -> 488
A34: Tank 2 (1% = 48 liters) | C34: Previous Reading % | D34: 80 | E34: Current Reading % | F34: 80 | G34: Consumption Liters | H34: =(D34-F34)*48.8 -> 0
A35: Total Cost (@ 1.82 AED/Liter) | H35: =((H34+H33)*1.82)*0.5 -> 444.08
A36: Total Utilities | H36: =H35+D22+D9+D31 -> 14311.693

Sheet March-11
A1: Daily Utilities Consumption
A2: 11.3.2024
A3: District Cooling
A4: Previous Reading MWh | B4: 60312.25 | C4: Current Reading MWh | D4: 60326.2 | E4: Consumption MWH | F4: =D4-B4 -> 13.95 | G4: Consumption RTH | H4: =F4*284.35 -> 3966.6825
A5: Cost Calculation
A6: Total Cost (0.568/rth) | D6: =H4*0.568 -> 2253.0757
A7: Total Fuel Surchage Cost (0.075/rth) | D7: =H4*0.075 -> 297.50119
A8: Chilled Water Demand (2,866 AED/Day) | D8: 2866
A9: Grand Total Exc. VAT | D9: =SUM(D6:H8) -> 5416.5768
A10: Electrical
A11: MDB-G1 (39299675-8) | C11: Previous Reading KWH | D11: 41219 | E11: Current Reading KWH | F11: 41225 | G11: Consumption KWH | H11: =F11-D11 -> 6
A12: MDB-G2 (39299676-6) | C12: Previous Reading KWH | D12: 68190 | E12: Current Reading KWH | F12: 68202 | G12: Consumption KWH | H12: =F12-D12 -> 12
A13: MDB-G3 (39299677-4) | C13: Previous Reading KWH | D13: 69534 | E13: Current Reading KWH | F13: 69544 | G13: Consumption KWH | H13: =F13-D13 -> 10
A14: Total Consumption KWH | H14: =SUM(H11:H13) -> 28
A15: Total Consumption * Multiplication Factor (487.20) | H15: =H14*487.2 -> 13641.6
A16: Cost Calculation
A17: 0-2000 kwh @ 0.230 /KWH | D17: 460
A18: 2000-4000 kwh @ 0.280 /KWH | D18: 560
A19: 4000-6000 kwh @ 0.320 /KWH | D19: 640
A20: 6000 & above @ 0.380 /KWH | D20: =H15*0.38 -> 5183.808
A21: Fuel Surcharge @ 0.060 /KWH | D21: =H15*0.06 -> 818.496
A22: Grand Total Exc. VAT | D22: =D20+D21 -> 6002.304
A23: WATER
A24: Previous Reading | B24: 253210 | C24: Present Reading | D24: 253372 | E24: Consumption m3 | F24: =D24-B24 -> 162 | G24: Consumption IG | H24: =F24*220 -> 35640
A25: Cost calculation
A26: 0-10000 @ 0.035 / IG | D26: 350
A27: 10000-20000 @ 0.04 / IG | D27: 400
A28: 20000 & above @ 0.046 / IG | D28: =(H24-20000)*0.046 -> 719.44
A29: Fuel Surcharge @ 0.004 / IG | D29: =H24*0.004 -> 142.56
A30: Sewerage Fees | D30: =H24*0.01 -> 356.4
A31: Grand Total Exc. VAT | D31: =SUM(D26:H30) -> 1968.4
A32: LPG Gas
A33: Tank 1 (1% = 48 liters) | C33: Previous Reading % | D33: 55 | E33: Current Reading % | F33: 45 | G33: Consumption Liters | H33: =(D33-F33)*48.8 -> 488
A34: Tank 2 (1% = 48 liters) | C34: Previous Reading % | D34: 80 | E34: Current Reading % | F34: 80 | G34: Consumption Liters | H34: =(D34-F34)*48.8 -> 0
A35: Total Cost (@ 1.82 AED/Liter) | H35: =((H34+H33)*1.82)*0.5 -> 444.08
A36: Total Utilities | H36: =H35+D22+D9+D31 -> 13831.361

Sheet March-10
A1: Daily Utilities Consumption
A2: 10.3.2024
A3: District Cooling
A4: Previous Reading MWh | B4: 60298.31 | C4: Current Reading MWh | D4: 60312.25 | E4: Consumption MWH | F4: =D4-B4 -> 13.94 | G4: Consumption RTH | H4: =F4*284.35 -> 3963.839
A5: Cost Calculation
A6: Total Cost (0.568/rth) | D6: =H4*0.568 -> 2251.4606
A7: Total Fuel Surchage Cost (0.075/rth) | D7: =H4*0.075 -> 297.28793
A8: Chilled Water Demand (2,866 AED/Day) | D8: 2866
A9: Grand Total Exc. VAT | D9: =SUM(D6:H8) -> 5414.7485
A10: Electrical
A11: MDB-G1 (39299675-8) | C11: Previous Reading KWH | D11: 41212 | E11: Current Reading KWH | F11: 41219 | G11: Consumption KWH | H11: =F11-D11 -> 7
A12: MDB-G2 (39299676-6) | C12: Previous Reading KWH | D12: 68177 | E12: Current Reading KWH | F12: 68190 | G12: Consumption KWH | H12: =F12-D12 -> 13
A13: MDB-G3 (39299677-4) | C13: Previous Reading KWH | D13: 69524 | E13: Current Reading KWH | F13: 69534 | G13: Consumption KWH | H13: =F13-D13 -> 10
A14: Total Consumption KWH | H14: =SUM(H11:H13) -> 30
A15: Total Consumption * Multiplication Factor (487.20) | H15: =H14*487.2 -> 14616
A16: Cost Calculation
A17: 0-2000 kwh @ 0.230 /KWH | D17: 460
A18: 2000-4000 kwh @ 0.280 /KWH | D18: 560
A19: 4000-6000 kwh @ 0.320 /KWH | D19: 640
A20: 6000 & above @ 0.380 /KWH | D20: =H15*0.38 -> 5554.08
A21: Fuel Surcharge @ 0.060 /KWH | D21: =H15*0.06 -> 876.96
A22: Grand Total Exc. VAT | D22: =D20+D21 -> 6431.04
A23: WATER
A24: Previous Reading | B24: 253032 | C24: Present Reading | D24: 253210 | E24: Consumption m3 | F24: =D24-B24 -> 178 | G24: Consumption IG | H24: =F24*220 -> 39160
A25: Cost calculation
A26: 0-10000 @ 0.035 / IG | D26: 350
A27: 10000-20000 @ 0.04 / IG | D27: 400
A28: 20000 & above @ 0.046 / IG | D28: =(H24-20000)*0.046 -> 881.36
A29: Fuel Surcharge @ 0.004 / IG | D29: =H24*0.004 -> 156.64
A30: Sewerage Fees | D30: =H24*0.01 -> 391.6
A31: Grand Total Exc. VAT | D31: =SUM(D26:H30) -> 2179.6
A32: LPG Gas
A33: Tank 1 (1% = 48 liters) | C33: Previous Reading % | D33: 63 | E33: Current Reading % | F33: 55 | G33: Consumption Liters | H33: =(D33-F33)*48.8 -> 390.4
A34: Tank 2 (1% = 48 liters) | C34: Previous Reading % | D34: 80 | E34: Current Reading % | F34: 80 | G34: Consumption Liters | H34: =(D34-F34)*48.8 -> 0
A35: Total Cost (@ 1.82 AED/Liter) | H35: =((H34+H33)*1.82)*0.5 -> 355.264
A36: Total Utilities | H36: =H35+D22+D9+D31 -> 14380.652

Sheet March-09
A1: Daily Utilities Consumption
A2: 09.3.2024
A3: District Cooling
A4: Previous Reading MWh | B4: 60284.17 | C4: Current Reading MWh | D4: 60298.31 | E4: Consumption MWH | F4: =D4-B4 -> 14.14 | G4: Consumption RTH | H4: =F4*284.35 -> 4020.709
A5: Cost Calculation
A6: Total Cost (0.568/rth) | D6: =H4*0.568 -> 2283.7627
A7: Total Fuel Surchage Cost (0.075/rth) | D7: =H4*0.075 -> 301.55317
A8: Chilled Water Demand (2,866 AED/Day) | D8: 2866
A9: Grand Total Exc. VAT | D9: =SUM(D6:H8) -> 5451.3159
A10: Electrical
A11: MDB-G1 (39299675-8) | C11: Previous Reading KWH | D11: 41205 | E11: Current Reading KWH | F11: 41212 | G11: Consumption KWH | H11: =F11-D11 -> 7
A12: MDB-G2 (39299676-6) | C12: Previous Reading KWH | D12: 68164 | E12: Current Reading KWH | F12: 68177 | G12: Consumption KWH | H12: =F12-D12 -> 13
A13: MDB-G3 (39299677-4) | C13: Previous Reading KWH | D13: 69513 | E13: Current Reading KWH | F13: 69524 | G13: Consumption KWH | H13: =F13-D13 -> 11
A14: Total Consumption KWH | H14: =SUM(H11:H13) -> 31
A15: Total Consumption * Multiplication Factor (487.20) | H15: =H14*487.2 -> 15103.2
A16: Cost Calculation
A17: 0-2000 kwh @ 0.230 /KWH | D17: 460
A18: 2000-4000 kwh @ 0.280 /KWH | D18: 560
A19: 4000-6000 kwh @ 0.320 /KWH | D19: 640
A20: 6000 & above @ 0.380 /KWH | D20: =H15*0.38 -> 5739.216
A21: Fuel Surcharge @ 0.060 /KWH | D21: =H15*0.06 -> 906.192
A22: Grand Total Exc. VAT | D22: =D20+D21 -> 6645.408
A23: WATER
A24: Previous Reading | B24: 252842 | C24: Present Reading | D24: 253032 | E24: Consumption m3 | F24: =D24-B24 -> 190 | G24: Consumption IG | H24: =F24*220 -> 41800
A25: Cost calculation
A26: 0-10000 @ 0.035 / IG | D26: 350
A27: 10000-20000 @ 0.04 / IG | D27: 400
A28: 20000 & above @ 0.046 / IG | D28: =(H24-20000)*0.046 -> 1002.8
A29: Fuel Surcharge @ 0.004 / IG | D29: =H24*0.004 -> 167.2
A30: Sewerage Fees | D30: =H24*0.01 -> 418
A31: Grand Total Exc. VAT | D31: =SUM(D26:H30) -> 2338
A32: LPG Gas
A33: Tank 1 (1% = 48 liters) | C33: Previous Reading % | D33: 72 | E33: Current Reading % | F33: 63 | G33: Consumption Liters | H33: =(D33-F33)*48.8 -> 439.2
A34: Tank 2 (1% = 48 liters) | C34: Previous Reading % | D34: 80 | E34: Current Reading % | F34: 80 | G34: Consumption Liters | H34: =(D34-F34)*48.8 -> 0
A35: Total Cost (@ 1.82 AED/Liter) | H35: =((H34+H33)*1.82)*0.5 -> 399.672
A36: Total Utilities | H36: =H35+D22+D9+D31 -> 14834.396

Sheet March-08
A1: Daily Utilities Consumption
A2: 08.3.2024
A3: District Cooling
A4: Previous Reading MWh | B4: 60267.33 | C4: Current Reading MWh | D4: 60284.17 | E4: Consumption MWH | F4: =D4-B4 -> 16.84 | G4: Consumption RTH | H4: =F4*284.35 -> 4788.454
A5: Cost Calculation
A6: Total Cost (0.568/rth) | D6: =H4*0.568 -> 2719.8419
A7: Total Fuel Surchage Cost (0.075/rth) | D7: =H4*0.075 -> 359.13405
A8: Chilled Water Demand (2,866 AED/Day) | D8: 2866
A9: Grand Total Exc. VAT | D9: =SUM(D6:H8) -> 5944.9759
A10: Electrical
A11: MDB-G1 (39299675-8) | C11: Previous Reading KWH | D11: 41198 | E11: Current Reading KWH | F11: 41205 | G11: Consumption KWH | H11: =F11-D11 -> 7
A12: MDB-G2 (39299676-6) | C12: Previous Reading KWH | D12: 68151 | E12: Current Reading KWH | F12: 68164 | G12: Consumption KWH | H12: =F12-D12 -> 13
A13: MDB-G3 (39299677-4) | C13: Previous Reading KWH | D13: 69503 | E13: Current Reading KWH | F13: 69513 | G13: Consumption KWH | H13: =F13-D13 -> 10
A14: Total Consumption KWH | H14: =SUM(H11:H13) -> 30
A15: Total Consumption * Multiplication Factor (487.20) | H15: =H14*487.2 -> 14616
A16: Cost Calculation
A17: 0-2000 kwh @ 0.230 /KWH | D17: 460
A18: 2000-4000 kwh @ 0.280 /KWH | D18: 560
A19: 4000-6000 kwh @ 0.320 /KWH | D19: 640
A20: 6000 & above @ 0.380 /KWH | D20: =H15*0.38 -> 5554.08
A21: Fuel Surcharge @ 0.060 /KWH | D21: =H15*0.06 -> 876.96
A22: Grand Total Exc. VAT | D22: =D20+D21 -> 6431.04
A23: WATER
A24: Previous Reading | B24: 252622 | C24: Present Reading | D24: 252842 | E24: Consumption m3 | F24: =D24-B24 -> 220 | G24: Consumption IG | H24: =F24*220 -> 48400
A25: Cost calculation
A26: 0-10000 @ 0.035 / IG | D26: 350
A27: 10000-20000 @ 0.04 / IG | D27: 400
A28: 20000 & above @ 0.046 / IG | D28: =(H24-20000)*0.046 -> 1306.4
A29: Fuel Surcharge @ 0.004 / IG | D29: =H24*0.004 -> 193.6
A30: Sewerage Fees | D30: =H24*0.01 -> 484
A31: Grand Total Exc. VAT | D31: =SUM(D26:H30) -> 2734
A32: LPG Gas
A33: Tank 1 (1% = 48 liters) | C33: Previous Reading % | D33: 80 | E33: Current Reading % | F33: 72 | G33: Consumption Liters | H33: =(D33-F33)*48.8 -> 390.4
A34: Tank 2 (1% = 48 liters) | C34: Previous Reading % | D34: 80 | E34: Current Reading % | F34: 80 | G34: Consumption Liters | H34: =(D34-F34)*48.8 -> 0
A35: Total Cost (@ 1.82 AED/Liter) | H35: =((H34+H33)*1.82)*0.5 -> 355.264
A36: Total Utilities | H36: =H35+D22+D9+D31 -> 15465.28

Sheet March-07
A1: Daily Utilities Consumption
A2: 07.3.2024
A3: District Cooling
A4: Previous Reading MWh | B4: 60253.95 | C4: Current Reading MWh | D4: 60267.33 | E4: Consumption MWH | F4: =D4-B4 -> 13.38 | G4: Consumption RTH | H4: =F4*284.35 -> 3804.603
A5: Cost Calculation
A6: Total Cost (0.568/rth) | D6: =H4*0.568 -> 2161.0145
A7: Total Fuel Surchage Cost (0.075/rth) | D7: =H4*0.075 -> 285.34523
A8: Chilled Water Demand (2,866 AED/Day) | D8: 2866
A9: Grand Total Exc. VAT | D9: =SUM(D6:H8) -> 5312.3597
A10: Electrical
A11: MDB-G1 (39299675-8) | C11: Previous Reading KWH | D11: 41191 | E11: Current Reading KWH | F11: 41198 | G11: Consumption KWH | H11: =F11-D11 -> 7
A12: MDB-G2 (39299676-6) | C12: Previous Reading KWH | D12: 68139 | E12: Current Reading KWH | F12: 68151 | G12: Consumption KWH | H12: =F12-D12 -> 12
A13: MDB-G3 (39299677-4) | C13: Previous Reading KWH | D13: 69493 | E13: Current Reading KWH | F13: 69503 | G13: Consumption KWH | H13: =F13-D13 -> 10
A14: Total Consumption KWH | H14: =SUM(H11:H13) -> 29
A15: Total Consumption * Multiplication Factor (487.20) | H15: =H14*487.2 -> 14128.8
A16: Cost Calculation
A17: 0-2000 kwh @ 0.230 /KWH | D17: 460
A18: 2000-4000 kwh @ 0.280 /KWH | D18: 560
A19: 4000-6000 kwh @ 0.320 /KWH | D19: 640
A20: 6000 & above @ 0.380 /KWH | D20: =H15*0.38 -> 5368.944
A21: Fuel Surcharge @ 0.060 /KWH | D21: =H15*0.06 -> 847.728
A22: Grand Total Exc. VAT | D22: =D20+D21 -> 6216.672
A23: WATER
A24: Previous Reading | B24: 252418 | C24: Present Reading | D24: 252622 | E24: Consumption m3 | F24: =D24-B24 -> 204 | G24: Consumption IG | H24: =F24*220 -> 44880
A25: Cost calculation
A26: 0-10000 @ 0.035 / IG | D26: 350
A27: 10000-20000 @ 0.04 / IG | D27: 400
A28: 20000 & above @ 0.046 / IG | D28: =(H24-20000)*0.046 -> 1144.48
A29: Fuel Surcharge @ 0.004 / IG | D29: =H24*0.004 -> 179.52
A30: Sewerage Fees | D30: =H24*0.01 -> 448.8
A31: Grand Total Exc. VAT | D31: =SUM(D26:H30) -> 2522.8
A32: LPG Gas
A33: Tank 1 (1% = 48 liters) | C33: Previous Reading % | D33: 70 | E33: Current Reading % | F33: 62 | G33: Consumption Liters | H33: =(D33-F33)*48.8 -> 390.4
A34: Tank 2 (1% = 48 liters) | C34: Previous Reading % | D34: 20 | E34: Current Reading % | F34: 20 | G34: Consumption Liters | H34: =(D34-F34)*48.8 -> 0
A35: Total Cost (@ 1.82 AED/Liter) | H35: =((H34+H33)*1.82)*0.5 -> 355.264
A36: Total Utilities | H36: =H35+D22+D9+D31 -> 14407.096

Sheet March-06
A1: Daily Utilities Consumption
A2: 06.3.2024
A3: District Cooling
A4: Previous Reading MWh | B4: 60241.09 | C4: Current Reading MWh | D4: 60253.95 | E4: Consumption MWH | F4: =D4-B4 -> 12.86 | G4: Consumption RTH | H4: =F4*284.35 -> 3656.741
A5: Cost Calculation
A6: Total Cost (0.568/rth) | D6: =H4*0.568 -> 2077.0289
