Workbook

Sheet TOTAL
A1: Site Name | B1: Day | C1: Month | D1: Year | E1: Total Electricity Kwh | F1: Electricity Tariff ($/Kwh) | G1: LPG (Liters) | H1: LPG $/Liters | I1: Water Utility Supply (m3) m3 | J1: Water Utility Supply (m3) $/m3 | K1: District Energy Cooling RTH | L1: District Energy Cooling $/RTH | M1: Room Nights | N1: Total Guests
A2: Amwaj Rotana - Jumeirah Beach | B2: 1 | C2: 5 | D2: 2024 | E2: ='MTD Utility Sheet'!G4/0.439 -> 14160.979 | F2: 0.439 | G2: =('MTD Utility Sheet'!I4/1.82)/0.5 -> 488 | H2: =1.82*0.5 -> 0.91 | I2: ='MTD Utility Sheet'!H4/12.38 -> 233.63489 | J2: 12.38 | K2: =IF(('MTD Utility Sheet'!F4-2866)<0,"0",('MTD Utility Sheet'!F4-2866)/(0.568+0.075)) -> 8445.1944 | L2: ='MTD Utility Sheet'!F4/K2 -> 0.9823646 | M2: ='MTD Utility Sheet'!B4*301 -> 291.97
A3: Amwaj Rotana - Jumeirah Beach | B3: =B2+1 -> 2 | C3: 5 | D3: 2024 | E3: ='MTD Utility Sheet'!G5/0.439 -> 14160.979 | F3: 0.439 | G3: =('MTD Utility Sheet'!I5/1.82)/0.5 -> 487.91209 | H3: =1.82*0.5 -> 0.91 | I3: ='MTD Utility Sheet'!H5/12.38 -> 205.91276 | J3: 12.38 | K3: =IF(('MTD Utility Sheet'!F5-2866)<0,"0",('MTD Utility Sheet'!F5-2866)/(0.568+0.075)) -> 8493.0016 | L3: ='MTD Utility Sheet'!F5/K3 -> 0.98045431 | M3: ='MTD Utility Sheet'!B5*301 -> 274.9936
A4: Amwaj Rotana - Jumeirah Beach | B4: =B3+1 -> 3 | C4: 5 | D4: 2024 | E4: ='MTD Utility Sheet'!G6/0.439 -> 15137.608 | F4: 0.439 | G4: =('MTD Utility Sheet'!I6/1.82)/0.5 -> 488 | H4: =1.82*0.5 -> 0.91 | I4: ='MTD Utility Sheet'!H6/12.38 -> 221.9063 | J4: 12.38 | K4: =IF(('MTD Utility Sheet'!F6-2866)<0,"0",('MTD Utility Sheet'!F6-2866)/(0.568+0.075)) -> 8374.1058 | L4: ='MTD Utility Sheet'!F6/K4 -> 0.9852455 | M4: ='MTD Utility Sheet'!B6*301 -> 292.873
A5: Amwaj Rotana - Jumeirah Beach | B5: =B4+1 -> 4 | C5: 5 | D5: 2024 | E5: ='MTD Utility Sheet'!G7/0.439 -> 15137.608 | F5: 0.439 | G5: =('MTD Utility Sheet'!I7/1.82)/0.5 -> 488 | H5: =1.82*0.5 -> 0.91 | I5: ='MTD Utility Sheet'!H7/12.38 -> 221.9063 | J5: 12.38 | K5: =IF(('MTD Utility Sheet'!F7-2866)<0,"0",('MTD Utility Sheet'!F7-2866)/(0.568+0.075)) -> 8445.1944 | L5: ='MTD Utility Sheet'!F7/K5 -> 0.9823646 | M5: ='MTD Utility Sheet'!B7*301 -> 298.893
A6: Amwaj Rotana - Jumeirah Beach | B6: =B5+1 -> 5 | C6: 5 | D6: 2024 | E6: ='MTD Utility Sheet'!G8/0.439 -> 14649.294 | F6: 0.439 | G6: =('MTD Utility Sheet'!I8/1.82)/0.5 -> 488 | H6: =1.82*0.5 -> 0.91 | I6: ='MTD Utility Sheet'!H8/12.38 -> 214.44265 | J6: 12.38 | K6: =IF(('MTD Utility Sheet'!F8-2866)<0,"0",('MTD Utility Sheet'!F8-2866)/(0.568+0.075)) -> 8479.3157 | L6: ='MTD Utility Sheet'!F8/K6 -> 0.98099897 | M6: ='MTD Utility Sheet'!B8*301 -> 273.91
A7: Amwaj Rotana - Jumeirah Beach | B7: =B6+1 -> 6 | C7: 5 | D7: 2024 | E7: ='MTD Utility Sheet'!G9/0.439 -> 14649.294 | F7: 0.439 | G7: =('MTD Utility Sheet'!I9/1.82)/0.5 -> 488 | H7: =1.82*0.5 -> 0.91 | I7: ='MTD Utility Sheet'!H9/12.38 -> 204.84653 | J7: 12.38 | K7: =IF(('MTD Utility Sheet'!F9-2866)<0,"0",('MTD Utility Sheet'!F9-2866)/(0.568+0.075)) -> 8405.381 | L7: ='MTD Utility Sheet'!F9/K7 -> 0.98397205 | M7: ='MTD Utility Sheet'!B9*301 -> 266.084
A8: Amwaj Rotana - Jumeirah Beach | B8: =B7+1 -> 7 | C8: 5 | D8: 2024 | E8: ='MTD Utility Sheet'!G10/0.439 -> 15137.608 | F8: 0.439 | G8: =('MTD Utility Sheet'!I10/1.82)/0.5 -> 488 | H8: =1.82*0.5 -> 0.91 | I8: ='MTD Utility Sheet'!H10/12.38 -> 178.19063 | J8: 12.38 | K8: =IF(('MTD Utility Sheet'!F10-2866)<0,"0",('MTD Utility Sheet'!F10-2866)/(0.568+0.075)) -> 8985.4588 | L8: ='MTD Utility Sheet'!F10/K8 -> 0.96195978 | M8: ='MTD Utility Sheet'!B10*301 -> 282.94
A9: Amwaj Rotana - Jumeirah Beach | B9: =B8+1 -> 8 | C9: 5 | D9: 2024 | E9: ='MTD Utility Sheet'!G11/0.439 -> 14649.294 | F9: 0.439 | G9: =('MTD Utility Sheet'!I11/1.82)/0.5 -> 488 | H9: =1.82*0.5 -> 0.91 | I9: ='MTD Utility Sheet'!H11/12.38 -> 204.84653 | J9: 12.38 | K9: =IF(('MTD Utility Sheet'!F11-2866)<0,"0",('MTD Utility Sheet'!F11-2866)/(0.568+0.075)) -> 8248.9891 | L9: ='MTD Utility Sheet'!F11/K9 -> 0.99043651 | M9: ='MTD Utility Sheet'!B11*301 -> 294.98
A10: Amwaj Rotana - Jumeirah Beach | B10: =B9+1 -> 9 | C10: 5 | D10: 2024 | E10: ='MTD Utility Sheet'!G12/0.439 -> 14159.453 | F10: 0.439 | G10: =('MTD Utility Sheet'!I12/1.82)/0.5 -> 487.91209 | H10: =1.82*0.5 -> 0.91 | I10: ='MTD Utility Sheet'!H12/12.38 -> 185.62197 | J10: 12.38 | K10: =IF(('MTD Utility Sheet'!F12-2866)<0,"0",('MTD Utility Sheet'!F12-2866)/(0.568+0.075)) -> 10776.858 | L10: ='MTD Utility Sheet'!F12/K10 -> 0.90894021 | M10: ='MTD Utility Sheet'!B12*301 -> 266.987
A11: Amwaj Rotana - Jumeirah Beach | B11: =B10+1 -> 10 | C11: 5 | D11: 2024 | E11: ='MTD Utility Sheet'!G13/0.439 -> 16114.214 | F11: 0.439 | G11: =('MTD Utility Sheet'!I13/1.82)/0.5 -> 488 | H11: =1.82*0.5 -> 0.91 | I11: ='MTD Utility Sheet'!H13/12.38 -> 216.57512 | J11: 12.38 | K11: =IF(('MTD Utility Sheet'!F13-2866)<0,"0",('MTD Utility Sheet'!F13-2866)/(0.568+0.075)) -> 7148.5537 | L11: ='MTD Utility Sheet'!F13/K11 -> 1.0439203 | M11: ='MTD Utility Sheet'!B13*301 -> 297.087
A12: Amwaj Rotana - Jumeirah Beach | B12: =B11+1 -> 11 | C12: 5 | D12: 2024 | E12: ='MTD Utility Sheet'!G14/0.439 -> 14649.294 | F12: 0.439 | G12: =('MTD Utility Sheet'!I14/1.82)/0.5 -> 488 | H12: =1.82*0.5 -> 0.91 | I12: ='MTD Utility Sheet'!H14/12.38 -> 200.58158 | J12: 12.38 | K12: =IF(('MTD Utility Sheet'!F14-2866)<0,"0",('MTD Utility Sheet'!F14-2866)/(0.568+0.075)) -> 9221.4774 | L12: ='MTD Utility Sheet'!F14/K12 -> 0.95379618 | M12: ='MTD Utility Sheet'!B14*301 -> 264.88
A13: Amwaj Rotana - Jumeirah Beach | B13: =B12+1 -> 12 | C13: 5 | D13: 2024 | E13: ='MTD Utility Sheet'!G15/0.439 -> 14649.294 | F13: 0.439 | G13: =('MTD Utility Sheet'!I15/1.82)/0.5 -> 536.8022 | H13: =1.82*0.5 -> 0.91 | I13: ='MTD Utility Sheet'!H15/12.38 -> 205.91276 | J13: 12.38 | K13: =IF(('MTD Utility Sheet'!F15-2866)<0,"0",('MTD Utility Sheet'!F15-2866)/(0.568+0.075)) -> 8817.6983 | L13: ='MTD Utility Sheet'!F15/K13 -> 0.96802813 | M13: ='MTD Utility Sheet'!B15*301 -> 223.944
A14: Amwaj Rotana - Jumeirah Beach | B14: =B13+1 -> 13 | C14: 5 | D14: 2024 | E14: ='MTD Utility Sheet'!G16/0.439 -> 15137.608 | F14: 0.439 | G14: =('MTD Utility Sheet'!I16/1.82)/0.5 -> 488 | H14: =1.82*0.5 -> 0.91 | I14: ='MTD Utility Sheet'!H16/12.38 -> 205.91276 | J14: 12.38 | K14: =IF(('MTD Utility Sheet'!F16-2866)<0,"0",('MTD Utility Sheet'!F16-2866)/(0.568+0.075)) -> 9551.3219 | L14: ='MTD Utility Sheet'!F16/K14 -> 0.94306318 | M14: ='MTD Utility Sheet'!B16*301 -> 227.857
... A32: Amwaj Rotana - Jumeirah Beach | B32: =B31+1 -> 31 | C32: 5 | D32: 2026 | E32: ='MTD Utility Sheet'!G34/0.439 -> 17090.843 | F32: 0.439 | G32: =('MTD Utility Sheet'!I34/1.82)/0.5 -> 487.96703 | H32: =1.82*0.5 -> 0.91 | I32: ='MTD Utility Sheet'!H34/12.38 -> 270.95315 | J32: 12.38 | K32: =IF(('MTD Utility Sheet'!F34-2866)<0,"0",('MTD Utility Sheet'!F34-2866)/(0.568+0.075)) -> 13515.148 | L32: ='MTD Utility Sheet'!F34/K32 -> 0.85505836 | M32: ='MTD Utility Sheet'!B34*301 -> 299.0134

Sheet MTD Utility Sheet
A1: Daily Utilities May 2024
B3: Occ % | C3: Out. Temp at 2PM | D3: RH % | E3: F&B Covers | F3: Chilled water | G3: Electricity | H3: Water | I3: LPG | J3: Total
A4: 1 | B4: 0.97 | C4: 39c | D4: 0.54 | E4: 1085 | F4: 8296.26 | G4: 6216.67 | H4: 2892.4 | I4: 444.08 | J4: =SUM(F4+G4+H4+I4) -> 17849.41
A5: 2 | B5: 0.9136 | C5: 35c | D5: 0.6 | E5: 1206 | F5: 8327 | G5: 6216.67 | H5: 2549.2 | I5: 444 | J5: =SUM(F5+G5+H5+I5) -> 17536.87
A6: 3 | B6: 0.973 | C6: 32c | D6: 0.7 | E6: 1355 | F6: 8250.55 | G6: 6645.41 | H6: 2747.2 | I6: 444.08 | J6: =SUM(F6+G6+H6+I6) -> 18087.24
A7: 4 | B7: 0.993 | C7: 37c | D7: 0.48 | E7: 1326 | F7: 8296.26 | G7: 6645.41 | H7: 2747.2 | I7: 444.08 | J7: =SUM(F7+G7+H7+I7) -> 18132.95
A8: 5 | B8: 0.91 | C8: 37c | D8: 0.68 | E8: 1308 | F8: 8318.2 | G8: 6431.04 | H8: 2654.8 | I8: 444.08 | J8: =SUM(F8+G8+H8+I8) -> 17848.12
A9: 6 | B9: 0.884 | C9: 38c | D9: 0.52 | E9: 1049 | F9: 8270.66 | G9: 6431.04 | H9: 2536 | I9: 444.08 | J9: =SUM(F9+G9+H9+I9) -> 17681.78
A10: 7 | B10: 0.94 | C10: 39c | D10: 0.48 | E10: 1210 | F10: 8643.65 | G10: 6645.41 | H10: 2206 | I10: 444.08 | J10: =SUM(F10+G10+H10+I10) -> 17939.14
A11: 8 | B11: 0.98 | C11: 39.4c | D11: 0.68 | E11: 1362 | F11: 8170.1 | G11: 6431.04 | H11: 2536 | I11: 444.08 | J11: =SUM(F11+G11+H11+I11) -> 17581.22
A12: 9 | B12: 0.887 | C12: 38.5c | D12: 0.7 | E12: 1196 | F12: 9795.52 | G12: 6216 | H12: 2298 | I12: 444 | J12: =SUM(F12+G12+H12+I12) -> 18753.52
A13: 10 | B13: 0.987 | C13: 36c | D13: 0.58 | E13: 1307 | F13: 7462.52 | G13: 7074.14 | H13: 2681.2 | I13: 444.08 | J13: =SUM(F13+G13+H13+I13) -> 17661.94
A14: 11 | B14: 0.88 | C14: 34c | D14: 0.54 | E14: 1319 | F14: 8795.41 | G14: 6431.04 | H14: 2483.2 | I14: 444.08 | J14: =SUM(F14+G14+H14+I14) -> 18153.73
A15: 12 | B15: 0.744 | C15: 39c | D15: 0.48 | E15: 1204 | F15: 8535.78 | G15: 6431.04 | H15: 2549.2 | I15: 488.49 | J15: =SUM(F15+G15+H15+I15) -> 18004.51
... A34: 31 | B34: 0.9934 | C34: 40.0c | D34: 0.78 | E34: 1600 | F34: 11556.24 | G34: 7502.88 | H34: 3354.4 | I34: 444.05 | J34: =SUM(F34+G34+H34+I34) -> 22857.57
A35: Total Cost | F35: =SUM(F4:F34) -> 286288.71 | G35: =SUM(G4:G34) -> 210294.29 | H35: =SUM(H4:H34) -> 85928.08 | I35: =SUM(I4:I34) -> 13810.5 | J35: =SUM(J4:J34) -> 596321.58
A36: Total Units | B36: =AVERAGE(B4:B34) -> 0.93745161 | C36: =AVERAGE(C4:C34) -> #DIV/0! | D36: =AVERAGE(D4:D34) -> 0.64483871 | E36: =SUM(E4:E34) -> 40501 | F36: =F35*0.38 -> 108789.71 | G36: =G35/12.9 -> 16301.883 | H36: =H35/0.92 -> 93400.087 | I36: =I35/1.76 -> 7846.875

Sheet May 31
A1: Daily Utilities Consumption
A2: 31.5.2024
A3: District Cooling
A4: Previous Reading MWh | B4: 62439.39 | C4: Current Reading MWh | D4: 62486.92 | E4: Consumption MWH | F4: =D4-B4 -> 47.53 | G4: Consumption RTH | H4: =F4*284.35 -> 13515.155
A5: Cost Calculation
A6: Total Cost (0.568/rth) | D6: =H4*0.568 -> 7676.6083
A7: Total Fuel Surchage Cost (0.075/rth) | D7: =H4*0.075 -> 1013.6367
A8: Chilled Water Demand (2,866 AED/Day) | D8: 2866
A9: Grand Total Exc. VAT | D9: =SUM(D6:H8) -> 11556.245
A10: Electrical
A11: MDB-G1 (39299675-8) | C11: Previous Reading KWH | D11: 41806 | E11: Current Reading KWH | F11: 41815 | G11: Consumption KWH | H11: =F11-D11 -> 9
A12: MDB-G2 (39299676-6) | C12: Previous Reading KWH | D12: 69222 | E12: Current Reading KWH | F12: 69236 | G12: Consumption KWH | H12: =F12-D12 -> 14
A13: MDB-G3 (39299677-4) | C13: Previous Reading KWH | D13: 70393 | E13: Current Reading KWH | F13: 70405 | G13: Consumption KWH | H13: =F13-D13 -> 12
A14: Total Consumption KWH | H14: =SUM(H11:H13) -> 35
A15: Total Consumption * Multiplication Factor (487.20) | H15: =H14*487.2 -> 17052
A16: Cost Calculation
A17: 0-2000 kwh @ 0.230 /KWH | D17: 460
A18: 2000-4000 kwh @ 0.280 /KWH | D18: 560
A19: 4000-6000 kwh @ 0.320 /KWH | D19: 640
A20: 6000 & above @ 0.380 /KWH | D20: =H15*0.38 -> 6479.76
A21: Fuel Surcharge @ 0.060 /KWH | D21: =H15*0.06 -> 1023.12
A22: Grand Total Exc. VAT | D22: =D20+D21 -> 7502.88
A23: WATER
A24: Previous Reading | B24: 269893 | C24: Present Reading | D24: 270160 | E24: Consumption m3 | F24: =D24-B24 -> 267 | G24: Consumption IG | H24: =F24*220 -> 58740
A25: Cost calculation
A26: 0-10000 @ 0.035 / IG | D26: 350
A27: 10000-20000 @ 0.04 / IG | D27: 400
A28: 20000 & above @ 0.046 / IG | D28: =(H24-20000)*0.046 -> 1782.04
A29: Fuel Surcharge @ 0.004 / IG | D29: =H24*0.004 -> 234.96
A30: Sewerage Fees | D30: =H24*0.01 -> 587.4
A31: Grand Total Exc. VAT | D31: =SUM(D26:H30) -> 3354.4
A32: LPG Gas
A33: Tank 1 (1% = 48 liters) | C33: Previous Reading % | D33: 75 | E33: Current Reading % | F33: 65 | G33: Consumption Liters | H33: =(D33-F33)*48.8 -> 488
A34: Tank 2 (1% = 48 liters) | C34: Previous Reading % | D34: 80 | E34: Current Reading % | F34: 80 | G34: Consumption Liters | H34: =(D34-F34)*48.8 -> 0
A35: Total Cost (@ 1.82 AED/Liter) | H35: =((H34+H33)*1.82)*0.5 -> 444.08
A36: Total Utilities | H36: =H35+D22+D9+D31 -> 22857.605

Sheet May 30
A1: Daily Utilities Consumption
A2: 30.5.2024
A3: District Cooling
A4: Previous Reading MWh | B4: 62391.48 | C4: Current Reading MWh | D4: 62439.39 | E4: Consumption MWH | F4: =D4-B4 -> 47.91 | G4: Consumption RTH | H4: =F4*284.35 -> 13623.208
A5: Cost Calculation
A6: Total Cost (0.568/rth) | D6: =H4*0.568 -> 7737.9824
A7: Total Fuel Surchage Cost (0.075/rth) | D7: =H4*0.075 -> 1021.7406
A8: Chilled Water Demand (2,866 AED/Day) | D8: 2866
A9: Grand Total Exc. VAT | D9: =SUM(D6:H8) -> 11625.723
A10: Electrical
A11: MDB-G1 (39299675-8) | C11: Previous Reading KWH | D11: 41798 | E11: Current Reading KWH | F11: 41806 | G11: Consumption KWH | H11: =F11-D11 -> 8
A12: MDB-G2 (39299676-6) | C12: Previous Reading KWH | D12: 69207 | E12: Current Reading KWH | F12: 69222 | G12: Consumption KWH | H12: =F12-D12 -> 15
A13: MDB-G3 (39299677-4) | C13: Previous Reading KWH | D13: 70381 | E13: Current Reading KWH | F13: 70393 | G13: Consumption KWH | H13: =F13-D13 -> 12
A14: Total Consumption KWH | H14: =SUM(H11:H13) -> 35
A15: Total Consumption * Multiplication Factor (487.20) | H15: =H14*487.2 -> 17052
A16: Cost Calculation
A17: 0-2000 kwh @ 0.230 /KWH | D17: 460
A18: 2000-4000 kwh @ 0.280 /KWH | D18: 560
A19: 4000-6000 kwh @ 0.320 /KWH | D19: 640
A20: 6000 & above @ 0.380 /KWH | D20: =H15*0.38 -> 6479.76
A21: Fuel Surcharge @ 0.060 /KWH | D21: =H15*0.06 -> 1023.12
A22: Grand Total Exc. VAT | D22: =D20+D21 -> 7502.88
A23: WATER
A24: Previous Reading | B24: 269636 | C24: Present Reading | D24: 269893 | E24: Consumption m3 | F24: =D24-B24 -> 257 | G24: Consumption IG | H24: =F24*220 -> 56540
A25: Cost calculation
A26: 0-10000 @ 0.035 / IG | D26: 350
A27: 10000-20000 @ 0.04 / IG | D27: 400
A28: 20000 & above @ 0.046 / IG | D28: =(H24-20000)*0.046 -> 1680.84
A29: Fuel Surcharge @ 0.004 / IG | D29: =H24*0.004 -> 226.16
A30: Sewerage Fees | D30: =H24*0.01 -> 565.4
A31: Grand Total Exc. VAT | D31: =SUM(D26:H30) -> 3222.4
A32: LPG Gas
A33: Tank 1 (1% = 48 liters) | C33: Previous Reading % | D33: 85 | E33: Current Reading % | F33: 75 | G33: Consumption Liters | H33: =(D33-F33)*48.8 -> 488
A34: Tank 2 (1% = 48 liters) | C34: Previous Reading % | D34: 80 | E34: Current Reading % | F34: 80 | G34: Consumption Liters | H34: =(D34-F34)*48.8 -> 0
A35: Total Cost (@ 1.82 AED/Liter) | H35: =((H34+H33)*1.82)*0.5 -> 444.08
A36: Total Utilities | H36: =H35+D22+D9+D31 -> 22795.083

Sheet May 29
A1: Daily Utilities Consumption
A2: 29.5.2024
A3: District Cooling
A4: Previous Reading MWh | B4: 62344.91 | C4: Current Reading MWh | D4: 62391.48 | E4: Consumption MWH | F4: =D4-B4 -> 46.57 | G4: Consumption RTH | H4: =F4*284.35 -> 13242.179
A5: Cost Calculation
A6: Total Cost (0.568/rth) | D6: =H4*0.568 -> 7521.558
A7: Total Fuel Surchage Cost (0.075/rth) | D7: =H4*0.075 -> 993.16346
A8: Chilled Water Demand (2,866 AED/Day) | D8: 2866
A9: Grand Total Exc. VAT | D9: =SUM(D6:H8) -> 11380.721
A10: Electrical
A11: MDB-G1 (39299675-8) | C11: Previous Reading KWH | D11: 41791 | E11: Current Reading KWH | F11: 41798 | G11: Consumption KWH | H11: =F11-D11 -> 7
A12: MDB-G2 (39299676-6) | C12: Previous Reading KWH | D12: 69193 | E12: Current Reading KWH | F12: 69207 | G12: Consumption KWH | H12: =F12-D12 -> 14
A13: MDB-G3 (39299677-4) | C13: Previous Reading KWH | D13: 70369 | E13: Current Reading KWH | F13: 70381 | G13: Consumption KWH | H13: =F13-D13 -> 12
A14: Total Consumption KWH | H14: =SUM(H11:H13) -> 33
A15: Total Consumption * Multiplication Factor (487.20) | H15: =H14*487.2 -> 16077.6
A16: Cost Calculation
A17: 0-2000 kwh @ 0.230 /KWH | D17: 460
A18: 2000-4000 kwh @ 0.280 /KWH | D18: 560
A19: 4000-6000 kwh @ 0.320 /KWH | D19: 640
A20: 6000 & above @ 0.380 /KWH | D20: =H15*0.38 -> 6109.488
A21: Fuel Surcharge @ 0.060 /KWH | D21: =H15*0.06 -> 964.656
A22: Grand Total Exc. VAT | D22: =D20+D21 -> 7074.144
A23: WATER
A24: Previous Reading | B24: 269396 | C24: Present Reading | D24: 269636 | E24: Consumption m3 | F24: =D24-B24 -> 240 | G24: Consumption IG | H24: =F24*220 -> 52800
A25: Cost calculation
A26: 0-10000 @ 0.035 / IG | D26: 350
A27: 10000-20000 @ 0.04 / IG | D27: 400
A28: 20000 & above @ 0.046 / IG | D28: =(H24-20000)*0.046 -> 1508.8
A29: Fuel Surcharge @ 0.004 / IG | D29: =H24*0.004 -> 211.2
A30: Sewerage Fees | D30: =H24*0.01 -> 528
A31: Grand Total Exc. VAT | D31: =SUM(D26:H30) -> 2998
A32: LPG Gas
A33: Tank 1 (1% = 48 liters) | C33: Previous Reading % | D33: 75 | E33: Current Reading % | F33: 75 | G33: Consumption Liters | H33: =(D33-F33)*48.8 -> 0
A34: Tank 2 (1% = 48 liters) | C34: Previous Reading % | D34: 30 | E34: Current Reading % | F34: 18 | G34: Consumption Liters | H34: =(D34-F34)*48.8 -> 585.6
A35: Total Cost (@ 1.82 AED/Liter) | H35: =((H34+H33)*1.82)*0.5 -> 532.896
A36: Total Utilities | H36: =H35+D22+D9+D31 -> 21985.761

Sheet May 28
A1: Daily Utilities Consumption
A2: 28.5.2024
A3: District Cooling
A4: Previous Reading MWh | B4: 62302.01 | C4: Current Reading MWh | D4: 62344.91 | E4: Consumption MWH | F4: =D4-B4 -> 42.9 | G4: Consumption RTH | H4: =F4*284.35 -> 12198.615
A5: Cost Calculation
A6: Total Cost (0.568/rth) | D6: =H4*0.568 -> 6928.8133
A7: Total Fuel Surchage Cost (0.075/rth) | D7: =H4*0.075 -> 914.89613
A8: Chilled Water Demand (2,866 AED/Day) | D8: 2866
A9: Grand Total Exc. VAT | D9: =SUM(D6:H8) -> 10709.709
A10: Electrical
A11: MDB-G1 (39299675-8) | C11: Previous Reading KWH | D11: 41783 | E11: Current Reading KWH | F11: 41791 | G11: Consumption KWH | H11: =F11-D11 -> 8
A12: MDB-G2 (39299676-6) | C12: Previous Reading KWH | D12: 69179 | E12: Current Reading KWH | F12: 69193 | G12: Consumption KWH | H12: =F12-D12 -> 14
A13: MDB-G3 (39299677-4) | C13: Previous Reading KWH | D13: 70357 | E13: Current Reading KWH | F13: 70369 | G13: Consumption KWH | H13: =F13-D13 -> 12
A14: Total Consumption KWH | H14: =SUM(H11:H13) -> 34
A15: Total Consumption * Multiplication Factor (487.20) | H15: =H14*487.2 -> 16564.8
A16: Cost Calculation
A17: 0-2000 kwh @ 0.230 /KWH | D17: 460
A18: 2000-4000 kwh @ 0.280 /KWH | D18: 560
A19: 4000-6000 kwh @ 0.320 /KWH | D19: 640
A20: 6000 & above @ 0.380 /KWH | D20: =H15*0.38 -> 6294.624
A21: Fuel Surcharge @ 0.060 /KWH | D21: =H15*0.06 -> 993.888
A22: Grand Total Exc. VAT | D22: =D20+D21 -> 7288.512
A23: WATER
A24: Previous Reading | B24: 269131 | C24: Present Reading | D24: 269396 | E24: Consumption m3 | F24: =D24-B24 -> 265 | G24: Consumption IG | H24: =F24*220 -> 58300
A25: Cost calculation
A26: 0-10000 @ 0.035 / IG | D26: 350
A27: 10000-20000 @ 0.04 / IG | D27: 400
A28: 20000 & above @ 0.046 / IG | D28: =(H24-20000)*0.046 -> 1761.8
A29: Fuel Surcharge @ 0.004 / IG | D29: =H24*0.004 -> 233.2
A30: Sewerage Fees | D30: =H24*0.01 -> 583
A31: Grand Total Exc. VAT | D31: =SUM(D26:H30) -> 3328
A32: LPG Gas
A33: Tank 1 (1% = 48 liters) | C33: Previous Reading % | D33: 75 | E33: Current Reading % | F33: 75 | G33: Consumption Liters | H33: =(D33-F33)*48.8 -> 0
A34: Tank 2 (1% = 48 liters) | C34: Previous Reading % | D34: 40 | E34: Current Reading % | F34: 30 | G34: Consumption Liters | H34: =(D34-F34)*48.8 -> 488
A35: Total Cost (@ 1.82 AED/Liter) | H35: =((H34+H33)*1.82)*0.5 -> 444.08
A36: Total Utilities | H36: =H35+D22+D9+D31 -> 21770.301

Sheet May 27
A1: Daily Utilities Consumption
A2: 27.5.2024
A3: District Cooling
A4: Previous Reading MWh | B4: 62260.81 | C4: Current Reading MWh | D4: 62302.01 | E4: Consumption MWH | F4: =D4-B4 -> 41.2 | G4: Consumption RTH | H4: =F4*284.35 -> 11715.22
A5: Cost Calculation
A6: Total Cost (0.568/rth) | D6: =H4*0.568 -> 6654.245
A7: Total Fuel Surchage Cost (0.075/rth) | D7: =H4*0.075 -> 878.6415
A8: Chilled Water Demand (2,866 AED/Day) | D8: 2866
A9: Grand Total Exc. VAT | D9: =SUM(D6:H8) -> 10398.886
A10: Electrical
A11: MDB-G1 (39299675-8) | C11: Previous Reading KWH | D11: 41775 | E11: Current Reading KWH | F11: 41783 | G11: Consumption KWH | H11: =F11-D11 -> 8
A12: MDB-G2 (39299676-6) | C12: Previous Reading KWH | D12: 69164 | E12: Current Reading KWH | F12: 69179 | G12: Consumption KWH | H12: =F12-D12 -> 15
A13: MDB-G3 (39299677-4) | C13: Previous Reading KWH | D13: 70344 | E13: Current Reading KWH | F13: 70357 | G13: Consumption KWH | H13: =F13-D13 -> 13
A14: Total Consumption KWH | H14: =SUM(H11:H13) -> 36
A15: Total Consumption * Multiplication Factor (487.20) | H15: =H14*487.2 -> 17539.2
A16: Cost Calculation
A17: 0-2000 kwh @ 0.230 /KWH | D17: 460
A18: 2000-4000 kwh @ 0.280 /KWH | D18: 560
A19: 4000-6000 kwh @ 0.320 /KWH | D19: 640
A20: 6000 & above @ 0.380 /KWH | D20: =H15*0.38 -> 6664.896
A21: Fuel Surcharge @ 0.060 /KWH | D21: =H15*0.06 -> 1052.352
A22: Grand Total Exc. VAT | D22: =D20+D21 -> 7717.248
A23: WATER
A24: Previous Reading | B24: 268874 | C24: Present Reading | D24: 269131 | E24: Consumption m3 | F24: =D24-B24 -> 257 | G24: Consumption IG | H24: =F24*220 -> 56540
A25: Cost calculation
A26: 0-10000 @ 0.035 / IG | D26: 350
A27: 10000-20000 @ 0.04 / IG | D27: 400
A28: 20000 & above @ 0.046 / IG | D28: =(H24-20000)*0.046 -> 1680.84
A29: Fuel Surcharge @ 0.004 / IG | D29: =H24*0.004 -> 226.16
A30: Sewerage Fees | D30: =H24*0.01 -> 565.4
A31: Grand Total Exc. VAT | D31: =SUM(D26:H30) -> 3222.4
A32: LPG Gas
A33: Tank 1 (1% = 48 liters) | C33: Previous Reading % | D33: 75 | E33: Current Reading % | F33: 75 | G33: Consumption Liters | H33: =(D33-F33)*48.8 -> 0
A34: Tank 2 (1% = 48 liters) | C34: Previous Reading % | D34: 50 | E34: Current Reading % | F34: 40 | G34: Consumption Liters | H34: =(D34-F34)*48.8 -> 488
A35: Total Cost (@ 1.82 AED/Liter) | H35: =((H34+H33)*1.82)*0.5 -> 444.08
A36: Total Utilities | H36: =H35+D22+D9+D31 -> 21782.614

Sheet May 26
A1: Daily Utilities Consumption
A2: 26.5.2024
A3: District Cooling
A4: Previous Reading MWh | B4: 62220.69 | C4: Current Reading MWh | D4: 62260.81 | E4: Consumption MWH | F4: =D4-B4 -> 40.12 | G4: Consumption RTH | H4: =F4*284.35 -> 11408.122
A5: Cost Calculation
A6: Total Cost (0.568/rth) | D6: =H4*0.568 -> 6479.8133
A7: Total Fuel Surchage Cost (0.075/rth) | D7: =H4*0.075 -> 855.60915
A8: Chilled Water Demand (2,866 AED/Day) | D8: 2866
A9: Grand Total Exc. VAT | D9: =SUM(D6:H8) -> 10201.422
A10: Electrical
A11: MDB-G1 (39299675-8) | C11: Previous Reading KWH | D11: 41767 | E11: Current Reading KWH | F11: 41775 | G11: Consumption KWH | H11: =F11-D11 -> 8
A12: MDB-G2 (39299676-6) | C12: Previous Reading KWH | D12: 69151 | E12: Current Reading KWH | F12: 69164 | G12: Consumption KWH | H12: =F12-D12 -> 13
A13: MDB-G3 (39299677-4) | C13: Previous Reading KWH | D13: 70332 | E13: Current Reading KWH | F13: 70344 | G13: Consumption KWH | H13: =F13-D13 -> 12
A14: Total Consumption KWH | H14: =SUM(H11:H13) -> 33
A15: Total Consumption * Multiplication Factor (487.20) | H15: =H14*487.2 -> 16077.6
A16: Cost Calculation
A17: 0-2000 kwh @ 0.230 /KWH | D17: 460
A18: 2000-4000 kwh @ 0.280 /KWH | D18: 560
A19: 4000-6000 kwh @ 0.320 /KWH | D19: 640
A20: 6000 & above @ 0.380 /KWH | D20: =H15*0.38 -> 6109.488
A21: Fuel Surcharge @ 0.060 /KWH | D21: =H15*0.06 -> 964.656
A22: Grand Total Exc. VAT | D22: =D20+D21 -> 7074.144
A23: WATER
A24: Previous Reading | B24: 268630 | C24: Present Reading | D24: 268874 | E24: Consumption m3 | F24: =D24-B24 -> 244 | G24: Consumption IG | H24: =F24*220 -> 53680
A25: Cost calculation
A26: 0-10000 @ 0.035 / IG | D26: 350
A27: 10000-20000 @ 0.04 / IG | D27: 400
A28: 20000 & above @ 0.046 / IG | D28: =(H24-20000)*0.046 -> 1549.28
A29: Fuel Surcharge @ 0.004 / IG | D29: =H24*0.004 -> 214.72
A30: Sewerage Fees | D30: =H24*0.01 -> 536.8
A31: Grand Total Exc. VAT | D31: =SUM(D26:H30) -> 3050.8
A32: LPG Gas
A33: Tank 1 (1% = 48 liters) | C33: Previous Reading % | D33: 75 | E33: Current Reading % | F33: 75 | G33: Consumption Liters | H33: =(D33-F33)*48.8 -> 0
A34: Tank 2 (1% = 48 liters) | C34: Previous Reading % | D34: 60 | E34: Current Reading % | F34: 50 | G34: Consumption Liters | H34: =(D34-F34)*48.8 -> 488
A35: Total Cost (@ 1.82 AED/Liter) | H35: =((H34+H33)*1.82)*0.5 -> 444.08
A36: Total Utilities | H36: =H35+D22+D9+D31 -> 20770.446

Sheet May 25
A1: Daily Utilities Consumption
A2: 25.5.2024
A3: District Cooling
A4: Previous Reading MWh | B4: 62181.62 | C4: Current Reading MWh | D4: 62220.69 | E4: Consumption MWH | F4: =D4-B4 -> 39.07 | G4: Consumption RTH | H4: =F4*284.35 -> 11109.554
A5: Cost Calculation
A6: Total Cost (0.568/rth) | D6: =H4*0.568 -> 6310.227
A7: Total Fuel Surchage Cost (0.075/rth) | D7: =H4*0.075 -> 833.21659
A8: Chilled Water Demand (2,866 AED/Day) | D8: 2866
A9: Grand Total Exc. VAT | D9: =SUM(D6:H8) -> 10009.444
A10: Electrical
A11: MDB-G1 (39299675-8) | C11: Previous Reading KWH | D11: 41760 | E11: Current Reading KWH | F11: 41767 | G11: Consumption KWH | H11: =F11-D11 -> 7
A12: MDB-G2 (39299676-6) | C12: Previous Reading KWH | D12: 69138 | E12: Current Reading KWH | F12: 69151 | G12: Consumption KWH | H12: =F12-D12 -> 13
A13: MDB-G3 (39299677-4) | C13: Previous Reading KWH | D13: 70321 | E13: Current Reading KWH | F13: 70332 | G13: Consumption KWH | H13: =F13-D13 -> 11
A14: Total Consumption KWH | H14: =SUM(H11:H13) -> 31
A15: Total Consumption * Multiplication Factor (487.20) | H15: =H14*487.2 -> 15103.2
A16: Cost Calculation
A17: 0-2000 kwh @ 0.230 /KWH | D17: 460
A18: 2000-4000 kwh @ 0.280 /KWH | D18: 560
A19: 4000-6000 kwh @ 0.320 /KWH | D19: 640
A20: 6000 & above @ 0.380 /KWH | D20: =H15*0.38 -> 5739.216
A21: Fuel Surcharge @ 0.060 /KWH | D21: =H15*0.06 -> 906.192
A22: Grand Total Exc. VAT | D22: =D20+D21 -> 6645.408
A23: WATER
A24: Previous Reading | B24: 268378 | C24: Present Reading | D24: 268630 | E24: Consumption m3 | F24: =D24-B24 -> 252 | G24: Consumption IG | H24: =F24*220 -> 55440
A25: Cost calculation
A26: 0-10000 @ 0.035 / IG | D26: 350
A27: 10000-20000 @ 0.04 / IG | D27: 400
A28: 20000 & above @ 0.046 / IG | D28: =(H24-20000)*0.046 -> 1630.24
A29: Fuel Surcharge @ 0.004 / IG | D29: =H24*0.004 -> 221.76
A30: Sewerage Fees | D30: =H24*0.01 -> 554.4
A31: Grand Total Exc. VAT | D31: =SUM(D26:H30) -> 3156.4
A32: LPG Gas
A33: Tank 1 (1% = 48 liters) | C33: Previous Reading % | D33: 75 | E33: Current Reading % | F33: 75 | G33: Consumption Liters | H33: =(D33-F33)*48.8 -> 0
A34: Tank 2 (1% = 48 liters) | C34: Previous Reading % | D34: 70 | E34: Current Reading % | F34: 60 | G34: Consumption Liters | H34: =(D34-F34)*48.8 -> 488
A35: Total Cost (@ 1.82 AED/Liter) | H35: =((H34+H33)*1.82)*0.5 -> 444.08
A36: Total Utilities | H36: =H35+D22+D9+D31 -> 20255.332

Sheet May 24
A1: Daily Utilities Consumption
A2: 24.5.2024
A3: District Cooling
A4: Previous Reading MWh | B4: 62145.49 | C4: Current Reading MWh | D4: 62181.62 | E4: Consumption MWH | F4: =D4-B4 -> 36.13 | G4: Consumption RTH | H4: =F4*284.35 -> 10273.566
A5: Cost Calculation
A6: Total Cost (0.568/rth) | D6: =H4*0.568 -> 5835.3852
A7: Total Fuel Surchage Cost (0.075/rth) | D7: =H4*0.075 -> 770.51741
A8: Chilled Water Demand (2,866 AED/Day) | D8: 2866
A9: Grand Total Exc. VAT | D9: =SUM(D6:H8) -> 9471.9026
A10: Electrical
A11: MDB-G1 (39299675-8) | C11: Previous Reading KWH | D11: 41752 | E11: Current Reading KWH | F11: 41760 | G11: Consumption KWH | H11: =F11-D11 -> 8
A12: MDB-G2 (39299676-6) | C12: Previous Reading KWH | D12: 69125 | E12: Current Reading KWH | F12: 69138 | G12: Consumption KWH | H12: =F12-D12 -> 13
A13: MDB-G3 (39299677-4) | C13: Previous Reading KWH | D13: 70310 | E13: Current Reading KWH | F13: 70321 | G13: Consumption KWH | H13: =F13-D13 -> 11
A14: Total Consumption KWH | H14: =SUM(H11:H13) -> 32
A15: Total Consumption * Multiplication Factor (487.20) | H15: =H14*487.2 -> 15590.4
A16: Cost Calculation
A17: 0-2000 kwh @ 0.230 /KWH | D17: 460
A18: 2000-4000 kwh @ 0.280 /KWH | D18: 560
A19: 4000-6000 kwh @ 0.320 /KWH | D19: 640
A20: 6000 & above @ 0.380 /KWH | D20: =H15*0.38 -> 5924.352
A21: Fuel Surcharge @ 0.060 /KWH | D21: =H15*0.06 -> 935.424
A22: Grand Total Exc. VAT | D22: =D20+D21 -> 6859.776
A23: WATER
A24: Previous Reading | B24: 268145 | C24: Present Reading | D24: 268378 | E24: Consumption m3 | F24: =D24-B24 -> 233 | G24: Consumption IG | H24: =F24*220 -> 51260
A25: Cost calculation
A26: 0-10000 @ 0.035 / IG | D26: 350
A27: 10000-20000 @ 0.04 / IG | D27: 400
A28: 20000 & above @ 0.046 / IG | D28: =(H24-20000)*0.046 -> 1437.96
A29: Fuel Surcharge @ 0.004 / IG | D29: =H24*0.004 -> 205.04
A30: Sewerage Fees | D30: =H24*0.01 -> 512.6
A31: Grand Total Exc. VAT | D31: =SUM(D26:H30) -> 2905.6
A32: LPG Gas
A33: Tank 1 (1% = 48 liters) | C33: Previous Reading % | D33: 75 | E33: Current Reading % | F33: 75 | G33: Consumption Liters | H33: =(D33-F33)*48.8 -> 0
A34: Tank 2 (1% = 48 liters) | C34: Previous Reading % | D34: 80 | E34: Current Reading % | F34: 70 | G34: Consumption Liters | H34: =(D34-F34)*48.8 -> 488
A35: Total Cost (@ 1.82 AED/Liter) | H35: =((H34+H33)*1.82)*0.5 -> 444.08
A36: Total Utilities | H36: =H35+D22+D9+D31 -> 19681.359

Sheet May 23
A1: Daily Utilities Consumption
A2: 23.5.2024
A3: District Cooling
A4: Previous Reading MWh | B4: 62111.73 | C4: Current Reading MWh | D4: 62145.49 | E4: Consumption MWH | F4: =D4-B4 -> 33.76 | G4: Consumption RTH | H4: =F4*284.35 -> 9599.656
A5: Cost Calculation
A6: Total Cost (0.568/rth) | D6: =H4*0.568 -> 5452.6046
A7: Total Fuel Surchage Cost (0.075/rth) | D7: =H4*0.075 -> 719.9742
A8: Chilled Water Demand (2,866 AED/Day) | D8: 2866
A9: Grand Total Exc. VAT | D9: =SUM(D6:H8) -> 9038.5788
A10: Electrical
A11: MDB-G1 (39299675-8) | C11: Previous Reading KWH | D11: 41744 | E11: Current Reading KWH | F11: 41752 | G11: Consumption KWH | H11: =F11-D11 -> 8
A12: MDB-G2 (39299676-6) | C12: Previous Reading KWH | D12: 69111 | E12: Current Reading KWH | F12: 69125 | G12: Consumption KWH | H12: =F12-D12 -> 14
A13: MDB-G3 (39299677-4) | C13: Previous Reading KWH | D13: 70299 | E13: Current Reading KWH | F13: 70310 | G13: Consumption KWH | H13: =F13-D13 -> 11
A14: Total Consumption KWH | H14: =SUM(H11:H13) -> 33
A15: Total Consumption * Multiplication Factor (487.20) | H15: =H14*487.2 -> 16077.6
A16: Cost Calculation
A17: 0-2000 kwh @ 0.230 /KWH | D17: 460
A18: 2000-4000 kwh @ 0.280 /KWH | D18: 560
A19: 4000-6000 kwh @ 0.320 /KWH | D19: 640
A20: 6000 & above @ 0.380 /KWH | D20: =H15*0.38 -> 6109.488
A21: Fuel Surcharge @ 0.060 /KWH | D21: =H15*0.06 -> 964.656
A22: Grand Total Exc. VAT | D22: =D20+D21 -> 7074.144
A23: WATER
A24: Previous Reading | B24: 267914 | C24: Present Reading | D24: 268145 | E24: Consumption m3 | F24: =D24-B24 -> 231 | G24: Consumption IG | H24: =F24*220 -> 50820
A25: Cost calculation
A26: 0-10000 @ 0.035 / IG | D26: 350
A27: 10000-20000 @ 0.04 / IG | D27: 400
A28: 20000 & above @ 0.046 / IG | D28: =(H24-20000)*0.046 -> 1417.72
A29: Fuel Surcharge @ 0.004 / IG | D29: =H24*0.004 -> 203.28
A30: Sewerage Fees | D30: =H24*0.01 -> 508.2
A31: Grand Total Exc. VAT | D31: =SUM(D26:H30) -> 2879.2
A32: LPG Gas
A33: Tank 1 (1% = 48 liters) | C33: Previous Reading % | D33: 85 | E33: Current Reading % | F33: 75 | G33: Consumption Liters | H33: =(D33-F33)*48.8 -> 488
A34: Tank 2 (1% = 48 liters) | C34: Previous Reading % | D34: 80 | E34: Current Reading % | F34: 80 | G34: Consumption Liters | H34: =(D34-F34)*48.8 -> 0
A35: Total Cost (@ 1.82 AED/Liter) | H35: =((H34+H33)*1.82)*0.5 -> 444.08
A36: Total Utilities | H36: =H35+D22+D9+D31 -> 19436.003

Sheet May 22
A1: Daily Utilities Consumption
A2: 22.5.2024
A3: District Cooling
A4: Previous Reading MWh | B4: 62074.87 | C4: Current Reading MWh | D4: 62111.73 | E4: Consumption MWH | F4: =D4-B4 -> 36.86 | G4: Consumption RTH | H4: =F4*284.35 -> 10481.141
A5: Cost Calculation
A6: Total Cost (0.568/rth) | D6: =H4*0.568 -> 5953.2881
A7: Total Fuel Surchage Cost (0.075/rth) | D7: =H4*0.075 -> 786.08558
A8: Chilled Water Demand (2,866 AED/Day) | D8: 2866
A9: Grand Total Exc. VAT | D9: =SUM(D6:H8) -> 9605.3737
A10: Electrical
A11: MDB-G1 (39299675-8) | C11: Previous Reading KWH | D11: 41736 | E11: Current Reading KWH | F11: 41744 | G11: Consumption KWH | H11: =F11-D11 -> 8
A12: MDB-G2 (39299676-6) | C12: Previous Reading KWH | D12: 69098 | E12: Current Reading KWH | F12: 69111 | G12: Consumption KWH | H12: =F12-D12 -> 13
A13: MDB-G3 (39299677-4) | C13: Previous Reading KWH | D13: 70287 | E13: Current Reading KWH | F13: 70299 | G13: Consumption KWH | H13: =F13-D13 -> 12
A14: Total Consumption KWH | H14: =SUM(H11:H13) -> 33
A15: Total Consumption * Multiplication Factor (487.20) | H15: =H14*487.2 -> 16077.6
A16: Cost Calculation
A17: 0-2000 kwh @ 0.230 /KWH | D17: 460
A18: 2000-4000 kwh @ 0.280 /KWH | D18: 560
A19: 4000-6000 kwh @ 0.320 /KWH | D19: 640
A20: 6000 & above @ 0.380 /KWH | D20: =H15*0.38 -> 6109.488
A21: Fuel Surcharge @ 0.060 /KWH | D21: =H15*0.06 -> 964.656
A22: Grand Total Exc. VAT | D22: =D20+D21 -> 7074.144
A23: WATER
A24: Previous Reading | B24: 267680 | C24: Present Reading | D24: 267914 | E24: Consumption m3 | F24: =D24-B24 -> 234 | G24: Consumption IG | H24: =F24*220 -> 51480
A25: Cost calculation
A26: 0-10000 @ 0.035 / IG | D26: 350
A27: 10000-20000 @ 0.04 / IG | D27: 400
A28: 20000 & above @ 0.046 / IG | D28: =(H24-20000)*0.046 -> 1448.08
A29: Fuel Surcharge @ 0.004 / IG | D29: =H24*0.004 -> 205.92
A30: Sewerage Fees | D30: =H24*0.01 -> 514.8
A31: Grand Total Exc. VAT | D31: =SUM(D26:H30) -> 2918.8
A32: LPG Gas
A33: Tank 1 (1% = 48 liters) | C33: Previous Reading % | D33: 80 | E33: Current Reading % | F33: 70 | G33: Consumption Liters | H33: =(D33-F33)*48.8 -> 488
A34: Tank 2 (1% = 48 liters) | C34: Previous Reading % | D34: 22 | E34: Current Reading % | F34: 22 | G34: Consumption Liters | H34: =(D34-F34)*48.8 -> 0
A35: Total Cost (@ 1.82 AED/Liter) | H35: =((H34+H33)*1.82)*0.5 -> 444.08
A36: Total Utilities | H36: =H35+D22+D9+D31 -> 20042.398

Sheet May 21
A1: Daily Utilities Consumption
A2: 21.5.2024
A3: District Cooling
A4: Previous Reading MWh | B4: 62037.17 | C4: Current Reading MWh | D4: 62074.87 | E4: Consumption MWH | F4: =D4-B4 -> 37.7 | G4: Consumption RTH | H4: =F4*284.35 -> 10719.995
A5: Cost Calculation
A6: Total Cost (0.568/rth) | D6: =H4*0.568 -> 6088.9572
A7: Total Fuel Surchage Cost (0.075/rth) | D7: =H4*0.075 -> 803.99963
A8: Chilled Water Demand (2,866 AED/Day) | D8: 2866
A9: Grand Total Exc. VAT | D9: =SUM(D6:H8) -> 9758.9568
A10: Electrical
A11: MDB-G1 (39299675-8) | C11: Previous Reading KWH | D11: 41728 | E11: Current Reading KWH | F11: 41736 | G11: Consumption KWH | H11: =F11-D11 -> 8
A12: MDB-G2 (39299676-6) | C12: Previous Reading KWH | D12: 69085 | E12: Current Reading KWH | F12: 69098 | G12: Consumption KWH | H12: =F12-D12 -> 13
A13: MDB-G3 (39299677-4) | C13: Previous Reading KWH | D13: 70275 | E13: Current Reading KWH | F13: 70287 | G13: Consumption KWH | H13: =F13-D13 -> 12
A14: Total Consumption KWH | H14: =SUM(H11:H13) -> 33
A15: Total Consumption * Multiplication Factor (487.20) | H15: =H14*487.2 -> 16077.6
A16: Cost Calculation
A17: 0-2000 kwh @ 0.230 /KWH | D17: 460
A18: 2000-4000 kwh @ 0.280 /KWH | D18: 560
A19: 4000-6000 kwh @ 0.320 /KWH | D19: 640
A20: 6000 & above @ 0.380 /KWH | D20: =H15*0.38 -> 6109.488
A21: Fuel Surcharge @ 0.060 /KWH | D21: =H15*0.06 -> 964.656
A22: Grand Total Exc. VAT | D22: =D20+D21 -> 7074.144
A23: WATER
A24: Previous Reading | B24: 267456 | C24: Present Reading | D24: 267680 | E24: Consumption m3 | F24: =D24-B24 -> 224 | G24: Consumption IG | H24: =F24*220 -> 49280
A25: Cost calculation
A26: 0-10000 @ 0.035 / IG | D26: 350
A27: 10000-20000 @ 0.04 / IG | D27: 400
A28: 20000 & above @ 0.046 / IG | D28: =(H24-20000)*0.046 -> 1346.88
A29: Fuel Surcharge @ 0.004 / IG | D29: =H24*0.004 -> 197.12
A30: Sewerage Fees | D30: =H24*0.01 -> 492.8
A31: Grand Total Exc. VAT | D31: =SUM(D26:H30) -> 2786.8
A32: LPG Gas
A33: Tank 1 (1% = 48 liters) | C33: Previous Reading % | D33: 80 | E33: Current Reading % | F33: 80 | G33: Consumption Liters | H33: =(D33-F33)*48.8 -> 0
A34: Tank 2 (1% = 48 liters) | C34: Previous Reading % | D34: 32 | E34: Current Reading % | F34: 22 | G34: Consumption Liters | H34: =(D34-F34)*48.8 -> 488
A35: Total Cost (@ 1.82 AED/Liter) | H35: =((H34+H33)*1.82)*0.5 -> 444.08
A36: Total Utilities | H36: =H35+D22+D9+D31 -> 20063.981

Sheet May 20
A1: Daily Utilities Consumption
A2: 20.5.2024
A3: District Cooling
A4: Previous Reading MWh | B4: 62002.69 | C4: Current Reading MWh | D4: 62037.17 | E4: Consumption MWH | F4: =D4-B4 -> 34.48 | G4: Consumption RTH | H4: =F4*284.35 -> 9804.388
A5: Cost Calculation
A6: Total Cost (0.568/rth) | D6: =H4*0.568 -> 5568.8924
A7: Total Fuel Surchage Cost (0.075/rth) | D7: =H4*0.075 -> 735.3291
A8: Chilled Water Demand (2,866 AED/Day) | D8: 2866
A9: Grand Total Exc. VAT | D9: =SUM(D6:H8) -> 9170.2215
A10: Electrical
A11: MDB-G1 (39299675-8) | C11: Previous Reading KWH | D11: 41721 | E11: Current Reading KWH | F11: 41728 | G11: Consumption KWH | H11: =F11-D11 -> 7
A12: MDB-G2 (39299676-6) | C12: Previous Reading KWH | D12: 69072 | E12: Current Reading KWH | F12: 69085 | G12: Consumption KWH | H12: =F12-D12 -> 13
A13: MDB-G3 (39299677-4) | C13: Previous Reading KWH | D13: 70265 | E13: Current Reading KWH | F13: 70275 | G13: Consumption KWH | H13: =F13-D13 -> 10
A14: Total Consumption KWH | H14: =SUM(H11:H13) -> 30
A15: Total Consumption * Multiplication Factor (487.20) | H15: =H14*487.2 -> 14616
A16: Cost Calculation
A17: 0-2000 kwh @ 0.230 /KWH | D17: 460
A18: 2000-4000 kwh @ 0.280 /KWH | D18: 560
A19: 4000-6000 kwh @ 0.320 /KWH | D19: 640
A20: 6000 & above @ 0.380 /KWH | D20: =H15*0.38 -> 5554.08
A21: Fuel Surcharge @ 0.060 /KWH | D21: =H15*0.06 -> 876.96
A22: Grand Total Exc. VAT | D22: =D20+D21 -> 6431.04
A23: WATER
A24: Previous Reading | B24: 267162 | C24: Present Reading | D24: 267456 | E24: Consumption m3 | F24: =D24-B24 -> 294 | G24: Consumption IG | H24: =F24*220 -> 64680
A25: Cost calculation
A26: 0-10000 @ 0.035 / IG | D26: 350
A27: 10000-20000 @ 0.04 / IG | D27: 400
A28: 20000 & above @ 0.046 / IG | D28: =(H24-20000)*0.046 -> 2055.28
A29: Fuel Surcharge @ 0.004 / IG | D29: =H24*0.004 -> 258.72
A30: Sewerage Fees | D30: =H24*0.01 -> 646.8
A31: Grand Total Exc. VAT | D31: =SUM(D26:H30) -> 3710.8
A32: LPG Gas
A33: Tank 1 (1% = 48 liters) | C33: Previous Reading % | D33: 80 | E33: Current Reading % | F33: 80 | G33: Consumption Liters | H33: =(D33-F33)*48.8 -> 0
A34: Tank 2 (1% = 48 liters) | C34: Previous Reading % | D34: 42 | E34: Current Reading % | F34: 32 | G34: Consumption Liters | H34: =(D34-F34)*48.8 -> 488
A35: Total Cost (@ 1.82 AED/Liter) | H35: =((H34+H33)*1.82)*0.5 -> 444.08
A36: Total Utilities | H36: =H35+D22+D9+D31 -> 19756.141

Sheet May 19
A1: Daily Utilities Consumption
A2: 19.5.2024
A3: District Cooling
A4: Previous Reading MWh | B4: 61969.08 | C4: Current Reading MWh | D4: 62002.69 | E4: Consumption MWH | F4: =D4-B4 -> 33.61 | G4: Consumption RTH | H4: =F4*284.35 -> 9557.0035
A5: Cost Calculation
A6: Total Cost (0.568/rth) | D6: =H4*0.568 -> 5428.378
A7: Total Fuel Surchage Cost (0.075/rth) | D7: =H4*0.075 -> 716.77526
A8: Chilled Water Demand (2,866 AED/Day) | D8: 2866
A9: Grand Total Exc. VAT | D9: =SUM(D6:H8) -> 9011.1533
A10: Electrical
A11: MDB-G1 (39299675-8) | C11: Previous Reading KWH | D11: 41713 | E11: Current Reading KWH | F11: 41721 | G11: Consumption KWH | H11: =F11-D11 -> 8
A12: MDB-G2 (39299676-6) | C12: Previous Reading KWH | D12: 69059 | E12: Current Reading KWH | F12: 69072 | G12: Consumption KWH | H12: =F12-D12 -> 13
A13: MDB-G3 (39299677-4) | C13: Previous Reading KWH | D13: 70252 | E13: Current Reading KWH | F13: 70265 | G13: Consumption KWH | H13: =F13-D13 -> 13
A14: Total Consumption KWH | H14: =SUM(H11:H13) -> 34
A15: Total Consumption * Multiplication Factor (487.20) | H15: =H14*487.2 -> 16564.8
A16: Cost Calculation
A17: 0-2000 kwh @ 0.230 /KWH | D17: 460
A18: 2000-4000 kwh @ 0.280 /KWH | D18: 560
A19: 4000-6000 kwh @ 0.320 /KWH | D19: 640
A20: 6000 & above @ 0.380 /KWH | D20: =H15*0.38 -> 6294.624
A21: Fuel Surcharge @ 0.060 /KWH | D21: =H15*0.06 -> 993.888
A22: Grand Total Exc. VAT | D22: =D20+D21 -> 7288.512
A23: WATER
A24: Previous Reading | B24: 266975 | C24: Present Reading | D24: 267162 | E24: Consumption m3 | F24: =D24-B24 -> 187 | G24: Consumption IG | H24: =F24*220 -> 41140
A25: Cost calculation
A26: 0-10000 @ 0.035 / IG | D26: 350
A27: 10000-20000 @ 0.04 / IG | D27: 400
A28: 20000 & above @ 0.046 / IG | D28: =(H24-20000)*0.046 -> 972.44
A29: Fuel Surcharge @ 0.004 / IG | D29: =H24*0.004 -> 164.56
A30: Sewerage Fees | D30: =H24*0.01 -> 411.4
A31: Grand Total Exc. VAT | D31: =SUM(D26:H30) -> 2298.4
A32: LPG Gas
A33: Tank 1 (1% = 48 liters) | C33: Previous Reading % | D33: 80 | E33: Current Reading % | F33: 80 | G33: Consumption Liters | H33: =(D33-F33)*48.8 -> 0
A34: Tank 2 (1% = 48 liters) | C34: Previous Reading % | D34: 52 | E34: Current Reading % | F34: 42 | G34: Consumption Liters | H34: =(D34-F34)*48.8 -> 488
A35: Total Cost (@ 1.82 AED/Liter) | H35: =((H34+H33)*1.82)*0.5 -> 444.08
A36: Total Utilities | H36: =H35+D22+D9+D31 -> 19042.145

Sheet May 18
A1: Daily Utilities Consumption
A2: 18.5.2024
A3: District Cooling
A4: Previous Reading MWh | B4: 61935.75 | C4: Current Reading MWh | D4: 61969.08 | E4: Consumption MWH | F4: =D4-B4 -> 33.33 | G4: Consumption RTH | H4: =F4*284.35 -> 9477.3855
A5: Cost Calculation
A6: Total Cost (0.568/rth) | D6: =H4*0.568 -> 5383.155
A7: Total Fuel Surchage Cost (0.075/rth) | D7: =H4*0.075 -> 710.80391
A8: Chilled Water Demand (2,866 AED/Day) | D8: 2866
A9: Grand Total Exc. VAT | D9: =SUM(D6:H8) -> 8959.9589
A10: Electrical
A11: MDB-G1 (39299675-8) | C11: Previous Reading KWH | D11: 41705 | E11: Current Reading KWH | F11: 41713 | G11: Consumption KWH | H11: =F11-D11 -> 8
A12: MDB-G2 (39299676-6) | C12: Previous Reading KWH | D12: 69047 | E12: Current Reading KWH | F12: 69059 | G12: Consumption KWH | H12: =F12-D12 -> 12
A13: MDB-G3 (39299677-4) | C13: Previous Reading KWH | D13: 70241 | E13: Current Reading KWH | F13: 70252 | G13: Consumption KWH | H13: =F13-D13 -> 11
A14: Total Consumption KWH | H14: =SUM(H11:H13) -> 31
A15: Total Consumption * Multiplication Factor (487.20) | H15: =H14*487.2 -> 15103.2
A16: Cost Calculation
A17: 0-2000 kwh @ 0.230 /KWH | D17: 460
A18: 2000-4000 kwh @ 0.280 /KWH | D18: 560
A19: 4000-6000 kwh @ 0.320 /KWH | D19: 640
A20: 6000 & above @ 0.380 /KWH | D20: =H15*0.38 -> 5739.216
A21: Fuel Surcharge @ 0.060 /KWH | D21: =H15*0.06 -> 906.192
A22: Grand Total Exc. VAT | D22: =D20+D21 -> 6645.408
A23: WATER
A24: Previous Reading | B24: 266750 | C24: Present Reading | D24: 266975 | E24: Consumption m3 | F24: =D24-B24 -> 225 | G24: Consumption IG | H24: =F24*220 -> 49500
A25: Cost calculation
A26: 0-10000 @ 0.035 / IG | D26: 350
A27: 10000-20000 @ 0.04 / IG | D27: 400
A28: 20000 & above @ 0.046 / IG | D28: =(H24-20000)*0.046 -> 1357
A29: Fuel Surcharge @ 0.004 / IG | D29: =H24*0.004 -> 198
A30: Sewerage Fees | D30: =H24*0.01 -> 495
A31: Grand Total Exc. VAT | D31: =SUM(D26:H30) -> 2800
A32: LPG Gas
A33: Tank 1 (1% = 48 liters) | C33: Previous Reading % | D33: 80 | E33: Current Reading % | F33: 80 | G33: Consumption Liters | H33: =(D33-F33)*48.8 -> 0
A34: Tank 2 (1% = 48 liters) | C34: Previous Reading % | D34: 62 | E34: Current Reading % | F34: 52 | G34: Consumption Liters | H34: =(D34-F34)*48.8 -> 488
A35: Total Cost (@ 1.82 AED/Liter) | H35: =((H34+H33)*1.82)*0.5 -> 444.08
A36: Total Utilities | H36: =H35+D22+D9+D31 -> 18849.447

Sheet May 17
A1: Daily Utilities Consumption
A2: 17.5.2024
A3: District Cooling
A4: Previous Reading MWh | B4: 61903.32 | C4: Current Reading MWh | D4: 61935.75 | E4: Consumption MWH | F4: =D4-B4 -> 32.43 | G4: Consumption RTH | H4: =F4*284.35 -> 9221.4705
A5: Cost Calculation
A6: Total Cost (0.568/rth) | D6: =H4*0.568 -> 5237.7952
A7: Total Fuel Surchage Cost (0.075/rth) | D7: =H4*0.075 -> 691.61029
A8: Chilled Water Demand (2,866 AED/Day) | D8: 2866
A9: Grand Total Exc. VAT | D9: =SUM(D6:H8) -> 8795.4055
A10: Electrical
A11: MDB-G1 (39299675-8) | C11: Previous Reading KWH | D11: 41697 | E11: Current Reading KWH | F11: 41705 | G11: Consumption KWH | H11: =F11-D11 -> 8
A12: MDB-G2 (39299676-6) | C12: Previous Reading KWH | D12: 69035 | E12: Current Reading KWH | F12: 69047 | G12: Consumption KWH | H12: =F12-D12 -> 12
A13: MDB-G3 (39299677-4) | C13: Previous Reading KWH | D13: 70230 | E13: Current Reading KWH | F13: 70241 | G13: Consumption KWH | H13: =F13-D13 -> 11
A14: Total Consumption KWH | H14: =SUM(H11:H13) -> 31
A15: Total Consumption * Multiplication Factor (487.20) | H15: =H14*487.2 -> 15103.2
A16: Cost Calculation
A17: 0-2000 kwh @ 0.230 /KWH | D17: 460
A18: 2000-4000 kwh @ 0.280 /KWH | D18: 560
A19: 4000-6000 kwh @ 0.320 /KWH | D19: 640
A20: 6000 & above @ 0.380 /KWH | D20: =H15*0.38 -> 5739.216
A21: Fuel Surcharge @ 0.060 /KWH | D21: =H15*0.06 -> 906.192
A22: Grand Total Exc. VAT | D22: =D20+D21 -> 6645.408
A23: WATER
A24: Previous Reading | B24: 266515 | C24: Present Reading | D24: 266750 | E24: Consumption m3 | F24: =D24-B24 -> 235 | G24: Consumption IG | H24: =F24*220 -> 51700
A25: Cost calculation
A26: 0-10000 @ 0.035 / IG | D26: 350
A27: 10000-20000 @ 0.04 / IG | D27: 400
A28: 20000 & above @ 0.046 / IG | D28: =(H24-20000)*0.046 -> 1458.2
A29: Fuel Surcharge @ 0.004 / IG | D29: =H24*0.004 -> 206.8
A30: Sewerage Fees | D30: =H24*0.01 -> 517
A31: Grand Total Exc. VAT | D31: =SUM(D26:H30) -> 2932
A32: LPG Gas
A33: Tank 1 (1% = 48 liters) | C33: Previous Reading % | D33: 80 | E33: Current Reading % | F33: 80 | G33: Consumption Liters | H33: =(D33-F33)*48.8 -> 0
A34: Tank 2 (1% = 48 liters) | C34: Previous Reading % | D34: 70 | E34: Current Reading % | F34: 62 | G34: Consumption Liters | H34: =(D34-F34)*48.8 -> 390.4
A35: Total Cost (@ 1.82 AED/Liter) | H35: =((H34+H33)*1.82)*0.5 -> 355.264
A36: Total Utilities | H36: =H35+D22+D9+D31 -> 18728.078

Sheet May 16
A1: Daily Utilities Consumption
A2: 16.5.2024
A3: District Cooling
A4: Previous Reading MWh | B4: 61870.44 | C4: Current Reading MWh | D4: 61903.32 | E4: Consumption MWH | F4: =D4-B4 -> 32.88 | G4: Consumption RTH | H4: =F4*284.35 -> 9349.428
A5: Cost Calculation
A6: Total Cost (0.568/rth) | D6: =H4*0.568 -> 5310.4751
A7: Total Fuel Surchage Cost (0.075/rth) | D7: =H4*0.075 -> 701.2071
A8: Chilled Water Demand (2,866 AED/Day) | D8: 2866
A9: Grand Total Exc. VAT | D9: =SUM(D6:H8) -> 8877.6822
A10: Electrical
A11: MDB-G1 (39299675-8) | C11: Previous Reading KWH | D11: 41689 | E11: Current Reading KWH | F11: 41697 | G11: Consumption KWH | H11: =F11-D11 -> 8
A12: MDB-G2 (39299676-6) | C12: Previous Reading KWH | D12: 69022 | E12: Current Reading KWH | F12: 69035 | G12: Consumption KWH | H12: =F12-D12 -> 13
A13: MDB-G3 (39299677-4) | C13: Previous Reading KWH | D13: 70219 | E13: Current Reading KWH | F13: 70230 | G13: Consumption KWH | H13: =F13-D13 -> 11
A14: Total Consumption KWH | H14: =SUM(H11:H13) -> 32
A15: Total Consumption * Multiplication Factor (487.20) | H15: =H14*487.2 -> 15590.4
A16: Cost Calculation
A17: 0-2000 kwh @ 0.230 /KWH | D17: 460
A18: 2000-4000 kwh @ 0.280 /KWH | D18: 560
A19: 4000-6000 kwh @ 0.320 /KWH | D19: 640
A20: 6000 & above @ 0.380 /KWH | D20: =H15*0.38 -> 5924.352
A21: Fuel Surcharge @ 0.060 /KWH | D21: =H15*0.06 -> 935.424
A22: Grand Total Exc. VAT | D22: =D20+D21 -> 6859.776
A23: WATER
A24: Previous Reading | B24: 266323 | C24: Present Reading | D24: 266515 | E24: Consumption m3 | F24: =D24-B24 -> 192 | G24: Consumption IG | H24: =F24*220 -> 42240
A25: Cost calculation
A26: 0-10000 @ 0.035 / IG | D26: 350
A27: 10000-20000 @ 0.04 / IG | D27: 400
A28: 20000 & above @ 0.046 / IG | D28: =(H24-20000)*0.046 -> 1023.04
A29: Fuel Surcharge @ 0.004 / IG | D29: =H24*0.004 -> 168.96
A30: Sewerage Fees | D30: =H24*0.01 -> 422.4
A31: Grand Total Exc. VAT | D31: =SUM(D26:H30) -> 2364.4
A32: LPG Gas
A33: Tank 1 (1% = 48 liters) | C33: Previous Reading % | D33: 80 | E33: Current Reading % | F33: 80 | G33: Consumption Liters | H33: =(D33-F33)*48.8 -> 0
A34: Tank 2 (1% = 48 liters) | C34: Previous Reading % | D34: 80 | E34: Current Reading % | F34: 70 | G34: Consumption Liters | H34: =(D34-F34)*48.8 -> 488
A35: Total Cost (@ 1.82 AED/Liter) | H35: =((H34+H33)*1.82)*0.5 -> 444.08
A36: Total Utilities | H36: =H35+D22+D9+D31 -> 18545.938

Sheet May 15
A1: Daily Utilities Consumption
A2: 15.5.2024
A3: District Cooling
A4: Previous Reading MWh | B4: 61838.08 | C4: Current Reading MWh | D4: 61870.44 | E4: Consumption MWH | F4: =D4-B4 -> 32.36 | G4: Consumption RTH | H4: =F4*284.35 -> 9201.566
A5: Cost Calculation
A6: Total Cost (0.568/rth) | D6: =H4*0.568 -> 5226.4895
A7: Total Fuel Surchage Cost (0.075/rth) | D7: =H4*0.075 -> 690.11745
A8: Chilled Water Demand (2,866 AED/Day) | D8: 2866
A9: Grand Total Exc. VAT | D9: =SUM(D6:H8) -> 8782.6069
A10: Electrical
A11: MDB-G1 (39299675-8) | C11: Previous Reading KWH | D11: 41681 | E11: Current Reading KWH | F11: 41689 | G11: Consumption KWH | H11: =F11-D11 -> 8
A12: MDB-G2 (39299676-6) | C12: Previous Reading KWH | D12: 69010 | E12: Current Reading KWH | F12: 69022 | G12: Consumption KWH | H12: =F12-D12 -> 12
A13: MDB-G3 (39299677-4) | C13: Previous Reading KWH | D13: 70209 | E13: Current Reading KWH | F13: 70219 | G13: Consumption KWH | H13: =F13-D13 -> 10
A14: Total Consumption KWH | H14: =SUM(H11:H13) -> 30
A15: Total Consumption * Multiplication Factor (487.20) | H15: =H14*487.2 -> 14616
A16: Cost Calculation
A17: 0-2000 kwh @ 0.230 /KWH | D17: 460
A18: 2000-4000 kwh @ 0.280 /KWH | D18: 560
A19: 4000-6000 kwh @ 0.320 /KWH | D19: 640
A20: 6000 & above @ 0.380 /KWH | D20: =H15*0.38 -> 5554.08
A21: Fuel Surcharge @ 0.060 /KWH | D21: =H15*0.06 -> 876.96
A22: Grand Total Exc. VAT | D22: =D20+D21 -> 6431.04
A23: WATER
A24: Previous Reading | B24: 266128 | C24: Present Reading | D24: 266323 | E24: Consumption m3 | F24: =D24-B24 -> 195 | G24: Consumption IG | H24: =F24*220 -> 42900
A25: Cost calculation
A26: 0-10000 @ 0.035 / IG | D26: 350
A27: 10000-20000 @ 0.04 / IG | D27: 400
A28: 20000 & above @ 0.046 / IG | D28: =(H24-20000)*0.046 -> 1053.4
A29: Fuel Surcharge @ 0.004 / IG | D29: =H24*0.004 -> 171.6
A30: Sewerage Fees | D30: =H24*0.01 -> 429
A31: Grand Total Exc. VAT | D31: =SUM(D26:H30) -> 2404
A32: LPG Gas
A33: Tank 1 (1% = 48 liters) | C33: Previous Reading % | D33: 27 | E33: Current Reading % | F33: 17 | G33: Consumption Liters | H33: =(D33-F33)*48.8 -> 488
A34: Tank 2 (1% = 48 liters) | C34: Previous Reading % | D34: 80 | E34: Current Reading % | F34: 80 | G34: Consumption Liters | H34: =(D34-F34)*48.8 -> 0
A35: Total Cost (@ 1.82 AED/Liter) | H35: =((H34+H33)*1.82)*0.5 -> 444.08
A36: Total Utilities | H36: =H35+D22+D9+D31 -> 18061.727

Sheet May 14
A1: Daily Utilities Consumption
A2: 14.5.2024
A3: District Cooling
A4: Previous Reading MWh | B4: 61805.81 | C4: Current Reading MWh | D4: 61838.08 | E4: Consumption MWH | F4: =D4-B4 -> 32.27 | G4: Consumption RTH | H4: =F4*284.35 -> 9175.9745
A5: Cost Calculation
A6: Total Cost (0.568/rth) | D6: =H4*0.568 -> 5211.9535
A7: Total Fuel Surchage Cost (0.075/rth) | D7: =H4*0.075 -> 688.19809
A8: Chilled Water Demand (2,866 AED/Day) | D8: 2866
A9: Grand Total Exc. VAT | D9: =SUM(D6:H8) -> 8766.1516
A10: Electrical
A11: MDB-G1 (39299675-8) | C11: Previous Reading KWH | D11: 41673 | E11: Current Reading KWH | F11: 41681 | G11: Consumption KWH | H11: =F11-D11 -> 8
A12: MDB-G2 (39299676-6) | C12: Previous Reading KWH | D12: 68998 | E12: Current Reading KWH | F12: 69010 | G12: Consumption KWH | H12: =F12-D12 -> 12
A13: MDB-G3 (39299677-4) | C13: Previous Reading KWH | D13: 70198 | E13: Current Reading KWH | F13: 70209 | G13: Consumption KWH | H13: =F13-D13 -> 11
A14: Total Consumption KWH | H14: =SUM(H11:H13) -> 31
A15: Total Consumption * Multiplication Factor (487.20) | H15: =H14*487.2 -> 15103.2
A16: Cost Calculation
A17: 0-2000 kwh @ 0.230 /KWH | D17: 460
A18: 2000-4000 kwh @ 0.280 /KWH | D18: 560
A19: 4000-6000 kwh @ 0.320 /KWH | D19: 640
A20: 6000 & above @ 0.380 /KWH | D20: =H15*0.38 -> 5739.216
A21: Fuel Surcharge @ 0.060 /KWH | D21: =H15*0.06 -> 906.192
A22: Grand Total Exc. VAT | D22: =D20+D21 -> 6645.408
A23: WATER
A24: Previous Reading | B24: 265951 | C24: Present Reading | D24: 266128 | E24: Consumption m3 | F24: =D24-B24 -> 177 | G24: Consumption IG | H24: =F24*220 -> 38940
A25: Cost calculation
A26: 0-10000 @ 0.035 / IG | D26: 350
A27: 10000-20000 @ 0.04 / IG | D27: 400
A28: 20000 & above @ 0.046 / IG | D28: =(H24-20000)*0.046 -> 871.24
A29: Fuel Surcharge @ 0.004 / IG | D29: =H24*0.004 -> 155.76
A30: Sewerage Fees | D30: =H24*0.01 -> 389.4
A31: Grand Total Exc. VAT | D31: =SUM(D26:H30) -> 2166.4
A32: LPG Gas
A33: Tank 1 (1% = 48 liters) | C33: Previous Reading % | D33: 37 | E33: Current Reading % | F33: 27 | G33: Consumption Liters | H33: =(D33-F33)*48.8 -> 488
A34: Tank 2 (1% = 48 liters) | C34: Previous Reading % | D34: 80 | E34: Current Reading % | F34: 80 | G34: Consumption Liters | H34: =(D34-F34)*48.8 -> 0
A35: Total Cost (@ 1.82 AED/Liter) | H35: =((H34+H33)*1.82)*0.5 -> 444.08
A36: Total Utilities | H36: =H35+D22+D9+D31 -> 18022.04

Sheet May 13
A1: Daily Utilities Consumption
A2: 13.5.2024
A3: District Cooling
A4: Previous Reading MWh | B4: 61772.22 | C4: Current Reading MWh | D4: 61805.81 | E4: Consumption MWH | F4: =D4-B4 -> 33.59 | G4: Consumption RTH | H4: =F4*284.35 -> 9551.3165
A5: Cost Calculation
A6: Total Cost (0.568/rth) | D6: =H4*0.568 -> 5425.1478
A7: Total Fuel Surchage Cost (0.075/rth) | D7: =H4*0.075 -> 716.34874
A8: Chilled Water Demand (2,866 AED/Day) | D8: 2866
A9: Grand Total Exc. VAT | D9: =SUM(D6:H8) -> 9007.4965
A10: Electrical
A11: MDB-G1 (39299675-8) | C11: Previous Reading KWH | D11: 41665 | E11: Current Reading KWH | F11: 41673 | G11: Consumption KWH | H11: =F11-D11 -> 8
A12: MDB-G2 (39299676-6) | C12: Previous Reading KWH | D12: 68985 | E12: Current Reading KWH | F12: 68998 | G12: Consumption KWH | H12: =F12-D12 -> 13
A13: MDB-G3 (39299677-4) | C13: Previous Reading KWH | D13: 70188 | E13: Current Reading KWH | F13: 70198 | G13: Consumption KWH | H13: =F13-D13 -> 10
A14: Total Consumption KWH | H14: =SUM(H11:H13) -> 31
A15: Total Consumption * Multiplication Factor (487.20) | H15: =H14*487.2 -> 15103.2
A16: Cost Calculation
A17: 0-2000 kwh @ 0.230 /KWH | D17: 460
A18: 2000-4000 kwh @ 0.280 /KWH | D18: 560
A19: 4000-6000 kwh @ 0.320 /KWH | D19: 640
A20: 6000 & above @ 0.380 /KWH | D20: =H15*0.38 -> 5739.216
A21: Fuel Surcharge @ 0.060 /KWH | D21: =H15*0.06 -> 906.192
A22: Grand Total Exc. VAT | D22: =D20+D21 -> 6645.408
A23: WATER
A24: Previous Reading | B24: 265745 | C24: Present Reading | D24: 265951 | E24: Consumption m3 | F24: =D24-B24 -> 206 | G24: Consumption IG | H24: =F24*220 -> 45320
A25: Cost calculation
A26: 0-10000 @ 0.035 / IG | D26: 350
A27: 10000-20000 @ 0.04 / IG | D27: 400
A28: 20000 & above @ 0.046 / IG | D28: =(H24-20000)*0.046 -> 1164.72
A29: Fuel Surcharge @ 0.004 / IG | D29: =H24*0.004 -> 181.28
A30: Sewerage Fees | D30: =H24*0.01 -> 453.2
A31: Grand Total Exc. VAT | D31: =SUM(D26:H30) -> 2549.2
A32: LPG Gas
A33: Tank 1 (1% = 48 liters) | C33: Previous Reading % | D33: 47 | E33: Current Reading % | F33: 37 | G33: Consumption Liters | H33: =(D33-F33)*48.8 -> 488
A34: Tank 2 (1% = 48 liters) | C34: Previous Reading % | D34: 80 | E34: Current Reading % | F34: 80 | G34: Consumption Liters | H34: =(D34-F34)*48.8 -> 0
A35: Total Cost (@ 1.82 AED/Liter) | H35: =((H34+H33)*1.82)*0.5 -> 444.08
A36: Total Utilities | H36: =H35+D22+D9+D31 -> 18646.185

Sheet May 12
A1: Daily Utilities Consumption
A2: 12.5.2024
A3: District Cooling
A4: Previous Reading MWh | B4: 61741.21 | C4: Current Reading MWh | D4: 61772.22 | E4: Consumption MWH | F4: =D4-B4 -> 31.01 | G4: Consumption RTH | H4: =F4*284.35 -> 8817.6935
A5: Cost Calculation
A6: Total Cost (0.568/rth) | D6: =H4*0.568 -> 5008.4499
A7: Total Fuel Surchage Cost (0.075/rth) | D7: =H4*0.075 -> 661.32701
A8: Chilled Water Demand (2,866 AED/Day) | D8: 2866
A9: Grand Total Exc. VAT | D9: =SUM(D6:H8) -> 8535.7769
A10: Electrical
A11: MDB-G1 (39299675-8) | C11: Previous Reading KWH | D11: 41658 | E11: Current Reading KWH | F11: 41665 | G11: Consumption KWH | H11: =F11-D11 -> 7
A12: MDB-G2 (39299676-6) | C12: Previous Reading KWH | D12: 68973 | E12: Current Reading KWH | F12: 68985 | G12: Consumption KWH | H12: =F12-D12 -> 12
A13: MDB-G3 (39299677-4) | C13: Previous Reading KWH | D13: 70177 | E13: Current Reading KWH | F13: 70188 | G13: Consumption KWH | H13: =F13-D13 -> 11
A14: Total Consumption KWH | H14: =SUM(H11:H13) -> 30
A15: Total Consumption * Multiplication Factor (487.20) | H15: =H14*487.2 -> 14616
A16: Cost Calculation
A17: 0-2000 kwh @ 0.230 /KWH | D17: 460
A18: 2000-4000 kwh @ 0.280 /KWH | D18: 560
A19: 4000-6000 kwh @ 0.320 /KWH | D19: 640
A20: 6000 & above @ 0.380 /KWH | D20: =H15*0.38 -> 5554.08
A21: Fuel Surcharge @ 0.060 /KWH | D21: =H15*0.06 -> 876.96
A22: Grand Total Exc. VAT | D22: =D20+D21 -> 6431.04
A23: WATER
A24: Previous Reading | B24: 265539 | C24: Present Reading | D24: 265745 | E24: Consumption m3 | F24: =D24-B24 -> 206 | G24: Consumption IG | H24: =F24*220 -> 45320
A25: Cost calculation
A26: 0-10000 @ 0.035 / IG | D26: 350
A27: 10000-20000 @ 0.04 / IG | D27: 400
A28: 20000 & above @ 0.046 / IG | D28: =(H24-20000)*0.046 -> 1164.72
A29: Fuel Surcharge @ 0.004 / IG | D29: =H24*0.004 -> 181.28
A30: Sewerage Fees | D30: =H24*0.01 -> 453.2
A31: Grand Total Exc. VAT | D31: =SUM(D26:H30) -> 2549.2
A32: LPG Gas
A33: Tank 1 (1% = 48 liters) | C33: Previous Reading % | D33: 58 | E33: Current Reading % | F33: 47 | G33: Consumption Liters | H33: =(D33-F33)*48.8 -> 536.8
A34: Tank 2 (1% = 48 liters) | C34: Previous Reading % | D34: 80 | E34: Current Reading % | F34: 80 | G34: Consumption Liters | H34: =(D34-F34)*48.8 -> 0
A35: Total Cost (@ 1.82 AED/Liter) | H35: =((H34+H33)*1.82)*0.5 -> 488.488
A36: Total Utilities | H36: =H35+D22+D9+D31 -> 18004.505

Sheet May 11
A1: Daily Utilities Consumption
A2: 11.5.2024
A3: District Cooling
A4: Previous Reading MWh | B4: 61708.78 | C4: Current Reading MWh | D4: 61741.21 | E4: Consumption MWH | F4: =D4-B4 -> 32.43 | G4: Consumption RTH | H4: =F4*284.35 -> 9221.4705
A5: Cost Calculation
A6: Total Cost (0.568/rth) | D6: =H4*0.568 -> 5237.7952
A7: Total Fuel Surchage Cost (0.075/rth) | D7: =H4*0.075 -> 691.61029
A8: Chilled Water Demand (2,866 AED/Day) | D8: 2866
A9: Grand Total Exc. VAT | D9: =SUM(D6:H8) -> 8795.4055
A10: Electrical
A11: MDB-G1 (39299675-8) | C11: Previous Reading KWH | D11: 41650 | E11: Current Reading KWH | F11: 41658 | G11: Consumption KWH | H11: =F11-D11 -> 8
A12: MDB-G2 (39299676-6) | C12: Previous Reading KWH | D12: 68961 | E12: Current Reading KWH | F12: 68973 | G12: Consumption KWH | H12: =F12-D12 -> 12
A13: MDB-G3 (39299677-4) | C13: Previous Reading KWH | D13: 70167 | E13: Current Reading KWH | F13: 70177 | G13: Consumption KWH | H13: =F13-D13 -> 10
A14: Total Consumption KWH | H14: =SUM(H11:H13) -> 30
A15: Total Consumption * Multiplication Factor (487.20) | H15: =H14*487.2 -> 14616
A16: Cost Calculation
A17: 0-2000 kwh @ 0.230 /KWH | D17: 460
A18: 2000-4000 kwh @ 0.280 /KWH | D18: 560
A19: 4000-6000 kwh @ 0.320 /KWH | D19: 640
A20: 6000 & above @ 0.380 /KWH | D20: =H15*0.38 -> 5554.08
A21: Fuel Surcharge @ 0.060 /KWH | D21: =H15*0.06 -> 876.96
A22: Grand Total Exc. VAT | D22: =D20+D21 -> 6431.04
A23: WATER
A24: Previous Reading | B24: 265338 | C24: Present Reading | D24: 265539 | E24: Consumption m3 | F24: =D24-B24 -> 201 | G24: Consumption IG | H24: =F24*220 -> 44220
A25: Cost calculation
A26: 0-10000 @ 0.035 / IG | D26: 350
A27: 10000-20000 @ 0.04 / IG | D27: 400
A28: 20000 & above @ 0.046 / IG | D28: =(H24-20000)*0.046 -> 1114.12
A29: Fuel Surcharge @ 0.004 / IG | D29: =H24*0.004 -> 176.88
A30: Sewerage Fees | D30: =H24*0.01 -> 442.2
A31: Grand Total Exc. VAT | D31: =SUM(D26:H30) -> 2483.2
A32: LPG Gas
A33: Tank 1 (1% = 48 liters) | C33: Previous Reading % | D33: 68 | E33: Current Reading % | F33: 58 | G33: Consumption Liters | H33: =(D33-F33)*48.8 -> 488
A34: Tank 2 (1% = 48 liters) | C34: Previous Reading % | D34: 80 | E34: Current Reading % | F34: 80 | G34: Consumption Liters | H34: =(D34-F34)*48.8 -> 0
A35: Total Cost (@ 1.82 AED/Liter) | H35: =((H34+H33)*1.82)*0.5 -> 444.08
A36: Total Utilities | H36: =H35+D22+D9+D31 -> 18153.726

Sheet May 10
A1: Daily Utilities Consumption
A2: 10.5.2024
A3: District Cooling
