Workbook

Sheet Total
A1: Site Name | B1: Day | C1: Month | D1: Year | E1: Total Electricity Kwh | F1: Electricity Tariff ($/Kwh) | G1: Natural Gas (m3) | H1: Natural Gas $/m3 | I1: Water Utility Supply (m3) m3 | J1: Water Utility Supply (m3) $/m3 | K1: District Energy Cooling RTH | L1: District Energy Cooling $/RTH | M1: Room Nights | N1: Total Guests
A2: Pearl Rotana Capital Centre | B2: 1 | C2: 7 | D2: 2024 | E2: =Submetering!E2+Submetering!F2+Submetering!G2 -> 14309 | F2: 0.2 | G2: ='July 2024'!T5 -> 32.7267 | H2: 17.08 | I2: =Submetering!H2 -> 117 | J2: 7.84 | K2: ='July 2024'!X5 -> 10520.765 | L2: 0.36 | M2: =Submetering!N2 -> 302.9985 | N2: =Submetering!O2 -> 394
A3: Pearl Rotana Capital Centre | B3: =B2+1 -> 2 | C3: 7 | D3: 2024 | E3: =Submetering!E3+Submetering!F3+Submetering!G3 -> 14364 | F3: 0.2 | G3: ='July 2024'!T6 -> 32.7267 | H3: 17.08 | I3: =Submetering!H3 -> 113 | J3: 7.84 | K3: ='July 2024'!X6 -> 10520.765 | L3: 0.36 | M3: =Submetering!N3 -> 297.0135 | N3: =Submetering!O3 -> 367
A4: Pearl Rotana Capital Centre | B4: =B3+1 -> 3 | C4: 7 | D4: 2024 | E4: =Submetering!E4+Submetering!F4+Submetering!G4 -> 14575 | F4: 0.2 | G4: ='July 2024'!T7 -> 34.8381 | H4: 17.08 | I4: =Submetering!H4 -> 124 | J4: 7.84 | K4: ='July 2024'!X7 -> 11658.145 | L4: 0.36 | M4: =Submetering!N4 -> 293.9895 | N4: =Submetering!O4 -> 349
A5: Pearl Rotana Capital Centre | B5: =B4+1 -> 4 | C5: 7 | D5: 2024 | E5: =Submetering!E5+Submetering!F5+Submetering!G5 -> 14668 | F5: 0.2 | G5: ='July 2024'!T8 -> 36.9495 | H5: 17.08 | I5: =Submetering!H5 -> 103 | J5: 7.84 | K5: ='July 2024'!X8 -> 10805.11 | L5: 0.36 | M5: =Submetering!N5 -> 293.9895 | N5: =Submetering!O5 -> 372
A6: Pearl Rotana Capital Centre | B6: =B5+1 -> 5 | C6: 7 | D6: 2024 | E6: =Submetering!E6+Submetering!F6+Submetering!G6 -> 14737 | F6: 0.2 | G6: ='July 2024'!T9 -> 36.9495 | H6: 17.08 | I6: =Submetering!H6 -> 104 | J6: 7.84 | K6: ='July 2024'!X9 -> 11942.49 | L6: 0.36 | M6: =Submetering!N6 -> 234.99 | N6: =Submetering!O6 -> 339
A7: Pearl Rotana Capital Centre | B7: =B6+1 -> 6 | C7: 7 | D7: 2024 | E7: =Submetering!E7+Submetering!F7+Submetering!G7 -> 14258 | F7: 0.2 | G7: ='July 2024'!T10 -> 36.9495 | H7: 17.08 | I7: =Submetering!H7 -> 94 | J7: 7.84 | K7: ='July 2024'!X10 -> 10236.42 | L7: 0.36 | M7: =Submetering!N7 -> 198.009 | N7: =Submetering!O7 -> 273
A8: Pearl Rotana Capital Centre | B8: =B7+1 -> 7 | C8: 7 | D8: 2024 | E8: =Submetering!E8+Submetering!F8+Submetering!G8 -> 14290 | F8: 0.2 | G8: ='July 2024'!T11 -> 33.7824 | H8: 17.08 | I8: =Submetering!H8 -> 93 | J8: 7.84 | K8: ='July 2024'!X11 -> 10236.42 | L8: 0.36 | M8: =Submetering!N8 -> 262.9935 | N8: =Submetering!O8 -> 313
A9: Pearl Rotana Capital Centre | B9: =B8+1 -> 8 | C9: 7 | D9: 2024 | E9: =Submetering!E9+Submetering!F9+Submetering!G9 -> 14369 | F9: 0.2 | G9: ='July 2024'!T12 -> 33.7824 | H9: 17.08 | I9: =Submetering!H9 -> 109 | J9: 7.84 | K9: ='July 2024'!X12 -> 11942.49 | L9: 0.36 | M9: =Submetering!N9 -> 308.007 | N9: =Submetering!O9 -> 368
A10: Pearl Rotana Capital Centre | B10: =B9+1 -> 9 | C10: 7 | D10: 2024 | E10: =Submetering!E10+Submetering!F10+Submetering!G10 -> 14193 | F10: 0.2 | G10: ='July 2024'!T13 -> 33.7824 | H10: 17.08 | I10: =Submetering!H10 -> 112 | J10: 7.84 | K10: ='July 2024'!X13 -> 11658.145 | L10: 0.36 | M10: =Submetering!N10 -> 305.991 | N10: =Submetering!O10 -> 368
A11: Pearl Rotana Capital Centre | B11: =B10+1 -> 10 | C11: 7 | D11: 2024 | E11: =Submetering!E11+Submetering!F11+Submetering!G11 -> 14389 | F11: 0.2 | G11: ='July 2024'!T14 -> 32.7267 | H11: 17.08 | I11: =Submetering!H11 -> 116 | J11: 7.84 | K11: ='July 2024'!X14 -> 11373.8 | L11: 0.36 | M11: =Submetering!N11 -> 302.9985 | N11: =Submetering!O11 -> 365
A12: Pearl Rotana Capital Centre | B12: =B11+1 -> 11 | C12: 7 | D12: 2024 | E12: =Submetering!E12+Submetering!F12+Submetering!G12 -> 14184 | F12: 0.2 | G12: ='July 2024'!T15 -> 35.8938 | H12: 17.08 | I12: =Submetering!H12 -> 114 | J12: 7.84 | K12: ='July 2024'!X15 -> 11658.145 | L12: 0.36 | M12: =Submetering!N12 -> 261.9855 | N12: =Submetering!O12 -> 325
A13: Pearl Rotana Capital Centre | B13: =B12+1 -> 12 | C13: 7 | D13: 2024 | E13: =Submetering!E13+Submetering!F13+Submetering!G13 -> 14006 | F13: 0.2 | G13: ='July 2024'!T16 -> 36.9495 | H13: 17.08 | I13: =Submetering!H13 -> 107 | J13: 7.84 | K13: ='July 2024'!X16 -> 11089.455 | L13: 0.36 | M13: =Submetering!N13 -> 170.0055 | N13: =Submetering!O13 -> 231
A14: Pearl Rotana Capital Centre | B14: =B13+1 -> 13 | C14: 7 | D14: 2024 | E14: =Submetering!E14+Submetering!F14+Submetering!G14 -> 13765 | F14: 0.2 | G14: ='July 2024'!T17 -> 39.0609 | H14: 17.08 | I14: =Submetering!H14 -> 104 | J14: 7.84 | K14: ='July 2024'!X17 -> 9952.075 | L14: 0.36 | M14: =Submetering!N14 -> 187.0155 | N14: =Submetering!O14 -> 266
... A32: Pearl Rotana Capital Centre | B32: =B31+1 -> 31 | C32: 7 | D32: 2024 | E32: =Submetering!E32+Submetering!F32+Submetering!G32 -> 13370 | F32: 0.2 | G32: ='July 2024'!T35 -> 34.8381 | H32: 17.08 | I32: =Submetering!H32 -> 119 | J32: 7.84 | K32: ='July 2024'!X35 -> 11658.145 | L32: 0.36 | M32: =Submetering!N32 -> 310.9995 | N32: =Submetering!O32 -> 425

Sheet Submetering
A1: Site Name | B1: Day | C1: Month | D1: Year | E1: MDB#2 | F1: MDB#3 | G1: MDB#1 Façade | H1: Water | I1: Gas Meter#1 GF Kitchen | J1: Gas Meter#2 1st floor Kitchen | K1: District Cooling | L1: District Cooling ETS | M1: Water Main Kitchen | N1: Room Nights | O1: Total Guests
A2: Pearl Rotana Capital Centre | B2: 1 | C2: 7 | D2: 2024 | E2: ='July 2024'!C5 -> 7413 | F2: ='July 2024'!E5 -> 6790 | G2: ='July 2024'!G5 -> 106 | H2: ='July 2024'!K5 -> 117 | I2: ='July 2024'!N5 -> 18 | J2: ='July 2024'!P5 -> 13 | K2: ='July 2024'!X5 -> 10520.765 | L2: ='July 2024'!AC5 -> 12601 | M2: ='July 2024'!AP5 -> 10 | N2: ='July 2024'!AD5*315 -> 302.9985 | O2: ='July 2024'!AE5 -> 394
A3: Pearl Rotana Capital Centre | B3: =B2+1 -> 2 | C3: 7 | D3: 2024 | E3: ='July 2024'!C6 -> 7486 | F3: ='July 2024'!E6 -> 6772 | G3: ='July 2024'!G6 -> 106 | H3: ='July 2024'!K6 -> 113 | I3: ='July 2024'!N6 -> 19 | J3: ='July 2024'!P6 -> 13 | K3: ='July 2024'!X6 -> 10520.765 | L3: ='July 2024'!AC6 -> 12772 | M3: ='July 2024'!AP6 -> 9 | N3: ='July 2024'!AD6*315 -> 297.0135 | O3: ='July 2024'!AE6 -> 367
A4: Pearl Rotana Capital Centre | B4: =B3+1 -> 3 | C4: 7 | D4: 2024 | E4: ='July 2024'!C7 -> 7553 | F4: ='July 2024'!E7 -> 6916 | G4: ='July 2024'!G7 -> 106 | H4: ='July 2024'!K7 -> 124 | I4: ='July 2024'!N7 -> 19 | J4: ='July 2024'!P7 -> 14 | K4: ='July 2024'!X7 -> 11658.145 | L4: ='July 2024'!AC7 -> 14358 | M4: ='July 2024'!AP7 -> 14 | N4: ='July 2024'!AD7*315 -> 293.9895 | O4: ='July 2024'!AE7 -> 349
A5: Pearl Rotana Capital Centre | B5: =B4+1 -> 4 | C5: 7 | D5: 2024 | E5: ='July 2024'!C8 -> 7437 | F5: ='July 2024'!E8 -> 7124 | G5: ='July 2024'!G8 -> 107 | H5: ='July 2024'!K8 -> 103 | I5: ='July 2024'!N8 -> 19 | J5: ='July 2024'!P8 -> 15 | K5: ='July 2024'!X8 -> 10805.11 | L5: ='July 2024'!AC8 -> 13921 | M5: ='July 2024'!AP8 -> 9 | N5: ='July 2024'!AD8*315 -> 293.9895 | O5: ='July 2024'!AE8 -> 372
A6: Pearl Rotana Capital Centre | B6: =B5+1 -> 5 | C6: 7 | D6: 2024 | E6: ='July 2024'!C9 -> 7608 | F6: ='July 2024'!E9 -> 7030 | G6: ='July 2024'!G9 -> 99 | H6: ='July 2024'!K9 -> 104 | I6: ='July 2024'!N9 -> 20 | J6: ='July 2024'!P9 -> 15 | K6: ='July 2024'!X9 -> 11942.49 | L6: ='July 2024'!AC9 -> 14981 | M6: ='July 2024'!AP9 -> 7 | N6: ='July 2024'!AD9*315 -> 234.99 | O6: ='July 2024'!AE9 -> 339
A7: Pearl Rotana Capital Centre | B7: =B6+1 -> 6 | C7: 7 | D7: 2024 | E7: ='July 2024'!C10 -> 7414 | F7: ='July 2024'!E10 -> 6737 | G7: ='July 2024'!G10 -> 107 | H7: ='July 2024'!K10 -> 94 | I7: ='July 2024'!N10 -> 18 | J7: ='July 2024'!P10 -> 16 | K7: ='July 2024'!X10 -> 10236.42 | L7: ='July 2024'!AC10 -> 12656 | M7: ='July 2024'!AP10 -> 8 | N7: ='July 2024'!AD10*315 -> 198.009 | O7: ='July 2024'!AE10 -> 273
A8: Pearl Rotana Capital Centre | B8: =B7+1 -> 7 | C8: 7 | D8: 2024 | E8: ='July 2024'!C11 -> 7467 | F8: ='July 2024'!E11 -> 6717 | G8: ='July 2024'!G11 -> 106 | H8: ='July 2024'!K11 -> 93 | I8: ='July 2024'!N11 -> 17 | J8: ='July 2024'!P11 -> 16 | K8: ='July 2024'!X11 -> 10236.42 | L8: ='July 2024'!AC11 -> 12651 | M8: ='July 2024'!AP11 -> 7 | N8: ='July 2024'!AD11*315 -> 262.9935 | O8: ='July 2024'!AE11 -> 313
A9: Pearl Rotana Capital Centre | B9: =B8+1 -> 8 | C9: 7 | D9: 2024 | E9: ='July 2024'!C12 -> 7510 | F9: ='July 2024'!E12 -> 6752 | G9: ='July 2024'!G12 -> 107 | H9: ='July 2024'!K12 -> 109 | I9: ='July 2024'!N12 -> 18 | J9: ='July 2024'!P12 -> 13 | K9: ='July 2024'!X12 -> 11942.49 | L9: ='July 2024'!AC12 -> 14973 | M9: ='July 2024'!AP12 -> 10 | N9: ='July 2024'!AD12*315 -> 308.007 | O9: ='July 2024'!AE12 -> 368
A10: Pearl Rotana Capital Centre | B10: =B9+1 -> 9 | C10: 7 | D10: 2024 | E10: ='July 2024'!C13 -> 7380 | F10: ='July 2024'!E13 -> 6713 | G10: ='July 2024'!G13 -> 100 | H10: ='July 2024'!K13 -> 112 | I10: ='July 2024'!N13 -> 19 | J10: ='July 2024'!P13 -> 13 | K10: ='July 2024'!X13 -> 11658.145 | L10: ='July 2024'!AC13 -> 15113 | M10: ='July 2024'!AP13 -> 9 | N10: ='July 2024'!AD13*315 -> 305.991 | O10: ='July 2024'!AE13 -> 368
A11: Pearl Rotana Capital Centre | B11: =B10+1 -> 10 | C11: 7 | D11: 2024 | E11: ='July 2024'!C14 -> 7467 | F11: ='July 2024'!E14 -> 6817 | G11: ='July 2024'!G14 -> 105 | H11: ='July 2024'!K14 -> 116 | I11: ='July 2024'!N14 -> 18 | J11: ='July 2024'!P14 -> 12 | K11: ='July 2024'!X14 -> 11373.8 | L11: ='July 2024'!AC14 -> 14501 | M11: ='July 2024'!AP14 -> 9 | N11: ='July 2024'!AD14*315 -> 302.9985 | O11: ='July 2024'!AE14 -> 365
A12: Pearl Rotana Capital Centre | B12: =B11+1 -> 11 | C12: 7 | D12: 2024 | E12: ='July 2024'!C15 -> 7412 | F12: ='July 2024'!E15 -> 6668 | G12: ='July 2024'!G15 -> 104 | H12: ='July 2024'!K15 -> 114 | I12: ='July 2024'!N15 -> 18 | J12: ='July 2024'!P15 -> 16 | K12: ='July 2024'!X15 -> 11658.145 | L12: ='July 2024'!AC15 -> 14870 | M12: ='July 2024'!AP15 -> 11 | N12: ='July 2024'!AD15*315 -> 261.9855 | O12: ='July 2024'!AE15 -> 325
A13: Pearl Rotana Capital Centre | B13: =B12+1 -> 12 | C13: 7 | D13: 2024 | E13: ='July 2024'!C16 -> 7319 | F13: ='July 2024'!E16 -> 6582 | G13: ='July 2024'!G16 -> 105 | H13: ='July 2024'!K16 -> 107 | I13: ='July 2024'!N16 -> 19 | J13: ='July 2024'!P16 -> 15 | K13: ='July 2024'!X16 -> 11089.455 | L13: ='July 2024'!AC16 -> 14396 | M13: ='July 2024'!AP16 -> 11 | N13: ='July 2024'!AD16*315 -> 170.0055 | O13: ='July 2024'!AE16 -> 231
A14: Pearl Rotana Capital Centre | B14: =B13+1 -> 13 | C14: 7 | D14: 2024 | E14: ='July 2024'!C17 -> 7366 | F14: ='July 2024'!E17 -> 6293 | G14: ='July 2024'!G17 -> 106 | H14: ='July 2024'!K17 -> 104 | I14: ='July 2024'!N17 -> 19 | J14: ='July 2024'!P17 -> 17 | K14: ='July 2024'!X17 -> 9952.075 | L14: ='July 2024'!AC17 -> 12671 | M14: ='July 2024'!AP17 -> 9 | N14: ='July 2024'!AD17*315 -> 187.0155 | O14: ='July 2024'!AE17 -> 266
... A32: Pearl Rotana Capital Centre | B32: =B31+1 -> 31 | C32: 7 | D32: 2024 | E32: ='July 2024'!C35 -> 7174 | F32: ='July 2024'!E35 -> 6098 | G32: ='July 2024'!G35 -> 98 | H32: ='July 2024'!K35 -> 119 | I32: ='July 2024'!N35 -> 18 | J32: ='July 2024'!P35 -> 14 | K32: ='July 2024'!X35 -> 11658.145 | L32: ='July 2024'!AC35 -> 14393 | M32: ='July 2024'!AP35 -> 9 | N32: ='July 2024'!AD35*315 -> 310.9995 | O32: ='July 2024'!AE35 -> 425

Sheet July 2024
A1: PEARL ROTANA CAPITAL CENTRE UTILITIES CONSUMPTION - JULY 2024
A2: DATE | B2: Electricity | J2: Water | M2: SNG Gas | V2: District Cooling | AD2: Additional Info | AF2: Additional Meter
B3: MDB #2 | D3: MDB #3 | F3: MDB #1 Façade | H3: Total ELE Cons. KW | I3: Electricity AED | J3: Hotel Reading | K3: Water Cons. M3 | L3: Water AED | M3: Gas Meter #1 G Floor Kitchen | O3: Gas Meter #2 1st Floor Kitchen | Q3: Total Gas Cons. M3 | R3: PRS Meter Reading | S3: PRS Meter Cons. M3 | T3: Meter factor (1.05570) | U3: Gas AED | V3: Hotel BTU Meter Energy Reading | W3: District Cooling Cons. MWH | X3: District Cooling Cons. Ton Hour | Y3: District Cooling Cons. AED | Z3: District Cooling Fixed Charge | AA3: District Cooling Total AED | AB3: ETS Energy Meter Reading | AC3: ETS Cons. | AD3: Hotel Occupancy % | AE3: Adl. & Chl. | AF3: Electricity MDB-1 | AI3: Electricity MDB-E | AL3: Electricity-MCC Panel Chilled water Secondary Pumps | AO3: Water - Main kitchen | AR3: Water - Swimming Pool | AU3: Water - Bottling Plant
B4: Reading | C4: Cons. | D4: Reading | E4: Cons. | F4: Reading | G4: Cons. | M4: Reading | N4: Cons. | O4: Reading | P4: Cons. | AF4: Meter Reading | AG4: Cons. KWH | AH4: AED | AI4: Meter Reading | AJ4: Cons. KWH | AK4: AED | AL4: Meter Reading | AM4: Cons. KWH | AN4: AED | AO4: Meter Reading | AP4: Cons. M3 | AQ4: AED | AR4: Meter Reading | AS4: Cons. M3 | AT4: AED | AU4: Meter Reading | AV4: Cons. M3 | AW4: AED
A5: 45474 | B5: 19621826 | C5: 7413 | D5: 20453146 | E5: 6790 | F5: 462035 | G5: 106 | H5: =C5+E5+G5 -> 14309 | I5: =H5*0.2 -> 2861.8 | J5: 87201 | K5: 117 | L5: =K5*7.84 -> 917.28 | M5: 37034 | N5: 18 | O5: 21760 | P5: 13 | Q5: =N5+P5 -> 31 | R5: 54900 | S5: 31 | T5: =S5*1.0557 -> 32.7267 | U5: =IF(ISBLANK(M5),"0",T5*11.05+209.677) -> 571.30704 | V5: 69951 | W5: 37 | X5: =IF(ISBLANK(V5),"0 ",W5*284.345) -> 10520.765 | Y5: =X5*0.3442 -> 3621.2473 | Z5: =IF(ISBLANK(V5),"0",1570*1546.86/12/31*0.65) -> 4243.4694 | AA5: =Y5+Z5 -> 7864.7167 | AB5: 7027950 | AC5: 12601 | AD5: 0.9619 | AE5: 394 | AF5: 13773201 | AG5: 5935 | AH5: =AG5*0.2 -> 1187 | AI5: 6375295 | AJ5: 2256 | AK5: =AJ5*0.2 -> 451.2 | AL5: 156102 | AM5: 483 | AN5: =AM5*0.2 -> 96.6 | AO5: 6936 | AP5: 10 | AQ5: =AP5*7.84 -> 78.4 | AR5: 2869 | AS5: 1 | AT5: =AS5*7.84 -> 7.84 | AU5: 184 | AV5: 1 | AW5: =AV5*7.84 -> 7.84
A6: 45475 | B6: 19629312 | C6: =IF(ISBLANK(B6),"0",B6-B5) -> 7486 | D6: 20459918 | E6: =IF(ISBLANK(D6),"0",D6-D5) -> 6772 | F6: 462141 | G6: =IF(ISBLANK(F6),"0",F6-F5) -> 106 | H6: =C6+E6+G6 -> 14364 | I6: =H6*0.2 -> 2872.8 | J6: 87314 | K6: =IF(ISBLANK(J6),"0",J6-J5) -> 113 | L6: =K6*7.84 -> 885.92 | M6: 37053 | N6: =IF(ISBLANK(M6),"0",M6-M5) -> 19 | O6: 21773 | P6: =IF(ISBLANK(O6),"0",O6-O5) -> 13 | Q6: =N6+P6 -> 32 | R6: 54931 | S6: =IF(ISBLANK(R6),"0",R6-R5) -> 31 | T6: =S6*1.0557 -> 32.7267 | U6: =IF(ISBLANK(M6),"0",T6*11.05+209.677) -> 571.30704 | V6: 69988 | W6: =IF(ISBLANK(V6)," ",V6-V5) -> 37 | X6: =IF(ISBLANK(V6),"0 ",W6*284.345) -> 10520.765 | Y6: =X6*0.3442 -> 3621.2473 | Z6: =IF(ISBLANK(V6),"0",1570*1546.86/12/31*0.65) -> 4243.4694 | AA6: =Y6+Z6 -> 7864.7167 | AB6: 7040722 | AC6: =IF(ISBLANK(AB6),"0 ",AB6-AB5) -> 12772 | AD6: 0.9429 | AE6: 367 | AF6: 13779105 | AG6: =IF(ISBLANK(AF6),"0",AF6-AF5) -> 5904 | AH6: =AG6*0.2 -> 1180.8 | AI6: 6377512 | AJ6: =IF(ISBLANK(AI6),"0",AI6-AI5) -> 2217 | AK6: =AJ6*0.2 -> 443.4 | AL6: 156608 | AM6: =IF(ISBLANK(AL6),"0",AL6-AL5) -> 506 | AN6: =AM6*0.2 -> 101.2 | AO6: 6945 | AP6: =IF(ISBLANK(AO6),"0",AO6-AO5) -> 9 | AQ6: =AP6*7.84 -> 70.56 | AR6: 2870 | AS6: =IF(ISBLANK(AR6),"0",AR6-AR5) -> 1 | AT6: =AS6*7.84 -> 7.84 | AU6: 185 | AV6: =IF(ISBLANK(AU6),"0",AU6-AU5) -> 1 | AW6: =AV6*7.84 -> 7.84
A7: 45476 | B7: 19636865 | C7: =IF(ISBLANK(B7),"0",B7-B6) -> 7553 | D7: 20466834 | E7: =IF(ISBLANK(D7),"0",D7-D6) -> 6916 | F7: 462247 | G7: =IF(ISBLANK(F7),"0",F7-F6) -> 106 | H7: =C7+E7+G7 -> 14575 | I7: =H7*0.2 -> 2915 | J7: 87438 | K7: =IF(ISBLANK(J7),"0",J7-J6) -> 124 | L7: =K7*7.84 -> 972.16 | M7: 37072 | N7: =IF(ISBLANK(M7),"0",M7-M6) -> 19 | O7: 21787 | P7: =IF(ISBLANK(O7),"0",O7-O6) -> 14 | Q7: =N7+P7 -> 33 | R7: 54964 | S7: =IF(ISBLANK(R7),"0",R7-R6) -> 33 | T7: =S7*1.0557 -> 34.8381 | U7: =IF(ISBLANK(M7),"0",T7*11.05+209.677) -> 594.63801 | V7: 70029 | W7: =IF(ISBLANK(V7)," ",V7-V6) -> 41 | X7: =IF(ISBLANK(V7),"0 ",W7*284.345) -> 11658.145 | Y7: =X7*0.3442 -> 4012.7335 | Z7: =IF(ISBLANK(V7),"0",1570*1546.86/12/31*0.65) -> 4243.4694 | AA7: =Y7+Z7 -> 8256.2029 | AB7: 7055080 | AC7: =IF(ISBLANK(AB7),"0 ",AB7-AB6) -> 14358 | AD7: 0.9333 | AE7: 349 | AF7: 13785070 | AG7: =IF(ISBLANK(AF7),"0",AF7-AF6) -> 5965 | AH7: =AG7*0.2 -> 1193 | AI7: 6379754 | AJ7: =IF(ISBLANK(AI7),"0",AI7-AI6) -> 2242 | AK7: =AJ7*0.2 -> 448.4 | AL7: 157305 | AM7: =IF(ISBLANK(AL7),"0",AL7-AL6) -> 697 | AN7: =AM7*0.2 -> 139.4 | AO7: 6959 | AP7: =IF(ISBLANK(AO7),"0",AO7-AO6) -> 14 | AQ7: =AP7*7.84 -> 109.76 | AR7: 2871 | AS7: =IF(ISBLANK(AR7),"0",AR7-AR6) -> 1 | AT7: =AS7*7.84 -> 7.84 | AU7: 186 | AV7: =IF(ISBLANK(AU7),"0",AU7-AU6) -> 1 | AW7: =AV7*7.84 -> 7.84
A8: 45477 | B8: 19644302 | C8: =IF(ISBLANK(B8),"0",B8-B7) -> 7437 | D8: 20473958 | E8: =IF(ISBLANK(D8),"0",D8-D7) -> 7124 | F8: 462354 | G8: =IF(ISBLANK(F8),"0",F8-F7) -> 107 | H8: =C8+E8+G8 -> 14668 | I8: =H8*0.2 -> 2933.6 | J8: 87541 | K8: =IF(ISBLANK(J8),"0",J8-J7) -> 103 | L8: =K8*7.84 -> 807.52 | M8: 37091 | N8: =IF(ISBLANK(M8),"0",M8-M7) -> 19 | O8: 21802 | P8: =IF(ISBLANK(O8),"0",O8-O7) -> 15 | Q8: =N8+P8 -> 34 | R8: 54999 | S8: =IF(ISBLANK(R8),"0",R8-R7) -> 35 | T8: =S8*1.0557 -> 36.9495 | U8: =IF(ISBLANK(M8),"0",T8*11.05+209.677) -> 617.96898 | V8: 70067 | W8: =IF(ISBLANK(V8)," ",V8-V7) -> 38 | X8: =IF(ISBLANK(V8),"0 ",W8*284.345) -> 10805.11 | Y8: =X8*0.3442 -> 3719.1189 | Z8: =IF(ISBLANK(V8),"0",1570*1546.86/12/31*0.65) -> 4243.4694 | AA8: =Y8+Z8 -> 7962.5883 | AB8: 7069001 | AC8: =IF(ISBLANK(AB8),"0 ",AB8-AB7) -> 13921 | AD8: 0.9333 | AE8: 372 | AF8: 13790898 | AG8: =IF(ISBLANK(AF8),"0",AF8-AF7) -> 5828 | AH8: =AG8*0.2 -> 1165.6 | AI8: 6381934 | AJ8: =IF(ISBLANK(AI8),"0",AI8-AI7) -> 2180 | AK8: =AJ8*0.2 -> 436 | AL8: 157894 | AM8: =IF(ISBLANK(AL8),"0",AL8-AL7) -> 589 | AN8: =AM8*0.2 -> 117.8 | AO8: 6968 | AP8: =IF(ISBLANK(AO8),"0",AO8-AO7) -> 9 | AQ8: =AP8*7.84 -> 70.56 | AR8: 2872 | AS8: =IF(ISBLANK(AR8),"0",AR8-AR7) -> 1 | AT8: =AS8*7.84 -> 7.84 | AU8: 187 | AV8: =IF(ISBLANK(AU8),"0",AU8-AU7) -> 1 | AW8: =AV8*7.84 -> 7.84
A9: 45478 | B9: 19651910 | C9: =IF(ISBLANK(B9),"0",B9-B8) -> 7608 | D9: 20480988 | E9: =IF(ISBLANK(D9),"0",D9-D8) -> 7030 | F9: 462453 | G9: =IF(ISBLANK(F9),"0",F9-F8) -> 99 | H9: =C9+E9+G9 -> 14737 | I9: =H9*0.2 -> 2947.4 | J9: 87645 | K9: =IF(ISBLANK(J9),"0",J9-J8) -> 104 | L9: =K9*7.84 -> 815.36 | M9: 37111 | N9: =IF(ISBLANK(M9),"0",M9-M8) -> 20 | O9: 21817 | P9: =IF(ISBLANK(O9),"0",O9-O8) -> 15 | Q9: =N9+P9 -> 35 | R9: 55034 | S9: =IF(ISBLANK(R9),"0",R9-R8) -> 35 | T9: =S9*1.0557 -> 36.9495 | U9: =IF(ISBLANK(M9),"0",T9*11.05+209.677) -> 617.96898 | V9: 70109 | W9: =IF(ISBLANK(V9)," ",V9-V8) -> 42 | X9: =IF(ISBLANK(V9),"0 ",W9*284.345) -> 11942.49 | Y9: =X9*0.3442 -> 4110.6051 | Z9: =IF(ISBLANK(V9),"0",1570*1546.86/12/31*0.65) -> 4243.4694 | AA9: =Y9+Z9 -> 8354.0745 | AB9: 7083982 | AC9: =IF(ISBLANK(AB9),"0 ",AB9-AB8) -> 14981 | AD9: 0.746 | AE9: 339 | AF9: 13796612 | AG9: =IF(ISBLANK(AF9),"0",AF9-AF8) -> 5714 | AH9: =AG9*0.2 -> 1142.8 | AI9: 6384106 | AJ9: =IF(ISBLANK(AI9),"0",AI9-AI8) -> 2172 | AK9: =AJ9*0.2 -> 434.4 | AL9: 158492 | AM9: =IF(ISBLANK(AL9),"0",AL9-AL8) -> 598 | AN9: =AM9*0.2 -> 119.6 | AO9: 6975 | AP9: =IF(ISBLANK(AO9),"0",AO9-AO8) -> 7 | AQ9: =AP9*7.84 -> 54.88 | AR9: 2873 | AS9: =IF(ISBLANK(AR9),"0",AR9-AR8) -> 1 | AT9: =AS9*7.84 -> 7.84 | AU9: 188 | AV9: =IF(ISBLANK(AU9),"0",AU9-AU8) -> 1 | AW9: =AV9*7.84 -> 7.84
A10: 45479 | B10: 19659324 | C10: =IF(ISBLANK(B10),"0",B10-B9) -> 7414 | D10: 20487725 | E10: =IF(ISBLANK(D10),"0",D10-D9) -> 6737 | F10: 462560 | G10: =IF(ISBLANK(F10),"0",F10-F9) -> 107 | H10: =C10+E10+G10 -> 14258 | I10: =H10*0.2 -> 2851.6 | J10: 87739 | K10: =IF(ISBLANK(J10),"0",J10-J9) -> 94 | L10: =K10*7.84 -> 736.96 | M10: 37129 | N10: =IF(ISBLANK(M10),"0",M10-M9) -> 18 | O10: 21833 | P10: =IF(ISBLANK(O10),"0",O10-O9) -> 16 | Q10: =N10+P10 -> 34 | R10: 55069 | S10: =IF(ISBLANK(R10),"0",R10-R9) -> 35 | T10: =S10*1.0557 -> 36.9495 | U10: =IF(ISBLANK(M10),"0",T10*11.05+209.677) -> 617.96898 | V10: 70145 | W10: =IF(ISBLANK(V10)," ",V10-V9) -> 36 | X10: =IF(ISBLANK(V10),"0 ",W10*284.345) -> 10236.42 | Y10: =X10*0.3442 -> 3523.3758 | Z10: =IF(ISBLANK(V10),"0",1570*1546.86/12/31*0.65) -> 4243.4694 | AA10: =Y10+Z10 -> 7766.8452 | AB10: 7096638 | AC10: =IF(ISBLANK(AB10),"0 ",AB10-AB9) -> 12656 | AD10: 0.6286 | AE10: 273 | AF10: 13801399 | AG10: =IF(ISBLANK(AF10),"0",AF10-AF9) -> 4787 | AH10: =AG10*0.2 -> 957.4 | AI10: 6386132 | AJ10: =IF(ISBLANK(AI10),"0",AI10-AI9) -> 2026 | AK10: =AJ10*0.2 -> 405.2 | AL10: 158943 | AM10: =IF(ISBLANK(AL10),"0",AL10-AL9) -> 451 | AN10: =AM10*0.2 -> 90.2 | AO10: 6983 | AP10: =IF(ISBLANK(AO10),"0",AO10-AO9) -> 8 | AQ10: =AP10*7.84 -> 62.72 | AR10: 2874 | AS10: =IF(ISBLANK(AR10),"0",AR10-AR9) -> 1 | AT10: =AS10*7.84 -> 7.84 | AU10: 188 | AV10: =IF(ISBLANK(AU10),"0",AU10-AU9) -> 0 | AW10: =AV10*7.84 -> 0
A11: 45480 | B11: 19666791 | C11: =IF(ISBLANK(B11),"0",B11-B10) -> 7467 | D11: 20494442 | E11: =IF(ISBLANK(D11),"0",D11-D10) -> 6717 | F11: 462666 | G11: =IF(ISBLANK(F11),"0",F11-F10) -> 106 | H11: =C11+E11+G11 -> 14290 | I11: =H11*0.2 -> 2858 | J11: 87832 | K11: =IF(ISBLANK(J11),"0",J11-J10) -> 93 | L11: =K11*7.84 -> 729.12 | M11: 37146 | N11: =IF(ISBLANK(M11),"0",M11-M10) -> 17 | O11: 21849 | P11: =IF(ISBLANK(O11),"0",O11-O10) -> 16 | Q11: =N11+P11 -> 33 | R11: 55101 | S11: =IF(ISBLANK(R11),"0",R11-R10) -> 32 | T11: =S11*1.0557 -> 33.7824 | U11: =IF(ISBLANK(M11),"0",T11*11.05+209.677) -> 582.97252 | V11: 70181 | W11: =IF(ISBLANK(V11)," ",V11-V10) -> 36 | X11: =IF(ISBLANK(V11),"0 ",W11*284.345) -> 10236.42 | Y11: =X11*0.3442 -> 3523.3758 | Z11: =IF(ISBLANK(V11),"0",1570*1546.86/12/31*0.65) -> 4243.4694 | AA11: =Y11+Z11 -> 7766.8452 | AB11: 7109289 | AC11: =IF(ISBLANK(AB11),"0 ",AB11-AB10) -> 12651 | AD11: 0.8349 | AE11: 313 | AF11: 13806108 | AG11: =IF(ISBLANK(AF11),"0",AF11-AF10) -> 4709 | AH11: =AG11*0.2 -> 941.8 | AI11: 6388177 | AJ11: =IF(ISBLANK(AI11),"0",AI11-AI10) -> 2045 | AK11: =AJ11*0.2 -> 409 | AL11: 159391 | AM11: =IF(ISBLANK(AL11),"0",AL11-AL10) -> 448 | AN11: =AM11*0.2 -> 89.6 | AO11: 6990 | AP11: =IF(ISBLANK(AO11),"0",AO11-AO10) -> 7 | AQ11: =AP11*7.84 -> 54.88 | AR11: 2874 | AS11: =IF(ISBLANK(AR11),"0",AR11-AR10) -> 0 | AT11: =AS11*7.84 -> 0 | AU11: 189 | AV11: =IF(ISBLANK(AU11),"0",AU11-AU10) -> 1 | AW11: =AV11*7.84 -> 7.84
A12: 45481 | B12: 19674301 | C12: =IF(ISBLANK(B12),"0",B12-B11) -> 7510 | D12: 20501194 | E12: =IF(ISBLANK(D12),"0",D12-D11) -> 6752 | F12: 462773 | G12: =IF(ISBLANK(F12),"0",F12-F11) -> 107 | H12: =C12+E12+G12 -> 14369 | I12: =H12*0.2 -> 2873.8 | J12: 87941 | K12: =IF(ISBLANK(J12),"0",J12-J11) -> 109 | L12: =K12*7.84 -> 854.56 | M12: 37164 | N12: =IF(ISBLANK(M12),"0",M12-M11) -> 18 | O12: 21862 | P12: =IF(ISBLANK(O12),"0",O12-O11) -> 13 | Q12: =N12+P12 -> 31 | R12: 55133 | S12: =IF(ISBLANK(R12),"0",R12-R11) -> 32 | T12: =S12*1.0557 -> 33.7824 | U12: =IF(ISBLANK(M12),"0",T12*11.05+209.677) -> 582.97252 | V12: 70223 | W12: =IF(ISBLANK(V12)," ",V12-V11) -> 42 | X12: =IF(ISBLANK(V12),"0 ",W12*284.345) -> 11942.49 | Y12: =X12*0.3442 -> 4110.6051 | Z12: =IF(ISBLANK(V12),"0",1570*1546.86/12/31*0.65) -> 4243.4694 | AA12: =Y12+Z12 -> 8354.0745 | AB12: 7124262 | AC12: =IF(ISBLANK(AB12),"0 ",AB12-AB11) -> 14973 | AD12: 0.9778 | AE12: 368 | AF12: 13811934 | AG12: =IF(ISBLANK(AF12),"0",AF12-AF11) -> 5826 | AH12: =AG12*0.2 -> 1165.2 | AI12: 6390373 | AJ12: =IF(ISBLANK(AI12),"0",AI12-AI11) -> 2196 | AK12: =AJ12*0.2 -> 439.2 | AL12: 159944 | AM12: =IF(ISBLANK(AL12),"0",AL12-AL11) -> 553 | AN12: =AM12*0.2 -> 110.6 | AO12: 7000 | AP12: =IF(ISBLANK(AO12),"0",AO12-AO11) -> 10 | AQ12: =AP12*7.84 -> 78.4 | AR12: 2875 | AS12: =IF(ISBLANK(AR12),"0",AR12-AR11) -> 1 | AT12: =AS12*7.84 -> 7.84 | AU12: 0 | AV12: 0 | AW12: =AV12*7.84 -> 0 | AX12: New water meter installed.
A13: 45482 | B13: 19681681 | C13: =IF(ISBLANK(B13),"0",B13-B12) -> 7380 | D13: 20507907 | E13: =IF(ISBLANK(D13),"0",D13-D12) -> 6713 | F13: 462873 | G13: =IF(ISBLANK(F13),"0",F13-F12) -> 100 | H13: =C13+E13+G13 -> 14193 | I13: =H13*0.2 -> 2838.6 | J13: 88053 | K13: =IF(ISBLANK(J13),"0",J13-J12) -> 112 | L13: =K13*7.84 -> 878.08 | M13: 37183 | N13: =IF(ISBLANK(M13),"0",M13-M12) -> 19 | O13: 21875 | P13: =IF(ISBLANK(O13),"0",O13-O12) -> 13 | Q13: =N13+P13 -> 32 | R13: 55165 | S13: =IF(ISBLANK(R13),"0",R13-R12) -> 32 | T13: =S13*1.0557 -> 33.7824 | U13: =IF(ISBLANK(M13),"0",T13*11.05+209.677) -> 582.97252 | V13: 70264 | W13: =IF(ISBLANK(V13)," ",V13-V12) -> 41 | X13: =IF(ISBLANK(V13),"0 ",W13*284.345) -> 11658.145 | Y13: =X13*0.3442 -> 4012.7335 | Z13: =IF(ISBLANK(V13),"0",1570*1546.86/12/31*0.65) -> 4243.4694 | AA13: =Y13+Z13 -> 8256.2029 | AB13: 7139375 | AC13: =IF(ISBLANK(AB13),"0 ",AB13-AB12) -> 15113 | AD13: 0.9714 | AE13: 368 | AF13: 13817757 | AG13: =IF(ISBLANK(AF13),"0",AF13-AF12) -> 5823 | AH13: =AG13*0.2 -> 1164.6 | AI13: 6392589 | AJ13: =IF(ISBLANK(AI13),"0",AI13-AI12) -> 2216 | AK13: =AJ13*0.2 -> 443.2 | AL13: 160517 | AM13: =IF(ISBLANK(AL13),"0",AL13-AL12) -> 573 | AN13: =AM13*0.2 -> 114.6 | AO13: 7009 | AP13: =IF(ISBLANK(AO13),"0",AO13-AO12) -> 9 | AQ13: =AP13*7.84 -> 70.56 | AR13: 2877 | AS13: =IF(ISBLANK(AR13),"0",AR13-AR12) -> 2 | AT13: =AS13*7.84 -> 15.68 | AU13: 2 | AV13: =IF(ISBLANK(AU13),"0",AU13-AU12) -> 2 | AW13: =AV13*7.84 -> 15.68
A14: 45483 | B14: 19689148 | C14: =IF(ISBLANK(B14),"0",B14-B13) -> 7467 | D14: 20514724 | E14: =IF(ISBLANK(D14),"0",D14-D13) -> 6817 | F14: 462978 | G14: =IF(ISBLANK(F14),"0",F14-F13) -> 105 | H14: =C14+E14+G14 -> 14389 | I14: =H14*0.2 -> 2877.8 | J14: 88169 | K14: =IF(ISBLANK(J14),"0",J14-J13) -> 116 | L14: =K14*7.84 -> 909.44 | M14: 37201 | N14: =IF(ISBLANK(M14),"0",M14-M13) -> 18 | O14: 21887 | P14: =IF(ISBLANK(O14),"0",O14-O13) -> 12 | Q14: =N14+P14 -> 30 | R14: 55196 | S14: =IF(ISBLANK(R14),"0",R14-R13) -> 31 | T14: =S14*1.0557 -> 32.7267 | U14: =IF(ISBLANK(M14),"0",T14*11.05+209.677) -> 571.30704 | V14: 70304 | W14: =IF(ISBLANK(V14)," ",V14-V13) -> 40 | X14: =IF(ISBLANK(V14),"0 ",W14*284.345) -> 11373.8 | Y14: =X14*0.3442 -> 3914.862 | Z14: =IF(ISBLANK(V14),"0",1570*1546.86/12/31*0.65) -> 4243.4694 | AA14: =Y14+Z14 -> 8158.3314 | AB14: 7153876 | AC14: =IF(ISBLANK(AB14),"0 ",AB14-AB13) -> 14501 | AD14: 0.9619 | AE14: 365 | AF14: 13823677 | AG14: =IF(ISBLANK(AF14),"0",AF14-AF13) -> 5920 | AH14: =AG14*0.2 -> 1184 | AI14: 6394780 | AJ14: =IF(ISBLANK(AI14),"0",AI14-AI13) -> 2191 | AK14: =AJ14*0.2 -> 438.2 | AL14: 161022 | AM14: =IF(ISBLANK(AL14),"0",AL14-AL13) -> 505 | AN14: =AM14*0.2 -> 101 | AO14: 7018 | AP14: =IF(ISBLANK(AO14),"0",AO14-AO13) -> 9 | AQ14: =AP14*7.84 -> 70.56 | AR14: 2878 | AS14: =IF(ISBLANK(AR14),"0",AR14-AR13) -> 1 | AT14: =AS14*7.84 -> 7.84 | AU14: 3 | AV14: =IF(ISBLANK(AU14),"0",AU14-AU13) -> 1 | AW14: =AV14*7.84 -> 7.84
A15: 45484 | B15: 19696560 | C15: =IF(ISBLANK(B15),"0",B15-B14) -> 7412 | D15: 20521392 | E15: =IF(ISBLANK(D15),"0",D15-D14) -> 6668 | F15: 463082 | G15: =IF(ISBLANK(F15),"0",F15-F14) -> 104 | H15: =C15+E15+G15 -> 14184 | I15: =H15*0.2 -> 2836.8 | J15: 88283 | K15: =IF(ISBLANK(J15),"0",J15-J14) -> 114 | L15: =K15*7.84 -> 893.76 | M15: 37219 | N15: =IF(ISBLANK(M15),"0",M15-M14) -> 18 | O15: 21903 | P15: =IF(ISBLANK(O15),"0",O15-O14) -> 16 | Q15: =N15+P15 -> 34 | R15: 55230 | S15: =IF(ISBLANK(R15),"0",R15-R14) -> 34 | T15: =S15*1.0557 -> 35.8938 | U15: =IF(ISBLANK(M15),"0",T15*11.05+209.677) -> 606.30349 | V15: 70345 | W15: =IF(ISBLANK(V15)," ",V15-V14) -> 41 | X15: =IF(ISBLANK(V15),"0 ",W15*284.345) -> 11658.145 | Y15: =X15*0.3442 -> 4012.7335 | Z15: =IF(ISBLANK(V15),"0",1570*1546.86/12/31*0.65) -> 4243.4694 | AA15: =Y15+Z15 -> 8256.2029 | AB15: 7168746 | AC15: =IF(ISBLANK(AB15),"0 ",AB15-AB14) -> 14870 | AD15: 0.8317 | AE15: 325 | AF15: 13829550 | AG15: =IF(ISBLANK(AF15),"0",AF15-AF14) -> 5873 | AH15: =AG15*0.2 -> 1174.6 | AI15: 6396976 | AJ15: =IF(ISBLANK(AI15),"0",AI15-AI14) -> 2196 | AK15: =AJ15*0.2 -> 439.2 | AL15: 161544 | AM15: =IF(ISBLANK(AL15),"0",AL15-AL14) -> 522 | AN15: =AM15*0.2 -> 104.4 | AO15: 7029 | AP15: =IF(ISBLANK(AO15),"0",AO15-AO14) -> 11 | AQ15: =AP15*7.84 -> 86.24 | AR15: 2879 | AS15: =IF(ISBLANK(AR15),"0",AR15-AR14) -> 1 | AT15: =AS15*7.84 -> 7.84 | AU15: 4 | AV15: =IF(ISBLANK(AU15),"0",AU15-AU14) -> 1 | AW15: =AV15*7.84 -> 7.84
A16: 45485 | B16: 19703879 | C16: =IF(ISBLANK(B16),"0",B16-B15) -> 7319 | D16: 20527974 | E16: =IF(ISBLANK(D16),"0",D16-D15) -> 6582 | F16: 463187 | G16: =IF(ISBLANK(F16),"0",F16-F15) -> 105 | H16: =C16+E16+G16 -> 14006 | I16: =H16*0.2 -> 2801.2 | J16: 88390 | K16: =IF(ISBLANK(J16),"0",J16-J15) -> 107 | L16: =K16*7.84 -> 838.88 | M16: 37238 | N16: =IF(ISBLANK(M16),"0",M16-M15) -> 19 | O16: 21918 | P16: =IF(ISBLANK(O16),"0",O16-O15) -> 15 | Q16: =N16+P16 -> 34 | R16: 55265 | S16: =IF(ISBLANK(R16),"0",R16-R15) -> 35 | T16: =S16*1.0557 -> 36.9495 | U16: =IF(ISBLANK(M16),"0",T16*11.05+209.677) -> 617.96898 | V16: 70384 | W16: =IF(ISBLANK(V16)," ",V16-V15) -> 39 | X16: =IF(ISBLANK(V16),"0 ",W16*284.345) -> 11089.455 | Y16: =X16*0.3442 -> 3816.9904 | Z16: =IF(ISBLANK(V16),"0",1570*1546.86/12/31*0.65) -> 4243.4694 | AA16: =Y16+Z16 -> 8060.4598 | AB16: 7183142 | AC16: =IF(ISBLANK(AB16),"0 ",AB16-AB15) -> 14396 | AD16: 0.5397 | AE16: 231 | AF16: 13835299 | AG16: =IF(ISBLANK(AF16),"0",AF16-AF15) -> 5749 | AH16: =AG16*0.2 -> 1149.8 | AI16: 6399101 | AJ16: =IF(ISBLANK(AI16),"0",AI16-AI15) -> 2125 | AK16: =AJ16*0.2 -> 425 | AL16: 162083 | AM16: =IF(ISBLANK(AL16),"0",AL16-AL15) -> 539 | AN16: =AM16*0.2 -> 107.8 | AO16: 7040 | AP16: =IF(ISBLANK(AO16),"0",AO16-AO15) -> 11 | AQ16: =AP16*7.84 -> 86.24 | AR16: 2879 | AS16: =IF(ISBLANK(AR16),"0",AR16-AR15) -> 0 | AT16: =AS16*7.84 -> 0 | AU16: 5 | AV16: =IF(ISBLANK(AU16),"0",AU16-AU15) -> 1 | AW16: =AV16*7.84 -> 7.84
A17: 45486 | B17: 19711245 | C17: =IF(ISBLANK(B17),"0",B17-B16) -> 7366 | D17: 20534267 | E17: =IF(ISBLANK(D17),"0",D17-D16) -> 6293 | F17: 463293 | G17: =IF(ISBLANK(F17),"0",F17-F16) -> 106 | H17: =C17+E17+G17 -> 13765 | I17: =H17*0.2 -> 2753 | J17: 88494 | K17: =IF(ISBLANK(J17),"0",J17-J16) -> 104 | L17: =K17*7.84 -> 815.36 | M17: 37257 | N17: =IF(ISBLANK(M17),"0",M17-M16) -> 19 | O17: 21935 | P17: =IF(ISBLANK(O17),"0",O17-O16) -> 17 | Q17: =N17+P17 -> 36 | R17: 55302 | S17: =IF(ISBLANK(R17),"0",R17-R16) -> 37 | T17: =S17*1.0557 -> 39.0609 | U17: =IF(ISBLANK(M17),"0",T17*11.05+209.677) -> 641.29995 | V17: 70419 | W17: =IF(ISBLANK(V17)," ",V17-V16) -> 35 | X17: =IF(ISBLANK(V17),"0 ",W17*284.345) -> 9952.075 | Y17: =X17*0.3442 -> 3425.5042 | Z17: =IF(ISBLANK(V17),"0",1570*1546.86/12/31*0.65) -> 4243.4694 | AA17: =Y17+Z17 -> 7668.9737 | AB17: 7195813 | AC17: =IF(ISBLANK(AB17),"0 ",AB17-AB16) -> 12671 | AD17: 0.5937 | AE17: 266 | AF17: 13840353 | AG17: =IF(ISBLANK(AF17),"0",AF17-AF16) -> 5054 | AH17: =AG17*0.2 -> 1010.8 | AI17: 6401134 | AJ17: =IF(ISBLANK(AI17),"0",AI17-AI16) -> 2033 | AK17: =AJ17*0.2 -> 406.6 | AL17: 162523 | AM17: =IF(ISBLANK(AL17),"0",AL17-AL16) -> 440 | AN17: =AM17*0.2 -> 88 | AO17: 7049 | AP17: =IF(ISBLANK(AO17),"0",AO17-AO16) -> 9 | AQ17: =AP17*7.84 -> 70.56 | AR17: 2879 | AS17: =IF(ISBLANK(AR17),"0",AR17-AR16) -> 0 | AT17: =AS17*7.84 -> 0 | AU17: 6 | AV17: =IF(ISBLANK(AU17),"0",AU17-AU16) -> 1 | AW17: =AV17*7.84 -> 7.84
A18: 45487 | B18: 19718574 | C18: =IF(ISBLANK(B18),"0",B18-B17) -> 7329 | D18: 20540454 | E18: =IF(ISBLANK(D18),"0",D18-D17) -> 6187 | F18: 463391 | G18: =IF(ISBLANK(F18),"0",F18-F17) -> 98 | H18: =C18+E18+G18 -> 13614 | I18: =H18*0.2 -> 2722.8 | J18: 88586 | K18: =IF(ISBLANK(J18),"0",J18-J17) -> 92 | L18: =K18*7.84 -> 721.28 | M18: 37275 | N18: =IF(ISBLANK(M18),"0",M18-M17) -> 18 | O18: 21950 | P18: =IF(ISBLANK(O18),"0",O18-O17) -> 15 | Q18: =N18+P18 -> 33 | R18: 55334 | S18: =IF(ISBLANK(R18),"0",R18-R17) -> 32 | T18: =S18*1.0557 -> 33.7824 | U18: =IF(ISBLANK(M18),"0",T18*11.05+209.677) -> 582.97252 | V18: 70457 | W18: =IF(ISBLANK(V18)," ",V18-V17) -> 38 | X18: =IF(ISBLANK(V18),"0 ",W18*284.345) -> 10805.11 | Y18: =X18*0.3442 -> 3719.1189 | Z18: =IF(ISBLANK(V18),"0",1570*1546.86/12/31*0.65) -> 4243.4694 | AA18: =Y18+Z18 -> 7962.5883 | AB18: 7209168 | AC18: =IF(ISBLANK(AB18),"0 ",AB18-AB17) -> 13355 | AD18: 0.7397 | AE18: 306 | AF18: 13845370 | AG18: =IF(ISBLANK(AF18),"0",AF18-AF17) -> 5017 | AH18: =AG18*0.2 -> 1003.4 | AI18: 6403168 | AJ18: =IF(ISBLANK(AI18),"0",AI18-AI17) -> 2034 | AK18: =AJ18*0.2 -> 406.8 | AL18: 163005 | AM18: =IF(ISBLANK(AL18),"0",AL18-AL17) -> 482 | AN18: =AM18*0.2 -> 96.4 | AO18: 7057 | AP18: =IF(ISBLANK(AO18),"0",AO18-AO17) -> 8 | AQ18: =AP18*7.84 -> 62.72 | AR18: 2879 | AS18: =IF(ISBLANK(AR18),"0",AR18-AR17) -> 0 | AT18: =AS18*7.84 -> 0 | AU18: 7 | AV18: =IF(ISBLANK(AU18),"0",AU18-AU17) -> 1 | AW18: =AV18*7.84 -> 7.84
A19: 45488 | B19: 19726047 | C19: =IF(ISBLANK(B19),"0",B19-B18) -> 7473 | D19: 20546903 | E19: =IF(ISBLANK(D19),"0",D19-D18) -> 6449 | F19: 463494 | G19: =IF(ISBLANK(F19),"0",F19-F18) -> 103 | H19: =C19+E19+G19 -> 14025 | I19: =H19*0.2 -> 2805 | J19: 88703 | K19: =IF(ISBLANK(J19),"0",J19-J18) -> 117 | L19: =K19*7.84 -> 917.28 | M19: 37292 | N19: =IF(ISBLANK(M19),"0",M19-M18) -> 17 | O19: 21965 | P19: =IF(ISBLANK(O19),"0",O19-O18) -> 15 | Q19: =N19+P19 -> 32 | R19: 55366 | S19: =IF(ISBLANK(R19),"0",R19-R18) -> 32 | T19: =S19*1.0557 -> 33.7824 | U19: =IF(ISBLANK(M19),"0",T19*11.05+209.677) -> 582.97252 | V19: 70500 | W19: =IF(ISBLANK(V19)," ",V19-V18) -> 43 | X19: =IF(ISBLANK(V19),"0 ",W19*284.345) -> 12226.835 | Y19: =X19*0.3442 -> 4208.4766 | Z19: =IF(ISBLANK(V19),"0",1570*1546.86/12/31*0.65) -> 4243.4694 | AA19: =Y19+Z19 -> 8451.946 | AB19: 7225100 | AC19: =IF(ISBLANK(AB19),"0 ",AB19-AB18) -> 15932 | AD19: 0.946 | AE19: 388 | AF19: 13851292 | AG19: =IF(ISBLANK(AF19),"0",AF19-AF18) -> 5922 | AH19: =AG19*0.2 -> 1184.4 | AI19: 6405368 | AJ19: =IF(ISBLANK(AI19),"0",AI19-AI18) -> 2200 | AK19: =AJ19*0.2 -> 440 | AL19: 163557 | AM19: =IF(ISBLANK(AL19),"0",AL19-AL18) -> 552 | AN19: =AM19*0.2 -> 110.4 | AO19: 7066 | AP19: =IF(ISBLANK(AO19),"0",AO19-AO18) -> 9 | AQ19: =AP19*7.84 -> 70.56 | AR19: 2879 | AS19: =IF(ISBLANK(AR19),"0",AR19-AR18) -> 0 | AT19: =AS19*7.84 -> 0 | AU19: 8 | AV19: =IF(ISBLANK(AU19),"0",AU19-AU18) -> 1 | AW19: =AV19*7.84 -> 7.84
A20: 45489 | B20: 19733799 | C20: =IF(ISBLANK(B20),"0",B20-B19) -> 7752 | D20: 20553433 | E20: =IF(ISBLANK(D20),"0",D20-D19) -> 6530 | F20: 463588 | G20: =IF(ISBLANK(F20),"0",F20-F19) -> 94 | H20: =C20+E20+G20 -> 14376 | I20: =H20*0.2 -> 2875.2 | J20: 88874 | K20: =IF(ISBLANK(J20),"0",J20-J19) -> 171 | L20: =K20*7.84 -> 1340.64 | M20: 37310 | N20: =IF(ISBLANK(M20),"0",M20-M19) -> 18 | O20: 21981 | P20: =IF(ISBLANK(O20),"0",O20-O19) -> 16 | Q20: =N20+P20 -> 34 | R20: 55400 | S20: =IF(ISBLANK(R20),"0",R20-R19) -> 34 | T20: =S20*1.0557 -> 35.8938 | U20: =IF(ISBLANK(M20),"0",T20*11.05+209.677) -> 606.30349 | V20: 70546 | W20: =IF(ISBLANK(V20)," ",V20-V19) -> 46 | X20: =IF(ISBLANK(V20),"0 ",W20*284.345) -> 13079.87 | Y20: =X20*0.3442 -> 4502.0913 | Z20: =IF(ISBLANK(V20),"0",1570*1546.86/12/31*0.65) -> 4243.4694 | AA20: =Y20+Z20 -> 8745.5607 | AB20: 7241870 | AC20: =IF(ISBLANK(AB20),"0 ",AB20-AB19) -> 16770 | AD20: 0.9556 | AE20: 397 | AF20: 13857458 | AG20: =IF(ISBLANK(AF20),"0",AF20-AF19) -> 6166 | AH20: =AG20*0.2 -> 1233.2 | AI20: 6407711 | AJ20: =IF(ISBLANK(AI20),"0",AI20-AI19) -> 2343 | AK20: =AJ20*0.2 -> 468.6 | AL20: 164124 | AM20: =IF(ISBLANK(AL20),"0",AL20-AL19) -> 567 | AN20: =AM20*0.2 -> 113.4 | AO20: 7076 | AP20: =IF(ISBLANK(AO20),"0",AO20-AO19) -> 10 | AQ20: =AP20*7.84 -> 78.4 | AR20: 2879 | AS20: =IF(ISBLANK(AR20),"0",AR20-AR19) -> 0 | AT20: =AS20*7.84 -> 0 | AU20: 9 | AV20: =IF(ISBLANK(AU20),"0",AU20-AU19) -> 1 | AW20: =AV20*7.84 -> 7.84
A21: 45490 | B21: 19740756 | C21: =IF(ISBLANK(B21),"0",B21-B20) -> 6957 | D21: 20559404 | E21: =IF(ISBLANK(D21),"0",D21-D20) -> 5971 | F21: 463686 | G21: =IF(ISBLANK(F21),"0",F21-F20) -> 98 | H21: =C21+E21+G21 -> 13026 | I21: =H21*0.2 -> 2605.2 | J21: 88974 | K21: =IF(ISBLANK(J21),"0",J21-J20) -> 100 | L21: =K21*7.84 -> 784 | M21: 37328 | N21: =IF(ISBLANK(M21),"0",M21-M20) -> 18 | O21: 21994 | P21: =IF(ISBLANK(O21),"0",O21-O20) -> 13 | Q21: =N21+P21 -> 31 | R21: 55432 | S21: =IF(ISBLANK(R21),"0",R21-R20) -> 32 | T21: =S21*1.0557 -> 33.7824 | U21: =IF(ISBLANK(M21),"0",T21*11.05+209.677) -> 582.97252 | V21: 70590 | W21: =IF(ISBLANK(V21)," ",V21-V20) -> 44 | X21: =IF(ISBLANK(V21),"0 ",W21*284.345) -> 12511.18 | Y21: =X21*0.3442 -> 4306.3482 | Z21: =IF(ISBLANK(V21),"0",1570*1546.86/12/31*0.65) -> 4243.4694 | AA21: =Y21+Z21 -> 8549.8176 | AB21: 7256929 | AC21: =IF(ISBLANK(AB21),"0 ",AB21-AB20) -> 15059 | AD21: 0.8349 | AE21: 350 | AF21: 13863024 | AG21: =IF(ISBLANK(AF21),"0",AF21-AF20) -> 5566 | AH21: =AG21*0.2 -> 1113.2 | AI21: 6409717 | AJ21: =IF(ISBLANK(AI21),"0",AI21-AI20) -> 2006 | AK21: =AJ21*0.2 -> 401.2 | AL21: 164616 | AM21: =IF(ISBLANK(AL21),"0",AL21-AL20) -> 492 | AN21: =AM21*0.2 -> 98.4 | AO21: 7082 | AP21: =IF(ISBLANK(AO21),"0",AO21-AO20) -> 6 | AQ21: =AP21*7.84 -> 47.04 | AR21: 2879 | AS21: =IF(ISBLANK(AR21),"0",AR21-AR20) -> 0 | AT21: =AS21*7.84 -> 0 | AU21: 10 | AV21: =IF(ISBLANK(AU21),"0",AU21-AU20) -> 1 | AW21: =AV21*7.84 -> 7.84
A22: 45491 | B22: 19748363 | C22: =IF(ISBLANK(B22),"0",B22-B21) -> 7607 | D22: 20565972 | E22: =IF(ISBLANK(D22),"0",D22-D21) -> 6568 | F22: 463785 | G22: =IF(ISBLANK(F22),"0",F22-F21) -> 99 | H22: =C22+E22+G22 -> 14274 | I22: =H22*0.2 -> 2854.8 | J22: 89066 | K22: =IF(ISBLANK(J22),"0",J22-J21) -> 92 | L22: =K22*7.84 -> 721.28 | M22: 37346 | N22: =IF(ISBLANK(M22),"0",M22-M21) -> 18 | O22: 22007 | P22: =IF(ISBLANK(O22),"0",O22-O21) -> 13 | Q22: =N22+P22 -> 31 | R22: 55464 | S22: =IF(ISBLANK(R22),"0",R22-R21) -> 32 | T22: =S22*1.0557 -> 33.7824 | U22: =IF(ISBLANK(M22),"0",T22*11.05+209.677) -> 582.97252 | V22: 70633 | W22: =IF(ISBLANK(V22)," ",V22-V21) -> 43 | X22: =IF(ISBLANK(V22),"0 ",W22*284.345) -> 12226.835 | Y22: =X22*0.3442 -> 4208.4766 | Z22: =IF(ISBLANK(V22),"0",1570*1546.86/12/31*0.65) -> 4243.4694 | AA22: =Y22+Z22 -> 8451.946 | AB22: 7272536 | AC22: =IF(ISBLANK(AB22),"0 ",AB22-AB21) -> 15607 | AD22: 0.746 | AE22: 315 | AF22: 13869004 | AG22: =IF(ISBLANK(AF22),"0",AF22-AF21) -> 5980 | AH22: =AG22*0.2 -> 1196 | AI22: 6411864 | AJ22: =IF(ISBLANK(AI22),"0",AI22-AI21) -> 2147 | AK22: =AJ22*0.2 -> 429.4 | AL22: 165211 | AM22: =IF(ISBLANK(AL22),"0",AL22-AL21) -> 595 | AN22: =AM22*0.2 -> 119 | AO22: 7090 | AP22: =IF(ISBLANK(AO22),"0",AO22-AO21) -> 8 | AQ22: =AP22*7.84 -> 62.72 | AR22: 2879 | AS22: =IF(ISBLANK(AR22),"0",AR22-AR21) -> 0 | AT22: =AS22*7.84 -> 0 | AU22: 11 | AV22: =IF(ISBLANK(AU22),"0",AU22-AU21) -> 1 | AW22: =AV22*7.84 -> 7.84
A23: 45492 | B23: 19755727 | C23: =IF(ISBLANK(B23),"0",B23-B22) -> 7364 | D23: 20572495 | E23: =IF(ISBLANK(D23),"0",D23-D22) -> 6523 | F23: 463889 | G23: =IF(ISBLANK(F23),"0",F23-F22) -> 104 | H23: =C23+E23+G23 -> 13991 | I23: =H23*0.2 -> 2798.2 | J23: 89180 | K23: =IF(ISBLANK(J23),"0",J23-J22) -> 114 | L23: =K23*7.84 -> 893.76 | M23: 37365 | N23: =IF(ISBLANK(M23),"0",M23-M22) -> 19 | O23: 22023 | P23: =IF(ISBLANK(O23),"0",O23-O22) -> 16 | Q23: =N23+P23 -> 35 | R23: 55499 | S23: =IF(ISBLANK(R23),"0",R23-R22) -> 35 | T23: =S23*1.0557 -> 36.9495 | U23: =IF(ISBLANK(M23),"0",T23*11.05+209.677) -> 617.96898 | V23: 70677 | W23: =IF(ISBLANK(V23)," ",V23-V22) -> 44 | X23: =IF(ISBLANK(V23),"0 ",W23*284.345) -> 12511.18 | Y23: =X23*0.3442 -> 4306.3482 | Z23: =IF(ISBLANK(V23),"0",1570*1546.86/12/31*0.65) -> 4243.4694 | AA23: =Y23+Z23 -> 8549.8176 | AB23: 7287859 | AC23: =IF(ISBLANK(AB23),"0 ",AB23-AB22) -> 15323 | AD23: 0.6889 | AE23: 321 | AF23: 13874653 | AG23: =IF(ISBLANK(AF23),"0",AF23-AF22) -> 5649 | AH23: =AG23*0.2 -> 1129.8 | AI23: 6413967 | AJ23: =IF(ISBLANK(AI23),"0",AI23-AI22) -> 2103 | AK23: =AJ23*0.2 -> 420.6 | AL23: 165795 | AM23: =IF(ISBLANK(AL23),"0",AL23-AL22) -> 584 | AN23: =AM23*0.2 -> 116.8 | AO23: 7100 | AP23: =IF(ISBLANK(AO23),"0",AO23-AO22) -> 10 | AQ23: =AP23*7.84 -> 78.4 | AR23: 2883 | AS23: =IF(ISBLANK(AR23),"0",AR23-AR22) -> 4 | AT23: =AS23*7.84 -> 31.36 | AU23: 12 | AV23: =IF(ISBLANK(AU23),"0",AU23-AU22) -> 1 | AW23: =AV23*7.84 -> 7.84
A24: 45493 | B24: 19763046 | C24: =IF(ISBLANK(B24),"0",B24-B23) -> 7319 | D24: 20579142 | E24: =IF(ISBLANK(D24),"0",D24-D23) -> 6647 | F24: 463992 | G24: =IF(ISBLANK(F24),"0",F24-F23) -> 103 | H24: =C24+E24+G24 -> 14069 | I24: =H24*0.2 -> 2813.8 | J24: 89280 | K24: =IF(ISBLANK(J24),"0",J24-J23) -> 100 | L24: =K24*7.84 -> 784 | M24: 37384 | N24: =IF(ISBLANK(M24),"0",M24-M23) -> 19 | O24: 22036 | P24: =IF(ISBLANK(O24),"0",O24-O23) -> 13 | Q24: =N24+P24 -> 32 | R24: 55531 | S24: =IF(ISBLANK(R24),"0",R24-R23) -> 32 | T24: =S24*1.0557 -> 33.7824 | U24: =IF(ISBLANK(M24),"0",T24*11.05+209.677) -> 582.97252 | V24: 70721 | W24: =IF(ISBLANK(V24)," ",V24-V23) -> 44 | X24: =IF(ISBLANK(V24),"0 ",W24*284.345) -> 12511.18 | Y24: =X24*0.3442 -> 4306.3482 | Z24: =IF(ISBLANK(V24),"0",1570*1546.86/12/31*0.65) -> 4243.4694 | AA24: =Y24+Z24 -> 8549.8176 | AB24: 7303204 | AC24: =IF(ISBLANK(AB24),"0 ",AB24-AB23) -> 15345 | AD24: 0.6889 | AE24: 321 | AF24: 13879506 | AG24: =IF(ISBLANK(AF24),"0",AF24-AF23) -> 4853 | AH24: =AG24*0.2 -> 970.6 | AI24: 6416006 | AJ24: =IF(ISBLANK(AI24),"0",AI24-AI23) -> 2039 | AK24: =AJ24*0.2 -> 407.8 | AL24: 166359 | AM24: =IF(ISBLANK(AL24),"0",AL24-AL23) -> 564 | AN24: =AM24*0.2 -> 112.8 | AO24: 7105 | AP24: =IF(ISBLANK(AO24),"0",AO24-AO23) -> 5 | AQ24: =AP24*7.84 -> 39.2 | AR24: 2883 | AS24: =IF(ISBLANK(AR24),"0",AR24-AR23) -> 0 | AT24: =AS24*7.84 -> 0 | AU24: 13 | AV24: =IF(ISBLANK(AU24),"0",AU24-AU23) -> 1 | AW24: =AV24*7.84 -> 7.84
... A35: 45504 | B35: 19843676 | C35: =IF(ISBLANK(B35),"0",B35-B34) -> 7174 | D35: 20649916 | E35: =IF(ISBLANK(D35),"0",D35-D34) -> 6098 | F35: 465119 | G35: =IF(ISBLANK(F35),"0",F35-F34) -> 98 | H35: =C35+E35+G35 -> 13370 | I35: =H35*0.2 -> 2674 | J35: 90621 | K35: =IF(ISBLANK(J35),"0",J35-J34) -> 119 | L35: =K35*7.84 -> 932.96 | M35: 37584 | N35: =IF(ISBLANK(M35),"0",M35-M34) -> 18 | O35: 22191 | P35: =IF(ISBLANK(O35),"0",O35-O34) -> 14 | Q35: =N35+P35 -> 32 | R35: 55890 | S35: =IF(ISBLANK(R35),"0",R35-R34) -> 33 | T35: =S35*1.0557 -> 34.8381 | U35: =IF(ISBLANK(M35),"0",T35*11.05+209.677) -> 594.63801 | V35: 71180 | W35: =IF(ISBLANK(V35)," ",V35-V34) -> 41 | X35: =IF(ISBLANK(V35),"0 ",W35*284.345) -> 11658.145 | Y35: =X35*0.3442 -> 4012.7335 | Z35: =IF(ISBLANK(V35),"0",1570*1546.86/12/31*0.65) -> 4243.4694 | AA35: =Y35+Z35 -> 8256.2029 | AB35: 7464657 | AC35: =IF(ISBLANK(AB35),"0 ",AB35-AB34) -> 14393 | AD35: 0.9873 | AE35: 425 | AF35: 13941025 | AG35: =IF(ISBLANK(AF35),"0",AF35-AF34) -> 5730 | AH35: =AG35*0.2 -> 1146 | AI35: 6439661 | AJ35: =IF(ISBLANK(AI35),"0",AI35-AI34) -> 2126 | AK35: =AJ35*0.2 -> 425.2 | AL35: 172166 | AM35: =IF(ISBLANK(AL35),"0",AL35-AL34) -> 502 | AN35: =AM35*0.2 -> 100.4 | AO35: 7196 | AP35: =IF(ISBLANK(AO35),"0",AO35-AO34) -> 9 | AQ35: =AP35*7.84 -> 70.56 | AR35: 2994 | AS35: =IF(ISBLANK(AR35),"0",AR35-AR34) -> 0 | AT35: =AS35*7.84 -> 0 | AU35: 19 | AV35: =IF(ISBLANK(AU35),"0",AU35-AU34) -> 0 | AW35: =AV35*7.84 -> 0
C36: =SUM(C5:C35) -> 229263 | E36: =SUM(E5:E35) -> 203560 | G36: =SUM(G5:G35) -> 3190 | H36: =SUM(H5:H35) -> 436013 | I36: =H36*0.2 -> 87202.6 | K36: =SUM(K5:K35) -> 3537 | L36: =K36*7.84 -> 27730.08 | N36: =SUM(N5:N35) -> 568 | P36: =SUM(P5:P35) -> 444 | Q36: =SUM(Q5:Q35) -> 1012 | S36: =SUM(S5:S35) -> 1021 | T36: =SUM(T5:T35) -> 1077.8697 | U36: =SUM(U5:U35) -> 18410.447 | W36: =SUM(W5:W35) -> 1266 | X36: =SUM(X5:X35) -> 359980.77 | Y36: =SUM(Y5:Y35) -> 123905.38 | Z36: =SUM(Z5:Z35) -> 131547.55 | AA36: =SUM(AA5:AA35) -> 255452.93 | AC36: =SUM(AC5:AC35) -> 449308 | AD36: =AVERAGE(AD5:AD35) -> 0.85775806 | AE36: =SUM(AE5:AE35) -> 11115 | AG36: =SUM(AG5:AG35) -> 173759 | AH36: =SUM(AH5:AH35) -> 34751.8 | AJ36: =SUM(AJ5:AJ35) -> 66622 | AK36: =SUM(AK5:AK35) -> 13324.4 | AM36: =SUM(AM5:AM35) -> 16547 | AN36: =SUM(AN5:AN35) -> 3309.4 | AP36: =SUM(AP5:AP35) -> 270 | AQ36: =SUM(AQ5:AQ35) -> 2116.8 | AS36: =SUM(AS5:AS35) -> 126 | AT36: =SUM(AT5:AT35) -> 987.84 | AV36: =SUM(AV5:AV35) -> 25 | AW36: =SUM(AW5:AW35) -> 196
V37: AVT Charges should be Zero in the DC invoice - Please notify if not
B38: Electricity | D38: AED | G38: KW | J38: Water | L38: AED | M38: M3 | O38: Gas | R38: AED | T38: M3 | V38: Chilled Water | X38: AED | Z38: Ton Hour | AG38: =131547.55*7 -> 920832.85 | AH38: CHW Fixed Charges YTD 2024
B39: Actual July 2024 | D39: =I36 -> 87202.6 | G39: =D39/0.2 -> 436013 | J39: =B39 -> Actual July 2024 | L39: =L36 -> 27730.08 | M39: =K36 -> 3537 | O39: =B39 -> Actual July 2024 | R39: =U36 -> 18410.447 | T39: =T36 -> 1077.8697 | V39: =B39 -> Actual July 2024 | X39: =AA36 -> 255452.93 | Z39: =X36 -> 359980.77 | AD39: =AC36 -> 449308 | AE39: =AD39-X36 -> 89327.23 | AG39: =126488.42*7 -> 885418.94 | AH39: CHW Fixed Charges YTD 2023
B40: Budget July 2024 | D40: 97845.3 | G40: =D40/0.2 -> 489226.5 | J40: =B40 -> Budget July 2024 | L40: 24206.179 | M40: =L40/7.84 -> 3087.5229 | O40: =B40 -> Budget July 2024 | R40: 17051.903 | T40: =(R40-6500)/11.05 -> 954.92333 | V40: =B40 -> Budget July 2024 | X40: 263600.21 | Z40: =AG40/0.3442 -> 383650.96 | AD40: =R39/T39 -> 17.080401 | AG40: =X40-131547.55 -> 132052.66 | AH40: CHW Consumption Charges (Budgeted 2024 MTD)
B41: Actual July 2023 | D41: 96887.8 | G41: =D41/0.2 -> 484439 | J41: =B41 -> Actual July 2023 | L41: 24641.12 | M41: =L41/7.84 -> 3143 | O41: =B41 -> Actual July 2023 | R41: 17705.46 | T41: =(R41-6500)/11.05 -> 1014.0688 | V41: =B41 -> Actual July 2023 | X41: 253461.74 | Z41: =AG41/0.3435 -> 369645.76 | AG41: =X41-126488.42 -> 126973.32 | AH41: CHW Consumption Charges (Actual 2023 MTD)
B42: Actual YTD 2024 | D42: =D39+526580 -> 613782.6 | G42: =D42/0.2 -> 3068913 | J42: =B42 -> Actual YTD 2024 | L42: =L39+143009.44 -> 170739.52 | M42: =L42/7.84 -> 21778 | O42: =B42 -> Actual YTD 2024 | R42: =R39+110282.04 -> 128692.49 | T42: =(R42-6500*7)/11.05 -> 7528.7319 | V42: =B42 -> Actual YTD 2024 | X42: =X39+1215561.31 -> 1471014.2 | Z42: =AG42/0.3442 -> 1598435.2 | AG42: =X42-AG38 -> 550181.39 | AH42: CHW Consumption Charges (Actual 2024 YTD)
B43: Budget YTD 2024 | D43: =D40+574490.7 -> 672336 | G43: =D43/0.2 -> 3361680 | J43: =B43 -> Budget YTD 2024 | L43: =L40+144101.9 -> 168308.08 | M43: =L43/7.84 -> 21467.867 | O43: =B43 -> Budget YTD 2024 | R43: =R40+109114.94 -> 126166.84 | T43: =(R43-6500*7)/11.05 -> 7300.1668 | V43: =B43 -> Budget YTD 2024 | X43: =X40+1197324.4 -> 1460924.6 | Z43: =AG43/0.3442 -> 1569121.9 | AG43: =X43-AG38 -> 540091.76 | AH43: CHW Consumption Charges (Budgeted 2024 YTD)
B44: Actual YTD 2023 | D44: 656463 | G44: =D44/0.2 -> 3282315 | J44: =B44 -> Actual YTD 2023 | L44: 152362.56 | M44: =L44/7.84 -> 19434 | O44: =B44 -> Actual YTD 2023 | R44: 117302.25 | T44: =(R44-6500*7)/11.05 -> 6497.9412 | V44: =B44 -> Actual YTD 2023 | X44: 1396357 | Z44: =AG44/0.3435 -> 1487447.1 | AG44: =X44-AG39 -> 510938.08 | AH44: CHW Consumption Charges (Actual 2023 YTD)
H45: 45474 | I45: =TODAY() -> 45509 | J45: 31
A46: Monthly Budget | D46: Daily Budget | I46: MTD Average | N46: MTD Budget | U46: MTD Actual | Z46: YTD Budget | AD46: YTD Actual | AG46: Savings | AH46: Exceeds
A47: Electricity | B47: =D40 -> 97845.3 | D47: Electricity | G47: =B47/31 -> 3156.3 | I47: Electricity | L47: =I36/J45 -> 2812.9871 | N47: Electricity | R47: =G47*J45 -> 97845.3 | U47: Electricity | W47: =I36 -> 87202.6 | Y47: =R47-W47 -> 10642.7 | Z47: Electricity | AB47: =R47+574490.7 -> 672336 | AD47: Electricity | AF47: =W47+526580 -> 613782.6 | AG47: =AB47-AF47 -> 58553.4 | AH47: =AF47-AB47 -> -58553.4
A48: Water | B48: =L40 -> 24206.179 | D48: Water | G48: =B48/31 -> 780.8445 | I48: Water | L48: =L36/J45 -> 894.51871 | N48: Water | R48: =G48*J45 -> 24206.179 | U48: Water | W48: =L36 -> 27730.08 | Y48: =R48-W48 -> -3523.9006 | Z48: Water | AB48: =R48+144101.9 -> 168308.08 | AD48: Water | AF48: =W48+143009.44 -> 170739.52 | AG48: =AB48-AF48 -> -2431.4406 | AH48: =AF48-AB48 -> 2431.4406
A49: Gas | B49: =R40 -> 17051.903 | D49: Gas | G49: =B49/31 -> 550.06138 | I49: Gas | L49: =U36/J45 -> 593.88539 | N49: Gas | R49: =G49*J45 -> 17051.903 | U49: Gas | W49: =U36 -> 18410.447 | Y49: =R49-W49 -> -1358.5444 | Z49: Gas | AB49: =R49+109114.94 -> 126166.84 | AD49: Gas | AF49: =W49+110282.04 -> 128692.49 | AG49: =AB49-AF49 -> -2525.6444 | AH49: =AF49-AB49 -> 2525.6444
A50: Chilled Water | B50: =X40 -> 263600.21 | D50: Chilled Water | G50: =B50/31 -> 8503.2326 | I50: Chilled Water | L50: =AA36/J45 -> 8240.4172 | N50: Chilled Water | R50: =G50*J45 -> 263600.21 | U50: Chilled Water | W50: =AA36 -> 255452.93 | Y50: =R50-W50 -> 8147.2761 | Z50: Chilled Water | AB50: =R50+1197324.4 -> 1460924.6 | AD50: Chilled Water | AF50: =W50+1215561.31 -> 1471014.2 | AG50: =AB50-AF50 -> -10089.634 | AH50: =AF50-AB50 -> 10089.634
...
