Workbook

Sheet Total
A1: Site Name | B1: Day | C1: Month | D1: Year | E1: Total Electricity Kwh | F1: Electricity Tariff ($/Kwh) | G1: Natural Gas (m3) | H1: Natural Gas $/m3 | I1: Water Utility Supply (m3) m3 | J1: Water Utility Supply (m3) $/m3 | K1: District Energy Cooling RTH | L1: District Energy Cooling $/RTH | M1: Room Nights | N1: Total Guests
A2: Pearl Rotana Capital Centre | B2: 1 | C2: 6 | D2: 2024 | E2: =Submetering!E2+Submetering!F2+Submetering!G2 -> 14322 | F2: 0.2 | G2: ='June 2024'!T5 -> 35.8938 | H2: 11.902583 | I2: =Submetering!H2 -> 103 | J2: 7.84 | K2: =Submetering!K2 -> 9952.075 | L2: 0.75616225 | M2: =Submetering!N2 -> 191.9925 | N2: =Submetering!O2 -> 268
A3: Pearl Rotana Capital Centre | B3: =B2+1 -> 2 | C3: 6 | D3: 2024 | E3: =Submetering!E3+Submetering!F3+Submetering!G3 -> 14499 | F3: 0.2 | G3: ='June 2024'!T6 -> 36.9495 | H3: 11.902583 | I3: =Submetering!H3 -> 85 | J3: 7.84 | K3: =Submetering!K3 -> 10805.11 | L3: 0.75616225 | M3: =Submetering!N3 -> 261.009 | N3: =Submetering!O3 -> 319
A4: Pearl Rotana Capital Centre | B4: =B3+1 -> 3 | C4: 6 | D4: 2024 | E4: =Submetering!E4+Submetering!F4+Submetering!G4 -> 14601 | F4: 0.2 | G4: ='June 2024'!T7 -> 38.0052 | H4: 11.902583 | I4: =Submetering!H4 -> 100 | J4: 7.84 | K4: =Submetering!K4 -> 10520.765 | L4: 0.75616225 | M4: =Submetering!N4 -> 305.991 | N4: =Submetering!O4 -> 399
A5: Pearl Rotana Capital Centre | B5: =B4+1 -> 4 | C5: 6 | D5: 2024 | E5: =Submetering!E5+Submetering!F5+Submetering!G5 -> 14594 | F5: 0.2 | G5: ='June 2024'!T8 -> 39.0609 | H5: 11.902583 | I5: =Submetering!H5 -> 101 | J5: 7.84 | K5: =Submetering!K5 -> 10805.11 | L5: 0.75616225 | M5: =Submetering!N5 -> 312.0075 | N5: =Submetering!O5 -> 414
A6: Pearl Rotana Capital Centre | B6: =B5+1 -> 5 | C6: 6 | D6: 2024 | E6: =Submetering!E6+Submetering!F6+Submetering!G6 -> 14851 | F6: 0.2 | G6: ='June 2024'!T9 -> 41.1723 | H6: 11.902583 | I6: =Submetering!H6 -> 105 | J6: 7.84 | K6: =Submetering!K6 -> 10236.42 | L6: 0.75616225 | M6: =Submetering!N6 -> 276.003 | N6: =Submetering!O6 -> 359
A7: Pearl Rotana Capital Centre | B7: =B6+1 -> 6 | C7: 6 | D7: 2024 | E7: =Submetering!E7+Submetering!F7+Submetering!G7 -> 14352 | F7: 0.2 | G7: ='June 2024'!T10 -> 42.228 | H7: 11.902583 | I7: =Submetering!H7 -> 113 | J7: 7.84 | K7: =Submetering!K7 -> 9099.04 | L7: 0.75616225 | M7: =Submetering!N7 -> 293.9895 | N7: =Submetering!O7 -> 428
A8: Pearl Rotana Capital Centre | B8: =B7+1 -> 7 | C8: 6 | D8: 2024 | E8: =Submetering!E8+Submetering!F8+Submetering!G8 -> 14069 | F8: 0.2 | G8: ='June 2024'!T11 -> 42.228 | H8: 11.902583 | I8: =Submetering!H8 -> 102 | J8: 7.84 | K8: =Submetering!K8 -> 9952.075 | L8: 0.75616225 | M8: =Submetering!N8 -> 281.988 | N8: =Submetering!O8 -> 424
A9: Pearl Rotana Capital Centre | B9: =B8+1 -> 8 | C9: 6 | D9: 2024 | E9: =Submetering!E9+Submetering!F9+Submetering!G9 -> 13810 | F9: 0.2 | G9: ='June 2024'!T12 -> 38.0052 | H9: 11.902583 | I9: =Submetering!H9 -> 96 | J9: 7.84 | K9: =Submetering!K9 -> 9383.385 | L9: 0.75616225 | M9: =Submetering!N9 -> 292.005 | N9: =Submetering!O9 -> 446
A10: Pearl Rotana Capital Centre | B10: =B9+1 -> 9 | C10: 6 | D10: 2024 | E10: =Submetering!E10+Submetering!F10+Submetering!G10 -> 14140 | F10: 0.2 | G10: ='June 2024'!T13 -> 39.0609 | H10: 11.902583 | I10: =Submetering!H10 -> 110 | J10: 7.84 | K10: =Submetering!K10 -> 10520.765 | L10: 0.75616225 | M10: =Submetering!N10 -> 273.987 | N10: =Submetering!O10 -> 367
A11: Pearl Rotana Capital Centre | B11: =B10+1 -> 10 | C11: 6 | D11: 2024 | E11: =Submetering!E11+Submetering!F11+Submetering!G11 -> 14209 | F11: 0.2 | G11: ='June 2024'!T14 -> 40.1166 | H11: 11.902583 | I11: =Submetering!H11 -> 98 | J11: 7.84 | K11: =Submetering!K11 -> 10805.11 | L11: 0.75616225 | M11: =Submetering!N11 -> 268.002 | N11: =Submetering!O11 -> 328
A12: Pearl Rotana Capital Centre | B12: =B11+1 -> 11 | C12: 6 | D12: 2024 | E12: =Submetering!E12+Submetering!F12+Submetering!G12 -> 14399 | F12: 0.2 | G12: ='June 2024'!T15 -> 40.1166 | H12: 11.902583 | I12: =Submetering!H12 -> 99 | J12: 7.84 | K12: =Submetering!K12 -> 10520.765 | L12: 0.75616225 | M12: =Submetering!N12 -> 252 | N12: =Submetering!O12 -> 309
A13: Pearl Rotana Capital Centre | B13: =B12+1 -> 12 | C13: 6 | D13: 2024 | E13: =Submetering!E13+Submetering!F13+Submetering!G13 -> 14269 | F13: 0.2 | G13: ='June 2024'!T16 -> 39.0609 | H13: 11.902583 | I13: =Submetering!H13 -> 90 | J13: 7.84 | K13: =Submetering!K13 -> 9952.075 | L13: 0.75616225 | M13: =Submetering!N13 -> 230.013 | N13: =Submetering!O13 -> 285
A14: Pearl Rotana Capital Centre | B14: =B13+1 -> 13 | C14: 6 | D14: 2024 | E14: =Submetering!E14+Submetering!F14+Submetering!G14 -> 14331 | F14: 0.2 | G14: ='June 2024'!T17 -> 39.0609 | H14: 11.902583 | I14: =Submetering!H14 -> 94 | J14: 7.84 | K14: =Submetering!K14 -> 10236.42 | L14: 0.75616225 | M14: =Submetering!N14 -> 226.989 | N14: =Submetering!O14 -> 298
... A31: Pearl Rotana Capital Centre | B31: =B30+1 -> 30 | C31: 6 | D31: 2024 | E31: =Submetering!E31+Submetering!F31+Submetering!G31 -> 14075 | F31: 0.2 | G31: ='June 2024'!T34 -> 33.7824 | H31: 11.902583 | I31: =Submetering!H31 -> 111 | J31: 7.84 | K31: =Submetering!K31 -> 10805.11 | L31: 0.75616225 | M31: =Submetering!N31 -> 293.013 | N31: =Submetering!O31 -> 406

Sheet Submetering
A1: Site Name | B1: Day | C1: Month | D1: Year | E1: MDB#2 | F1: MDB#3 | G1: MDB#1 Façade | H1: Water | I1: Gas Meter#1 GF Kitchen | J1: Gas Meter#2 1st floor Kitchen | K1: District Cooling | L1: District Cooling ETS | M1: Water Main Kitchen | N1: Room Nights | O1: Total Guests
A2: Pearl Rotana Capital Centre | B2: 1 | C2: 6 | D2: 2024 | E2: ='June 2024'!C5 -> 7990 | F2: ='June 2024'!E5 -> 6217 | G2: ='June 2024'!G5 -> 115 | H2: ='June 2024'!K5 -> 103 | I2: ='June 2024'!N5 -> 19 | J2: ='June 2024'!P5 -> 14 | K2: ='June 2024'!X5 -> 9952.075 | L2: ='June 2024'!AC5 -> 12601 | M2: ='June 2024'!AP5 -> 12 | N2: ='June 2024'!AD5*315 -> 191.9925 | O2: ='June 2024'!AE5 -> 268
A3: Pearl Rotana Capital Centre | B3: =B2+1 -> 2 | C3: 6 | D3: 2024 | E3: ='June 2024'!C6 -> 7934 | F3: ='June 2024'!E6 -> 6454 | G3: ='June 2024'!G6 -> 111 | H3: ='June 2024'!K6 -> 85 | I3: ='June 2024'!N6 -> 19 | J3: ='June 2024'!P6 -> 16 | K3: ='June 2024'!X6 -> 10805.11 | L3: ='June 2024'!AC6 -> 12546 | M3: ='June 2024'!AP6 -> 10 | N3: ='June 2024'!AD6*315 -> 261.009 | O3: ='June 2024'!AE6 -> 319
A4: Pearl Rotana Capital Centre | B4: =B3+1 -> 3 | C4: 6 | D4: 2024 | E4: ='June 2024'!C7 -> 8015 | F4: ='June 2024'!E7 -> 6474 | G4: ='June 2024'!G7 -> 112 | H4: ='June 2024'!K7 -> 100 | I4: ='June 2024'!N7 -> 18 | J4: ='June 2024'!P7 -> 18 | K4: ='June 2024'!X7 -> 10520.765 | L4: ='June 2024'!AC7 -> 12719 | M4: ='June 2024'!AP7 -> 7 | N4: ='June 2024'!AD7*315 -> 305.991 | O4: ='June 2024'!AE7 -> 399
A5: Pearl Rotana Capital Centre | B5: =B4+1 -> 4 | C5: 6 | D5: 2024 | E5: ='June 2024'!C8 -> 7999 | F5: ='June 2024'!E8 -> 6482 | G5: ='June 2024'!G8 -> 113 | H5: ='June 2024'!K8 -> 101 | I5: ='June 2024'!N8 -> 19 | J5: ='June 2024'!P8 -> 18 | K5: ='June 2024'!X8 -> 10805.11 | L5: ='June 2024'!AC8 -> 12898 | M5: ='June 2024'!AP8 -> 9 | N5: ='June 2024'!AD8*315 -> 312.0075 | O5: ='June 2024'!AE8 -> 414
A6: Pearl Rotana Capital Centre | B6: =B5+1 -> 5 | C6: 6 | D6: 2024 | E6: ='June 2024'!C9 -> 8139 | F6: ='June 2024'!E9 -> 6602 | G6: ='June 2024'!G9 -> 110 | H6: ='June 2024'!K9 -> 105 | I6: ='June 2024'!N9 -> 19 | J6: ='June 2024'!P9 -> 21 | K6: ='June 2024'!X9 -> 10236.42 | L6: ='June 2024'!AC9 -> 12321 | M6: ='June 2024'!AP9 -> 8 | N6: ='June 2024'!AD9*315 -> 276.003 | O6: ='June 2024'!AE9 -> 359
A7: Pearl Rotana Capital Centre | B7: =B6+1 -> 6 | C7: 6 | D7: 2024 | E7: ='June 2024'!C10 -> 7704 | F7: ='June 2024'!E10 -> 6529 | G7: ='June 2024'!G10 -> 119 | H7: ='June 2024'!K10 -> 113 | I7: ='June 2024'!N10 -> 20 | J7: ='June 2024'!P10 -> 20 | K7: ='June 2024'!X10 -> 9099.04 | L7: ='June 2024'!AC10 -> 11033 | M7: ='June 2024'!AP10 -> 12 | N7: ='June 2024'!AD10*315 -> 293.9895 | O7: ='June 2024'!AE10 -> 428
A8: Pearl Rotana Capital Centre | B8: =B7+1 -> 7 | C8: 6 | D8: 2024 | E8: ='June 2024'!C11 -> 7566 | F8: ='June 2024'!E11 -> 6389 | G8: ='June 2024'!G11 -> 114 | H8: ='June 2024'!K11 -> 102 | I8: ='June 2024'!N11 -> 20 | J8: ='June 2024'!P11 -> 20 | K8: ='June 2024'!X11 -> 9952.075 | L8: ='June 2024'!AC11 -> 11748 | M8: ='June 2024'!AP11 -> 9 | N8: ='June 2024'!AD11*315 -> 281.988 | O8: ='June 2024'!AE11 -> 424
A9: Pearl Rotana Capital Centre | B9: =B8+1 -> 8 | C9: 6 | D9: 2024 | E9: ='June 2024'!C12 -> 7428 | F9: ='June 2024'!E12 -> 6272 | G9: ='June 2024'!G12 -> 110 | H9: ='June 2024'!K12 -> 96 | I9: ='June 2024'!N12 -> 18 | J9: ='June 2024'!P12 -> 18 | K9: ='June 2024'!X12 -> 9383.385 | L9: ='June 2024'!AC12 -> 11114 | M9: ='June 2024'!AP12 -> 12 | N9: ='June 2024'!AD12*315 -> 292.005 | O9: ='June 2024'!AE12 -> 446
A10: Pearl Rotana Capital Centre | B10: =B9+1 -> 9 | C10: 6 | D10: 2024 | E10: ='June 2024'!C13 -> 7598 | F10: ='June 2024'!E13 -> 6429 | G10: ='June 2024'!G13 -> 113 | H10: ='June 2024'!K13 -> 110 | I10: ='June 2024'!N13 -> 18 | J10: ='June 2024'!P13 -> 19 | K10: ='June 2024'!X13 -> 10520.765 | L10: ='June 2024'!AC13 -> 12408 | M10: ='June 2024'!AP13 -> 10 | N10: ='June 2024'!AD13*315 -> 273.987 | O10: ='June 2024'!AE13 -> 367
A11: Pearl Rotana Capital Centre | B11: =B10+1 -> 10 | C11: 6 | D11: 2024 | E11: ='June 2024'!C14 -> 7719 | F11: ='June 2024'!E14 -> 6377 | G11: ='June 2024'!G14 -> 113 | H11: ='June 2024'!K14 -> 98 | I11: ='June 2024'!N14 -> 19 | J11: ='June 2024'!P14 -> 19 | K11: ='June 2024'!X14 -> 10805.11 | L11: ='June 2024'!AC14 -> 12777 | M11: ='June 2024'!AP14 -> 9 | N11: ='June 2024'!AD14*315 -> 268.002 | O11: ='June 2024'!AE14 -> 328
A12: Pearl Rotana Capital Centre | B12: =B11+1 -> 11 | C12: 6 | D12: 2024 | E12: ='June 2024'!C15 -> 7728 | F12: ='June 2024'!E15 -> 6558 | G12: ='June 2024'!G15 -> 113 | H12: ='June 2024'!K15 -> 99 | I12: ='June 2024'!N15 -> 18 | J12: ='June 2024'!P15 -> 19 | K12: ='June 2024'!X15 -> 10520.765 | L12: ='June 2024'!AC15 -> 12649 | M12: ='June 2024'!AP15 -> 9 | N12: ='June 2024'!AD15*315 -> 252 | O12: ='June 2024'!AE15 -> 309
A13: Pearl Rotana Capital Centre | B13: =B12+1 -> 12 | C13: 6 | D13: 2024 | E13: ='June 2024'!C16 -> 7711 | F13: ='June 2024'!E16 -> 6445 | G13: ='June 2024'!G16 -> 113 | H13: ='June 2024'!K16 -> 90 | I13: ='June 2024'!N16 -> 18 | J13: ='June 2024'!P16 -> 19 | K13: ='June 2024'!X16 -> 9952.075 | L13: ='June 2024'!AC16 -> 12085 | M13: ='June 2024'!AP16 -> 9 | N13: ='June 2024'!AD16*315 -> 230.013 | O13: ='June 2024'!AE16 -> 285
A14: Pearl Rotana Capital Centre | B14: =B13+1 -> 13 | C14: 6 | D14: 2024 | E14: ='June 2024'!C17 -> 7709 | F14: ='June 2024'!E17 -> 6516 | G14: ='June 2024'!G17 -> 106 | H14: ='June 2024'!K17 -> 94 | I14: ='June 2024'!N17 -> 20 | J14: ='June 2024'!P17 -> 17 | K14: ='June 2024'!X17 -> 10236.42 | L14: ='June 2024'!AC17 -> 12210 | M14: ='June 2024'!AP17 -> 10 | N14: ='June 2024'!AD17*315 -> 226.989 | O14: ='June 2024'!AE17 -> 298
... A31: Pearl Rotana Capital Centre | B31: =B30+1 -> 30 | C31: 6 | D31: 2024 | E31: ='June 2024'!C34 -> 7479 | F31: ='June 2024'!E34 -> 6538 | G31: ='June 2024'!G34 -> 58 | H31: ='June 2024'!K34 -> 111 | I31: ='June 2024'!N34 -> 18 | J31: ='June 2024'!P34 -> 14 | K31: ='June 2024'!X34 -> 10805.11 | L31: ='June 2024'!AC34 -> 12604 | M31: ='June 2024'!AP34 -> 8 | N31: ='June 2024'!AD34*315 -> 293.013 | O31: ='June 2024'!AE34 -> 406

Sheet June 2024
A1: PEARL ROTANA CAPITAL CENTRE UTILITIES CONSUMPTION - JUNE 2024
A2: DATE | B2: Electricity | J2: Water | M2: SNG Gas | V2: District Cooling | AD2: Additional Info | AF2: Additional Meter
B3: MDB #2 | D3: MDB #3 | F3: MDB #1 Façade | H3: Total ELE Cons. KW | I3: Electricity AED | J3: Hotel Reading | K3: Water Cons. M3 | L3: Water AED | M3: Gas Meter #1 G Floor Kitchen | O3: Gas Meter #2 1st Floor Kitchen | Q3: Total Gas Cons. M3 | R3: PRS Meter Reading | S3: PRS Meter Cons. M3 | T3: Meter factor (1.05570) | U3: Gas AED | V3: Hotel BTU Meter Energy Reading | W3: District Cooling Cons. MWH | X3: District Cooling Cons. Ton Hour | Y3: District Cooling Cons. AED | Z3: District Cooling Fixed Charge | AA3: District Cooling Total AED | AB3: ETS Energy Meter Reading | AC3: ETS Cons. | AD3: Hotel Occupancy % | AE3: Adl. & Chl. | AF3: Electricity MDB-1 | AI3: Electricity MDB-E | AL3: Electricity-MCC Panel Chilled water Secondary Pumps | AO3: Water - Main kitchen | AR3: Water - Swimming Pool | AU3: Water - Bottling Plant
B4: Reading | C4: Cons. | D4: Reading | E4: Cons. | F4: Reading | G4: Cons. | M4: Reading | N4: Cons. | O4: Reading | P4: Cons. | AF4: Meter Reading | AG4: Cons. KWH | AH4: AED | AI4: Meter Reading | AJ4: Cons. KWH | AK4: AED | AL4: Meter Reading | AM4: Cons. KWH | AN4: AED | AO4: Meter Reading | AP4: Cons. M3 | AQ4: AED | AR4: Meter Reading | AS4: Cons. M3 | AT4: AED | AU4: Meter Reading | AV4: Cons. M3 | AW4: AED
A5: 45444 | B5: 19392411 | C5: 7990 | D5: 20258005 | E5: 6217 | F5: 459025 | G5: 115 | H5: =C5+E5+G5 -> 14322 | I5: =H5*0.2 -> 2864.4 | J5: 84133 | K5: 103 | L5: =K5*7.84 -> 807.52 | M5: 36475 | N5: 19 | O5: 21215 | P5: 14 | Q5: =N5+P5 -> 33 | R5: 53792 | S5: 34 | T5: =S5*1.0557 -> 35.8938 | U5: =IF(ISBLANK(M5),"0",T5*11.05+216.666) -> 613.29249 | V5: 68826 | W5: 35 | X5: =IF(ISBLANK(V5),"0 ",W5*284.345) -> 9952.075 | Y5: =X5*0.3442 -> 3425.5042 | Z5: =IF(ISBLANK(V5),"0",1570*1546.86/12/30*0.65) -> 4384.9184 | AA5: =Y5+Z5 -> 7810.4226 | AB5: 6647133 | AC5: 12601 | AD5: 0.6095 | AE5: 268 | AF5: 13613857 | AG5: 4704 | AH5: =AG5*0.2 -> 940.8 | AI5: 6311413 | AJ5: 2016 | AK5: =AJ5*0.2 -> 403.2 | AL5: 141168 | AM5: 397 | AN5: =AM5*0.2 -> 79.4 | AO5: 6655 | AP5: 12 | AQ5: =AP5*7.84 -> 94.08 | AR5: 2831 | AS5: 0 | AT5: =AS5*7.84 -> 0 | AU5: 158 | AV5: 0 | AW5: =AV5*7.84 -> 0
A6: 45445 | B6: 19400345 | C6: =IF(ISBLANK(B6),"0",B6-B5) -> 7934 | D6: 20264459 | E6: =IF(ISBLANK(D6),"0",D6-D5) -> 6454 | F6: 459136 | G6: =IF(ISBLANK(F6),"0",F6-F5) -> 111 | H6: =C6+E6+G6 -> 14499 | I6: =H6*0.2 -> 2899.8 | J6: 84218 | K6: =IF(ISBLANK(J6),"0",J6-J5) -> 85 | L6: =K6*7.84 -> 666.4 | M6: 36494 | N6: =IF(ISBLANK(M6),"0",M6-M5) -> 19 | O6: 21231 | P6: =IF(ISBLANK(O6),"0",O6-O5) -> 16 | Q6: =N6+P6 -> 35 | R6: 53827 | S6: =IF(ISBLANK(R6),"0",R6-R5) -> 35 | T6: =S6*1.0557 -> 36.9495 | U6: =IF(ISBLANK(M6),"0",T6*11.05+216.666) -> 624.95798 | V6: 68864 | W6: =IF(ISBLANK(V6)," ",V6-V5) -> 38 | X6: =IF(ISBLANK(V6),"0 ",W6*284.345) -> 10805.11 | Y6: =X6*0.3442 -> 3719.1189 | Z6: =IF(ISBLANK(V6),"0",1570*1546.86/12/30*0.65) -> 4384.9184 | AA6: =Y6+Z6 -> 8104.0373 | AB6: 6659679 | AC6: =IF(ISBLANK(AB6),"0 ",AB6-AB5) -> 12546 | AD6: 0.8286 | AE6: 319 | AF6: 13618659 | AG6: =IF(ISBLANK(AF6),"0",AF6-AF5) -> 4802 | AH6: =AG6*0.2 -> 960.4 | AI6: 6313424 | AJ6: =IF(ISBLANK(AI6),"0",AI6-AI5) -> 2011 | AK6: =AJ6*0.2 -> 402.2 | AL6: 141642 | AM6: =IF(ISBLANK(AL6),"0",AL6-AL5) -> 474 | AN6: =AM6*0.2 -> 94.8 | AO6: 6665 | AP6: =IF(ISBLANK(AO6),"0",AO6-AO5) -> 10 | AQ6: =AP6*7.84 -> 78.4 | AR6: 2832 | AS6: =IF(ISBLANK(AR6),"0",AR6-AR5) -> 1 | AT6: =AS6*7.84 -> 7.84 | AU6: 159 | AV6: =IF(ISBLANK(AU6),"0",AU6-AU5) -> 1 | AW6: =AV6*7.84 -> 7.84
A7: 45446 | B7: 19408360 | C7: =IF(ISBLANK(B7),"0",B7-B6) -> 8015 | D7: 20270933 | E7: =IF(ISBLANK(D7),"0",D7-D6) -> 6474 | F7: 459248 | G7: =IF(ISBLANK(F7),"0",F7-F6) -> 112 | H7: =C7+E7+G7 -> 14601 | I7: =H7*0.2 -> 2920.2 | J7: 84318 | K7: =IF(ISBLANK(J7),"0",J7-J6) -> 100 | L7: =K7*7.84 -> 784 | M7: 36512 | N7: =IF(ISBLANK(M7),"0",M7-M6) -> 18 | O7: 21249 | P7: =IF(ISBLANK(O7),"0",O7-O6) -> 18 | Q7: =N7+P7 -> 36 | R7: 53863 | S7: =IF(ISBLANK(R7),"0",R7-R6) -> 36 | T7: =S7*1.0557 -> 38.0052 | U7: =IF(ISBLANK(M7),"0",T7*11.05+216.666) -> 636.62346 | V7: 68901 | W7: =IF(ISBLANK(V7)," ",V7-V6) -> 37 | X7: =IF(ISBLANK(V7),"0 ",W7*284.345) -> 10520.765 | Y7: =X7*0.3442 -> 3621.2473 | Z7: =IF(ISBLANK(V7),"0",1570*1546.86/12/30*0.65) -> 4384.9184 | AA7: =Y7+Z7 -> 8006.1657 | AB7: 6672398 | AC7: =IF(ISBLANK(AB7),"0 ",AB7-AB6) -> 12719 | AD7: 0.9714 | AE7: 399 | AF7: 13624473 | AG7: =IF(ISBLANK(AF7),"0",AF7-AF6) -> 5814 | AH7: =AG7*0.2 -> 1162.8 | AI7: 6315626 | AJ7: =IF(ISBLANK(AI7),"0",AI7-AI6) -> 2202 | AK7: =AJ7*0.2 -> 440.4 | AL7: 142100 | AM7: =IF(ISBLANK(AL7),"0",AL7-AL6) -> 458 | AN7: =AM7*0.2 -> 91.6 | AO7: 6672 | AP7: =IF(ISBLANK(AO7),"0",AO7-AO6) -> 7 | AQ7: =AP7*7.84 -> 54.88 | AR7: 2833 | AS7: =IF(ISBLANK(AR7),"0",AR7-AR6) -> 1 | AT7: =AS7*7.84 -> 7.84 | AU7: 160 | AV7: =IF(ISBLANK(AU7),"0",AU7-AU6) -> 1 | AW7: =AV7*7.84 -> 7.84
A8: 45447 | B8: 19416359 | C8: =IF(ISBLANK(B8),"0",B8-B7) -> 7999 | D8: 20277415 | E8: =IF(ISBLANK(D8),"0",D8-D7) -> 6482 | F8: 459361 | G8: =IF(ISBLANK(F8),"0",F8-F7) -> 113 | H8: =C8+E8+G8 -> 14594 | I8: =H8*0.2 -> 2918.8 | J8: 84419 | K8: =IF(ISBLANK(J8),"0",J8-J7) -> 101 | L8: =K8*7.84 -> 791.84 | M8: 36531 | N8: =IF(ISBLANK(M8),"0",M8-M7) -> 19 | O8: 21267 | P8: =IF(ISBLANK(O8),"0",O8-O7) -> 18 | Q8: =N8+P8 -> 37 | R8: 53900 | S8: =IF(ISBLANK(R8),"0",R8-R7) -> 37 | T8: =S8*1.0557 -> 39.0609 | U8: =IF(ISBLANK(M8),"0",T8*11.05+216.666) -> 648.28895 | V8: 68939 | W8: =IF(ISBLANK(V8)," ",V8-V7) -> 38 | X8: =IF(ISBLANK(V8),"0 ",W8*284.345) -> 10805.11 | Y8: =X8*0.3442 -> 3719.1189 | Z8: =IF(ISBLANK(V8),"0",1570*1546.86/12/30*0.65) -> 4384.9184 | AA8: =Y8+Z8 -> 8104.0373 | AB8: 6685296 | AC8: =IF(ISBLANK(AB8),"0 ",AB8-AB7) -> 12898 | AD8: 0.9905 | AE8: 414 | AF8: 13630275 | AG8: =IF(ISBLANK(AF8),"0",AF8-AF7) -> 5802 | AH8: =AG8*0.2 -> 1160.4 | AI8: 6317805 | AJ8: =IF(ISBLANK(AI8),"0",AI8-AI7) -> 2179 | AK8: =AJ8*0.2 -> 435.8 | AL8: 142559 | AM8: =IF(ISBLANK(AL8),"0",AL8-AL7) -> 459 | AN8: =AM8*0.2 -> 91.8 | AO8: 6681 | AP8: =IF(ISBLANK(AO8),"0",AO8-AO7) -> 9 | AQ8: =AP8*7.84 -> 70.56 | AR8: 2834 | AS8: =IF(ISBLANK(AR8),"0",AR8-AR7) -> 1 | AT8: =AS8*7.84 -> 7.84 | AU8: 161 | AV8: =IF(ISBLANK(AU8),"0",AU8-AU7) -> 1 | AW8: =AV8*7.84 -> 7.84
A9: 45448 | B9: 19424498 | C9: =IF(ISBLANK(B9),"0",B9-B8) -> 8139 | D9: 20284017 | E9: =IF(ISBLANK(D9),"0",D9-D8) -> 6602 | F9: 459471 | G9: =IF(ISBLANK(F9),"0",F9-F8) -> 110 | H9: =C9+E9+G9 -> 14851 | I9: =H9*0.2 -> 2970.2 | J9: 84524 | K9: =IF(ISBLANK(J9),"0",J9-J8) -> 105 | L9: =K9*7.84 -> 823.2 | M9: 36550 | N9: =IF(ISBLANK(M9),"0",M9-M8) -> 19 | O9: 21288 | P9: =IF(ISBLANK(O9),"0",O9-O8) -> 21 | Q9: =N9+P9 -> 40 | R9: 53939 | S9: =IF(ISBLANK(R9),"0",R9-R8) -> 39 | T9: =S9*1.0557 -> 41.1723 | U9: =IF(ISBLANK(M9),"0",T9*11.05+216.666) -> 671.61991 | V9: 68975 | W9: =IF(ISBLANK(V9)," ",V9-V8) -> 36 | X9: =IF(ISBLANK(V9),"0 ",W9*284.345) -> 10236.42 | Y9: =X9*0.3442 -> 3523.3758 | Z9: =IF(ISBLANK(V9),"0",1570*1546.86/12/30*0.65) -> 4384.9184 | AA9: =Y9+Z9 -> 7908.2942 | AB9: 6697617 | AC9: =IF(ISBLANK(AB9),"0 ",AB9-AB8) -> 12321 | AD9: 0.8762 | AE9: 359 | AF9: 13636186 | AG9: =IF(ISBLANK(AF9),"0",AF9-AF8) -> 5911 | AH9: =AG9*0.2 -> 1182.2 | AI9: 6320021 | AJ9: =IF(ISBLANK(AI9),"0",AI9-AI8) -> 2216 | AK9: =AJ9*0.2 -> 443.2 | AL9: 142988 | AM9: =IF(ISBLANK(AL9),"0",AL9-AL8) -> 429 | AN9: =AM9*0.2 -> 85.8 | AO9: 6689 | AP9: =IF(ISBLANK(AO9),"0",AO9-AO8) -> 8 | AQ9: =AP9*7.84 -> 62.72 | AR9: 2835 | AS9: =IF(ISBLANK(AR9),"0",AR9-AR8) -> 1 | AT9: =AS9*7.84 -> 7.84 | AU9: 162 | AV9: =IF(ISBLANK(AU9),"0",AU9-AU8) -> 1 | AW9: =AV9*7.84 -> 7.84
A10: 45449 | B10: 19432202 | C10: =IF(ISBLANK(B10),"0",B10-B9) -> 7704 | D10: 20290546 | E10: =IF(ISBLANK(D10),"0",D10-D9) -> 6529 | F10: 459590 | G10: =IF(ISBLANK(F10),"0",F10-F9) -> 119 | H10: =C10+E10+G10 -> 14352 | I10: =H10*0.2 -> 2870.4 | J10: 84637 | K10: =IF(ISBLANK(J10),"0",J10-J9) -> 113 | L10: =K10*7.84 -> 885.92 | M10: 36570 | N10: =IF(ISBLANK(M10),"0",M10-M9) -> 20 | O10: 21308 | P10: =IF(ISBLANK(O10),"0",O10-O9) -> 20 | Q10: =N10+P10 -> 40 | R10: 53979 | S10: =IF(ISBLANK(R10),"0",R10-R9) -> 40 | T10: =S10*1.0557 -> 42.228 | U10: =IF(ISBLANK(M10),"0",T10*11.05+216.666) -> 683.2854 | V10: 69007 | W10: =IF(ISBLANK(V10)," ",V10-V9) -> 32 | X10: =IF(ISBLANK(V10),"0 ",W10*284.345) -> 9099.04 | Y10: =X10*0.3442 -> 3131.8896 | Z10: =IF(ISBLANK(V10),"0",1570*1546.86/12/30*0.65) -> 4384.9184 | AA10: =Y10+Z10 -> 7516.808 | AB10: 6708650 | AC10: =IF(ISBLANK(AB10),"0 ",AB10-AB9) -> 11033 | AD10: 0.9333 | AE10: 428 | AF10: 13641966 | AG10: =IF(ISBLANK(AF10),"0",AF10-AF9) -> 5780 | AH10: =AG10*0.2 -> 1156 | AI10: 6322223 | AJ10: =IF(ISBLANK(AI10),"0",AI10-AI9) -> 2202 | AK10: =AJ10*0.2 -> 440.4 | AL10: 143351 | AM10: =IF(ISBLANK(AL10),"0",AL10-AL9) -> 363 | AN10: =AM10*0.2 -> 72.6 | AO10: 6701 | AP10: =IF(ISBLANK(AO10),"0",AO10-AO9) -> 12 | AQ10: =AP10*7.84 -> 94.08 | AR10: 2835 | AS10: =IF(ISBLANK(AR10),"0",AR10-AR9) -> 0 | AT10: =AS10*7.84 -> 0 | AU10: 163 | AV10: =IF(ISBLANK(AU10),"0",AU10-AU9) -> 1 | AW10: =AV10*7.84 -> 7.84
A11: 45450 | B11: 19439768 | C11: =IF(ISBLANK(B11),"0",B11-B10) -> 7566 | D11: 20296935 | E11: =IF(ISBLANK(D11),"0",D11-D10) -> 6389 | F11: 459704 | G11: =IF(ISBLANK(F11),"0",F11-F10) -> 114 | H11: =C11+E11+G11 -> 14069 | I11: =H11*0.2 -> 2813.8 | J11: 84739 | K11: =IF(ISBLANK(J11),"0",J11-J10) -> 102 | L11: =K11*7.84 -> 799.68 | M11: 36590 | N11: =IF(ISBLANK(M11),"0",M11-M10) -> 20 | O11: 21328 | P11: =IF(ISBLANK(O11),"0",O11-O10) -> 20 | Q11: =N11+P11 -> 40 | R11: 54019 | S11: =IF(ISBLANK(R11),"0",R11-R10) -> 40 | T11: =S11*1.0557 -> 42.228 | U11: =IF(ISBLANK(M11),"0",T11*11.05+216.666) -> 683.2854 | V11: 69042 | W11: =IF(ISBLANK(V11)," ",V11-V10) -> 35 | X11: =IF(ISBLANK(V11),"0 ",W11*284.345) -> 9952.075 | Y11: =X11*0.3442 -> 3425.5042 | Z11: =IF(ISBLANK(V11),"0",1570*1546.86/12/30*0.65) -> 4384.9184 | AA11: =Y11+Z11 -> 7810.4226 | AB11: 6720398 | AC11: =IF(ISBLANK(AB11),"0 ",AB11-AB10) -> 11748 | AD11: 0.8952 | AE11: 424 | AF11: 13647581 | AG11: =IF(ISBLANK(AF11),"0",AF11-AF10) -> 5615 | AH11: =AG11*0.2 -> 1123 | AI11: 6324383 | AJ11: =IF(ISBLANK(AI11),"0",AI11-AI10) -> 2160 | AK11: =AJ11*0.2 -> 432 | AL11: 143767 | AM11: =IF(ISBLANK(AL11),"0",AL11-AL10) -> 416 | AN11: =AM11*0.2 -> 83.2 | AO11: 6710 | AP11: =IF(ISBLANK(AO11),"0",AO11-AO10) -> 9 | AQ11: =AP11*7.84 -> 70.56 | AR11: 2837 | AS11: =IF(ISBLANK(AR11),"0",AR11-AR10) -> 2 | AT11: =AS11*7.84 -> 15.68 | AU11: 163 | AV11: =IF(ISBLANK(AU11),"0",AU11-AU10) -> 0 | AW11: =AV11*7.84 -> 0
A12: 45451 | B12: 19447196 | C12: =IF(ISBLANK(B12),"0",B12-B11) -> 7428 | D12: 20303207 | E12: =IF(ISBLANK(D12),"0",D12-D11) -> 6272 | F12: 459814 | G12: =IF(ISBLANK(F12),"0",F12-F11) -> 110 | H12: =C12+E12+G12 -> 13810 | I12: =H12*0.2 -> 2762 | J12: 84835 | K12: =IF(ISBLANK(J12),"0",J12-J11) -> 96 | L12: =K12*7.84 -> 752.64 | M12: 36608 | N12: =IF(ISBLANK(M12),"0",M12-M11) -> 18 | O12: 21346 | P12: =IF(ISBLANK(O12),"0",O12-O11) -> 18 | Q12: =N12+P12 -> 36 | R12: 54055 | S12: =IF(ISBLANK(R12),"0",R12-R11) -> 36 | T12: =S12*1.0557 -> 38.0052 | U12: =IF(ISBLANK(M12),"0",T12*11.05+216.666) -> 636.62346 | V12: 69075 | W12: =IF(ISBLANK(V12)," ",V12-V11) -> 33 | X12: =IF(ISBLANK(V12),"0 ",W12*284.345) -> 9383.385 | Y12: =X12*0.3442 -> 3229.7611 | Z12: =IF(ISBLANK(V12),"0",1570*1546.86/12/30*0.65) -> 4384.9184 | AA12: =Y12+Z12 -> 7614.6795 | AB12: 6731512 | AC12: =IF(ISBLANK(AB12),"0 ",AB12-AB11) -> 11114 | AD12: 0.927 | AE12: 446 | AF12: 13652195 | AG12: =IF(ISBLANK(AF12),"0",AF12-AF11) -> 4614 | AH12: =AG12*0.2 -> 922.8 | AI12: 6326384 | AJ12: =IF(ISBLANK(AI12),"0",AI12-AI11) -> 2001 | AK12: =AJ12*0.2 -> 400.2 | AL12: 144156 | AM12: =IF(ISBLANK(AL12),"0",AL12-AL11) -> 389 | AN12: =AM12*0.2 -> 77.8 | AO12: 6722 | AP12: =IF(ISBLANK(AO12),"0",AO12-AO11) -> 12 | AQ12: =AP12*7.84 -> 94.08 | AR12: 2837 | AS12: =IF(ISBLANK(AR12),"0",AR12-AR11) -> 0 | AT12: =AS12*7.84 -> 0 | AU12: 164 | AV12: =IF(ISBLANK(AU12),"0",AU12-AU11) -> 1 | AW12: =AV12*7.84 -> 7.84
A13: 45452 | B13: 19454794 | C13: =IF(ISBLANK(B13),"0",B13-B12) -> 7598 | D13: 20309636 | E13: =IF(ISBLANK(D13),"0",D13-D12) -> 6429 | F13: 459927 | G13: =IF(ISBLANK(F13),"0",F13-F12) -> 113 | H13: =C13+E13+G13 -> 14140 | I13: =H13*0.2 -> 2828 | J13: 84945 | K13: =IF(ISBLANK(J13),"0",J13-J12) -> 110 | L13: =K13*7.84 -> 862.4 | M13: 36626 | N13: =IF(ISBLANK(M13),"0",M13-M12) -> 18 | O13: 21365 | P13: =IF(ISBLANK(O13),"0",O13-O12) -> 19 | Q13: =N13+P13 -> 37 | R13: 54092 | S13: =IF(ISBLANK(R13),"0",R13-R12) -> 37 | T13: =S13*1.0557 -> 39.0609 | U13: =IF(ISBLANK(M13),"0",T13*11.05+216.666) -> 648.28895 | V13: 69112 | W13: =IF(ISBLANK(V13)," ",V13-V12) -> 37 | X13: =IF(ISBLANK(V13),"0 ",W13*284.345) -> 10520.765 | Y13: =X13*0.3442 -> 3621.2473 | Z13: =IF(ISBLANK(V13),"0",1570*1546.86/12/30*0.65) -> 4384.9184 | AA13: =Y13+Z13 -> 8006.1657 | AB13: 6743920 | AC13: =IF(ISBLANK(AB13),"0 ",AB13-AB12) -> 12408 | AD13: 0.8698 | AE13: 367 | AF13: 13656906 | AG13: =IF(ISBLANK(AF13),"0",AF13-AF12) -> 4711 | AH13: =AG13*0.2 -> 942.2 | AI13: 6328447 | AJ13: =IF(ISBLANK(AI13),"0",AI13-AI12) -> 2063 | AK13: =AJ13*0.2 -> 412.6 | AL13: 144616 | AM13: =IF(ISBLANK(AL13),"0",AL13-AL12) -> 460 | AN13: =AM13*0.2 -> 92 | AO13: 6732 | AP13: =IF(ISBLANK(AO13),"0",AO13-AO12) -> 10 | AQ13: =AP13*7.84 -> 78.4 | AR13: 2838 | AS13: =IF(ISBLANK(AR13),"0",AR13-AR12) -> 1 | AT13: =AS13*7.84 -> 7.84 | AU13: 165 | AV13: =IF(ISBLANK(AU13),"0",AU13-AU12) -> 1 | AW13: =AV13*7.84 -> 7.84
A14: 45453 | B14: 19462513 | C14: =IF(ISBLANK(B14),"0",B14-B13) -> 7719 | D14: 20316013 | E14: =IF(ISBLANK(D14),"0",D14-D13) -> 6377 | F14: 460040 | G14: =IF(ISBLANK(F14),"0",F14-F13) -> 113 | H14: =C14+E14+G14 -> 14209 | I14: =H14*0.2 -> 2841.8 | J14: 85043 | K14: =IF(ISBLANK(J14),"0",J14-J13) -> 98 | L14: =K14*7.84 -> 768.32 | M14: 36645 | N14: =IF(ISBLANK(M14),"0",M14-M13) -> 19 | O14: 21384 | P14: =IF(ISBLANK(O14),"0",O14-O13) -> 19 | Q14: =N14+P14 -> 38 | R14: 54130 | S14: =IF(ISBLANK(R14),"0",R14-R13) -> 38 | T14: =S14*1.0557 -> 40.1166 | U14: =IF(ISBLANK(M14),"0",T14*11.05+216.666) -> 659.95443 | V14: 69150 | W14: =IF(ISBLANK(V14)," ",V14-V13) -> 38 | X14: =IF(ISBLANK(V14),"0 ",W14*284.345) -> 10805.11 | Y14: =X14*0.3442 -> 3719.1189 | Z14: =IF(ISBLANK(V14),"0",1570*1546.86/12/30*0.65) -> 4384.9184 | AA14: =Y14+Z14 -> 8104.0373 | AB14: 6756697 | AC14: =IF(ISBLANK(AB14),"0 ",AB14-AB13) -> 12777 | AD14: 0.8508 | AE14: 328 | AF14: 13662630 | AG14: =IF(ISBLANK(AF14),"0",AF14-AF13) -> 5724 | AH14: =AG14*0.2 -> 1144.8 | AI14: 6330622 | AJ14: =IF(ISBLANK(AI14),"0",AI14-AI13) -> 2175 | AK14: =AJ14*0.2 -> 435 | AL14: 145085 | AM14: =IF(ISBLANK(AL14),"0",AL14-AL13) -> 469 | AN14: =AM14*0.2 -> 93.8 | AO14: 6741 | AP14: =IF(ISBLANK(AO14),"0",AO14-AO13) -> 9 | AQ14: =AP14*7.84 -> 70.56 | AR14: 2839 | AS14: =IF(ISBLANK(AR14),"0",AR14-AR13) -> 1 | AT14: =AS14*7.84 -> 7.84 | AU14: 166 | AV14: =IF(ISBLANK(AU14),"0",AU14-AU13) -> 1 | AW14: =AV14*7.84 -> 7.84
A15: 45454 | B15: 19470241 | C15: =IF(ISBLANK(B15),"0",B15-B14) -> 7728 | D15: 20322571 | E15: =IF(ISBLANK(D15),"0",D15-D14) -> 6558 | F15: 460153 | G15: =IF(ISBLANK(F15),"0",F15-F14) -> 113 | H15: =C15+E15+G15 -> 14399 | I15: =H15*0.2 -> 2879.8 | J15: 85142 | K15: =IF(ISBLANK(J15),"0",J15-J14) -> 99 | L15: =K15*7.84 -> 776.16 | M15: 36663 | N15: =IF(ISBLANK(M15),"0",M15-M14) -> 18 | O15: 21403 | P15: =IF(ISBLANK(O15),"0",O15-O14) -> 19 | Q15: =N15+P15 -> 37 | R15: 54168 | S15: =IF(ISBLANK(R15),"0",R15-R14) -> 38 | T15: =S15*1.0557 -> 40.1166 | U15: =IF(ISBLANK(M15),"0",T15*11.05+216.666) -> 659.95443 | V15: 69187 | W15: =IF(ISBLANK(V15)," ",V15-V14) -> 37 | X15: =IF(ISBLANK(V15),"0 ",W15*284.345) -> 10520.765 | Y15: =X15*0.3442 -> 3621.2473 | Z15: =IF(ISBLANK(V15),"0",1570*1546.86/12/30*0.65) -> 4384.9184 | AA15: =Y15+Z15 -> 8006.1657 | AB15: 6769346 | AC15: =IF(ISBLANK(AB15),"0 ",AB15-AB14) -> 12649 | AD15: 0.8 | AE15: 309 | AF15: 13668389 | AG15: =IF(ISBLANK(AF15),"0",AF15-AF14) -> 5759 | AH15: =AG15*0.2 -> 1151.8 | AI15: 6332805 | AJ15: =IF(ISBLANK(AI15),"0",AI15-AI14) -> 2183 | AK15: =AJ15*0.2 -> 436.6 | AL15: 145532 | AM15: =IF(ISBLANK(AL15),"0",AL15-AL14) -> 447 | AN15: =AM15*0.2 -> 89.4 | AO15: 6750 | AP15: =IF(ISBLANK(AO15),"0",AO15-AO14) -> 9 | AQ15: =AP15*7.84 -> 70.56 | AR15: 2840 | AS15: =IF(ISBLANK(AR15),"0",AR15-AR14) -> 1 | AT15: =AS15*7.84 -> 7.84 | AU15: 166 | AV15: =IF(ISBLANK(AU15),"0",AU15-AU14) -> 0 | AW15: =AV15*7.84 -> 0
A16: 45455 | B16: 19477952 | C16: =IF(ISBLANK(B16),"0",B16-B15) -> 7711 | D16: 20329016 | E16: =IF(ISBLANK(D16),"0",D16-D15) -> 6445 | F16: 460266 | G16: =IF(ISBLANK(F16),"0",F16-F15) -> 113 | H16: =C16+E16+G16 -> 14269 | I16: =H16*0.2 -> 2853.8 | J16: 85232 | K16: =IF(ISBLANK(J16),"0",J16-J15) -> 90 | L16: =K16*7.84 -> 705.6 | M16: 36681 | N16: =IF(ISBLANK(M16),"0",M16-M15) -> 18 | O16: 21422 | P16: =IF(ISBLANK(O16),"0",O16-O15) -> 19 | Q16: =N16+P16 -> 37 | R16: 54205 | S16: =IF(ISBLANK(R16),"0",R16-R15) -> 37 | T16: =S16*1.0557 -> 39.0609 | U16: =IF(ISBLANK(M16),"0",T16*11.05+216.666) -> 648.28895 | V16: 69222 | W16: =IF(ISBLANK(V16)," ",V16-V15) -> 35 | X16: =IF(ISBLANK(V16),"0 ",W16*284.345) -> 9952.075 | Y16: =X16*0.3442 -> 3425.5042 | Z16: =IF(ISBLANK(V16),"0",1570*1546.86/12/30*0.65) -> 4384.9184 | AA16: =Y16+Z16 -> 7810.4226 | AB16: 6781431 | AC16: =IF(ISBLANK(AB16),"0 ",AB16-AB15) -> 12085 | AD16: 0.7302 | AE16: 285 | AF16: 13674054 | AG16: =IF(ISBLANK(AF16),"0",AF16-AF15) -> 5665 | AH16: =AG16*0.2 -> 1133 | AI16: 6334968 | AJ16: =IF(ISBLANK(AI16),"0",AI16-AI15) -> 2163 | AK16: =AJ16*0.2 -> 432.6 | AL16: 145950 | AM16: =IF(ISBLANK(AL16),"0",AL16-AL15) -> 418 | AN16: =AM16*0.2 -> 83.6 | AO16: 6759 | AP16: =IF(ISBLANK(AO16),"0",AO16-AO15) -> 9 | AQ16: =AP16*7.84 -> 70.56 | AR16: 2841 | AS16: =IF(ISBLANK(AR16),"0",AR16-AR15) -> 1 | AT16: =AS16*7.84 -> 7.84 | AU16: 167 | AV16: =IF(ISBLANK(AU16),"0",AU16-AU15) -> 1 | AW16: =AV16*7.84 -> 7.84
A17: 45456 | B17: 19485661 | C17: =IF(ISBLANK(B17),"0",B17-B16) -> 7709 | D17: 20335532 | E17: =IF(ISBLANK(D17),"0",D17-D16) -> 6516 | F17: 460372 | G17: =IF(ISBLANK(F17),"0",F17-F16) -> 106 | H17: =C17+E17+G17 -> 14331 | I17: =H17*0.2 -> 2866.2 | J17: 85326 | K17: =IF(ISBLANK(J17),"0",J17-J16) -> 94 | L17: =K17*7.84 -> 736.96 | M17: 36701 | N17: =IF(ISBLANK(M17),"0",M17-M16) -> 20 | O17: 21439 | P17: =IF(ISBLANK(O17),"0",O17-O16) -> 17 | Q17: =N17+P17 -> 37 | R17: 54242 | S17: =IF(ISBLANK(R17),"0",R17-R16) -> 37 | T17: =S17*1.0557 -> 39.0609 | U17: =IF(ISBLANK(M17),"0",T17*11.05+216.666) -> 648.28895 | V17: 69258 | W17: =IF(ISBLANK(V17)," ",V17-V16) -> 36 | X17: =IF(ISBLANK(V17),"0 ",W17*284.345) -> 10236.42 | Y17: =X17*0.3442 -> 3523.3758 | Z17: =IF(ISBLANK(V17),"0",1570*1546.86/12/30*0.65) -> 4384.9184 | AA17: =Y17+Z17 -> 7908.2942 | AB17: 6793641 | AC17: =IF(ISBLANK(AB17),"0 ",AB17-AB16) -> 12210 | AD17: 0.7206 | AE17: 298 | AF17: 13679694 | AG17: =IF(ISBLANK(AF17),"0",AF17-AF16) -> 5640 | AH17: =AG17*0.2 -> 1128 | AI17: 6337109 | AJ17: =IF(ISBLANK(AI17),"0",AI17-AI16) -> 2141 | AK17: =AJ17*0.2 -> 428.2 | AL17: 146387 | AM17: =IF(ISBLANK(AL17),"0",AL17-AL16) -> 437 | AN17: =AM17*0.2 -> 87.4 | AO17: 6769 | AP17: =IF(ISBLANK(AO17),"0",AO17-AO16) -> 10 | AQ17: =AP17*7.84 -> 78.4 | AR17: 2841 | AS17: =IF(ISBLANK(AR17),"0",AR17-AR16) -> 0 | AT17: =AS17*7.84 -> 0 | AU17: 168 | AV17: =IF(ISBLANK(AU17),"0",AU17-AU16) -> 1 | AW17: =AV17*7.84 -> 7.84
... A34: 45473 | B34: 19614413 | C34: =IF(ISBLANK(B34),"0",B34-B33) -> 7479 | D34: 20446356 | E34: =IF(ISBLANK(D34),"0",D34-D33) -> 6538 | F34: 461929 | G34: =IF(ISBLANK(F34),"0",F34-F33) -> 58 | H34: =C34+E34+G34 -> 14075 | I34: =H34*0.2 -> 2815 | J34: 87084 | K34: =IF(ISBLANK(J34),"0",J34-J33) -> 111 | L34: =K34*7.84 -> 870.24 | M34: 37016 | N34: =IF(ISBLANK(M34),"0",M34-M33) -> 18 | O34: 21747 | P34: =IF(ISBLANK(O34),"0",O34-O33) -> 14 | Q34: =N34+P34 -> 32 | R34: 54869 | S34: =IF(ISBLANK(R34),"0",R34-R33) -> 32 | T34: =S34*1.0557 -> 33.7824 | U34: =IF(ISBLANK(M34),"0",T34*11.05+216.666) -> 589.96152 | V34: 69914 | W34: =IF(ISBLANK(V34)," ",V34-V33) -> 38 | X34: =IF(ISBLANK(V34),"0 ",W34*284.345) -> 10805.11 | Y34: =X34*0.3442 -> 3719.1189 | Z34: =IF(ISBLANK(V34),"0",1570*1546.86/12/30*0.65) -> 4384.9184 | AA34: =Y34+Z34 -> 8104.0373 | AB34: 7014741 | AC34: =IF(ISBLANK(AB34),"0 ",AB34-AB33) -> 12604 | AD34: 0.9302 | AE34: 406 | AF34: 13767266 | AG34: =IF(ISBLANK(AF34),"0",AF34-AF33) -> 4950 | AH34: =AG34*0.2 -> 990 | AI34: 6373039 | AJ34: =IF(ISBLANK(AI34),"0",AI34-AI33) -> 2111 | AK34: =AJ34*0.2 -> 422.2 | AL34: 155619 | AM34: =IF(ISBLANK(AL34),"0",AL34-AL33) -> 484 | AN34: =AM34*0.2 -> 96.8 | AO34: 6926 | AP34: =IF(ISBLANK(AO34),"0",AO34-AO33) -> 8 | AQ34: =AP34*7.84 -> 62.72 | AR34: 2868 | AS34: =IF(ISBLANK(AR34),"0",AR34-AR33) -> 2 | AT34: =AS34*7.84 -> 15.68 | AU34: 183 | AV34: =IF(ISBLANK(AU34),"0",AU34-AU33) -> 1 | AW34: =AV34*7.84 -> 7.84
C35: =SUM(C5:C34) -> 229992 | E35: =SUM(E5:E34) -> 194568 | G35: =SUM(G5:G34) -> 3019 | H35: =SUM(H5:H34) -> 427579 | I35: =H35*0.2 -> 85515.8 | K35: =SUM(K5:K34) -> 3054 | L35: =K35*7.84 -> 23943.36 | N35: =SUM(N5:N34) -> 560 | P35: =SUM(P5:P34) -> 546 | Q35: =SUM(Q5:Q34) -> 1106 | S35: =SUM(S5:S34) -> 1111 | T35: =SUM(T5:T34) -> 1172.8827 | U35: =SUM(U5:U34) -> 19460.334 | W35: =SUM(W5:W34) -> 1123 | X35: =SUM(X5:X34) -> 319319.44 | Y35: =SUM(Y5:Y34) -> 109909.75 | Z35: =SUM(Z5:Z34) -> 131547.55 | AA35: =SUM(AA5:AA34) -> 241457.3 | AC35: =SUM(AC5:AC34) -> 380209 | AD35: =AVERAGE(AD5:AD34) -> 0.83036667 | AE35: =SUM(AE5:AE34) -> 10905 | AG35: =SUM(AG5:AG34) -> 158113 | AH35: =SUM(AH5:AH34) -> 31622.6 | AJ35: =SUM(AJ5:AJ34) -> 63642 | AK35: =SUM(AK5:AK34) -> 12728.4 | AM35: =SUM(AM5:AM34) -> 14848 | AN35: =SUM(AN5:AN34) -> 2969.6 | AP35: =SUM(AP5:AP34) -> 283 | AQ35: =SUM(AQ5:AQ34) -> 2218.72 | AS35: =SUM(AS5:AS34) -> 37 | AT35: =SUM(AT5:AT34) -> 290.08 | AV35: =SUM(AV5:AV34) -> 25 | AW35: =SUM(AW5:AW34) -> 196
V36: AVT Charges should be Zero in the DC invoice - Please notify if not
B37: Electricity | D37: AED | G37: KW | J37: Water | L37: AED | M37: M3 | O37: Gas | R37: AED | T37: M3 | V37: Chilled Water | X37: AED | Z37: Ton Hour | AG37: =131547.55*6 -> 789285.3 | AH37: CHW Fixed Charges YTD 2024
B38: Actual June 2024 | D38: =I35 -> 85515.8 | G38: =D38/0.2 -> 427579 | J38: =B38 -> Actual June 2024 | L38: =L35 -> 23943.36 | M38: =K35 -> 3054 | O38: =B38 -> Actual June 2024 | R38: =U35 -> 19460.334 | T38: =T35 -> 1172.8827 | V38: =B38 -> Actual June 2024 | X38: =AA35 -> 241457.3 | Z38: =X35 -> 319319.44 | AC38: =(R38-5500)/T38 -> 11.902583 | AD38: =AC35 -> 380209 | AE38: =AD38-X35 -> 60889.565 | AG38: =126488.42*6 -> 758930.52 | AH38: CHW Fixed Charges YTD 2023
B39: Budget June 2024 | D39: 94027.5 | G39: =D39/0.2 -> 470137.5 | J39: =B39 -> Budget June 2024 | L39: 20143.671 | M39: =L39/7.84 -> 2569.3458 | O39: =B39 -> Budget June 2024 | R39: 18008.244 | T39: =(R39-6500)/11.05 -> 1041.47 | V39: =B39 -> Budget June 2024 | X39: 232006.63 | Z39: =AG39/0.3442 -> 291862.53 | AG39: =X39-131547.55 -> 100459.08 | AH39: CHW Consumption Charges (Budgeted 2024 MTD)
B40: Actual June 2023 | D40: 93055 | G40: =D40/0.2 -> 465275 | J40: =B40 -> Actual June 2023 | L40: 20219.36 | M40: =L40/7.84 -> 2579 | O40: =B40 -> Actual June 2023 | R40: 17896.94 | T40: =(R40-6500)/11.05 -> 1031.3973 | V40: =B40 -> Actual June 2023 | X40: 223083.3 | Z40: =AG40/0.3435 -> 281207.8 | AG40: =X40-126488.42 -> 96594.88 | AH40: CHW Consumption Charges (Actual 2023 MTD)
B41: Actual YTD 2024 | D41: =D38+441064.2 -> 526580 | G41: =D41/0.2 -> 2632900 | J41: =B41 -> Actual YTD 2024 | L41: =L38+119066.08 -> 143009.44 | M41: =L41/7.84 -> 18241 | O41: =B41 -> Actual YTD 2024 | R41: =R38+90695.64 -> 110155.97 | T41: =(R41-6500*6)/11.05 -> 6439.4546 | V41: =B41 -> Actual YTD 2024 | X41: =X38+979026.7 -> 1220484 | Z41: =AG41/0.3442 -> 1252756.3 | AG41: =X41-AG37 -> 431198.7 | AH41: CHW Consumption Charges (Actual 2024 YTD)
B42: Budget YTD 2024 | D42: =D39+480463.2 -> 574490.7 | G42: =D42/0.2 -> 2872453.5 | J42: =B42 -> Budget YTD 2024 | L42: =L39+123958.23 -> 144101.9 | M42: =L42/7.84 -> 18380.344 | O42: =B42 -> Budget YTD 2024 | R42: =R39+91106.69 -> 109114.93 | T42: =(R42-6500*6)/11.05 -> 6345.2429 | V42: =B42 -> Budget YTD 2024 | X42: =X39+965317.77 -> 1197324.4 | Z42: =AG42/0.3442 -> 1185471 | AG42: =X42-AG37 -> 408039.1 | AH42: CHW Consumption Charges (Budgeted 2024 YTD)
B43: Actual YTD 2023 | D43: 559575.2 | G43: =D43/0.2 -> 2797876 | J43: =B43 -> Actual YTD 2023 | L43: 127721.44 | M43: =L43/7.84 -> 16291 | O43: =B43 -> Actual YTD 2023 | R43: 99596.79 | T43: =(R43-6500*6)/11.05 -> 5483.8724 | V43: =B43 -> Actual YTD 2023 | X43: 1142895.3 | Z43: =AG43/0.3435 -> 1117801.3 | AG43: =X43-AG38 -> 383964.76 | AH43: CHW Consumption Charges (Actual 2023 YTD)
H44: 45444 | I44: =TODAY() -> 45509 | J44: 30
A45: Monthly Budget | D45: Daily Budget | I45: MTD Average | N45: MTD Budget | U45: MTD Actual | Z45: YTD Budget | AD45: YTD Actual | AG45: Savings | AH45: Exceeds
A46: Electricity | B46: =D39 -> 94027.5 | D46: Electricity | G46: =B46/30 -> 3134.25 | I46: Electricity | L46: =I35/J44 -> 2850.5267 | N46: Electricity | R46: =G46*J44 -> 94027.5 | U46: Electricity | W46: =I35 -> 85515.8 | Y46: =R46-W46 -> 8511.7 | Z46: Electricity | AB46: =R46+480463.2 -> 574490.7 | AD46: Electricity | AF46: =W46+441064.2 -> 526580 | AG46: =AB46-AF46 -> 47910.7 | AH46: =AF46-AB46 -> -47910.7
A47: Water | B47: =L39 -> 20143.671 | D47: Water | G47: =B47/30 -> 671.45569 | I47: Water | L47: =L35/J44 -> 798.112 | N47: Water | R47: =G47*J44 -> 20143.671 | U47: Water | W47: =L35 -> 23943.36 | Y47: =R47-W47 -> -3799.6893 | Z47: Water | AB47: =R47+119066.08 -> 139209.75 | AD47: Water | AF47: =W47+119066.08 -> 143009.44 | AG47: =AB47-AF47 -> -3799.6893 | AH47: =AF47-AB47 -> 3799.6893
A48: Gas | B48: =R39 -> 18008.244 | D48: Gas | G48: =B48/30 -> 600.2748 | I48: Gas | L48: =U35/J44 -> 648.67779 | N48: Gas | R48: =G48*J44 -> 18008.244 | U48: Gas | W48: =U35 -> 19460.334 | Y48: =R48-W48 -> -1452.0899 | Z48: Gas | AB48: =R48+91106.7 -> 109114.94 | AD48: Gas | AF48: =W48+90695.64 -> 110155.97 | AG48: =AB48-AF48 -> -1041.0299 | AH48: =AF48-AB48 -> 1041.0299
A49: Chilled Water | B49: =X39 -> 232006.63 | D49: Chilled Water | G49: =B49/30 -> 7733.5544 | I49: Chilled Water | L49: =AA35/J44 -> 8048.5767 | N49: Chilled Water | R49: =G49*J44 -> 232006.63 | U49: Chilled Water | W49: =AA35 -> 241457.3 | Y49: =R49-W49 -> -9450.67 | Z49: Chilled Water | AB49: =R49+965317.77 -> 1197324.4 | AD49: Chilled Water | AF49: =W49+979026.7 -> 1220484 | AG49: =AB49-AF49 -> -23159.6 | AH49: =AF49-AB49 -> 23159.6
B50: =SUM(B46:B49) -> 364186.05 | R50: =SUM(R46:S49) -> 364186.05 | W50: =SUM(W46:X49) -> 370376.8 | Y50: =R50-W50 -> -6190.7492 | AA50: Total Energy cost | AB50: =SUM(AB46:AB49) -> 2020139.8 | AF50: =SUM(AF46:AF49) -> 2000229.4 | AG50: =AB50-AF50 -> 19910.381
B51: =B50*X51 -> -6190.7492 | X51: =1-(W50/R50) -> -0.016998864 | AF51: =1-(AF50/AB50) -> 0.0098559421
A53: Actual Last Year | D53: Average Daily Consumption Last Year | I53: MTD Average Last Year | N53: MTD Actual | U53: MTD Actual Vs Last Year | Z53: MTD Fcst | AA53: YTD Fcst | AD53: MTD Saving Fcst Vs LY | AE53: YTD Saving Fcst Vs LY
A54: Electricity | B54: =D40 -> 93055 | D54: Electricity | G54: =B54/30 -> 3101.8333 | I54: Electricity | L54: =G54*J44 -> 93055 | N54: Electricity | R54: =W46 -> 85515.8 | U54: Electricity | W54: =L54-R54 -> 7539.2 | Z54: =L46*30 -> 85515.8 | AA54: =Z54+441064.2 -> 526580 | AD54: =D40-Z54 -> 7539.2 | AE54: =D43-AA54 -> 32995.2
A55: Water | B55: =L40 -> 20219.36 | D55: Water | G55: =B55/30 -> 673.97867 | I55: Water | L55: =G55*J44 -> 20219.36 | N55: Water | R55: =W47 -> 23943.36 | U55: Water | W55: =L55-R55 -> -3724 | Z55: =L47*30 -> 23943.36 | AA55: =Z55+119066.08 -> 143009.44 | AD55: =L40-Z55 -> -3724 | AE55: =L43-AA55 -> -15288
A56: Gas | B56: =R40 -> 17896.94 | D56: Gas | G56: =B56/30 -> 596.56467 | I56: Gas | L56: =G56*J44 -> 17896.94 | N56: Gas | R56: =W48 -> 19460.334 | U56: Gas | W56: =L56-R56 -> -1563.3938 | Z56: =L48*30 -> 19460.334 | AA56: =Z56+90695.64 -> 110155.97 | AD56: =R40-Z56 -> -1563.3938 | AE56: =R43-AA56 -> -10559.184
A57: Chilled Water | B57: =X40 -> 223083.3 | D57: Chilled Water | G57: =B57/30 -> 7436.11 | I57: Chilled Water | L57: =G57*J44 -> 223083.3 | N57: Chilled Water | R57: =W49 -> 241457.3 | U57: Chilled Water | W57: =L57-R57 -> -18374.002 | Z57: =L49*30 -> 241457.3 | AA57: =Z57+979026.7 -> 1220484 | AD57: =X40-Z57 -> -18374.002 | AE57: =Z43-AA57 -> -102682.66
...
