Workbook

Sheet Total
A1: Site Name | B1: Day | C1: Month | D1: Year | E1: Total Electricity Kwh | F1: Electricity Tariff ($/Kwh) | G1: Natural Gas (m3) | H1: Natural Gas $/m3 | I1: Water Utility Supply (m3) m3 | J1: Water Utility Supply (m3) $/m3 | K1: District Energy Cooling RTH | L1: District Energy Cooling $/RTH | M1: Room Nights | N1: Total Guests
A2: Pearl Rotana Capital Centre | B2: 1 | C2: 10 | D2: 2024 | E2: =Submetering!E2+Submetering!F2+Submetering!G2 -> 14562 | F2: 0.2 | G2: ='OCT 2024'!T5 -> 31.671 | H2: 16.76 | I2: =Submetering!H2 -> 87 | J2: 7.84 | K2: ='OCT 2024'!X5 -> 10236.42 | L2: 0.3449 | M2: =Submetering!N2 -> 250.0155 | N2: =Submetering!O2 -> 306
A3: Pearl Rotana Capital Centre | B3: =B2+1 -> 2 | C3: 10 | D3: 2024 | E3: =Submetering!E3+Submetering!F3+Submetering!G3 -> 14673 | F3: 0.2 | G3: ='OCT 2024'!T6 -> 42.228 | H3: 16.76 | I3: =Submetering!H3 -> 94 | J3: 7.84 | K3: ='OCT 2024'!X6 -> 11089.455 | L3: 0.3449 | M3: =Submetering!N3 -> 265.0095 | N3: =Submetering!O3 -> 339
A4: Pearl Rotana Capital Centre | B4: =B3+1 -> 3 | C4: 10 | D4: 2024 | E4: =Submetering!E4+Submetering!F4+Submetering!G4 -> 14732 | F4: 0.2 | G4: ='OCT 2024'!T7 -> 31.671 | H4: 16.76 | I4: =Submetering!H4 -> 92 | J4: 7.84 | K4: ='OCT 2024'!X7 -> 11373.8 | L4: 0.3449 | M4: =Submetering!N4 -> 198.9855 | N4: =Submetering!O4 -> 245
A5: Pearl Rotana Capital Centre | B5: =B4+1 -> 4 | C5: 10 | D5: 2024 | E5: =Submetering!E5+Submetering!F5+Submetering!G5 -> 14752 | F5: 0.2 | G5: ='OCT 2024'!T8 -> 40.1166 | H5: 16.76 | I5: =Submetering!H5 -> 79 | J5: 7.84 | K5: ='OCT 2024'!X8 -> 10805.11 | L5: 0.3449 | M5: =Submetering!N5 -> 175.014 | N5: =Submetering!O5 -> 233
A6: Pearl Rotana Capital Centre | B6: =B5+1 -> 5 | C6: 10 | D6: 2024 | E6: =Submetering!E6+Submetering!F6+Submetering!G6 -> 15420 | F6: 0.2 | G6: ='OCT 2024'!T9 -> 34.8381 | H6: 16.76 | I6: =Submetering!H6 -> 87 | J6: 7.84 | K6: ='OCT 2024'!X9 -> 10520.765 | L6: 0.3449 | M6: =Submetering!N6 -> 148.995 | N6: =Submetering!O6 -> 200
A7: Pearl Rotana Capital Centre | B7: =B6+1 -> 6 | C7: 10 | D7: 2024 | E7: =Submetering!E7+Submetering!F7+Submetering!G7 -> 15598 | F7: 0.2 | G7: ='OCT 2024'!T10 -> 34.8381 | H7: 16.76 | I7: =Submetering!H7 -> 75 | J7: 7.84 | K7: ='OCT 2024'!X10 -> 9667.73 | L7: 0.3449 | M7: =Submetering!N7 -> 214.9875 | N7: =Submetering!O7 -> 269
A8: Pearl Rotana Capital Centre | B8: =B7+1 -> 7 | C8: 10 | D8: 2024 | E8: =Submetering!E8+Submetering!F8+Submetering!G8 -> 14730 | F8: 0.2 | G8: ='OCT 2024'!T11 -> 34.8381 | H8: 16.76 | I8: =Submetering!H8 -> 83 | J8: 7.84 | K8: ='OCT 2024'!X11 -> 9099.04 | L8: 0.3449 | M8: =Submetering!N8 -> 277.9875 | N8: =Submetering!O8 -> 333
A9: Pearl Rotana Capital Centre | B9: =B8+1 -> 8 | C9: 10 | D9: 2024 | E9: =Submetering!E9+Submetering!F9+Submetering!G9 -> 14299 | F9: 0.2 | G9: ='OCT 2024'!T12 -> 38.0052 | H9: 16.76 | I9: =Submetering!H9 -> 90 | J9: 7.84 | K9: ='OCT 2024'!X12 -> 8814.695 | L9: 0.3449 | M9: =Submetering!N9 -> 315 | N9: =Submetering!O9 -> 378
A10: Pearl Rotana Capital Centre | B10: =B9+1 -> 9 | C10: 10 | D10: 2024 | E10: =Submetering!E10+Submetering!F10+Submetering!G10 -> 15040 | F10: 0.2 | G10: ='OCT 2024'!T13 -> 36.9495 | H10: 16.76 | I10: =Submetering!H10 -> 105 | J10: 7.84 | K10: ='OCT 2024'!X13 -> 9383.385 | L10: 0.3449 | M10: =Submetering!N10 -> 298.998 | N10: =Submetering!O10 -> 366
A11: Pearl Rotana Capital Centre | B11: =B10+1 -> 10 | C11: 10 | D11: 2024 | E11: =Submetering!E11+Submetering!F11+Submetering!G11 -> 14708 | F11: 0.2 | G11: ='OCT 2024'!T14 -> 29.5596 | H11: 16.76 | I11: =Submetering!H11 -> 98 | J11: 7.84 | K11: ='OCT 2024'!X14 -> 9667.73 | L11: 0.3449 | M11: =Submetering!N11 -> 229.005 | N11: =Submetering!O11 -> 295
A12: Pearl Rotana Capital Centre | B12: =B11+1 -> 11 | C12: 10 | D12: 2024 | E12: =Submetering!E12+Submetering!F12+Submetering!G12 -> 14095 | F12: 0.2 | G12: ='OCT 2024'!T15 -> 38.0052 | H12: 16.76 | I12: =Submetering!H12 -> 92 | J12: 7.84 | K12: ='OCT 2024'!X15 -> 9383.385 | L12: 0.3449 | M12: =Submetering!N12 -> 207.9945 | N12: =Submetering!O12 -> 292
A13: Pearl Rotana Capital Centre | B13: =B12+1 -> 12 | C13: 10 | D13: 2024 | E13: =Submetering!E13+Submetering!F13+Submetering!G13 -> 14741 | F13: 0.2 | G13: ='OCT 2024'!T16 -> 34.8381 | H13: 16.76 | I13: =Submetering!H13 -> 101 | J13: 7.84 | K13: ='OCT 2024'!X16 -> 9099.04 | L13: 0.3449 | M13: =Submetering!N13 -> 274.995 | N13: =Submetering!O13 -> 392
A14: Pearl Rotana Capital Centre | B14: =B13+1 -> 13 | C14: 10 | D14: 2024 | E14: =Submetering!E14+Submetering!F14+Submetering!G14 -> 14872 | F14: 0.2 | G14: ='OCT 2024'!T17 -> 26.3925 | H14: 16.76 | I14: =Submetering!H14 -> 113 | J14: 7.84 | K14: ='OCT 2024'!X17 -> 8814.695 | L14: 0.3449 | M14: =Submetering!N14 -> 253.008 | N14: =Submetering!O14 -> 326
... A32: Pearl Rotana Capital Centre | B32: =B31+1 -> 31 | C32: 10 | D32: 2024 | E32: =Submetering!E32+Submetering!F32+Submetering!G32 -> 14736 | F32: 0.2 | G32: ='OCT 2024'!T35 -> 35.8938 | H32: 16.76 | I32: =Submetering!H32 -> 95 | J32: 7.84 | K32: ='OCT 2024'!X35 -> 9099.04 | L32: 0.3449 | M32: =Submetering!N32 -> 246.9915 | N32: =Submetering!O32 -> 311

Sheet Submetering
A1: Site Name | B1: Day | C1: Month | D1: Year | E1: MDB#2 | F1: MDB#3 | G1: MDB#1 Façade | H1: Water | I1: Gas Meter#1 GF Kitchen | J1: Gas Meter#2 1st floor Kitchen | K1: District Cooling | L1: District Cooling ETS | M1: Water Main Kitchen | N1: Room Nights | O1: Total Guests
A2: Pearl Rotana Capital Centre | B2: 1 | C2: 10 | D2: 2024 | E2: ='OCT 2024'!C5 -> 7824 | F2: ='OCT 2024'!E5 -> 6605 | G2: ='OCT 2024'!G5 -> 133 | H2: ='OCT 2024'!K5 -> 87 | I2: ='OCT 2024'!N5 -> 19 | J2: ='OCT 2024'!P5 -> 11 | K2: ='OCT 2024'!X5 -> 10236.42 | L2: ='OCT 2024'!AC5 -> 12529 | M2: ='OCT 2024'!AR5 -> 7 | N2: ='OCT 2024'!AD5*315 -> 250.0155 | O2: ='OCT 2024'!AE5 -> 306
A3: Pearl Rotana Capital Centre | B3: =B2+1 -> 2 | C3: 10 | D3: 2024 | E3: ='OCT 2024'!C6 -> 7802 | F3: ='OCT 2024'!E6 -> 6738 | G3: ='OCT 2024'!G6 -> 133 | H3: ='OCT 2024'!K6 -> 94 | I3: ='OCT 2024'!N6 -> 21 | J3: ='OCT 2024'!P6 -> 19 | K3: ='OCT 2024'!X6 -> 11089.455 | L3: ='OCT 2024'!AC6 -> 13300 | M3: ='OCT 2024'!AR6 -> 9 | N3: ='OCT 2024'!AD6*315 -> 265.0095 | O3: ='OCT 2024'!AE6 -> 339
A4: Pearl Rotana Capital Centre | B4: =B3+1 -> 3 | C4: 10 | D4: 2024 | E4: ='OCT 2024'!C7 -> 7824 | F4: ='OCT 2024'!E7 -> 6775 | G4: ='OCT 2024'!G7 -> 133 | H4: ='OCT 2024'!K7 -> 92 | I4: ='OCT 2024'!N7 -> 22 | J4: ='OCT 2024'!P7 -> 11 | K4: ='OCT 2024'!X7 -> 11373.8 | L4: ='OCT 2024'!AC7 -> 8247 | M4: ='OCT 2024'!AR7 -> 9 | N4: ='OCT 2024'!AD7*315 -> 198.9855 | O4: ='OCT 2024'!AE7 -> 245
A5: Pearl Rotana Capital Centre | B5: =B4+1 -> 4 | C5: 10 | D5: 2024 | E5: ='OCT 2024'!C8 -> 7622 | F5: ='OCT 2024'!E8 -> 6995 | G5: ='OCT 2024'!G8 -> 135 | H5: ='OCT 2024'!K8 -> 79 | I5: ='OCT 2024'!N8 -> 23 | J5: ='OCT 2024'!P8 -> 13 | K5: ='OCT 2024'!X8 -> 10805.11 | L5: ='OCT 2024'!AC8 -> 14882 | M5: ='OCT 2024'!AR8 -> 6 | N5: ='OCT 2024'!AD8*315 -> 175.014 | O5: ='OCT 2024'!AE8 -> 233
A6: Pearl Rotana Capital Centre | B6: =B5+1 -> 5 | C6: 10 | D6: 2024 | E6: ='OCT 2024'!C9 -> 7681 | F6: ='OCT 2024'!E9 -> 7603 | G6: ='OCT 2024'!G9 -> 136 | H6: ='OCT 2024'!K9 -> 87 | I6: ='OCT 2024'!N9 -> 21 | J6: ='OCT 2024'!P9 -> 14 | K6: ='OCT 2024'!X9 -> 10520.765 | L6: ='OCT 2024'!AC9 -> 10440 | M6: ='OCT 2024'!AR9 -> 8 | N6: ='OCT 2024'!AD9*315 -> 148.995 | O6: ='OCT 2024'!AE9 -> 200
A7: Pearl Rotana Capital Centre | B7: =B6+1 -> 6 | C7: 10 | D7: 2024 | E7: ='OCT 2024'!C10 -> 7901 | F7: ='OCT 2024'!E10 -> 7563 | G7: ='OCT 2024'!G10 -> 134 | H7: ='OCT 2024'!K10 -> 75 | I7: ='OCT 2024'!N10 -> 20 | J7: ='OCT 2024'!P10 -> 12 | K7: ='OCT 2024'!X10 -> 9667.73 | L7: ='OCT 2024'!AC10 -> 11915 | M7: ='OCT 2024'!AR10 -> 4 | N7: ='OCT 2024'!AD10*315 -> 214.9875 | O7: ='OCT 2024'!AE10 -> 269
A8: Pearl Rotana Capital Centre | B8: =B7+1 -> 7 | C8: 10 | D8: 2024 | E8: ='OCT 2024'!C11 -> 7644 | F8: ='OCT 2024'!E11 -> 6953 | G8: ='OCT 2024'!G11 -> 133 | H8: ='OCT 2024'!K11 -> 83 | I8: ='OCT 2024'!N11 -> 21 | J8: ='OCT 2024'!P11 -> 13 | K8: ='OCT 2024'!X11 -> 9099.04 | L8: ='OCT 2024'!AC11 -> 11422 | M8: ='OCT 2024'!AR11 -> 7 | N8: ='OCT 2024'!AD11*315 -> 277.9875 | O8: ='OCT 2024'!AE11 -> 333
A9: Pearl Rotana Capital Centre | B9: =B8+1 -> 8 | C9: 10 | D9: 2024 | E9: ='OCT 2024'!C12 -> 7575 | F9: ='OCT 2024'!E12 -> 6593 | G9: ='OCT 2024'!G12 -> 131 | H9: ='OCT 2024'!K12 -> 90 | I9: ='OCT 2024'!N12 -> 21 | J9: ='OCT 2024'!P12 -> 14 | K9: ='OCT 2024'!X12 -> 8814.695 | L9: ='OCT 2024'!AC12 -> 11231 | M9: ='OCT 2024'!AR12 -> 6 | N9: ='OCT 2024'!AD12*315 -> 315 | O9: ='OCT 2024'!AE12 -> 378
A10: Pearl Rotana Capital Centre | B10: =B9+1 -> 9 | C10: 10 | D10: 2024 | E10: ='OCT 2024'!C13 -> 7754 | F10: ='OCT 2024'!E13 -> 7154 | G10: ='OCT 2024'!G13 -> 132 | H10: ='OCT 2024'!K13 -> 105 | I10: ='OCT 2024'!N13 -> 20 | J10: ='OCT 2024'!P13 -> 15 | K10: ='OCT 2024'!X13 -> 9383.385 | L10: ='OCT 2024'!AC13 -> 12008 | M10: ='OCT 2024'!AR13 -> 7 | N10: ='OCT 2024'!AD13*315 -> 298.998 | O10: ='OCT 2024'!AE13 -> 366
A11: Pearl Rotana Capital Centre | B11: =B10+1 -> 10 | C11: 10 | D11: 2024 | E11: ='OCT 2024'!C14 -> 7658 | F11: ='OCT 2024'!E14 -> 6919 | G11: ='OCT 2024'!G14 -> 131 | H11: ='OCT 2024'!K14 -> 98 | I11: ='OCT 2024'!N14 -> 18 | J11: ='OCT 2024'!P14 -> 15 | K11: ='OCT 2024'!X14 -> 9667.73 | L11: ='OCT 2024'!AC14 -> 12117 | M11: ='OCT 2024'!AR14 -> 8 | N11: ='OCT 2024'!AD14*315 -> 229.005 | O11: ='OCT 2024'!AE14 -> 295
A12: Pearl Rotana Capital Centre | B12: =B11+1 -> 11 | C12: 10 | D12: 2024 | E12: ='OCT 2024'!C15 -> 7376 | F12: ='OCT 2024'!E15 -> 6588 | G12: ='OCT 2024'!G15 -> 131 | H12: ='OCT 2024'!K15 -> 92 | I12: ='OCT 2024'!N15 -> 22 | J12: ='OCT 2024'!P15 -> 17 | K12: ='OCT 2024'!X15 -> 9383.385 | L12: ='OCT 2024'!AC15 -> 11920 | M12: ='OCT 2024'!AR15 -> 6 | N12: ='OCT 2024'!AD15*315 -> 207.9945 | O12: ='OCT 2024'!AE15 -> 292
A13: Pearl Rotana Capital Centre | B13: =B12+1 -> 12 | C13: 10 | D13: 2024 | E13: ='OCT 2024'!C16 -> 7733 | F13: ='OCT 2024'!E16 -> 6874 | G13: ='OCT 2024'!G16 -> 134 | H13: ='OCT 2024'!K16 -> 101 | I13: ='OCT 2024'!N16 -> 21 | J13: ='OCT 2024'!P16 -> 12 | K13: ='OCT 2024'!X16 -> 9099.04 | L13: ='OCT 2024'!AC16 -> 11573 | M13: ='OCT 2024'!AR16 -> 6 | N13: ='OCT 2024'!AD16*315 -> 274.995 | O13: ='OCT 2024'!AE16 -> 392
A14: Pearl Rotana Capital Centre | B14: =B13+1 -> 13 | C14: 10 | D14: 2024 | E14: ='OCT 2024'!C17 -> 7818 | F14: ='OCT 2024'!E17 -> 6919 | G14: ='OCT 2024'!G17 -> 135 | H14: ='OCT 2024'!K17 -> 113 | I14: ='OCT 2024'!N17 -> 19 | J14: ='OCT 2024'!P17 -> 10 | K14: ='OCT 2024'!X17 -> 8814.695 | L14: ='OCT 2024'!AC17 -> 11151 | M14: ='OCT 2024'!AR17 -> 7 | N14: ='OCT 2024'!AD17*315 -> 253.008 | O14: ='OCT 2024'!AE17 -> 326
... A32: Pearl Rotana Capital Centre | B32: =B31+1 -> 31 | C32: 10 | D32: 2024 | E32: ='OCT 2024'!C35 -> 7758 | F32: ='OCT 2024'!E35 -> 6840 | G32: ='OCT 2024'!G35 -> 138 | H32: ='OCT 2024'!K35 -> 95 | I32: ='OCT 2024'!N35 -> 19 | J32: ='OCT 2024'!P35 -> 15 | K32: ='OCT 2024'!X35 -> 9099.04 | L32: ='OCT 2024'!AC35 -> 10378 | M32: ='OCT 2024'!AR35 -> 6 | N32: ='OCT 2024'!AD35*315 -> 246.9915 | O32: ='OCT 2024'!AE35 -> 311

Sheet OCT 2024
A1: PEARL ROTANA CAPITAL CENTRE UTILITIES CONSUMPTION - OCTOBER 2024
A2: DATE | B2: Electricity | J2: Water | M2: SNG Gas | V2: District Cooling | AD2: Additional Info | AF2: Additional Meter
B3: MDB #2 | D3: MDB #3 | F3: MDB #1 Façade | H3: Total ELE Cons. KW | I3: Electricity AED | J3: Hotel Reading | K3: Water Cons. M3 | L3: Water AED | M3: Gas Meter #1 G Floor Kitchen | O3: Gas Meter #2 1st Floor Kitchen | Q3: Total Gas Cons. M3 | R3: PRS Meter Reading | S3: PRS Meter Cons. M3 | T3: Meter factor (1.05570) | U3: Gas AED | V3: Hotel BTU Meter Energy Reading | W3: District Cooling Cons. MWH | X3: District Cooling Cons. Ton Hour | Y3: District Cooling Cons. AED | Z3: District Cooling Fixed Charge | AA3: District Cooling Total AED | AB3: ETS Energy Bulk Meter Reading | AC3: ETS Cons. Ton Hours | AD3: Hotel Occupancy % | AE3: Adl. & Chl. | AF3: Blue Sky tower Chilled water | AH3: Electricity MDB-1 | AK3: Electricity MDB-E | AN3: Electricity-MCC Panel Chilled water Secondary Pumps | AQ3: Water - Main kitchen | AT3: Water - Swimming Pool | AW3: Water - Bottling Plant
B4: Reading | C4: Cons. | D4: Reading | E4: Cons. | F4: Reading | G4: Cons. | M4: Reading | N4: Cons. | O4: Reading | P4: Cons. | AF4: Meter Reading | AG4: Cons. MWH | AH4: Meter Reading | AI4: Cons. KWH | AJ4: AED | AK4: Meter Reading | AL4: Cons. KWH | AM4: AED | AN4: Meter Reading | AO4: Cons. KWH | AP4: AED | AQ4: Meter Reading | AR4: Cons. M3 | AS4: AED | AT4: Meter Reading | AU4: Cons. M3 | AV4: AED | AW4: Meter Reading | AX4: Cons. M3 | AY4: AED
A5: 45566 | B5: 20305604 | C5: 7824 | D5: 21064355 | E5: 6605 | F5: 471819 | G5: 133 | H5: =C5+E5+G5 -> 14562 | I5: =H5*0.2 -> 2912.4 | J5: 96796 | K5: 87 | L5: =K5*7.84 -> 682.08 | M5: 38806 | N5: 19 | O5: 23058 | P5: 11 | Q5: =N5+P5 -> 30 | R5: 57984 | S5: 30 | T5: =S5*1.0557 -> 31.671 | U5: =IF(ISBLANK(M5),"0",T5*11.05+209.677) -> 559.64155 | V5: 73792 | W5: 36 | X5: =IF(ISBLANK(V5),"0 ",W5*284.345) -> 10236.42 | Y5: =X5*0.3449 -> 3530.5413 | Z5: =IF(ISBLANK(V5),"0",1570*1608.73/12/31*0.65) -> 4413.1961 | AA5: =Y5+Z5 -> 7943.7374 | AB5: 8359134 | AC5: 12529 | AD5: 0.7937 | AE5: 306 | AH5: 14283502 | AI5: 5742 | AJ5: =AI5*0.2 -> 1148.4 | AK5: 6572403 | AL5: 2223 | AM5: =AL5*0.2 -> 444.6 | AN5: 205471 | AO5: 547 | AP5: =AO5*0.2 -> 109.4 | AQ5: 7683 | AR5: 7 | AS5: =AR5*7.84 -> 54.88 | AT5: 3068 | AU5: 1 | AV5: =AU5*7.84 -> 7.84 | AW5: 44 | AX5: 1 | AY5: =AX5*7.84 -> 7.84
A6: 45567 | B6: 20313406 | C6: =IF(ISBLANK(B6),"0",B6-B5) -> 7802 | D6: 21071093 | E6: =IF(ISBLANK(D6),"0",D6-D5) -> 6738 | F6: 471952 | G6: =IF(ISBLANK(F6),"0",F6-F5) -> 133 | H6: =C6+E6+G6 -> 14673 | I6: =H6*0.2 -> 2934.6 | J6: 96890 | K6: =IF(ISBLANK(J6),"0",J6-J5) -> 94 | L6: =K6*7.84 -> 736.96 | M6: 38827 | N6: =IF(ISBLANK(M6),"0",M6-M5) -> 21 | O6: 23077 | P6: =IF(ISBLANK(O6),"0",O6-O5) -> 19 | Q6: =N6+P6 -> 40 | R6: 58024 | S6: =IF(ISBLANK(R6),"0",R6-R5) -> 40 | T6: =S6*1.0557 -> 42.228 | U6: =IF(ISBLANK(M6),"0",T6*11.05+209.677) -> 676.2964 | V6: 73831 | W6: 39 | X6: =IF(ISBLANK(V6),"0 ",W6*284.345) -> 11089.455 | Y6: =X6*0.3449 -> 3824.753 | Z6: =IF(ISBLANK(V6),"0",1570*1608.73/12/31*0.65) -> 4413.1961 | AA6: =Y6+Z6 -> 8237.9492 | AB6: 8372434 | AC6: =IF(ISBLANK(AB6),"0 ",AB6-AB5) -> 13300 | AD6: 0.8413 | AE6: 339 | AH6: 14289258 | AI6: =IF(ISBLANK(AH6),"0",AH6-AH5) -> 5756 | AJ6: =AI6*0.2 -> 1151.2 | AK6: 6574602 | AL6: =IF(ISBLANK(AK6),"0",AK6-AK5) -> 2199 | AM6: =AL6*0.2 -> 439.8 | AN6: 206101 | AO6: =IF(ISBLANK(AN6),"0",AN6-AN5) -> 630 | AP6: =AO6*0.2 -> 126 | AQ6: 7692 | AR6: =IF(ISBLANK(AQ6),"0",AQ6-AQ5) -> 9 | AS6: =AR6*7.84 -> 70.56 | AT6: 3068 | AU6: =IF(ISBLANK(AT6),"0",AT6-AT5) -> 0 | AV6: =AU6*7.84 -> 0 | AW6: 44 | AX6: =IF(ISBLANK(AW6),"0",AW6-AW5) -> 0 | AY6: =AX6*7.84 -> 0
A7: 45568 | B7: 20321230 | C7: =IF(ISBLANK(B7),"0",B7-B6) -> 7824 | D7: 21077868 | E7: =IF(ISBLANK(D7),"0",D7-D6) -> 6775 | F7: 472085 | G7: =IF(ISBLANK(F7),"0",F7-F6) -> 133 | H7: =C7+E7+G7 -> 14732 | I7: =H7*0.2 -> 2946.4 | J7: 96982 | K7: =IF(ISBLANK(J7),"0",J7-J6) -> 92 | L7: =K7*7.84 -> 721.28 | M7: 38849 | N7: =IF(ISBLANK(M7),"0",M7-M6) -> 22 | O7: 23088 | P7: =IF(ISBLANK(O7),"0",O7-O6) -> 11 | Q7: =N7+P7 -> 33 | R7: 58054 | S7: =IF(ISBLANK(R7),"0",R7-R6) -> 30 | T7: =S7*1.0557 -> 31.671 | U7: =IF(ISBLANK(M7),"0",T7*11.05+209.677) -> 559.64155 | V7: 73871 | W7: 40 | X7: =IF(ISBLANK(V7),"0 ",W7*284.345) -> 11373.8 | Y7: =X7*0.3449 -> 3922.8236 | Z7: =IF(ISBLANK(V7),"0",1570*1608.73/12/31*0.65) -> 4413.1961 | AA7: =Y7+Z7 -> 8336.0198 | AB7: 8380681 | AC7: =IF(ISBLANK(AB7),"0 ",AB7-AB6) -> 8247 | AD7: 0.6317 | AE7: 245 | AH7: 14295014 | AI7: =IF(ISBLANK(AH7),"0",AH7-AH6) -> 5756 | AJ7: =AI7*0.2 -> 1151.2 | AK7: 6576796 | AL7: =IF(ISBLANK(AK7),"0",AK7-AK6) -> 2194 | AM7: =AL7*0.2 -> 438.8 | AN7: 206746 | AO7: =IF(ISBLANK(AN7),"0",AN7-AN6) -> 645 | AP7: =AO7*0.2 -> 129 | AQ7: 7701 | AR7: =IF(ISBLANK(AQ7),"0",AQ7-AQ6) -> 9 | AS7: =AR7*7.84 -> 70.56 | AT7: 3068 | AU7: =IF(ISBLANK(AT7),"0",AT7-AT6) -> 0 | AV7: =AU7*7.84 -> 0 | AW7: 45 | AX7: =IF(ISBLANK(AW7),"0",AW7-AW6) -> 1 | AY7: =AX7*7.84 -> 7.84
A8: 45569 | B8: 20328852 | C8: =IF(ISBLANK(B8),"0",B8-B7) -> 7622 | D8: 21084863 | E8: =IF(ISBLANK(D8),"0",D8-D7) -> 6995 | F8: 472220 | G8: =IF(ISBLANK(F8),"0",F8-F7) -> 135 | H8: =C8+E8+G8 -> 14752 | I8: =H8*0.2 -> 2950.4 | J8: 97061 | K8: =IF(ISBLANK(J8),"0",J8-J7) -> 79 | L8: =K8*7.84 -> 619.36 | M8: 38872 | N8: =IF(ISBLANK(M8),"0",M8-M7) -> 23 | O8: 23101 | P8: =IF(ISBLANK(O8),"0",O8-O7) -> 13 | Q8: =N8+P8 -> 36 | R8: 58092 | S8: =IF(ISBLANK(R8),"0",R8-R7) -> 38 | T8: =S8*1.0557 -> 40.1166 | U8: =IF(ISBLANK(M8),"0",T8*11.05+209.677) -> 652.96543 | V8: 73909 | W8: 38 | X8: =IF(ISBLANK(V8),"0 ",W8*284.345) -> 10805.11 | Y8: =X8*0.3449 -> 3726.6824 | Z8: =IF(ISBLANK(V8),"0",1570*1608.73/12/31*0.65) -> 4413.1961 | AA8: =Y8+Z8 -> 8139.8786 | AB8: 14882 | AC8: 14882 | AD8: 0.5556 | AE8: 233 | AH8: 14300649 | AI8: =IF(ISBLANK(AH8),"0",AH8-AH7) -> 5635 | AJ8: =AI8*0.2 -> 1127 | AK8: 6578947 | AL8: =IF(ISBLANK(AK8),"0",AK8-AK7) -> 2151 | AM8: =AL8*0.2 -> 430.2 | AN8: 207657 | AO8: =IF(ISBLANK(AN8),"0",AN8-AN7) -> 911 | AP8: =AO8*0.2 -> 182.2 | AQ8: 7707 | AR8: =IF(ISBLANK(AQ8),"0",AQ8-AQ7) -> 6 | AS8: =AR8*7.84 -> 47.04 | AT8: 3071 | AU8: =IF(ISBLANK(AT8),"0",AT8-AT7) -> 3 | AV8: =AU8*7.84 -> 23.52 | AW8: 45 | AX8: =IF(ISBLANK(AW8),"0",AW8-AW7) -> 0 | AY8: =AX8*7.84 -> 0
A9: 45570 | B9: 20336533 | C9: =IF(ISBLANK(B9),"0",B9-B8) -> 7681 | D9: 21092466 | E9: =IF(ISBLANK(D9),"0",D9-D8) -> 7603 | F9: 472356 | G9: =IF(ISBLANK(F9),"0",F9-F8) -> 136 | H9: =C9+E9+G9 -> 15420 | I9: =H9*0.2 -> 3084 | J9: 97148 | K9: =IF(ISBLANK(J9),"0",J9-J8) -> 87 | L9: =K9*7.84 -> 682.08 | M9: 38893 | N9: =IF(ISBLANK(M9),"0",M9-M8) -> 21 | O9: 23115 | P9: =IF(ISBLANK(O9),"0",O9-O8) -> 14 | Q9: =N9+P9 -> 35 | R9: 58125 | S9: =IF(ISBLANK(R9),"0",R9-R8) -> 33 | T9: =S9*1.0557 -> 34.8381 | U9: =IF(ISBLANK(M9),"0",T9*11.05+209.677) -> 594.63801 | V9: 73946 | W9: 37 | X9: =IF(ISBLANK(V9),"0 ",W9*284.345) -> 10520.765 | Y9: =X9*0.3449 -> 3628.6118 | Z9: =IF(ISBLANK(V9),"0",1570*1608.73/12/31*0.65) -> 4413.1961 | AA9: =Y9+Z9 -> 8041.808 | AB9: 25322 | AC9: =IF(ISBLANK(AB9),"0 ",AB9-AB8) -> 10440 | AD9: 0.473 | AE9: 200 | AH9: 14305379 | AI9: =IF(ISBLANK(AH9),"0",AH9-AH8) -> 4730 | AJ9: =AI9*0.2 -> 946 | AK9: 6580966 | AL9: =IF(ISBLANK(AK9),"0",AK9-AK8) -> 2019 | AM9: =AL9*0.2 -> 403.8 | AN9: 208940 | AO9: =IF(ISBLANK(AN9),"0",AN9-AN8) -> 1283 | AP9: =AO9*0.2 -> 256.6 | AQ9: 7715 | AR9: =IF(ISBLANK(AQ9),"0",AQ9-AQ8) -> 8 | AS9: =AR9*7.84 -> 62.72 | AT9: 3071 | AU9: =IF(ISBLANK(AT9),"0",AT9-AT8) -> 0 | AV9: =AU9*7.84 -> 0 | AW9: 46 | AX9: =IF(ISBLANK(AW9),"0",AW9-AW8) -> 1 | AY9: =AX9*7.84 -> 7.84
A10: 45571 | B10: 20344434 | C10: =IF(ISBLANK(B10),"0",B10-B9) -> 7901 | D10: 21100029 | E10: =IF(ISBLANK(D10),"0",D10-D9) -> 7563 | F10: 472490 | G10: =IF(ISBLANK(F10),"0",F10-F9) -> 134 | H10: =C10+E10+G10 -> 15598 | I10: =H10*0.2 -> 3119.6 | J10: 97223 | K10: =IF(ISBLANK(J10),"0",J10-J9) -> 75 | L10: =K10*7.84 -> 588 | M10: 38913 | N10: =IF(ISBLANK(M10),"0",M10-M9) -> 20 | O10: 23127 | P10: =IF(ISBLANK(O10),"0",O10-O9) -> 12 | Q10: =N10+P10 -> 32 | R10: 58158 | S10: =IF(ISBLANK(R10),"0",R10-R9) -> 33 | T10: =S10*1.0557 -> 34.8381 | U10: =IF(ISBLANK(M10),"0",T10*11.05+209.677) -> 594.63801 | V10: 73980 | W10: 34 | X10: =IF(ISBLANK(V10),"0 ",W10*284.345) -> 9667.73 | Y10: =X10*0.3449 -> 3334.4001 | Z10: =IF(ISBLANK(V10),"0",1570*1608.73/12/31*0.65) -> 4413.1961 | AA10: =Y10+Z10 -> 7747.5962 | AB10: 37237 | AC10: =IF(ISBLANK(AB10),"0 ",AB10-AB9) -> 11915 | AD10: 0.6825 | AE10: 269 | AH10: 14310185 | AI10: =IF(ISBLANK(AH10),"0",AH10-AH9) -> 4806 | AJ10: =AI10*0.2 -> 961.2 | AK10: 6583032 | AL10: =IF(ISBLANK(AK10),"0",AK10-AK9) -> 2066 | AM10: =AL10*0.2 -> 413.2 | AN10: 210264 | AO10: =IF(ISBLANK(AN10),"0",AN10-AN9) -> 1324 | AP10: =AO10*0.2 -> 264.8 | AQ10: 7719 | AR10: =IF(ISBLANK(AQ10),"0",AQ10-AQ9) -> 4 | AS10: =AR10*7.84 -> 31.36 | AT10: 3072 | AU10: =IF(ISBLANK(AT10),"0",AT10-AT9) -> 1 | AV10: =AU10*7.84 -> 7.84 | AW10: 47 | AX10: =IF(ISBLANK(AW10),"0",AW10-AW9) -> 1 | AY10: =AX10*7.84 -> 7.84
A11: 45572 | B11: 20352078 | C11: =IF(ISBLANK(B11),"0",B11-B10) -> 7644 | D11: 21106982 | E11: =IF(ISBLANK(D11),"0",D11-D10) -> 6953 | F11: 472623 | G11: =IF(ISBLANK(F11),"0",F11-F10) -> 133 | H11: =C11+E11+G11 -> 14730 | I11: =H11*0.2 -> 2946 | J11: 97306 | K11: =IF(ISBLANK(J11),"0",J11-J10) -> 83 | L11: =K11*7.84 -> 650.72 | M11: 38934 | N11: =IF(ISBLANK(M11),"0",M11-M10) -> 21 | O11: 23140 | P11: =IF(ISBLANK(O11),"0",O11-O10) -> 13 | Q11: =N11+P11 -> 34 | R11: 58191 | S11: =IF(ISBLANK(R11),"0",R11-R10) -> 33 | T11: =S11*1.0557 -> 34.8381 | U11: =IF(ISBLANK(M11),"0",T11*11.05+209.677) -> 594.63801 | V11: 74021 | W11: 32 | X11: =IF(ISBLANK(V11),"0 ",W11*284.345) -> 9099.04 | Y11: =X11*0.3449 -> 3138.2589 | Z11: =IF(ISBLANK(V11),"0",1570*1608.73/12/31*0.65) -> 4413.1961 | AA11: =Y11+Z11 -> 7551.455 | AB11: 48659 | AC11: =IF(ISBLANK(AB11),"0 ",AB11-AB10) -> 11422 | AD11: 0.8825 | AE11: 333 | AH11: 14315821 | AI11: =IF(ISBLANK(AH11),"0",AH11-AH10) -> 5636 | AJ11: =AI11*0.2 -> 1127.2 | AK11: 6585202 | AL11: =IF(ISBLANK(AK11),"0",AK11-AK10) -> 2170 | AM11: =AL11*0.2 -> 434 | AN11: 211160 | AO11: =IF(ISBLANK(AN11),"0",AN11-AN10) -> 896 | AP11: =AO11*0.2 -> 179.2 | AQ11: 7726 | AR11: =IF(ISBLANK(AQ11),"0",AQ11-AQ10) -> 7 | AS11: =AR11*7.84 -> 54.88 | AT11: 3073 | AU11: =IF(ISBLANK(AT11),"0",AT11-AT10) -> 1 | AV11: =AU11*7.84 -> 7.84 | AW11: 48 | AX11: =IF(ISBLANK(AW11),"0",AW11-AW10) -> 1 | AY11: =AX11*7.84 -> 7.84
A12: 45573 | B12: 20359653 | C12: =IF(ISBLANK(B12),"0",B12-B11) -> 7575 | D12: 21113575 | E12: =IF(ISBLANK(D12),"0",D12-D11) -> 6593 | F12: 472754 | G12: =IF(ISBLANK(F12),"0",F12-F11) -> 131 | H12: =C12+E12+G12 -> 14299 | I12: =H12*0.2 -> 2859.8 | J12: 97396 | K12: =IF(ISBLANK(J12),"0",J12-J11) -> 90 | L12: =K12*7.84 -> 705.6 | M12: 38955 | N12: =IF(ISBLANK(M12),"0",M12-M11) -> 21 | O12: 23154 | P12: =IF(ISBLANK(O12),"0",O12-O11) -> 14 | Q12: =N12+P12 -> 35 | R12: 58227 | S12: =IF(ISBLANK(R12),"0",R12-R11) -> 36 | T12: =S12*1.0557 -> 38.0052 | U12: =IF(ISBLANK(M12),"0",T12*11.05+209.677) -> 629.63446 | V12: 74079 | W12: 31 | X12: =IF(ISBLANK(V12),"0 ",W12*284.345) -> 8814.695 | Y12: =X12*0.3449 -> 3040.1883 | Z12: =IF(ISBLANK(V12),"0",1570*1608.73/12/31*0.65) -> 4413.1961 | AA12: =Y12+Z12 -> 7453.3844 | AB12: 59890 | AC12: =IF(ISBLANK(AB12),"0 ",AB12-AB11) -> 11231 | AD12: 1 | AE12: 378 | AH12: 14321493 | AI12: =IF(ISBLANK(AH12),"0",AH12-AH11) -> 5672 | AJ12: =AI12*0.2 -> 1134.4 | AK12: 6587389 | AL12: =IF(ISBLANK(AK12),"0",AK12-AK11) -> 2187 | AM12: =AL12*0.2 -> 437.4 | AN12: 211766 | AO12: =IF(ISBLANK(AN12),"0",AN12-AN11) -> 606 | AP12: =AO12*0.2 -> 121.2 | AQ12: 7732 | AR12: =IF(ISBLANK(AQ12),"0",AQ12-AQ11) -> 6 | AS12: =AR12*7.84 -> 47.04 | AT12: 3073 | AU12: =IF(ISBLANK(AT12),"0",AT12-AT11) -> 0 | AV12: =AU12*7.84 -> 0 | AW12: 48 | AX12: =IF(ISBLANK(AW12),"0",AW12-AW11) -> 0 | AY12: =AX12*7.84 -> 0
A13: 45574 | B13: 20367407 | C13: =IF(ISBLANK(B13),"0",B13-B12) -> 7754 | D13: 21120729 | E13: =IF(ISBLANK(D13),"0",D13-D12) -> 7154 | F13: 472886 | G13: =IF(ISBLANK(F13),"0",F13-F12) -> 132 | H13: =C13+E13+G13 -> 15040 | I13: =H13*0.2 -> 3008 | J13: 97501 | K13: =IF(ISBLANK(J13),"0",J13-J12) -> 105 | L13: =K13*7.84 -> 823.2 | M13: 38975 | N13: =IF(ISBLANK(M13),"0",M13-M12) -> 20 | O13: 23169 | P13: =IF(ISBLANK(O13),"0",O13-O12) -> 15 | Q13: =N13+P13 -> 35 | R13: 58262 | S13: =IF(ISBLANK(R13),"0",R13-R12) -> 35 | T13: =S13*1.0557 -> 36.9495 | U13: =IF(ISBLANK(M13),"0",T13*11.05+209.677) -> 617.96898 | V13: 74140 | W13: 33 | X13: =IF(ISBLANK(V13),"0 ",W13*284.345) -> 9383.385 | Y13: =X13*0.3449 -> 3236.3295 | Z13: =IF(ISBLANK(V13),"0",1570*1608.73/12/31*0.65) -> 4413.1961 | AA13: =Y13+Z13 -> 7649.5256 | AB13: 71898 | AC13: =IF(ISBLANK(AB13),"0 ",AB13-AB12) -> 12008 | AD13: 0.9492 | AE13: 366 | AH13: 14327313 | AI13: =IF(ISBLANK(AH13),"0",AH13-AH12) -> 5820 | AJ13: =AI13*0.2 -> 1164 | AK13: 6589619 | AL13: =IF(ISBLANK(AK13),"0",AK13-AK12) -> 2230 | AM13: =AL13*0.2 -> 446 | AN13: 212504 | AO13: =IF(ISBLANK(AN13),"0",AN13-AN12) -> 738 | AP13: =AO13*0.2 -> 147.6 | AQ13: 7739 | AR13: =IF(ISBLANK(AQ13),"0",AQ13-AQ12) -> 7 | AS13: =AR13*7.84 -> 54.88 | AT13: 3074 | AU13: =IF(ISBLANK(AT13),"0",AT13-AT12) -> 1 | AV13: =AU13*7.84 -> 7.84 | AW13: 49 | AX13: =IF(ISBLANK(AW13),"0",AW13-AW12) -> 1 | AY13: =AX13*7.84 -> 7.84
A14: 45575 | B14: 20375065 | C14: =IF(ISBLANK(B14),"0",B14-B13) -> 7658 | D14: 21127648 | E14: =IF(ISBLANK(D14),"0",D14-D13) -> 6919 | F14: 473017 | G14: =IF(ISBLANK(F14),"0",F14-F13) -> 131 | H14: =C14+E14+G14 -> 14708 | I14: =H14*0.2 -> 2941.6 | J14: 97599 | K14: =IF(ISBLANK(J14),"0",J14-J13) -> 98 | L14: =K14*7.84 -> 768.32 | M14: 38993 | N14: =IF(ISBLANK(M14),"0",M14-M13) -> 18 | O14: 23184 | P14: =IF(ISBLANK(O14),"0",O14-O13) -> 15 | Q14: =N14+P14 -> 33 | R14: 58290 | S14: =IF(ISBLANK(R14),"0",R14-R13) -> 28 | T14: =S14*1.0557 -> 29.5596 | U14: =IF(ISBLANK(M14),"0",T14*11.05+209.677) -> 536.31058 | V14: 74200 | W14: 34 | X14: =IF(ISBLANK(V14),"0 ",W14*284.345) -> 9667.73 | Y14: =X14*0.3449 -> 3334.4001 | Z14: =IF(ISBLANK(V14),"0",1570*1608.73/12/31*0.65) -> 4413.1961 | AA14: =Y14+Z14 -> 7747.5962 | AB14: 84015 | AC14: =IF(ISBLANK(AB14),"0 ",AB14-AB13) -> 12117 | AD14: 0.727 | AE14: 295 | AH14: 14333099 | AI14: =IF(ISBLANK(AH14),"0",AH14-AH13) -> 5786 | AJ14: =AI14*0.2 -> 1157.2 | AK14: 6591843 | AL14: =IF(ISBLANK(AK14),"0",AK14-AK13) -> 2224 | AM14: =AL14*0.2 -> 444.8 | AN14: 213172 | AO14: =IF(ISBLANK(AN14),"0",AN14-AN13) -> 668 | AP14: =AO14*0.2 -> 133.6 | AQ14: 7747 | AR14: =IF(ISBLANK(AQ14),"0",AQ14-AQ13) -> 8 | AS14: =AR14*7.84 -> 62.72 | AT14: 3074 | AU14: =IF(ISBLANK(AT14),"0",AT14-AT13) -> 0 | AV14: =AU14*7.84 -> 0 | AW14: 50 | AX14: =IF(ISBLANK(AW14),"0",AW14-AW13) -> 1 | AY14: =AX14*7.84 -> 7.84
A15: 45576 | B15: 20382441 | C15: =IF(ISBLANK(B15),"0",B15-B14) -> 7376 | D15: 21134236 | E15: =IF(ISBLANK(D15),"0",D15-D14) -> 6588 | F15: 473148 | G15: =IF(ISBLANK(F15),"0",F15-F14) -> 131 | H15: =C15+E15+G15 -> 14095 | I15: =H15*0.2 -> 2819 | J15: 97691 | K15: =IF(ISBLANK(J15),"0",J15-J14) -> 92 | L15: =K15*7.84 -> 721.28 | M15: 39015 | N15: =IF(ISBLANK(M15),"0",M15-M14) -> 22 | O15: 23201 | P15: =IF(ISBLANK(O15),"0",O15-O14) -> 17 | Q15: =N15+P15 -> 39 | R15: 58326 | S15: =IF(ISBLANK(R15),"0",R15-R14) -> 36 | T15: =S15*1.0557 -> 38.0052 | U15: =IF(ISBLANK(M15),"0",T15*11.05+209.677) -> 629.63446 | V15: 74261 | W15: 33 | X15: =IF(ISBLANK(V15),"0 ",W15*284.345) -> 9383.385 | Y15: =X15*0.3449 -> 3236.3295 | Z15: =IF(ISBLANK(V15),"0",1570*1608.73/12/31*0.65) -> 4413.1961 | AA15: =Y15+Z15 -> 7649.5256 | AB15: 95935 | AC15: =IF(ISBLANK(AB15),"0 ",AB15-AB14) -> 11920 | AD15: 0.6603 | AE15: 292 | AH15: 14338588 | AI15: =IF(ISBLANK(AH15),"0",AH15-AH14) -> 5489 | AJ15: =AI15*0.2 -> 1097.8 | AK15: 6593955 | AL15: =IF(ISBLANK(AK15),"0",AK15-AK14) -> 2112 | AM15: =AL15*0.2 -> 422.4 | AN15: 213755 | AO15: =IF(ISBLANK(AN15),"0",AN15-AN14) -> 583 | AP15: =AO15*0.2 -> 116.6 | AQ15: 7753 | AR15: =IF(ISBLANK(AQ15),"0",AQ15-AQ14) -> 6 | AS15: =AR15*7.84 -> 47.04 | AT15: 3077 | AU15: =IF(ISBLANK(AT15),"0",AT15-AT14) -> 3 | AV15: =AU15*7.84 -> 23.52 | AW15: 51 | AX15: =IF(ISBLANK(AW15),"0",AW15-AW14) -> 1 | AY15: =AX15*7.84 -> 7.84
A16: 45577 | B16: 20390174 | C16: =IF(ISBLANK(B16),"0",B16-B15) -> 7733 | D16: 21141110 | E16: =IF(ISBLANK(D16),"0",D16-D15) -> 6874 | F16: 473282 | G16: =IF(ISBLANK(F16),"0",F16-F15) -> 134 | H16: =C16+E16+G16 -> 14741 | I16: =H16*0.2 -> 2948.2 | J16: 97792 | K16: =IF(ISBLANK(J16),"0",J16-J15) -> 101 | L16: =K16*7.84 -> 791.84 | M16: 39036 | N16: =IF(ISBLANK(M16),"0",M16-M15) -> 21 | O16: 23213 | P16: =IF(ISBLANK(O16),"0",O16-O15) -> 12 | Q16: =N16+P16 -> 33 | R16: 58359 | S16: =IF(ISBLANK(R16),"0",R16-R15) -> 33 | T16: =S16*1.0557 -> 34.8381 | U16: =IF(ISBLANK(M16),"0",T16*11.05+209.677) -> 594.63801 | V16: 74319 | W16: 32 | X16: =IF(ISBLANK(V16),"0 ",W16*284.345) -> 9099.04 | Y16: =X16*0.3449 -> 3138.2589 | Z16: =IF(ISBLANK(V16),"0",1570*1608.73/12/31*0.65) -> 4413.1961 | AA16: =Y16+Z16 -> 7551.455 | AB16: 107508 | AC16: =IF(ISBLANK(AB16),"0 ",AB16-AB15) -> 11573 | AD16: 0.873 | AE16: 392 | AH16: 14343366 | AI16: =IF(ISBLANK(AH16),"0",AH16-AH15) -> 4778 | AJ16: =AI16*0.2 -> 955.6 | AK16: 6596014 | AL16: =IF(ISBLANK(AK16),"0",AK16-AK15) -> 2059 | AM16: =AL16*0.2 -> 411.8 | AN16: 214327 | AO16: =IF(ISBLANK(AN16),"0",AN16-AN15) -> 572 | AP16: =AO16*0.2 -> 114.4 | AQ16: 7759 | AR16: =IF(ISBLANK(AQ16),"0",AQ16-AQ15) -> 6 | AS16: =AR16*7.84 -> 47.04 | AT16: 3077 | AU16: =IF(ISBLANK(AT16),"0",AT16-AT15) -> 0 | AV16: =AU16*7.84 -> 0 | AW16: 52 | AX16: =IF(ISBLANK(AW16),"0",AW16-AW15) -> 1 | AY16: =AX16*7.84 -> 7.84
A17: 45578 | B17: 20397992 | C17: =IF(ISBLANK(B17),"0",B17-B16) -> 7818 | D17: 21148029 | E17: =IF(ISBLANK(D17),"0",D17-D16) -> 6919 | F17: 473417 | G17: =IF(ISBLANK(F17),"0",F17-F16) -> 135 | H17: =C17+E17+G17 -> 14872 | I17: =H17*0.2 -> 2974.4 | J17: 97905 | K17: =IF(ISBLANK(J17),"0",J17-J16) -> 113 | L17: =K17*7.84 -> 885.92 | M17: 39055 | N17: =IF(ISBLANK(M17),"0",M17-M16) -> 19 | O17: 23223 | P17: =IF(ISBLANK(O17),"0",O17-O16) -> 10 | Q17: =N17+P17 -> 29 | R17: 58384 | S17: =IF(ISBLANK(R17),"0",R17-R16) -> 25 | T17: =S17*1.0557 -> 26.3925 | U17: =IF(ISBLANK(M17),"0",T17*11.05+209.677) -> 501.31412 | V17: 74375 | W17: 31 | X17: =IF(ISBLANK(V17),"0 ",W17*284.345) -> 8814.695 | Y17: =X17*0.3449 -> 3040.1883 | Z17: =IF(ISBLANK(V17),"0",1570*1608.73/12/31*0.65) -> 4413.1961 | AA17: =Y17+Z17 -> 7453.3844 | AB17: 118659 | AC17: =IF(ISBLANK(AB17),"0 ",AB17-AB16) -> 11151 | AD17: 0.8032 | AE17: 326 | AH17: 14348199 | AI17: =IF(ISBLANK(AH17),"0",AH17-AH16) -> 4833 | AJ17: =AI17*0.2 -> 966.6 | AK17: 6598128 | AL17: =IF(ISBLANK(AK17),"0",AK17-AK16) -> 2114 | AM17: =AL17*0.2 -> 422.8 | AN17: 214847 | AO17: =IF(ISBLANK(AN17),"0",AN17-AN16) -> 520 | AP17: =AO17*0.2 -> 104 | AQ17: 7766 | AR17: =IF(ISBLANK(AQ17),"0",AQ17-AQ16) -> 7 | AS17: =AR17*7.84 -> 54.88 | AT17: 3078 | AU17: =IF(ISBLANK(AT17),"0",AT17-AT16) -> 1 | AV17: =AU17*7.84 -> 7.84 | AW17: 53 | AX17: =IF(ISBLANK(AW17),"0",AW17-AW16) -> 1 | AY17: =AX17*7.84 -> 7.84
A18: 45579 | B18: 20405868 | C18: =IF(ISBLANK(B18),"0",B18-B17) -> 7876 | D18: 21155238 | E18: =IF(ISBLANK(D18),"0",D18-D17) -> 7209 | F18: 473550 | G18: =IF(ISBLANK(F18),"0",F18-F17) -> 133 | H18: =C18+E18+G18 -> 15218 | I18: =H18*0.2 -> 3043.6 | J18: 97987 | K18: =IF(ISBLANK(J18),"0",J18-J17) -> 82 | L18: =K18*7.84 -> 642.88 | M18: 39076 | N18: =IF(ISBLANK(M18),"0",M18-M17) -> 21 | O18: 23242 | P18: =IF(ISBLANK(O18),"0",O18-O17) -> 19 | Q18: =N18+P18 -> 40 | R18: 58423 | S18: =IF(ISBLANK(R18),"0",R18-R17) -> 39 | T18: =S18*1.0557 -> 41.1723 | U18: =IF(ISBLANK(M18),"0",T18*11.05+209.677) -> 664.63092 | V18: 74433 | W18: 29 | X18: =IF(ISBLANK(V18),"0 ",W18*284.345) -> 8246.005 | Y18: =X18*0.3449 -> 2844.0471 | Z18: =IF(ISBLANK(V18),"0",1570*1608.73/12/31*0.65) -> 4413.1961 | AA18: =Y18+Z18 -> 7257.2433 | AB18: 129017 | AC18: =IF(ISBLANK(AB18),"0 ",AB18-AB17) -> 10358 | AD18: 0.8667 | AE18: 346 | AH18: 14354156 | AI18: =IF(ISBLANK(AH18),"0",AH18-AH17) -> 5957 | AJ18: =AI18*0.2 -> 1191.4 | AK18: 6600396 | AL18: =IF(ISBLANK(AK18),"0",AK18-AK17) -> 2268 | AM18: =AL18*0.2 -> 453.6 | AN18: 215447 | AO18: =IF(ISBLANK(AN18),"0",AN18-AN17) -> 600 | AP18: =AO18*0.2 -> 120 | AQ18: 7773 | AR18: =IF(ISBLANK(AQ18),"0",AQ18-AQ17) -> 7 | AS18: =AR18*7.84 -> 54.88 | AT18: 3079 | AU18: =IF(ISBLANK(AT18),"0",AT18-AT17) -> 1 | AV18: =AU18*7.84 -> 7.84 | AW18: 54 | AX18: =IF(ISBLANK(AW18),"0",AW18-AW17) -> 1 | AY18: =AX18*7.84 -> 7.84
A19: 45580 | B19: 20413514 | C19: =IF(ISBLANK(B19),"0",B19-B18) -> 7646 | D19: 21162316 | E19: =IF(ISBLANK(D19),"0",D19-D18) -> 7078 | F19: 473683 | G19: =IF(ISBLANK(F19),"0",F19-F18) -> 133 | H19: =C19+E19+G19 -> 14857 | I19: =H19*0.2 -> 2971.4 | J19: 98090 | K19: =IF(ISBLANK(J19),"0",J19-J18) -> 103 | L19: =K19*7.84 -> 807.52 | M19: 39100 | N19: =IF(ISBLANK(M19),"0",M19-M18) -> 24 | O19: 23256 | P19: =IF(ISBLANK(O19),"0",O19-O18) -> 14 | Q19: =N19+P19 -> 38 | R19: 58461 | S19: =IF(ISBLANK(R19),"0",R19-R18) -> 38 | T19: =S19*1.0557 -> 40.1166 | U19: =IF(ISBLANK(M19),"0",T19*11.05+209.677) -> 652.96543 | V19: 74484 | W19: 31 | X19: =IF(ISBLANK(V19),"0 ",W19*284.345) -> 8814.695 | Y19: =X19*0.3449 -> 3040.1883 | Z19: =IF(ISBLANK(V19),"0",1570*1608.73/12/31*0.65) -> 4413.1961 | AA19: =Y19+Z19 -> 7453.3844 | AB19: 140220 | AC19: =IF(ISBLANK(AB19),"0 ",AB19-AB18) -> 11203 | AD19: 0.9016 | AE19: 360 | AF19: 20148 | AH19: 14359950 | AI19: =IF(ISBLANK(AH19),"0",AH19-AH18) -> 5794 | AJ19: =AI19*0.2 -> 1158.8 | AK19: 6602612 | AL19: =IF(ISBLANK(AK19),"0",AK19-AK18) -> 2216 | AM19: =AL19*0.2 -> 443.2 | AN19: 216019 | AO19: =IF(ISBLANK(AN19),"0",AN19-AN18) -> 572 | AP19: =AO19*0.2 -> 114.4 | AQ19: 7782 | AR19: =IF(ISBLANK(AQ19),"0",AQ19-AQ18) -> 9 | AS19: =AR19*7.84 -> 70.56 | AT19: 3080 | AU19: =IF(ISBLANK(AT19),"0",AT19-AT18) -> 1 | AV19: =AU19*7.84 -> 7.84 | AW19: 54 | AX19: =IF(ISBLANK(AW19),"0",AW19-AW18) -> 0 | AY19: =AX19*7.84 -> 0
A20: 45581 | B20: 20421119 | C20: =IF(ISBLANK(B20),"0",B20-B19) -> 7605 | D20: 21169221 | E20: =IF(ISBLANK(D20),"0",D20-D19) -> 6905 | F20: 473812 | G20: =IF(ISBLANK(F20),"0",F20-F19) -> 129 | H20: =C20+E20+G20 -> 14639 | I20: =H20*0.2 -> 2927.8 | J20: 98199 | K20: =IF(ISBLANK(J20),"0",J20-J19) -> 109 | L20: =K20*7.84 -> 854.56 | M20: 39124 | N20: =IF(ISBLANK(M20),"0",M20-M19) -> 24 | O20: 23269 | P20: =IF(ISBLANK(O20),"0",O20-O19) -> 13 | Q20: =N20+P20 -> 37 | R20: 58496 | S20: =IF(ISBLANK(R20),"0",R20-R19) -> 35 | T20: =S20*1.0557 -> 36.9495 | U20: =IF(ISBLANK(M20),"0",T20*11.05+209.677) -> 617.96898 | V20: 74529 | W20: 32 | X20: =IF(ISBLANK(V20),"0 ",W20*284.345) -> 9099.04 | Y20: =X20*0.3449 -> 3138.2589 | Z20: =IF(ISBLANK(V20),"0",1570*1608.73/12/31*0.65) -> 4413.1961 | AA20: =Y20+Z20 -> 7551.455 | AB20: 151788 | AC20: =IF(ISBLANK(AB20),"0 ",AB20-AB19) -> 11568 | AD20: 0.9556 | AE20: 380 | AF20: 20154 | AG20: =IF(ISBLANK(V20)," ",AF20-AF19) -> 6 | AH20: 14365655 | AI20: =IF(ISBLANK(AH20),"0",AH20-AH19) -> 5705 | AJ20: =AI20*0.2 -> 1141 | AK20: 6604836 | AL20: =IF(ISBLANK(AK20),"0",AK20-AK19) -> 2224 | AM20: =AL20*0.2 -> 444.8 | AN20: 216520 | AO20: =IF(ISBLANK(AN20),"0",AN20-AN19) -> 501 | AP20: =AO20*0.2 -> 100.2 | AQ20: 7789 | AR20: =IF(ISBLANK(AQ20),"0",AQ20-AQ19) -> 7 | AS20: =AR20*7.84 -> 54.88 | AT20: 3081 | AU20: =IF(ISBLANK(AT20),"0",AT20-AT19) -> 1 | AV20: =AU20*7.84 -> 7.84 | AW20: 56 | AX20: =IF(ISBLANK(AW20),"0",AW20-AW19) -> 2 | AY20: =AX20*7.84 -> 15.68
A21: 45582 | B21: 20428632 | C21: =IF(ISBLANK(B21),"0",B21-B20) -> 7513 | D21: 21175894 | E21: =IF(ISBLANK(D21),"0",D21-D20) -> 6673 | F21: 473945 | G21: =IF(ISBLANK(F21),"0",F21-F20) -> 133 | H21: =C21+E21+G21 -> 14319 | I21: =H21*0.2 -> 2863.8 | J21: 98301 | K21: =IF(ISBLANK(J21),"0",J21-J20) -> 102 | L21: =K21*7.84 -> 799.68 | M21: 39144 | N21: =IF(ISBLANK(M21),"0",M21-M20) -> 20 | O21: 23284 | P21: =IF(ISBLANK(O21),"0",O21-O20) -> 15 | Q21: =N21+P21 -> 35 | R21: 58532 | S21: =IF(ISBLANK(R21),"0",R21-R20) -> 36 | T21: =S21*1.0557 -> 38.0052 | U21: =IF(ISBLANK(M21),"0",T21*11.05+209.677) -> 629.63446 | V21: 74576 | W21: 33 | X21: =IF(ISBLANK(V21),"0 ",W21*284.345) -> 9383.385 | Y21: =X21*0.3449 -> 3236.3295 | Z21: =IF(ISBLANK(V21),"0",1570*1608.73/12/31*0.65) -> 4413.1961 | AA21: =Y21+Z21 -> 7649.5256 | AB21: 163592 | AC21: =IF(ISBLANK(AB21),"0 ",AB21-AB20) -> 11804 | AD21: 0.8984 | AE21: 360 | AF21: 20163 | AG21: =IF(ISBLANK(V21)," ",AF21-AF20) -> 9 | AH21: 14371280 | AI21: =IF(ISBLANK(AH21),"0",AH21-AH20) -> 5625 | AJ21: =AI21*0.2 -> 1125 | AK21: 6607002 | AL21: =IF(ISBLANK(AK21),"0",AK21-AK20) -> 2166 | AM21: =AL21*0.2 -> 433.2 | AN21: 216984 | AO21: =IF(ISBLANK(AN21),"0",AN21-AN20) -> 464 | AP21: =AO21*0.2 -> 92.8 | AQ21: 7798 | AR21: =IF(ISBLANK(AQ21),"0",AQ21-AQ20) -> 9 | AS21: =AR21*7.84 -> 70.56 | AT21: 3081 | AU21: =IF(ISBLANK(AT21),"0",AT21-AT20) -> 0 | AV21: =AU21*7.84 -> 0 | AW21: 57 | AX21: =IF(ISBLANK(AW21),"0",AW21-AW20) -> 1 | AY21: =AX21*7.84 -> 7.84
A22: 45583 | B22: 20436296 | C22: =IF(ISBLANK(B22),"0",B22-B21) -> 7664 | D22: 21182722 | E22: =IF(ISBLANK(D22),"0",D22-D21) -> 6828 | F22: 474074 | G22: =IF(ISBLANK(F22),"0",F22-F21) -> 129 | H22: =C22+E22+G22 -> 14621 | I22: =H22*0.2 -> 2924.2 | J22: 98412 | K22: =IF(ISBLANK(J22),"0",J22-J21) -> 111 | L22: =K22*7.84 -> 870.24 | M22: 39169 | N22: =IF(ISBLANK(M22),"0",M22-M21) -> 25 | O22: 23300 | P22: =IF(ISBLANK(O22),"0",O22-O21) -> 16 | Q22: =N22+P22 -> 41 | R22: 58573 | S22: =IF(ISBLANK(R22),"0",R22-R21) -> 41 | T22: =S22*1.0557 -> 43.2837 | U22: =IF(ISBLANK(M22),"0",T22*11.05+209.677) -> 687.96189 | V22: 74626 | W22: 35 | X22: =IF(ISBLANK(V22),"0 ",W22*284.345) -> 9952.075 | Y22: =X22*0.3449 -> 3432.4707 | Z22: =IF(ISBLANK(V22),"0",1570*1608.73/12/31*0.65) -> 4413.1961 | AA22: =Y22+Z22 -> 7845.6668 | AB22: 176191 | AC22: =IF(ISBLANK(AB22),"0 ",AB22-AB21) -> 12599 | AD22: 0.8889 | AE22: 367 | AF22: 20172 | AG22: =IF(ISBLANK(V22)," ",AF22-AF21) -> 9 | AH22: 14376825 | AI22: =IF(ISBLANK(AH22),"0",AH22-AH21) -> 5545 | AJ22: =AI22*0.2 -> 1109 | AK22: 6609235 | AL22: =IF(ISBLANK(AK22),"0",AK22-AK21) -> 2233 | AM22: =AL22*0.2 -> 446.6 | AN22: 217487 | AO22: =IF(ISBLANK(AN22),"0",AN22-AN21) -> 503 | AP22: =AO22*0.2 -> 100.6 | AQ22: 7805 | AR22: =IF(ISBLANK(AQ22),"0",AQ22-AQ21) -> 7 | AS22: =AR22*7.84 -> 54.88 | AT22: 3081 | AU22: =IF(ISBLANK(AT22),"0",AT22-AT21) -> 0 | AV22: =AU22*7.84 -> 0 | AW22: 58 | AX22: =IF(ISBLANK(AW22),"0",AW22-AW21) -> 1 | AY22: =AX22*7.84 -> 7.84
A23: 45584 | B23: 20443720 | C23: =IF(ISBLANK(B23),"0",B23-B22) -> 7424 | D23: 21189308 | E23: =IF(ISBLANK(D23),"0",D23-D22) -> 6586 | F23: 474204 | G23: =IF(ISBLANK(F23),"0",F23-F22) -> 130 | H23: =C23+E23+G23 -> 14140 | I23: =H23*0.2 -> 2828 | J23: 98507 | K23: =IF(ISBLANK(J23),"0",J23-J22) -> 95 | L23: =K23*7.84 -> 744.8 | M23: 39190 | N23: =IF(ISBLANK(M23),"0",M23-M22) -> 21 | O23: 23316 | P23: =IF(ISBLANK(O23),"0",O23-O22) -> 16 | Q23: =N23+P23 -> 37 | R23: 58610 | S23: =IF(ISBLANK(R23),"0",R23-R22) -> 37 | T23: =S23*1.0557 -> 39.0609 | U23: =IF(ISBLANK(M23),"0",T23*11.05+209.677) -> 641.29995 | V23: 74685 | W23: 36 | X23: =IF(ISBLANK(V23),"0 ",W23*284.345) -> 10236.42 | Y23: =X23*0.3449 -> 3530.5413 | Z23: =IF(ISBLANK(V23),"0",1570*1608.73/12/31*0.65) -> 4413.1961 | AA23: =Y23+Z23 -> 7943.7374 | AB23: 189112 | AC23: =IF(ISBLANK(AB23),"0 ",AB23-AB22) -> 12921 | AD23: 0.9143 | AE23: 394 | AF23: 20181 | AG23: =IF(ISBLANK(V23)," ",AF23-AF22) -> 9 | AH23: 14381479 | AI23: =IF(ISBLANK(AH23),"0",AH23-AH22) -> 4654 | AJ23: =AI23*0.2 -> 930.8 | AK23: 6611305 | AL23: =IF(ISBLANK(AK23),"0",AK23-AK22) -> 2070 | AM23: =AL23*0.2 -> 414 | AN23: 217937 | AO23: =IF(ISBLANK(AN23),"0",AN23-AN22) -> 450 | AP23: =AO23*0.2 -> 90 | AQ23: 7813 | AR23: =IF(ISBLANK(AQ23),"0",AQ23-AQ22) -> 8 | AS23: =AR23*7.84 -> 62.72 | AT23: 3082 | AU23: =IF(ISBLANK(AT23),"0",AT23-AT22) -> 1 | AV23: =AU23*7.84 -> 7.84 | AW23: 59 | AX23: =IF(ISBLANK(AW23),"0",AW23-AW22) -> 1 | AY23: =AX23*7.84 -> 7.84
A24: 45585 | B24: 20451085 | C24: =IF(ISBLANK(B24),"0",B24-B23) -> 7365 | D24: 21195819 | E24: =IF(ISBLANK(D24),"0",D24-D23) -> 6511 | F24: 474335 | G24: =IF(ISBLANK(F24),"0",F24-F23) -> 131 | H24: =C24+E24+G24 -> 14007 | I24: =H24*0.2 -> 2801.4 | J24: 98621 | K24: =IF(ISBLANK(J24),"0",J24-J23) -> 114 | L24: =K24*7.84 -> 893.76 | M24: 39209 | N24: =IF(ISBLANK(M24),"0",M24-M23) -> 19 | O24: 23327 | P24: =IF(ISBLANK(O24),"0",O24-O23) -> 11 | Q24: =N24+P24 -> 30 | R24: 58639 | S24: =IF(ISBLANK(R24),"0",R24-R23) -> 29 | T24: =S24*1.0557 -> 30.6153 | U24: =IF(ISBLANK(M24),"0",T24*11.05+209.677) -> 547.97607 | V24: 74742 | W24: 36 | X24: =IF(ISBLANK(V24),"0 ",W24*284.345) -> 10236.42 | Y24: =X24*0.3449 -> 3530.5413 | Z24: =IF(ISBLANK(V24),"0",1570*1608.73/12/31*0.65) -> 4413.1961 | AA24: =Y24+Z24 -> 7943.7374 | AB24: 202037 | AC24: =IF(ISBLANK(AB24),"0 ",AB24-AB23) -> 12925 | AD24: 0.7937 | AE24: 309 | AF24: 20190 | AG24: =IF(ISBLANK(V24)," ",AF24-AF23) -> 9 | AH24: 14386215 | AI24: =IF(ISBLANK(AH24),"0",AH24-AH23) -> 4736 | AJ24: =AI24*0.2 -> 947.2 | AK24: 6613407 | AL24: =IF(ISBLANK(AK24),"0",AK24-AK23) -> 2102 | AM24: =AL24*0.2 -> 420.4 | AN24: 218318 | AO24: =IF(ISBLANK(AN24),"0",AN24-AN23) -> 381 | AP24: =AO24*0.2 -> 76.2 | AQ24: 7818 | AR24: =IF(ISBLANK(AQ24),"0",AQ24-AQ23) -> 5 | AS24: =AR24*7.84 -> 39.2 | AT24: 3084 | AU24: =IF(ISBLANK(AT24),"0",AT24-AT23) -> 2 | AV24: =AU24*7.84 -> 15.68 | AW24: 60 | AX24: =IF(ISBLANK(AW24),"0",AW24-AW23) -> 1 | AY24: =AX24*7.84 -> 7.84
A25: 45586 | B25: 20458556 | C25: =IF(ISBLANK(B25),"0",B25-B24) -> 7471 | D25: 21202387 | E25: =IF(ISBLANK(D25),"0",D25-D24) -> 6568 | F25: 474458 | G25: =IF(ISBLANK(F25),"0",F25-F24) -> 123 | H25: =C25+E25+G25 -> 14162 | I25: =H25*0.2 -> 2832.4 | J25: 98684 | K25: =IF(ISBLANK(J25),"0",J25-J24) -> 63 | L25: =K25*7.84 -> 493.92 | M25: 39228 | N25: =IF(ISBLANK(M25),"0",M25-M24) -> 19 | O25: 23343 | P25: =IF(ISBLANK(O25),"0",O25-O24) -> 16 | Q25: =N25+P25 -> 35 | R25: 58674 | S25: =IF(ISBLANK(R25),"0",R25-R24) -> 35 | T25: =S25*1.0557 -> 36.9495 | U25: =IF(ISBLANK(M25),"0",T25*11.05+209.677) -> 617.96898 | V25: 74796 | W25: 36 | X25: =IF(ISBLANK(V25),"0 ",W25*284.345) -> 10236.42 | Y25: =X25*0.3449 -> 3530.5413 | Z25: =IF(ISBLANK(V25),"0",1570*1608.73/12/31*0.65) -> 4413.1961 | AA25: =Y25+Z25 -> 7943.7374 | AB25: 215172 | AC25: =IF(ISBLANK(AB25),"0 ",AB25-AB24) -> 13135 | AD25: 0.8159 | AE25: 289 | AF25: 20200 | AG25: =IF(ISBLANK(V25)," ",AF25-AF24) -> 10 | AH25: 14391881 | AI25: =IF(ISBLANK(AH25),"0",AH25-AH24) -> 5666 | AJ25: =AI25*0.2 -> 1133.2 | AK25: 6615616 | AL25: =IF(ISBLANK(AK25),"0",AK25-AK24) -> 2209 | AM25: =AL25*0.2 -> 441.8 | AN25: 218692 | AO25: =IF(ISBLANK(AN25),"0",AN25-AN24) -> 374 | AP25: =AO25*0.2 -> 74.8 | AQ25: 7822 | AR25: =IF(ISBLANK(AQ25),"0",AQ25-AQ24) -> 4 | AS25: =AR25*7.84 -> 31.36 | AT25: 3084 | AU25: =IF(ISBLANK(AT25),"0",AT25-AT24) -> 0 | AV25: =AU25*7.84 -> 0 | AW25: 61 | AX25: =IF(ISBLANK(AW25),"0",AW25-AW24) -> 1 | AY25: =AX25*7.84 -> 7.84
A26: 45587 | B26: 20466011 | C26: =IF(ISBLANK(B26),"0",B26-B25) -> 7455 | D26: 21209000 | E26: =IF(ISBLANK(D26),"0",D26-D25) -> 6613 | F26: 474594 | G26: =IF(ISBLANK(F26),"0",F26-F25) -> 136 | H26: =C26+E26+G26 -> 14204 | I26: =H26*0.2 -> 2840.8 | J26: 98782 | K26: =IF(ISBLANK(J26),"0",J26-J25) -> 98 | L26: =K26*7.84 -> 768.32 | M26: 39250 | N26: =IF(ISBLANK(M26),"0",M26-M25) -> 22 | O26: 23358 | P26: =IF(ISBLANK(O26),"0",O26-O25) -> 15 | Q26: =N26+P26 -> 37 | R26: 58710 | S26: =IF(ISBLANK(R26),"0",R26-R25) -> 36 | T26: =S26*1.0557 -> 38.0052 | U26: =IF(ISBLANK(M26),"0",T26*11.05+209.677) -> 629.63446 | V26: 74849 | W26: 35 | X26: =IF(ISBLANK(V26),"0 ",W26*284.345) -> 9952.075 | Y26: =X26*0.3449 -> 3432.4707 | Z26: =IF(ISBLANK(V26),"0",1570*1608.73/12/31*0.65) -> 4413.1961 | AA26: =Y26+Z26 -> 7845.6668 | AB26: 227923 | AC26: =IF(ISBLANK(AB26),"0 ",AB26-AB25) -> 12751 | AD26: 1 | AE26: 371 | AF26: 20210 | AG26: =IF(ISBLANK(V26)," ",AF26-AF25) -> 10 | AH26: 14397635 | AI26: =IF(ISBLANK(AH26),"0",AH26-AH25) -> 5754 | AJ26: =AI26*0.2 -> 1150.8 | AK26: 6617824 | AL26: =IF(ISBLANK(AK26),"0",AK26-AK25) -> 2208 | AM26: =AL26*0.2 -> 441.6 | AN26: 218961 | AO26: =IF(ISBLANK(AN26),"0",AN26-AN25) -> 269 | AP26: =AO26*0.2 -> 53.8 | AQ26: 7834 | AR26: =IF(ISBLANK(AQ26),"0",AQ26-AQ25) -> 12 | AS26: =AR26*7.84 -> 94.08 | AT26: 3085 | AU26: =IF(ISBLANK(AT26),"0",AT26-AT25) -> 1 | AV26: =AU26*7.84 -> 7.84 | AW26: 62 | AX26: =IF(ISBLANK(AW26),"0",AW26-AW25) -> 1 | AY26: =AX26*7.84 -> 7.84
A27: 45588 | B27: 20473539 | C27: =IF(ISBLANK(B27),"0",B27-B26) -> 7528 | D27: 21215751 | E27: =IF(ISBLANK(D27),"0",D27-D26) -> 6751 | F27: 474732 | G27: =IF(ISBLANK(F27),"0",F27-F26) -> 138 | H27: =C27+E27+G27 -> 14417 | I27: =H27*0.2 -> 2883.4 | J27: 98881 | K27: =IF(ISBLANK(J27),"0",J27-J26) -> 99 | L27: =K27*7.84 -> 776.16 | M27: 39271 | N27: =IF(ISBLANK(M27),"0",M27-M26) -> 21 | O27: 23373 | P27: =IF(ISBLANK(O27),"0",O27-O26) -> 15 | Q27: =N27+P27 -> 36 | R27: 58745 | S27: =IF(ISBLANK(R27),"0",R27-R26) -> 35 | T27: =S27*1.0557 -> 36.9495 | U27: =IF(ISBLANK(M27),"0",T27*11.05+209.677) -> 617.96898 | V27: 74898 | W27: 33 | X27: =IF(ISBLANK(V27),"0 ",W27*284.345) -> 9383.385 | Y27: =X27*0.3449 -> 3236.3295 | Z27: =IF(ISBLANK(V27),"0",1570*1608.73/12/31*0.65) -> 4413.1961 | AA27: =Y27+Z27 -> 7649.5256 | AB27: 240101 | AC27: =IF(ISBLANK(AB27),"0 ",AB27-AB26) -> 12178 | AD27: 0.9587 | AE27: 363 | AF27: 20220 | AG27: =IF(ISBLANK(V27)," ",AF27-AF26) -> 10 | AH27: 14403426 | AI27: =IF(ISBLANK(AH27),"0",AH27-AH26) -> 5791 | AJ27: =AI27*0.2 -> 1158.2 | AK27: 6620061 | AL27: =IF(ISBLANK(AK27),"0",AK27-AK26) -> 2237 | AM27: =AL27*0.2 -> 447.4 | AN27: 219423 | AO27: =IF(ISBLANK(AN27),"0",AN27-AN26) -> 462 | AP27: =AO27*0.2 -> 92.4 | AQ27: 7843 | AR27: =IF(ISBLANK(AQ27),"0",AQ27-AQ26) -> 9 | AS27: =AR27*7.84 -> 70.56 | AT27: 3086 | AU27: =IF(ISBLANK(AT27),"0",AT27-AT26) -> 1 | AV27: =AU27*7.84 -> 7.84 | AW27: 63 | AX27: =IF(ISBLANK(AW27),"0",AW27-AW26) -> 1 | AY27: =AX27*7.84 -> 7.84
A28: 45589 | B28: 20481082 | C28: =IF(ISBLANK(B28),"0",B28-B27) -> 7543 | D28: 21222538 | E28: =IF(ISBLANK(D28),"0",D28-D27) -> 6787 | F28: 474871 | G28: =IF(ISBLANK(F28),"0",F28-F27) -> 139 | H28: =C28+E28+G28 -> 14469 | I28: =H28*0.2 -> 2893.8 | J28: 98987 | K28: =IF(ISBLANK(J28),"0",J28-J27) -> 106 | L28: =K28*7.84 -> 831.04 | M28: 39289 | N28: =IF(ISBLANK(M28),"0",M28-M27) -> 18 | O28: 23388 | P28: =IF(ISBLANK(O28),"0",O28-O27) -> 15 | Q28: =N28+P28 -> 33 | R28: 58779 | S28: =IF(ISBLANK(R28),"0",R28-R27) -> 34 | T28: =S28*1.0557 -> 35.8938 | U28: =IF(ISBLANK(M28),"0",T28*11.05+209.677) -> 606.30349 | V28: 74943 | W28: 33 | X28: =IF(ISBLANK(V28),"0 ",W28*284.345) -> 9383.385 | Y28: =X28*0.3449 -> 3236.3295 | Z28: =IF(ISBLANK(V28),"0",1570*1608.73/12/31*0.65) -> 4413.1961 | AA28: =Y28+Z28 -> 7649.5256 | AB28: 252218 | AC28: =IF(ISBLANK(AB28),"0 ",AB28-AB27) -> 12117 | AD28: 0.9968 | AE28: 397 | AF28: 20230 | AG28: =IF(ISBLANK(V28)," ",AF28-AF27) -> 10 | AH28: 14409275 | AI28: =IF(ISBLANK(AH28),"0",AH28-AH27) -> 5849 | AJ28: =AI28*0.2 -> 1169.8 | AK28: 6622312 | AL28: =IF(ISBLANK(AK28),"0",AK28-AK27) -> 2251 | AM28: =AL28*0.2 -> 450.2 | AN28: 219887 | AO28: =IF(ISBLANK(AN28),"0",AN28-AN27) -> 464 | AP28: =AO28*0.2 -> 92.8 | AQ28: 7851 | AR28: =IF(ISBLANK(AQ28),"0",AQ28-AQ27) -> 8 | AS28: =AR28*7.84 -> 62.72 | AT28: 3086 | AU28: =IF(ISBLANK(AT28),"0",AT28-AT27) -> 0 | AV28: =AU28*7.84 -> 0 | AW28: 63 | AX28: =IF(ISBLANK(AW28),"0",AW28-AW27) -> 0 | AY28: =AX28*7.84 -> 0
A29: 45590 | B29: 20488536 | C29: =IF(ISBLANK(B29),"0",B29-B28) -> 7454 | D29: 21229129 | E29: =IF(ISBLANK(D29),"0",D29-D28) -> 6591 | F29: 475000 | G29: =IF(ISBLANK(F29),"0",F29-F28) -> 129 | H29: =C29+E29+G29 -> 14174 | I29: =H29*0.2 -> 2834.8 | J29: 99084 | K29: =IF(ISBLANK(J29),"0",J29-J28) -> 97 | L29: =K29*7.84 -> 760.48 | M29: 39309 | N29: =IF(ISBLANK(M29),"0",M29-M28) -> 20 | O29: 23403 | P29: =IF(ISBLANK(O29),"0",O29-O28) -> 15 | Q29: =N29+P29 -> 35 | R29: 58813 | S29: =IF(ISBLANK(R29),"0",R29-R28) -> 34 | T29: =S29*1.0557 -> 35.8938 | U29: =IF(ISBLANK(M29),"0",T29*11.05+209.677) -> 606.30349 | V29: 74983 | W29: 33 | X29: =IF(ISBLANK(V29),"0 ",W29*284.345) -> 9383.385 | Y29: =X29*0.3449 -> 3236.3295 | Z29: =IF(ISBLANK(V29),"0",1570*1608.73/12/31*0.65) -> 4413.1961 | AA29: =Y29+Z29 -> 7649.5256 | AB29: 264380 | AC29: =IF(ISBLANK(AB29),"0 ",AB29-AB28) -> 12162 | AD29: 0.9587 | AE29: 383 | AF29: 20240 | AG29: =IF(ISBLANK(V29)," ",AF29-AF28) -> 10 | AH29: 14414736 | AI29: =IF(ISBLANK(AH29),"0",AH29-AH28) -> 5461 | AJ29: =AI29*0.2 -> 1092.2 | AK29: 6624509 | AL29: =IF(ISBLANK(AK29),"0",AK29-AK28) -> 2197 | AM29: =AL29*0.2 -> 439.4 | AN29: 220248 | AO29: =IF(ISBLANK(AN29),"0",AN29-AN28) -> 361 | AP29: =AO29*0.2 -> 72.2 | AQ29: 7859 | AR29: =IF(ISBLANK(AQ29),"0",AQ29-AQ28) -> 8 | AS29: =AR29*7.84 -> 62.72 | AT29: 3087 | AU29: =IF(ISBLANK(AT29),"0",AT29-AT28) -> 1 | AV29: =AU29*7.84 -> 7.84 | AW29: 64 | AX29: =IF(ISBLANK(AW29),"0",AW29-AW28) -> 1 | AY29: =AX29*7.84 -> 7.84
A30: 45591 | B30: 20496046 | C30: =IF(ISBLANK(B30),"0",B30-B29) -> 7510 | D30: 21235912 | E30: =IF(ISBLANK(D30),"0",D30-D29) -> 6783 | F30: 475138 | G30: =IF(ISBLANK(F30),"0",F30-F29) -> 138 | H30: =C30+E30+G30 -> 14431 | I30: =H30*0.2 -> 2886.2 | J30: 99188 | K30: =IF(ISBLANK(J30),"0",J30-J29) -> 104 | L30: =K30*7.84 -> 815.36 | M30: 39332 | N30: =IF(ISBLANK(M30),"0",M30-M29) -> 23 | O30: 23418 | P30: =IF(ISBLANK(O30),"0",O30-O29) -> 15 | Q30: =N30+P30 -> 38 | R30: 58850 | S30: =IF(ISBLANK(R30),"0",R30-R29) -> 37 | T30: =S30*1.0557 -> 39.0609 | U30: =IF(ISBLANK(M30),"0",T30*11.05+209.677) -> 641.29995 | V30: 75020 | W30: 34 | X30: =IF(ISBLANK(V30),"0 ",W30*284.345) -> 9667.73 | Y30: =X30*0.3449 -> 3334.4001 | Z30: =IF(ISBLANK(V30),"0",1570*1608.73/12/31*0.65) -> 4413.1961 | AA30: =Y30+Z30 -> 7747.5962 | AB30: 276310 | AC30: =IF(ISBLANK(AB30),"0 ",AB30-AB29) -> 11930 | AD30: 0.9841 | AE30: 413 | AF30: 20248 | AG30: =IF(ISBLANK(V30)," ",AF30-AF29) -> 8 | AH30: 14419405 | AI30: =IF(ISBLANK(AH30),"0",AH30-AH29) -> 4669 | AJ30: =AI30*0.2 -> 933.8 | AK30: 6626615 | AL30: =IF(ISBLANK(AK30),"0",AK30-AK29) -> 2106 | AM30: =AL30*0.2 -> 421.2 | AN30: 220687 | AO30: =IF(ISBLANK(AN30),"0",AN30-AN29) -> 439 | AP30: =AO30*0.2 -> 87.8 | AQ30: 7870 | AR30: =IF(ISBLANK(AQ30),"0",AQ30-AQ29) -> 11 | AS30: =AR30*7.84 -> 86.24 | AT30: 3087 | AU30: =IF(ISBLANK(AT30),"0",AT30-AT29) -> 0 | AV30: =AU30*7.84 -> 0 | AW30: 64 | AX30: =IF(ISBLANK(AW30),"0",AW30-AW29) -> 0 | AY30: =AX30*7.84 -> 0
A31: 45592 | B31: 20503480 | C31: =IF(ISBLANK(B31),"0",B31-B30) -> 7434 | D31: 21242506 | E31: =IF(ISBLANK(D31),"0",D31-D30) -> 6594 | F31: 475275 | G31: =IF(ISBLANK(F31),"0",F31-F30) -> 137 | H31: =C31+E31+G31 -> 14165 | I31: =H31*0.2 -> 2833 | J31: 99292 | K31: =IF(ISBLANK(J31),"0",J31-J30) -> 104 | L31: =K31*7.84 -> 815.36 | M31: 39353 | N31: =IF(ISBLANK(M31),"0",M31-M30) -> 21 | O31: 23431 | P31: =IF(ISBLANK(O31),"0",O31-O30) -> 13 | Q31: =N31+P31 -> 34 | R31: 58884 | S31: =IF(ISBLANK(R31),"0",R31-R30) -> 34 | T31: =S31*1.0557 -> 35.8938 | U31: =IF(ISBLANK(M31),"0",T31*11.05+209.677) -> 606.30349 | V31: 75056 | W31: 31 | X31: =IF(ISBLANK(V31),"0 ",W31*284.345) -> 8814.695 | Y31: =X31*0.3449 -> 3040.1883 | Z31: =IF(ISBLANK(V31),"0",1570*1608.73/12/31*0.65) -> 4413.1961 | AA31: =Y31+Z31 -> 7453.3844 | AB31: 287389 | AC31: =IF(ISBLANK(AB31),"0 ",AB31-AB30) -> 11079 | AD31: 0.9302 | AE31: 379 | AF31: 20256 | AG31: =IF(ISBLANK(V31)," ",AF31-AF30) -> 8 | AH31: 14424101 | AI31: =IF(ISBLANK(AH31),"0",AH31-AH30) -> 4696 | AJ31: =AI31*0.2 -> 939.2 | AK31: 6628726 | AL31: =IF(ISBLANK(AK31),"0",AK31-AK30) -> 2111 | AM31: =AL31*0.2 -> 422.2 | AN31: 221012 | AO31: =IF(ISBLANK(AN31),"0",AN31-AN30) -> 325 | AP31: =AO31*0.2 -> 65 | AQ31: 7879 | AR31: =IF(ISBLANK(AQ31),"0",AQ31-AQ30) -> 9 | AS31: =AR31*7.84 -> 70.56 | AT31: 3089 | AU31: =IF(ISBLANK(AT31),"0",AT31-AT30) -> 2 | AV31: =AU31*7.84 -> 15.68 | AW31: 65 | AX31: =IF(ISBLANK(AW31),"0",AW31-AW30) -> 1 | AY31: =AX31*7.84 -> 7.84
... A35: 45596 | B35: 20534305 | C35: =IF(ISBLANK(B35),"0",B35-B34) -> 7758 | D35: 21270163 | E35: =IF(ISBLANK(D35),"0",D35-D34) -> 6840 | F35: 475831 | G35: =IF(ISBLANK(F35),"0",F35-F34) -> 138 | H35: =C35+E35+G35 -> 14736 | I35: =H35*0.2 -> 2947.2 | J35: 99696 | K35: =IF(ISBLANK(J35),"0",J35-J34) -> 95 | L35: =K35*7.84 -> 744.8 | M35: 39438 | N35: =IF(ISBLANK(M35),"0",M35-M34) -> 19 | O35: 23487 | P35: =IF(ISBLANK(O35),"0",O35-O34) -> 15 | Q35: =N35+P35 -> 34 | R35: 59024 | S35: =IF(ISBLANK(R35),"0",R35-R34) -> 34 | T35: =S35*1.0557 -> 35.8938 | U35: =IF(ISBLANK(M35),"0",T35*11.05+209.677) -> 606.30349 | V35: 75187 | W35: 32 | X35: =IF(ISBLANK(V35),"0 ",W35*284.345) -> 9099.04 | Y35: =X35*0.3449 -> 3138.2589 | Z35: =IF(ISBLANK(V35),"0",1570*1608.73/12/31*0.65) -> 4413.1961 | AA35: =Y35+Z35 -> 7551.455 | AB35: 329283 | AC35: =IF(ISBLANK(AB35),"0 ",AB35-AB34) -> 10378 | AD35: 0.7841 | AE35: 311 | AF35: 20291 | AG35: =IF(ISBLANK(V35)," ",AF35-AF34) -> 9 | AH35: 14446856 | AI35: =IF(ISBLANK(AH35),"0",AH35-AH34) -> 5685 | AJ35: =AI35*0.2 -> 1137 | AK35: 6637643 | AL35: =IF(ISBLANK(AK35),"0",AK35-AK34) -> 2232 | AM35: =AL35*0.2 -> 446.4 | AN35: 222296 | AO35: =IF(ISBLANK(AN35),"0",AN35-AN34) -> 369 | AP35: =AO35*0.2 -> 73.8 | AQ35: 7907 | AR35: =IF(ISBLANK(AQ35),"0",AQ35-AQ34) -> 6 | AS35: =AR35*7.84 -> 47.04 | AT35: 3092 | AU35: =IF(ISBLANK(AT35),"0",AT35-AT34) -> 0 | AV35: =AU35*7.84 -> 0 | AW35: 70 | AX35: =IF(ISBLANK(AW35),"0",AW35-AW34) -> 1 | AY35: =AX35*7.84 -> 7.84
C36: =SUM(C5:C35) -> 236525 | E36: =SUM(E5:E35) -> 212413 | G36: =SUM(G5:G35) -> 4145 | H36: =SUM(H5:H35) -> 453083 | I36: =H36*0.2 -> 90616.6 | K36: =SUM(K5:K35) -> 2987 | L36: =K36*7.84 -> 23418.08 | N36: =SUM(N5:N35) -> 651 | P36: =SUM(P5:P35) -> 440 | Q36: =SUM(Q5:Q35) -> 1091 | S36: =SUM(S5:S35) -> 1070 | T36: =SUM(T5:T35) -> 1129.599 | U36: =SUM(U5:U35) -> 18982.056 | W36: =SUM(W5:W35) -> 1043 | X36: =SUM(X5:X35) -> 296571.84 | Y36: =SUM(Y5:Y35) -> 102287.63 | Z36: =SUM(Z5:Z35) -> 136809.08 | AA36: =SUM(AA5:AA35) -> 239096.71 | AC36: =SUM(AC5:AC35) -> 363359 | AD36: =AVERAGE(AD5:AD35) -> 0.85069677 | AE36: =SUM(AE5:AE35) -> 10520 | AG36: =SUM(AG5:AG35) -> 143 | AI36: =SUM(AI5:AI35) -> 169096 | AJ36: =SUM(AJ5:AJ35) -> 33819.2 | AL36: =SUM(AL5:AL35) -> 67463 | AM36: =SUM(AM5:AM35) -> 13492.6 | AO36: =SUM(AO5:AO35) -> 17372 | AP36: =SUM(AP5:AP35) -> 3474.4 | AR36: =SUM(AR5:AR35) -> 231 | AS36: =SUM(AS5:AS35) -> 1811.04 | AU36: =SUM(AU5:AU35) -> 25 | AV36: =SUM(AV5:AV35) -> 196 | AX36: =SUM(AX5:AX35) -> 27 | AY36: =SUM(AY5:AY35) -> 211.68
V37: AVT Charges should be Zero in the DC invoice - Please notify if not
B38: Electricity | D38: AED | G38: KW | J38: Water | L38: AED | M38: M3 | O38: Gas | R38: AED | T38: M3 | V38: Chilled Water | X38: AED | Z38: Ton Hour | AG38: =(131547.55*7)+(135620.99)+(136809.08*2) -> 1330072 | AH38: CHW Fixed Charges YTD 2024
B39: Actual October 2024 | D39: =I36 -> 90616.6 | G39: =D39/0.2 -> 453083 | J39: =B39 -> Actual October 2024 | L39: =L36 -> 23418.08 | M39: =K36 -> 2987 | O39: =B39 -> Actual October 2024 | R39: =U36 -> 18982.056 | T39: =T36 -> 1129.599 | V39: =B39 -> Actual October 2024 | X39: =AA36 -> 239096.71 | Z39: =X36 -> 296571.84 | AD39: =AC36 -> 363359 | AE39: =AD39-X36 -> 66787.165 | AG39: =(126488.42*7)+(130404.97)+(131547.55*2) -> 1278919 | AH39: CHW Fixed Charges YTD 2023
B40: Budget October 2024 | D40: 98138.25 | G40: =D40/0.2 -> 490691.25 | J40: =B40 -> Budget October 2024 | L40: 26702.45 | M40: =L40/7.84 -> 3405.9248 | O40: =B40 -> Budget October 2024 | R40: 21382.731 | T40: =(R40-6500)/11.05 -> 1346.8535 | V40: =B40 -> Budget October 2024 | X40: 243486.88 | Z40: =AG40/0.3449 -> 324555.9 | AG40: =X40-131547.55 -> 111939.33 | AH40: CHW Consumption Charges (Budgeted 2024 MTD)
B41: Actual October 2023 | D41: 94810.2 | G41: =D41/0.2 -> 474051 | J41: =B41 -> Actual October 2023 | L41: 22430.24 | M41: =L41/7.84 -> 2861 | O41: =B41 -> Actual October 2023 | R41: 18185.52 | T41: =(R41-6500)/11.05 -> 1057.5131 | V41: =B41 -> Actual October 2023 | X41: 236614.51 | Z41: =AG41/0.3442 -> 319947.97 | AG41: =X41-126488.42 -> 110126.09 | AH41: CHW Consumption Charges (Actual 2023 MTD)
B42: Actual YTD 2024 | D42: =D39+787483.6 -> 878100.2 | G42: =D42/0.2 -> 4390501 | J42: =B42 -> Actual YTD 2024 | L42: =L39+218469.44 -> 241887.52 | M42: =L42/7.84 -> 30853 | O42: =B42 -> Actual YTD 2024 | R42: =R39+164022.83 -> 183004.89 | T42: =(R42-6500*10)/11.05 -> 10679.175 | V42: =B42 -> Actual YTD 2024 | X42: =X39+1987394.45 -> 2226491.2 | Z42: =AG42/0.3449 -> 2599069.7 | AG42: =X42-AG38 -> 896419.16 | AH42: CHW Consumption Charges (Actual 2024 YTD)
B43: Budget YTD 2024 | D43: =D40+863005.5 -> 961143.75 | G43: =D43/0.2 -> 4805718.8 | J43: =B43 -> Budget YTD 2024 | L43: =L40+220311.93 -> 247014.38 | M43: =L43/7.84 -> 31506.936 | O43: =B43 -> Budget YTD 2024 | R43: =R40+164069.23 -> 185451.96 | T43: =(R43-6500*10)/11.05 -> 10900.63 | V43: =B43 -> Budget YTD 2024 | X43: =X40+1991025.48 -> 2234512.4 | Z43: =AG43/0.3449 -> 2622326.4 | AG43: =X43-AG38 -> 904440.36 | AH43: CHW Consumption Charges (Budgeted 2024 YTD)
...
