Workbook

Sheet Total
A1: Site Name | B1: Day | C1: Month | D1: Year | E1: Total Electricity Kwh | F1: Electricity Tariff ($/Kwh) | G1: Natural Gas (m3) | H1: Natural Gas $/m3 | I1: Water Utility Supply (m3) m3 | J1: Water Utility Supply (m3) $/m3 | K1: District Energy Cooling RTH | L1: District Energy Cooling $/RTH | M1: Room Nights | N1: Total Guests
A2: Pearl Rotana Capital Centre | B2: 1 | C2: 12 | D2: 2024 | E2: =Submetering!E2+Submetering!F2+Submetering!G2 -> 15360 | F2: 0.2 | G2: ='Dec 2024'!T5 -> 32.7267 | H2: 16.76 | I2: =Submetering!H2 -> 112 | J2: 7.84 | K2: ='Dec 2024'!X5 -> 6539.935 | L2: 0.3449 | M2: =Submetering!N2 -> 265.986 | N2: =Submetering!O2 -> 431
A3: Pearl Rotana Capital Centre | B3: =B2+1 -> 2 | C3: 12 | D3: 2024 | E3: =Submetering!E3+Submetering!F3+Submetering!G3 -> 15751 | F3: 0.2 | G3: ='Dec 2024'!T6 -> 34.8381 | H3: 16.76 | I3: =Submetering!H3 -> 103 | J3: 7.84 | K3: ='Dec 2024'!X6 -> 5971.245 | L3: 0.3449 | M3: =Submetering!N3 -> 253.9845 | N3: =Submetering!O3 -> 348
A4: Pearl Rotana Capital Centre | B4: =B3+1 -> 3 | C4: 12 | D4: 2024 | E4: =Submetering!E4+Submetering!F4+Submetering!G4 -> 15311 | F4: 0.2 | G4: ='Dec 2024'!T7 -> 33.7824 | H4: 16.76 | I4: =Submetering!H4 -> 98 | J4: 7.84 | K4: ='Dec 2024'!X7 -> 5971.245 | L4: 0.3449 | M4: =Submetering!N4 -> 264.0015 | N4: =Submetering!O4 -> 329
A5: Pearl Rotana Capital Centre | B5: =B4+1 -> 4 | C5: 12 | D5: 2024 | E5: =Submetering!E5+Submetering!F5+Submetering!G5 -> 14893 | F5: 0.2 | G5: ='Dec 2024'!T8 -> 33.7824 | H5: 16.76 | I5: =Submetering!H5 -> 95 | J5: 7.84 | K5: ='Dec 2024'!X8 -> 5971.245 | L5: 0.3449 | M5: =Submetering!N5 -> 281.0115 | N5: =Submetering!O5 -> 331
A6: Pearl Rotana Capital Centre | B6: =B5+1 -> 5 | C6: 12 | D6: 2024 | E6: =Submetering!E6+Submetering!F6+Submetering!G6 -> 15089 | F6: 0.2 | G6: ='Dec 2024'!T9 -> 34.8381 | H6: 16.76 | I6: =Submetering!H6 -> 103 | J6: 7.84 | K6: ='Dec 2024'!X9 -> 5971.245 | L6: 0.3449 | M6: =Submetering!N6 -> 306.999 | N6: =Submetering!O6 -> 391
A7: Pearl Rotana Capital Centre | B7: =B6+1 -> 6 | C7: 12 | D7: 2024 | E7: =Submetering!E7+Submetering!F7+Submetering!G7 -> 15072 | F7: 0.2 | G7: ='Dec 2024'!T10 -> 35.8938 | H7: 16.76 | I7: =Submetering!H7 -> 88 | J7: 7.84 | K7: ='Dec 2024'!X10 -> 6824.28 | L7: 0.3449 | M7: =Submetering!N7 -> 305.0145 | N7: =Submetering!O7 -> 421
A8: Pearl Rotana Capital Centre | B8: =B7+1 -> 7 | C8: 12 | D8: 2024 | E8: =Submetering!E8+Submetering!F8+Submetering!G8 -> 14925 | F8: 0.2 | G8: ='Dec 2024'!T11 -> 33.7824 | H8: 16.76 | I8: =Submetering!H8 -> 106 | J8: 7.84 | K8: ='Dec 2024'!X11 -> 6255.59 | L8: 0.3449 | M8: =Submetering!N8 -> 274.995 | N8: =Submetering!O8 -> 378
A9: Pearl Rotana Capital Centre | B9: =B8+1 -> 8 | C9: 12 | D9: 2024 | E9: =Submetering!E9+Submetering!F9+Submetering!G9 -> 15251 | F9: 0.2 | G9: ='Dec 2024'!T12 -> 36.9495 | H9: 16.76 | I9: =Submetering!H9 -> 101 | J9: 7.84 | K9: ='Dec 2024'!X12 -> 6824.28 | L9: 0.3449 | M9: =Submetering!N9 -> 315 | N9: =Submetering!O9 -> 413
A10: Pearl Rotana Capital Centre | B10: =B9+1 -> 9 | C10: 12 | D10: 2024 | E10: =Submetering!E10+Submetering!F10+Submetering!G10 -> 15494 | F10: 0.2 | G10: ='Dec 2024'!T13 -> 36.9495 | H10: 16.76 | I10: =Submetering!H10 -> 112 | J10: 7.84 | K10: ='Dec 2024'!X13 -> 5686.9 | L10: 0.3449 | M10: =Submetering!N10 -> 315 | N10: =Submetering!O10 -> 384
A11: Pearl Rotana Capital Centre | B11: =B10+1 -> 10 | C11: 12 | D11: 2024 | E11: =Submetering!E11+Submetering!F11+Submetering!G11 -> 15105 | F11: 0.2 | G11: ='Dec 2024'!T14 -> 36.9495 | H11: 16.76 | I11: =Submetering!H11 -> 103 | J11: 7.84 | K11: ='Dec 2024'!X14 -> 5971.245 | L11: 0.3449 | M11: =Submetering!N11 -> 304.0065 | N11: =Submetering!O11 -> 378
A12: Pearl Rotana Capital Centre | B12: =B11+1 -> 11 | C12: 12 | D12: 2024 | E12: =Submetering!E12+Submetering!F12+Submetering!G12 -> 15173 | F12: 0.2 | G12: ='Dec 2024'!T15 -> 33.7824 | H12: 16.76 | I12: =Submetering!H12 -> 106 | J12: 7.84 | K12: ='Dec 2024'!X15 -> 6255.59 | L12: 0.3449 | M12: =Submetering!N12 -> 306.999 | N12: =Submetering!O12 -> 408
A13: Pearl Rotana Capital Centre | B13: =B12+1 -> 12 | C13: 12 | D13: 2024 | E13: =Submetering!E13+Submetering!F13+Submetering!G13 -> 15409 | F13: 0.2 | G13: ='Dec 2024'!T16 -> 34.8381 | H13: 16.76 | I13: =Submetering!H13 -> 94 | J13: 7.84 | K13: ='Dec 2024'!X16 -> 5402.555 | L13: 0.3449 | M13: =Submetering!N13 -> 258.993 | N13: =Submetering!O13 -> 366
A14: Pearl Rotana Capital Centre | B14: =B13+1 -> 13 | C14: 12 | D14: 2024 | E14: =Submetering!E14+Submetering!F14+Submetering!G14 -> 15672 | F14: 0.2 | G14: ='Dec 2024'!T17 -> 35.8938 | H14: 16.76 | I14: =Submetering!H14 -> 108 | J14: 7.84 | K14: ='Dec 2024'!X17 -> 6539.935 | L14: 0.3449 | M14: =Submetering!N14 -> 266.994 | N14: =Submetering!O14 -> 416
... A32: Pearl Rotana Capital Centre | B32: =B31+1 -> 31 | C32: 12 | D32: 2024 | E32: =Submetering!E32+Submetering!F32+Submetering!G32 -> 14926 | F32: 0.2 | G32: ='Dec 2024'!T35 -> 32.7267 | H32: 16.76 | I32: =Submetering!H32 -> 106 | J32: 7.84 | K32: ='Dec 2024'!X35 -> 6539.935 | L32: 0.3449 | M32: =Submetering!N32 -> 250.0155 | N32: =Submetering!O32 -> 386

Sheet Submetering
A1: Site Name | B1: Day | C1: Month | D1: Year | E1: MDB#2 | F1: MDB#3 | G1: MDB#1 Façade | H1: Water | I1: Gas Meter#1 GF Kitchen | J1: Gas Meter#2 1st floor Kitchen | K1: District Cooling | L1: District Cooling ETS | M1: Water Main Kitchen | N1: Room Nights | O1: Total Guests
A2: Pearl Rotana Capital Centre | B2: 1 | C2: 12 | D2: 2024 | E2: ='Dec 2024'!C5 -> 7715 | F2: ='Dec 2024'!E5 -> 7506 | G2: ='Dec 2024'!G5 -> 139 | H2: ='Dec 2024'!K5 -> 112 | I2: ='Dec 2024'!N5 -> 19 | J2: ='Dec 2024'!P5 -> 13 | K2: ='Dec 2024'!X5 -> 6539.935 | L2: ='Dec 2024'!AC5 -> 6825 | M2: ='Dec 2024'!AS5 -> 10 | N2: ='Dec 2024'!AE5*315 -> 265.986 | O2: ='Dec 2024'!AF5 -> 431
A3: Pearl Rotana Capital Centre | B3: =B2+1 -> 2 | C3: 12 | D3: 2024 | E3: ='Dec 2024'!C6 -> 7924 | F3: ='Dec 2024'!E6 -> 7682 | G3: ='Dec 2024'!G6 -> 145 | H3: ='Dec 2024'!K6 -> 103 | I3: ='Dec 2024'!N6 -> 19 | J3: ='Dec 2024'!P6 -> 15 | K3: ='Dec 2024'!X6 -> 5971.245 | L3: ='Dec 2024'!AC6 -> 6476 | M3: ='Dec 2024'!AS6 -> 9 | N3: ='Dec 2024'!AE6*315 -> 253.9845 | O3: ='Dec 2024'!AF6 -> 348
A4: Pearl Rotana Capital Centre | B4: =B3+1 -> 3 | C4: 12 | D4: 2024 | E4: ='Dec 2024'!C7 -> 7738 | F4: ='Dec 2024'!E7 -> 7427 | G4: ='Dec 2024'!G7 -> 146 | H4: ='Dec 2024'!K7 -> 98 | I4: ='Dec 2024'!N7 -> 20 | J4: ='Dec 2024'!P7 -> 13 | K4: ='Dec 2024'!X7 -> 5971.245 | L4: ='Dec 2024'!AC7 -> 6411 | M4: ='Dec 2024'!AS7 -> 6 | N4: ='Dec 2024'!AE7*315 -> 264.0015 | O4: ='Dec 2024'!AF7 -> 329
A5: Pearl Rotana Capital Centre | B5: =B4+1 -> 4 | C5: 12 | D5: 2024 | E5: ='Dec 2024'!C8 -> 7784 | F5: ='Dec 2024'!E8 -> 6966 | G5: ='Dec 2024'!G8 -> 143 | H5: ='Dec 2024'!K8 -> 95 | I5: ='Dec 2024'!N8 -> 21 | J5: ='Dec 2024'!P8 -> 12 | K5: ='Dec 2024'!X8 -> 5971.245 | L5: ='Dec 2024'!AC8 -> 6535 | M5: ='Dec 2024'!AS8 -> 5 | N5: ='Dec 2024'!AE8*315 -> 281.0115 | O5: ='Dec 2024'!AF8 -> 331
A6: Pearl Rotana Capital Centre | B6: =B5+1 -> 5 | C6: 12 | D6: 2024 | E6: ='Dec 2024'!C9 -> 7779 | F6: ='Dec 2024'!E9 -> 7173 | G6: ='Dec 2024'!G9 -> 137 | H6: ='Dec 2024'!K9 -> 103 | I6: ='Dec 2024'!N9 -> 20 | J6: ='Dec 2024'!P9 -> 14 | K6: ='Dec 2024'!X9 -> 5971.245 | L6: ='Dec 2024'!AC9 -> 6908 | M6: ='Dec 2024'!AS9 -> 6 | N6: ='Dec 2024'!AE9*315 -> 306.999 | O6: ='Dec 2024'!AF9 -> 391
A7: Pearl Rotana Capital Centre | B7: =B6+1 -> 6 | C7: 12 | D7: 2024 | E7: ='Dec 2024'!C10 -> 7634 | F7: ='Dec 2024'!E10 -> 7306 | G7: ='Dec 2024'!G10 -> 132 | H7: ='Dec 2024'!K10 -> 88 | I7: ='Dec 2024'!N10 -> 22 | J7: ='Dec 2024'!P10 -> 12 | K7: ='Dec 2024'!X10 -> 6824.28 | L7: ='Dec 2024'!AC10 -> 7498 | M7: ='Dec 2024'!AS10 -> 6 | N7: ='Dec 2024'!AE10*315 -> 305.0145 | O7: ='Dec 2024'!AF10 -> 421
A8: Pearl Rotana Capital Centre | B8: =B7+1 -> 7 | C8: 12 | D8: 2024 | E8: ='Dec 2024'!C11 -> 7579 | F8: ='Dec 2024'!E11 -> 7213 | G8: ='Dec 2024'!G11 -> 133 | H8: ='Dec 2024'!K11 -> 106 | I8: ='Dec 2024'!N11 -> 21 | J8: ='Dec 2024'!P11 -> 13 | K8: ='Dec 2024'!X11 -> 6255.59 | L8: ='Dec 2024'!AC11 -> 7317 | M8: ='Dec 2024'!AS11 -> 4 | N8: ='Dec 2024'!AE11*315 -> 274.995 | O8: ='Dec 2024'!AF11 -> 378
A9: Pearl Rotana Capital Centre | B9: =B8+1 -> 8 | C9: 12 | D9: 2024 | E9: ='Dec 2024'!C12 -> 7868 | F9: ='Dec 2024'!E12 -> 7241 | G9: ='Dec 2024'!G12 -> 142 | H9: ='Dec 2024'!K12 -> 101 | I9: ='Dec 2024'!N12 -> 20 | J9: ='Dec 2024'!P12 -> 16 | K9: ='Dec 2024'!X12 -> 6824.28 | L9: ='Dec 2024'!AC12 -> 7088 | M9: ='Dec 2024'!AS12 -> 8 | N9: ='Dec 2024'!AE12*315 -> 315 | O9: ='Dec 2024'!AF12 -> 413
A10: Pearl Rotana Capital Centre | B10: =B9+1 -> 9 | C10: 12 | D10: 2024 | E10: ='Dec 2024'!C13 -> 7931 | F10: ='Dec 2024'!E13 -> 7415 | G10: ='Dec 2024'!G13 -> 148 | H10: ='Dec 2024'!K13 -> 112 | I10: ='Dec 2024'!N13 -> 21 | J10: ='Dec 2024'!P13 -> 15 | K10: ='Dec 2024'!X13 -> 5686.9 | L10: ='Dec 2024'!AC13 -> 6552 | M10: ='Dec 2024'!AS13 -> 8 | N10: ='Dec 2024'!AE13*315 -> 315 | O10: ='Dec 2024'!AF13 -> 384
A11: Pearl Rotana Capital Centre | B11: =B10+1 -> 10 | C11: 12 | D11: 2024 | E11: ='Dec 2024'!C14 -> 7786 | F11: ='Dec 2024'!E14 -> 7183 | G11: ='Dec 2024'!G14 -> 136 | H11: ='Dec 2024'!K14 -> 103 | I11: ='Dec 2024'!N14 -> 21 | J11: ='Dec 2024'!P14 -> 15 | K11: ='Dec 2024'!X14 -> 5971.245 | L11: ='Dec 2024'!AC14 -> 6880 | M11: ='Dec 2024'!AS14 -> 6 | N11: ='Dec 2024'!AE14*315 -> 304.0065 | O11: ='Dec 2024'!AF14 -> 378
A12: Pearl Rotana Capital Centre | B12: =B11+1 -> 11 | C12: 12 | D12: 2024 | E12: ='Dec 2024'!C15 -> 7770 | F12: ='Dec 2024'!E15 -> 7267 | G12: ='Dec 2024'!G15 -> 136 | H12: ='Dec 2024'!K15 -> 106 | I12: ='Dec 2024'!N15 -> 21 | J12: ='Dec 2024'!P15 -> 13 | K12: ='Dec 2024'!X15 -> 6255.59 | L12: ='Dec 2024'!AC15 -> 6986 | M12: ='Dec 2024'!AS15 -> 8 | N12: ='Dec 2024'!AE15*315 -> 306.999 | O12: ='Dec 2024'!AF15 -> 408
A13: Pearl Rotana Capital Centre | B13: =B12+1 -> 12 | C13: 12 | D13: 2024 | E13: ='Dec 2024'!C16 -> 7794 | F13: ='Dec 2024'!E16 -> 7472 | G13: ='Dec 2024'!G16 -> 143 | H13: ='Dec 2024'!K16 -> 94 | I13: ='Dec 2024'!N16 -> 20 | J13: ='Dec 2024'!P16 -> 14 | K13: ='Dec 2024'!X16 -> 5402.555 | L13: ='Dec 2024'!AC16 -> 6592 | M13: ='Dec 2024'!AS16 -> 7 | N13: ='Dec 2024'!AE16*315 -> 258.993 | O13: ='Dec 2024'!AF16 -> 366
A14: Pearl Rotana Capital Centre | B14: =B13+1 -> 13 | C14: 12 | D14: 2024 | E14: ='Dec 2024'!C17 -> 7842 | F14: ='Dec 2024'!E17 -> 7690 | G14: ='Dec 2024'!G17 -> 140 | H14: ='Dec 2024'!K17 -> 108 | I14: ='Dec 2024'!N17 -> 20 | J14: ='Dec 2024'!P17 -> 14 | K14: ='Dec 2024'!X17 -> 6539.935 | L14: ='Dec 2024'!AC17 -> 7213 | M14: ='Dec 2024'!AS17 -> 9 | N14: ='Dec 2024'!AE17*315 -> 266.994 | O14: ='Dec 2024'!AF17 -> 416
... A32: Pearl Rotana Capital Centre | B32: =B31+1 -> 31 | C32: 12 | D32: 2024 | E32: ='Dec 2024'!C35 -> 7857 | F32: ='Dec 2024'!E35 -> 6922 | G32: ='Dec 2024'!G35 -> 147 | H32: ='Dec 2024'!K35 -> 106 | I32: ='Dec 2024'!N35 -> 18 | J32: ='Dec 2024'!P35 -> 13 | K32: ='Dec 2024'!X35 -> 6539.935 | L32: ='Dec 2024'!AC35 -> 6233 | M32: ='Dec 2024'!AS35 -> 5 | N32: ='Dec 2024'!AE35*315 -> 250.0155 | O32: ='Dec 2024'!AF35 -> 386

Sheet Dec 2024
A1: PEARL ROTANA CAPITAL CENTRE UTILITIES CONSUMPTION - DECEMBER 2024
A2: DATE | B2: Electricity | J2: Water | M2: SNG Gas | V2: District Cooling | AE2: Additional Info | AG2: Additional Meter
B3: MDB #2 | D3: MDB #3 | F3: MDB #1 Façade | H3: Total ELE Cons. KW | I3: Electricity AED | J3: Hotel Reading | K3: Water Cons. M3 | L3: Water AED | M3: Gas Meter #1 G Floor Kitchen | O3: Gas Meter #2 1st Floor Kitchen | Q3: Total Gas Cons. M3 | R3: PRS Meter Reading | S3: PRS Meter Cons. M3 | T3: Meter factor (1.05570) | U3: Gas AED | V3: Hotel BTU Meter Energy Reading | W3: District Cooling Cons. MWH | X3: District Cooling Cons. Ton Hour | Y3: District Cooling Cons. AED | Z3: District Cooling Fixed Charge | AA3: District Cooling Total AED | AB3: ETS Energy Bulk Meter Reading | AC3: ETS Cons. Ton Hours | AD3: ETS Cons. MWH | AE3: Hotel Occupancy % | AF3: Adl. & Chl. | AG3: Blue Sky tower Chilled water | AI3: Electricity MDB-1 | AL3: Electricity MDB-E | AO3: Electricity-MCC Panel Chilled water Secondary Pumps | AR3: Water - Main kitchen | AU3: Water - Swimming Pool | AX3: Water - Bottling Plant
B4: Reading | C4: Cons. | D4: Reading | E4: Cons. | F4: Reading | G4: Cons. | M4: Reading | N4: Cons. | O4: Reading | P4: Cons. | AG4: Meter Reading | AH4: Cons. MWH | AI4: Meter Reading | AJ4: Cons. KWH | AK4: AED | AL4: Meter Reading | AM4: Cons. KWH | AN4: AED | AO4: Meter Reading | AP4: Cons. KWH | AQ4: AED | AR4: Meter Reading | AS4: Cons. M3 | AT4: AED | AU4: Meter Reading | AV4: Cons. M3 | AW4: AED | AX4: Meter Reading | AY4: Cons. M3 | AZ4: AED
A5: 45627 | B5: 20773911 | C5: 7715 | D5: 21487112 | E5: 7506 | F5: 480105 | G5: 139 | H5: =C5+E5+G5 -> 15360 | I5: =H5*0.2 -> 3072 | J5: 102786 | K5: 112 | L5: =K5*7.84 -> 878.08 | M5: 40083 | N5: 19 | O5: 23913 | P5: 13 | Q5: =N5+P5 -> 32 | R5: 60035 | S5: 31 | T5: =S5*1.0557 -> 32.7267 | U5: =IF(ISBLANK(M5),"0",T5*11.05+209.67) -> 571.30003 | V5: 76113 | W5: 23 | X5: =IF(ISBLANK(V5),"0 ",W5*284.345) -> 6539.935 | Y5: =X5*0.3449 -> 2255.6236 | Z5: =IF(ISBLANK(V5),"0",1570*1608.73/12/31*0.65) -> 4413.1961 | AA5: =Y5+Z5 -> 6668.8197 | AB5: 622083 | AC5: 6825 | AD5: =IF(ISBLANK(V5),"0 ",AC5/284.345) -> 24.002532 | AE5: 0.8444 | AF5: 431 | AG5: 20522 | AH5: 5 | AI5: 14611395 | AJ5: 4351 | AK5: =AJ5*0.2 -> 870.2 | AL5: 6705496 | AM5: 2119 | AN5: =AM5*0.2 -> 423.8 | AO5: 229944 | AP5: 247 | AQ5: =AP5*0.2 -> 49.4 | AR5: 8170 | AS5: 10 | AT5: =AS5*7.84 -> 78.4 | AU5: 3123 | AV5: 1 | AW5: =AV5*7.84 -> 7.84 | AX5: 100 | AY5: 1 | AZ5: =AY5*7.84 -> 7.84
A6: 45628 | B6: 20781835 | C6: =IF(ISBLANK(B6),"0",B6-B5) -> 7924 | D6: 21494794 | E6: =IF(ISBLANK(D6),"0",D6-D5) -> 7682 | F6: 480250 | G6: =IF(ISBLANK(F6),"0",F6-F5) -> 145 | H6: =C6+E6+G6 -> 15751 | I6: =H6*0.2 -> 3150.2 | J6: 102889 | K6: =IF(ISBLANK(J6),"0",J6-J5) -> 103 | L6: =K6*7.84 -> 807.52 | M6: 40102 | N6: =IF(ISBLANK(M6),"0",M6-M5) -> 19 | O6: 23928 | P6: =IF(ISBLANK(O6),"0",O6-O5) -> 15 | Q6: =N6+P6 -> 34 | R6: 60068 | S6: =IF(ISBLANK(R6),"0",R6-R5) -> 33 | T6: =S6*1.0557 -> 34.8381 | U6: =IF(ISBLANK(M6),"0",T6*11.05+209.67) -> 594.63101 | V6: 76134 | W6: =IF(ISBLANK(V6),"0",V6-V5) -> 21 | X6: =IF(ISBLANK(V6),"0 ",W6*284.345) -> 5971.245 | Y6: =X6*0.3449 -> 2059.4824 | Z6: =IF(ISBLANK(V6),"0",1570*1608.73/12/31*0.65) -> 4413.1961 | AA6: =Y6+Z6 -> 6472.6785 | AB6: 628559 | AC6: =IF(ISBLANK(AB6),"0 ",AB6-AB5) -> 6476 | AD6: =IF(ISBLANK(V6),"0 ",AC6/284.345) -> 22.77515 | AE6: 0.8063 | AF6: 348 | AG6: 20526 | AH6: =IF(ISBLANK(V6),"0 ",AG6-AG5) -> 4 | AI6: 14615728 | AJ6: =IF(ISBLANK(AI6),"0",AI6-AI5) -> 4333 | AK6: =AJ6*0.2 -> 866.6 | AL6: 6707647 | AM6: =IF(ISBLANK(AL6),"0",AL6-AL5) -> 2151 | AN6: =AM6*0.2 -> 430.2 | AO6: 230131 | AP6: =IF(ISBLANK(AO6),"0",AO6-AO5) -> 187 | AQ6: =AP6*0.2 -> 37.4 | AR6: 8179 | AS6: =IF(ISBLANK(AR6),"0",AR6-AR5) -> 9 | AT6: =AS6*7.84 -> 70.56 | AU6: 3124 | AV6: =IF(ISBLANK(AU6),"0",AU6-AU5) -> 1 | AW6: =AV6*7.84 -> 7.84 | AX6: 101 | AY6: =IF(ISBLANK(AX6),"0",AX6-AX5) -> 1 | AZ6: =AY6*7.84 -> 7.84
A7: 45629 | B7: 20789573 | C7: =IF(ISBLANK(B7),"0",B7-B6) -> 7738 | D7: 21502221 | E7: =IF(ISBLANK(D7),"0",D7-D6) -> 7427 | F7: 480396 | G7: =IF(ISBLANK(F7),"0",F7-F6) -> 146 | H7: =C7+E7+G7 -> 15311 | I7: =H7*0.2 -> 3062.2 | J7: 102987 | K7: =IF(ISBLANK(J7),"0",J7-J6) -> 98 | L7: =K7*7.84 -> 768.32 | M7: 40122 | N7: =IF(ISBLANK(M7),"0",M7-M6) -> 20 | O7: 23941 | P7: =IF(ISBLANK(O7),"0",O7-O6) -> 13 | Q7: =N7+P7 -> 33 | R7: 60100 | S7: =IF(ISBLANK(R7),"0",R7-R6) -> 32 | T7: =S7*1.0557 -> 33.7824 | U7: =IF(ISBLANK(M7),"0",T7*11.05+209.67) -> 582.96552 | V7: 76155 | W7: =IF(ISBLANK(V7),"0",V7-V6) -> 21 | X7: =IF(ISBLANK(V7),"0 ",W7*284.345) -> 5971.245 | Y7: =X7*0.3449 -> 2059.4824 | Z7: =IF(ISBLANK(V7),"0",1570*1608.73/12/31*0.65) -> 4413.1961 | AA7: =Y7+Z7 -> 6472.6785 | AB7: 634970 | AC7: =IF(ISBLANK(AB7),"0 ",AB7-AB6) -> 6411 | AD7: =IF(ISBLANK(V7),"0 ",AC7/284.345) -> 22.546554 | AE7: 0.8381 | AF7: 329 | AG7: 20530 | AH7: =IF(ISBLANK(V7),"0 ",AG7-AG6) -> 4 | AI7: 14620129 | AJ7: =IF(ISBLANK(AI7),"0",AI7-AI6) -> 4401 | AK7: =AJ7*0.2 -> 880.2 | AL7: 6709732 | AM7: =IF(ISBLANK(AL7),"0",AL7-AL6) -> 2085 | AN7: =AM7*0.2 -> 417 | AO7: 230270 | AP7: =IF(ISBLANK(AO7),"0",AO7-AO6) -> 139 | AQ7: =AP7*0.2 -> 27.8 | AR7: 8185 | AS7: =IF(ISBLANK(AR7),"0",AR7-AR6) -> 6 | AT7: =AS7*7.84 -> 47.04 | AU7: 3125 | AV7: =IF(ISBLANK(AU7),"0",AU7-AU6) -> 1 | AW7: =AV7*7.84 -> 7.84 | AX7: 101 | AY7: =IF(ISBLANK(AX7),"0",AX7-AX6) -> 0 | AZ7: =AY7*7.84 -> 0
A8: 45630 | B8: 20797357 | C8: =IF(ISBLANK(B8),"0",B8-B7) -> 7784 | D8: 21509187 | E8: =IF(ISBLANK(D8),"0",D8-D7) -> 6966 | F8: 480539 | G8: =IF(ISBLANK(F8),"0",F8-F7) -> 143 | H8: =C8+E8+G8 -> 14893 | I8: =H8*0.2 -> 2978.6 | J8: 103082 | K8: =IF(ISBLANK(J8),"0",J8-J7) -> 95 | L8: =K8*7.84 -> 744.8 | M8: 40143 | N8: =IF(ISBLANK(M8),"0",M8-M7) -> 21 | O8: 23953 | P8: =IF(ISBLANK(O8),"0",O8-O7) -> 12 | Q8: =N8+P8 -> 33 | R8: 60132 | S8: =IF(ISBLANK(R8),"0",R8-R7) -> 32 | T8: =S8*1.0557 -> 33.7824 | U8: =IF(ISBLANK(M8),"0",T8*11.05+209.67) -> 582.96552 | V8: 76176 | W8: =IF(ISBLANK(V8),"0",V8-V7) -> 21 | X8: =IF(ISBLANK(V8),"0 ",W8*284.345) -> 5971.245 | Y8: =X8*0.3449 -> 2059.4824 | Z8: =IF(ISBLANK(V8),"0",1570*1608.73/12/31*0.65) -> 4413.1961 | AA8: =Y8+Z8 -> 6472.6785 | AB8: 641505 | AC8: =IF(ISBLANK(AB8),"0 ",AB8-AB7) -> 6535 | AD8: =IF(ISBLANK(V8),"0 ",AC8/284.345) -> 22.982644 | AE8: 0.8921 | AF8: 331 | AG8: 20536 | AH8: =IF(ISBLANK(V8),"0 ",AG8-AG7) -> 6 | AI8: 14625513 | AJ8: =IF(ISBLANK(AI8),"0",AI8-AI7) -> 5384 | AK8: =AJ8*0.2 -> 1076.8 | AL8: 6711920 | AM8: =IF(ISBLANK(AL8),"0",AL8-AL7) -> 2188 | AN8: =AM8*0.2 -> 437.6 | AO8: 230411 | AP8: =IF(ISBLANK(AO8),"0",AO8-AO7) -> 141 | AQ8: =AP8*0.2 -> 28.2 | AR8: 8190 | AS8: =IF(ISBLANK(AR8),"0",AR8-AR7) -> 5 | AT8: =AS8*7.84 -> 39.2 | AU8: 3126 | AV8: =IF(ISBLANK(AU8),"0",AU8-AU7) -> 1 | AW8: =AV8*7.84 -> 7.84 | AX8: 102 | AY8: =IF(ISBLANK(AX8),"0",AX8-AX7) -> 1 | AZ8: =AY8*7.84 -> 7.84
A9: 45631 | B9: 20805136 | C9: =IF(ISBLANK(B9),"0",B9-B8) -> 7779 | D9: 21516360 | E9: =IF(ISBLANK(D9),"0",D9-D8) -> 7173 | F9: 480676 | G9: =IF(ISBLANK(F9),"0",F9-F8) -> 137 | H9: =C9+E9+G9 -> 15089 | I9: =H9*0.2 -> 3017.8 | J9: 103185 | K9: =IF(ISBLANK(J9),"0",J9-J8) -> 103 | L9: =K9*7.84 -> 807.52 | M9: 40163 | N9: =IF(ISBLANK(M9),"0",M9-M8) -> 20 | O9: 23967 | P9: =IF(ISBLANK(O9),"0",O9-O8) -> 14 | Q9: =N9+P9 -> 34 | R9: 60165 | S9: =IF(ISBLANK(R9),"0",R9-R8) -> 33 | T9: =S9*1.0557 -> 34.8381 | U9: =IF(ISBLANK(M9),"0",T9*11.05+209.67) -> 594.63101 | V9: 76197 | W9: =IF(ISBLANK(V9),"0",V9-V8) -> 21 | X9: =IF(ISBLANK(V9),"0 ",W9*284.345) -> 5971.245 | Y9: =X9*0.3449 -> 2059.4824 | Z9: =IF(ISBLANK(V9),"0",1570*1608.73/12/31*0.65) -> 4413.1961 | AA9: =Y9+Z9 -> 6472.6785 | AB9: 648413 | AC9: =IF(ISBLANK(AB9),"0 ",AB9-AB8) -> 6908 | AD9: =IF(ISBLANK(V9),"0 ",AC9/284.345) -> 24.294431 | AE9: 0.9746 | AF9: 391 | AG9: 20541 | AH9: =IF(ISBLANK(V9),"0 ",AG9-AG8) -> 5 | AI9: 14631066 | AJ9: =IF(ISBLANK(AI9),"0",AI9-AI8) -> 5553 | AK9: =AJ9*0.2 -> 1110.6 | AL9: 6714155 | AM9: =IF(ISBLANK(AL9),"0",AL9-AL8) -> 2235 | AN9: =AM9*0.2 -> 447 | AO9: 230581 | AP9: =IF(ISBLANK(AO9),"0",AO9-AO8) -> 170 | AQ9: =AP9*0.2 -> 34 | AR9: 8196 | AS9: =IF(ISBLANK(AR9),"0",AR9-AR8) -> 6 | AT9: =AS9*7.84 -> 47.04 | AU9: 3127 | AV9: =IF(ISBLANK(AU9),"0",AU9-AU8) -> 1 | AW9: =AV9*7.84 -> 7.84 | AX9: 103 | AY9: =IF(ISBLANK(AX9),"0",AX9-AX8) -> 1 | AZ9: =AY9*7.84 -> 7.84
A10: 45632 | B10: 20812770 | C10: =IF(ISBLANK(B10),"0",B10-B9) -> 7634 | D10: 21523666 | E10: =IF(ISBLANK(D10),"0",D10-D9) -> 7306 | F10: 480808 | G10: =IF(ISBLANK(F10),"0",F10-F9) -> 132 | H10: =C10+E10+G10 -> 15072 | I10: =H10*0.2 -> 3014.4 | J10: 103273 | K10: =IF(ISBLANK(J10),"0",J10-J9) -> 88 | L10: =K10*7.84 -> 689.92 | M10: 40185 | N10: =IF(ISBLANK(M10),"0",M10-M9) -> 22 | O10: 23979 | P10: =IF(ISBLANK(O10),"0",O10-O9) -> 12 | Q10: =N10+P10 -> 34 | R10: 60199 | S10: =IF(ISBLANK(R10),"0",R10-R9) -> 34 | T10: =S10*1.0557 -> 35.8938 | U10: =IF(ISBLANK(M10),"0",T10*11.05+209.67) -> 606.29649 | V10: 76221 | W10: =IF(ISBLANK(V10),"0",V10-V9) -> 24 | X10: =IF(ISBLANK(V10),"0 ",W10*284.345) -> 6824.28 | Y10: =X10*0.3449 -> 2353.6942 | Z10: =IF(ISBLANK(V10),"0",1570*1608.73/12/31*0.65) -> 4413.1961 | AA10: =Y10+Z10 -> 6766.8903 | AB10: 655911 | AC10: =IF(ISBLANK(AB10),"0 ",AB10-AB9) -> 7498 | AD10: =IF(ISBLANK(V10),"0 ",AC10/284.345) -> 26.369375 | AE10: 0.9683 | AF10: 421 | AG10: 20547 | AH10: =IF(ISBLANK(V10),"0 ",AG10-AG9) -> 6 | AI10: 14636549 | AJ10: =IF(ISBLANK(AI10),"0",AI10-AI9) -> 5483 | AK10: =AJ10*0.2 -> 1096.6 | AL10: 6716339 | AM10: =IF(ISBLANK(AL10),"0",AL10-AL9) -> 2184 | AN10: =AM10*0.2 -> 436.8 | AO10: 230763 | AP10: =IF(ISBLANK(AO10),"0",AO10-AO9) -> 182 | AQ10: =AP10*0.2 -> 36.4 | AR10: 8202 | AS10: =IF(ISBLANK(AR10),"0",AR10-AR9) -> 6 | AT10: =AS10*7.84 -> 47.04 | AU10: 3128 | AV10: =IF(ISBLANK(AU10),"0",AU10-AU9) -> 1 | AW10: =AV10*7.84 -> 7.84 | AX10: 103 | AY10: =IF(ISBLANK(AX10),"0",AX10-AX9) -> 0 | AZ10: =AY10*7.84 -> 0
A11: 45633 | B11: 20820349 | C11: =IF(ISBLANK(B11),"0",B11-B10) -> 7579 | D11: 21530879 | E11: =IF(ISBLANK(D11),"0",D11-D10) -> 7213 | F11: 480941 | G11: =IF(ISBLANK(F11),"0",F11-F10) -> 133 | H11: =C11+E11+G11 -> 14925 | I11: =H11*0.2 -> 2985 | J11: 103379 | K11: =IF(ISBLANK(J11),"0",J11-J10) -> 106 | L11: =K11*7.84 -> 831.04 | M11: 40206 | N11: =IF(ISBLANK(M11),"0",M11-M10) -> 21 | O11: 23992 | P11: =IF(ISBLANK(O11),"0",O11-O10) -> 13 | Q11: =N11+P11 -> 34 | R11: 60231 | S11: =IF(ISBLANK(R11),"0",R11-R10) -> 32 | T11: =S11*1.0557 -> 33.7824 | U11: =IF(ISBLANK(M11),"0",T11*11.05+209.67) -> 582.96552 | V11: 76243 | W11: =IF(ISBLANK(V11),"0",V11-V10) -> 22 | X11: =IF(ISBLANK(V11),"0 ",W11*284.345) -> 6255.59 | Y11: =X11*0.3449 -> 2157.553 | Z11: =IF(ISBLANK(V11),"0",1570*1608.73/12/31*0.65) -> 4413.1961 | AA11: =Y11+Z11 -> 6570.7491 | AB11: 663228 | AC11: =IF(ISBLANK(AB11),"0 ",AB11-AB10) -> 7317 | AD11: =IF(ISBLANK(V11),"0 ",AC11/284.345) -> 25.732825 | AE11: 0.873 | AF11: 378 | AG11: 20553 | AH11: =IF(ISBLANK(V11),"0 ",AG11-AG10) -> 6 | AI11: 14641042 | AJ11: =IF(ISBLANK(AI11),"0",AI11-AI10) -> 4493 | AK11: =AJ11*0.2 -> 898.6 | AL11: 6718374 | AM11: =IF(ISBLANK(AL11),"0",AL11-AL10) -> 2035 | AN11: =AM11*0.2 -> 407 | AO11: 230942 | AP11: =IF(ISBLANK(AO11),"0",AO11-AO10) -> 179 | AQ11: =AP11*0.2 -> 35.8 | AR11: 8206 | AS11: =IF(ISBLANK(AR11),"0",AR11-AR10) -> 4 | AT11: =AS11*7.84 -> 31.36 | AU11: 3129 | AV11: =IF(ISBLANK(AU11),"0",AU11-AU10) -> 1 | AW11: =AV11*7.84 -> 7.84 | AX11: 103 | AY11: =IF(ISBLANK(AX11),"0",AX11-AX10) -> 0 | AZ11: =AY11*7.84 -> 0
A12: 45634 | B12: 20828217 | C12: =IF(ISBLANK(B12),"0",B12-B11) -> 7868 | D12: 21538120 | E12: =IF(ISBLANK(D12),"0",D12-D11) -> 7241 | F12: 481083 | G12: =IF(ISBLANK(F12),"0",F12-F11) -> 142 | H12: =C12+E12+G12 -> 15251 | I12: =H12*0.2 -> 3050.2 | J12: 103480 | K12: =IF(ISBLANK(J12),"0",J12-J11) -> 101 | L12: =K12*7.84 -> 791.84 | M12: 40226 | N12: =IF(ISBLANK(M12),"0",M12-M11) -> 20 | O12: 24008 | P12: =IF(ISBLANK(O12),"0",O12-O11) -> 16 | Q12: =N12+P12 -> 36 | R12: 60266 | S12: =IF(ISBLANK(R12),"0",R12-R11) -> 35 | T12: =S12*1.0557 -> 36.9495 | U12: =IF(ISBLANK(M12),"0",T12*11.05+209.67) -> 617.96198 | V12: 76267 | W12: =IF(ISBLANK(V12),"0",V12-V11) -> 24 | X12: =IF(ISBLANK(V12),"0 ",W12*284.345) -> 6824.28 | Y12: =X12*0.3449 -> 2353.6942 | Z12: =IF(ISBLANK(V12),"0",1570*1608.73/12/31*0.65) -> 4413.1961 | AA12: =Y12+Z12 -> 6766.8903 | AB12: 670316 | AC12: =IF(ISBLANK(AB12),"0 ",AB12-AB11) -> 7088 | AD12: =IF(ISBLANK(V12),"0 ",AC12/284.345) -> 24.927465 | AE12: 1 | AF12: 413 | AG12: 20558 | AH12: =IF(ISBLANK(V12),"0 ",AG12-AG11) -> 5 | AI12: 14645636 | AJ12: =IF(ISBLANK(AI12),"0",AI12-AI11) -> 4594 | AK12: =AJ12*0.2 -> 918.8 | AL12: 6720508 | AM12: =IF(ISBLANK(AL12),"0",AL12-AL11) -> 2134 | AN12: =AM12*0.2 -> 426.8 | AO12: 231123 | AP12: =IF(ISBLANK(AO12),"0",AO12-AO11) -> 181 | AQ12: =AP12*0.2 -> 36.2 | AR12: 8214 | AS12: =IF(ISBLANK(AR12),"0",AR12-AR11) -> 8 | AT12: =AS12*7.84 -> 62.72 | AU12: 3132 | AV12: =IF(ISBLANK(AU12),"0",AU12-AU11) -> 3 | AW12: =AV12*7.84 -> 23.52 | AX12: 104 | AY12: =IF(ISBLANK(AX12),"0",AX12-AX11) -> 1 | AZ12: =AY12*7.84 -> 7.84
A13: 45635 | B13: 20836148 | C13: =IF(ISBLANK(B13),"0",B13-B12) -> 7931 | D13: 21545535 | E13: =IF(ISBLANK(D13),"0",D13-D12) -> 7415 | F13: 481231 | G13: =IF(ISBLANK(F13),"0",F13-F12) -> 148 | H13: =C13+E13+G13 -> 15494 | I13: =H13*0.2 -> 3098.8 | J13: 103592 | K13: =IF(ISBLANK(J13),"0",J13-J12) -> 112 | L13: =K13*7.84 -> 878.08 | M13: 40247 | N13: =IF(ISBLANK(M13),"0",M13-M12) -> 21 | O13: 24023 | P13: =IF(ISBLANK(O13),"0",O13-O12) -> 15 | Q13: =N13+P13 -> 36 | R13: 60301 | S13: =IF(ISBLANK(R13),"0",R13-R12) -> 35 | T13: =S13*1.0557 -> 36.9495 | U13: =IF(ISBLANK(M13),"0",T13*11.05+209.67) -> 617.96198 | V13: 76287 | W13: =IF(ISBLANK(V13),"0",V13-V12) -> 20 | X13: =IF(ISBLANK(V13),"0 ",W13*284.345) -> 5686.9 | Y13: =X13*0.3449 -> 1961.4118 | Z13: =IF(ISBLANK(V13),"0",1570*1608.73/12/31*0.65) -> 4413.1961 | AA13: =Y13+Z13 -> 6374.608 | AB13: 676868 | AC13: =IF(ISBLANK(AB13),"0 ",AB13-AB12) -> 6552 | AD13: =IF(ISBLANK(V13),"0 ",AC13/284.345) -> 23.042431 | AE13: 1 | AF13: 384 | AG13: 20563 | AH13: =IF(ISBLANK(V13),"0 ",AG13-AG12) -> 5 | AI13: 14651223 | AJ13: =IF(ISBLANK(AI13),"0",AI13-AI12) -> 5587 | AK13: =AJ13*0.2 -> 1117.4 | AL13: 6722747 | AM13: =IF(ISBLANK(AL13),"0",AL13-AL12) -> 2239 | AN13: =AM13*0.2 -> 447.8 | AO13: 231285 | AP13: =IF(ISBLANK(AO13),"0",AO13-AO12) -> 162 | AQ13: =AP13*0.2 -> 32.4 | AR13: 8222 | AS13: =IF(ISBLANK(AR13),"0",AR13-AR12) -> 8 | AT13: =AS13*7.84 -> 62.72 | AU13: 3133 | AV13: =IF(ISBLANK(AU13),"0",AU13-AU12) -> 1 | AW13: =AV13*7.84 -> 7.84 | AX13: 105 | AY13: =IF(ISBLANK(AX13),"0",AX13-AX12) -> 1 | AZ13: =AY13*7.84 -> 7.84
A14: 45636 | B14: 20843934 | C14: =IF(ISBLANK(B14),"0",B14-B13) -> 7786 | D14: 21552718 | E14: =IF(ISBLANK(D14),"0",D14-D13) -> 7183 | F14: 481367 | G14: =IF(ISBLANK(F14),"0",F14-F13) -> 136 | H14: =C14+E14+G14 -> 15105 | I14: =H14*0.2 -> 3021 | J14: 103695 | K14: =IF(ISBLANK(J14),"0",J14-J13) -> 103 | L14: =K14*7.84 -> 807.52 | M14: 40268 | N14: =IF(ISBLANK(M14),"0",M14-M13) -> 21 | O14: 24038 | P14: =IF(ISBLANK(O14),"0",O14-O13) -> 15 | Q14: =N14+P14 -> 36 | R14: 60336 | S14: =IF(ISBLANK(R14),"0",R14-R13) -> 35 | T14: =S14*1.0557 -> 36.9495 | U14: =IF(ISBLANK(M14),"0",T14*11.05+209.67) -> 617.96198 | V14: 76308 | W14: =IF(ISBLANK(V14),"0",V14-V13) -> 21 | X14: =IF(ISBLANK(V14),"0 ",W14*284.345) -> 5971.245 | Y14: =X14*0.3449 -> 2059.4824 | Z14: =IF(ISBLANK(V14),"0",1570*1608.73/12/31*0.65) -> 4413.1961 | AA14: =Y14+Z14 -> 6472.6785 | AB14: 683748 | AC14: =IF(ISBLANK(AB14),"0 ",AB14-AB13) -> 6880 | AD14: =IF(ISBLANK(V14),"0 ",AC14/284.345) -> 24.195959 | AE14: 0.9651 | AF14: 378 | AG14: 20568 | AH14: =IF(ISBLANK(V14),"0 ",AG14-AG13) -> 5 | AI14: 14656843 | AJ14: =IF(ISBLANK(AI14),"0",AI14-AI13) -> 5620 | AK14: =AJ14*0.2 -> 1124 | AL14: 6725000 | AM14: =IF(ISBLANK(AL14),"0",AL14-AL13) -> 2253 | AN14: =AM14*0.2 -> 450.6 | AO14: 231449 | AP14: =IF(ISBLANK(AO14),"0",AO14-AO13) -> 164 | AQ14: =AP14*0.2 -> 32.8 | AR14: 8228 | AS14: =IF(ISBLANK(AR14),"0",AR14-AR13) -> 6 | AT14: =AS14*7.84 -> 47.04 | AU14: 3134 | AV14: =IF(ISBLANK(AU14),"0",AU14-AU13) -> 1 | AW14: =AV14*7.84 -> 7.84 | AX14: 106 | AY14: =IF(ISBLANK(AX14),"0",AX14-AX13) -> 1 | AZ14: =AY14*7.84 -> 7.84
A15: 45637 | B15: 20851704 | C15: =IF(ISBLANK(B15),"0",B15-B14) -> 7770 | D15: 21559985 | E15: =IF(ISBLANK(D15),"0",D15-D14) -> 7267 | F15: 481503 | G15: =IF(ISBLANK(F15),"0",F15-F14) -> 136 | H15: =C15+E15+G15 -> 15173 | I15: =H15*0.2 -> 3034.6 | J15: 103801 | K15: =IF(ISBLANK(J15),"0",J15-J14) -> 106 | L15: =K15*7.84 -> 831.04 | M15: 40289 | N15: =IF(ISBLANK(M15),"0",M15-M14) -> 21 | O15: 24051 | P15: =IF(ISBLANK(O15),"0",O15-O14) -> 13 | Q15: =N15+P15 -> 34 | R15: 60368 | S15: =IF(ISBLANK(R15),"0",R15-R14) -> 32 | T15: =S15*1.0557 -> 33.7824 | U15: =IF(ISBLANK(M15),"0",T15*11.05+209.67) -> 582.96552 | V15: 76330 | W15: =IF(ISBLANK(V15),"0",V15-V14) -> 22 | X15: =IF(ISBLANK(V15),"0 ",W15*284.345) -> 6255.59 | Y15: =X15*0.3449 -> 2157.553 | Z15: =IF(ISBLANK(V15),"0",1570*1608.73/12/31*0.65) -> 4413.1961 | AA15: =Y15+Z15 -> 6570.7491 | AB15: 690734 | AC15: =IF(ISBLANK(AB15),"0 ",AB15-AB14) -> 6986 | AD15: =IF(ISBLANK(V15),"0 ",AC15/284.345) -> 24.568746 | AE15: 0.9746 | AF15: 408 | AG15: 20574 | AH15: =IF(ISBLANK(V15),"0 ",AG15-AG14) -> 6 | AI15: 14662411 | AJ15: =IF(ISBLANK(AI15),"0",AI15-AI14) -> 5568 | AK15: =AJ15*0.2 -> 1113.6 | AL15: 6727214 | AM15: =IF(ISBLANK(AL15),"0",AL15-AL14) -> 2214 | AN15: =AM15*0.2 -> 442.8 | AO15: 231621 | AP15: =IF(ISBLANK(AO15),"0",AO15-AO14) -> 172 | AQ15: =AP15*0.2 -> 34.4 | AR15: 8236 | AS15: =IF(ISBLANK(AR15),"0",AR15-AR14) -> 8 | AT15: =AS15*7.84 -> 62.72 | AU15: 3135 | AV15: =IF(ISBLANK(AU15),"0",AU15-AU14) -> 1 | AW15: =AV15*7.84 -> 7.84 | AX15: 107 | AY15: =IF(ISBLANK(AX15),"0",AX15-AX14) -> 1 | AZ15: =AY15*7.84 -> 7.84
A16: 45638 | B16: 20859498 | C16: =IF(ISBLANK(B16),"0",B16-B15) -> 7794 | D16: 21567457 | E16: =IF(ISBLANK(D16),"0",D16-D15) -> 7472 | F16: 481646 | G16: =IF(ISBLANK(F16),"0",F16-F15) -> 143 | H16: =C16+E16+G16 -> 15409 | I16: =H16*0.2 -> 3081.8 | J16: 103895 | K16: =IF(ISBLANK(J16),"0",J16-J15) -> 94 | L16: =K16*7.84 -> 736.96 | M16: 40309 | N16: =IF(ISBLANK(M16),"0",M16-M15) -> 20 | O16: 24065 | P16: =IF(ISBLANK(O16),"0",O16-O15) -> 14 | Q16: =N16+P16 -> 34 | R16: 60401 | S16: =IF(ISBLANK(R16),"0",R16-R15) -> 33 | T16: =S16*1.0557 -> 34.8381 | U16: =IF(ISBLANK(M16),"0",T16*11.05+209.67) -> 594.63101 | V16: 76349 | W16: =IF(ISBLANK(V16),"0",V16-V15) -> 19 | X16: =IF(ISBLANK(V16),"0 ",W16*284.345) -> 5402.555 | Y16: =X16*0.3449 -> 1863.3412 | Z16: =IF(ISBLANK(V16),"0",1570*1608.73/12/31*0.65) -> 4413.1961 | AA16: =Y16+Z16 -> 6276.5374 | AB16: 697326 | AC16: =IF(ISBLANK(AB16),"0 ",AB16-AB15) -> 6592 | AD16: =IF(ISBLANK(V16),"0 ",AC16/284.345) -> 23.183105 | AE16: 0.8222 | AF16: 366 | AG16: 20580 | AH16: =IF(ISBLANK(V16),"0 ",AG16-AG15) -> 6 | AI16: 14668126 | AJ16: =IF(ISBLANK(AI16),"0",AI16-AI15) -> 5715 | AK16: =AJ16*0.2 -> 1143 | AL16: 6729497 | AM16: =IF(ISBLANK(AL16),"0",AL16-AL15) -> 2283 | AN16: =AM16*0.2 -> 456.6 | AO16: 231775 | AP16: =IF(ISBLANK(AO16),"0",AO16-AO15) -> 154 | AQ16: =AP16*0.2 -> 30.8 | AR16: 8243 | AS16: =IF(ISBLANK(AR16),"0",AR16-AR15) -> 7 | AT16: =AS16*7.84 -> 54.88 | AU16: 3136 | AV16: =IF(ISBLANK(AU16),"0",AU16-AU15) -> 1 | AW16: =AV16*7.84 -> 7.84 | AX16: 107 | AY16: =IF(ISBLANK(AX16),"0",AX16-AX15) -> 0 | AZ16: =AY16*7.84 -> 0
A17: 45639 | B17: 20867340 | C17: =IF(ISBLANK(B17),"0",B17-B16) -> 7842 | D17: 21575147 | E17: =IF(ISBLANK(D17),"0",D17-D16) -> 7690 | F17: 481786 | G17: =IF(ISBLANK(F17),"0",F17-F16) -> 140 | H17: =C17+E17+G17 -> 15672 | I17: =H17*0.2 -> 3134.4 | J17: 104003 | K17: =IF(ISBLANK(J17),"0",J17-J16) -> 108 | L17: =K17*7.84 -> 846.72 | M17: 40329 | N17: =IF(ISBLANK(M17),"0",M17-M16) -> 20 | O17: 24079 | P17: =IF(ISBLANK(O17),"0",O17-O16) -> 14 | Q17: =N17+P17 -> 34 | R17: 60435 | S17: =IF(ISBLANK(R17),"0",R17-R16) -> 34 | T17: =S17*1.0557 -> 35.8938 | U17: =IF(ISBLANK(M17),"0",T17*11.05+209.67) -> 606.29649 | V17: 76372 | W17: =IF(ISBLANK(V17),"0",V17-V16) -> 23 | X17: =IF(ISBLANK(V17),"0 ",W17*284.345) -> 6539.935 | Y17: =X17*0.3449 -> 2255.6236 | Z17: =IF(ISBLANK(V17),"0",1570*1608.73/12/31*0.65) -> 4413.1961 | AA17: =Y17+Z17 -> 6668.8197 | AB17: 704539 | AC17: =IF(ISBLANK(AB17),"0 ",AB17-AB16) -> 7213 | AD17: =IF(ISBLANK(V17),"0 ",AC17/284.345) -> 25.367072 | AE17: 0.8476 | AF17: 416 | AG17: 20586 | AH17: =IF(ISBLANK(V17),"0 ",AG17-AG16) -> 6 | AI17: 14673635 | AJ17: =IF(ISBLANK(AI17),"0",AI17-AI16) -> 5509 | AK17: =AJ17*0.2 -> 1101.8 | AL17: 6731719 | AM17: =IF(ISBLANK(AL17),"0",AL17-AL16) -> 2222 | AN17: =AM17*0.2 -> 444.4 | AO17: 231949 | AP17: =IF(ISBLANK(AO17),"0",AO17-AO16) -> 174 | AQ17: =AP17*0.2 -> 34.8 | AR17: 8252 | AS17: =IF(ISBLANK(AR17),"0",AR17-AR16) -> 9 | AT17: =AS17*7.84 -> 70.56 | AU17: 3141 | AV17: =IF(ISBLANK(AU17),"0",AU17-AU16) -> 5 | AW17: =AV17*7.84 -> 39.2 | AX17: 109 | AY17: =IF(ISBLANK(AX17),"0",AX17-AX16) -> 2 | AZ17: =AY17*7.84 -> 15.68
... A35: 45657 | B35: 21010982 | C35: =IF(ISBLANK(B35),"0",B35-B34) -> 7857 | D35: 21710601 | E35: =IF(ISBLANK(D35),"0",D35-D34) -> 6922 | F35: 484256 | G35: =IF(ISBLANK(F35),"0",F35-F34) -> 147 | H35: =C35+E35+G35 -> 14926 | I35: =H35*0.2 -> 2985.2 | J35: 105996 | K35: =IF(ISBLANK(J35),"0",J35-J34) -> 106 | L35: =K35*7.84 -> 831.04 | M35: 40662 | N35: =IF(ISBLANK(M35),"0",M35-M34) -> 18 | O35: 24308 | P35: =IF(ISBLANK(O35),"0",O35-O34) -> 13 | Q35: =N35+P35 -> 31 | R35: 60978 | S35: =IF(ISBLANK(R35),"0",R35-R34) -> 31 | T35: =S35*1.0557 -> 32.7267 | U35: =IF(ISBLANK(M35),"0",T35*11.05+209.67) -> 571.30003 | V35: 76713 | W35: =IF(ISBLANK(V35),"0",V35-V34) -> 23 | X35: =IF(ISBLANK(V35),"0 ",W35*284.345) -> 6539.935 | Y35: =X35*0.3449 -> 2255.6236 | Z35: =IF(ISBLANK(V35),"0",1570*1608.73/12/31*0.65) -> 4413.1961 | AA35: =Y35+Z35 -> 6668.8197 | AB35: 808374 | AC35: =IF(ISBLANK(AB35),"0 ",AB35-AB34) -> 6233 | AD35: =IF(ISBLANK(V35),"0 ",AC35/284.345) -> 21.920554 | AE35: 0.7937 | AF35: 386 | AG35: 20659 | AH35: =IF(ISBLANK(V35),"0 ",AG35-AG34) -> 2 | AI35: 14764960 | AJ35: =IF(ISBLANK(AI35),"0",AI35-AI34) -> 5131 | AK35: =AJ35*0.2 -> 1026.2 | AL35: 6770287 | AM35: =IF(ISBLANK(AL35),"0",AL35-AL34) -> 2120 | AN35: =AM35*0.2 -> 424 | AO35: 234802 | AP35: =IF(ISBLANK(AO35),"0",AO35-AO34) -> 125 | AQ35: =AP35*0.2 -> 25 | AR35: 8385 | AS35: =IF(ISBLANK(AR35),"0",AR35-AR34) -> 5 | AT35: =AS35*7.84 -> 39.2 | AU35: 3246 | AV35: =IF(ISBLANK(AU35),"0",AU35-AU34) -> 2 | AW35: =AV35*7.84 -> 15.68 | AX35: 124 | AY35: =IF(ISBLANK(AX35),"0",AX35-AX34) -> 0 | AZ35: =AY35*7.84 -> 0
C36: =SUM(C5:C35) -> 244786 | E36: =SUM(E5:E35) -> 230995 | G36: =SUM(G5:G35) -> 4290 | H36: =SUM(H5:H35) -> 480071 | I36: =H36*0.2 -> 96014.2 | K36: =SUM(K5:K35) -> 3322 | L36: =K36*7.84 -> 26044.48 | N36: =SUM(N5:N35) -> 598 | P36: =SUM(P5:P35) -> 408 | Q36: =SUM(Q5:Q35) -> 1006 | S36: =SUM(S5:S35) -> 974 | T36: =SUM(T5:T35) -> 1028.2518 | U36: =SUM(U5:U35) -> 17861.952 | W36: =SUM(W5:W35) -> 623 | X36: =SUM(X5:X35) -> 177146.93 | Y36: =SUM(Y5:Y35) -> 61097.978 | Z36: =SUM(Z5:Z35) -> 136809.08 | AA36: =SUM(AA5:AA35) -> 197907.06 | AC36: =SUM(AC5:AC35) -> 193116 | AD36: =SUM(AD5:AD35) -> 679.16088 | AE36: =AVERAGE(AE5:AE35) -> 0.86778387 | AF36: =SUM(AF5:AF35) -> 12399 | AH36: =SUM(AH5:AH35) -> 142 | AJ36: =SUM(AJ5:AJ35) -> 157916 | AK36: =SUM(AK5:AK35) -> 31583.2 | AM36: =SUM(AM5:AM35) -> 66910 | AN36: =SUM(AN5:AN35) -> 13382 | AP36: =SUM(AP5:AP35) -> 5105 | AQ36: =SUM(AQ5:AQ35) -> 1021 | AS36: =SUM(AS5:AS35) -> 225 | AT36: =SUM(AT5:AT35) -> 1764 | AV36: =SUM(AV5:AV35) -> 124 | AW36: =SUM(AW5:AW35) -> 972.16 | AY36: =SUM(AY5:AY35) -> 25 | AZ36: =SUM(AZ5:AZ35) -> 196
V37: AVT Charges should be Zero in the DC invoice - Please notify if not
B38: Electricity | D38: AED | G38: KW | J38: Water | L38: AED | M38: M3 | O38: Gas | R38: AED | T38: M3 | V38: Chilled Water | X38: AED | Z38: Ton Hour | AG38: =(131547.55*7)+(135620.99)+(136809.08*4) -> 1603690.2 | AH38: CHW Fixed Charges YTD 2024
B39: Actual December2024 | D39: =I36 -> 96014.2 | G39: =D39/0.2 -> 480071 | J39: =B39 -> Actual December2024 | L39: =L36 -> 26044.48 | M39: =K36 -> 3322 | O39: =B39 -> Actual December2024 | R39: =U36 -> 17861.952 | T39: =T36 -> 1028.2518 | V39: =B39 -> Actual December2024 | X39: =AA36 -> 197907.06 | Z39: =X36 -> 177146.93 | AD39: =AC36 -> 193116 | AE39: =AD39-X36 -> 15969.065 | AG39: =(126488.42*7)+(130404.97)+(131547.55*4) -> 1542014.1 | AH39: CHW Fixed Charges YTD 2023
B40: Budget December 2024 | D40: 95697 | G40: =D40/0.2 -> 478485 | J40: =B40 -> Budget December 2024 | L40: 26565.61 | M40: =L40/7.84 -> 3388.4707 | O40: =B40 -> Budget December 2024 | R40: 20961.33 | T40: =(R40-6500)/11.05 -> 1308.7176 | V40: =B40 -> Budget December 2024 | X40: 208102.96 | Z40: =AG40/0.3449 -> 206708.84 | AG40: =X40-136809.08 -> 71293.88 | AH40: CHW Consumption Charges (Budgeted 2024 MTD)
B41: Actual December 2023 | D41: 89662.2 | G41: =D41/0.2 -> 448311 | J41: =B41 -> Actual December 2023 | L41: 23841.44 | M41: =L41/7.84 -> 3041 | O41: =B41 -> Actual December 2023 | R41: 17185 | T41: =(R41-6500)/11.05 -> 966.96833 | V41: =B41 -> Actual December 2023 | X41: 188553.07 | Z41: =AG41/0.3442 -> 165617.43 | AG41: =X41-131547.55 -> 57005.52 | AH41: CHW Consumption Charges (Actual 2023 MTD)
B42: Actual YTD 2024 | D42: =D39+967194 -> 1063208.2 | G42: =D42/0.2 -> 5316041 | J42: =B42 -> Actual YTD 2024 | L42: =L39+265235.04 -> 291279.52 | M42: =L42/7.84 -> 37153 | O42: =B42 -> Actual YTD 2024 | R42: =R39+201294.73 -> 219156.68 | T42: =(R42-6500*12)/11.05 -> 12774.36 | V42: =B42 -> Actual YTD 2024 | X42: =X39+2447393.39 -> 2645300.4 | Z42: =AG42/0.3449 -> 3020035.6 | AG42: =X42-AG38 -> 1041610.3 | AH42: CHW Consumption Charges (Actual 2024 YTD)
B43: Budget YTD 2024 | D43: =D40+1057061.25 -> 1152758.2 | G43: =D43/0.2 -> 5763791.2 | J43: =B43 -> Budget YTD 2024 | L43: =L40+275756.58 -> 302322.19 | M43: =L43/7.84 -> 38561.504 | O43: =B43 -> Budget YTD 2024 | R43: =R40+209486.4 -> 230447.73 | T43: =(R43-6500*12)/11.05 -> 13796.175 | V43: =B43 -> Budget YTD 2024 | X43: =X40+2463755.4 -> 2671858.4 | Z43: =AG43/0.3449 -> 3097037.4 | AG43: =X43-AG38 -> 1068168.2 | AH43: CHW Consumption Charges (Budgeted 2024 YTD)
B44: Actual YTD 2023 | D44: 1119373.4 | G44: =D44/0.2 -> 5596867 | J44: =B44 -> Actual YTD 2023 | L44: 271122.88 | M44: =L44/7.84 -> 34582 | O44: =B44 -> Actual YTD 2023 | R44: 205908.88 | T44: =(R44-6500*12)/11.05 -> 11575.464 | V44: =B44 -> Actual YTD 2023 | X44: 2533325 | Z44: =AG44/0.3442 -> 2880043.3 | AG44: =X44-AG39 -> 991310.9 | AH44: CHW Consumption Charges (Actual 2023 YTD)
H45: 45627 | I45: =TODAY() -> 45672 | J45: 31
A46: Monthly Budget | D46: Daily Budget | I46: MTD Average | N46: MTD Budget | U46: MTD Actual | Z46: YTD Budget | AD46: YTD Actual | AG46: Savings | AH46: Exceeds
A47: Electricity | B47: =D40 -> 95697 | D47: Electricity | G47: =B47/31 -> 3087 | I47: Electricity | L47: =I36/J45 -> 3097.2323 | N47: Electricity | R47: =G47*J45 -> 95697 | U47: Electricity | W47: =I36 -> 96014.2 | Y47: =R47-W47 -> -317.2 | Z47: Electricity | AB47: =R47+1057061.25 -> 1152758.2 | AD47: Electricity | AF47: =W47+967194 -> 1063208.2 | AG47: =AB47-AF47 -> 89550.05 | AH47: =AF47-AB47 -> -89550.05
A48: Water | B48: =L40 -> 26565.61 | D48: Water | G48: =B48/31 -> 856.95516 | I48: Water | L48: =L36/J45 -> 840.14452 | N48: Water | R48: =G48*J45 -> 26565.61 | U48: Water | W48: =L36 -> 26044.48 | Y48: =R48-W48 -> 521.13 | Z48: Water | AB48: =R48+275756.58 -> 302322.19 | AD48: Water | AF48: =W48+265235.04 -> 291279.52 | AG48: =AB48-AF48 -> 11042.67 | AH48: =AF48-AB48 -> -11042.67
A49: Gas | B49: =R40 -> 20961.33 | D49: Gas | G49: =B49/31 -> 676.17194 | I49: Gas | L49: =U36/J45 -> 576.19201 | N49: Gas | R49: =G49*J45 -> 20961.33 | U49: Gas | W49: =U36 -> 17861.952 | Y49: =R49-W49 -> 3099.3776 | Z49: Gas | AB49: =R49+209486.4 -> 230447.73 | AD49: Gas | AF49: =W49+201294.73 -> 219156.68 | AG49: =AB49-AF49 -> 11291.048 | AH49: =AF49-AB49 -> -11291.048
A50: Chilled Water | B50: =X40 -> 208102.96 | D50: Chilled Water | G50: =B50/31 -> 6712.9987 | I50: Chilled Water | L50: =AA36/J45 -> 6384.0987 | N50: Chilled Water | R50: =G50*J45 -> 208102.96 | U50: Chilled Water | W50: =AA36 -> 197907.06 | Y50: =R50-W50 -> 10195.902 | Z50: Chilled Water | AB50: =R50+2463755.4 -> 2671858.4 | AD50: Chilled Water | AF50: =W50+2447393.39 -> 2645300.4 | AG50: =AB50-AF50 -> 26557.912 | AH50: =AF50-AB50 -> -26557.912
B51: =SUM(B47:B50) -> 351326.9 | R51: =SUM(R47:S50) -> 351326.9 | W51: =SUM(W47:X50) -> 337827.69 | Y51: =R51-W51 -> 13499.209 | AA51: Total Energy cost | AB51: =SUM(AB47:AB50) -> 4357386.5 | AF51: =SUM(AF47:AF50) -> 4218944.9 | AG51: =AB51-AF51 -> 138441.68
B52: =B51*X52 -> 13499.209 | X52: =1-(W51/R51) -> 0.0384235 | AF52: =1-(AF51/AB51) -> 0.031771723
A54: Actual Last Year | D54: Average Daily Consumption Last Year | I54: MTD Average Last Year | N54: MTD Actual | U54: MTD Actual Vs Last Year | Z54: MTD Fcst | AA54: YTD Fcst | AD54: MTD Saving Fcst Vs LY | AE54: YTD Saving Fcst Vs LY
A55: Electricity | B55: =D41 -> 89662.2 | D55: Electricity | G55: =B55/31 -> 2892.329 | I55: Electricity | L55: =G55*J45 -> 89662.2 | N55: Electricity | R55: =W47 -> 96014.2 | U55: Electricity | W55: =L55-R55 -> -6352 | Z55: =L47*31 -> 96014.2 | AA55: =Z55+967194 -> 1063208.2 | AD55: =D41-Z55 -> -6352 | AE55: =D44-AA55 -> 56165.2
A56: Water | B56: =L41 -> 23841.44 | D56: Water | G56: =B56/31 -> 769.07871 | I56: Water | L56: =G56*J45 -> 23841.44 | N56: Water | R56: =W48 -> 26044.48 | U56: Water | W56: =L56-R56 -> -2203.04 | Z56: =L48*31 -> 26044.48 | AA56: =Z56+265235.04 -> 291279.52 | AD56: =L41-Z56 -> -2203.04 | AE56: =L44-AA56 -> -20156.64
A57: Gas | B57: =R41 -> 17185 | D57: Gas | G57: =B57/31 -> 554.35484 | I57: Gas | L57: =G57*J45 -> 17185 | N57: Gas | R57: =W49 -> 17861.952 | U57: Gas | W57: =L57-R57 -> -676.95239 | Z57: =L49*31 -> 17861.952 | AA57: =Z57+201294.73 -> 219156.68 | AD57: =R41-Z57 -> -676.95239 | AE57: =R44-AA57 -> -13247.802
A58: Chilled Water | B58: =X41 -> 188553.07 | D58: Chilled Water | G58: =B58/31 -> 6082.3571 | I58: Chilled Water | L58: =G58*J45 -> 188553.07 | N58: Chilled Water | R58: =W50 -> 197907.06 | U58: Chilled Water | W58: =L58-R58 -> -9353.9883 | Z58: =L50*31 -> 197907.06 | AA58: =Z58+2447393.39 -> 2645300.4 | AD58: =X41-Z58 -> -9353.9883 | AE58: =X44-AA58 -> -111975.44
...
