Workbook

Sheet Total
A1: Site Name | B1: Day | C1: Month | D1: Year | E1: Total Electricity Kwh | F1: Electricity Tariff ($/Kwh) | G1: Natural Gas (m3) | H1: Natural Gas $/m3 | I1: Water Utility Supply (m3) m3 | J1: Water Utility Supply (m3) $/m3 | K1: District Energy Cooling RTH | L1: District Energy Cooling $/RTH | M1: Room Nights | N1: Total Guests
A2: Pearl Rotana Capital Centre | B2: 1 | C2: 2 | D2: 2025 | E2: =Submetering!E2+Submetering!F2+Submetering!G2 -> 16024 | F2: 0.2 | G2: ='Feb 2025'!T5 -> 32.7267 | H2: 17.62 | I2: =Submetering!H2 -> 129 | J2: 7.84 | K2: ='Feb 2025'!X5 -> 5118.21 | L2: 0.3449 | M2: =Submetering!N2 -> 286.9965 | N2: =Submetering!O2 -> 440
A3: Pearl Rotana Capital Centre | B3: =B2+1 -> 2 | C3: 2 | D3: 2025 | E3: =Submetering!E3+Submetering!F3+Submetering!G3 -> 16172 | F3: 0.2 | G3: ='Feb 2025'!T6 -> 32.7267 | H3: 17.62 | I3: =Submetering!H3 -> 109 | J3: 7.84 | K3: ='Feb 2025'!X6 -> 5971.245 | L3: 0.3449 | M3: =Submetering!N3 -> 269.9865 | N3: =Submetering!O3 -> 392
A4: Pearl Rotana Capital Centre | B4: =B3+1 -> 3 | C4: 2 | D4: 2025 | E4: =Submetering!E4+Submetering!F4+Submetering!G4 -> 16310 | F4: 0.2 | G4: ='Feb 2025'!T7 -> 32.7267 | H4: 17.62 | I4: =Submetering!H4 -> 105 | J4: 7.84 | K4: ='Feb 2025'!X7 -> 6255.59 | L4: 0.3449 | M4: =Submetering!N4 -> 290.997 | N4: =Submetering!O4 -> 393
A5: Pearl Rotana Capital Centre | B5: =B4+1 -> 4 | C5: 2 | D5: 2025 | E5: =Submetering!E5+Submetering!F5+Submetering!G5 -> 16309 | F5: 0.2 | G5: ='Feb 2025'!T8 -> 29.5596 | H5: 17.62 | I5: =Submetering!H5 -> 108 | J5: 7.84 | K5: ='Feb 2025'!X8 -> 5686.9 | L5: 0.3449 | M5: =Submetering!N5 -> 306.999 | N5: =Submetering!O5 -> 428
A6: Pearl Rotana Capital Centre | B6: =B5+1 -> 5 | C6: 2 | D6: 2025 | E6: =Submetering!E6+Submetering!F6+Submetering!G6 -> 16141 | F6: 0.2 | G6: ='Feb 2025'!T9 -> 33.7824 | H6: 17.62 | I6: =Submetering!H6 -> 111 | J6: 7.84 | K6: ='Feb 2025'!X9 -> 5402.555 | L6: 0.3449 | M6: =Submetering!N6 -> 312.0075 | N6: =Submetering!O6 -> 448
A7: Pearl Rotana Capital Centre | B7: =B6+1 -> 6 | C7: 2 | D7: 2025 | E7: =Submetering!E7+Submetering!F7+Submetering!G7 -> 16229 | F7: 0.2 | G7: ='Feb 2025'!T10 -> 35.8938 | H7: 17.62 | I7: =Submetering!H7 -> 106 | J7: 7.84 | K7: ='Feb 2025'!X10 -> 5686.9 | L7: 0.3449 | M7: =Submetering!N7 -> 308.007 | N7: =Submetering!O7 -> 437
A8: Pearl Rotana Capital Centre | B8: =B7+1 -> 7 | C8: 2 | D8: 2025 | E8: =Submetering!E8+Submetering!F8+Submetering!G8 -> 15978 | F8: 0.2 | G8: ='Feb 2025'!T11 -> 33.7824 | H8: 17.62 | I8: =Submetering!H8 -> 121 | J8: 7.84 | K8: ='Feb 2025'!X11 -> 5402.555 | L8: 0.3449 | M8: =Submetering!N8 -> 304.0065 | N8: =Submetering!O8 -> 467
A9: Pearl Rotana Capital Centre | B9: =B8+1 -> 8 | C9: 2 | D9: 2025 | E9: =Submetering!E9+Submetering!F9+Submetering!G9 -> 15978 | F9: 0.2 | G9: ='Feb 2025'!T12 -> 34.8381 | H9: 17.62 | I9: =Submetering!H9 -> 115 | J9: 7.84 | K9: ='Feb 2025'!X12 -> 5686.9 | L9: 0.3449 | M9: =Submetering!N9 -> 298.998 | N9: =Submetering!O9 -> 452
A10: Pearl Rotana Capital Centre | B10: =B9+1 -> 9 | C10: 2 | D10: 2025 | E10: =Submetering!E10+Submetering!F10+Submetering!G10 -> 15993 | F10: 0.2 | G10: ='Feb 2025'!T13 -> 33.7824 | H10: 17.62 | I10: =Submetering!H10 -> 107 | J10: 7.84 | K10: ='Feb 2025'!X13 -> 5402.555 | L10: 0.3449 | M10: =Submetering!N10 -> 258.993 | N10: =Submetering!O10 -> 346
A11: Pearl Rotana Capital Centre | B11: =B10+1 -> 10 | C11: 2 | D11: 2025 | E11: =Submetering!E11+Submetering!F11+Submetering!G11 -> 15654 | F11: 0.2 | G11: ='Feb 2025'!T14 -> 32.7267 | H11: 17.62 | I11: =Submetering!H11 -> 110 | J11: 7.84 | K11: ='Feb 2025'!X14 -> 4833.865 | L11: 0.3449 | M11: =Submetering!N11 -> 297.0135 | N11: =Submetering!O11 -> 405
A12: Pearl Rotana Capital Centre | B12: =B11+1 -> 11 | C12: 2 | D12: 2025 | E12: =Submetering!E12+Submetering!F12+Submetering!G12 -> 15443 | F12: 0.2 | G12: ='Feb 2025'!T15 -> 32.7267 | H12: 17.62 | I12: =Submetering!H12 -> 111 | J12: 7.84 | K12: ='Feb 2025'!X15 -> 5118.21 | L12: 0.3449 | M12: =Submetering!N12 -> 293.9895 | N12: =Submetering!O12 -> 387
A13: Pearl Rotana Capital Centre | B13: =B12+1 -> 12 | C13: 2 | D13: 2025 | E13: =Submetering!E13+Submetering!F13+Submetering!G13 -> 15403 | F13: 0.2 | G13: ='Feb 2025'!T16 -> 31.671 | H13: 17.62 | I13: =Submetering!H13 -> 95 | J13: 7.84 | K13: ='Feb 2025'!X16 -> 5971.245 | L13: 0.3449 | M13: =Submetering!N13 -> 301.014 | N13: =Submetering!O13 -> 385
A14: Pearl Rotana Capital Centre | B14: =B13+1 -> 13 | C14: 2 | D14: 2025 | E14: =Submetering!E14+Submetering!F14+Submetering!G14 -> 15191 | F14: 0.2 | G14: ='Feb 2025'!T17 -> 34.8381 | H14: 17.62 | I14: =Submetering!H14 -> 107 | J14: 7.84 | K14: ='Feb 2025'!X17 -> 5971.245 | L14: 0.3449 | M14: =Submetering!N14 -> 315 | N14: =Submetering!O14 -> 421
... A29: Pearl Rotana Capital Centre | B29: =B28+1 -> 28 | C29: 2 | D29: 2025 | E29: =Submetering!E29+Submetering!F29+Submetering!G29 -> 15433 | F29: 0.2 | G29: ='Feb 2025'!T32 -> 33.7824 | H29: 17.62 | I29: =Submetering!H29 -> 91 | J29: 7.84 | K29: ='Feb 2025'!X32 -> 5118.21 | L29: 0.3449 | M29: =Submetering!N29 -> 159.9885 | N29: =Submetering!O29 -> 205

Sheet Submetering
A1: Site Name | B1: Day | C1: Month | D1: Year | E1: MDB#2 | F1: MDB#3 | G1: MDB#1 Façade | H1: Water | I1: Gas Meter#1 GF Kitchen | J1: Gas Meter#2 1st floor Kitchen | K1: District Cooling | L1: District Cooling ETS | M1: Water Main Kitchen | N1: Room Nights | O1: Total Guests
A2: Pearl Rotana Capital Centre | B2: 1 | C2: 2 | D2: 2025 | E2: ='Feb 2025'!C5 -> 7911 | F2: ='Feb 2025'!E5 -> 7968 | G2: ='Feb 2025'!G5 -> 145 | H2: ='Feb 2025'!K5 -> 129 | I2: ='Feb 2025'!N5 -> 19 | J2: ='Feb 2025'!P5 -> 13 | K2: ='Feb 2025'!X5 -> 5118.21 | L2: ='Feb 2025'!AC5 -> 5258 | M2: ='Feb 2025'!AS5 -> 10 | N2: ='Feb 2025'!AE5*315 -> 286.9965 | O2: ='Feb 2025'!AF5 -> 440
A3: Pearl Rotana Capital Centre | B3: =B2+1 -> 2 | C3: 2 | D3: 2025 | E3: ='Feb 2025'!C6 -> 7945 | F3: ='Feb 2025'!E6 -> 8083 | G3: ='Feb 2025'!G6 -> 144 | H3: ='Feb 2025'!K6 -> 109 | I3: ='Feb 2025'!N6 -> 19 | J3: ='Feb 2025'!P6 -> 14 | K3: ='Feb 2025'!X6 -> 5971.245 | L3: ='Feb 2025'!AC6 -> 5297 | M3: ='Feb 2025'!AS6 -> 10 | N3: ='Feb 2025'!AE6*315 -> 269.9865 | O3: ='Feb 2025'!AF6 -> 392
A4: Pearl Rotana Capital Centre | B4: =B3+1 -> 3 | C4: 2 | D4: 2025 | E4: ='Feb 2025'!C7 -> 7935 | F4: ='Feb 2025'!E7 -> 8237 | G4: ='Feb 2025'!G7 -> 138 | H4: ='Feb 2025'!K7 -> 105 | I4: ='Feb 2025'!N7 -> 18 | J4: ='Feb 2025'!P7 -> 14 | K4: ='Feb 2025'!X7 -> 6255.59 | L4: ='Feb 2025'!AC7 -> 5469 | M4: ='Feb 2025'!AS7 -> 8 | N4: ='Feb 2025'!AE7*315 -> 290.997 | O4: ='Feb 2025'!AF7 -> 393
A5: Pearl Rotana Capital Centre | B5: =B4+1 -> 4 | C5: 2 | D5: 2025 | E5: ='Feb 2025'!C8 -> 7931 | F5: ='Feb 2025'!E8 -> 8235 | G5: ='Feb 2025'!G8 -> 143 | H5: ='Feb 2025'!K8 -> 108 | I5: ='Feb 2025'!N8 -> 19 | J5: ='Feb 2025'!P8 -> 11 | K5: ='Feb 2025'!X8 -> 5686.9 | L5: ='Feb 2025'!AC8 -> 5523 | M5: ='Feb 2025'!AS8 -> 10 | N5: ='Feb 2025'!AE8*315 -> 306.999 | O5: ='Feb 2025'!AF8 -> 428
A6: Pearl Rotana Capital Centre | B6: =B5+1 -> 5 | C6: 2 | D6: 2025 | E6: ='Feb 2025'!C9 -> 7829 | F6: ='Feb 2025'!E9 -> 8169 | G6: ='Feb 2025'!G9 -> 143 | H6: ='Feb 2025'!K9 -> 111 | I6: ='Feb 2025'!N9 -> 18 | J6: ='Feb 2025'!P9 -> 14 | K6: ='Feb 2025'!X9 -> 5402.555 | L6: ='Feb 2025'!AC9 -> 5442 | M6: ='Feb 2025'!AS9 -> 11 | N6: ='Feb 2025'!AE9*315 -> 312.0075 | O6: ='Feb 2025'!AF9 -> 448
A7: Pearl Rotana Capital Centre | B7: =B6+1 -> 6 | C7: 2 | D7: 2025 | E7: ='Feb 2025'!C10 -> 7877 | F7: ='Feb 2025'!E10 -> 8204 | G7: ='Feb 2025'!G10 -> 148 | H7: ='Feb 2025'!K10 -> 106 | I7: ='Feb 2025'!N10 -> 19 | J7: ='Feb 2025'!P10 -> 16 | K7: ='Feb 2025'!X10 -> 5686.9 | L7: ='Feb 2025'!AC10 -> 5573 | M7: ='Feb 2025'!AS10 -> 10 | N7: ='Feb 2025'!AE10*315 -> 308.007 | O7: ='Feb 2025'!AF10 -> 437
A8: Pearl Rotana Capital Centre | B8: =B7+1 -> 7 | C8: 2 | D8: 2025 | E8: ='Feb 2025'!C11 -> 7802 | F8: ='Feb 2025'!E11 -> 8030 | G8: ='Feb 2025'!G11 -> 146 | H8: ='Feb 2025'!K11 -> 121 | I8: ='Feb 2025'!N11 -> 19 | J8: ='Feb 2025'!P11 -> 14 | K8: ='Feb 2025'!X11 -> 5402.555 | L8: ='Feb 2025'!AC11 -> 5849 | M8: ='Feb 2025'!AS11 -> 7 | N8: ='Feb 2025'!AE11*315 -> 304.0065 | O8: ='Feb 2025'!AF11 -> 467
A9: Pearl Rotana Capital Centre | B9: =B8+1 -> 8 | C9: 2 | D9: 2025 | E9: ='Feb 2025'!C12 -> 7902 | F9: ='Feb 2025'!E12 -> 7953 | G9: ='Feb 2025'!G12 -> 123 | H9: ='Feb 2025'!K12 -> 115 | I9: ='Feb 2025'!N12 -> 20 | J9: ='Feb 2025'!P12 -> 14 | K9: ='Feb 2025'!X12 -> 5686.9 | L9: ='Feb 2025'!AC12 -> 5650 | M9: ='Feb 2025'!AS12 -> 13 | N9: ='Feb 2025'!AE12*315 -> 298.998 | O9: ='Feb 2025'!AF12 -> 452
A10: Pearl Rotana Capital Centre | B10: =B9+1 -> 9 | C10: 2 | D10: 2025 | E10: ='Feb 2025'!C13 -> 7905 | F10: ='Feb 2025'!E13 -> 7952 | G10: ='Feb 2025'!G13 -> 136 | H10: ='Feb 2025'!K13 -> 107 | I10: ='Feb 2025'!N13 -> 19 | J10: ='Feb 2025'!P13 -> 15 | K10: ='Feb 2025'!X13 -> 5402.555 | L10: ='Feb 2025'!AC13 -> 5185 | M10: ='Feb 2025'!AS13 -> 4 | N10: ='Feb 2025'!AE13*315 -> 258.993 | O10: ='Feb 2025'!AF13 -> 346
A11: Pearl Rotana Capital Centre | B11: =B10+1 -> 10 | C11: 2 | D11: 2025 | E11: ='Feb 2025'!C14 -> 7754 | F11: ='Feb 2025'!E14 -> 7770 | G11: ='Feb 2025'!G14 -> 130 | H11: ='Feb 2025'!K14 -> 110 | I11: ='Feb 2025'!N14 -> 18 | J11: ='Feb 2025'!P14 -> 14 | K11: ='Feb 2025'!X14 -> 4833.865 | L11: ='Feb 2025'!AC14 -> 5215 | M11: ='Feb 2025'!AS14 -> 8 | N11: ='Feb 2025'!AE14*315 -> 297.0135 | O11: ='Feb 2025'!AF14 -> 405
A12: Pearl Rotana Capital Centre | B12: =B11+1 -> 11 | C12: 2 | D12: 2025 | E12: ='Feb 2025'!C15 -> 7746 | F12: ='Feb 2025'!E15 -> 7568 | G12: ='Feb 2025'!G15 -> 129 | H12: ='Feb 2025'!K15 -> 111 | I12: ='Feb 2025'!N15 -> 18 | J12: ='Feb 2025'!P15 -> 14 | K12: ='Feb 2025'!X15 -> 5118.21 | L12: ='Feb 2025'!AC15 -> 5521 | M12: ='Feb 2025'!AS15 -> 8 | N12: ='Feb 2025'!AE15*315 -> 293.9895 | O12: ='Feb 2025'!AF15 -> 387
A13: Pearl Rotana Capital Centre | B13: =B12+1 -> 12 | C13: 2 | D13: 2025 | E13: ='Feb 2025'!C16 -> 7677 | F13: ='Feb 2025'!E16 -> 7589 | G13: ='Feb 2025'!G16 -> 137 | H13: ='Feb 2025'!K16 -> 95 | I13: ='Feb 2025'!N16 -> 18 | J13: ='Feb 2025'!P16 -> 13 | K13: ='Feb 2025'!X16 -> 5971.245 | L13: ='Feb 2025'!AC16 -> 6213 | M13: ='Feb 2025'!AS16 -> 11 | N13: ='Feb 2025'!AE16*315 -> 301.014 | O13: ='Feb 2025'!AF16 -> 385
A14: Pearl Rotana Capital Centre | B14: =B13+1 -> 13 | C14: 2 | D14: 2025 | E14: ='Feb 2025'!C17 -> 7582 | F14: ='Feb 2025'!E17 -> 7470 | G14: ='Feb 2025'!G17 -> 139 | H14: ='Feb 2025'!K17 -> 107 | I14: ='Feb 2025'!N17 -> 19 | J14: ='Feb 2025'!P17 -> 14 | K14: ='Feb 2025'!X17 -> 5971.245 | L14: ='Feb 2025'!AC17 -> 6748 | M14: ='Feb 2025'!AS17 -> 8 | N14: ='Feb 2025'!AE17*315 -> 315 | O14: ='Feb 2025'!AF17 -> 421
... A29: Pearl Rotana Capital Centre | B29: =B28+1 -> 28 | C29: 2 | D29: 2025 | E29: ='Feb 2025'!C32 -> 7685 | F29: ='Feb 2025'!E32 -> 7627 | G29: ='Feb 2025'!G32 -> 121 | H29: ='Feb 2025'!K32 -> 91 | I29: ='Feb 2025'!N32 -> 21 | J29: ='Feb 2025'!P32 -> 12 | K29: ='Feb 2025'!X32 -> 5118.21 | L29: ='Feb 2025'!AC32 -> 5187 | M29: ='Feb 2025'!AS32 -> 5 | N29: ='Feb 2025'!AE32*315 -> 159.9885 | O29: ='Feb 2025'!AF32 -> 205

Sheet Feb 2025
A1: PEARL ROTANA CAPITAL CENTRE UTILITIES CONSUMPTION - FEBRUARY 2025
A2: DATE | B2: Electricity | J2: Water | M2: SNG Gas | V2: District Cooling | AE2: Additional Info | AG2: Additional Meter
B3: MDB #2 | D3: MDB #3 | F3: MDB #1 Façade | H3: Total ELE Cons. KW | I3: Electricity AED | J3: Hotel Reading | K3: Water Cons. M3 | L3: Water AED | M3: Gas Meter #1 G Floor Kitchen | O3: Gas Meter #2 1st Floor Kitchen | Q3: Total Gas Cons. M3 | R3: PRS Meter Reading | S3: PRS Meter Cons. M3 | T3: Meter factor (1.05570) | U3: Gas AED | V3: Hotel BTU Meter Energy Reading | W3: District Cooling Cons. MWH | X3: District Cooling Cons. Ton Hour | Y3: District Cooling Cons. AED | Z3: District Cooling Fixed Charge | AA3: District Cooling Total AED | AB3: ETS Energy Bulk Meter Reading | AC3: ETS Cons. Ton Hours | AD3: ETS Cons. MWH | AE3: Hotel Occupancy % | AF3: Adl. & Chl. | AG3: Blue Sky tower Chilled water | AI3: Electricity MDB-1 | AL3: Electricity MDB-E | AO3: Electricity-MCC Panel Chilled water Secondary Pumps | AR3: Water - Main kitchen | AU3: Water - Swimming Pool | AX3: Water - Bottling Plant
B4: Reading | C4: Cons. | D4: Reading | E4: Cons. | F4: Reading | G4: Cons. | M4: Reading | N4: Cons. | O4: Reading | P4: Cons. | AG4: Meter Reading | AH4: Cons. MWH | AI4: Meter Reading | AJ4: Cons. KWH | AK4: AED | AL4: Meter Reading | AM4: Cons. KWH | AN4: AED | AO4: Meter Reading | AP4: Cons. KWH | AQ4: AED | AR4: Meter Reading | AS4: Cons. M3 | AT4: AED | AU4: Meter Reading | AV4: Cons. M3 | AW4: AED | AX4: Meter Reading | AY4: Cons. M3 | AZ4: AED
A5: 45689 | B5: 21261749 | C5: 7911 | D5: 21956026 | E5: 7968 | F5: 488706 | G5: 145 | H5: =C5+E5+G5 -> 16024 | I5: =H5*0.2 -> 3204.8 | J5: 109213 | K5: 129 | L5: =K5*7.84 -> 1011.36 | M5: 41274 | N5: 19 | O5: 24741 | P5: 13 | Q5: =N5+P5 -> 32 | R5: 61984 | S5: 31 | T5: =S5*1.0557 -> 32.7267 | U5: =IF(ISBLANK(M5),"0",T5*11.05+232.14) -> 593.77004 | V5: 77300 | W5: 18 | X5: =IF(ISBLANK(V5),"0 ",W5*284.345) -> 5118.21 | Y5: =X5*0.3449 -> 1765.2706 | Z5: =IF(ISBLANK(V5),"0",1570*1608.73/12/28*0.65) -> 4886.0386 | AA5: =Y5+Z5 -> 6651.3092 | AB5: 978653 | AC5: 5258 | AD5: =IF(ISBLANK(V5),"0 ",AC5/284.345) -> 18.491621 | AE5: 0.9111 | AF5: 440 | AG5: 20784 | AH5: 3 | AI5: 14928561 | AJ5: 4451 | AK5: =AJ5*0.2 -> 890.2 | AL5: 6839125 | AM5: 2082 | AN5: =AM5*0.2 -> 416.4 | AO5: 242885 | AP5: 281 | AQ5: =AP5*0.2 -> 56.2 | AR5: 8631 | AS5: 10 | AT5: =AS5*7.84 -> 78.4 | AU5: 3285 | AV5: 1 | AW5: =AV5*7.84 -> 7.84 | AX5: 154 | AY5: 1 | AZ5: =AY5*7.84 -> 7.84
A6: 45690 | B6: 21269694 | C6: =IF(ISBLANK(B6),"0",B6-B5) -> 7945 | D6: 21964109 | E6: =IF(ISBLANK(D6),"0",D6-D5) -> 8083 | F6: 488850 | G6: =IF(ISBLANK(F6),"0",F6-F5) -> 144 | H6: =C6+E6+G6 -> 16172 | I6: =H6*0.2 -> 3234.4 | J6: 109322 | K6: =IF(ISBLANK(J6),"0",J6-J5) -> 109 | L6: =K6*7.84 -> 854.56 | M6: 41293 | N6: =IF(ISBLANK(M6),"0",M6-M5) -> 19 | O6: 24755 | P6: =IF(ISBLANK(O6),"0",O6-O5) -> 14 | Q6: =N6+P6 -> 33 | R6: 62015 | S6: =IF(ISBLANK(R6),"0",R6-R5) -> 31 | T6: =S6*1.0557 -> 32.7267 | U6: =IF(ISBLANK(M6),"0",T6*11.05+232.14) -> 593.77004 | V6: 77321 | W6: =IF(ISBLANK(V6),"0",V6-V5) -> 21 | X6: =IF(ISBLANK(V6),"0 ",W6*284.345) -> 5971.245 | Y6: =X6*0.3449 -> 2059.4824 | Z6: =IF(ISBLANK(V6),"0",1570*1608.73/12/28*0.65) -> 4886.0386 | AA6: =Y6+Z6 -> 6945.521 | AB6: 983950 | AC6: =IF(ISBLANK(AB6),"0 ",AB6-AB5) -> 5297 | AD6: =IF(ISBLANK(V6),"0 ",AC6/284.345) -> 18.628778 | AE6: 0.8571 | AF6: 392 | AG6: 20788 | AH6: =IF(ISBLANK(V6),"0 ",AG6-AG5) -> 4 | AI6: 14933193 | AJ6: =IF(ISBLANK(AI6),"0",AI6-AI5) -> 4632 | AK6: =AJ6*0.2 -> 926.4 | AL6: 6841223 | AM6: =IF(ISBLANK(AL6),"0",AL6-AL5) -> 2098 | AN6: =AM6*0.2 -> 419.6 | AO6: 243391 | AP6: =IF(ISBLANK(AO6),"0",AO6-AO5) -> 506 | AQ6: =AP6*0.2 -> 101.2 | AR6: 8641 | AS6: =IF(ISBLANK(AR6),"0",AR6-AR5) -> 10 | AT6: =AS6*7.84 -> 78.4 | AU6: 3286 | AV6: =IF(ISBLANK(AU6),"0",AU6-AU5) -> 1 | AW6: =AV6*7.84 -> 7.84 | AX6: 155 | AY6: =IF(ISBLANK(AX6),"0",AX6-AX5) -> 1 | AZ6: =AY6*7.84 -> 7.84
A7: 45691 | B7: 21277629 | C7: =IF(ISBLANK(B7),"0",B7-B6) -> 7935 | D7: 21972346 | E7: =IF(ISBLANK(D7),"0",D7-D6) -> 8237 | F7: 488988 | G7: =IF(ISBLANK(F7),"0",F7-F6) -> 138 | H7: =C7+E7+G7 -> 16310 | I7: =H7*0.2 -> 3262 | J7: 109427 | K7: =IF(ISBLANK(J7),"0",J7-J6) -> 105 | L7: =K7*7.84 -> 823.2 | M7: 41311 | N7: =IF(ISBLANK(M7),"0",M7-M6) -> 18 | O7: 24769 | P7: =IF(ISBLANK(O7),"0",O7-O6) -> 14 | Q7: =N7+P7 -> 32 | R7: 62046 | S7: =IF(ISBLANK(R7),"0",R7-R6) -> 31 | T7: =S7*1.0557 -> 32.7267 | U7: =IF(ISBLANK(M7),"0",T7*11.05+232.14) -> 593.77004 | V7: 77343 | W7: =IF(ISBLANK(V7),"0",V7-V6) -> 22 | X7: =IF(ISBLANK(V7),"0 ",W7*284.345) -> 6255.59 | Y7: =X7*0.3449 -> 2157.553 | Z7: =IF(ISBLANK(V7),"0",1570*1608.73/12/28*0.65) -> 4886.0386 | AA7: =Y7+Z7 -> 7043.5916 | AB7: 989419 | AC7: =IF(ISBLANK(AB7),"0 ",AB7-AB6) -> 5469 | AD7: =IF(ISBLANK(V7),"0 ",AC7/284.345) -> 19.233677 | AE7: 0.9238 | AF7: 393 | AG7: 20792 | AH7: =IF(ISBLANK(V7),"0 ",AG7-AG6) -> 4 | AI7: 14938713 | AJ7: =IF(ISBLANK(AI7),"0",AI7-AI6) -> 5520 | AK7: =AJ7*0.2 -> 1104 | AL7: 6843451 | AM7: =IF(ISBLANK(AL7),"0",AL7-AL6) -> 2228 | AN7: =AM7*0.2 -> 445.6 | AO7: 243962 | AP7: =IF(ISBLANK(AO7),"0",AO7-AO6) -> 571 | AQ7: =AP7*0.2 -> 114.2 | AR7: 8649 | AS7: =IF(ISBLANK(AR7),"0",AR7-AR6) -> 8 | AT7: =AS7*7.84 -> 62.72 | AU7: 3287 | AV7: =IF(ISBLANK(AU7),"0",AU7-AU6) -> 1 | AW7: =AV7*7.84 -> 7.84 | AX7: 156 | AY7: =IF(ISBLANK(AX7),"0",AX7-AX6) -> 1 | AZ7: =AY7*7.84 -> 7.84
A8: 45692 | B8: 21285560 | C8: =IF(ISBLANK(B8),"0",B8-B7) -> 7931 | D8: 21980581 | E8: =IF(ISBLANK(D8),"0",D8-D7) -> 8235 | F8: 489131 | G8: =IF(ISBLANK(F8),"0",F8-F7) -> 143 | H8: =C8+E8+G8 -> 16309 | I8: =H8*0.2 -> 3261.8 | J8: 109535 | K8: =IF(ISBLANK(J8),"0",J8-J7) -> 108 | L8: =K8*7.84 -> 846.72 | M8: 41330 | N8: =IF(ISBLANK(M8),"0",M8-M7) -> 19 | O8: 24780 | P8: =IF(ISBLANK(O8),"0",O8-O7) -> 11 | Q8: =N8+P8 -> 30 | R8: 62074 | S8: =IF(ISBLANK(R8),"0",R8-R7) -> 28 | T8: =S8*1.0557 -> 29.5596 | U8: =IF(ISBLANK(M8),"0",T8*11.05+232.14) -> 558.77358 | V8: 77363 | W8: =IF(ISBLANK(V8),"0",V8-V7) -> 20 | X8: =IF(ISBLANK(V8),"0 ",W8*284.345) -> 5686.9 | Y8: =X8*0.3449 -> 1961.4118 | Z8: =IF(ISBLANK(V8),"0",1570*1608.73/12/28*0.65) -> 4886.0386 | AA8: =Y8+Z8 -> 6847.4504 | AB8: 994942 | AC8: =IF(ISBLANK(AB8),"0 ",AB8-AB7) -> 5523 | AD8: =IF(ISBLANK(V8),"0 ",AC8/284.345) -> 19.423588 | AE8: 0.9746 | AF8: 428 | AG8: 20796 | AH8: =IF(ISBLANK(V8),"0 ",AG8-AG7) -> 4 | AI8: 14944241 | AJ8: =IF(ISBLANK(AI8),"0",AI8-AI7) -> 5528 | AK8: =AJ8*0.2 -> 1105.6 | AL8: 6845663 | AM8: =IF(ISBLANK(AL8),"0",AL8-AL7) -> 2212 | AN8: =AM8*0.2 -> 442.4 | AO8: 244551 | AP8: =IF(ISBLANK(AO8),"0",AO8-AO7) -> 589 | AQ8: =AP8*0.2 -> 117.8 | AR8: 8659 | AS8: =IF(ISBLANK(AR8),"0",AR8-AR7) -> 10 | AT8: =AS8*7.84 -> 78.4 | AU8: 3288 | AV8: =IF(ISBLANK(AU8),"0",AU8-AU7) -> 1 | AW8: =AV8*7.84 -> 7.84 | AX8: 157 | AY8: =IF(ISBLANK(AX8),"0",AX8-AX7) -> 1 | AZ8: =AY8*7.84 -> 7.84
A9: 45693 | B9: 21293389 | C9: =IF(ISBLANK(B9),"0",B9-B8) -> 7829 | D9: 21988750 | E9: =IF(ISBLANK(D9),"0",D9-D8) -> 8169 | F9: 489274 | G9: =IF(ISBLANK(F9),"0",F9-F8) -> 143 | H9: =C9+E9+G9 -> 16141 | I9: =H9*0.2 -> 3228.2 | J9: 109646 | K9: =IF(ISBLANK(J9),"0",J9-J8) -> 111 | L9: =K9*7.84 -> 870.24 | M9: 41348 | N9: =IF(ISBLANK(M9),"0",M9-M8) -> 18 | O9: 24794 | P9: =IF(ISBLANK(O9),"0",O9-O8) -> 14 | Q9: =N9+P9 -> 32 | R9: 62106 | S9: =IF(ISBLANK(R9),"0",R9-R8) -> 32 | T9: =S9*1.0557 -> 33.7824 | U9: =IF(ISBLANK(M9),"0",T9*11.05+232.14) -> 605.43552 | V9: 77382 | W9: =IF(ISBLANK(V9),"0",V9-V8) -> 19 | X9: =IF(ISBLANK(V9),"0 ",W9*284.345) -> 5402.555 | Y9: =X9*0.3449 -> 1863.3412 | Z9: =IF(ISBLANK(V9),"0",1570*1608.73/12/28*0.65) -> 4886.0386 | AA9: =Y9+Z9 -> 6749.3798 | AB9: 1000384 | AC9: =IF(ISBLANK(AB9),"0 ",AB9-AB8) -> 5442 | AD9: =IF(ISBLANK(V9),"0 ",AC9/284.345) -> 19.138722 | AE9: 0.9905 | AF9: 448 | AG9: 20800 | AH9: =IF(ISBLANK(V9),"0 ",AG9-AG8) -> 4 | AI9: 14949793 | AJ9: =IF(ISBLANK(AI9),"0",AI9-AI8) -> 5552 | AK9: =AJ9*0.2 -> 1110.4 | AL9: 6847903 | AM9: =IF(ISBLANK(AL9),"0",AL9-AL8) -> 2240 | AN9: =AM9*0.2 -> 448 | AO9: 245124 | AP9: =IF(ISBLANK(AO9),"0",AO9-AO8) -> 573 | AQ9: =AP9*0.2 -> 114.6 | AR9: 8670 | AS9: =IF(ISBLANK(AR9),"0",AR9-AR8) -> 11 | AT9: =AS9*7.84 -> 86.24 | AU9: 3290 | AV9: =IF(ISBLANK(AU9),"0",AU9-AU8) -> 2 | AW9: =AV9*7.84 -> 15.68 | AX9: 158 | AY9: =IF(ISBLANK(AX9),"0",AX9-AX8) -> 1 | AZ9: =AY9*7.84 -> 7.84
A10: 45694 | B10: 21301266 | C10: =IF(ISBLANK(B10),"0",B10-B9) -> 7877 | D10: 21996954 | E10: =IF(ISBLANK(D10),"0",D10-D9) -> 8204 | F10: 489422 | G10: =IF(ISBLANK(F10),"0",F10-F9) -> 148 | H10: =C10+E10+G10 -> 16229 | I10: =H10*0.2 -> 3245.8 | J10: 109752 | K10: =IF(ISBLANK(J10),"0",J10-J9) -> 106 | L10: =K10*7.84 -> 831.04 | M10: 41367 | N10: =IF(ISBLANK(M10),"0",M10-M9) -> 19 | O10: 24810 | P10: =IF(ISBLANK(O10),"0",O10-O9) -> 16 | Q10: =N10+P10 -> 35 | R10: 62140 | S10: =IF(ISBLANK(R10),"0",R10-R9) -> 34 | T10: =S10*1.0557 -> 35.8938 | U10: =IF(ISBLANK(M10),"0",T10*11.05+232.14) -> 628.76649 | V10: 77402 | W10: =IF(ISBLANK(V10),"0",V10-V9) -> 20 | X10: =IF(ISBLANK(V10),"0 ",W10*284.345) -> 5686.9 | Y10: =X10*0.3449 -> 1961.4118 | Z10: =IF(ISBLANK(V10),"0",1570*1608.73/12/28*0.65) -> 4886.0386 | AA10: =Y10+Z10 -> 6847.4504 | AB10: 1005957 | AC10: =IF(ISBLANK(AB10),"0 ",AB10-AB9) -> 5573 | AD10: =IF(ISBLANK(V10),"0 ",AC10/284.345) -> 19.59943 | AE10: 0.9778 | AF10: 437 | AG10: 20804 | AH10: =IF(ISBLANK(V10),"0 ",AG10-AG9) -> 4 | AI10: 14955336 | AJ10: =IF(ISBLANK(AI10),"0",AI10-AI9) -> 5543 | AK10: =AJ10*0.2 -> 1108.6 | AL10: 6850104 | AM10: =IF(ISBLANK(AL10),"0",AL10-AL9) -> 2201 | AN10: =AM10*0.2 -> 440.2 | AO10: 245595 | AP10: =IF(ISBLANK(AO10),"0",AO10-AO9) -> 471 | AQ10: =AP10*0.2 -> 94.2 | AR10: 8680 | AS10: =IF(ISBLANK(AR10),"0",AR10-AR9) -> 10 | AT10: =AS10*7.84 -> 78.4 | AU10: 3292 | AV10: =IF(ISBLANK(AU10),"0",AU10-AU9) -> 2 | AW10: =AV10*7.84 -> 15.68 | AX10: 159 | AY10: =IF(ISBLANK(AX10),"0",AX10-AX9) -> 1 | AZ10: =AY10*7.84 -> 7.84
A11: 45695 | B11: 21309068 | C11: =IF(ISBLANK(B11),"0",B11-B10) -> 7802 | D11: 22004984 | E11: =IF(ISBLANK(D11),"0",D11-D10) -> 8030 | F11: 489568 | G11: =IF(ISBLANK(F11),"0",F11-F10) -> 146 | H11: =C11+E11+G11 -> 15978 | I11: =H11*0.2 -> 3195.6 | J11: 109873 | K11: =IF(ISBLANK(J11),"0",J11-J10) -> 121 | L11: =K11*7.84 -> 948.64 | M11: 41386 | N11: =IF(ISBLANK(M11),"0",M11-M10) -> 19 | O11: 24824 | P11: =IF(ISBLANK(O11),"0",O11-O10) -> 14 | Q11: =N11+P11 -> 33 | R11: 62172 | S11: =IF(ISBLANK(R11),"0",R11-R10) -> 32 | T11: =S11*1.0557 -> 33.7824 | U11: =IF(ISBLANK(M11),"0",T11*11.05+232.14) -> 605.43552 | V11: 77421 | W11: =IF(ISBLANK(V11),"0",V11-V10) -> 19 | X11: =IF(ISBLANK(V11),"0 ",W11*284.345) -> 5402.555 | Y11: =X11*0.3449 -> 1863.3412 | Z11: =IF(ISBLANK(V11),"0",1570*1608.73/12/28*0.65) -> 4886.0386 | AA11: =Y11+Z11 -> 6749.3798 | AB11: 1011806 | AC11: =IF(ISBLANK(AB11),"0 ",AB11-AB10) -> 5849 | AD11: =IF(ISBLANK(V11),"0 ",AC11/284.345) -> 20.570082 | AE11: 0.9651 | AF11: 467 | AG11: 20808 | AH11: =IF(ISBLANK(V11),"0 ",AG11-AG10) -> 4 | AI11: 14960751 | AJ11: =IF(ISBLANK(AI11),"0",AI11-AI10) -> 5415 | AK11: =AJ11*0.2 -> 1083 | AL11: 6852353 | AM11: =IF(ISBLANK(AL11),"0",AL11-AL10) -> 2249 | AN11: =AM11*0.2 -> 449.8 | AO11: 245958 | AP11: =IF(ISBLANK(AO11),"0",AO11-AO10) -> 363 | AQ11: =AP11*0.2 -> 72.6 | AR11: 8687 | AS11: =IF(ISBLANK(AR11),"0",AR11-AR10) -> 7 | AT11: =AS11*7.84 -> 54.88 | AU11: 3294 | AV11: =IF(ISBLANK(AU11),"0",AU11-AU10) -> 2 | AW11: =AV11*7.84 -> 15.68 | AX11: 160 | AY11: =IF(ISBLANK(AX11),"0",AX11-AX10) -> 1 | AZ11: =AY11*7.84 -> 7.84
A12: 45696 | B12: 21316970 | C12: =IF(ISBLANK(B12),"0",B12-B11) -> 7902 | D12: 22012937 | E12: =IF(ISBLANK(D12),"0",D12-D11) -> 7953 | F12: 489691 | G12: =IF(ISBLANK(F12),"0",F12-F11) -> 123 | H12: =C12+E12+G12 -> 15978 | I12: =H12*0.2 -> 3195.6 | J12: 109988 | K12: =IF(ISBLANK(J12),"0",J12-J11) -> 115 | L12: =K12*7.84 -> 901.6 | M12: 41406 | N12: =IF(ISBLANK(M12),"0",M12-M11) -> 20 | O12: 24838 | P12: =IF(ISBLANK(O12),"0",O12-O11) -> 14 | Q12: =N12+P12 -> 34 | R12: 62205 | S12: =IF(ISBLANK(R12),"0",R12-R11) -> 33 | T12: =S12*1.0557 -> 34.8381 | U12: =IF(ISBLANK(M12),"0",T12*11.05+232.14) -> 617.101 | V12: 77441 | W12: =IF(ISBLANK(V12),"0",V12-V11) -> 20 | X12: =IF(ISBLANK(V12),"0 ",W12*284.345) -> 5686.9 | Y12: =X12*0.3449 -> 1961.4118 | Z12: =IF(ISBLANK(V12),"0",1570*1608.73/12/28*0.65) -> 4886.0386 | AA12: =Y12+Z12 -> 6847.4504 | AB12: 1017456 | AC12: =IF(ISBLANK(AB12),"0 ",AB12-AB11) -> 5650 | AD12: =IF(ISBLANK(V12),"0 ",AC12/284.345) -> 19.870228 | AE12: 0.9492 | AF12: 452 | AG12: 20811 | AH12: =IF(ISBLANK(V12),"0 ",AG12-AG11) -> 3 | AI12: 14965240 | AJ12: =IF(ISBLANK(AI12),"0",AI12-AI11) -> 4489 | AK12: =AJ12*0.2 -> 897.8 | AL12: 6854468 | AM12: =IF(ISBLANK(AL12),"0",AL12-AL11) -> 2115 | AN12: =AM12*0.2 -> 423 | AO12: 246210 | AP12: =IF(ISBLANK(AO12),"0",AO12-AO11) -> 252 | AQ12: =AP12*0.2 -> 50.4 | AR12: 8700 | AS12: =IF(ISBLANK(AR12),"0",AR12-AR11) -> 13 | AT12: =AS12*7.84 -> 101.92 | AU12: 3295 | AV12: =IF(ISBLANK(AU12),"0",AU12-AU11) -> 1 | AW12: =AV12*7.84 -> 7.84 | AX12: 161 | AY12: =IF(ISBLANK(AX12),"0",AX12-AX11) -> 1 | AZ12: =AY12*7.84 -> 7.84
A13: 45697 | B13: 21324875 | C13: =IF(ISBLANK(B13),"0",B13-B12) -> 7905 | D13: 22020889 | E13: =IF(ISBLANK(D13),"0",D13-D12) -> 7952 | F13: 489827 | G13: =IF(ISBLANK(F13),"0",F13-F12) -> 136 | H13: =C13+E13+G13 -> 15993 | I13: =H13*0.2 -> 3198.6 | J13: 110095 | K13: =IF(ISBLANK(J13),"0",J13-J12) -> 107 | L13: =K13*7.84 -> 838.88 | M13: 41425 | N13: =IF(ISBLANK(M13),"0",M13-M12) -> 19 | O13: 24853 | P13: =IF(ISBLANK(O13),"0",O13-O12) -> 15 | Q13: =N13+P13 -> 34 | R13: 62237 | S13: =IF(ISBLANK(R13),"0",R13-R12) -> 32 | T13: =S13*1.0557 -> 33.7824 | U13: =IF(ISBLANK(M13),"0",T13*11.05+232.14) -> 605.43552 | V13: 77460 | W13: =IF(ISBLANK(V13),"0",V13-V12) -> 19 | X13: =IF(ISBLANK(V13),"0 ",W13*284.345) -> 5402.555 | Y13: =X13*0.3449 -> 1863.3412 | Z13: =IF(ISBLANK(V13),"0",1570*1608.73/12/28*0.65) -> 4886.0386 | AA13: =Y13+Z13 -> 6749.3798 | AB13: 1022641 | AC13: =IF(ISBLANK(AB13),"0 ",AB13-AB12) -> 5185 | AD13: =IF(ISBLANK(V13),"0 ",AC13/284.345) -> 18.234891 | AE13: 0.8222 | AF13: 346 | AG13: 20814 | AH13: =IF(ISBLANK(V13),"0 ",AG13-AG12) -> 3 | AI13: 14969706 | AJ13: =IF(ISBLANK(AI13),"0",AI13-AI12) -> 4466 | AK13: =AJ13*0.2 -> 893.2 | AL13: 6856572 | AM13: =IF(ISBLANK(AL13),"0",AL13-AL12) -> 2104 | AN13: =AM13*0.2 -> 420.8 | AO13: 246458 | AP13: =IF(ISBLANK(AO13),"0",AO13-AO12) -> 248 | AQ13: =AP13*0.2 -> 49.6 | AR13: 8704 | AS13: =IF(ISBLANK(AR13),"0",AR13-AR12) -> 4 | AT13: =AS13*7.84 -> 31.36 | AU13: 3296 | AV13: =IF(ISBLANK(AU13),"0",AU13-AU12) -> 1 | AW13: =AV13*7.84 -> 7.84 | AX13: 162 | AY13: =IF(ISBLANK(AX13),"0",AX13-AX12) -> 1 | AZ13: =AY13*7.84 -> 7.84
A14: 45698 | B14: 21332629 | C14: =IF(ISBLANK(B14),"0",B14-B13) -> 7754 | D14: 22028659 | E14: =IF(ISBLANK(D14),"0",D14-D13) -> 7770 | F14: 489957 | G14: =IF(ISBLANK(F14),"0",F14-F13) -> 130 | H14: =C14+E14+G14 -> 15654 | I14: =H14*0.2 -> 3130.8 | J14: 110205 | K14: =IF(ISBLANK(J14),"0",J14-J13) -> 110 | L14: =K14*7.84 -> 862.4 | M14: 41443 | N14: =IF(ISBLANK(M14),"0",M14-M13) -> 18 | O14: 24867 | P14: =IF(ISBLANK(O14),"0",O14-O13) -> 14 | Q14: =N14+P14 -> 32 | R14: 62268 | S14: =IF(ISBLANK(R14),"0",R14-R13) -> 31 | T14: =S14*1.0557 -> 32.7267 | U14: =IF(ISBLANK(M14),"0",T14*11.05+232.14) -> 593.77004 | V14: 77477 | W14: =IF(ISBLANK(V14),"0",V14-V13) -> 17 | X14: =IF(ISBLANK(V14),"0 ",W14*284.345) -> 4833.865 | Y14: =X14*0.3449 -> 1667.2 | Z14: =IF(ISBLANK(V14),"0",1570*1608.73/12/28*0.65) -> 4886.0386 | AA14: =Y14+Z14 -> 6553.2386 | AB14: 1027856 | AC14: =IF(ISBLANK(AB14),"0 ",AB14-AB13) -> 5215 | AD14: =IF(ISBLANK(V14),"0 ",AC14/284.345) -> 18.340396 | AE14: 0.9429 | AF14: 405 | AG14: 20818 | AH14: =IF(ISBLANK(V14),"0 ",AG14-AG13) -> 4 | AI14: 14975077 | AJ14: =IF(ISBLANK(AI14),"0",AI14-AI13) -> 5371 | AK14: =AJ14*0.2 -> 1074.2 | AL14: 6858800 | AM14: =IF(ISBLANK(AL14),"0",AL14-AL13) -> 2228 | AN14: =AM14*0.2 -> 445.6 | AO14: 246681 | AP14: =IF(ISBLANK(AO14),"0",AO14-AO13) -> 223 | AQ14: =AP14*0.2 -> 44.6 | AR14: 8712 | AS14: =IF(ISBLANK(AR14),"0",AR14-AR13) -> 8 | AT14: =AS14*7.84 -> 62.72 | AU14: 3297 | AV14: =IF(ISBLANK(AU14),"0",AU14-AU13) -> 1 | AW14: =AV14*7.84 -> 7.84 | AX14: 163 | AY14: =IF(ISBLANK(AX14),"0",AX14-AX13) -> 1 | AZ14: =AY14*7.84 -> 7.84
A15: 45699 | B15: 21340375 | C15: =IF(ISBLANK(B15),"0",B15-B14) -> 7746 | D15: 22036227 | E15: =IF(ISBLANK(D15),"0",D15-D14) -> 7568 | F15: 490086 | G15: =IF(ISBLANK(F15),"0",F15-F14) -> 129 | H15: =C15+E15+G15 -> 15443 | I15: =H15*0.2 -> 3088.6 | J15: 110316 | K15: =IF(ISBLANK(J15),"0",J15-J14) -> 111 | L15: =K15*7.84 -> 870.24 | M15: 41461 | N15: =IF(ISBLANK(M15),"0",M15-M14) -> 18 | O15: 24881 | P15: =IF(ISBLANK(O15),"0",O15-O14) -> 14 | Q15: =N15+P15 -> 32 | R15: 62299 | S15: =IF(ISBLANK(R15),"0",R15-R14) -> 31 | T15: =S15*1.0557 -> 32.7267 | U15: =IF(ISBLANK(M15),"0",T15*11.05+232.14) -> 593.77004 | V15: 77495 | W15: =IF(ISBLANK(V15),"0",V15-V14) -> 18 | X15: =IF(ISBLANK(V15),"0 ",W15*284.345) -> 5118.21 | Y15: =X15*0.3449 -> 1765.2706 | Z15: =IF(ISBLANK(V15),"0",1570*1608.73/12/28*0.65) -> 4886.0386 | AA15: =Y15+Z15 -> 6651.3092 | AB15: 1033377 | AC15: =IF(ISBLANK(AB15),"0 ",AB15-AB14) -> 5521 | AD15: =IF(ISBLANK(V15),"0 ",AC15/284.345) -> 19.416554 | AE15: 0.9333 | AF15: 387 | AG15: 20822 | AH15: =IF(ISBLANK(V15),"0 ",AG15-AG14) -> 4 | AI15: 14980579 | AJ15: =IF(ISBLANK(AI15),"0",AI15-AI14) -> 5502 | AK15: =AJ15*0.2 -> 1100.4 | AL15: 6861058 | AM15: =IF(ISBLANK(AL15),"0",AL15-AL14) -> 2258 | AN15: =AM15*0.2 -> 451.6 | AO15: 246878 | AP15: =IF(ISBLANK(AO15),"0",AO15-AO14) -> 197 | AQ15: =AP15*0.2 -> 39.4 | AR15: 8720 | AS15: =IF(ISBLANK(AR15),"0",AR15-AR14) -> 8 | AT15: =AS15*7.84 -> 62.72 | AU15: 3298 | AV15: =IF(ISBLANK(AU15),"0",AU15-AU14) -> 1 | AW15: =AV15*7.84 -> 7.84 | AX15: 164 | AY15: =IF(ISBLANK(AX15),"0",AX15-AX14) -> 1 | AZ15: =AY15*7.84 -> 7.84
A16: 45700 | B16: 21348052 | C16: =IF(ISBLANK(B16),"0",B16-B15) -> 7677 | D16: 22043816 | E16: =IF(ISBLANK(D16),"0",D16-D15) -> 7589 | F16: 490223 | G16: =IF(ISBLANK(F16),"0",F16-F15) -> 137 | H16: =C16+E16+G16 -> 15403 | I16: =H16*0.2 -> 3080.6 | J16: 110411 | K16: =IF(ISBLANK(J16),"0",J16-J15) -> 95 | L16: =K16*7.84 -> 744.8 | M16: 41479 | N16: =IF(ISBLANK(M16),"0",M16-M15) -> 18 | O16: 24894 | P16: =IF(ISBLANK(O16),"0",O16-O15) -> 13 | Q16: =N16+P16 -> 31 | R16: 62329 | S16: =IF(ISBLANK(R16),"0",R16-R15) -> 30 | T16: =S16*1.0557 -> 31.671 | U16: =IF(ISBLANK(M16),"0",T16*11.05+232.14) -> 582.10455 | V16: 77516 | W16: =IF(ISBLANK(V16),"0",V16-V15) -> 21 | X16: =IF(ISBLANK(V16),"0 ",W16*284.345) -> 5971.245 | Y16: =X16*0.3449 -> 2059.4824 | Z16: =IF(ISBLANK(V16),"0",1570*1608.73/12/28*0.65) -> 4886.0386 | AA16: =Y16+Z16 -> 6945.521 | AB16: 1039590 | AC16: =IF(ISBLANK(AB16),"0 ",AB16-AB15) -> 6213 | AD16: =IF(ISBLANK(V16),"0 ",AC16/284.345) -> 21.850217 | AE16: 0.9556 | AF16: 385 | AG16: 20827 | AH16: =IF(ISBLANK(V16),"0 ",AG16-AG15) -> 5 | AI16: 14986040 | AJ16: =IF(ISBLANK(AI16),"0",AI16-AI15) -> 5461 | AK16: =AJ16*0.2 -> 1092.2 | AL16: 6863276 | AM16: =IF(ISBLANK(AL16),"0",AL16-AL15) -> 2218 | AN16: =AM16*0.2 -> 443.6 | AO16: 247093 | AP16: =IF(ISBLANK(AO16),"0",AO16-AO15) -> 215 | AQ16: =AP16*0.2 -> 43 | AR16: 8731 | AS16: =IF(ISBLANK(AR16),"0",AR16-AR15) -> 11 | AT16: =AS16*7.84 -> 86.24 | AU16: 3299 | AV16: =IF(ISBLANK(AU16),"0",AU16-AU15) -> 1 | AW16: =AV16*7.84 -> 7.84 | AX16: 165 | AY16: =IF(ISBLANK(AX16),"0",AX16-AX15) -> 1 | AZ16: =AY16*7.84 -> 7.84
A17: 45701 | B17: 21355634 | C17: =IF(ISBLANK(B17),"0",B17-B16) -> 7582 | D17: 22051286 | E17: =IF(ISBLANK(D17),"0",D17-D16) -> 7470 | F17: 490362 | G17: =IF(ISBLANK(F17),"0",F17-F16) -> 139 | H17: =C17+E17+G17 -> 15191 | I17: =H17*0.2 -> 3038.2 | J17: 110518 | K17: =IF(ISBLANK(J17),"0",J17-J16) -> 107 | L17: =K17*7.84 -> 838.88 | M17: 41498 | N17: =IF(ISBLANK(M17),"0",M17-M16) -> 19 | O17: 24908 | P17: =IF(ISBLANK(O17),"0",O17-O16) -> 14 | Q17: =N17+P17 -> 33 | R17: 62362 | S17: =IF(ISBLANK(R17),"0",R17-R16) -> 33 | T17: =S17*1.0557 -> 34.8381 | U17: =IF(ISBLANK(M17),"0",T17*11.05+232.14) -> 617.101 | V17: 77537 | W17: =IF(ISBLANK(V17),"0",V17-V16) -> 21 | X17: =IF(ISBLANK(V17),"0 ",W17*284.345) -> 5971.245 | Y17: =X17*0.3449 -> 2059.4824 | Z17: =IF(ISBLANK(V17),"0",1570*1608.73/12/28*0.65) -> 4886.0386 | AA17: =Y17+Z17 -> 6945.521 | AB17: 1046338 | AC17: =IF(ISBLANK(AB17),"0 ",AB17-AB16) -> 6748 | AD17: =IF(ISBLANK(V17),"0 ",AC17/284.345) -> 23.731734 | AE17: 1 | AF17: 421 | AG17: 20832 | AH17: =IF(ISBLANK(V17),"0 ",AG17-AG16) -> 5 | AI17: 14991491 | AJ17: =IF(ISBLANK(AI17),"0",AI17-AI16) -> 5451 | AK17: =AJ17*0.2 -> 1090.2 | AL17: 6865500 | AM17: =IF(ISBLANK(AL17),"0",AL17-AL16) -> 2224 | AN17: =AM17*0.2 -> 444.8 | AO17: 247291 | AP17: =IF(ISBLANK(AO17),"0",AO17-AO16) -> 198 | AQ17: =AP17*0.2 -> 39.6 | AR17: 8739 | AS17: =IF(ISBLANK(AR17),"0",AR17-AR16) -> 8 | AT17: =AS17*7.84 -> 62.72 | AU17: 3300 | AV17: =IF(ISBLANK(AU17),"0",AU17-AU16) -> 1 | AW17: =AV17*7.84 -> 7.84 | AX17: 166 | AY17: =IF(ISBLANK(AX17),"0",AX17-AX16) -> 1 | AZ17: =AY17*7.84 -> 7.84
... A32: 45716 | B32: 21473167 | C32: =IF(ISBLANK(B32),"0",B32-B31) -> 7685 | D32: 22165830 | E32: =IF(ISBLANK(D32),"0",D32-D31) -> 7627 | F32: 492235 | G32: =IF(ISBLANK(F32),"0",F32-F31) -> 121 | H32: =C32+E32+G32 -> 15433 | I32: =H32*0.2 -> 3086.6 | J32: 112017 | K32: =IF(ISBLANK(J32),"0",J32-J31) -> 91 | L32: =K32*7.84 -> 713.44 | M32: 41820 | N32: =IF(ISBLANK(M32),"0",M32-M31) -> 21 | O32: 25117 | P32: =IF(ISBLANK(O32),"0",O32-O31) -> 12 | Q32: =N32+P32 -> 33 | R32: 62878 | S32: =IF(ISBLANK(R32),"0",R32-R31) -> 32 | T32: =S32*1.0557 -> 33.7824 | U32: =IF(ISBLANK(M32),"0",T32*11.05+232.14) -> 605.43552 | V32: 77866 | W32: =IF(ISBLANK(V32),"0",V32-V31) -> 18 | X32: =IF(ISBLANK(V32),"0 ",W32*284.345) -> 5118.21 | Y32: =X32*0.3449 -> 1765.2706 | Z32: =IF(ISBLANK(V32),"0",1570*1608.73/12/28*0.65) -> 4886.0386 | AA32: =Y32+Z32 -> 6651.3092 | AB32: 1145107 | AC32: =IF(ISBLANK(AB32),"0 ",AB32-AB31) -> 5187 | AD32: =IF(ISBLANK(V32),"0 ",AC32/284.345) -> 18.241924 | AE32: 0.5079 | AF32: 205 | AG32: 20899 | AH32: =IF(ISBLANK(V32),"0 ",AG32-AG31) -> 3 | AI32: 15069447 | AJ32: =IF(ISBLANK(AI32),"0",AI32-AI31) -> 5271 | AK32: =AJ32*0.2 -> 1054.2 | AL32: 6898346 | AM32: =IF(ISBLANK(AL32),"0",AL32-AL31) -> 2128 | AN32: =AM32*0.2 -> 425.6 | AO32: 250605 | AP32: =IF(ISBLANK(AO32),"0",AO32-AO31) -> 229 | AQ32: =AP32*0.2 -> 45.8 | AR32: 8818 | AS32: =IF(ISBLANK(AR32),"0",AR32-AR31) -> 5 | AT32: =AS32*7.84 -> 39.2 | AU32: 3321 | AV32: =IF(ISBLANK(AU32),"0",AU32-AU31) -> 3 | AW32: =AV32*7.84 -> 23.52 | AX32: 180 | AY32: =IF(ISBLANK(AX32),"0",AX32-AX31) -> 0 | AZ32: =AY32*7.84 -> 0
C33: =SUM(C5:C32) -> 219329 | E33: =SUM(E5:E32) -> 217772 | G33: =SUM(G5:G32) -> 3674 | H33: =SUM(H5:H32) -> 440775 | I33: =H33*0.2 -> 88155 | K33: =SUM(K5:K32) -> 2933 | L33: =K33*7.84 -> 22994.72 | N33: =SUM(N5:N32) -> 565 | P33: =SUM(P5:P32) -> 389 | Q33: =SUM(Q5:Q32) -> 954 | S33: =SUM(S5:S32) -> 925 | T33: =SUM(T5:T32) -> 976.5225 | U33: =SUM(U5:U32) -> 17290.494 | W33: =SUM(W5:W32) -> 584 | X33: =SUM(X5:X32) -> 166057.48 | Y33: =SUM(Y5:Y32) -> 57273.225 | Z33: =SUM(Z5:Z32) -> 136809.08 | AA33: =SUM(AA5:AA32) -> 194082.31 | AC33: =SUM(AC5:AC32) -> 171712 | AD33: =SUM(AD5:AD32) -> 603.88612 | AE33: =AVERAGE(AE5:AE32) -> 0.90136071 | AF33: =SUM(AF5:AF32) -> 10469 | AH33: =SUM(AH5:AH32) -> 118 | AJ33: =SUM(AJ5:AJ32) -> 145337 | AK33: =SUM(AK5:AK32) -> 29067.4 | AM33: =SUM(AM5:AM32) -> 61303 | AN33: =SUM(AN5:AN32) -> 12260.6 | AP33: =SUM(AP5:AP32) -> 8001 | AQ33: =SUM(AQ5:AQ32) -> 1600.2 | AS33: =SUM(AS5:AS32) -> 197 | AT33: =SUM(AT5:AT32) -> 1544.48 | AV33: =SUM(AV5:AV32) -> 37 | AW33: =SUM(AW5:AW32) -> 290.08 | AY33: =SUM(AY5:AY32) -> 27 | AZ33: =SUM(AZ5:AZ32) -> 211.68
V34: AVT Charges should be Zero in the DC invoice - Please notify if not
B35: Electricity | D35: AED | G35: KW | J35: Water | L35: AED | M35: M3 | O35: Gas | R35: AED | T35: M3 | V35: Chilled Water | X35: AED | Z35: Ton Hour | AG35: =136809.08*2 -> 273618.16 | AH35: CHW Fixed Charges YTD 2025
B36: Actual February 2025 | D36: =I33 -> 88155 | G36: =D36/0.2 -> 440775 | J36: =B36 -> Actual February 2025 | L36: =L33 -> 22994.72 | M36: =K33 -> 2933 | O36: =B36 -> Actual February 2025 | R36: =U33 -> 17290.494 | T36: =T33 -> 976.5225 | V36: =B36 -> Actual February 2025 | X36: =AA33 -> 194082.31 | Z36: =X33 -> 166057.48 | AD36: =AC33 -> 171712 | AE36: =AD36-X33 -> 5654.52 | AG36: =131547.55*2 -> 263095.1 | AH36: CHW Fixed Charges YTD 2024
B37: Budget February 2025 | D37: 85554 | G37: =D37/0.2 -> 427770 | J37: =B37 -> Budget February 2025 | L37: 25367.395 | M37: =L37/7.84 -> 3235.6371 | O37: =B37 -> Budget February 2025 | R37: 18197.499 | T37: =(R37-6500)/11.05 -> 1058.5972 | V37: =B37 -> Budget February 2025 | X37: 188015.61 | Z37: =AG37/0.3449 -> 148467.75 | AG37: =X37-136809.08 -> 51206.528 | AH37: CHW Consumption Charges (Budgeted 2025 MTD)
B38: Actual February 2024 | D38: 84074.2 | G38: =D38/0.2 -> 420371 | J38: =B38 -> Actual February 2024 | L38: 24100.16 | M38: =L38/7.84 -> 3074 | O38: =B38 -> Actual February 2024 | R38: 17738.75 | T38: =(R38-6500)/11.05 -> 1017.0814 | V38: =B38 -> Actual February 2024 | X38: 178112.55 | Z38: =AG38/0.3442 -> 135284.72 | AG38: =X38-131547.55 -> 46565 | AH38: CHW Consumption Charges (Actual 2024 MTD)
B39: Actual YTD 2025 | D39: =D36+96923.6 -> 185078.6 | G39: =D39/0.2 -> 925393 | J39: =B39 -> Actual YTD 2025 | L39: =L36+24209.92 -> 47204.64 | M39: =L39/7.84 -> 6021 | O39: =B39 -> Actual YTD 2025 | R39: =R36+17600.66 -> 34891.154 | T39: =(R39-6500)*2/11.05 -> 5138.6703 | V39: =B39 -> Actual YTD 2025 | X39: =X36+192611.25 -> 386693.56 | Z39: =AG39/0.3449 -> 327849.8 | AG39: =X39-AG35 -> 113075.4 | AH39: CHW Consumption Charges (Actual 2025 YTD)
B40: Budget YTD 2025 | D40: =D37+93744 -> 179298 | G40: =D40/0.2 -> 896490 | J40: =B40 -> Budget YTD 2025 | L40: =L37+28575.5248678943 -> 53942.92 | M40: =L40/7.84 -> 6880.4745 | O40: =B40 -> Budget YTD 2025 | R40: =R37+19314.1163869365 -> 37511.616 | T40: =(R40-6500)*2/11.05 -> 5612.9621 | V40: =B40 -> Budget YTD 2025 | X40: =X37+197611.7754 -> 385627.38 | Z40: =AG40/0.3449 -> 324758.55 | AG40: =X40-AG35 -> 112009.22 | AH40: CHW Consumption Charges (Budgeted 2025 YTD)
B41: Actual YTD 2024 | D41: 172084.4 | G41: =D41/0.2 -> 860422 | J41: =B41 -> Actual YTD 2024 | L41: 49086.24 | M41: =L41/7.84 -> 6261 | O41: =B41 -> Actual YTD 2024 | R41: 35082.39 | T41: =(R41-6500)*2/11.05 -> 5173.2833 | V41: =B41 -> Actual YTD 2024 | X41: 363489.45 | Z41: =AG41/0.3442 -> 291674.46 | AG41: =X41-AG36 -> 100394.35 | AH41: CHW Consumption Charges (Actual 2024 YTD)
H42: 45689 | I42: =TODAY() -> 45719 | J42: 28
A43: Monthly Budget | D43: Daily Budget | I43: MTD Average | N43: MTD Budget | U43: MTD Actual | Z43: YTD Budget | AD43: YTD Actual | AG43: Savings | AH43: Exceeds
A44: Electricity | B44: =D37 -> 85554 | D44: Electricity | G44: =B44/28 -> 3055.5 | I44: Electricity | L44: =I33/J42 -> 3148.3929 | N44: Electricity | R44: =G44*J42 -> 85554 | U44: Electricity | W44: =I33 -> 88155 | Y44: =R44-W44 -> -2601 | Z44: Electricity | AB44: =R44+93744 -> 179298 | AD44: Electricity | AF44: =W44+96923.6 -> 185078.6 | AG44: =AB44-AF44 -> -5780.6 | AH44: =AF44-AB44 -> 5780.6
A45: Water | B45: =L37 -> 25367.395 | D45: Water | G45: =B45/28 -> 905.97839 | I45: Water | L45: =L33/J42 -> 821.24 | N45: Water | R45: =G45*J42 -> 25367.395 | U45: Water | W45: =L33 -> 22994.72 | Y45: =R45-W45 -> 2372.6749 | Z45: Water | AB45: =R45+28575.5248678943 -> 53942.92 | AD45: Water | AF45: =W45+24209.92 -> 47204.64 | AG45: =AB45-AF45 -> 6738.2797 | AH45: =AF45-AB45 -> -6738.2797
A46: Gas | B46: =R37 -> 18197.499 | D46: Gas | G46: =B46/28 -> 649.91069 | I46: Gas | L46: =U33/J42 -> 617.51763 | N46: Gas | R46: =G46*J42 -> 18197.499 | U46: Gas | W46: =U33 -> 17290.494 | Y46: =R46-W46 -> 907.00578 | Z46: Gas | AB46: =R46+19314.1163869365 -> 37511.616 | AD46: Gas | AF46: =W46+17600.66 -> 34891.154 | AG46: =AB46-AF46 -> 2620.4622 | AH46: =AF46-AB46 -> -2620.4622
A47: Chilled Water | B47: =X37 -> 188015.61 | D47: Chilled Water | G47: =B47/28 -> 6714.8431 | I47: Chilled Water | L47: =AA33/J42 -> 6931.5109 | N47: Chilled Water | R47: =G47*J42 -> 188015.61 | U47: Chilled Water | W47: =AA33 -> 194082.31 | Y47: =R47-W47 -> -6066.6975 | Z47: Chilled Water | AB47: =R47+197611.7754 -> 385627.38 | AD47: Chilled Water | AF47: =W47+192611.25 -> 386693.56 | AG47: =AB47-AF47 -> -1066.1721 | AH47: =AF47-AB47 -> 1066.1721
B48: =SUM(B44:B47) -> 317134.5 | R48: =SUM(R44:S47) -> 317134.5 | W48: =SUM(W44:X47) -> 322522.52 | Y48: =R48-W48 -> -5388.0169 | AA48: Total Energy cost | AB48: =SUM(AB44:AB47) -> 656379.92 | AF48: =SUM(AF44:AF47) -> 653867.95 | AG48: =AB48-AF48 -> 2511.9698
B49: =B48*X49 -> -5388.0169 | X49: =1-(W48/R48) -> -0.01698969 | AF49: =1-(AF48/AB48) -> 0.0038270059
A51: Actual Last Year | D51: Average Daily Consumption Last Year | I51: MTD Average Last Year | N51: MTD Actual | U51: MTD Actual Vs Last Year | Z51: MTD Fcst | AA51: YTD Fcst | AD51: MTD Saving Fcst Vs LY | AE51: YTD Saving Fcst Vs LY
A52: Electricity | B52: =D38 -> 84074.2 | D52: Electricity | G52: =B52/28 -> 3002.65 | I52: Electricity | L52: =G52*J42 -> 84074.2 | N52: Electricity | R52: =W44 -> 88155 | U52: Electricity | W52: =L52-R52 -> -4080.8 | Z52: =L44*28 -> 88155 | AA52: =Z52+96923.6 -> 185078.6 | AD52: =D38-Z52 -> -4080.8 | AE52: =D41-AA52 -> -12994.2
A53: Water | B53: =L38 -> 24100.16 | D53: Water | G53: =B53/28 -> 860.72 | I53: Water | L53: =G53*J42 -> 24100.16 | N53: Water | R53: =W45 -> 22994.72 | U53: Water | W53: =L53-R53 -> 1105.44 | Z53: =L45*28 -> 22994.72 | AA53: =Z53+24209.92 -> 47204.64 | AD53: =L38-Z53 -> 1105.44 | AE53: =L41-AA53 -> 1881.6
A54: Gas | B54: =R38 -> 17738.75 | D54: Gas | G54: =B54/28 -> 633.52679 | I54: Gas | L54: =G54*J42 -> 17738.75 | N54: Gas | R54: =W46 -> 17290.494 | U54: Gas | W54: =L54-R54 -> 448.25637 | Z54: =L46*28 -> 17290.494 | AA54: =Z54+17600.66 -> 34891.154 | AD54: =R38-Z54 -> 448.25637 | AE54: =R41-AA54 -> 191.23637
A55: Chilled Water | B55: =X38 -> 178112.55 | D55: Chilled Water | G55: =B55/28 -> 6361.1625 | I55: Chilled Water | L55: =G55*J42 -> 178112.55 | N55: Chilled Water | R55: =W47 -> 194082.31 | U55: Chilled Water | W55: =L55-R55 -> -15969.755 | Z55: =L47*28 -> 194082.31 | AA55: =Z55+192611.25 -> 386693.56 | AD55: =X38-Z55 -> -15969.755 | AE55: =X41-AA55 -> -23204.105
...
