Workbook

Sheet Total
A1: Site Name | B1: Day | C1: Month | D1: Year | E1: Total Electricity Kwh | F1: Electricity Tariff ($/Kwh) | G1: Total Fuel Oil (Liter) | H1: Fuel Oil $/Liter | I1: Water Utility Supply (m3) m3 | J1: Water Utility Supply (m3) $/m3 | K1: Room Nights | L1: Total Guests
A2: Al Manakha Rotana Madinah | B2: 1 | C2: 3 | D2: 2025 | E2: ='Cost.2.25'!J8 -> 20524 | F2: ='Cost.2.25'!M8/'Cost.2.25'!J8 -> 0.34 | G2: ='Cost.2.25'!O8 -> 0 | H2: ='Cost.2.25'!S8/'Cost.2.25'!O8 -> #DIV/0! | I2: ='Cost.2.25'!U8 -> 0 | J2: ='Cost.2.25'!Y8/'Cost.2.25'!U8 -> #DIV/0! | K2: ='Cost.2.25'!F8 -> 232
A3: Al Manakha Rotana Madinah | B3: =B2+1 -> 2 | C3: 3 | D3: 2025 | E3: ='Cost.2.25'!J9 -> 19871 | F3: ='Cost.2.25'!M9/'Cost.2.25'!J9 -> 0.34 | G3: ='Cost.2.25'!O9 -> 0 | H3: ='Cost.2.25'!S9/'Cost.2.25'!O9 -> #DIV/0! | I3: ='Cost.2.25'!U9 -> 0 | J3: ='Cost.2.25'!Y9/'Cost.2.25'!U9 -> #DIV/0! | K3: ='Cost.2.25'!F9 -> 204
A4: Al Manakha Rotana Madinah | B4: =B3+1 -> 3 | C4: 3 | D4: 2025 | E4: ='Cost.2.25'!J10 -> 19821 | F4: ='Cost.2.25'!M10/'Cost.2.25'!J10 -> 0.34 | G4: ='Cost.2.25'!O10 -> 0 | H4: ='Cost.2.25'!S10/'Cost.2.25'!O10 -> #DIV/0! | I4: ='Cost.2.25'!U10 -> 0 | J4: ='Cost.2.25'!Y10/'Cost.2.25'!U10 -> #DIV/0! | K4: ='Cost.2.25'!F10 -> 195
A5: Al Manakha Rotana Madinah | B5: =B4+1 -> 4 | C5: 3 | D5: 2025 | E5: ='Cost.2.25'!J11 -> 20273 | F5: ='Cost.2.25'!M11/'Cost.2.25'!J11 -> 0.34 | G5: ='Cost.2.25'!O11 -> 0 | H5: ='Cost.2.25'!S11/'Cost.2.25'!O11 -> #DIV/0! | I5: ='Cost.2.25'!U11 -> 0 | J5: ='Cost.2.25'!Y11/'Cost.2.25'!U11 -> #DIV/0! | K5: ='Cost.2.25'!F11 -> 179
A6: Al Manakha Rotana Madinah | B6: =B5+1 -> 5 | C6: 3 | D6: 2025 | E6: ='Cost.2.25'!J12 -> 19570 | F6: ='Cost.2.25'!M12/'Cost.2.25'!J12 -> 0.34 | G6: ='Cost.2.25'!O12 -> 0 | H6: ='Cost.2.25'!S12/'Cost.2.25'!O12 -> #DIV/0! | I6: ='Cost.2.25'!U12 -> 0 | J6: ='Cost.2.25'!Y12/'Cost.2.25'!U12 -> #DIV/0! | K6: ='Cost.2.25'!F12 -> 231
A7: Al Manakha Rotana Madinah | B7: =B6+1 -> 6 | C7: 3 | D7: 2025 | E7: ='Cost.2.25'!J13 -> 19721 | F7: ='Cost.2.25'!M13/'Cost.2.25'!J13 -> 0.34 | G7: ='Cost.2.25'!O13 -> 0 | H7: ='Cost.2.25'!S13/'Cost.2.25'!O13 -> #DIV/0! | I7: ='Cost.2.25'!U13 -> 0 | J7: ='Cost.2.25'!Y13/'Cost.2.25'!U13 -> #DIV/0! | K7: ='Cost.2.25'!F13 -> 310
A8: Al Manakha Rotana Madinah | B8: =B7+1 -> 7 | C8: 3 | D8: 2025 | E8: ='Cost.2.25'!J14 -> 19621 | F8: ='Cost.2.25'!M14/'Cost.2.25'!J14 -> 0.34 | G8: ='Cost.2.25'!O14 -> 0 | H8: ='Cost.2.25'!S14/'Cost.2.25'!O14 -> #DIV/0! | I8: ='Cost.2.25'!U14 -> 0 | J8: ='Cost.2.25'!Y14/'Cost.2.25'!U14 -> #DIV/0! | K8: ='Cost.2.25'!F14 -> 288
A9: Al Manakha Rotana Madinah | B9: =B8+1 -> 8 | C9: 3 | D9: 2025 | E9: ='Cost.2.25'!J15 -> 19922 | F9: ='Cost.2.25'!M15/'Cost.2.25'!J15 -> 0.34 | G9: ='Cost.2.25'!O15 -> 0 | H9: ='Cost.2.25'!S15/'Cost.2.25'!O15 -> #DIV/0! | I9: ='Cost.2.25'!U15 -> 0 | J9: ='Cost.2.25'!Y15/'Cost.2.25'!U15 -> #DIV/0! | K9: ='Cost.2.25'!F15 -> 224
A10: Al Manakha Rotana Madinah | B10: =B9+1 -> 9 | C10: 3 | D10: 2025 | E10: ='Cost.2.25'!J16 -> 19721 | F10: ='Cost.2.25'!M16/'Cost.2.25'!J16 -> 0.34 | G10: ='Cost.2.25'!O16 -> 0 | H10: ='Cost.2.25'!S16/'Cost.2.25'!O16 -> #DIV/0! | I10: ='Cost.2.25'!U16 -> 190 | J10: ='Cost.2.25'!Y16/'Cost.2.25'!U16 -> 4.63 | K10: ='Cost.2.25'!F16 -> 218
A11: Al Manakha Rotana Madinah | B11: =B10+1 -> 10 | C11: 3 | D11: 2025 | E11: ='Cost.2.25'!J17 -> 19871 | F11: ='Cost.2.25'!M17/'Cost.2.25'!J17 -> 0.34 | G11: ='Cost.2.25'!O17 -> 0 | H11: ='Cost.2.25'!S17/'Cost.2.25'!O17 -> #DIV/0! | I11: ='Cost.2.25'!U17 -> 80 | J11: ='Cost.2.25'!Y17/'Cost.2.25'!U17 -> 4.63 | K11: ='Cost.2.25'!F17 -> 182
A12: Al Manakha Rotana Madinah | B12: =B11+1 -> 11 | C12: 3 | D12: 2025 | E12: ='Cost.2.25'!J18 -> 0 | F12: ='Cost.2.25'!M18/'Cost.2.25'!J18 -> #DIV/0! | G12: ='Cost.2.25'!O18 -> 0 | H12: ='Cost.2.25'!S18/'Cost.2.25'!O18 -> #DIV/0! | I12: ='Cost.2.25'!U18 -> 0 | J12: ='Cost.2.25'!Y18/'Cost.2.25'!U18 -> #DIV/0! | K12: ='Cost.2.25'!F18 -> 0
A13: Al Manakha Rotana Madinah | B13: =B12+1 -> 12 | C13: 3 | D13: 2025 | E13: ='Cost.2.25'!J19 -> 0 | F13: ='Cost.2.25'!M19/'Cost.2.25'!J19 -> #DIV/0! | G13: ='Cost.2.25'!O19 -> 0 | H13: ='Cost.2.25'!S19/'Cost.2.25'!O19 -> #DIV/0! | I13: ='Cost.2.25'!U19 -> 0 | J13: ='Cost.2.25'!Y19/'Cost.2.25'!U19 -> #DIV/0! | K13: ='Cost.2.25'!F19 -> 0
A14: Al Manakha Rotana Madinah | B14: =B13+1 -> 13 | C14: 3 | D14: 2025 | E14: ='Cost.2.25'!J20 -> 0 | F14: ='Cost.2.25'!M20/'Cost.2.25'!J20 -> #DIV/0! | G14: ='Cost.2.25'!O20 -> 0 | H14: ='Cost.2.25'!S20/'Cost.2.25'!O20 -> #DIV/0! | I14: ='Cost.2.25'!U20 -> 0 | J14: ='Cost.2.25'!Y20/'Cost.2.25'!U20 -> #DIV/0! | K14: ='Cost.2.25'!F20 -> 0
... A32: Al Manakha Rotana Madinah | B32: =B31+1 -> 31 | C32: 3 | D32: 2025 | E32: ='Cost.2.25'!J38 -> 0 | F32: ='Cost.2.25'!M38/'Cost.2.25'!J38 -> #DIV/0! | G32: ='Cost.2.25'!O38 -> 0 | H32: ='Cost.2.25'!S38/'Cost.2.25'!O38 -> #DIV/0! | I32: ='Cost.2.25'!U38 -> 0 | J32: ='Cost.2.25'!Y38/'Cost.2.25'!U38 -> #DIV/0! | K32: ='Cost.2.25'!F38 -> 0

Sheet Cost.2.25
H1: =H8*31 -> 12862 | K1: =K8*31 -> 373723 | P1: =P8*31 -> 300 | Q1: =Q8*31 -> 240 | V1: =V8*31 -> 5364 | W1: =W8*31 -> 48280
A2: Energy Cost February 2025 | AB2: Energy Cost - February 2025
B3: 1 | C3: 2 | D3: 3 | E3: 4 | F3: 5 | G3: 6 | H3: 7 | I3: 8 | J3: 9 | K3: 10 | L3: 11 | M3: 12 | N3: 13 | O3: 14 | P3: 15 | Q3: 17 | R3: 18 | S3: 19 | T3: 20 | U3: 21 | V3: 22 | W3: 23 | X3: 24 | Y3: 25 | Z3: 26 | AA3: 46 | AB3: 47 | AC3: 48 | AD3: 49 | AE3: 50 | AF3: 53 | AG3: 54 | AH3: 55 | AI3: 56 | AJ3: 57 | AK3: 58 | AL3: 59 | AM3: 60
J5: ELECTRICITY | O5: FUEL | U5: WATER | AB5: ELECTRICITY | AD5: WATER | AG5: LAST YEAR TOTAL ENERGY SAR | AH5: BUDGET TOTAL ENERGY SAR. | AI5: ACTUAL TOTAL ENERGY SAR | AK5: ENERGY LAST YEAR / OCCUPIED ROOM | AL5: ENERGY BUDGET / OCCUPIED ROOM | AM5: ENERGY ACTUAL / OCCUPIED ROOM
B6: DATE | D6: Occ. | F6: Occupied Rooms | H6: Occupied Rooms Budget | J6: CONSUMP. KWH | K6: BUDGET SAR | L6: LAST YEAR ACTUAL SAR | M6: ACTUAL SAR | O6: CONSUMP. LITRE | P6: BUDGET LITRE | Q6: BUDGET SAR | R6: LAST YEAR ACTUAL SAR | S6: ACTUAL SAR | U6: CONSUMP. M³ | V6: BUDGET M³ | W6: BUDGET SAR. | X6: LAST YEAR ACTUAL SAR | Y6: ACTUAL SAR | AB6: KWH / Occupied Room | AC6: SAR / Occupied Room | AD6: Cu.Mt. / Occupied Room | AE6: SAR/ Occupied Room
B8: 45658 | D8: ='Reading.2.25'!AC6 -> 0 | F8: ='Reading.2.25'!AH6 -> 232 | H8: ='Reading.2.25'!AJ6 -> 414.90323 | J8: ='Reading.2.25'!S6 -> 20524 | K8: =373723/31 -> 12055.581 | L8: =#REF! -> #REF! | M8: =J8*0.34 -> 6978.16 | O8: ='Reading.2.25'!P6 -> 0 | P8: =300/31 -> 9.6774194 | Q8: =240/31 -> 7.7419355 | R8: =#REF! -> #REF! | S8: =O8*5.86 -> 0 | U8: ='Reading.2.25'!G6 -> 0 | V8: ='Reading.2.25'!H6 -> 173.03226 | W8: =48280/31 -> 1557.4194 | X8: =#REF! -> #REF! | Y8: ='Reading.2.25'!G6*4.63 -> 0 | AB8: =J8/F8 -> 88.465517 | AC8: =(M8+S8)/F8 -> 30.078276 | AD8: =U8/F8 -> 0 | AE8: =Y8/F8 -> 0 | AG8: =#REF! -> #REF! | AH8: =W8+Q8+K8 -> 13620.742 | AI8: =Y8+S8+M8 -> 6978.16 | AK8: =#REF! -> #REF! | AL8: =AH8/H8 -> 32.82872 | AM8: =(M8+Y8+S8)/F8 -> 30.078276
B9: 45659 | D9: ='Reading.2.25'!AD7 -> 0.398 | F9: ='Reading.2.25'!AH7 -> 204 | H9: ='Reading.2.25'!AJ7 -> 414.90323 | J9: ='Reading.2.25'!S7 -> 19871 | K9: =373723/31 -> 12055.581 | L9: =#REF! -> #REF! | M9: =J9*0.34 -> 6756.14 | O9: ='Reading.2.25'!P7 -> 0 | P9: =300/31 -> 9.6774194 | Q9: =240/31 -> 7.7419355 | R9: =#REF! -> #REF! | S9: =O9*5.86 -> 0 | U9: ='Reading.2.25'!G7 -> 0 | V9: ='Reading.2.25'!H7 -> 173.03226 | W9: =48280/31 -> 1557.4194 | X9: =#REF! -> #REF! | Y9: ='Reading.2.25'!G7*4.63 -> 0 | AB9: =J9/F9 -> 97.406863 | AC9: =(M9+S9)/F9 -> 33.118333 | AD9: =U9/F9 -> 0 | AE9: =Y9/F9 -> 0 | AG9: =#REF! -> #REF! | AH9: =W9+Q9+K9 -> 13620.742 | AI9: =Y9+S9+M9 -> 6756.14 | AK9: =#REF! -> #REF! | AL9: =AH9/H9 -> 32.82872 | AM9: =(M9+Y9+S9)/F9 -> 33.118333
B10: 45660 | D10: ='Reading.2.25'!AD8 -> 0.381 | F10: ='Reading.2.25'!AH8 -> 195 | H10: ='Reading.2.25'!AJ8 -> 414.90323 | J10: ='Reading.2.25'!S8 -> 19821 | K10: =373723/31 -> 12055.581 | L10: =#REF! -> #REF! | M10: =J10*0.34 -> 6739.14 | O10: ='Reading.2.25'!P8 -> 0 | P10: =300/31 -> 9.6774194 | Q10: =240/31 -> 7.7419355 | R10: =#REF! -> #REF! | S10: =O10*5.86 -> 0 | U10: ='Reading.2.25'!G8 -> 0 | V10: ='Reading.2.25'!H8 -> 173.03226 | W10: =48280/31 -> 1557.4194 | X10: =#REF! -> #REF! | Y10: ='Reading.2.25'!G8*4.63 -> 0 | AB10: =J10/F10 -> 101.64615 | AC10: =(M10+S10)/F10 -> 34.559692 | AD10: =U10/F10 -> 0 | AE10: =Y10/F10 -> 0 | AG10: =#REF! -> #REF! | AH10: =W10+Q10+K10 -> 13620.742 | AI10: =Y10+S10+M10 -> 6739.14 | AK10: =#REF! -> #REF! | AL10: =AH10/H10 -> 32.82872 | AM10: =(M10+Y10+S10)/F10 -> 34.559692
B11: 45661 | D11: ='Reading.2.25'!AD9 -> 0.35 | F11: ='Reading.2.25'!AH9 -> 179 | H11: ='Reading.2.25'!AJ9 -> 414.90323 | J11: ='Reading.2.25'!S9 -> 20273 | K11: =373723/31 -> 12055.581 | L11: =#REF! -> #REF! | M11: =J11*0.34 -> 6892.82 | O11: ='Reading.2.25'!P9 -> 0 | P11: =300/31 -> 9.6774194 | Q11: =240/31 -> 7.7419355 | R11: =#REF! -> #REF! | S11: =O11*5.86 -> 0 | U11: ='Reading.2.25'!G9 -> 0 | V11: ='Reading.2.25'!H9 -> 173.03226 | W11: =48280/31 -> 1557.4194 | X11: =#REF! -> #REF! | Y11: ='Reading.2.25'!G9*4.63 -> 0 | AB11: =J11/F11 -> 113.25698 | AC11: =(M11+S11)/F11 -> 38.507374 | AD11: =U11/F11 -> 0 | AE11: =Y11/F11 -> 0 | AG11: =#REF! -> #REF! | AH11: =W11+Q11+K11 -> 13620.742 | AI11: =Y11+S11+M11 -> 6892.82 | AK11: =#REF! -> #REF! | AL11: =AH11/H11 -> 32.82872 | AM11: =(M11+Y11+S11)/F11 -> 38.507374
B12: 45662 | D12: ='Reading.2.25'!AD10 -> 0.451 | F12: ='Reading.2.25'!AH10 -> 231 | H12: ='Reading.2.25'!AJ10 -> 414.90323 | J12: ='Reading.2.25'!S10 -> 19570 | K12: =373723/31 -> 12055.581 | L12: =#REF! -> #REF! | M12: =J12*0.34 -> 6653.8 | O12: ='Reading.2.25'!P10 -> 0 | P12: =300/31 -> 9.6774194 | Q12: =240/31 -> 7.7419355 | R12: =#REF! -> #REF! | S12: =O12*5.86 -> 0 | U12: ='Reading.2.25'!G10 -> 0 | V12: ='Reading.2.25'!H10 -> 173.03226 | W12: =48280/31 -> 1557.4194 | X12: =#REF! -> #REF! | Y12: ='Reading.2.25'!G10*4.63 -> 0 | AB12: =J12/F12 -> 84.718615 | AC12: =(M12+S12)/F12 -> 28.804329 | AD12: =U12/F12 -> 0 | AE12: =Y12/F12 -> 0 | AG12: =#REF! -> #REF! | AH12: =W12+Q12+K12 -> 13620.742 | AI12: =Y12+S12+M12 -> 6653.8 | AK12: =#REF! -> #REF! | AL12: =AH12/H12 -> 32.82872 | AM12: =(M12+Y12+S12)/F12 -> 28.804329
B13: 45663 | D13: ='Reading.2.25'!AD11 -> 0.605 | F13: ='Reading.2.25'!AH11 -> 310 | H13: ='Reading.2.25'!AJ11 -> 414.90323 | J13: ='Reading.2.25'!S11 -> 19721 | K13: =373723/31 -> 12055.581 | L13: =#REF! -> #REF! | M13: =J13*0.34 -> 6705.14 | O13: ='Reading.2.25'!P11 -> 0 | P13: =300/31 -> 9.6774194 | Q13: =240/31 -> 7.7419355 | R13: =#REF! -> #REF! | S13: =O13*5.86 -> 0 | U13: ='Reading.2.25'!G11 -> 0 | V13: ='Reading.2.25'!H11 -> 173.03226 | W13: =48280/31 -> 1557.4194 | X13: =#REF! -> #REF! | Y13: ='Reading.2.25'!G11*4.63 -> 0 | AB13: =J13/F13 -> 63.616129 | AC13: =(M13+S13)/F13 -> 21.629484 | AD13: =U13/F13 -> 0 | AE13: =Y13/F13 -> 0 | AG13: =#REF! -> #REF! | AH13: =W13+Q13+K13 -> 13620.742 | AI13: =Y13+S13+M13 -> 6705.14 | AK13: =#REF! -> #REF! | AL13: =AH13/H13 -> 32.82872 | AM13: =(M13+Y13+S13)/F13 -> 21.629484
B14: 45664 | D14: ='Reading.2.25'!AD12 -> 0.563 | F14: ='Reading.2.25'!AH12 -> 288 | H14: ='Reading.2.25'!AJ12 -> 414.90323 | J14: ='Reading.2.25'!S12 -> 19621 | K14: =373723/31 -> 12055.581 | L14: =#REF! -> #REF! | M14: =J14*0.34 -> 6671.14 | O14: ='Reading.2.25'!P12 -> 0 | P14: =300/31 -> 9.6774194 | Q14: =240/31 -> 7.7419355 | R14: =#REF! -> #REF! | S14: =O14*5.86 -> 0 | U14: ='Reading.2.25'!G12 -> 0 | V14: ='Reading.2.25'!H12 -> 173.03226 | W14: =48280/31 -> 1557.4194 | X14: =#REF! -> #REF! | Y14: ='Reading.2.25'!G12*4.63 -> 0 | AB14: =J14/F14 -> 68.128472 | AC14: =(M14+S14)/F14 -> 23.163681 | AD14: =U14/F14 -> 0 | AE14: =Y14/F14 -> 0 | AG14: =#REF! -> #REF! | AH14: =W14+Q14+K14 -> 13620.742 | AI14: =Y14+S14+M14 -> 6671.14 | AK14: =#REF! -> #REF! | AL14: =AH14/H14 -> 32.82872 | AM14: =(M14+Y14+S14)/F14 -> 23.163681
B15: 45665 | D15: ='Reading.2.25'!AD13 -> 0.438 | F15: ='Reading.2.25'!AH13 -> 224 | H15: ='Reading.2.25'!AJ13 -> 414.90323 | J15: ='Reading.2.25'!S13 -> 19922 | K15: =373723/31 -> 12055.581 | L15: =#REF! -> #REF! | M15: =J15*0.34 -> 6773.48 | O15: ='Reading.2.25'!P13 -> 0 | P15: =300/31 -> 9.6774194 | Q15: =240/31 -> 7.7419355 | R15: =#REF! -> #REF! | S15: =O15*5.86 -> 0 | U15: ='Reading.2.25'!G13 -> 0 | V15: ='Reading.2.25'!H13 -> 173.03226 | W15: =48280/31 -> 1557.4194 | X15: =#REF! -> #REF! | Y15: ='Reading.2.25'!G13*4.63 -> 0 | AB15: =J15/F15 -> 88.9375 | AC15: =(M15+S15)/F15 -> 30.23875 | AD15: =U15/F15 -> 0 | AE15: =Y15/F15 -> 0 | AG15: =#REF! -> #REF! | AH15: =W15+Q15+K15 -> 13620.742 | AI15: =Y15+S15+M15 -> 6773.48 | AK15: =#REF! -> #REF! | AL15: =AH15/H15 -> 32.82872 | AM15: =(M15+Y15+S15)/F15 -> 30.23875
B16: 45666 | D16: ='Reading.2.25'!AD14 -> 0.426 | F16: ='Reading.2.25'!AH14 -> 218 | H16: ='Reading.2.25'!AJ14 -> 414.90323 | J16: ='Reading.2.25'!S14 -> 19721 | K16: =373723/31 -> 12055.581 | L16: =#REF! -> #REF! | M16: =J16*0.34 -> 6705.14 | O16: ='Reading.2.25'!P14 -> 0 | P16: =300/31 -> 9.6774194 | Q16: =240/31 -> 7.7419355 | R16: =#REF! -> #REF! | S16: =O16*5.86 -> 0 | U16: ='Reading.2.25'!G14 -> 190 | V16: ='Reading.2.25'!H14 -> 173.03226 | W16: =48280/31 -> 1557.4194 | X16: =#REF! -> #REF! | Y16: ='Reading.2.25'!G14*4.63 -> 879.7 | AB16: =J16/F16 -> 90.463303 | AC16: =(M16+S16)/F16 -> 30.757523 | AD16: =U16/F16 -> 0.87155963 | AE16: =Y16/F16 -> 4.0353211 | AG16: =#REF! -> #REF! | AH16: =W16+Q16+K16 -> 13620.742 | AI16: =Y16+S16+M16 -> 7584.84 | AK16: =#REF! -> #REF! | AL16: =AH16/H16 -> 32.82872 | AM16: =(M16+Y16+S16)/F16 -> 34.792844
B17: 45667 | D17: ='Reading.2.25'!AD15 -> 0.355 | F17: ='Reading.2.25'!AH15 -> 182 | H17: ='Reading.2.25'!AJ15 -> 414.90323 | J17: ='Reading.2.25'!S15 -> 19871 | K17: =373723/31 -> 12055.581 | L17: =#REF! -> #REF! | M17: =J17*0.34 -> 6756.14 | O17: ='Reading.2.25'!P15 -> 0 | P17: =300/31 -> 9.6774194 | Q17: =240/31 -> 7.7419355 | R17: =#REF! -> #REF! | S17: =O17*5.86 -> 0 | U17: ='Reading.2.25'!G15 -> 80 | V17: ='Reading.2.25'!H15 -> 173.03226 | W17: =48280/31 -> 1557.4194 | X17: =#REF! -> #REF! | Y17: ='Reading.2.25'!G15*4.63 -> 370.4 | AB17: =J17/F17 -> 109.18132 | AC17: =(M17+S17)/F17 -> 37.121648 | AD17: =U17/F17 -> 0.43956044 | AE17: =Y17/F17 -> 2.0351648 | AG17: =#REF! -> #REF! | AH17: =W17+Q17+K17 -> 13620.742 | AI17: =Y17+S17+M17 -> 7126.54 | AK17: =#REF! -> #REF! | AL17: =AH17/H17 -> 32.82872 | AM17: =(M17+Y17+S17)/F17 -> 39.156813
B18: 45668 | D18: ='Reading.2.25'!AD16 -> 0 | F18: ='Reading.2.25'!AH16 -> 0 | H18: ='Reading.2.25'!AJ16 -> 414.90323 | J18: ='Reading.2.25'!S16 -> 0 | K18: =373723/31 -> 12055.581 | L18: =#REF! -> #REF! | M18: =J18*0.34 -> 0 | O18: ='Reading.2.25'!P16 -> 0 | P18: =300/31 -> 9.6774194 | Q18: =240/31 -> 7.7419355 | R18: =#REF! -> #REF! | S18: =O18*5.86 -> 0 | U18: ='Reading.2.25'!G16 -> 0 | V18: ='Reading.2.25'!H16 -> 173.03226 | W18: =48280/31 -> 1557.4194 | X18: =#REF! -> #REF! | Y18: ='Reading.2.25'!G16*4.63 -> 0 | AB18: =J18/F18 -> #DIV/0! | AC18: =(M18+S18)/F18 -> #DIV/0! | AD18: =U18/F18 -> #DIV/0! | AE18: =Y18/F18 -> #DIV/0! | AG18: =#REF! -> #REF! | AH18: =W18+Q18+K18 -> 13620.742 | AI18: =Y18+S18+M18 -> 0 | AK18: =#REF! -> #REF! | AL18: =AH18/H18 -> 32.82872 | AM18: =(M18+Y18+S18)/F18 -> #DIV/0!
B19: 45669 | D19: ='Reading.2.25'!AD17 -> 0 | F19: ='Reading.2.25'!AH17 -> 0 | H19: ='Reading.2.25'!AJ17 -> 414.90323 | J19: ='Reading.2.25'!S17 -> 0 | K19: =373723/31 -> 12055.581 | L19: =#REF! -> #REF! | M19: =J19*0.34 -> 0 | O19: ='Reading.2.25'!P17 -> 0 | P19: =300/31 -> 9.6774194 | Q19: =240/31 -> 7.7419355 | R19: =#REF! -> #REF! | S19: =O19*5.86 -> 0 | U19: ='Reading.2.25'!G17 -> 0 | V19: ='Reading.2.25'!H17 -> 173.03226 | W19: =48280/31 -> 1557.4194 | X19: =#REF! -> #REF! | Y19: ='Reading.2.25'!G17*4.63 -> 0 | AB19: =J19/F19 -> #DIV/0! | AC19: =(M19+S19)/F19 -> #DIV/0! | AD19: =U19/F19 -> #DIV/0! | AE19: =Y19/F19 -> #DIV/0! | AG19: =#REF! -> #REF! | AH19: =W19+Q19+K19 -> 13620.742 | AI19: =Y19+S19+M19 -> 0 | AK19: =#REF! -> #REF! | AL19: =AH19/H19 -> 32.82872 | AM19: =(M19+Y19+S19)/F19 -> #DIV/0!
B20: 45670 | D20: ='Reading.2.25'!AD18 -> 0 | F20: ='Reading.2.25'!AH18 -> 0 | H20: ='Reading.2.25'!AJ18 -> 414.90323 | J20: ='Reading.2.25'!S18 -> 0 | K20: =373723/31 -> 12055.581 | L20: =#REF! -> #REF! | M20: =J20*0.34 -> 0 | O20: ='Reading.2.25'!P18 -> 0 | P20: =300/31 -> 9.6774194 | Q20: =240/31 -> 7.7419355 | R20: =#REF! -> #REF! | S20: =O20*5.86 -> 0 | U20: ='Reading.2.25'!G18 -> 0 | V20: ='Reading.2.25'!H18 -> 173.03226 | W20: =48280/31 -> 1557.4194 | X20: =#REF! -> #REF! | Y20: ='Reading.2.25'!G18*4.63 -> 0 | AB20: =J20/F20 -> #DIV/0! | AC20: =(M20+S20)/F20 -> #DIV/0! | AD20: =U20/F20 -> #DIV/0! | AE20: =Y20/F20 -> #DIV/0! | AG20: =#REF! -> #REF! | AH20: =W20+Q20+K20 -> 13620.742 | AI20: =Y20+S20+M20 -> 0 | AK20: =#REF! -> #REF! | AL20: =AH20/H20 -> 32.82872 | AM20: =(M20+Y20+S20)/F20 -> #DIV/0!
... B29: 45679 | D29: ='Reading.2.25'!AD27 -> 0 | F29: ='Reading.2.25'!AH27 -> 0 | H29: ='Reading.2.25'!AJ27 -> 414.90323 | J29: ='Reading.2.25'!S27 -> 0 | K29: =373723/31 -> 12055.581 | L29: =#REF! -> #REF! | M29: =J29*0.34 -> 0 | O29: ='Reading.2.25'!P27 -> 0 | P29: =300/31 -> 9.6774194 | Q29: =240/31 -> 7.7419355 | R29: =#REF! -> #REF! | S29: =O29*5.86 -> 0 | U29: ='Reading.2.25'!G27 -> 0 | V29: ='Reading.2.25'!H27 -> 173.03226 | W29: =48280/31 -> 1557.4194 | X29: =#REF! -> #REF! | Y29: ='Reading.2.25'!G27*4.63 -> 0 | AB29: =J29/F29 -> #DIV/0! | AC29: =(M29+S29)/F29 -> #DIV/0! | AD29: =U29/F29 -> #DIV/0! | AE29: =Y29/F29 -> #DIV/0! | AG29: =#REF! -> #REF! | AH29: =W29+Q29+K29 -> 13620.742 | AI29: =Y29+S29+M29 -> 0 | AK29: =#REF! -> #REF! | AL29: =AH29/H29 -> 32.82872 | AM29: =(M29+Y29+S29)/F29 -> #DIV/0!
B30: 45680 | D30: ='Reading.2.25'!AD28 -> 0 | F30: ='Reading.2.25'!AH28 -> 0 | H30: ='Reading.2.25'!AJ28 -> 414.90323 | J30: ='Reading.2.25'!S28 -> 0 | K30: =373723/31 -> 12055.581 | L30: =#REF! -> #REF! | M30: =J30*1.3 -> 0 | O30: ='Reading.2.25'!P28 -> 0 | P30: =300/31 -> 9.6774194 | Q30: =240/31 -> 7.7419355 | R30: =#REF! -> #REF! | S30: =O30*5.86 -> 0 | U30: ='Reading.2.25'!G28 -> 0 | V30: ='Reading.2.25'!H28 -> 173.03226 | W30: =48280/31 -> 1557.4194 | X30: =#REF! -> #REF! | Y30: ='Reading.2.25'!G28*4.63 -> 0 | AB30: =J30/F30 -> #DIV/0! | AC30: =(M30+S30)/F30 -> #DIV/0! | AD30: =U30/F30 -> #DIV/0! | AE30: =Y30/F30 -> #DIV/0! | AG30: =#REF! -> #REF! | AH30: =W30+Q30+K30 -> 13620.742 | AI30: =Y30+S30+M30 -> 0 | AK30: =#REF! -> #REF! | AL30: =AH30/H30 -> 32.82872 | AM30: =(M30+Y30+S30)/F30 -> #DIV/0!
B31: 45681 | D31: ='Reading.2.25'!AD29 -> 0 | F31: ='Reading.2.25'!AH29 -> 0 | H31: ='Reading.2.25'!AJ29 -> 414.90323 | J31: ='Reading.2.25'!S29 -> 0 | K31: =373723/31 -> 12055.581 | L31: =#REF! -> #REF! | M31: =J31*1.3 -> 0 | O31: ='Reading.2.25'!P29 -> 0 | P31: =300/31 -> 9.6774194 | Q31: =240/31 -> 7.7419355 | R31: =#REF! -> #REF! | S31: =O31*5.86 -> 0 | U31: ='Reading.2.25'!G29 -> 0 | V31: ='Reading.2.25'!H29 -> 173.03226 | W31: =48280/31 -> 1557.4194 | X31: =#REF! -> #REF! | Y31: ='Reading.2.25'!G29*4.63 -> 0 | AB31: =J31/F31 -> #DIV/0! | AC31: =(M31+S31)/F31 -> #DIV/0! | AD31: =U31/F31 -> #DIV/0! | AE31: =Y31/F31 -> #DIV/0! | AG31: =#REF! -> #REF! | AH31: =W31+Q31+K31 -> 13620.742 | AI31: =Y31+S31+M31 -> 0 | AK31: =#REF! -> #REF! | AL31: =AH31/H31 -> 32.82872 | AM31: =(M31+Y31+S31)/F31 -> #DIV/0!
B32: 45682 | D32: ='Reading.2.25'!AD30 -> 0 | F32: ='Reading.2.25'!AH30 -> 0 | H32: ='Reading.2.25'!AJ30 -> 414.90323 | J32: ='Reading.2.25'!S30 -> 0 | K32: =373723/31 -> 12055.581 | L32: =#REF! -> #REF! | M32: =J32*1.3 -> 0 | O32: ='Reading.2.25'!P30 -> 0 | P32: =300/31 -> 9.6774194 | Q32: =240/31 -> 7.7419355 | R32: =#REF! -> #REF! | S32: =O32*5.86 -> 0 | U32: ='Reading.2.25'!G30 -> 0 | V32: ='Reading.2.25'!H30 -> 173.03226 | W32: =48280/31 -> 1557.4194 | X32: =#REF! -> #REF! | Y32: ='Reading.2.25'!G30*4.63 -> 0 | AB32: =J32/F32 -> #DIV/0! | AC32: =(M32+S32)/F32 -> #DIV/0! | AD32: =U32/F32 -> #DIV/0! | AE32: =Y32/F32 -> #DIV/0! | AG32: =#REF! -> #REF! | AH32: =W32+Q32+K32 -> 13620.742 | AI32: =Y32+S32+M32 -> 0 | AK32: =#REF! -> #REF! | AL32: =AH32/H32 -> 32.82872 | AM32: =(M32+Y32+S32)/F32 -> #DIV/0!
B33: 45683 | D33: ='Reading.2.25'!AD31 -> 0 | F33: ='Reading.2.25'!AH31 -> 0 | H33: ='Reading.2.25'!AJ31 -> 414.90323 | J33: ='Reading.2.25'!S31 -> 0 | K33: =373723/31 -> 12055.581 | L33: =#REF! -> #REF! | M33: =J33*1.3 -> 0 | O33: ='Reading.2.25'!P31 -> 0 | P33: =300/31 -> 9.6774194 | Q33: =240/31 -> 7.7419355 | R33: =#REF! -> #REF! | S33: =O33*5.86 -> 0 | U33: ='Reading.2.25'!G31 -> 0 | V33: ='Reading.2.25'!H31 -> 173.03226 | W33: =48280/31 -> 1557.4194 | X33: =#REF! -> #REF! | Y33: ='Reading.2.25'!G31*4.63 -> 0 | AB33: =J33/F33 -> #DIV/0! | AC33: =(M33+S33)/F33 -> #DIV/0! | AD33: =U33/F33 -> #DIV/0! | AE33: =Y33/F33 -> #DIV/0! | AG33: =#REF! -> #REF! | AH33: =W33+Q33+K33 -> 13620.742 | AI33: =Y33+S33+M33 -> 0 | AK33: =#REF! -> #REF! | AL33: =AH33/H33 -> 32.82872 | AM33: =(M33+Y33+S33)/F33 -> #DIV/0!
B34: 45684 | D34: ='Reading.2.25'!AD32 -> 0 | F34: ='Reading.2.25'!AH32 -> 0 | H34: ='Reading.2.25'!AJ32 -> 414.90323 | J34: ='Reading.2.25'!S32 -> 0 | K34: =373723/31 -> 12055.581 | L34: =#REF! -> #REF! | M34: =J34*1.3 -> 0 | O34: ='Reading.2.25'!P32 -> 0 | P34: =300/31 -> 9.6774194 | Q34: =240/31 -> 7.7419355 | R34: =#REF! -> #REF! | S34: =O34*5.86 -> 0 | U34: ='Reading.2.25'!G32 -> 0 | V34: ='Reading.2.25'!H32 -> 173.03226 | W34: =48280/31 -> 1557.4194 | X34: =#REF! -> #REF! | Y34: ='Reading.2.25'!G32*4.63 -> 0 | AB34: =J34/F34 -> #DIV/0! | AC34: =(M34+S34)/F34 -> #DIV/0! | AD34: =U34/F34 -> #DIV/0! | AE34: =Y34/F34 -> #DIV/0! | AG34: =#REF! -> #REF! | AH34: =W34+Q34+K34 -> 13620.742 | AI34: =Y34+S34+M34 -> 0 | AK34: =#REF! -> #REF! | AL34: =AH34/H34 -> 32.82872 | AM34: =(M34+Y34+S34)/F34 -> #DIV/0!
B35: 45685 | D35: ='Reading.2.25'!AD33 -> 0 | F35: ='Reading.2.25'!AH33 -> 0 | H35: ='Reading.2.25'!AJ33 -> 414.90323 | J35: ='Reading.2.25'!S33 -> 0 | K35: =373723/31 -> 12055.581 | L35: =#REF! -> #REF! | M35: =J35*1.3 -> 0 | O35: ='Reading.2.25'!P33 -> 0 | P35: =300/31 -> 9.6774194 | Q35: =240/31 -> 7.7419355 | R35: =#REF! -> #REF! | S35: =O35*5.86 -> 0 | U35: ='Reading.2.25'!G33 -> 0 | V35: ='Reading.2.25'!H33 -> 173.03226 | W35: =48280/31 -> 1557.4194 | X35: =#REF! -> #REF! | Y35: ='Reading.2.25'!G33*4.63 -> 0 | AB35: =J35/F35 -> #DIV/0! | AC35: =(M35+S35)/F35 -> #DIV/0! | AD35: =U35/F35 -> #DIV/0! | AE35: =Y35/F35 -> #DIV/0! | AG35: =#REF! -> #REF! | AH35: =W35+Q35+K35 -> 13620.742 | AI35: =Y35+S35+M35 -> 0 | AK35: =#REF! -> #REF! | AL35: =AH35/H35 -> 32.82872 | AM35: =(M35+Y35+S35)/F35 -> #DIV/0!
B36: 45686 | D36: ='Reading.2.25'!AD34 -> 0 | F36: ='Reading.2.25'!AH34 -> 0 | H36: ='Reading.2.25'!AJ34 -> 414.90323 | J36: ='Reading.2.25'!S34 -> 0 | K36: =373723/31 -> 12055.581 | L36: =#REF! -> #REF! | M36: =J36*1.3 -> 0 | O36: ='Reading.2.25'!P34 -> 0 | P36: =300/31 -> 9.6774194 | Q36: =240/31 -> 7.7419355 | R36: =#REF! -> #REF! | S36: =O36*5.86 -> 0 | U36: ='Reading.2.25'!G34 -> 0 | V36: ='Reading.2.25'!H34 -> 173.03226 | W36: =48280/31 -> 1557.4194 | X36: =#REF! -> #REF! | Y36: ='Reading.2.25'!G34*4.63 -> 0 | AB36: =J36/F36 -> #DIV/0! | AC36: =(M36+S36)/F36 -> #DIV/0! | AD36: =U36/F36 -> #DIV/0! | AE36: =Y36/F36 -> #DIV/0! | AG36: =#REF! -> #REF! | AH36: =W36+Q36+K36 -> 13620.742 | AI36: =Y36+S36+M36 -> 0 | AK36: =#REF! -> #REF! | AL36: =AH36/H36 -> 32.82872 | AM36: =(M36+Y36+S36)/F36 -> #DIV/0!
B37: 45687 | D37: ='Reading.2.25'!AD35 -> 0 | F37: ='Reading.2.25'!AH35 -> 0 | H37: ='Reading.2.25'!AJ35 -> 414.90323 | J37: ='Reading.2.25'!S35 -> 0 | K37: =373723/31 -> 12055.581 | L37: =#REF! -> #REF! | M37: =J37*1.3 -> 0 | O37: ='Reading.2.25'!P35 -> 0 | P37: =300/31 -> 9.6774194 | Q37: =240/31 -> 7.7419355 | R37: =#REF! -> #REF! | S37: =O37*5.86 -> 0 | U37: ='Reading.2.25'!G35 -> 0 | V37: ='Reading.2.25'!H35 -> 173.03226 | W37: =48280/31 -> 1557.4194 | X37: =#REF! -> #REF! | Y37: ='Reading.2.25'!G35*4.63 -> 0 | AB37: =J37/F37 -> #DIV/0! | AC37: =(M37+S37)/F37 -> #DIV/0! | AD37: =U37/F37 -> #DIV/0! | AE37: =Y37/F37 -> #DIV/0! | AG37: =#REF! -> #REF! | AH37: =W37+Q37+K37 -> 13620.742 | AI37: =Y37+S37+M37 -> 0 | AK37: =#REF! -> #REF! | AL37: =AH37/H37 -> 32.82872 | AM37: =(M37+Y37+S37)/F37 -> #DIV/0!
B38: 45688 | V38: ='Reading.2.25'!H36 -> 173.03226 | W38: =48280/31 -> 1557.4194 | AM38: =(M38+Y38+S38)/F38 -> #DIV/0!
B39: TOTAL | D39: =AVERAGE(D8:D38) -> 0.13223333 | F39: =SUM(F8:F38) -> 2263 | H39: =SUM(H8:H38) -> 12447.097 | J39: =SUM(J8:J38) -> 198915 | K39: =SUM(K8:K38) -> 361667.42 | L39: =SUM(L8:L38) -> #REF! | M39: =SUM(M8:M38) -> 67631.1 | O39: =SUM(O8:O38) -> 0 | P39: =SUM(P8:P38) -> 290.32258 | Q39: =SUM(Q8:Q38) -> 232.25806 | R39: =SUM(R8:R38) -> #REF! | S39: =SUM(S8:S38) -> 0 | U39: =SUM(U8:U38) -> 270 | V39: =SUM(V8:V38) -> 5364 | W39: =SUM(W8:W38) -> 48280 | X39: =SUM(X8:X38) -> #REF! | Y39: =SUM(Y8:Y38) -> 1250.1 | AB39: =AVERAGE(AB8:AB38) -> #DIV/0! | AC39: =AVERAGE(AC8:AC38) -> #DIV/0! | AD39: =AVERAGE(AD8:AD38) -> #DIV/0! | AE39: =AVERAGE(AE8:AE38) -> #DIV/0! | AG39: =SUM(AG8:AG38) -> #REF! | AH39: =SUM(AH8:AH38) -> 408622.26 | AI39: =SUM(AI8:AI38) -> 68881.2 | AK39: =AG39/'Reading.2.25'!AI37 -> #REF! | AL39: =AVERAGE(AL8:AL38) -> 32.82872 | AM39: =AVERAGE(AM8:AM38) -> #DIV/0!

Sheet Reading.2.25
A1: 1 | B1: 2 | E1: 3 | F1: 4 | G1: 7 | I1: 8 | J1: 17 | K1: 18 | O1: 19 | P1: 20 | Q1: 21 | R1: 22 | S1: 24 | T1: 25 | V1: 25 | Y1: 30 | Z1: 31 | AA1: 32 | AB1: 33 | AC1: 34 | AD1: 35 | AE1: 36 | AF1: 37 | AG1: 38 | AH1: 39 | AI1: 40 | AJ1: 41 | AK1: 45 | AL1: 48 | AM1: 54 | AN1: 55 | AO1: 56 | AP1: 57 | AQ1: 58 | AR1: 59 | AS1: 60 | AT1: 61 | AU1: 62 | AV1: 63 | AW1: 64 | AX1: 65 | AY1: 66 | AZ1: 67 | BA1: 68 | BB1: 69 | BC1: 70 | BD1: 71 | BE1: 72 | BF1: 73 | BG1: 74 | BH1: 104 | BI1: 105 | BJ1: 106 | BK1: 107 | BL1: 108 | BM1: 109 | BN1: 110 | BO1: 111 | BP1: 112 | BQ1: 113 | BR1: 114 | BS1: 115 | BT1: 116 | BU1: 117 | BV1: 118 | BW1: 119 | BX1: 120 | BY1: 121 | BZ1: 122 | CA1: 123 | CB1: 124 | CC1: 121 | CD1: 122 | CE1: 123 | CF1: 120 | CG1: 121 | CH1: 122 | CI1: 123 | CJ1: 120 | CK1: 121 | CL1: 122 | CM1: 123 | CN1: 120 | CO1: 121 | CP1: 122 | CQ1: 123 | CU1: 125 | CY1: 126 | DC1: 127 | DD1: 128
B2: WATER | K2: FUEL | Z2: TOTAL KWH | AD2: Occupancy % | AH2: Rooms Occupied | AN2: Weather Temperature | AW2: Available Rooms | AY2: Water Sold Last Year | BA2: Kitchen Water | BE2: Laundry Water | BI2: Laundry Electricity | BM2: Kit. Equip. Electricity | BQ2: Chiller 1-H2-Circuit1 | BU2: Chiller 1-H2-Circuit 2 | BY2: Chiller 2-H2-Circuit1 | CC2: Chiller 2-H2-Circuit2 | CG2: Chiller 3 Mall-H2-Circuit1 | CK2: Chiller 3 Mall-H2-Circuit2 | CO2: Chiller 1-H3-Circuit1 | CR2: Chiller 1-H3-Circuit2 | CU2: Chilled Pumps KWH | CV2: Chiller 2-H3-Circuit1 | CY2: Chiller 2-H3-Circuit2 | DC2: Total Chillers
K3: Tower 1 | M3: Tower 2 | S3: Tower 1 | U3: Tower 2 | W3: Total Consump
A4: Date | B4: Reading Tower 1 | C4: Consump. Tower 1 | D4: Reading Tower 2 | E4: Consump. Tower 2 | F4: Buy | G4: Consump. This Year | H4: Budget m | I4: Last Year | K4: Reading | L4: Consump. | M4: Reading | N4: Consump. | O4: Add | P4: Consump. This Year | Q4: Last Year | S4: Consump. This Year | T4: Consump. Last Year | U4: Consump. This Year | V4: Consump. Last Year | W4: Consump. This Year | X4: Consump. Last Year | Z4: This Year | AA4: Last Year | AB4: Budget | AD4: This Year | AE4: Last Year | AF4: Budget | AH4: This Year | AI4: Last Year | AJ4: Budget | AL4: Cos Ø | AN4: This Year - October 2024 | AR4: Last Year - October 2023 | BA4: Counter Reading | BB4: Consumption This year | BC4: Consumption Last Year | BE4: Counter Reading | BF4: Consumption | BG4: Consumption Last Year | BI4: Counter Reading | BJ4: Cons. | BK4: Cons. Last Year | BM4: Counter Reading | BN4: Cons. | BO4: Cons. Last Year | BQ4: Counter Reading | BR4: Cons. | BS4: Cons. Last Year | BU4: Counter Reading | BV4: Cons. | BW4: Cons. Last Year | BY4: Counter Reading | BZ4: Cons. | CA4: Cons. Last Year | CC4: Counter Reading | CD4: Cons. | CE4: Cons. Last Year | CG4: Counter Reading | CH4: Cons. | CI4: Cons. Last Year | CK4: Counter Reading | CL4: Cons. | CM4: Cons. Last Year | CO4: Counter Reading | CP4: Cons. | CQ4: Cons. Last Year | CR4: Counter Reading | CS4: Cons. | CT4: Cons. Last Year | CV4: Counter Reading | CW4: Cons. | CX4: Cons. Last Year | CY4: Counter Reading | CZ4: Cons. | DA4: Cons. Last Year | DC4: Cons. | DD4: Cons. Last Year
K5: 1000 | M5: 1000 | AN5: Max | AO5: Avg | AP5: Min | AQ5: Hum | AR5: Max | AS5: Avg | AT5: Min | AU5: Hum | BQ5: 41016 | BU5: 41580 | BY5: 43179 | CC5: 36423 | CG5: 52498 | CK5: 48855 | CO5: 92674 | CR5: 43799 | CV5: 49297 | CY5: 5098
A6: 45717 | F6: 0 | G6: =E6+C6 -> 0 | H6: =5364/31 -> 173.03226 | K6: 1000 | L6: =K5-K6 -> 0 | M6: 1000 | N6: =M5-M6 -> 0 | O6: 0 | P6: =N6+L6 -> 0 | S6: 20524 | U6: 9434 | W6: =S6+U6 -> 29958 | Z6: =W6 -> 29958 | AB6: =1132495/31 -> 36532.097 | AD6: 0.453 | AF6: 0.81 | AH6: 232 | AJ6: =12862/31 -> 414.90323 | AL6: 0.97 | AN6: 27 | AO6: 21.3 | AP6: 13 | AQ6: 41 | AR6: 28 | AS6: 20.7 | AT6: 14 | AU6: 22 | BQ6: 41016 | BR6: =BQ6-BQ5 -> 0 | BU6: 41580 | BV6: =BU6-BU5 -> 0 | BY6: 43179 | BZ6: =BY6-BY5 -> 0 | CC6: 36423 | CD6: =CC6-CC5 -> 0 | CG6: 52498 | CH6: =CG6-CG5 -> 0 | CK6: 48855 | CL6: =CK6-CK5 -> 0 | CO6: 92674 | CP6: =CO6-CO5 -> 0 | CR6: 43799 | CS6: =CR6-CR5 -> 0 | CV6: 49297 | CW6: =CV6-CV5 -> 0 | CY6: 5098 | CZ6: =CY6-CY5 -> 0 | DC6: =BR6+BV6+BZ6+CU6 -> 0 | DD6: =#REF! -> #REF!
A7: 45718 | F7: 0 | G7: =E7+C7 -> 0 | H7: =5364/31 -> 173.03226 | K7: 1000 | L7: =K6-K7 -> 0 | M7: 1000 | N7: =M6-M7 -> 0 | O7: 0 | P7: =N7+L7 -> 0 | S7: 19871 | U7: 9233 | W7: =S7+U7 -> 29104 | Z7: =W7 -> 29104 | AB7: =1132495/31 -> 36532.097 | AD7: 0.398 | AF7: 0.81 | AH7: 204 | AJ7: =12862/31 -> 414.90323 | AL7: 0.97 | AN7: 24 | AO7: 17.6 | AP7: 14 | AQ7: 27 | AR7: 31 | AS7: 24.6 | AT7: 18 | AU7: 57 | BQ7: 41018 | BR7: =BQ7-BQ6 -> 2 | BU7: 41723 | BV7: =BU7-BU6 -> 143 | BY7: 43192 | BZ7: =BY7-BY6 -> 13 | CC7: 36467 | CD7: =CC7-CC6 -> 44 | CG7: 52644 | CH7: =CG7-CG6 -> 146 | CK7: 48863 | CL7: =CK7-CK6 -> 8 | CO7: 92675 | CP7: =CO7-CO6 -> 1 | CR7: 43955 | CS7: =CR7-CR6 -> 156 | CV7: 49298 | CW7: =CV7-CV6 -> 1 | CY7: 5100 | CZ7: =CY7-CY6 -> 2 | DC7: =BR7+BV7+BZ7+CU7 -> 158 | DD7: =#REF! -> #REF!
A8: 45719 | F8: 0 | G8: =E8+C8 -> 0 | H8: =5364/31 -> 173.03226 | K8: 1000 | L8: =K7-K8 -> 0 | M8: 1000 | N8: =M7-M8 -> 0 | O8: 0 | P8: =N8+L8 -> 0 | S8: 19821 | U8: 8882 | W8: =S8+U8 -> 28703 | Z8: =W8 -> 28703 | AB8: =1132495/31 -> 36532.097 | AD8: 0.381 | AF8: 0.81 | AH8: 195 | AJ8: =12862/31 -> 414.90323 | AL8: 0.97 | AN8: 28 | AO8: 22.1 | AP8: 15 | AQ8: 19 | AR8: 31 | AS8: 26.6 | AT8: 22 | AU8: 57 | BQ8: 41044 | BR8: =BQ8-BQ7 -> 26 | BU8: 41825 | BV8: =BU8-BU7 -> 102 | BY8: 43194 | BZ8: =BY8-BY7 -> 2 | CC8: 36471 | CD8: =CC8-CC7 -> 4 | CG8: 52967 | CH8: =CG8-CG7 -> 323 | CK8: 48867 | CL8: =CK8-CK7 -> 4 | CO8: 92677 | CP8: =CO8-CO7 -> 2 | CR8: 44104 | CS8: =CR8-CR7 -> 149 | CV8: 49299 | CW8: =CV8-CV7 -> 1 | CY8: 5101 | CZ8: =CY8-CY7 -> 1
A9: 45720 | F9: 0 | G9: =E9+C9 -> 0 | H9: =5364/31 -> 173.03226 | K9: 1000 | L9: =K8-K9 -> 0 | M9: 1000 | N9: =M8-M9 -> 0 | O9: 0 | P9: =N9+L9 -> 0 | S9: 20273 | U9: 9133 | W9: =S9+U9 -> 29406 | Z9: =W9 -> 29406 | AB9: =1132495/31 -> 36532.097 | AD9: 0.35 | AF9: 0.81 | AH9: 179 | AJ9: =12862/31 -> 414.90323 | AL9: 0.97 | AN9: 29 | AO9: 23.4 | AP9: 21 | AQ9: 27 | AR9: 30 | AS9: 24.8 | AT9: 18 | AU9: 28 | BQ9: 41189 | BR9: =BQ9-BQ8 -> 145 | BU9: 41826 | BV9: =BU9-BU8 -> 1 | BY9: 43214 | BZ9: =BY9-BY8 -> 20 | CC9: 36486 | CD9: =CC9-CC8 -> 15 | CG9: 52932 | CH9: =CG9-CG8 -> -35 | CK9: 48872 | CL9: =CK9-CK8 -> 5 | CO9: 92678 | CP9: =CO9-CO8 -> 1 | CR9: 44242 | CS9: =CR9-CR8 -> 138 | CV9: 49300 | CW9: =CV9-CV8 -> 1 | CY9: 5102 | CZ9: =CY9-CY8 -> 1
A10: 45721 | F10: 0 | G10: =E10+C10 -> 0 | H10: =5364/31 -> 173.03226 | K10: 1000 | L10: =K9-K10 -> 0 | M10: 1000 | N10: =M9-M10 -> 0 | O10: 0 | P10: =N10+L10 -> 0 | S10: 19570 | U10: 8982 | W10: =S10+U10 -> 28552 | Z10: =W10 -> 28552 | AB10: =1132495/31 -> 36532.097 | AD10: 0.451 | AF10: 0.81 | AH10: 231 | AJ10: =12862/31 -> 414.90323 | AL10: 0.97 | AN10: 26 | AO10: 21.5 | AP10: 15 | AQ10: 55 | AR10: 31 | AS10: 24.8 | AT10: 19 | AU10: 25 | BQ10: 41190 | BR10: =BQ10-BQ9 -> 1 | BU10: 41977 | BV10: =BU10-BU9 -> 151 | BY10: 43250 | BZ10: =BY10-BY9 -> 36 | CC10: 36501 | CD10: =CC10-CC9 -> 15 | CG10: 53080 | CH10: =CG10-CG9 -> 148 | CK10: 48883 | CL10: =CK10-CK9 -> 11 | CO10: 92679 | CP10: =CO10-CO9 -> 1 | CR10: 44392 | CS10: =CR10-CR9 -> 150 | CV10: 49301 | CW10: =CV10-CV9 -> 1 | CY10: 5103 | CZ10: =CY10-CY9 -> 1
A11: 45722 | F11: 0 | G11: =E11+C11 -> 0 | H11: =5364/31 -> 173.03226 | K11: 1000 | L11: =K10-K11 -> 0 | M11: 1000 | N11: =M10-M11 -> 0 | O11: 0 | P11: =N11+L11 -> 0 | S11: 19721 | U11: 9133 | W11: =S11+U11 -> 28854 | Z11: =W11 -> 28854 | AB11: =1132495/31 -> 36532.097 | AD11: 0.605 | AF11: 0.81 | AH11: 310 | AJ11: =12862/31 -> 414.90323 | AL11: 0.97 | AN11: 28 | AO11: 22.6 | AP11: 17 | AQ11: 37 | AR11: 31 | AS11: 25.6 | AT11: 20 | AU11: 24
A12: 45723 | F12: 0 | G12: =E12+C12 -> 0 | H12: =5364/31 -> 173.03226 | K12: 1000 | L12: =K11-K12 -> 0 | M12: 1000 | N12: =M11-M12 -> 0 | O12: 0 | P12: =N12+L12 -> 0 | S12: 19621 | U12: 9032 | W12: =S12+U12 -> 28653 | Z12: =W12 -> 28653 | AB12: =1132495/31 -> 36532.097 | AD12: 0.563 | AF12: 0.81 | AH12: 288 | AJ12: =12862/31 -> 414.90323 | AL12: 0.97 | AN12: 26 | AO12: 20.6 | AP12: 16 | AQ12: 39 | AR12: 30 | AS12: 25.4 | AT12: 18 | AU12: 37 | BQ12: 41193 | BU12: 42269 | BY12: 43283 | CC12: 36546 | CG12: 53324 | CK12: 48905 | CO12: 92681 | CR12: 44704 | CV12: 49304 | CY12: 5105
A13: 45724 | F13: 0 | G13: =E13+C13 -> 0 | H13: =5364/31 -> 173.03226 | K13: 1000 | L13: =K12-K13 -> 0 | M13: 1000 | N13: =M12-M13 -> 0 | O13: 0 | P13: =N13+L13 -> 0 | S13: 19922 | U13: 8882 | W13: =S13+U13 -> 28804 | Z13: =W13 -> 28804 | AB13: =1132495/31 -> 36532.097 | AD13: 0.438 | AF13: 0.81 | AH13: 224 | AJ13: =12862/31 -> 414.90323 | AL13: 0.97 | AN13: 25 | AO13: 19.8 | AP13: 14 | AQ13: 42 | AR13: 30 | AS13: 24.8 | AT13: 19 | AU13: 21
A14: 45725 | B14: 161 | C14: 161 | D14: 29 | E14: 29 | F14: 0 | G14: =E14+C14 -> 190 | H14: =5364/31 -> 173.03226 | K14: 1000 | L14: =K13-K14 -> 0 | M14: 1000 | N14: =M13-M14 -> 0 | O14: 0 | P14: =N14+L14 -> 0 | S14: 19721 | U14: 8781 | W14: =S14+U14 -> 28502 | Z14: =W14 -> 28502 | AB14: =1132495/31 -> 36532.097 | AD14: 0.426 | AF14: 0.81 | AH14: 218 | AJ14: =12862/31 -> 414.90323 | AL14: 0.97 | AN14: 28 | AO14: 21.3 | AP14: 13 | AQ14: 41 | AR14: 30 | AS14: 23.8 | AT14: 16 | AU14: 19
A15: 45726 | B15: 224 | C15: =B15-B14 -> 63 | D15: 46 | E15: =D15-D14 -> 17 | F15: 0 | G15: =E15+C15 -> 80 | H15: =5364/31 -> 173.03226 | K15: 1000 | L15: =K14-K15 -> 0 | M15: 1000 | N15: =M14-M15 -> 0 | O15: 0 | P15: =N15+L15 -> 0 | S15: 19871 | U15: 8882 | W15: =S15+U15 -> 28753 | Z15: =W15 -> 28753 | AB15: =1132495/31 -> 36532.097 | AD15: 0.355 | AF15: 0.81 | AH15: 182 | AJ15: =12862/31 -> 414.90323 | AL15: 0.97 | AN15: 28 | AO15: 22.6 | AP15: 15 | AQ15: 37 | AR15: 34 | AS15: 26.4 | AT15: 17 | AU15: 16
A16: 45727 | F16: 0 | G16: =E16+C16 -> 0 | H16: =5364/31 -> 173.03226 | K16: 1000 | L16: =K15-K16 -> 0 | M16: 1000 | N16: =M15-M16 -> 0 | O16: 0 | P16: =N16+L16 -> 0 | AB16: =1132495/31 -> 36532.097 | AF16: 0.81 | AJ16: =12862/31 -> 414.90323 | AL16: 0.97 | AR16: 33 | AS16: 27.9 | AT16: 22 | AU16: 26
A17: 45728 | F17: 0 | G17: =E17+C17 -> 0 | H17: =5364/31 -> 173.03226 | K17: 1000 | L17: =K16-K17 -> 0 | M17: 1000 | N17: =M16-M17 -> 0 | O17: 0 | P17: =N17+L17 -> 0 | AB17: =1132495/31 -> 36532.097 | AF17: 0.81 | AJ17: =12862/31 -> 414.90323 | AL17: 0.97 | AR17: 32 | AS17: 25.5 | AT17: 20 | AU17: 15
A18: 45729 | F18: 0 | G18: =E18+C18 -> 0 | H18: =5364/31 -> 173.03226 | K18: 1000 | L18: =K17-K18 -> 0 | M18: 1000 | N18: =M17-M18 -> 0 | O18: 0 | P18: =N18+L18 -> 0 | AB18: =1132495/31 -> 36532.097 | AF18: 0.81 | AJ18: =12862/31 -> 414.90323 | AL18: 0.97 | AR18: 36 | AS18: 28.1 | AT18: 21 | AU18: 35
A19: 45730 | F19: 0 | G19: =E19+C19 -> 0 | H19: =5364/31 -> 173.03226 | K19: 1000 | L19: =K18-K19 -> 0 | M19: 1000 | N19: =M18-M19 -> 0 | O19: 0 | P19: =N19+L19 -> 0 | AB19: =1132495/31 -> 36532.097 | AF19: 0.81 | AJ19: =12862/31 -> 414.90323 | AL19: 0.97 | AR19: 35 | AS19: 30 | AT19: 25 | AU19: 44
A20: 45731 | F20: 0 | G20: =E20+C20 -> 0 | H20: =5364/31 -> 173.03226 | K20: 1000 | L20: =K19-K20 -> 0 | M20: 1000 | N20: =M19-M20 -> 0 | O20: 0 | P20: =N20+L20 -> 0 | AB20: =1132495/31 -> 36532.097 | AF20: 0.81 | AJ20: =12862/31 -> 414.90323 | AL20: 0.97 | AR20: 34 | AS20: 28.5 | AT20: 23 | AU20: 48
A21: 45732 | F21: 0 | G21: =E21+C21 -> 0 | H21: =5364/31 -> 173.03226 | K21: 1000 | L21: =K20-K21 -> 0 | M21: 1000 | N21: =M20-M21 -> 0 | O21: 0 | P21: =N21+L21 -> 0 | AB21: =1132495/31 -> 36532.097 | AF21: 0.81 | AJ21: =12862/31 -> 414.90323 | AL21: 0.97 | AR21: 31 | AS21: 27.3 | AT21: 22 | AU21: 19
A22: 45733 | F22: 0 | G22: =E22+C22 -> 0 | H22: =5364/31 -> 173.03226 | K22: 1000 | L22: =K21-K22 -> 0 | M22: 1000 | N22: =M21-M22 -> 0 | O22: 0 | P22: =N22+L22 -> 0 | AB22: =1132495/31 -> 36532.097 | AF22: 0.81 | AJ22: =12862/31 -> 414.90323 | AL22: 0.97 | AR22: 34 | AS22: 28.5 | AT22: 23 | AU22: 34
A23: 45734 | F23: 0 | G23: =E23+C23 -> 0 | H23: =5364/31 -> 173.03226 | K23: 1000 | L23: =K22-K23 -> 0 | M23: 1000 | N23: =M22-M23 -> 0 | O23: 0 | P23: =N23+L23 -> 0 | AB23: =1132495/31 -> 36532.097 | AF23: 0.81 | AJ23: =12862/31 -> 414.90323 | AL23: 0.97 | AR23: 33 | AS23: 27 | AT23: 21 | AU23: 53
A24: 45735 | F24: 0 | G24: =E24+C24 -> 0 | H24: =5364/31 -> 173.03226 | K24: 1000 | L24: =K23-K24 -> 0 | M24: 1000 | N24: =M23-M24 -> 0 | O24: 0 | P24: =N24+L24 -> 0 | AB24: =1132495/31 -> 36532.097 | AF24: 0.81 | AJ24: =12862/31 -> 414.90323 | AL24: 0.97 | AR24: 26 | AS24: 21 | AT24: 17 | AU24: 88
A25: 45736 | F25: 0 | G25: =E25+C25 -> 0 | H25: =5364/31 -> 173.03226 | K25: 1000 | L25: =K24-K25 -> 0 | M25: 1000 | N25: =M24-M25 -> 0 | O25: 0 | P25: =N25+L25 -> 0 | AB25: =1132495/31 -> 36532.097 | AF25: 0.81 | AJ25: =12862/31 -> 414.90323 | AL25: 0.97 | AR25: 29 | AS25: 21.8 | AT25: 14 | AU25: 59
A26: 45737 | F26: 0 | G26: =E26+C26 -> 0 | H26: =5364/31 -> 173.03226 | K26: 1000 | L26: =K25-K26 -> 0 | M26: 1000 | N26: =M25-M26 -> 0 | O26: 0 | P26: =N26+L26 -> 0 | AB26: =1132495/31 -> 36532.097 | AF26: 0.81 | AJ26: =12862/31 -> 414.90323 | AL26: 0.97 | AR26: 31 | AS26: 25.5 | AT26: 19 | AU26: 46
A27: 45738 | F27: 0 | G27: =E27+C27 -> 0 | H27: =5364/31 -> 173.03226 | K27: 1000 | L27: =K26-K27 -> 0 | M27: 1000 | N27: =M26-M27 -> 0 | O27: 0 | P27: =N27+L27 -> 0 | AB27: =1132495/31 -> 36532.097 | AF27: 0.81 | AJ27: =12862/31 -> 414.90323 | AL27: 0.97 | AR27: 31 | AS27: 27 | AT27: 22 | AU27: 26
... A33: 45744 | F33: 0 | G33: =E33+C33 -> 0 | H33: =5364/31 -> 173.03226 | K33: 1000 | L33: =K32-K33 -> 0 | M33: 1000 | N33: =M32-M33 -> 0 | O33: 0 | P33: =N33+L33 -> 0 | AB33: =1132495/31 -> 36532.097 | AF33: 0.81 | AJ33: =12862/31 -> 414.90323 | AL33: 0.97 | AR33: 33 | AS33: 28.1 | AT33: 23 | AU33: 34
A34: 45745 | F34: 0 | G34: =E34+C34 -> 0 | H34: =5364/31 -> 173.03226 | K34: 1000 | M34: 1000 | N34: 0 | O34: 0 | P34: 0 | AB34: =1132495/31 -> 36532.097 | AF34: 0.81 | AJ34: =12862/31 -> 414.90323 | AL34: 0.97 | AR34: 26 | AS34: 20.3 | AT34: 17 | AU34: 100
A35: 45746 | F35: 0 | G35: =E35+C35 -> 0 | H35: =5364/31 -> 173.03226 | K35: 1000 | M35: 1000 | N35: 0 | O35: 0 | P35: 0 | AB35: =1132495/31 -> 36532.097 | AF35: 0.81 | AJ35: =12862/31 -> 414.90323 | AL35: 0.97 | AR35: 29 | AS35: 21.8 | AT35: 15 | AU35: 94
A36: 45747 | F36: 0 | G36: =E36+C36 -> 0 | H36: =5364/31 -> 173.03226 | K36: 1000 | M36: 1000 | N36: 0 | O36: 0 | P36: 0 | AB36: =1132495/31 -> 36532.097 | AF36: 0.81 | AJ36: =12862/31 -> 414.90323 | AL36: 0.97 | AR36: 30 | AS36: 24.9 | AT36: 20 | AU36: 60
E37: =AVERAGE(E6:E36) -> 23 | G37: =SUM(G6:G36) -> 270 | I37: =SUM(I6:I36) -> 0 | O37: =SUM(O6:O36) -> 0 | P37: =SUM(P6:P36) -> 0 | Q37: =SUM(Q6:Q36) -> 0 | S37: =SUM(S6:S36) -> 198915 | T37: =SUM(T6:T36) -> 0 | U37: =SUM(U6:U36) -> 90374 | V37: =SUM(V6:V36) -> 0 | W37: =SUM(W6:W36) -> 289289 | Z37: =SUM(Z6:Z36) -> 289289 | AA37: =SUM(AA6:AA36) -> 0 | AB37: =SUM(AB6:AB36) -> 1132495 | AD37: =AVERAGE(AD6:AD36) -> 0.442 | AE37: =AVERAGE(AE6:AE36) -> #DIV/0! | AF37: =AVERAGE(AF6:AF36) -> 0.81 | AH37: =SUM(AH6:AH36) -> 2263 | AI37: =SUM(AI6:AI36) -> 0 | AJ37: =SUM(AJ6:AJ36) -> 12862 | AL37: =AVERAGE(AL6:AL36) -> 0.97 | AN37: =AVERAGE(AN6:AN36) -> 26.9 | AO37: =AVERAGE(AO6:AO36) -> 21.28 | AP37: =AVERAGE(AP6:AP36) -> 15.3 | AQ37: =AVERAGE(AQ6:AQ36) -> 36.5 | AR37: =AVERAGE(AR6:AR36) -> 30.806452 | AS37: =AVERAGE(AS6:AS36) -> 25.141935 | AT37: =AVERAGE(AT6:AT36) -> 19.225806 | AU37: =AVERAGE(AU6:AU36) -> 39.225806 | AW37: =SUM(AW6:AW36) -> 0 | AY37: =SUM(AY6:AY36) -> 0 | BB37: =SUM(BB6:BB36) -> 0 | BC37: =SUM(BC6:BC36) -> 0 | BF37: =SUM(BF6:BF36) -> 0 | BG37: =SUM(BG6:BG36) -> 0 | BJ37: =SUM(BJ6:BJ36) -> 0 | BK37: =SUM(BK6:BK36) -> 0 | BN37: =SUM(BN6:BN36) -> 0 | BO37: =SUM(BO6:BO36) -> 0 | CD37: =CC37-CC36 -> 0
E38: Average/Day
E39: =SUM(E6:E36) -> 46
Q40: ENERGY COST / OCCUPIED ROOM - LAST YEAR = | AA40: OCCUPANCY - LAST YEAR = | AE40: =AE37 -> #DIV/0! | AH40: KWH / OCCUPIED ROOM - LAST YEAR | AN40: https://www.wunderground.com/history/monthly/sa/medina/OEMA/date/2025-3
Q41: ENERGY COST / OCCUPIED ROOM - THIS YEAR = | AA41: OCCUPANCY - THIS YEAR = | AE41: =AD37 -> 0.442 | AH41: KWH / OCCU[PIED ROOM - THIS YEAR
Q42: ENERGY COST / OCCUPIED ROOM - BUDGET = | AA42: OCCUPANCY - BUDGET= | AE42: =AF37 -> 0.81 | AH42: KWH / OCCUPIED ROOM - BUDGET
AH44: KWH / AVAILABLE ROOM - LAST YEAR
AH45: KWH / AVAILABLE ROOM - THIS YEAR
AH46: KWH / AVAILABLE ROOM - BUDGET
...

Sheet Sheet1
B5: Daily Observations
B6: Time | C6: Temperature (° C) | F6: Dew Point (° C) | I6: Humidity (%) | L6: Wind Speed (mph) | O6: Pressure (Hg) | R6: Precipitation (in)
B7: Jun | C7: Max | D7: Avg | E7: Min | F7: Max | G7: Avg | H7: Min | I7: Max | J7: Avg | K7: Min | L7: Max | M7: Avg | N7: Min | O7: Max | P7: Avg | Q7: Min
B8: 1 | C8: 35 | D8: 29.8 | E8: 25 | F8: 14 | G8: 10.3 | H8: 7 | I8: 50 | J8: 31 | K8: 20 | L8: 37 | M8: 23.4 | N8: 4 | O8: 1003.9 | P8: 1002.9 | Q8: 1001.9
B9: 2 | C9: 39 | D9: 33.4 | E9: 26 | F9: 12 | G9: 8.6 | H9: 4 | I9: 42 | J9: 22.9 | K9: 14 | L9: 33 | M9: 13.8 | N9: 0 | O9: 1001.9 | P9: 1000.2 | Q9: 998.9
B10: 3 | C10: 33 | D10: 28.9 | E10: 24 | F10: 17 | G10: 12.1 | H10: 7 | I10: 65 | J10: 37.2 | K10: 20 | L10: 30 | M10: 16.3 | N10: 0 | O10: 1005.9 | P10: 1003.7 | Q10: 1001.9
B11: 4 | C11: 36 | D11: 31.1 | E11: 26 | F11: 15 | G11: 11.7 | H11: 10 | I11: 51 | J11: 31.3 | K11: 20 | L11: 30 | M11: 16.1 | N11: 6 | O11: 1004.9 | P11: 1003.4 | Q11: 1001.9
B12: 5 | C12: 36 | D12: 30.8 | E12: 26 | F12: 18 | G12: 15.1 | H12: 12 | I12: 61 | J12: 39.5 | K12: 28 | L12: 35 | M12: 25.1 | N12: 11 | O12: 1004.9 | P12: 1002.9 | Q12: 1000.9
B13: 6 | C13: 37 | D13: 31.4 | E13: 27 | F13: 17 | G13: 14.7 | H13: 11 | I13: 54 | J13: 37.6 | K13: 21 | L13: 28 | M13: 14.5 | N13: 0 | O13: 1004.9 | P13: 1002.6 | Q13: 1000.9
B14: 7 | C14: 39 | D14: 32.2 | E14: 28 | F14: 18 | G14: 15.3 | H14: 13 | I14: 48 | J14: 36.9 | K14: 22 | L14: 22 | M14: 9.2 | N14: 0 | O14: 1002.9 | P14: 1001 | Q14: 999.9
B15: 8 | C15: 39 | D15: 33.7 | E15: 26 | F15: 21 | G15: 15.5 | H15: 12 | I15: 51 | J15: 34.5 | K15: 20 | L15: 19 | M15: 8.4 | N15: 0 | O15: 1000.9 | P15: 999.3 | Q15: 997.9
B16: 9 | C16: 38 | D16: 33 | E16: 29 | F16: 16 | G16: 14.1 | H16: 12 | I16: 45 | J16: 32.3 | K16: 21 | L16: 28 | M16: 15.9 | N16: 6 | O16: 1001.9 | P16: 1000.1 | Q16: 998.9
B17: 10 | C17: 38 | D17: 33 | E17: 28 | F17: 17 | G17: 13.5 | H17: 9 | I17: 51 | J17: 32 | K17: 18 | L17: 37 | M17: 22.5 | N17: 9 | O17: 1002.9 | P17: 1001.9 | Q17: 1000.9
B18: 11 | C18: 38 | D18: 33.5 | E18: 29 | F18: 17 | G18: 14.2 | H18: 12 | I18: 45 | J18: 31.5 | K18: 22 | L18: 31 | M18: 23.9 | N18: 19 | O18: 1003.9 | P18: 1002.1 | Q18: 1000.9
B19: 12 | C19: 37 | D19: 31.9 | E19: 26 | F19: 17 | G19: 15.6 | H19: 14 | I19: 51 | J19: 37.9 | K19: 29 | L19: 44 | M19: 32.5 | N19: 20 | O19: 1002.9 | P19: 1001.6 | Q19: 1000.9
... B37: 30 | C37: 37 | D37: 33.7 | E37: 29 | F37: 15 | G37: 11.5 | H37: 8 | I37: 40 | J37: 26.3 | K37: 19 | L37: 26 | M37: 17.1 | N37: 7 | O37: 998.9 | P37: 997 | Q37: 996
