Workbook

Sheet Total
A1: Site Name | B1: Day | C1: Month | D1: Year | E1: Total Electricity Kwh | F1: Electricity Tariff ($/Kwh) | G1: Water Utility Supply (m3) m3 | H1: Water Utility Supply (m3) $/m3 | I1: LPG (Liters) | J1: LPG $/Liters | K1: District Energy Cooling RTH | L1: District Energy Cooling $/RTH | M1: Room Nights | N1: Total Guests
A2: Capital Centre Arjaan | B2: 1 | C2: 1 | D2: 2025 | E2: =IF('Jan 2025'!R5>=0,'Jan 2025'!R5,0) -> 12633.429 | F2: ='Jan 2025'!S5/'Jan 2025'!R5 -> 0.2 | G2: =IF('Jan 2025'!X5>=0,'Jan 2025'!X5,0) -> 75 | H2: ='Jan 2025'!Y5/'Jan 2025'!X5 -> 7.84 | I2: =IF('Jan 2025'!AA5>=0,'Jan 2025'!AA5,0) -> 196 | J2: ='Jan 2025'!AB5/'Jan 2025'!AA5 -> 1.2551 | K2: =IF('Jan 2025'!AK5>=0,'Jan 2025'!AK5,0) -> 4277 | L2: ='Jan 2025'!AI5/'Jan 2025'!AK5 -> 1.4227357 | M2: ='Jan 2025'!AO5 -> 242.9938 | N2: ='Jan 2025'!AN5 -> 317
A3: Capital Centre Arjaan | B3: =B2+1 -> 2 | C3: 1 | D3: 2025 | E3: =IF('Jan 2025'!R6>=0,'Jan 2025'!R6,0) -> 12818.98 | F3: ='Jan 2025'!S6/'Jan 2025'!R6 -> 0.2 | G3: =IF('Jan 2025'!X6>=0,'Jan 2025'!X6,0) -> 93 | H3: ='Jan 2025'!Y6/'Jan 2025'!X6 -> 7.84 | I3: =IF('Jan 2025'!AA6>=0,'Jan 2025'!AA6,0) -> 98 | J3: ='Jan 2025'!AB6/'Jan 2025'!AA6 -> 1.2551 | K3: =IF('Jan 2025'!AK6>=0,'Jan 2025'!AK6,0) -> 3995 | L3: ='Jan 2025'!AI6/'Jan 2025'!AK6 -> 1.4740674 | M3: ='Jan 2025'!AO6 -> 237.9951 | N3: ='Jan 2025'!AN6 -> 305
A4: Capital Centre Arjaan | B4: =B3+1 -> 3 | C4: 1 | D4: 2025 | E4: =IF('Jan 2025'!R7>=0,'Jan 2025'!R7,0) -> 13599.619 | F4: ='Jan 2025'!S7/'Jan 2025'!R7 -> 0.2 | G4: =IF('Jan 2025'!X7>=0,'Jan 2025'!X7,0) -> 45 | H4: ='Jan 2025'!Y7/'Jan 2025'!X7 -> 7.84 | I4: =IF('Jan 2025'!AA7>=0,'Jan 2025'!AA7,0) -> 98 | J4: ='Jan 2025'!AB7/'Jan 2025'!AA7 -> 1.2551 | K4: =IF('Jan 2025'!AK7>=0,'Jan 2025'!AK7,0) -> 3850 | L4: ='Jan 2025'!AI7/'Jan 2025'!AK7 -> 1.5295842 | M4: ='Jan 2025'!AO7 -> 237.0109 | N4: ='Jan 2025'!AN7 -> 316
A5: Capital Centre Arjaan | B5: =B4+1 -> 4 | C5: 1 | D5: 2025 | E5: =IF('Jan 2025'!R8>=0,'Jan 2025'!R8,0) -> 11537.708 | F5: ='Jan 2025'!S8/'Jan 2025'!R8 -> 0.2 | G5: =IF('Jan 2025'!X8>=0,'Jan 2025'!X8,0) -> 99 | H5: ='Jan 2025'!Y8/'Jan 2025'!X8 -> 7.84 | I5: =IF('Jan 2025'!AA8>=0,'Jan 2025'!AA8,0) -> 98 | J5: ='Jan 2025'!AB8/'Jan 2025'!AA8 -> 1.2551 | K5: =IF('Jan 2025'!AK8>=0,'Jan 2025'!AK8,0) -> 3571 | L5: ='Jan 2025'!AI8/'Jan 2025'!AK8 -> 1.6216266 | M5: ='Jan 2025'!AO8 -> 215.0477 | N5: ='Jan 2025'!AN8 -> 279
A6: Capital Centre Arjaan | B6: =B5+1 -> 5 | C6: 1 | D6: 2025 | E6: =IF('Jan 2025'!R9>=0,'Jan 2025'!R9,0) -> 12167.246 | F6: ='Jan 2025'!S9/'Jan 2025'!R9 -> 0.2 | G6: =IF('Jan 2025'!X9>=0,'Jan 2025'!X9,0) -> 87 | H6: ='Jan 2025'!Y9/'Jan 2025'!X9 -> 7.84 | I6: =IF('Jan 2025'!AA9>=0,'Jan 2025'!AA9,0) -> 98 | J6: ='Jan 2025'!AB9/'Jan 2025'!AA9 -> 1.2551 | K6: =IF('Jan 2025'!AK9>=0,'Jan 2025'!AK9,0) -> 3411 | L6: ='Jan 2025'!AI9/'Jan 2025'!AK9 -> 1.6976924 | M6: ='Jan 2025'!AO9 -> 206.0086 | N6: ='Jan 2025'!AN9 -> 253
A7: Capital Centre Arjaan | B7: =B6+1 -> 6 | C7: 1 | D7: 2025 | E7: =IF('Jan 2025'!R10>=0,'Jan 2025'!R10,0) -> 12406.401 | F7: ='Jan 2025'!S10/'Jan 2025'!R10 -> 0.2 | G7: =IF('Jan 2025'!X10>=0,'Jan 2025'!X10,0) -> 82 | H7: ='Jan 2025'!Y10/'Jan 2025'!X10 -> 7.84 | I7: =IF('Jan 2025'!AA10>=0,'Jan 2025'!AA10,0) -> 98 | J7: ='Jan 2025'!AB10/'Jan 2025'!AA10 -> 1.2551 | K7: =IF('Jan 2025'!AK10>=0,'Jan 2025'!AK10,0) -> 3773 | L7: ='Jan 2025'!AI10/'Jan 2025'!AK10 -> 1.5348075 | M7: ='Jan 2025'!AO10 -> 216.006 | N7: ='Jan 2025'!AN10 -> 254
A8: Capital Centre Arjaan | B8: =B7+1 -> 7 | C8: 1 | D8: 2025 | E8: =IF('Jan 2025'!R11>=0,'Jan 2025'!R11,0) -> 12589.602 | F8: ='Jan 2025'!S11/'Jan 2025'!R11 -> 0.2 | G8: =IF('Jan 2025'!X11>=0,'Jan 2025'!X11,0) -> 97 | H8: ='Jan 2025'!Y11/'Jan 2025'!X11 -> 7.84 | I8: =IF('Jan 2025'!AA11>=0,'Jan 2025'!AA11,0) -> 98 | J8: ='Jan 2025'!AB11/'Jan 2025'!AA11 -> 1.2551 | K8: =IF('Jan 2025'!AK11>=0,'Jan 2025'!AK11,0) -> 4100 | L8: ='Jan 2025'!AI11/'Jan 2025'!AK11 -> 1.4363169 | M8: ='Jan 2025'!AO11 -> 196.9954 | N8: ='Jan 2025'!AN11 -> 237
A9: Capital Centre Arjaan | B9: =B8+1 -> 8 | C9: 1 | D9: 2025 | E9: =IF('Jan 2025'!R12>=0,'Jan 2025'!R12,0) -> 11885.813 | F9: ='Jan 2025'!S12/'Jan 2025'!R12 -> 0.2 | G9: =IF('Jan 2025'!X12>=0,'Jan 2025'!X12,0) -> 62 | H9: ='Jan 2025'!Y12/'Jan 2025'!X12 -> 7.84 | I9: =IF('Jan 2025'!AA12>=0,'Jan 2025'!AA12,0) -> 98 | J9: ='Jan 2025'!AB12/'Jan 2025'!AA12 -> 1.2551 | K9: =IF('Jan 2025'!AK12>=0,'Jan 2025'!AK12,0) -> 3884 | L9: ='Jan 2025'!AI12/'Jan 2025'!AK12 -> 1.5161945 | M9: ='Jan 2025'!AO12 -> 234.9907 | N9: ='Jan 2025'!AN12 -> 281
A10: Capital Centre Arjaan | B10: =B9+1 -> 9 | C10: 1 | D10: 2025 | E10: =IF('Jan 2025'!R13>=0,'Jan 2025'!R13,0) -> 12409.366 | F10: ='Jan 2025'!S13/'Jan 2025'!R13 -> 0.2 | G10: =IF('Jan 2025'!X13>=0,'Jan 2025'!X13,0) -> 91 | H10: ='Jan 2025'!Y13/'Jan 2025'!X13 -> 7.84 | I10: =IF('Jan 2025'!AA13>=0,'Jan 2025'!AA13,0) -> 196 | J10: ='Jan 2025'!AB13/'Jan 2025'!AA13 -> 1.2551 | K10: =IF('Jan 2025'!AK13>=0,'Jan 2025'!AK13,0) -> 3997 | L10: ='Jan 2025'!AI13/'Jan 2025'!AK13 -> 1.4733298 | M10: ='Jan 2025'!AO13 -> 201.9941 | N10: ='Jan 2025'!AN13 -> 260
A11: Capital Centre Arjaan | B11: =B10+1 -> 10 | C11: 1 | D11: 2025 | E11: =IF('Jan 2025'!R14>=0,'Jan 2025'!R14,0) -> 12635.071 | F11: ='Jan 2025'!S14/'Jan 2025'!R14 -> 0.2 | G11: =IF('Jan 2025'!X14>=0,'Jan 2025'!X14,0) -> 71 | H11: ='Jan 2025'!Y14/'Jan 2025'!X14 -> 7.84 | I11: =IF('Jan 2025'!AA14>=0,'Jan 2025'!AA14,0) -> 98 | J11: ='Jan 2025'!AB14/'Jan 2025'!AA14 -> 1.2551 | K11: =IF('Jan 2025'!AK14>=0,'Jan 2025'!AK14,0) -> 4252 | L11: ='Jan 2025'!AI14/'Jan 2025'!AK14 -> 1.3849716 | M11: ='Jan 2025'!AO14 -> 201.0099 | N11: ='Jan 2025'!AN14 -> 260
A12: Capital Centre Arjaan | B12: =B11+1 -> 11 | C12: 1 | D12: 2025 | E12: =IF('Jan 2025'!R15>=0,'Jan 2025'!R15,0) -> 12649.215 | F12: ='Jan 2025'!S15/'Jan 2025'!R15 -> 0.2 | G12: =IF('Jan 2025'!X15>=0,'Jan 2025'!X15,0) -> 81 | H12: ='Jan 2025'!Y15/'Jan 2025'!X15 -> 7.84 | I12: =IF('Jan 2025'!AA15>=0,'Jan 2025'!AA15,0) -> 196 | J12: ='Jan 2025'!AB15/'Jan 2025'!AA15 -> 1.2551 | K12: =IF('Jan 2025'!AK15>=0,'Jan 2025'!AK15,0) -> 4012 | L12: ='Jan 2025'!AI15/'Jan 2025'!AK15 -> 1.443377 | M12: ='Jan 2025'!AO15 -> 221.0047 | N12: ='Jan 2025'!AN15 -> 299
A13: Capital Centre Arjaan | B13: =B12+1 -> 12 | C13: 1 | D13: 2025 | E13: =IF('Jan 2025'!R16>=0,'Jan 2025'!R16,0) -> 12081.913 | F13: ='Jan 2025'!S16/'Jan 2025'!R16 -> 0.2 | G13: =IF('Jan 2025'!X16>=0,'Jan 2025'!X16,0) -> 70 | H13: ='Jan 2025'!Y16/'Jan 2025'!X16 -> 7.84 | I13: =IF('Jan 2025'!AA16>=0,'Jan 2025'!AA16,0) -> 98 | J13: ='Jan 2025'!AB16/'Jan 2025'!AA16 -> 1.2551 | K13: =IF('Jan 2025'!AK16>=0,'Jan 2025'!AK16,0) -> 4252 | L13: ='Jan 2025'!AI16/'Jan 2025'!AK16 -> 1.4541653 | M13: ='Jan 2025'!AO16 -> 226.9876 | N13: ='Jan 2025'!AN16 -> 279
A14: Capital Centre Arjaan | B14: =B13+1 -> 13 | C14: 1 | D14: 2025 | E14: =IF('Jan 2025'!R17>=0,'Jan 2025'!R17,0) -> 12580.508 | F14: ='Jan 2025'!S17/'Jan 2025'!R17 -> 0.2 | G14: =IF('Jan 2025'!X17>=0,'Jan 2025'!X17,0) -> 43 | H14: ='Jan 2025'!Y17/'Jan 2025'!X17 -> 7.84 | I14: =IF('Jan 2025'!AA17>=0,'Jan 2025'!AA17,0) -> 98 | J14: ='Jan 2025'!AB17/'Jan 2025'!AA17 -> 1.2551 | K14: =IF('Jan 2025'!AK17>=0,'Jan 2025'!AK17,0) -> 4146 | L14: ='Jan 2025'!AI17/'Jan 2025'!AK17 -> 1.4203809 | M14: ='Jan 2025'!AO17 -> 236.0008 | N14: ='Jan 2025'!AN17 -> 284
... A32: Capital Centre Arjaan | B32: =B31+1 -> 31 | C32: 1 | D32: 2025 | E32: =IF('Jan 2025'!R35>=0,'Jan 2025'!R35,0) -> 12805.15 | F32: ='Jan 2025'!S35/'Jan 2025'!R35 -> 0.2 | G32: =IF('Jan 2025'!X35>=0,'Jan 2025'!X35,0) -> 78 | H32: ='Jan 2025'!Y35/'Jan 2025'!X35 -> 7.84 | I32: =IF('Jan 2025'!AA35>=0,'Jan 2025'!AA35,0) -> 196 | J32: ='Jan 2025'!AB35/'Jan 2025'!AA35 -> 1.2551 | K32: =IF('Jan 2025'!AK35>=0,'Jan 2025'!AK35,0) -> 3545 | L32: ='Jan 2025'!AI35/'Jan 2025'!AK35 -> 1.6335201 | M32: ='Jan 2025'!AO35 -> 259 | N32: ='Jan 2025'!AN35 -> 320

Sheet Jan 2025
A1: CAPITAL CENTRE ARJAAN UTILITIES CONSUMPTION - 2024.
A2: DATE | B2: Electricity | T2: Water | Z2: LP Gas | AD2: District Cooling | AM2: Additional Info
B3: MDB #2 | D3: MDB #3 | G3: MDB #1 MDB-E | J3: MDB #1 SMDB Kitchen | L3: MDB #1 Fire Pump #1 | O3: MDB #1 Fire Pump #2 | R3: Total ELE Cons. KW | S3: Electricity AED | T3: Hotel Reading | U3: Water Cons. M3 | V3: Irrigation water BHP | W3: Water Cons. M3 | X3: Total Water Cons. M3 | Y3: Water AED | Z3: 1st Floor Kitchen | AB3: Gas AED | AC3: Gas Cylinder purchased (50 litres) | AD3: Hotel BTU Meter Energy Reading | AE3: District Cooling Cons. MWH | AF3: District Cooling Cons. Ton Hour | AG3: District Cooling Cons. AED | AH3: District Cooling Fixed Charge | AI3: District Cooling Total AED | AJ3: Bulk ETS Energy Meter Reading | AK3: ETS Cons. Ton Hours | AL3: ETS Cons. MWH | AM3: Hotel Occupancy % | AN3: Adl. & Chl. | AO3: Room Nights
B4: Reading | C4: Cons. | D4: Reading | E4: Cons. | F4: Hotel share 94.38 % | G4: Reading | H4: Cons. | I4: Hotel share 65.36 % | J4: Reading | K4: Cons. | L4: Reading | M4: Cons. | N4: Hotel share 50 % | O4: Reading | P4: Cons. | Q4: Hotel share 50 % | V4: To be deducted from Hotel Meter. | Z4: No of Cylinder | AA4: Cons. Ltrs
A5: 45658 | B5: 9737972 | C5: 2325 | D5: 23585928 | E5: 6730 | F5: =E5*0.9438 -> 6351.774 | G5: 15327958 | H5: 4057 | I5: =H5*0.6536 -> 2651.6552 | J5: 3683019 | K5: 1305 | L5: 1385 | M5: 0 | N5: =M5*0.5 -> 0 | O5: 835 | P5: 0 | Q5: =P5*0.5 -> 0 | R5: =C5+F5+I5+K5+N5+Q5 -> 12633.429 | S5: =R5*0.2 -> 2526.6858 | T5: 79480 | U5: 75 | V5: 36727 | W5: 0 | X5: =U5-W5 -> 75 | Y5: =X5*7.84 -> 588 | Z5: 2 | AA5: =Z5*50*1.96 -> 196 | AB5: =AA5*1.2551 -> 245.9996 | AC5: 0 | AD5: 82138 | AE5: 11 | AF5: =IF(ISBLANK(AD5),"0 ",AE5*284.345) -> 3127.795 | AG5: =AF5*0.3449 -> 1078.7765 | AH5: =IF(ISBLANK(AD5),"0",1754*1608.73/12/31*0.66) -> 5006.264 | AI5: =AG5+AH5 -> 6085.0405 | AJ5: 2341830 | AK5: 4277 | AL5: =IF(ISBLANK(AK5),"0 ",AK5/284.345) -> 15.041587 | AM5: 0.9382 | AN5: 317 | AO5: =AM5*259 -> 242.9938
A6: 45659 | B6: 9740175 | C6: =IF(ISBLANK(B6),"0",B6-B5) -> 2203 | D6: 23592760 | E6: =IF(ISBLANK(D6),"0",D6-D5) -> 6832 | F6: =E6*0.9438 -> 6448.0416 | G6: 15332427 | H6: =IF(ISBLANK(G6),"0",G6-G5) -> 4469 | I6: =H6*0.6536 -> 2920.9384 | J6: 3684266 | K6: =IF(ISBLANK(J6),"0",J6-J5) -> 1247 | L6: 1385 | M6: =IF(ISBLANK(L6),"0",L6-L5) -> 0 | N6: =M6*0.5 -> 0 | O6: 835 | P6: =IF(ISBLANK(O6),"0",O6-O5) -> 0 | Q6: =P6*0.5 -> 0 | R6: =C6+F6+I6+K6+N6+Q6 -> 12818.98 | S6: =R6*0.2 -> 2563.796 | T6: 79584 | U6: =IF(ISBLANK(T6),"0",T6-T5) -> 104 | V6: 36738 | W6: =IF(ISBLANK(V6),"0",V6-V5) -> 11 | X6: =U6-W6 -> 93 | Y6: =X6*7.84 -> 729.12 | Z6: 1 | AA6: =Z6*50*1.96 -> 98 | AB6: =AA6*1.2551 -> 122.9998 | AC6: 4 | AD6: 82147 | AE6: =IF(ISBLANK(AD6),"0",AD6-AD5) -> 9 | AF6: =IF(ISBLANK(AD6),"0 ",AE6*284.345) -> 2559.105 | AG6: =AF6*0.3449 -> 882.63531 | AH6: =IF(ISBLANK(AD6),"0",1754*1608.73/12/31*0.66) -> 5006.264 | AI6: =AG6+AH6 -> 5888.8993 | AJ6: 2345825 | AK6: =IF(ISBLANK(AJ6),"0",AJ6-AJ5) -> 3995 | AL6: =IF(ISBLANK(AK6),"0 ",AK6/284.345) -> 14.049834 | AM6: 0.9189 | AN6: 305 | AO6: =AM6*259 -> 237.9951
A7: 45660 | B7: 9742374 | C7: =IF(ISBLANK(B7),"0",B7-B6) -> 2199 | D7: 23599999 | E7: =IF(ISBLANK(D7),"0",D7-D6) -> 7239 | F7: =E7*0.9438 -> 6832.1682 | G7: 15337469 | H7: =IF(ISBLANK(G7),"0",G7-G6) -> 5042 | I7: =H7*0.6536 -> 3295.4512 | J7: 3685539 | K7: =IF(ISBLANK(J7),"0",J7-J6) -> 1273 | L7: 1385 | M7: =IF(ISBLANK(L7),"0",L7-L6) -> 0 | N7: =M7*0.5 -> 0 | O7: 835 | P7: =IF(ISBLANK(O7),"0",O7-O6) -> 0 | Q7: =P7*0.5 -> 0 | R7: =C7+F7+I7+K7+N7+Q7 -> 13599.619 | S7: =R7*0.2 -> 2719.9239 | T7: 79636 | U7: =IF(ISBLANK(T7),"0",T7-T6) -> 52 | V7: 36745 | W7: =IF(ISBLANK(V7),"0",V7-V6) -> 7 | X7: =U7-W7 -> 45 | Y7: =X7*7.84 -> 352.8 | Z7: 1 | AA7: =Z7*50*1.96 -> 98 | AB7: =AA7*1.2551 -> 122.9998 | AC7: 0 | AD7: 82156 | AE7: =IF(ISBLANK(AD7),"0",AD7-AD6) -> 9 | AF7: =IF(ISBLANK(AD7),"0 ",AE7*284.345) -> 2559.105 | AG7: =AF7*0.3449 -> 882.63531 | AH7: =IF(ISBLANK(AD7),"0",1754*1608.73/12/31*0.66) -> 5006.264 | AI7: =AG7+AH7 -> 5888.8993 | AJ7: 2349675 | AK7: =IF(ISBLANK(AJ7),"0",AJ7-AJ6) -> 3850 | AL7: =IF(ISBLANK(AK7),"0 ",AK7/284.345) -> 13.53989 | AM7: 0.9151 | AN7: 316 | AO7: =AM7*259 -> 237.0109
A8: 45661 | B8: 9744596 | C8: =IF(ISBLANK(B8),"0",B8-B7) -> 2222 | D8: 23606596 | E8: =IF(ISBLANK(D8),"0",D8-D7) -> 6597 | F8: =E8*0.9438 -> 6226.2486 | G8: 15340291 | H8: =IF(ISBLANK(G8),"0",G8-G7) -> 2822 | I8: =H8*0.6536 -> 1844.4592 | J8: 3686771 | K8: =IF(ISBLANK(J8),"0",J8-J7) -> 1232 | L8: 1401 | M8: =IF(ISBLANK(L8),"0",L8-L7) -> 16 | N8: =M8*0.5 -> 8 | O8: 845 | P8: =IF(ISBLANK(O8),"0",O8-O7) -> 10 | Q8: =P8*0.5 -> 5 | R8: =C8+F8+I8+K8+N8+Q8 -> 11537.708 | S8: =R8*0.2 -> 2307.5416 | T8: 79742 | U8: =IF(ISBLANK(T8),"0",T8-T7) -> 106 | V8: 36752 | W8: =IF(ISBLANK(V8),"0",V8-V7) -> 7 | X8: =U8-W8 -> 99 | Y8: =X8*7.84 -> 776.16 | Z8: 1 | AA8: =Z8*50*1.96 -> 98 | AB8: =AA8*1.2551 -> 122.9998 | AC8: 4 | AD8: 82164 | AE8: =IF(ISBLANK(AD8),"0",AD8-AD7) -> 8 | AF8: =IF(ISBLANK(AD8),"0 ",AE8*284.345) -> 2274.76 | AG8: =AF8*0.3449 -> 784.56472 | AH8: =IF(ISBLANK(AD8),"0",1754*1608.73/12/31*0.66) -> 5006.264 | AI8: =AG8+AH8 -> 5790.8287 | AJ8: 2353246 | AK8: =IF(ISBLANK(AJ8),"0",AJ8-AJ7) -> 3571 | AL8: =IF(ISBLANK(AK8),"0 ",AK8/284.345) -> 12.558688 | AM8: 0.8303 | AN8: 279 | AO8: =AM8*259 -> 215.0477
A9: 45662 | B9: 9746704 | C9: =IF(ISBLANK(B9),"0",B9-B8) -> 2108 | D9: 23613194 | E9: =IF(ISBLANK(D9),"0",D9-D8) -> 6598 | F9: =E9*0.9438 -> 6227.1924 | G9: 15344292 | H9: =IF(ISBLANK(G9),"0",G9-G8) -> 4001 | I9: =H9*0.6536 -> 2615.0536 | J9: 3687988 | K9: =IF(ISBLANK(J9),"0",J9-J8) -> 1217 | L9: 1401 | M9: =IF(ISBLANK(L9),"0",L9-L8) -> 0 | N9: =M9*0.5 -> 0 | O9: 845 | P9: =IF(ISBLANK(O9),"0",O9-O8) -> 0 | Q9: =P9*0.5 -> 0 | R9: =C9+F9+I9+K9+N9+Q9 -> 12167.246 | S9: =R9*0.2 -> 2433.4492 | T9: 79838 | U9: =IF(ISBLANK(T9),"0",T9-T8) -> 96 | V9: 36761 | W9: =IF(ISBLANK(V9),"0",V9-V8) -> 9 | X9: =U9-W9 -> 87 | Y9: =X9*7.84 -> 682.08 | Z9: 1 | AA9: =Z9*50*1.96 -> 98 | AB9: =AA9*1.2551 -> 122.9998 | AC9: 0 | AD9: 82172 | AE9: =IF(ISBLANK(AD9),"0",AD9-AD8) -> 8 | AF9: =IF(ISBLANK(AD9),"0 ",AE9*284.345) -> 2274.76 | AG9: =AF9*0.3449 -> 784.56472 | AH9: =IF(ISBLANK(AD9),"0",1754*1608.73/12/31*0.66) -> 5006.264 | AI9: =AG9+AH9 -> 5790.8287 | AJ9: 2356657 | AK9: =IF(ISBLANK(AJ9),"0",AJ9-AJ8) -> 3411 | AL9: =IF(ISBLANK(AK9),"0 ",AK9/284.345) -> 11.995991 | AM9: 0.7954 | AN9: 253 | AO9: =AM9*259 -> 206.0086
A10: 45663 | B10: 9748792 | C10: =IF(ISBLANK(B10),"0",B10-B9) -> 2088 | D10: 23619913 | E10: =IF(ISBLANK(D10),"0",D10-D9) -> 6719 | F10: =E10*0.9438 -> 6341.3922 | G10: 15348475 | H10: =IF(ISBLANK(G10),"0",G10-G9) -> 4183 | I10: =H10*0.6536 -> 2734.0088 | J10: 3689231 | K10: =IF(ISBLANK(J10),"0",J10-J9) -> 1243 | L10: 1401 | M10: =IF(ISBLANK(L10),"0",L10-L9) -> 0 | N10: =M10*0.5 -> 0 | O10: 845 | P10: =IF(ISBLANK(O10),"0",O10-O9) -> 0 | Q10: =P10*0.5 -> 0 | R10: =C10+F10+I10+K10+N10+Q10 -> 12406.401 | S10: =R10*0.2 -> 2481.2802 | T10: 79947 | U10: =IF(ISBLANK(T10),"0",T10-T9) -> 109 | V10: 36788 | W10: =IF(ISBLANK(V10),"0",V10-V9) -> 27 | X10: =U10-W10 -> 82 | Y10: =X10*7.84 -> 642.88 | Z10: 1 | AA10: =Z10*50*1.96 -> 98 | AB10: =AA10*1.2551 -> 122.9998 | AC10: 0 | AD10: 82180 | AE10: =IF(ISBLANK(AD10),"0",AD10-AD9) -> 8 | AF10: =IF(ISBLANK(AD10),"0 ",AE10*284.345) -> 2274.76 | AG10: =AF10*0.3449 -> 784.56472 | AH10: =IF(ISBLANK(AD10),"0",1754*1608.73/12/31*0.66) -> 5006.264 | AI10: =AG10+AH10 -> 5790.8287 | AJ10: 2360430 | AK10: =IF(ISBLANK(AJ10),"0",AJ10-AJ9) -> 3773 | AL10: =IF(ISBLANK(AK10),"0 ",AK10/284.345) -> 13.269092 | AM10: 0.834 | AN10: 254 | AO10: =AM10*259 -> 216.006
A11: 45664 | B11: 9750935 | C11: =IF(ISBLANK(B11),"0",B11-B10) -> 2143 | D11: 23626711 | E11: =IF(ISBLANK(D11),"0",D11-D10) -> 6798 | F11: =E11*0.9438 -> 6415.9524 | G11: 15352711 | H11: =IF(ISBLANK(G11),"0",G11-G10) -> 4236 | I11: =H11*0.6536 -> 2768.6496 | J11: 3690493 | K11: =IF(ISBLANK(J11),"0",J11-J10) -> 1262 | L11: 1401 | M11: =IF(ISBLANK(L11),"0",L11-L10) -> 0 | N11: =M11*0.5 -> 0 | O11: 845 | P11: =IF(ISBLANK(O11),"0",O11-O10) -> 0 | Q11: =P11*0.5 -> 0 | R11: =C11+F11+I11+K11+N11+Q11 -> 12589.602 | S11: =R11*0.2 -> 2517.9204 | T11: 80054 | U11: =IF(ISBLANK(T11),"0",T11-T10) -> 107 | V11: 36798 | W11: =IF(ISBLANK(V11),"0",V11-V10) -> 10 | X11: =U11-W11 -> 97 | Y11: =X11*7.84 -> 760.48 | Z11: 1 | AA11: =Z11*50*1.96 -> 98 | AB11: =AA11*1.2551 -> 122.9998 | AC11: 4 | AD11: 82189 | AE11: =IF(ISBLANK(AD11),"0",AD11-AD10) -> 9 | AF11: =IF(ISBLANK(AD11),"0 ",AE11*284.345) -> 2559.105 | AG11: =AF11*0.3449 -> 882.63531 | AH11: =IF(ISBLANK(AD11),"0",1754*1608.73/12/31*0.66) -> 5006.264 | AI11: =AG11+AH11 -> 5888.8993 | AJ11: 2364530 | AK11: =IF(ISBLANK(AJ11),"0",AJ11-AJ10) -> 4100 | AL11: =IF(ISBLANK(AK11),"0 ",AK11/284.345) -> 14.419104 | AM11: 0.7606 | AN11: 237 | AO11: =AM11*259 -> 196.9954
A12: 45665 | B12: 9752988 | C12: =IF(ISBLANK(B12),"0",B12-B11) -> 2053 | D12: 23633093 | E12: =IF(ISBLANK(D12),"0",D12-D11) -> 6382 | F12: =E12*0.9438 -> 6023.3316 | G12: 15356692 | H12: =IF(ISBLANK(G12),"0",G12-G11) -> 3981 | I12: =H12*0.6536 -> 2601.9816 | J12: 3691700 | K12: =IF(ISBLANK(J12),"0",J12-J11) -> 1207 | L12: 1401 | M12: =IF(ISBLANK(L12),"0",L12-L11) -> 0 | N12: =M12*0.5 -> 0 | O12: 846 | P12: =IF(ISBLANK(O12),"0",O12-O11) -> 1 | Q12: =P12*0.5 -> 0.5 | R12: =C12+F12+I12+K12+N12+Q12 -> 11885.813 | S12: =R12*0.2 -> 2377.1626 | T12: 80117 | U12: =IF(ISBLANK(T12),"0",T12-T11) -> 63 | V12: 36799 | W12: =IF(ISBLANK(V12),"0",V12-V11) -> 1 | X12: =U12-W12 -> 62 | Y12: =X12*7.84 -> 486.08 | Z12: 1 | AA12: =Z12*50*1.96 -> 98 | AB12: =AA12*1.2551 -> 122.9998 | AC12: 0 | AD12: 82198 | AE12: =IF(ISBLANK(AD12),"0",AD12-AD11) -> 9 | AF12: =IF(ISBLANK(AD12),"0 ",AE12*284.345) -> 2559.105 | AG12: =AF12*0.3449 -> 882.63531 | AH12: =IF(ISBLANK(AD12),"0",1754*1608.73/12/31*0.66) -> 5006.264 | AI12: =AG12+AH12 -> 5888.8993 | AJ12: 2368414 | AK12: =IF(ISBLANK(AJ12),"0",AJ12-AJ11) -> 3884 | AL12: =IF(ISBLANK(AK12),"0 ",AK12/284.345) -> 13.659463 | AM12: 0.9073 | AN12: 281 | AO12: =AM12*259 -> 234.9907
A13: 45666 | B13: 9755106 | C13: =IF(ISBLANK(B13),"0",B13-B12) -> 2118 | D13: 23639916 | E13: =IF(ISBLANK(D13),"0",D13-D12) -> 6823 | F13: =E13*0.9438 -> 6439.5474 | G13: 15360711 | H13: =IF(ISBLANK(G13),"0",G13-G12) -> 4019 | I13: =H13*0.6536 -> 2626.8184 | J13: 3692925 | K13: =IF(ISBLANK(J13),"0",J13-J12) -> 1225 | L13: 1401 | M13: =IF(ISBLANK(L13),"0",L13-L12) -> 0 | N13: =M13*0.5 -> 0 | O13: 846 | P13: =IF(ISBLANK(O13),"0",O13-O12) -> 0 | Q13: =P13*0.5 -> 0 | R13: =C13+F13+I13+K13+N13+Q13 -> 12409.366 | S13: =R13*0.2 -> 2481.8732 | T13: 80214 | U13: =IF(ISBLANK(T13),"0",T13-T12) -> 97 | V13: 36805 | W13: =IF(ISBLANK(V13),"0",V13-V12) -> 6 | X13: =U13-W13 -> 91 | Y13: =X13*7.84 -> 713.44 | Z13: 2 | AA13: =Z13*50*1.96 -> 196 | AB13: =AA13*1.2551 -> 245.9996 | AC13: 0 | AD13: 82207 | AE13: =IF(ISBLANK(AD13),"0",AD13-AD12) -> 9 | AF13: =IF(ISBLANK(AD13),"0 ",AE13*284.345) -> 2559.105 | AG13: =AF13*0.3449 -> 882.63531 | AH13: =IF(ISBLANK(AD13),"0",1754*1608.73/12/31*0.66) -> 5006.264 | AI13: =AG13+AH13 -> 5888.8993 | AJ13: 2372411 | AK13: =IF(ISBLANK(AJ13),"0",AJ13-AJ12) -> 3997 | AL13: =IF(ISBLANK(AK13),"0 ",AK13/284.345) -> 14.056868 | AM13: 0.7799 | AN13: 260 | AO13: =AM13*259 -> 201.9941
A14: 45667 | B14: 9757219 | C14: =IF(ISBLANK(B14),"0",B14-B13) -> 2113 | D14: 23646933 | E14: =IF(ISBLANK(D14),"0",D14-D13) -> 7017 | F14: =E14*0.9438 -> 6622.6446 | G14: 15364760 | H14: =IF(ISBLANK(G14),"0",G14-G13) -> 4049 | I14: =H14*0.6536 -> 2646.4264 | J14: 3694178 | K14: =IF(ISBLANK(J14),"0",J14-J13) -> 1253 | L14: 1401 | M14: =IF(ISBLANK(L14),"0",L14-L13) -> 0 | N14: =M14*0.5 -> 0 | O14: 846 | P14: =IF(ISBLANK(O14),"0",O14-O13) -> 0 | Q14: =P14*0.5 -> 0 | R14: =C14+F14+I14+K14+N14+Q14 -> 12635.071 | S14: =R14*0.2 -> 2527.0142 | T14: 80285 | U14: =IF(ISBLANK(T14),"0",T14-T13) -> 71 | V14: 36805 | W14: =IF(ISBLANK(V14),"0",V14-V13) -> 0 | X14: =U14-W14 -> 71 | Y14: =X14*7.84 -> 556.64 | Z14: 1 | AA14: =Z14*50*1.96 -> 98 | AB14: =AA14*1.2551 -> 122.9998 | AC14: 5 | AD14: 82216 | AE14: =IF(ISBLANK(AD14),"0",AD14-AD13) -> 9 | AF14: =IF(ISBLANK(AD14),"0 ",AE14*284.345) -> 2559.105 | AG14: =AF14*0.3449 -> 882.63531 | AH14: =IF(ISBLANK(AD14),"0",1754*1608.73/12/31*0.66) -> 5006.264 | AI14: =AG14+AH14 -> 5888.8993 | AJ14: 2376663 | AK14: =IF(ISBLANK(AJ14),"0",AJ14-AJ13) -> 4252 | AL14: =IF(ISBLANK(AK14),"0 ",AK14/284.345) -> 14.953665 | AM14: 0.7761 | AN14: 260 | AO14: =AM14*259 -> 201.0099
A15: 45668 | B15: 9759381 | C15: =IF(ISBLANK(B15),"0",B15-B14) -> 2162 | D15: 23653893 | E15: =IF(ISBLANK(D15),"0",D15-D14) -> 6960 | F15: =E15*0.9438 -> 6568.848 | G15: 15368737 | H15: =IF(ISBLANK(G15),"0",G15-G14) -> 3977 | I15: =H15*0.6536 -> 2599.3672 | J15: 3695497 | K15: =IF(ISBLANK(J15),"0",J15-J14) -> 1319 | L15: 1401 | M15: =IF(ISBLANK(L15),"0",L15-L14) -> 0 | N15: =M15*0.5 -> 0 | O15: 846 | P15: =IF(ISBLANK(O15),"0",O15-O14) -> 0 | Q15: =P15*0.5 -> 0 | R15: =C15+F15+I15+K15+N15+Q15 -> 12649.215 | S15: =R15*0.2 -> 2529.843 | T15: 80366 | U15: =IF(ISBLANK(T15),"0",T15-T14) -> 81 | V15: 36805 | W15: =IF(ISBLANK(V15),"0",V15-V14) -> 0 | X15: =U15-W15 -> 81 | Y15: =X15*7.84 -> 635.04 | Z15: 2 | AA15: =Z15*50*1.96 -> 196 | AB15: =AA15*1.2551 -> 245.9996 | AC15: 0 | AD15: 82224 | AE15: =IF(ISBLANK(AD15),"0",AD15-AD14) -> 8 | AF15: =IF(ISBLANK(AD15),"0 ",AE15*284.345) -> 2274.76 | AG15: =AF15*0.3449 -> 784.56472 | AH15: =IF(ISBLANK(AD15),"0",1754*1608.73/12/31*0.66) -> 5006.264 | AI15: =AG15+AH15 -> 5790.8287 | AJ15: 2380675 | AK15: =IF(ISBLANK(AJ15),"0",AJ15-AJ14) -> 4012 | AL15: =IF(ISBLANK(AK15),"0 ",AK15/284.345) -> 14.10962 | AM15: 0.8533 | AN15: 299 | AO15: =AM15*259 -> 221.0047
A16: 45669 | B16: 9761525 | C16: =IF(ISBLANK(B16),"0",B16-B15) -> 2144 | D16: 23660137 | E16: =IF(ISBLANK(D16),"0",D16-D15) -> 6244 | F16: =E16*0.9438 -> 5893.0872 | G16: 15372883 | H16: =IF(ISBLANK(G16),"0",G16-G15) -> 4146 | I16: =H16*0.6536 -> 2709.8256 | J16: 3696822 | K16: =IF(ISBLANK(J16),"0",J16-J15) -> 1325 | L16: 1414 | M16: =IF(ISBLANK(L16),"0",L16-L15) -> 13 | N16: =M16*0.5 -> 6.5 | O16: 853 | P16: =IF(ISBLANK(O16),"0",O16-O15) -> 7 | Q16: =P16*0.5 -> 3.5 | R16: =C16+F16+I16+K16+N16+Q16 -> 12081.913 | S16: =R16*0.2 -> 2416.3826 | T16: 80444 | U16: =IF(ISBLANK(T16),"0",T16-T15) -> 78 | V16: 36813 | W16: =IF(ISBLANK(V16),"0",V16-V15) -> 8 | X16: =U16-W16 -> 70 | Y16: =X16*7.84 -> 548.8 | Z16: 1 | AA16: =Z16*50*1.96 -> 98 | AB16: =AA16*1.2551 -> 122.9998 | AC16: 0 | AD16: 82236 | AE16: =IF(ISBLANK(AD16),"0",AD16-AD15) -> 12 | AF16: =IF(ISBLANK(AD16),"0 ",AE16*284.345) -> 3412.14 | AG16: =AF16*0.3449 -> 1176.8471 | AH16: =IF(ISBLANK(AD16),"0",1754*1608.73/12/31*0.66) -> 5006.264 | AI16: =AG16+AH16 -> 6183.1111 | AJ16: 2384927 | AK16: =IF(ISBLANK(AJ16),"0",AJ16-AJ15) -> 4252 | AL16: =IF(ISBLANK(AK16),"0 ",AK16/284.345) -> 14.953665 | AM16: 0.8764 | AN16: 279 | AO16: =AM16*259 -> 226.9876
A17: 45670 | B17: 9763611 | C17: =IF(ISBLANK(B17),"0",B17-B16) -> 2086 | D17: 23667131 | E17: =IF(ISBLANK(D17),"0",D17-D16) -> 6994 | F17: =E17*0.9438 -> 6600.9372 | G17: 15376972 | H17: =IF(ISBLANK(G17),"0",G17-G16) -> 4089 | I17: =H17*0.6536 -> 2672.5704 | J17: 3698043 | K17: =IF(ISBLANK(J17),"0",J17-J16) -> 1221 | L17: 1414 | M17: =IF(ISBLANK(L17),"0",L17-L16) -> 0 | N17: =M17*0.5 -> 0 | O17: 853 | P17: =IF(ISBLANK(O17),"0",O17-O16) -> 0 | Q17: =P17*0.5 -> 0 | R17: =C17+F17+I17+K17+N17+Q17 -> 12580.508 | S17: =R17*0.2 -> 2516.1015 | T17: 80494 | U17: =IF(ISBLANK(T17),"0",T17-T16) -> 50 | V17: 36820 | W17: =IF(ISBLANK(V17),"0",V17-V16) -> 7 | X17: =U17-W17 -> 43 | Y17: =X17*7.84 -> 337.12 | Z17: 1 | AA17: =Z17*50*1.96 -> 98 | AB17: =AA17*1.2551 -> 122.9998 | AC17: 4 | AD17: 82245 | AE17: =IF(ISBLANK(AD17),"0",AD17-AD16) -> 9 | AF17: =IF(ISBLANK(AD17),"0 ",AE17*284.345) -> 2559.105 | AG17: =AF17*0.3449 -> 882.63531 | AH17: =IF(ISBLANK(AD17),"0",1754*1608.73/12/31*0.66) -> 5006.264 | AI17: =AG17+AH17 -> 5888.8993 | AJ17: 2389073 | AK17: =IF(ISBLANK(AJ17),"0",AJ17-AJ16) -> 4146 | AL17: =IF(ISBLANK(AK17),"0 ",AK17/284.345) -> 14.580879 | AM17: 0.9112 | AN17: 284 | AO17: =AM17*259 -> 236.0008
... A27: 45680 | B27: 9784771 | C27: =IF(ISBLANK(B27),"0",B27-B26) -> 2132 | D27: 23733896 | E27: =IF(ISBLANK(D27),"0",D27-D26) -> 7110 | F27: =E27*0.9438 -> 6710.418 | G27: 15417748 | H27: =IF(ISBLANK(G27),"0",G27-G26) -> 4079 | I27: =H27*0.6536 -> 2666.0344 | J27: 3710582 | K27: =IF(ISBLANK(J27),"0",J27-J26) -> 1273 | L27: 1442 | M27: =IF(ISBLANK(L27),"0",L27-L26) -> 0 | N27: =M27*0.5 -> 0 | O27: 864 | P27: =IF(ISBLANK(O27),"0",O27-O26) -> 0 | Q27: =P27*0.5 -> 0 | R27: =C27+F27+I27+K27+N27+Q27 -> 12781.452 | S27: =R27*0.2 -> 2556.2905 | T27: 81357 | U27: =IF(ISBLANK(T27),"0",T27-T26) -> 57 | V27: 36897 | W27: =IF(ISBLANK(V27),"0",V27-V26) -> 8 | X27: =U27-W27 -> 49 | Y27: =X27*7.84 -> 384.16 | Z27: 1 | AA27: =Z27*50*1.96 -> 98 | AB27: =AA27*1.2551 -> 122.9998 | AC27: 0 | AD27: 82329 | AE27: =IF(ISBLANK(AD27),"0",AD27-AD26) -> 8 | AF27: =IF(ISBLANK(AD27),"0 ",AE27*284.345) -> 2274.76 | AG27: =AF27*0.3449 -> 784.56472 | AH27: =IF(ISBLANK(AD27),"0",1754*1608.73/12/31*0.66) -> 5006.264 | AI27: =AG27+AH27 -> 5790.8287 | AJ27: 2427007 | AK27: =IF(ISBLANK(AJ27),"0",AJ27-AJ26) -> 3753 | AL27: =IF(ISBLANK(AK27),"0 ",AK27/284.345) -> 13.198755 | AM27: 0.9691 | AN27: 312 | AO27: =AM27*259 -> 250.9969
A28: 45681 | B28: 9786832 | C28: =IF(ISBLANK(B28),"0",B28-B27) -> 2061 | D28: 23740899 | E28: =IF(ISBLANK(D28),"0",D28-D27) -> 7003 | F28: =E28*0.9438 -> 6609.4314 | G28: 15421678 | H28: =IF(ISBLANK(G28),"0",G28-G27) -> 3930 | I28: =H28*0.6536 -> 2568.648 | J28: 3711818 | K28: =IF(ISBLANK(J28),"0",J28-J27) -> 1236 | L28: 1442 | M28: 0 | N28: =M28*0.5 -> 0 | O28: 864 | P28: =IF(ISBLANK(O28),"0",O28-O27) -> 0 | Q28: =P28*0.5 -> 0 | R28: =C28+F28+I28+K28+N28+Q28 -> 12475.079 | S28: =R28*0.2 -> 2495.0159 | T28: 81413 | U28: =IF(ISBLANK(T28),"0",T28-T27) -> 56 | V28: 36904 | W28: =IF(ISBLANK(V28),"0",V28-V27) -> 7 | X28: =U28-W28 -> 49 | Y28: =X28*7.84 -> 384.16 | Z28: 1 | AA28: =Z28*50*1.96 -> 98 | AB28: =AA28*1.2551 -> 122.9998 | AC28: 5 | AD28: 82337 | AE28: =IF(ISBLANK(AD28),"0",AD28-AD27) -> 8 | AF28: =IF(ISBLANK(AD28),"0 ",AE28*284.345) -> 2274.76 | AG28: =AF28*0.3449 -> 784.56472 | AH28: =IF(ISBLANK(AD28),"0",1754*1608.73/12/31*0.66) -> 5006.264 | AI28: =AG28+AH28 -> 5790.8287 | AJ28: 2430495 | AK28: =IF(ISBLANK(AJ28),"0",AJ28-AJ27) -> 3488 | AL28: =IF(ISBLANK(AK28),"0 ",AK28/284.345) -> 12.266789 | AM28: 0.9768 | AN28: 329 | AO28: =AM28*259 -> 252.9912
A29: 45682 | B29: 9788955 | C29: =IF(ISBLANK(B29),"0",B29-B28) -> 2123 | D29: 23747798 | E29: =IF(ISBLANK(D29),"0",D29-D28) -> 6899 | F29: =E29*0.9438 -> 6511.2762 | G29: 15425538 | H29: =IF(ISBLANK(G29),"0",G29-G28) -> 3860 | I29: =H29*0.6536 -> 2522.896 | J29: 3713057 | K29: =IF(ISBLANK(J29),"0",J29-J28) -> 1239 | L29: 1460 | M29: =IF(ISBLANK(L29),"0",L29-L28) -> 18 | N29: =M29*0.5 -> 9 | O29: 879 | P29: =IF(ISBLANK(O29),"0",O29-O28) -> 15 | Q29: =P29*0.5 -> 7.5 | R29: =C29+F29+I29+K29+N29+Q29 -> 12412.672 | S29: =R29*0.2 -> 2482.5344 | T29: 81497 | U29: =IF(ISBLANK(T29),"0",T29-T28) -> 84 | V29: 36911 | W29: =IF(ISBLANK(V29),"0",V29-V28) -> 7 | X29: =U29-W29 -> 77 | Y29: =X29*7.84 -> 603.68 | Z29: 1 | AA29: =Z29*50*1.96 -> 98 | AB29: =AA29*1.2551 -> 122.9998 | AC29: 0 | AD29: 82345 | AE29: =IF(ISBLANK(AD29),"0",AD29-AD28) -> 8 | AF29: =IF(ISBLANK(AD29),"0 ",AE29*284.345) -> 2274.76 | AG29: =AF29*0.3449 -> 784.56472 | AH29: =IF(ISBLANK(AD29),"0",1754*1608.73/12/31*0.66) -> 5006.264 | AI29: =AG29+AH29 -> 5790.8287 | AJ29: 2433946 | AK29: =IF(ISBLANK(AJ29),"0",AJ29-AJ28) -> 3451 | AL29: =IF(ISBLANK(AK29),"0 ",AK29/284.345) -> 12.136665 | AM29: 0.9537 | AN29: 310 | AO29: =AM29*259 -> 247.0083
A30: 45683 | B30: 9791140 | C30: =IF(ISBLANK(B30),"0",B30-B29) -> 2185 | D30: 23754846 | E30: =IF(ISBLANK(D30),"0",D30-D29) -> 7048 | F30: =E30*0.9438 -> 6651.9024 | G30: 15429496 | H30: =IF(ISBLANK(G30),"0",G30-G29) -> 3958 | I30: =H30*0.6536 -> 2586.9488 | J30: 3714301 | K30: =IF(ISBLANK(J30),"0",J30-J29) -> 1244 | L30: 1460 | M30: =IF(ISBLANK(L30),"0",L30-L29) -> 0 | N30: =M30*0.5 -> 0 | O30: 879 | P30: =IF(ISBLANK(O30),"0",O30-O29) -> 0 | Q30: =P30*0.5 -> 0 | R30: =C30+F30+I30+K30+N30+Q30 -> 12667.851 | S30: =R30*0.2 -> 2533.5702 | T30: 81554 | U30: =IF(ISBLANK(T30),"0",T30-T29) -> 57 | V30: 36919 | W30: =IF(ISBLANK(V30),"0",V30-V29) -> 8 | X30: =U30-W30 -> 49 | Y30: =X30*7.84 -> 384.16 | Z30: 2 | AA30: =Z30*50*1.96 -> 196 | AB30: =AA30*1.2551 -> 245.9996 | AC30: 0 | AD30: 82354 | AE30: =IF(ISBLANK(AD30),"0",AD30-AD29) -> 9 | AF30: =IF(ISBLANK(AD30),"0 ",AE30*284.345) -> 2559.105 | AG30: =AF30*0.3449 -> 882.63531 | AH30: =IF(ISBLANK(AD30),"0",1754*1608.73/12/31*0.66) -> 5006.264 | AI30: =AG30+AH30 -> 5888.8993 | AJ30: 2437825 | AK30: =IF(ISBLANK(AJ30),"0",AJ30-AJ29) -> 3879 | AL30: =IF(ISBLANK(AK30),"0 ",AK30/284.345) -> 13.641879 | AM30: 0.8224 | AN30: 246 | AO30: =AM30*259 -> 213.0016
A31: 45684 | B31: 9793289 | C31: =IF(ISBLANK(B31),"0",B31-B30) -> 2149 | D31: 23761877 | E31: =IF(ISBLANK(D31),"0",D31-D30) -> 7031 | F31: =E31*0.9438 -> 6635.8578 | G31: 15433545 | H31: =IF(ISBLANK(G31),"0",G31-G30) -> 4049 | I31: =H31*0.6536 -> 2646.4264 | J31: 3715559 | K31: =IF(ISBLANK(J31),"0",J31-J30) -> 1258 | L31: 1460 | M31: =IF(ISBLANK(L31),"0",L31-L30) -> 0 | N31: =M31*0.5 -> 0 | O31: 879 | P31: =IF(ISBLANK(O31),"0",O31-O30) -> 0 | Q31: =P31*0.5 -> 0 | R31: =C31+F31+I31+K31+N31+Q31 -> 12689.284 | S31: =R31*0.2 -> 2537.8568 | T31: 81600 | U31: =IF(ISBLANK(T31),"0",T31-T30) -> 46 | V31: 36926 | W31: =IF(ISBLANK(V31),"0",V31-V30) -> 7 | X31: =U31-W31 -> 39 | Y31: =X31*7.84 -> 305.76 | Z31: 1 | AA31: =Z31*50*1.96 -> 98 | AB31: =AA31*1.2551 -> 122.9998 | AC31: 0 | AD31: 82364 | AE31: =IF(ISBLANK(AD31),"0",AD31-AD30) -> 10 | AF31: =IF(ISBLANK(AD31),"0 ",AE31*284.345) -> 2843.45 | AG31: =AF31*0.3449 -> 980.70591 | AH31: =IF(ISBLANK(AD31),"0",1754*1608.73/12/31*0.66) -> 5006.264 | AI31: =AG31+AH31 -> 5986.9699 | AJ31: 2442224 | AK31: =IF(ISBLANK(AJ31),"0",AJ31-AJ30) -> 4399 | AL31: =IF(ISBLANK(AK31),"0 ",AK31/284.345) -> 15.470643 | AM31: 0.9614 | AN31: 294 | AO31: =AM31*259 -> 249.0026
A32: 45685 | B32: 9795378 | C32: =IF(ISBLANK(B32),"0",B32-B31) -> 2089 | D32: 23768447 | E32: =IF(ISBLANK(D32),"0",D32-D31) -> 6570 | F32: =E32*0.9438 -> 6200.766 | G32: 15437182 | H32: =IF(ISBLANK(G32),"0",G32-G31) -> 3637 | I32: =H32*0.6536 -> 2377.1432 | J32: 3716771 | K32: =IF(ISBLANK(J32),"0",J32-J31) -> 1212 | L32: 1460 | M32: =IF(ISBLANK(L32),"0",L32-L31) -> 0 | N32: =M32*0.5 -> 0 | O32: 879 | P32: =IF(ISBLANK(O32),"0",O32-O31) -> 0 | Q32: =P32*0.5 -> 0 | R32: =C32+F32+I32+K32+N32+Q32 -> 11878.909 | S32: =R32*0.2 -> 2375.7818 | T32: 81651 | U32: =IF(ISBLANK(T32),"0",T32-T31) -> 51 | V32: 36935 | W32: =IF(ISBLANK(V32),"0",V32-V31) -> 9 | X32: =U32-W32 -> 42 | Y32: =X32*7.84 -> 329.28 | Z32: 2 | AA32: =Z32*50*1.96 -> 196 | AB32: =AA32*1.2551 -> 245.9996 | AC32: 5 | AD32: 82374 | AE32: =IF(ISBLANK(AD32),"0",AD32-AD31) -> 10 | AF32: =IF(ISBLANK(AD32),"0 ",AE32*284.345) -> 2843.45 | AG32: =AF32*0.3449 -> 980.70591 | AH32: =IF(ISBLANK(AD32),"0",1754*1608.73/12/31*0.66) -> 5006.264 | AI32: =AG32+AH32 -> 5986.9699 | AJ32: 2446550 | AK32: =IF(ISBLANK(AJ32),"0",AJ32-AJ31) -> 4326 | AL32: =IF(ISBLANK(AK32),"0 ",AK32/284.345) -> 15.213913 | AM32: 0.9653 | AN32: 298 | AO32: =AM32*259 -> 250.0127
A33: 45686 | B33: 9797542 | C33: =IF(ISBLANK(B33),"0",B33-B32) -> 2164 | D33: 23775263 | E33: =IF(ISBLANK(D33),"0",D33-D32) -> 6816 | F33: =E33*0.9438 -> 6432.9408 | G33: 15441131 | H33: =IF(ISBLANK(G33),"0",G33-G32) -> 3949 | I33: =H33*0.6536 -> 2581.0664 | J33: 3718016 | K33: =IF(ISBLANK(J33),"0",J33-J32) -> 1245 | L33: 1460 | M33: =IF(ISBLANK(L33),"0",L33-L32) -> 0 | N33: =M33*0.5 -> 0 | O33: 880 | P33: =IF(ISBLANK(O33),"0",O33-O32) -> 1 | Q33: =P33*0.5 -> 0.5 | R33: =C33+F33+I33+K33+N33+Q33 -> 12423.507 | S33: =R33*0.2 -> 2484.7014 | T33: 81752 | U33: =IF(ISBLANK(T33),"0",T33-T32) -> 101 | V33: 36942 | W33: =IF(ISBLANK(V33),"0",V33-V32) -> 7 | X33: =U33-W33 -> 94 | Y33: =X33*7.84 -> 736.96 | Z33: 1 | AA33: =Z33*50*1.96 -> 98 | AB33: =AA33*1.2551 -> 122.9998 | AC33: 0 | AD33: 82383 | AE33: =IF(ISBLANK(AD33),"0",AD33-AD32) -> 9 | AF33: =IF(ISBLANK(AD33),"0 ",AE33*284.345) -> 2559.105 | AG33: =AF33*0.3449 -> 882.63531 | AH33: =IF(ISBLANK(AD33),"0",1754*1608.73/12/31*0.66) -> 5006.264 | AI33: =AG33+AH33 -> 5888.8993 | AJ33: 2450759 | AK33: =IF(ISBLANK(AJ33),"0",AJ33-AJ32) -> 4209 | AL33: =IF(ISBLANK(AK33),"0 ",AK33/284.345) -> 14.802441 | AM33: 0.9344 | AN33: 284 | AO33: =AM33*259 -> 242.0096
A34: 45687 | B34: 9799645 | C34: =IF(ISBLANK(B34),"0",B34-B33) -> 2103 | D34: 23782284 | E34: =IF(ISBLANK(D34),"0",D34-D33) -> 7021 | F34: =E34*0.9438 -> 6626.4198 | G34: 15445117 | H34: =IF(ISBLANK(G34),"0",G34-G33) -> 3986 | I34: =H34*0.6536 -> 2605.2496 | J34: 3719234 | K34: =IF(ISBLANK(J34),"0",J34-J33) -> 1218 | L34: 1460 | M34: =IF(ISBLANK(L34),"0",L34-L33) -> 0 | N34: =M34*0.5 -> 0 | O34: 880 | P34: =IF(ISBLANK(O34),"0",O34-O33) -> 0 | Q34: =P34*0.5 -> 0 | R34: =C34+F34+I34+K34+N34+Q34 -> 12552.669 | S34: =R34*0.2 -> 2510.5339 | T34: 81880 | U34: =IF(ISBLANK(T34),"0",T34-T33) -> 128 | V34: 36949 | W34: =IF(ISBLANK(V34),"0",V34-V33) -> 7 | X34: =U34-W34 -> 121 | Y34: =X34*7.84 -> 948.64 | Z34: 1 | AA34: =Z34*50*1.96 -> 98 | AB34: =AA34*1.2551 -> 122.9998 | AC34: 0 | AD34: 82392 | AE34: =IF(ISBLANK(AD34),"0",AD34-AD33) -> 9 | AF34: =IF(ISBLANK(AD34),"0 ",AE34*284.345) -> 2559.105 | AG34: =AF34*0.3449 -> 882.63531 | AH34: =IF(ISBLANK(AD34),"0",1754*1608.73/12/31*0.66) -> 5006.264 | AI34: =AG34+AH34 -> 5888.8993 | AJ34: 2454778 | AK34: =IF(ISBLANK(AJ34),"0",AJ34-AJ33) -> 4019 | AL34: =IF(ISBLANK(AK34),"0 ",AK34/284.345) -> 14.134238 | AM34: 0.9807 | AN34: 308 | AO34: =AM34*259 -> 254.0013
A35: 45688 | B35: 9801748 | C35: =IF(ISBLANK(B35),"0",B35-B34) -> 2103 | D35: 23789512 | E35: =IF(ISBLANK(D35),"0",D35-D34) -> 7228 | F35: =E35*0.9438 -> 6821.7864 | G35: 15449107 | H35: =IF(ISBLANK(G35),"0",G35-G34) -> 3990 | I35: =H35*0.6536 -> 2607.864 | J35: 3720506 | K35: =IF(ISBLANK(J35),"0",J35-J34) -> 1272 | L35: 1460 | M35: =IF(ISBLANK(L35),"0",L35-L34) -> 0 | N35: =M35*0.5 -> 0 | O35: 881 | P35: =IF(ISBLANK(O35),"0",O35-O34) -> 1 | Q35: =P35*0.5 -> 0.5 | R35: =C35+F35+I35+K35+N35+Q35 -> 12805.15 | S35: =R35*0.2 -> 2561.0301 | T35: 81970 | U35: =IF(ISBLANK(T35),"0",T35-T34) -> 90 | V35: 36961 | W35: =IF(ISBLANK(V35),"0",V35-V34) -> 12 | X35: =U35-W35 -> 78 | Y35: =X35*7.84 -> 611.52 | Z35: 2 | AA35: =Z35*50*1.96 -> 196 | AB35: =AA35*1.2551 -> 245.9996 | AC35: 6 | AD35: 82400 | AE35: =IF(ISBLANK(AD35),"0",AD35-AD34) -> 8 | AF35: =IF(ISBLANK(AD35),"0 ",AE35*284.345) -> 2274.76 | AG35: =AF35*0.3449 -> 784.56472 | AH35: =IF(ISBLANK(AD35),"0",1754*1608.73/12/31*0.66) -> 5006.264 | AI35: =AG35+AH35 -> 5790.8287 | AJ35: 2458323 | AK35: =IF(ISBLANK(AJ35),"0",AJ35-AJ34) -> 3545 | AL35: =IF(ISBLANK(AK35),"0 ",AK35/284.345) -> 12.467249 | AM35: 1 | AN35: 320 | AO35: =AM35*259 -> 259
C36: =SUM(C5:C35) -> 66101 | F36: =SUM(F5:F35) -> 198494.35 | I36: =SUM(I5:I35) -> 81834.642 | K36: =SUM(K5:K35) -> 38792 | N36: =SUM(N5:N35) -> 37.5 | Q36: =SUM(Q5:Q35) -> 23 | R36: =SUM(R5:R35) -> 385282.49 | S36: =R36*0.2 -> 77056.499 | U36: =SUM(U5:U35) -> 2565 | W36: =SUM(W5:W35) -> 234 | X36: =SUM(X5:X35) -> 2331 | Y36: =SUM(Y5:Y35) -> 18275.04 | Z36: =SUM(Z5:Z35) -> 37 | AA36: =SUM(AA5:AA35) -> 3626 | AB36: =SUM(AB5:AB35) -> 4550.9926 | AC36: =SUM(AC5:AC35) -> 48 | AE36: =SUM(AE5:AE35) -> 273 | AF36: =SUM(AF5:AF35) -> 77626.185 | AG36: =SUM(AG5:AG35) -> 26773.271 | AH36: =SUM(AH5:AH35) -> 155194.18 | AI36: =SUM(AI5:AI35) -> 181967.45 | AK36: =SUM(AK5:AK35) -> 120770 | AL36: =SUM(AL5:AL35) -> 424.73052 | AM36: =AVERAGE(AM5:AM35) -> 0.89845484 | AN36: =SUM(AN5:AN35) -> 8842 | AO36: =SUM(AO5:AO35) -> 7213.6939
AD37: AVT Charges should be Zero in the DC invoice - Please notify if not
B38: Electricity | G38: AED | K38: KW | T38: Water | V38: AED | X38: M3 | Z38: Gas | AA38: AED | AB38: Litres | AD38: District Cooling | AF38: AED | AH38: Ton Hour
B39: Actual January 2025 | G39: =S36 -> 77056.499 | K39: =G39/0.2 -> 385282.49 | T39: =B39 -> Actual January 2025 | V39: =Y36 -> 18275.04 | X39: =X36 -> 2331 | Z39: =T39 -> Actual January 2025 | AA39: =AB36 -> 4550.9926 | AB39: =AA39/1.2551 -> 3626 | AD39: =T39 -> Actual January 2025 | AF39: =AI36 -> 181967.45 | AH39: =AF36 -> 77626.185 | AI39: =(AD39-#REF!)/0.3428 -> #VALUE! | AP39: 149225.58
B40: Budget January 2025 | G40: 77595.369 | K40: =G40/0.2 -> 387976.84 | T40: =B40 -> Budget January 2025 | V40: 14242.697 | X40: =V40/7.84 -> 1816.6705 | Z40: =T40 -> Budget January 2025 | AA40: 4317.6851 | AB40: =AA40/1.2551 -> 3440.1124 | AD40: =T40 -> Budget January 2025 | AF40: 192800.98 | AH40: =AP40/0.3449 -> 109036.82 | AI40: =(AD40-AF36)/0.3428 -> #VALUE! | AP40: =AF40-AH36 -> 37606.798 | AQ40: CHW Consumption Charges (Budget 2025 MTD)
B41: Actual YTD 2025 | G41: =G39 -> 77056.499 | K41: =G41/0.2 -> 385282.49 | T41: =B41 -> Actual YTD 2025 | V41: =V39 -> 18275.04 | X41: =V41/7.84 -> 2331 | Z41: =T41 -> Actual YTD 2025 | AA41: =AA39 -> 4550.9926 | AB41: =AA41/1.2551 -> 3626 | AD41: =T41 -> Actual YTD 2025 | AF41: =AF39 -> 181967.45 | AH41: =AP41/0.3449 -> 77626.194 | AP41: =AF41-AP46 -> 26773.274 | AQ41: CHW Consumption Charges (Actual 2025 YTD)
B42: Budget YTD 2025 | G42: 77595.369 | K42: =G42/0.2 -> 387976.84 | T42: =B42 -> Budget YTD 2025 | V42: 14242.697 | X42: =V42/7.84 -> 1816.6705 | Z42: =T42 -> Budget YTD 2025 | AA42: 4317.6851 | AB42: =AA42/1.2551 -> 3440.1124 | AD42: =T42 -> Budget YTD 2025 | AF42: 192800.98 | AH42: =AP42/0.3449 -> 109036.83 | AI42: =(AD42-AF38)/0.3428 -> #VALUE! | AP42: =AF42-AP46 -> 37606.801 | AQ42: CHW Consumption Charges (Budget 2025 YTD)
B43: Actual January 2024 | G43: 75167.11 | K43: =G43/0.2 -> 375835.55 | T43: =B43 -> Actual January 2024 | V43: 12277.44 | X43: =V43/7.84 -> 1566 | Z43: =T43 -> Actual January 2024 | AA43: 3696.02 | AB43: =AA43/0.8571 -> 4312.2389 | AD43: =T43 -> Actual January 2024 | AF43: 180863.96 | AH43: =AP43/0.3442 -> 108594.86 | AI43: =(AD43-AF39)/0.3428 -> #VALUE! | AP43: =AF43-AP48 -> 37378.35 | AQ43: CHW Consumption Charges (Actual 2024 MTD)
B44: Actual YTD 2024 | G44: 75167.11 | K44: =G44/0.2 -> 375835.55 | T44: =B44 -> Actual YTD 2024 | V44: 12277.44 | X44: =V44/7.84 -> 1566 | Z44: =T44 -> Actual YTD 2024 | AA44: 3696.02 | AB44: =AA44/0.8571 -> 4312.2389 | AD44: =T44 -> Actual YTD 2024 | AF44: 180863.96 | AH44: =AP44/0.3442 -> 91918.594 | AI44: =(AD44-AF40)/0.3428 -> #VALUE! | AP44: =AF44-AP47 -> 31638.38 | AQ44: CHW Consumption Charges (Actual 2024 YTD)
G45: 45658 | I45: 45688 | J45: 31
A46: Monthly Budget | D46: Daily Budget | I46: MTD Average | N46: MTD Budget | U46: MTD Actual | Y46: YTD Budget | AD46: YTD Actual | AG46: Savings | AH46: Exceeds | AP46: =155194.18 -> 155194.18 | AQ46: CHW Fixed Charges YTD 2025
A47: Electricity | B47: =G40 -> 77595.369 | D47: Electricity | G47: =B47/31 -> 2503.0764 | I47: Electricity | L47: =S36/J45 -> 2485.6935 | N47: Electricity | S47: =G47*J45 -> 77595.369 | U47: Electricity | W47: =S36 -> 77056.499 | X47: =S47-W47 -> 538.8696 | Y47: Electricity | AA47: =S47+G42 -> 155190.74 | AD47: Electricity | AF47: =W47+G41 -> 154113 | AG47: =AA47-AF47 -> 1077.7392 | AH47: =AF47-AA47 -> -1077.7392 | AP47: =149225.58 -> 149225.58 | AQ47: CHW Fixed Charges YTD 2024
A48: Water | B48: =V40 -> 14242.697 | D48: Water | G48: =B48/31 -> 459.44183 | I48: Water | L48: =Y36/J45 -> 589.51742 | N48: Water | S48: =G48*J45 -> 14242.697 | U48: Water | W48: =Y36 -> 18275.04 | X48: =S48-W48 -> -4032.3433 | Y48: Water | AA48: =S48+V42 -> 28485.393 | AD48: Water | AF48: =W48+V41 -> 36550.08 | AG48: =AA48-AF48 -> -8064.6865 | AH48: =AF48-AA48 -> 8064.6865 | AP48: =143485.61 -> 143485.61
A49: Gas | B49: =AA40 -> 4317.6851 | D49: Gas | G49: =B49/31 -> 139.28016 | I49: Gas | L49: =AB36/J45 -> 146.80621 | N49: Gas | S49: =G49*J45 -> 4317.6851 | U49: Gas | W49: =AB36 -> 4550.9926 | X49: =S49-W49 -> -233.30754 | Y49: Gas | AA49: =S49+AA42 -> 8635.3701 | AD49: Gas | AF49: =W49+AA41 -> 9101.9852 | AG49: =AA49-AF49 -> -466.61507 | AH49: =AF49-AA49 -> 466.61507
...
