Workbook
Name شت8: 'cost.4.25'!$H$18

Sheet Total
A1: Site Name | B1: Day | C1: Month | D1: Year | E1: Total Electricity Kwh | F1: Electricity Tariff ($/Kwh) | G1: LPG (Liters) | H1: LPG $/Liters | I1: Total Fuel Oil (Liter) | J1: Fuel Oil $/Liter | K1: Water Utility Supply (m3) m3 | L1: Water Utility Supply (m3) $/m3 | M1: Room Nights | N1: Total Guests
A2: Grand Rotana Sharm El Cheikh | B2: 1 | C2: 4 | D2: 2025 | E2: ='cost.4.25'!J8 -> 34640 | F2: 1.49 | G2: ='cost.4.25'!AN8 -> 874.712 | H2: ='cost.4.25'!AS8/'cost.4.25'!AN8 -> 3.8150123 | I2: ='cost.4.25'!O8 -> 0 | J2: ='cost.4.25'!T8/'cost.4.25'!O8 -> #DIV/0! | K2: ='cost.4.25'!V8 -> 777 | L2: ='cost.4.25'!Z8/'cost.4.25'!V8 -> 5.1 | M2: ='cost.4.25'!F8 -> 459.1454
A3: Grand Rotana Sharm El Cheikh | B3: =B2+1 -> 2 | C3: 4 | D3: 2025 | E3: ='cost.4.25'!J9 -> 33760 | F3: 1.49 | G3: ='cost.4.25'!AN9 -> 925.306 | H3: ='cost.4.25'!AS9/'cost.4.25'!AN9 -> 3.8076397 | I3: ='cost.4.25'!O9 -> 0 | J3: ='cost.4.25'!T9/'cost.4.25'!O9 -> #DIV/0! | K3: ='cost.4.25'!V9 -> 754 | L3: ='cost.4.25'!Z9/'cost.4.25'!V9 -> 5.1 | M3: ='cost.4.25'!F9 -> 461.9858
A4: Grand Rotana Sharm El Cheikh | B4: =B3+1 -> 3 | C4: 4 | D4: 2025 | E4: ='cost.4.25'!J10 -> 35000 | F4: 1.49 | G4: ='cost.4.25'!AN10 -> 1031.626 | H4: ='cost.4.25'!AS10/'cost.4.25'!AN10 -> 3.8057468 | I4: ='cost.4.25'!O10 -> 0 | J4: ='cost.4.25'!T10/'cost.4.25'!O10 -> #DIV/0! | K4: ='cost.4.25'!V10 -> 753 | L4: ='cost.4.25'!Z10/'cost.4.25'!V10 -> 5.1 | M4: ='cost.4.25'!F10 -> 444.996
A5: Grand Rotana Sharm El Cheikh | B5: =B4+1 -> 4 | C5: 4 | D5: 2025 | E5: ='cost.4.25'!J11 -> 0 | F5: 1.49 | G5: ='cost.4.25'!AN11 -> 0 | H5: ='cost.4.25'!AS11/'cost.4.25'!AN11 -> #DIV/0! | I5: ='cost.4.25'!O11 -> 0 | J5: ='cost.4.25'!T11/'cost.4.25'!O11 -> #DIV/0! | K5: ='cost.4.25'!V11 -> 0 | L5: ='cost.4.25'!Z11/'cost.4.25'!V11 -> #DIV/0! | M5: ='cost.4.25'!F11 -> 0
A6: Grand Rotana Sharm El Cheikh | B6: =B5+1 -> 5 | C6: 4 | D6: 2025 | E6: ='cost.4.25'!J12 -> 0 | F6: 1.49 | G6: ='cost.4.25'!AN12 -> 0 | H6: ='cost.4.25'!AS12/'cost.4.25'!AN12 -> #DIV/0! | I6: ='cost.4.25'!O12 -> 0 | J6: ='cost.4.25'!T12/'cost.4.25'!O12 -> #DIV/0! | K6: ='cost.4.25'!V12 -> 0 | L6: ='cost.4.25'!Z12/'cost.4.25'!V12 -> #DIV/0! | M6: ='cost.4.25'!F12 -> 0
A7: Grand Rotana Sharm El Cheikh | B7: =B6+1 -> 6 | C7: 4 | D7: 2025 | E7: ='cost.4.25'!J13 -> 0 | F7: 1.49 | G7: ='cost.4.25'!AN13 -> 0 | H7: ='cost.4.25'!AS13/'cost.4.25'!AN13 -> #DIV/0! | I7: ='cost.4.25'!O13 -> 0 | J7: ='cost.4.25'!T13/'cost.4.25'!O13 -> #DIV/0! | K7: ='cost.4.25'!V13 -> 0 | L7: ='cost.4.25'!Z13/'cost.4.25'!V13 -> #DIV/0! | M7: ='cost.4.25'!F13 -> 0
A8: Grand Rotana Sharm El Cheikh | B8: =B7+1 -> 7 | C8: 4 | D8: 2025 | E8: ='cost.4.25'!J14 -> 0 | F8: 1.49 | G8: ='cost.4.25'!AN14 -> 0 | H8: ='cost.4.25'!AS14/'cost.4.25'!AN14 -> #DIV/0! | I8: ='cost.4.25'!O14 -> 0 | J8: ='cost.4.25'!T14/'cost.4.25'!O14 -> #DIV/0! | K8: ='cost.4.25'!V14 -> 0 | L8: ='cost.4.25'!Z14/'cost.4.25'!V14 -> #DIV/0! | M8: ='cost.4.25'!F14 -> 0
A9: Grand Rotana Sharm El Cheikh | B9: =B8+1 -> 8 | C9: 4 | D9: 2025 | E9: ='cost.4.25'!J15 -> 0 | F9: 1.49 | G9: ='cost.4.25'!AN15 -> 0 | H9: ='cost.4.25'!AS15/'cost.4.25'!AN15 -> #DIV/0! | I9: ='cost.4.25'!O15 -> 0 | J9: ='cost.4.25'!T15/'cost.4.25'!O15 -> #DIV/0! | K9: ='cost.4.25'!V15 -> 0 | L9: ='cost.4.25'!Z15/'cost.4.25'!V15 -> #DIV/0! | M9: ='cost.4.25'!F15 -> 0
A10: Grand Rotana Sharm El Cheikh | B10: =B9+1 -> 9 | C10: 4 | D10: 2025 | E10: ='cost.4.25'!J16 -> 0 | F10: 1.49 | G10: ='cost.4.25'!AN16 -> 0 | H10: ='cost.4.25'!AS16/'cost.4.25'!AN16 -> #DIV/0! | I10: ='cost.4.25'!O16 -> 0 | J10: ='cost.4.25'!T16/'cost.4.25'!O16 -> #DIV/0! | K10: ='cost.4.25'!V16 -> 0 | L10: ='cost.4.25'!Z16/'cost.4.25'!V16 -> #DIV/0! | M10: ='cost.4.25'!F16 -> 0
A11: Grand Rotana Sharm El Cheikh | B11: =B10+1 -> 10 | C11: 4 | D11: 2025 | E11: ='cost.4.25'!J17 -> 0 | F11: 1.49 | G11: ='cost.4.25'!AN17 -> 0 | H11: ='cost.4.25'!AS17/'cost.4.25'!AN17 -> #DIV/0! | I11: ='cost.4.25'!O17 -> 0 | J11: ='cost.4.25'!T17/'cost.4.25'!O17 -> #DIV/0! | K11: ='cost.4.25'!V17 -> 0 | L11: ='cost.4.25'!Z17/'cost.4.25'!V17 -> #DIV/0! | M11: ='cost.4.25'!F17 -> 0
A12: Grand Rotana Sharm El Cheikh | B12: =B11+1 -> 11 | C12: 4 | D12: 2025 | E12: ='cost.4.25'!J18 -> 0 | F12: 1.49 | G12: ='cost.4.25'!AN18 -> 0 | H12: ='cost.4.25'!AS18/'cost.4.25'!AN18 -> #DIV/0! | I12: ='cost.4.25'!O18 -> 0 | J12: ='cost.4.25'!T18/'cost.4.25'!O18 -> #DIV/0! | K12: ='cost.4.25'!V18 -> 0 | L12: ='cost.4.25'!Z18/'cost.4.25'!V18 -> #DIV/0! | M12: ='cost.4.25'!F18 -> 0
A13: Grand Rotana Sharm El Cheikh | B13: =B12+1 -> 12 | C13: 4 | D13: 2025 | E13: ='cost.4.25'!J19 -> 0 | F13: 1.49 | G13: ='cost.4.25'!AN19 -> 0 | H13: ='cost.4.25'!AS19/'cost.4.25'!AN19 -> #DIV/0! | I13: ='cost.4.25'!O19 -> 0 | J13: ='cost.4.25'!T19/'cost.4.25'!O19 -> #DIV/0! | K13: ='cost.4.25'!V19 -> 0 | L13: ='cost.4.25'!Z19/'cost.4.25'!V19 -> #DIV/0! | M13: ='cost.4.25'!F19 -> 0
A14: Grand Rotana Sharm El Cheikh | B14: =B13+1 -> 13 | C14: 4 | D14: 2025 | E14: ='cost.4.25'!J20 -> 0 | F14: 1.49 | G14: ='cost.4.25'!AN20 -> 0 | H14: ='cost.4.25'!AS20/'cost.4.25'!AN20 -> #DIV/0! | I14: ='cost.4.25'!O20 -> 0 | J14: ='cost.4.25'!T20/'cost.4.25'!O20 -> #DIV/0! | K14: ='cost.4.25'!V20 -> 0 | L14: ='cost.4.25'!Z20/'cost.4.25'!V20 -> #DIV/0! | M14: ='cost.4.25'!F20 -> 0
... A31: Grand Rotana Sharm El Cheikh | B31: =B30+1 -> 30 | C31: 4 | D31: 2025 | E31: ='cost.4.25'!J37 -> 0 | F31: 1.49 | G31: ='cost.4.25'!AN37 -> 0 | H31: ='cost.4.25'!AS37/'cost.4.25'!AN37 -> #DIV/0! | I31: ='cost.4.25'!O37 -> 0 | J31: ='cost.4.25'!T37/'cost.4.25'!O37 -> #DIV/0! | K31: ='cost.4.25'!V37 -> 0 | L31: ='cost.4.25'!Z37/'cost.4.25'!V37 -> #DIV/0! | M31: ='cost.4.25'!F37 -> 0
A32: Grand Rotana Sharm El Cheikh | B32: =B31+1 -> 31 | C32: 4 | D32: 2025 | I32: ='cost.4.25'!O38 -> 0 | J32: ='cost.4.25'!T38/'cost.4.25'!O38 -> #DIV/0!

Sheet Daily Consumption
A1: Date: | B1: =TODAY()-1 -> 45752
A2: Energy Consumption
L3: Month To Date Energy Cost per Occupied Room
B4: Today | F4: Month To Date
B5: Actual | C5: Budget | D5: Act Vs Bdgt | E5: Forecast | F5: Actual | G5: Budget | H5: Act Vs Bdgt | I5: Act Vs Forcast | J5: Forecast
A7: Occupied Rooms | B7: =VLOOKUP(B1,'Reading.4.25'!A5:EL35,39,FALSE) -> 0 | C7: ='Reading.4.25'!AO6 -> 341.9 | D7: =B7-C7 -> -341.9 | E7: 431.3 | F7: ='Reading.4.25'!AM36 -> 1366.1272 | G7: =C7*DAY(B1) -> 1709.5 | H7: =(F7-G7)/F7 -> -0.25134761 | I7: =(F7-J7)/F7 -> -0.57854993 | J7: =E7*DAY(B1) -> 2156.5
A8: Occupancy | B8: =VLOOKUP(B1,'Reading.4.25'!A5:EL35,35,FALSE) -> 0 | C8: ='Reading.4.25'!AK6 -> 0.65 | D8: =B8-C8 -> -0.65 | E8: 0.82 | F8: ='Reading.4.25'!AI36 -> 0.86573333 | G8: =C8 -> 0.65 | H8: =F8-G8 -> 0.21573333 | I8: =F8-J8 -> 0.17673333 | J8: 0.689
A10: Electricity - KWH | B10: =VLOOKUP(B1,'Reading.4.25'!A5:EL35,31,FALSE) -> 0 | C10: ='Reading.4.25'!AG6 -> 26554.533 | D10: =B10-C10 -> -26554.533 | E10: 39500 | F10: ='Reading.4.25'!AE36 -> 103620 | G10: =C10*DAY(B1) -> 132772.67 | H10: =(F10-G10)/F10 -> -0.28134208 | I10: =(F10-J10)/F10 -> -0.9060027 | J10: =+E10*DAY(B1) -> 197500
A11: Fuel - Liter | B11: =VLOOKUP(B1,'Reading.4.25'!A5:EL35,20,FALSE) -> 0 | C11: ='cost.4.25'!P8 -> 83.967742 | D11: =B11-C11 -> -83.967742 | E11: 0 | F11: ='Reading.4.25'!T36 -> 0 | G11: =C11*DAY(B1) -> 419.83871 | H11: =F11-G11 -> -419.83871 | I11: =F11-J11 -> 0 | J11: 0
A13: Boilers Gas - Cu.Mt. | B13: =VLOOKUP(B1,'Reading.4.25'!A5:EL35,15,FALSE) -> 0 | C13: ='cost.4.25'!AD8 -> 487.5 | D13: =B13-C13 -> -487.5 | E13: 636 | F13: ='Reading.4.25'!O36 -> 2000.74 | G13: =C13*DAY(B1) -> 2437.5 | H13: =(F13-G13)/F13 -> -0.21829923 | I13: =(F13-J13)/F13 -> -0.58941192 | J13: =E13*DAY(B1) -> 3180
A14: Kitchens Gas - Cu. Mt. | B14: =VLOOKUP(B1,'Reading.4.25'!A5:EL35,11,FALSE) -> 0 | C14: ='cost.4.25'!AJ8 -> 162.5 | D14: =B14-C14 -> -162.5 | E14: 212 | F14: ='Reading.4.25'!K36 -> 830.904 | G14: =C14*DAY(B1) -> 812.5 | H14: =(F14-G14)/F14 -> 0.02214937 | I14: =(F14-J14)/F14 -> -0.27571898 | J14: =E14*DAY(B1) -> 1060
H15: =F15-G15 -> 0
A16: Water To Staff House - Cu.Mt. | B16: =VLOOKUP(B1,'Reading.4.25'!A2:EL35,88,FALSE) -> 0 | C16: 0 | D16: =B16-C16 -> 0 | E16: 0 | F16: 0 | G16: 0 | H16: =F16-G16 -> 0 | J16: 0
A17: Laundry Water - Cu.Mt. | B17: =VLOOKUP(B1,'Reading.4.25'!A5:EL35,73,FALSE) -> 0 | C17: 0 | D17: =-B17-C17 -> 0 | E17: 0 | F17: ='Reading.4.25'!BU36 -> 172 | G17: 0 | H17: =F17-G17 -> 172 | J17: 0
A18: Kitchen Water - Cu.Mt. | B18: =VLOOKUP(B1,'Reading.4.25'!A5:EL35,69,FALSE) -> 0 | C18: 0 | D18: =B18-C18 -> 0 | E18: 0 | F18: ='Reading.4.25'!BQ36 -> 140 | G18: 0 | H18: =F18-G18 -> 140 | J18: 0
A19: Hotel Water - Cu.Mt. | B19: =VLOOKUP(B1,'Reading.4.25'!A5:EL35,6,FALSE) -> 0 | C19: ='cost.4.25'!W8 -> 493.48387 | D19: =B19-C19 -> -493.48387 | E19: 656 | F19: ='cost.4.25'!V38 -> 2284 | G19: ='cost.4.25'!W38 -> 1480.4516 | H19: =(F19-G19)/F19 -> 0.35181628 | I19: =(F19-J19)/F19 -> -0.43607706 | J19: =E19*DAY(B1) -> 3280
A21: Total Energy Cost - L.E. | B21: =VLOOKUP(B1,'cost.4.25'!B8:BI37,56,FALSE) -> 0 | C21: ='cost.4.25'!BD8 -> 71443.809 | D21: =B21-C21 -> -71443.809 | E21: =(E10*1.94)+(E19*5.1)+((E13+E11)*4) -> 82519.6 | F21: ='cost.4.25'!BE38 -> 223030.78 | G21: =C21*DAY(B1) -> 357219.04 | H21: =(F21-G21)/F21 -> -0.60165807 | I21: =(F21-J21)/F21 -> -0.88798159 | J21: =+(J10*1.94)+((J13+J14)*5)+(J19*5.1) -> 421078
A22: Energy Cost per Occupied Room | B22: =B21/B7 -> #DIV/0! | C22: =C21/C7 -> 208.96112 | D22: =B22-C22 -> #DIV/0! | E22: =E21/E7 -> 191.32761 | F22: =F21/F7 -> 163.25769 | G22: =G21/G7 -> 208.96112 | H22: =(F22-G22)/F22 -> -0.27994657 | I22: =(F22-J22)/F22 -> -0.19602272 | J22: =J21/J7 -> 195.25991
A23: Energy Cost per Available Room | B23: =B21/526 -> 0 | C23: =C21/526 -> 135.82473 | D23: =B23-C23 -> -135.82473 | E23: =E21/526 -> 156.88137 | F23: =F21/(526*DAY(B1)) -> 84.802577 | G23: =G21/(DAY(B1)*526) -> 135.82473 | H23: =(F23-G23)/F23 -> -0.60165807 | I23: =(F23-J23)/F23 -> -0.88798159 | J23: =J21/(526*DAY(B1)) -> 160.1057
A45: Month To Date Electricity Consumption | E45: Month To Date Energy Consumption | L45: Month To Date Kitchens' Gas Consumption
E46: Laundry Performance | L46: Kitchens Performance
A47: Electricity Maximum Demand KW | B47: Today | E47: Target | F47: Last Year | H47: Elec.(Kw)/Room | I47: Today | J47: MTD | K47: Budgeted | L47: Act. LE | M47: Budget LE | N47: Act Vs Bdg | O47: % Budget | P47: forcast | Q47: Act Vs Fos | R47: %forcast
B48: Actual | C48: Last Period | E48: This Period | F48: This Period | I48: =B10/B7 -> #DIV/0! | J48: =F10/F7 -> 75.849452 | K48: =C10/C7 -> 77.667544 | L48: ='cost.4.25'!M38 -> 200596 | M48: ='cost.4.25'!K38 -> 198281.9 | N48: =L48-M48 -> 2314.1 | O48: =(L48/M48)-1 -> 0.011670758 | P48: =J10*1.94 -> 383150 | Q48: =L48-P48 -> -182554 | R48: =(L48/P48)-1 -> -0.4764557
B49: ='Reading.4.25'!AQ36 -> 1332 | C49: ='Reading.4.25'!AQ37 -> 2216 | E49: 2180 | F49: 2120
A51: Weather Temperature ⁰C | B51: Today | E51: Month To Date | H51: Water(l)/Room | I51: Today | J51: MTD | K51: Budgeted | L51: Act. LE | M51: Budget LE | N51: Diff | O51: % | P51: forcast | Q51: Act Vs Fos | R51: % forcast
B52: Actual | C52: Last year | E52: Actual | F52: Last Year | I52: =B19/B7 -> #DIV/0! | J52: =F19/F7 -> 1.6718795 | K52: =C19/C7 -> 1.4433573 | L52: ='cost.4.25'!Z38 -> 11648.4 | M52: ='cost.4.25'!X38 -> 8067.3 | N52: =L52-M52 -> 3581.1 | O52: =(L52/M52)-1 -> 0.44390316 | P52: =J19*5.1 -> 16728 | Q52: =L52-P52 -> -5079.6 | R52: =(L52/P52)-1 -> -0.30365854
B53: =VLOOKUP(B1,'Reading.4.25'!A5:EL35,55,FALSE) -> 0 | C53: =VLOOKUP(B1,'Reading.4.25'!A5:EL35,59,FALSE) -> 0 | E53: ='Reading.4.25'!BC36 -> 16 | F53: ='Reading.4.25'!BG36 -> 80
A54: Humidity % | B54: =VLOOKUP(B1,'Reading.4.25'!A5:EL35,58,FALSE) -> 0 | C54: 60 | E54: ='Reading.4.25'!BF36 -> 25 | F54: =VLOOKUP(B1,'Reading.4.25'!A5:EL35,62,FALSE) -> 0 | H54: Energy - MTD | I54: Energy - forcast | J54: Diff | K54: % | P54: Ro. Production | R54: =VLOOKUP(B1,'Reading.4.25'!A5:EL35,3,FALSE) -> 0
H55: =+F21 -> 223030.78 | I55: =+J21 -> 421078 | J55: =+H55-I55 -> -198047.22 | K55: =+(H55/I55)-1 -> -0.47033382 | P55: Hotel consumption | R55: =+B19 -> 0
A56: Comments: | P56: Diff. | R56: =+R54-R55 -> 0

Sheet Reading.4.25
A1: 1 | B1: 2 | C1: 3 | D1: 4 | E1: 5 | F1: 6 | G1: 7 | H1: 8 | I1: 9 | J1: 10 | K1: 11 | L1: 12 | M1: 13 | N1: 14 | O1: 15 | P1: 16 | Q1: 17 | R1: 18 | S1: 19 | T1: 20 | U1: 21 | V1: 22 | W1: 23 | X1: 24 | Y1: 25 | Z1: 26 | AA1: 27 | AB1: 28 | AC1: 29 | AD1: 30 | AE1: 31 | AF1: 32 | AG1: 33 | AH1: 34 | AI1: 35 | AJ1: 36 | AK1: 37 | AL1: 38 | AM1: 39 | AN1: 40 | AO1: 41 | AP1: 42 | AQ1: 43 | AR1: 44 | AS1: 45 | AT1: 46 | AU1: 47 | AV1: 48 | AW1: 49 | AX1: 50 | AY1: 51 | AZ1: 52 | BA1: 53 | BB1: 54 | BC1: 55 | BD1: 56 | BE1: 57 | BF1: 58 | BG1: 59 | BH1: 60 | BI1: 61 | BJ1: 62 | BK1: 63 | BL1: 64 | BM1: 65 | BN1: 66 | BO1: 67 | BP1: 68 | BQ1: 69 | BR1: 70 | BS1: 71 | BT1: 72 | BU1: 73 | BV1: 74 | BW1: 75 | BX1: 76 | BY1: 77 | BZ1: 78 | CA1: 79 | CB1: 80 | CC1: 81 | CD1: 82 | CE1: 83 | CF1: 84 | CG1: 85 | CH1: 86 | CI1: 87 | CJ1: 88 | CK1: 89 | CL1: 90 | CM1: 91 | CN1: 92 | CO1: 93 | CP1: 94 | CQ1: 95 | CR1: 96 | CS1: 97 | CT1: 98 | CU1: 99 | CV1: 100 | CW1: 101 | CX1: 102 | CY1: 103 | CZ1: 104 | DA1: 105 | DB1: 106 | DC1: 107 | DD1: 108 | DE1: 109 | DF1: 110 | DG1: 111 | DH1: 112 | DI1: 113 | DJ1: 114 | DK1: 115 | DL1: 116 | DM1: 117 | DN1: 118 | DO1: 119 | DP1: 120 | DQ1: 121 | DR1: 122 | DS1: 123 | DT1: 124 | DU1: 125 | DV1: 126 | DW1: 127 | DX1: 128 | DY1: 129 | DZ1: 130 | EA1: 131 | EB1: 132 | EC1: 133 | ED1: 134 | EE1: 135 | EF1: 136 | EG1: 137 | EH1: 138 | EI1: 139 | EJ1: 140 | EK1: 141 | EL1: 142
B2: WATER | J2: KITCHEN GAS | N2: BOILER GAS | R2: FUEL | W2: ELECTRICITY | AA2: GENERATORS | AE2: TOTAL KWH | AI2: Occupancy % | AM2: Rooms Occupied | AQ2: Max. Demand | AT2: Power Factor | AY2: More Data | BC2: Weather Temperature | BL2: Available Rooms | BN2: Water Sold Last Year | BP2: Kitchen Water | BT2: Laundry Water | BX2: Fountain Water | CB2: S. Pool Water | CF2: Heated Pool Water | CI2: Staff Houses Water | CM2: Total Facilities Cons. | CP2: STP | CV2: Dishwasher | CZ2: Staff Kitchen | DD2: Laundry Electricity | DH2: Kit. Equip. Electricity | DL2: Chiller 1 | DP2: Chiller 2 | DT2: Chiller 3 | DX2: Chilled Pumps KWH | DZ2: Total Chillers | EC2: RO Plant | EF2: Staff Kitchen Gas | EJ2: Rotary Oven Gas | EN2: Water Counter Reading | ES2: Jockey Pump | ET2: Consumption
A4: Date | B4: Reading | C4: Product. | D4: Sold | E4: Tanks Level | F4: Counters reading | G4: Consump. This Year | H4: Last Year | J4: Reading | K4: Consump. This Year | L4: Last Year | N4: Reading | O4: Consump. This Year | P4: Last Year | R4: Reading | S4: Add | T4: Consump. This Year | U4: Last Year | W4: Reading | X4: Consump. This Year | Y4: Consump. Last Year | AA4: Reading | AB4: Consump. This Year | AC4: Consump. Last Year | AE4: This Year | AF4: Last Year | AG4: Budget | AI4: This Year | AJ4: Last Year | AK4: Budget | AM4: This Year | AN4: Last Year | AO4: Budget | AQ4: This Year KW | AR4: Last Year KW | AT4: KVAR Reading | AU4: KVAR Cons. | AV4: Cos Ø | AY4: Last Year OCT 2023 | BC4: This Year - OCT 2024 | BG4: Last Year - OCT 2023 | BP4: Counter Reading | BQ4: Consumption This year | BR4: Consumption Last Year | BT4: Counter Reading | BU4: Consumption | BV4: Consumption Last Year | BX4: Counter Reading | BY4: Consumption | BZ4: Consumption Last Year | CB4: Counter Reading | CC4: Consumption | CD4: Consumption Last Year | CF4: Counter Reading | CG4: Consumption | CH4: Consumption Last Year | CI4: Counter Reading | CJ4: Consumption | CK4: Consumption Last Year | CM4: This Year | CN4: Last Year | CP4: Counter Reading | CQ4: Recycled Water this Year | CR4: % | CS4: Reccycled Water Last Year | CT4: % | CV4: Counter Reading | CW4: Cons. | CX4: Cons. Last Year | CZ4: Counter Reading | DA4: Cons. | DB4: Cons. Last Year | DD4: Counter Reading | DE4: Cons. | DF4: Cons. Last Year | DH4: Counter Reading | DI4: Cons. | DJ4: Cons. Last Year | DL4: Counter Reading | DM4: Cons. | DN4: Cons. Last Year | DP4: Counter Reading | DQ4: Cons. | DR4: Cons. Last Year | DT4: Counter Reading | DU4: Cons. | DV4: Cons. Last Year | DZ4: Cons. | EA4: Cons. Last Year | EC4: KWH This Year | ED4: KWH Last Year | EF4: Counter Reading | EG4: Cons. | EH4: Cons. Last Year | EJ4: Counter Reading | EK4: Cons. | EL4: Cons. Last Year | EN4: C1 | EO4: C2 | EP4: C3 | EQ4: Total
B5: 502969 | E5: 770 | G5: =F5+ET5 -> 0 | J5: 224175 | N5: 770511 | R5: 65800 | W5: 48917.4 | AA5: 535640 | AT5: 7557.67 | BL5: 526 | BP5: 80374 | BT5: 96123 | BX5: 4317 | CB5: 248910 | CF5: 9150 | CI5: 19771 | CP5: 83180 | CV5: 418 | CZ5: 2417 | DD5: 1739496 | DH5: 3947489 | DL5: 3363547 | DP5: 2900611 | DT5: 3582939 | DX5: 720 | EF5: 69556 | EJ5: 32597 | EN5: 35710 | EO5: 34971 | EP5: 34295 | ES5: 6974
A6: 45748 | B6: 503666 | C6: =B6-B5 -> 697 | E6: 800 | F6: =EQ6 -> 746 | G6: =F6+ET6 -> 777 | H6: ='Reading.4.24'!G6 -> 505 | J6: 224234 | K6: =(J6-J5)*4.668 -> 275.412 | L6: ='Reading.4.24'!K6 -> 112.032 | N6: 770641 | O6: =(N6-N5)*4.61 -> 599.3 | P6: ='Reading.4.24'!O6 -> 391.85 | R6: 65800 | T6: =(R5+S5)-R6 -> 0 | U6: ='Reading.4.24'!T6 -> 0 | W6: 48926.06 | X6: =(W6-W5)*4000 -> 34640 | Y6: ='Reading.4.24'!X6 -> 27720 | AA6: 535860 | AB6: =AA6-AA5 -> 220 | AC6: ='Reading.4.24'!AB6 -> 0 | AE6: =+X6+AB6 -> 34860 | AF6: ='Reading.4.24'!AE6 -> 27720 | AG6: =796636/30 -> 26554.533 | AI6: 0.8729 | AJ6: ='Reading.4.24'!AI6 -> 0.5209 | AK6: 0.65 | AM6: =AI6*526 -> 459.1454 | AN6: ='Reading.4.24'!AM6 -> 274 | AO6: =10257/30 -> 341.9 | AQ6: =333*4 -> 1332 | AR6: ='Reading.4.24'!AQ6 -> 1460 | AT6: 7559.13 | AU6: =(AT6-AT5)*4000 -> 5840 | AV6: =+X6/SQRT(((POWER((X6),2)+(POWER((AU6),2))))) -> 0.98608445 | AY6: ='Reading.4.24'!X6 -> 27720 | AZ6: ='Reading.4.24'!Y6 -> 25200 | BA6: =AY6+AZ6 -> 52920 | BC6: 16 | BD6: 20 | BE6: 18 | BF6: 25 | BG6: 80 | BH6: ='Reading.4.24'!BD6 -> 16.1 | BI6: ='Reading.4.24'!BE6 -> 12 | BJ6: ='Reading.4.24'!BF6 -> 56 | BL6: 526 | BN6: ='Reading.4.24'!E3 -> 0 | BP6: 80400 | BQ6: =BP6-BP5 -> 26 | BR6: ='Reading.4.24'!BQ6 -> 30 | BT6: 96172 | BU6: =BT6-BT5 -> 49 | BV6: ='Reading.4.24'!BU6 -> 30 | BX6: 4317 | BY6: =BX6-BX5 -> 0 | BZ6: ='Reading.4.24'!BY6 -> 11 | CB6: 248950 | CC6: =CB6-CB5 -> 40 | CD6: ='Reading.4.24'!CC6 -> 30 | CF6: 9160 | CG6: =CF6-CF5 -> 10 | CH6: ='Reading.4.24'!CG6 -> 10 | CI6: 19771 | CJ6: =CI6-CI5 -> 0 | CK6: ='Reading.4.24'!CJ6 -> -3 | CM6: =BQ6+BU6+BY6+CC6+CJ6 -> 115 | CN6: =BR6+BV6+BZ6+CD6+CK6 -> 98 | CP6: 83780 | CQ6: =CP6-CP5 -> 600 | CR6: =CQ6/G6 -> 0.77220077 | CS6: ='Reading.4.24'!CN6 -> 135 | CT6: ='Reading.4.24'!CR6 -> 0.67920792 | CV6: 419 | CW6: =CV6-CV5 -> 1 | CX6: ='Reading.4.24'!CW6 -> 2 | CZ6: 2423 | DA6: =CZ6-CZ5 -> 6 | DB6: ='Reading.4.24'!DA6 -> 3 | DD6: 1740450 | DE6: =DD6-DD5 -> 954 | DF6: ='Reading.4.24'!DE6 -> 757 | DH6: 3949300 | DI6: =DH6-DH5 -> 1811 | DJ6: ='Reading.4.24'!DI6 -> 1866 | DL6: 3365383 | DM6: =DL6-DL5 -> 1836 | DN6: ='Reading.4.24'!DM6 -> 3208 | DP6: 2902187 | DQ6: =DP6-DP5 -> 1576 | DR6: ='Reading.4.24'!DQ6 -> 31 | DT6: 3582953 | DU6: =DT6-DT5 -> 14 | DV6: ='Reading.4.24'!DU6 -> 31 | DX6: 720 | DZ6: =DM6+DQ6+DU6+DX6 -> 4146 | EA6: ='Reading.4.24'!DZ6 -> 3990 | EC6: =C6*5.2 -> 3624.4 | ED6: ='Reading.4.24'!EC6 -> 2158 | EF6: 69598 | EG6: =EF6-EF5 -> 42 | EH6: ='Reading.4.24'!EG6 -> 40 | EJ6: 32629 | EK6: =EJ6-EJ5 -> 32 | EL6: ='Reading.4.24'!EK6 -> 33 | EN6: 35728 | EO6: 35550 | EP6: 34444 | EQ6: =(EN6-EN5)+(EO6-EO5)+(EP6-EP5) -> 746 | ES6: 7005 | ET6: =+ES6-ES5 -> 31
A7: 45749 | B7: 504119 | C7: =B7-B6 -> 453 | E7: 800 | F7: =EQ7 -> 723 | G7: =F7+ET7 -> 754 | H7: ='Reading.4.24'!G7 -> 460 | J7: 224291 | K7: =(J7-J6)*4.668 -> 266.076 | L7: ='Reading.4.24'!K7 -> 121.368 | N7: 770784 | O7: =(N7-N6)*4.61 -> 659.23 | P7: ='Reading.4.24'!O7 -> 410.29 | R7: 65800 | T7: =(R6+S6)-R7 -> 0 | U7: ='Reading.4.24'!T7 -> 0 | W7: 48934.5 | X7: =(W7-W6)*4000 -> 33760 | Y7: ='Reading.4.24'!X7 -> 28600 | AA7: 535860 | AB7: =AA7-AA6 -> 0 | AC7: ='Reading.4.24'!AB7 -> 0 | AE7: =+X7+AB7 -> 33760 | AF7: ='Reading.4.24'!AE7 -> 28600 | AG7: =796636/30 -> 26554.533 | AI7: 0.8783 | AJ7: ='Reading.4.24'!AI7 -> 0.4924 | AK7: 0.65 | AM7: =AI7*526 -> 461.9858 | AN7: ='Reading.4.24'!AM7 -> 259 | AO7: =10257/30 -> 341.9 | AQ7: =333*4 -> 1332 | AR7: ='Reading.4.24'!AQ7 -> 1460 | AT7: 7560.53 | AU7: =(AT7-AT6)*4000 -> 5600 | AV7: =+X7/SQRT(((POWER((X7),2)+(POWER((AU7),2))))) -> 0.98652 | AY7: ='Reading.4.24'!X7 -> 28600 | AZ7: ='Reading.4.24'!Y7 -> 25640 | BA7: =AY7+AZ7 -> 54240 | BC7: 16 | BD7: 20 | BE7: 18 | BF7: 25 | BG7: 80 | BH7: ='Reading.4.24'!BD7 -> 16.1 | BI7: ='Reading.4.24'!BE7 -> 12 | BJ7: ='Reading.4.24'!BF7 -> 56 | BL7: 526 | BN7: ='Reading.4.24'!E4 -> Sold | BP7: 80432 | BQ7: =BP7-BP6 -> 32 | BR7: ='Reading.4.24'!BQ7 -> 18 | BT7: 96234 | BU7: =BT7-BT6 -> 62 | BV7: ='Reading.4.24'!BU7 -> 34 | BX7: 4317 | BY7: =BX7-BX6 -> 0 | BZ7: ='Reading.4.24'!BY7 -> 0 | CB7: 249030 | CC7: =CB7-CB6 -> 80 | CD7: ='Reading.4.24'!CC7 -> 20 | CF7: 9170 | CG7: =CF7-CF6 -> 10 | CH7: ='Reading.4.24'!CG7 -> 0 | CI7: 19771 | CJ7: =CI7-CI6 -> 0 | CK7: ='Reading.4.24'!CJ7 -> 0 | CM7: =BQ7+BU7+BY7+CC7+CJ7 -> 174 | CN7: =BR7+BV7+BZ7+CD7+CK7 -> 72 | CP7: 84400 | CQ7: =CP7-CP6 -> 620 | CR7: =CQ7/G7 -> 0.82228117 | CS7: ='Reading.4.24'!CN7 -> 148 | CT7: ='Reading.4.24'!CR7 -> 0.76086957 | CV7: 420 | CW7: =CV7-CV6 -> 1 | CX7: ='Reading.4.24'!CW7 -> 2 | CZ7: 2428 | DA7: =CZ7-CZ6 -> 5 | DB7: ='Reading.4.24'!DA7 -> 2 | DD7: 1741445 | DE7: =DD7-DD6 -> 995 | DF7: ='Reading.4.24'!DE7 -> 706 | DH7: 3951100 | DI7: =DH7-DH6 -> 1800 | DJ7: ='Reading.4.24'!DI7 -> 1144 | DL7: 3367398 | DM7: =DL7-DL6 -> 2015 | DN7: ='Reading.4.24'!DM7 -> 3552 | DP7: 2903962 | DQ7: =DP7-DP6 -> 1775 | DR7: ='Reading.4.24'!DQ7 -> 34 | DT7: 3582972 | DU7: =DT7-DT6 -> 19 | DV7: ='Reading.4.24'!DU7 -> 31 | DX7: 720 | DZ7: =DM7+DQ7+DU7+DX7 -> 4529 | EA7: ='Reading.4.24'!DZ7 -> 4337 | EC7: =C7*5.2 -> 2355.6 | ED7: ='Reading.4.24'!EC7 -> 2626 | EF7: 69645 | EG7: =EF7-EF6 -> 47 | EH7: ='Reading.4.24'!EG7 -> 49 | EJ7: 32665 | EK7: =EJ7-EJ6 -> 36 | EL7: ='Reading.4.24'!EK7 -> 17 | EN7: 35838 | EO7: 35716 | EP7: 34891 | EQ7: =(EN7-EN6)+(EO7-EO6)+(EP7-EP6) -> 723 | ES7: 7036 | ET7: =+ES7-ES6 -> 31
A8: 45750 | B8: 504871 | C8: =B8-B7 -> 752 | E8: 695 | F8: =EQ8 -> 718 | G8: =F8+ET8 -> 753 | H8: ='Reading.4.24'!G8 -> 552 | J8: 224353 | K8: =(J8-J7)*4.668 -> 289.416 | L8: ='Reading.4.24'!K8 -> 149.376 | N8: 770945 | O8: =(N8-N7)*4.61 -> 742.21 | P8: ='Reading.4.24'!O8 -> 387.24 | R8: 65800 | T8: =(R7+S7)-R8 -> 0 | U8: ='Reading.4.24'!T8 -> 0 | W8: 48943.25 | X8: =(W8-W7)*4000 -> 35000 | Y8: ='Reading.4.24'!X8 -> 29160 | AA8: 535860 | AB8: =AA8-AA7 -> 0 | AC8: ='Reading.4.24'!AB8 -> 0 | AE8: =+X8+AB8 -> 35000 | AF8: ='Reading.4.24'!AE8 -> 29160 | AG8: =796636/30 -> 26554.533 | AI8: 0.846 | AJ8: ='Reading.4.24'!AI8 -> 0.4943 | AK8: 0.65 | AM8: =AI8*526 -> 444.996 | AN8: ='Reading.4.24'!AM8 -> 260 | AO8: =10257/30 -> 341.9 | AQ8: =333*4 -> 1332 | AR8: ='Reading.4.24'!AQ8 -> 1548 | AT8: 7561.84 | AU8: =(AT8-AT7)*4000 -> 5240 | AV8: =+X8/SQRT(((POWER((X8),2)+(POWER((AU8),2))))) -> 0.98897777 | AY8: ='Reading.4.24'!X8 -> 29160 | AZ8: ='Reading.4.24'!Y8 -> 25760 | BA8: =AY8+AZ8 -> 54920 | BC8: 16 | BD8: 20 | BE8: 18 | BF8: 25 | BG8: 80 | BH8: ='Reading.4.24'!BD8 -> 16.1 | BI8: ='Reading.4.24'!BE8 -> 12 | BJ8: ='Reading.4.24'!BF8 -> 56 | BL8: 526 | BN8: ='Reading.4.24'!E5 -> 0 | BP8: 80514 | BQ8: =BP8-BP7 -> 82 | BR8: ='Reading.4.24'!BQ8 -> 18 | BT8: 96295 | BU8: =BT8-BT7 -> 61 | BV8: ='Reading.4.24'!BU8 -> 36 | BX8: 4317 | BY8: =BX8-BX7 -> 0 | BZ8: ='Reading.4.24'!BY8 -> 0 | CB8: 249050 | CC8: =CB8-CB7 -> 20 | CD8: ='Reading.4.24'!CC8 -> 30 | CF8: 9185 | CG8: =CF8-CF7 -> 15 | CH8: ='Reading.4.24'!CG8 -> 10 | CI8: 19771 | CJ8: =CI8-CI7 -> 0 | CK8: ='Reading.4.24'!CJ8 -> 0 | CM8: =BQ8+BU8+BY8+CC8+CJ8 -> 163 | CN8: =BR8+BV8+BZ8+CD8+CK8 -> 84 | CP8: 84950 | CQ8: =CP8-CP7 -> 550 | CR8: =CQ8/G8 -> 0.73041169 | CS8: ='Reading.4.24'!CN8 -> 122 | CT8: ='Reading.4.24'!CR8 -> 0.66123188 | CV8: 423 | CW8: =CV8-CV7 -> 3 | CX8: ='Reading.4.24'!CW8 -> 2 | CZ8: 2429 | DA8: =CZ8-CZ7 -> 1 | DB8: ='Reading.4.24'!DA8 -> 3 | DD8: 1742447 | DE8: =DD8-DD7 -> 1002 | DF8: ='Reading.4.24'!DE8 -> 695 | DH8: 3952437 | DI8: =DH8-DH7 -> 1337 | DJ8: ='Reading.4.24'!DI8 -> 1151 | DL8: 3369186 | DM8: =DL8-DL7 -> 1788 | DN8: ='Reading.4.24'!DM8 -> 3782 | DP8: 2905512 | DQ8: =DP8-DP7 -> 1550 | DR8: ='Reading.4.24'!DQ8 -> 31 | DT8: 3582989 | DU8: =DT8-DT7 -> 17 | DV8: ='Reading.4.24'!DU8 -> 32 | DX8: 720 | DZ8: =DM8+DQ8+DU8+DX8 -> 4075 | EA8: ='Reading.4.24'!DZ8 -> 4565 | EC8: =C8*5.2 -> 3910.4 | ED8: ='Reading.4.24'!EC8 -> 3026.4 | EF8: 69779 | EG8: =EF8-EF7 -> 134 | EH8: ='Reading.4.24'!EG8 -> 45 | EJ8: 32674 | EK8: =EJ8-EJ7 -> 9 | EL8: ='Reading.4.24'!EK8 -> 25 | EN8: 36388 | EO8: 35763 | EP8: 35012 | EQ8: =(EN8-EN7)+(EO8-EO7)+(EP8-EP7) -> 718 | ES8: 7071 | ET8: =+ES8-ES7 -> 35
A9: 45751
A10: 45752
A11: 45753
A12: 45754
A13: 45755
A14: 45756
A15: 45757
A16: 45758
A17: 45759
A18: 45760
A19: 45761
A20: 45762
... A35: 45777
C36: =AVERAGE(C6:C35) -> 634 | G36: =SUM(G6:G35) -> 2284 | H36: =SUM(H6:H35) -> 1517 | K36: =SUM(K6:K35) -> 830.904 | L36: =SUM(L6:L35) -> 382.776 | O36: =SUM(O6:O35) -> 2000.74 | P36: =SUM(P6:P35) -> 1189.38 | S36: =SUM(S6:S35) -> 0 | T36: =SUM(T6:T35) -> 0 | U36: =SUM(U6:U35) -> 0 | X36: =SUM(X6:X35) -> 103400 | Y36: =SUM(Y6:Y35) -> 85480 | AB36: =SUM(AB6:AB35) -> 220 | AC36: =SUM(AC6:AC35) -> 0 | AE36: =SUM(AE6:AE35) -> 103620 | AF36: =SUM(AF6:AF35) -> 85480 | AG36: =SUM(AG6:AG35) -> 79663.6 | AI36: =AVERAGE(AI6:AI35) -> 0.86573333 | AJ36: =AVERAGE(AJ6:AJ35) -> 0.50253333 | AK36: =AVERAGE(AK6:AK35) -> 0.65 | AM36: =SUM(AM6:AM35) -> 1366.1272 | AN36: =SUM(AN6:AN35) -> 793 | AO36: =SUM(AO6:AO35) -> 1025.7 | AQ36: =MAX(AQ6:AQ35) -> 1332 | AR36: =MAX(AR6:AR35) -> 1548 | AV36: =AVERAGE(AV6:AV35) -> 0.98719407 | AY36: =SUM(AY6:AY35) -> 85480 | AZ36: =SUM(AZ6:AZ35) -> 76600 | BA36: =SUM(BA6:BA35) -> 162080 | BC36: =AVERAGE(BC6:BC35) -> 16 | BD36: =AVERAGE(BD6:BD35) -> 20 | BE36: =AVERAGE(BE6:BE35) -> 18 | BF36: =AVERAGE(BF6:BF35) -> 25 | BG36: =AVERAGE(BG6:BG35) -> 80 | BH36: =AVERAGE(BH6:BH35) -> 16.1 | BI36: =AVERAGE(BI6:BI35) -> 12 | BJ36: =AVERAGE(BJ6:BJ35) -> 56 | BL36: =SUM(BL6:BL35) -> 1578 | BN36: =SUM(BN6:BN35) -> 0 | BQ36: =SUM(BQ6:BQ35) -> 140 | BR36: =SUM(BR6:BR35) -> 66 | BU36: =SUM(BU6:BU35) -> 172 | BV36: =SUM(BV6:BV35) -> 100 | BY36: =SUM(BY6:BY35) -> 0 | BZ36: =SUM(BZ6:BZ35) -> 11 | CC36: =SUM(CC6:CC35) -> 140 | CD36: =SUM(CD6:CD35) -> 80 | CG36: =SUM(CG6:CG35) -> 35 | CH36: =SUM(CH6:CH35) -> 20 | CJ36: =SUM(CJ6:CJ35) -> 0 | CK36: =SUM(CK6:CK35) -> -3 | CM36: =SUM(CM6:CM35) -> 452 | CN36: =SUM(CN6:CN35) -> 254 | CQ36: =SUM(CQ6:CQ35) -> 1770 | CR36: =AVERAGE(CR13:CR35) -> #DIV/0! | CS36: ='Reading.4.24'!CN35 -> 123 | CT36: ='Reading.4.24'!CO35 -> 0 | CW36: =SUM(CW6:CW35) -> 5 | CX36: ='Reading.4.24'!CT37 -> 0.52997602 | DA36: =SUM(DA6:DA35) -> 12 | DB36: =SUM(DB6:DB35) -> 8 | DE36: =SUM(DE6:DE35) -> 2951 | DF36: =SUM(DF6:DF35) -> 2158 | DI36: =SUM(DI6:DI35) -> 4948 | DJ36: =SUM(DJ6:DJ35) -> 4161 | DM36: =SUM(DM6:DM35) -> 5639 | DN36: =SUM(DN6:DN35) -> 10542 | DQ36: =SUM(DQ6:DQ35) -> 4901 | DR36: =SUM(DR6:DR35) -> 96 | DU36: =SUM(DU6:DU35) -> 50 | DV36: =SUM(DV6:DV35) -> 94 | DZ36: =SUM(DZ6:DZ35) -> 12750 | EA36: =SUM(EA6:EA35) -> 12892 | EC36: =SUM(EC6:EC35) -> 9890.4 | ED36: =SUM(ED6:ED35) -> 7810.4 | EG36: =SUM(EG6:EG35) -> 223 | EH36: =SUM(EH6:EH35) -> 134 | EK36: =SUM(EK6:EK35) -> 77 | EL36: =SUM(EL6:EL35) -> 75
C37: Average/Day | AP37: Last Period Max. Demand: | AQ37: 2216 | CQ37: 0
C38: =SUM(C6:C35) -> 1902 | AP38: This Period Max. Demand: | AQ38: 2160
B39: =+B31-B30 -> 0 | U39: ENERGY COST / OCCUPIED ROOM - LAST YEAR = | AB39: ='cost.4.25'!BG38 -> 109.50475 | AC39: L.E. | AF39: OCCUPANCY - LAST YEAR = | AJ39: =AJ36 -> 0.50253333 | AM39: KWH / OCCUPIED ROOM - LAST YEAR | AR39: =AF36/AN36 -> 107.79319 | AY39: https://www.wunderground.com/history/monthly/eg/sharm-el-shiekh/HESH/date/2024-10
U40: ENERGY COST / OCCUPIED ROOM - THIS YEAR = | AB40: ='cost.4.25'!BI38 -> 163.33877 | AC40: L.E. | AF40: OCCUPANCY - THIS YEAR = | AJ40: =AI36 -> 0.86573333 | AM40: KWH / OCCU[PIED ROOM - THIS YEAR | AR40: =AE36/AM36 -> 75.849452
N41: =X36*2 -> 206800 | U41: ENERGY COST / OCCUPIED ROOM - BUDGET = | AB41: ='cost.4.25'!BH38 -> 334.74341 | AC41: L.E. | AF41: OCCUPANCY - BUDGET= | AJ41: =AK36 -> 0.65 | AM41: KWH / OCCUPIED ROOM - BUDGET | AR41: =AG36/AO36 -> 77.667544 | CC41: =229975+25 -> 230000
AM43: KWH / AVAILABLE ROOM - LAST YEAR | AR43: =AF36/BL36 -> 54.169835
AM44: KWH / AVAILABLE ROOM - THIS YEAR | AR44: =AE36/BL36 -> 65.665399
AM45: KWH / AVAILABLE ROOM - BUDGET | AR45: =AG36/BL36 -> 50.483904
DM80: .
BQ150: .

Sheet cost.4.25
H1: =H8*31 -> 6616.2857 | K1: =K8*31 -> 2048913 | P1: =P8*31 -> 2603 | R1: =R8*31 -> 0 | W1: =W8*31 -> 15298 | X1: =X8*31 -> 83362.1 | AD1: =AD8*31 -> 15112.5 | AJ1: =AJ8*31 -> 5037.5 | AP1: =AP8*31 -> 20150 | AQ1: =AQ8*31 -> 82483
A2: Energy Cost April 2025 | AV2: Energy Cost - April 2024
B3: 1 | C3: 2 | D3: 3 | E3: 4 | F3: 5 | G3: 6 | H3: 7 | I3: 8 | J3: 9 | K3: 10 | L3: 11 | M3: 12 | N3: 13 | O3: 14 | P3: 15 | Q3: 16 | R3: 17 | S3: 18 | T3: 19 | U3: 20 | V3: 21 | W3: 22 | X3: 23 | Y3: 24 | Z3: 25 | AA3: 26 | AB3: 27 | AC3: 28 | AD3: 29 | AE3: 30 | AF3: 31 | AG3: 32 | AH3: 33 | AI3: 34 | AJ3: 35 | AK3: 36 | AL3: 37 | AM3: 38 | AN3: 39 | AO3: 40 | AP3: 41 | AQ3: 42 | AR3: 43 | AS3: 44 | AT3: 45 | AU3: 46 | AV3: 47 | AW3: 48 | AX3: 49 | AY3: 50 | AZ3: 51 | BA3: 52 | BB3: 53 | BC3: 54 | BD3: 55 | BE3: 56 | BF3: 57 | BG3: 58 | BH3: 59 | BI3: 60
J5: ELECTRICITY | O5: FUEL | V5: WATER | AB5: NATURAL GAS | AV5: ELECTRICITY | AX5: WATER | AZ5: NATURAL GAS | BC5: LAST YEAR TOTAL ENERGY L.E. | BD5: BUDGET TOTAL ENERGY L.E. | BE5: ACTUAL TOTAL ENERGY L.E. | BG5: ENERGY LAST YEAR / OCCUPIED ROOM | BH5: ENERGY BUDGET / OCCUPIED ROOM | BI5: ENERGY ACTUAL / OCCUPIED ROOM
B6: DATE | D6: Occ. | F6: Occupied Rooms | H6: Occupied Rooms Budget | J6: CONSUMP. KWH | K6: BUDGET L.E. | L6: LAST YEAR ACTUAL L.E. | M6: ACTUAL L.E. | O6: CONSUMP. LITRE | P6: BUDGET LITRE | Q6: GENERATOR KWH | R6: BUDGET L.E. | S6: LAST YEAR ACTUAL L.E. | T6: ACTUAL L.E. | V6: CONSUMP. M³ | W6: BUDGET M³ | X6: BUDGET L.E. | Y6: LAST YEAR ACTUAL L.E. | Z6: ACTUAL L.E. | AB6: BOILER CONSUMP. M³ | AC6: BOILER COST L.E. | AD6: BOILER BUDGET CONSUMP. M³ | AE6: BOILER BUDGET COST L.E. | AF6: BOILER CONSUMP. LAST YEAR M³ | AG6: BOILER COST LAST YEAR L.E. | AH6: KITCHEN CONSUMP. M³ | AI6: KITCHEN COST L.E. | AJ6: KITCHEN BUDGET CONSUMP. M³ | AK6: KITCHEN BUDGET COST L.E. | AL6: KITCHEN CONSUMP. LAST YEAR M³ | AM6: KITCHEN COST LAST YEAR L.E. | AN6: TOTAL CONSUMP. M³ | AO6: TOTAL CONSUMP. LAST YEAR M³ | AP6: BUDGET TOTAL CONSUMP. M³ | AQ6: BUDGET L.E. | AR6: LAST YEAR ACTUAL L.E. | AS6: ACTUAL L.E. | AV6: KWH / Occupied Room | AW6: L.E. / Occupied Room | AX6: Cu.Mt. / Occupied Room | AY6: L.E. / Occupied Room | AZ6: Cu.Mt. / Occupied Room | BA6: L.E. / Occupied Room
B8: 45748 | D8: ='Reading.4.25'!AI6 -> 0.8729 | F8: ='Reading.4.25'!AM6 -> 459.1454 | H8: =5976/28 -> 213.42857 | J8: ='Reading.4.25'!X6 -> 34640 | K8: =1982819/30 -> 66093.967 | L8: ='Cost.4.24'!M7 -> 0 | M8: =J8*1.94 -> 67201.6 | O8: ='Reading.4.25'!T6 -> 0 | P8: =2603/31 -> 83.967742 | Q8: ='Reading.4.25'!AB6 -> 220 | R8: =0/30 -> 0 | S8: ='Cost.4.24'!T7 -> 0 | T8: =O8*7.55 -> 0 | V8: ='Reading.4.25'!G6 -> 777 | W8: =15298/31 -> 493.48387 | X8: =80673/30 -> 2689.1 | Y8: ='Cost.4.24'!Z7 -> 0 | Z8: ='Reading.4.25'!G6*5.1 -> 3962.7 | AB8: ='Reading.4.25'!O6 -> 599.3 | AC8: =AB8*3.73 -> 2235.389 | AD8: =((19500/4)*3)/30 -> 487.5 | AE8: =((83461/4)*3)/30 -> 2086.525 | AF8: ='Cost.4.24'!AB7 -> 0 | AG8: ='Cost.4.24'!AC7 -> 0 | AH8: ='Reading.4.25'!K6 -> 275.412 | AI8: =AH8*4 -> 1101.648 | AJ8: =(19500/4)/30 -> 162.5 | AK8: =(83461/4)/30 -> 695.50833 | AL8: ='Cost.4.24'!AH7 -> 0 | AM8: ='Cost.4.24'!AI7 -> 0 | AN8: =AB8+AH8 -> 874.712 | AO8: =AF8+AL8 -> 0 | AP8: =AD8+AJ8 -> 650 | AQ8: =82483/31 -> 2660.7419 | AR8: ='Cost.4.24'!AS7 -> 0 | AS8: =AC8+AI8 -> 3337.037 | AV8: ='Reading.4.25'!AE6/'cost.4.25'!F8 -> 75.923662 | AW8: =(M8+T8)/F8 -> 146.36235 | AX8: =V8/F8 -> 1.6922744 | AY8: =Z8/F8 -> 8.6305994 | AZ8: =AN8/F8 -> 1.9050871 | BA8: =AS8/F8 -> 7.2679308 | BC8: ='Cost.4.24'!BE7 -> 0 | BD8: =K8+R8+X8+AQ8 -> 71443.809 | BE8: =M8+T8+Z8+AS8 -> 74501.337 | BG8: ='Cost.4.24'!BI7 -> 0 | BH8: =BD8/H8 -> 334.74341 | BI8: =BE8/F8 -> 162.26088
B9: 45749 | D9: ='Reading.4.25'!AI7 -> 0.8783 | F9: ='Reading.4.25'!AM7 -> 461.9858 | H9: =5976/28 -> 213.42857 | J9: ='Reading.4.25'!X7 -> 33760 | K9: =1982819/30 -> 66093.967 | L9: ='Cost.4.24'!M8 -> 38530.8 | M9: =J9*1.94 -> 65494.4 | O9: ='Reading.4.25'!T7 -> 0 | P9: =2603/31 -> 83.967742 | Q9: ='Reading.4.25'!AB7 -> 0 | R9: =0/30 -> 0 | S9: ='Cost.4.24'!T8 -> 0 | T9: =O9*7.55 -> 0 | V9: ='Reading.4.25'!G7 -> 754 | W9: =15298/31 -> 493.48387 | X9: =80673/30 -> 2689.1 | Y9: ='Cost.4.24'!Z8 -> 2454.3 | Z9: ='Reading.4.25'!G7*5.1 -> 3845.4 | AB9: ='Reading.4.25'!O7 -> 659.23 | AC9: =AB9*3.73 -> 2458.9279 | AD9: =((19500/4)*3)/30 -> 487.5 | AE9: =((83461/4)*3)/30 -> 2086.525 | AF9: ='Cost.4.24'!AB8 -> 391.85 | AG9: ='Cost.4.24'!AC8 -> 1461.6005 | AH9: ='Reading.4.25'!K7 -> 266.076 | AI9: =AH9*4 -> 1064.304 | AJ9: =(19500/4)/30 -> 162.5 | AK9: =(83461/4)/30 -> 695.50833 | AL9: ='Cost.4.24'!AH8 -> 112.032 | AM9: ='Cost.4.24'!AI8 -> 417.87936 | AN9: =AB9+AH9 -> 925.306 | AO9: =AF9+AL9 -> 503.882 | AP9: =AD9+AJ9 -> 650 | AQ9: =82483/31 -> 2660.7419 | AR9: ='Cost.4.24'!AS8 -> 1879.4799 | AS9: =AC9+AI9 -> 3523.2319 | AV9: ='Reading.4.25'!AE7/'cost.4.25'!F9 -> 73.075839 | AW9: =(M9+T9)/F9 -> 141.76713 | AX9: =V9/F9 -> 1.6320848 | AY9: =Z9/F9 -> 8.3236325 | AZ9: =AN9/F9 -> 2.0028884 | BA9: =AS9/F9 -> 7.6262775 | BC9: ='Cost.4.24'!BE8 -> 42864.58 | BD9: =K9+R9+X9+AQ9 -> 71443.809 | BE9: =M9+T9+Z9+AS9 -> 72863.032 | BG9: ='Cost.4.24'!BI8 -> 156.44007 | BH9: =BD9/H9 -> 334.74341 | BI9: =BE9/F9 -> 157.71704
B10: 45750 | D10: ='Reading.4.25'!AI8 -> 0.846 | F10: ='Reading.4.25'!AM8 -> 444.996 | H10: =5976/28 -> 213.42857 | J10: ='Reading.4.25'!X8 -> 35000 | K10: =1982819/30 -> 66093.967 | L10: ='Cost.4.24'!M9 -> 39754 | M10: =J10*1.94 -> 67900 | O10: ='Reading.4.25'!T8 -> 0 | P10: =2603/31 -> 83.967742 | Q10: ='Reading.4.25'!AB8 -> 0 | R10: =0/30 -> 0 | S10: ='Cost.4.24'!T9 -> 0 | T10: =O10*7.55 -> 0 | V10: ='Reading.4.25'!G8 -> 753 | W10: =15298/31 -> 493.48387 | X10: =80673/30 -> 2689.1 | Y10: ='Cost.4.24'!Z9 -> 2235.6 | Z10: ='Reading.4.25'!G8*5.1 -> 3840.3 | AB10: ='Reading.4.25'!O8 -> 742.21 | AC10: =AB10*3.73 -> 2768.4433 | AD10: =((19500/4)*3)/30 -> 487.5 | AE10: =((83461/4)*3)/30 -> 2086.525 | AF10: ='Cost.4.24'!AB9 -> 410.29 | AG10: ='Cost.4.24'!AC9 -> 1530.3817 | AH10: ='Reading.4.25'!K8 -> 289.416 | AI10: =AH10*4 -> 1157.664 | AJ10: =(19500/4)/30 -> 162.5 | AK10: =(83461/4)/30 -> 695.50833 | AL10: ='Cost.4.24'!AH9 -> 121.368 | AM10: ='Cost.4.24'!AI9 -> 452.70264 | AN10: =AB10+AH10 -> 1031.626 | AO10: =AF10+AL10 -> 531.658 | AP10: =AD10+AJ10 -> 650 | AQ10: =82483/31 -> 2660.7419 | AR10: ='Cost.4.24'!AS9 -> 1983.0843 | AS10: =AC10+AI10 -> 3926.1073 | AV10: ='Reading.4.25'!AE8/'cost.4.25'!F10 -> 78.652392 | AW10: =(M10+T10)/F10 -> 152.58564 | AX10: =V10/F10 -> 1.69215 | AY10: =Z10/F10 -> 8.6299652 | AZ10: =AN10/F10 -> 2.3182815 | BA10: =AS10/F10 -> 8.8227923 | BC10: ='Cost.4.24'!BE9 -> 43972.684 | BD10: =K10+R10+X10+AQ10 -> 71443.809 | BE10: =M10+T10+Z10+AS10 -> 75666.407 | BG10: ='Cost.4.24'!BI9 -> 169.7787 | BH10: =BD10/H10 -> 334.74341 | BI10: =BE10/F10 -> 170.0384
B11: 45751
B12: 45752
B13: 45753
B14: 45754
B15: 45755
B16: 45756
B17: 45757
B18: 45758
B19: 45759
B20: 45760
B21: 45761
B22: 45762
... B37: 45777
B38: TOTAL | D38: =AVERAGE(D8:D37) -> 0.86573333 | F38: =SUM(F8:F37) -> 1366.1272 | H38: =+SUM(H8:H37) -> 640.28571 | J38: =SUM(J8:J37) -> 103400 | K38: =SUM(K8:K37) -> 198281.9 | L38: =SUM(L8:L37) -> 78284.8 | M38: =SUM(M8:M37) -> 200596 | O38: =SUM(O8:O37) -> 0 | P38: =SUM(P8:P37) -> 251.90323 | Q38: =SUM(Q8:Q37) -> 220 | R38: =SUM(R8:R37) -> 0 | S38: =SUM(S8:S37) -> 0 | T38: =SUM(T8:T37) -> 0 | V38: =SUM(V8:V37) -> 2284 | W38: =SUM(W8:W37) -> 1480.4516 | X38: =SUM(X8:X37) -> 8067.3 | Y38: =SUM(Y8:Y37) -> 4689.9 | Z38: =SUM(Z8:Z37) -> 11648.4 | AB38: =SUM(AB8:AB37) -> 2000.74 | AC38: =SUM(AC8:AC37) -> 7462.7602 | AD38: =SUM(AD8:AD37) -> 1462.5 | AE38: =SUM(AE8:AE37) -> 6259.575 | AF38: =SUM(AF8:AF37) -> 802.14 | AG38: =SUM(AG8:AG37) -> 2991.9822 | AH38: =SUM(AH8:AH37) -> 830.904 | AI38: =SUM(AI8:AI37) -> 3323.616 | ... AS38: =SUM(AS8:AS37) -> 10786.376 | AV38: =AVERAGE(AV8:AV37) -> 75.883964 | AW38: =AVERAGE(AW8:AW37) -> 146.90504 | AX38: =AVERAGE(AX8:AX37) -> 1.6721697 | AY38: =AVERAGE(AY8:AY37) -> 8.5280657 | AZ38: =AVERAGE(AZ8:AZ37) -> 2.075419 | BA38: =AVERAGE(BA8:BA37) -> 7.9056669 | BC38: =SUM(BC8:BC37) -> 86837.264 | BD38: =SUM(BD8:BD37) -> 214331.43 | BE38: =SUM(BE8:BE37) -> 223030.78 | BG38: =BC38/'Reading.4.25'!AN36 -> 109.50475 | BH38: =AVERAGE(BH8:BH37) -> 334.74341 | BI38: =AVERAGE(BI8:BI37) -> 163.33877

Sheet Domestic Water
A5: Engineering Department
A6: Domestic Water Parameters | L6: Month : | M6: April | N6: 2025
A8: Day | B8: Hardness | D8: Alkalinity | G8: Chloride | H8: PH | I8: Conductivity | J8: TDS | K8: Fe | L8: CL | M8: T ºc | N8: Production
B9: CAL | C9: Total | D9: P | E9: M | F9: CH | G9: CL/NaCL
A10: 1
A11: 2
A12: 3
A13: 4
A14: 5
A15: 6
A16: 7
A17: 8
A18: 9
A19: 10
A20: 11
A21: 12
... A40: 31
H41: =AVERAGE(H10:H40) -> #DIV/0! | J41: =AVERAGE(J10:J40) -> #DIV/0! | L41: =AVERAGE(L10:L40) -> #DIV/0! | M41: =AVERAGE(M10:M40) -> #DIV/0! | N41: =SUM(N10:N40) -> 0

Sheet Main Pool
A5: Engineering Department
A6: Main Swimming Pool | M6: Month : | N6: April | O6: 2025
A8: Pool Parameters | I8: Fresh Water Add (M³) | J8: Chemicals | O8: Backwash
A9: Day | B9: Calcium Hardness | C9: Total Alkalinity | D9: PH | E9: TDS | F9: Cyan. Acid | G9: CL | H9: T ºc | J9: Chlorine 65% (Kg) | K9: Chlorine 90% (Kg) | L9: Soda Ash PH+ (Kg) | M9: HCL PH- (Lit) | N9: Other Chemicals
A10: 1
A11: 2
A12: 3
A13: 4
A14: 5
A15: 6
A16: 7
A17: 8
A18: 9
A19: 10
A20: 11
A21: 12
... A40: 31
D41: =AVERAGE(D10:D40) -> #DIV/0! | G41: =AVERAGE(G10:G40) -> #DIV/0! | H41: =AVERAGE(H10:H40) -> #DIV/0! | I41: =SUM(I10:I40) -> 0 | J41: =SUM(J10:J40) -> 0 | K41: =SUM(K10:K40) -> 0

Sheet Heated Pool
A5: Engineering Department
A6: Heated Pool | M6: Month : | N6: April | O6: 2025
A8: Pool Parameters | I8: Fresh Water Add (M³) | J8: Chemicals | O8: Backwash
A9: Day | B9: Calcium Hardness | C9: Total Alkalinity | D9: PH | E9: TDS | F9: Cyan. Acid | G9: CL | H9: T ºc | J9: Chlorine 65% (Kg) | K9: Chlorine 90% (Kg) | L9: Sda Ash PH+ (Kg) | M9: HCL PH- (Lit) | N9: Other Chemicals
A10: 1
A11: 2
A12: 3
A13: 4
A14: 5
A15: 6
A16: 7
A17: 8
A18: 9
A19: 10
A20: 11
A21: 12
... A40: 31
D41: =AVERAGE(D10:D40) -> #DIV/0! | G41: =AVERAGE(G10:G40) -> #DIV/0! | H41: =AVERAGE(H10:H40) -> #DIV/0! | I41: =AVERAGE(I10:I40) -> #DIV/0! | J41: =SUM(J10:J40) -> 0 | K41: =SUM(K10:K40) -> 0

Sheet Kids pool 
A5: Engineering Department
A6: Kids Pool | M6: Month : | N6: April | O6: 2025
A8: Pool Parameters | I8: Fresh Water Add (M³) | J8: Chemicals | O8: Backwash
A9: Day | B9: Calcium Hardness | C9: Total Alkalinity | D9: PH | E9: TDS | F9: Cyan. Acid | G9: CL | H9: T ºc | J9: Chlorine 65% (Kg) | K9: Chlorine 90% (Kg) | L9: Sda Ash PH+ (Kg) | M9: HCL PH- (Lit) | N9: Other Chemicals
A10: 1
A11: 2
A12: 3
A13: 4
A14: 5
A15: 6
A16: 7
A17: 8
A18: 9
A19: 10
A20: 11
A21: 12
... A40: 31
D41: =AVERAGE(D10:D40) -> #DIV/0! | G41: =AVERAGE(G10:G40) -> #DIV/0! | H41: =AVERAGE(H10:H40) -> #DIV/0! | I41: =AVERAGE(I10:I40) -> #DIV/0! | J41: =SUM(J10:J40) -> 0 | K41: =SUM(K10:K40) -> 0

Sheet Jacuzzi
A5: Engineering Department
A6: Infinity Pool | M6: Month : | N6: April | O6: 2025
A8: Pool Parameters | I8: Fresh Water Add (M³) | J8: Chemicals | O8: Backwash
A9: Day | B9: Calcium Hardness | C9: Total Alkalinity | D9: PH | E9: TDS | F9: Cyan. Acid | G9: CL | H9: T ºc | J9: Chlorine 65% (Kg) | K9: Chlorine 90% (Kg) | L9: Sda Ash PH+ (Kg) | M9: HCL PH- (Lit) | N9: Other Chemicals
A10: 1
A11: 2
A12: 3
A13: 4
A14: 5
A15: 6
A16: 7
A17: 8
A18: 9
A19: 10
A20: 11
A21: 12
... A40: 31
D41: =AVERAGE(D10:D40) -> #DIV/0! | G41: =AVERAGE(G10:G40) -> #DIV/0! | H41: =AVERAGE(H10:H40) -> #DIV/0! | J41: =SUM(J10:J40) -> 0 | K41: =SUM(K10:K40) -> 0

Sheet Fountains & Lagoons
A5: Engineering Department
A6: Fountains, Water Falls and Lagoons | I6: Month : | M6: April | N6: 2021 | O6: 2025
B8: Lagoons | E8: Water Falls | H8: Entrance Fountain | J8: Shops Fountain | M8: Main Tank | O8: Irrigation Tank
A9: Day | B9: PH | C9: CL | D9: Backwash | E9: PH | F9: CL | G9: Backwash | H9: PH | I9: CL | J9: PH | K9: CL | L9: Backwash | M9: PH | N9: CL | O9: PH | P9: CL
A10: 1
A11: 2
A12: 3
A13: 4
A14: 5
A15: 6
A16: 7
A17: 8
A18: 9
A19: 10
A20: 11
A21: 12
... A40: 31

Sheet Boilers
A5: Engineering Department
A6: Boilers Water Parameters | V6: Month : | X6: April | Y6: 2025
A8: Day | B8: Feed Tank | M8: Boiler Water
B9: Alkalinity | E9: Chloride | F9: PH | G9: Conduc- tivity | H9: TDS | I9: Fe | J9: TH | K9: TºC | M9: Alkalinity | P9: Chloride | Q9: PH | R9: Conduc- tivity | S9: TDS | T9: Fe | U9: Po4 | V9: Na2 So3 | W9: TH | X9: Boiler No. | Y9: Company
B10: P | C10: M | D10: OH | E10: CL/NaCL | M10: P | N10: M | O10: OH | P10: CL/NaCL
A11: 1
A12: 2
A13: 3
A14: 4
A15: 5
A16: 6
A17: 7
A18: 8
A19: 9
A20: 10
A21: 11
A22: 12
... A41: 31
H42: =AVERAGE(H11:H41) -> #DIV/0! | I42: =AVERAGE(I11:I41) -> #DIV/0! | J42: =AVERAGE(J11:J41) -> #DIV/0! | K42: =AVERAGE(K11:K41) -> #DIV/0! | Q42: =AVERAGE(Q11:Q41) -> #DIV/0! | S42: =AVERAGE(S11:S41) -> #DIV/0! | T42: =AVERAGE(T11:T41) -> #DIV/0!

Sheet Chillers
A5: Engineering Department
A6: Chilled Water Parameters | L6: HISTORY
A8: Date | C8: Main Chillers | J8: Gym & Spa Chillers | Q8: Company
C9: PH | D9: Conduc- tivity | E9: TDS | F9: Fe | G9: INH | H9: Cu. | J9: PH | K9: Conduc- tivity | L9: TDS | M9: Fe | N9: INH | O9: Cu.
A10: 38591 | C10: 10.5 | D10: 2550 | E10: 1700 | F10: 0.8 | G10: 600 | Q10: System Technique
A11: 38599 | C11: 9.7 | D11: 2055 | E11: 1370 | F11: 0.8 | G11: 600 | Q11: System Technique
A12: 38606 | C12: 9.8 | D12: 2160 | E12: 1440 | F12: 0.7 | G12: 650 | Q12: System Technique
A13: 38613 | C13: 9.7 | D13: 2250 | E13: 1500 | F13: 0.8 | G13: 600 | Q13: System Technique
A14: 38634 | C14: 8 | D14: 585 | E14: 390 | F14: 0.3 | G14: Nil | Q14: System Technique
A15: 38662 | C15: 10 | D15: 1845 | E15: 1230 | F15: 0.8 | G15: 500 | Q15: System Technique
A16: 38722 | C16: 10 | D16: 2175 | E16: 1450 | F16: 0.6 | G16: 700 | H16: Nil | Q16: System Technique
A17: 38739 | C17: 10.1 | D17: 3150 | E17: 2300 | F17: 0.5 | G17: 450 | Q17: System Technique
A18: 38760 | C18: 9.9 | D18: 1675 | E18: 1250 | F18: 0.3 | G18: 600 | H18: Nil | Q18: System Technique
A19: 38767 | C19: 9.7 | D19: 22250 | E19: 1500 | F19: 0.5 | G19: 250 | Q19: System Technique
A20: 38788 | C20: 10.1 | D20: 2475 | E20: 1850 | F20: 0.6 | G20: 1000 | H20: Nil | Q20: System Technique
A21: 38802 | C21: 10.2 | D21: 3000 | E21: 2000 | F21: 0.3 | G21: 650 | Q21: System Technique
A22: 38844 | C22: 10.2 | D22: 2750 | E22: 1800 | F22: 0.5 | G22: 1000 | Q22: System Technique
A23: 38858 | C23: 10.2 | D23: 3750 | E23: 2500 | F23: 0.6 | G23: 1000 | H23: Nil | Q23: System Technique
A24: 38900 | C24: 10.5 | D24: 3000 | E24: 2000 | F24: 0.5 | G24: 1000 | H24: Nil | Q24: System Technique
A25: 38926 | C25: 10.4 | D25: 3000 | E25: 2000 | F25: 0.3 | G25: 700 | H25: Nil | J25: 10.2 | K25: 6000 | L25: 4000 | M25: 0.3 | N25: 2500 | O25: Nil | Q25: System Technique
A26: 38949 | C26: 10.5 | D26: 3000 | E26: 2000 | F26: 0.5 | G26: 1000 | H26: Nil | J26: 9.8 | K26: 7500 | L26: 5000 | M26: 0.6 | N26: 2000 | O26: Nil | Q26: System Technique
A27: 38963 | C27: 10.5 | D27: 1950 | E27: 1300 | F27: 0.3 | G27: 600 | J27: 10.7 | K27: 4500 | L27: 3000 | M27: 0.5 | N27: 2000 | Q27: System Technique
A28: 38977 | C28: 10.5 | D28: 2250 | E28: 1500 | F28: 0.5 | G28: 600 | J28: 9 | K28: 600 | L28: 400 | M28: 3 | N28: Nil | Q28: System Technique
A29: 38998 | C29: 10 | D29: 1950 | E29: 1300 | F29: 0.5 | G29: 600 | H29: Nil | J29: 10.5 | K29: 6000 | L29: 4000 | M29: 0.5 | N29: 1500 | O29: Nil | Q29: System Technique
A30: 39019 | C30: 10.5 | D30: 2700 | E30: 1800 | F30: 0.5 | G30: 600 | H30: Nil | J30: 11 | K30: 6000 | L30: 4000 | M30: 0.5 | N30: 2000 | O30: Nil | Q30: System Technique
A31: 39037 | C31: 10.5 | D31: 2700 | E31: 1800 | F31: 0.7 | G31: 1000 | H31: Nil | J31: 11 | K31: 6000 | L31: 4000 | M31: 0.7 | N31: 3000 | O31: Nil | Q31: System Technique
A32: 39047 | C32: 10.5 | D32: 2700 | E32: 1800 | F32: 0.7 | G32: 1000 | H32: Nil | J32: 11 | K32: 6000 | L32: 4000 | M32: 0.7 | N32: 2500 | O32: Nil | Q32: System Technique
A33: 39096 | C33: 10.6 | D33: 2550 | E33: 1700 | F33: 0.7 | G33: 1000 | H33: Nil | J33: 11 | K33: 5250 | L33: 3500 | M33: 0.7 | N33: 2500 | O33: Nil | Q33: System Technique
A34: 39124 | C34: 10.8 | D34: 3300 | E34: 4500 | F34: 0.6 | G34: 2000 | H34: Nil | J34: 11 | K34: 6750 | L34: 4500 | M34: 0.6 | N34: 2000 | O34: Nil | Q34: System Technique
A35: 39145 | C35: 10.9 | D35: 2700 | E35: 1800 | F35: 0.7 | G35: 600 | H35: Nil | J35: 11 | K35: 5250 | L35: 3500 | M35: 0.7 | N35: 1800 | O35: Nil | Q35: System Technique
A36: 39166 | C36: 10.8 | D36: 2400 | E36: 1600 | F36: 0.6 | G36: 600 | H36: Nil | J36: 10.3 | K36: 4200 | L36: 2800 | M36: 0.4 | N36: 1500 | O36: Nil | Q36: System Technique
A37: 39180 | C37: 10.8 | D37: 2700 | E37: 1800 | F37: 0.7 | G37: 600 | H37: Nil | J37: 10.9 | K37: 5250 | L37: 3500 | M37: 0.6 | N37: 1800 | O37: Nil | Q37: System Technique
A38: 39201 | C38: 10.7 | D38: 2250 | E38: 1700 | F38: 0.7 | H38: 8.2 | J38: 370 | K38: 4500 | L38: 1.2 | M38: 26 | N38: 496 | Q38: System Technique
A39: 39235 | C39: 10.3 | D39: 3000 | E39: 2000 | F39: 0.7 | G39: 1000 | H39: <0.1 | J39: 11 | K39: 5250 | L39: 3500 | M39: 0.7 | N39: 1500 | O39: <0.1 | Q39: System Technique
A40: 39250 | C40: 10.5 | D40: 3000 | E40: 2000 | F40: 0.6 | G40: 800 | H40: <0.1 | J40: 11 | K40: 4500 | L40: 3000 | M40: 0.6 | N40: 1500 | O40: <0.1 | Q40: System Technique
A41: 39264 | C41: 10.5 | D41: 3000 | E41: 2000 | F41: 0.6 | G41: 1000 | J41: 10.6 | K41: 2700 | L41: 1800 | M41: 0.6 | N41: 800 | Q41: System Technique
A42: 39292 | C42: 10.7 | D42: 2700 | E42: 1800 | F42: 0.6 | G42: 600 | H42: <0.1 | J42: 10.5 | K42: 2550 | L42: 1700 | M42: 0.6 | N42: 400 | O42: <0.1 | Q42: System Technique
A43: 39299 | C43: 10.5 | D43: 3000 | E43: 2000 | F43: 0.6 | G43: 1000 | J43: 10.6 | K43: 7500 | L43: 5000 | M43: 0.6 | N43: 3000 | Q43: System Technique
A44: 39327 | C44: 10.2 | D44: 3750 | E44: 2500 | F44: 0.6 | G44: 2000 | H44: Nil | J44: 10.7 | K44: 6000 | L44: 4000 | M44: 0.6 | N44: 3000 | O44: Nil | Q44: System Technique
A45: 39334 | C45: 10.2 | D45: 3750 | E45: 2500 | F45: 0.6 | G45: 2000 | H45: Nil | J45: 10.7 | K45: 6000 | L45: 4000 | M45: 0.6 | N45: 3000 | O45: Nil | Q45: System Technique
...

Sheet Reading.4.24
A1: 1 | B1: 2 | C1: 3 | D1: 4 | E1: 5 | F1: 6 | G1: 7 | H1: 8 | I1: 9 | J1: 10 | K1: 11 | L1: 12 | M1: 13 | N1: 14 | O1: 15 | P1: 16 | Q1: 17 | R1: 18 | S1: 19 | T1: 20 | U1: 21 | V1: 22 | W1: 23 | X1: 24 | Y1: 25 | Z1: 26 | AA1: 27 | AB1: 28 | AC1: 29 | AD1: 30 | AE1: 31 | AF1: 32 | AG1: 33 | AH1: 34 | AI1: 35 | AJ1: 36 | AK1: 37 | AL1: 38 | AM1: 39 | AN1: 40 | AO1: 41 | AP1: 42 | AQ1: 43 | AR1: 44 | AS1: 45 | AT1: 46 | AU1: 47 | AV1: 48 | AW1: 49 | AX1: 50 | AY1: 51 | AZ1: 52 | BA1: 53 | BB1: 54 | BC1: 55 | BD1: 56 | BE1: 57 | BF1: 58 | BG1: 59 | BH1: 60 | BI1: 61 | BJ1: 62 | BK1: 63 | BL1: 64 | BM1: 65 | BN1: 66 | BO1: 67 | BP1: 68 | BQ1: 69 | BR1: 70 | BS1: 71 | BT1: 72 | BU1: 73 | BV1: 74 | BW1: 75 | BX1: 76 | BY1: 77 | BZ1: 78 | CA1: 79 | CB1: 80 | CC1: 81 | CD1: 82 | CE1: 83 | CF1: 80 | CG1: 81 | CH1: 82 | CI1: 84 | CJ1: 85 | CK1: 86 | CL1: 87 | CM1: 88 | CN1: 89 | CO1: 90 | CP1: 91 | CQ1: 92 | CR1: 93 | CS1: 94 | CT1: 95 | CU1: 96 | CV1: 97 | CW1: 98 | CX1: 99 | CY1: 100 | CZ1: 101 | DA1: 102 | DB1: 103 | DC1: 104 | DD1: 105 | DE1: 106 | DF1: 107 | DG1: 108 | DH1: 109 | DI1: 110 | DJ1: 111 | DK1: 112 | DL1: 113 | DM1: 114 | DN1: 115 | DO1: 116 | DP1: 117 | DQ1: 118 | DR1: 119 | DS1: 120 | DT1: 121 | DU1: 122 | DV1: 123 | DW1: 124 | DX1: 125 | DY1: 126 | DZ1: 127 | EA1: 128 | EB1: 129 | EC1: 130 | ED1: 131 | EE1: 132 | EF1: 133 | EG1: 134 | EH1: 135 | EI1: 136 | EJ1: 137 | EK1: 138 | EL1: 139
B2: WATER | J2: KITCHEN GAS | N2: BOILER GAS | R2: FUEL | W2: ELECTRICITY | AA2: GENERATORS | AE2: TOTAL KWH | AI2: Occupancy % | AM2: Rooms Occupied | AQ2: Max. Demand | AT2: Power Factor | AY2: More Data | BC2: Weather Temperature | BL2: Available Rooms | BN2: Water Sold Last Year | BP2: Kitchen Water | BT2: Laundry Water | BX2: Fountain Water | CB2: S. Pool Water | CF2: Heated Pool Water | CI2: Staff Houses Water | CM2: Total Facilities Cons. | CP2: STP | CV2: Dishwasher | CZ2: Staff Kitchen | DD2: Laundry Electricity | DH2: Kit. Equip. Electricity | DL2: Chiller 1 | DP2: Chiller 2 | DT2: Chiller 3 | DX2: Chilled Pumps KWH | DZ2: Total Chillers | EC2: RO Plant | EF2: Staff Kitchen Gas | EJ2: Rotary Oven Gas
A4: Date | B4: Reading | C4: Product. | D4: Buy | E4: Sold | F4: Tanks Level | G4: Consump. This Year | H4: Last Year | J4: Reading | K4: Consump. This Year | L4: Last Year | N4: Reading | O4: Consump. This Year | P4: Last Year | R4: Reading | S4: Add | T4: Consump. This Year | U4: Last Year | W4: Reading | X4: Consump. This Year | Y4: Consump. Last Year | AA4: Reading | AB4: Consump. This Year | AC4: Consump. Last Year | AE4: This Year | AF4: Last Year | AG4: Budget | AI4: This Year | AJ4: Last Year | AK4: Budget | AM4: This Year | AN4: Last Year | AO4: Budget | AQ4: This Year KW | AR4: Last Year KW | AT4: KVAR Reading | AU4: KVAR Cons. | AV4: Cos Ø | AY4: Last Year January 2021 | BC4: This Year - September 2023 | BG4: Last Year - September 2022 | BP4: Counter Reading | BQ4: Consumption This year | BR4: Consumption Last Year | BT4: Counter Reading | BU4: Consumption | BV4: Consumption Last Year | BX4: Counter Reading | BY4: Consumption | BZ4: Consumption Last Year | CB4: Counter Reading | CC4: Consumption | CD4: Consumption Last Year | CF4: Counter Reading | CG4: Consumption | CH4: Consumption Last Year | CI4: Counter Reading | CJ4: Consumption | CK4: Consumption Last Year | CM4: This Year | CN4: Last Year | CP4: Counter Reading | CQ4: Recycled Water this Year | CR4: % | CS4: Reccycled Water Last Year | CT4: % | CV4: Counter Reading | CW4: Cons. | CX4: Cons. Last Year | CZ4: Counter Reading | DA4: Cons. | DB4: Cons. Last Year | DD4: Counter Reading | DE4: Cons. | DF4: Cons. Last Year | DH4: Counter Reading | DI4: Cons. | DJ4: Cons. Last Year | DL4: Counter Reading | DM4: Cons. | DN4: Cons. Last Year | DP4: Counter Reading | DQ4: Cons. | DR4: Cons. Last Year | DT4: Counter Reading | DU4: Cons. | DV4: Cons. Last Year | DZ4: Cons. | EA4: Cons. Last Year | EC4: KWH This Year | ED4: KWH Last Year | EF4: Counter Reading | EG4: Cons. | EH4: Cons. Last Year | EJ4: Counter Reading | EK4: Cons. | EL4: Cons. Last Year
B5: 277890 | F5: 840 | J5: 206864 | N5: 730976 | R5: 42700 | W5: 45656.55 | AA5: 520030 | AT5: 7138.69 | BP5: 66271 | BT5: 81071 | BX5: 3964 | CB5: 233360 | CF5: 6070 | CI5: 19776 | CP5: 100965 | CV5: 5213 | CZ5: 878 | DD5: 1420698 | DH5: 3314265 | DL5: 2903383 | DP5: 2284888 | DT5: 3046535 | EF5: 59556 | EJ5: 23762
A6: 45383 | B6: 278305 | C6: =B6-B5 -> 415 | E6: 0 | F6: 750 | G6: =C6+D6-E6+F5-F6 -> 505 | H6: ='[1]Reading.4.23'!G6 -> 624 | J6: 206888 | K6: =(J6-J5)*4.668 -> 112.032 | L6: ='[1]Reading.4.23'!K6 -> 149.376 | N6: 731061 | O6: =(N6-N5)*4.61 -> 391.85 | P6: ='[1]Reading.4.23'!O6 -> 419.51 | R6: 42700 | T6: =(R5+S5)-R6 -> 0 | U6: ='[1]Reading.4.23'!T6 -> 0 | W6: 45663.48 | X6: =(W6-W5)*4000 -> 27720 | Y6: ='[1]Reading.4.23'!X6 -> 25200 | AA6: 520030 | AB6: =AA6-AA5 -> 0 | AC6: ='[1]Reading.4.23'!AB6 -> 560 | AE6: =+X6+AB6 -> 27720 | AF6: ='[1]Reading.4.23'!AE6 -> 25760 | AG6: =989409/30 -> 32980.3 | AI6: 0.5209 | AJ6: ='[1]Reading.4.23'!AI6 -> 0.435 | AK6: 0.638 | AM6: 274 | AN6: ='[1]Reading.4.23'!AM6 -> 228 | AO6: =10065/30 -> 335.5 | AQ6: =365*4 -> 1460 | AR6: ='[1]Reading.4.23'!AQ6 -> 1380 | AT6: 7139.41 | AU6: =(AT6-AT5)*4000 -> 2880 | AV6: =+X6/SQRT(((POWER((X6),2)+(POWER((AU6),2))))) -> 0.99464611 | AY6: ='[1]Reading.4.23'!X6 -> 25200 | AZ6: ='[1]Reading.4.23'!AB6 -> 560 | BA6: =AY6+AZ6 -> 25760 | BC6: 19 | BD6: 16.1 | BE6: 12 | BF6: 56 | BG6: 79 | BH6: ='[1]Reading.4.23'!BD6 -> 20.3 | BI6: ='[1]Reading.4.23'!BE6 -> 17 | BJ6: ='[1]Reading.4.23'!BF6 -> 52 | BL6: 526 | BN6: ='[1]Reading.4.23'!E4 -> Sold | BP6: 66301 | BQ6: =BP6-BP5 -> 30 | BR6: ='[1]Reading.4.23'!BQ6 -> 26 | BT6: 81101 | BU6: =BT6-BT5 -> 30 | BV6: ='[1]Reading.4.23'!BU6 -> 29 | BX6: 3975 | BY6: =BX6-BX5 -> 11 | BZ6: ='[1]Reading.4.23'!BY6 -> 0 | CB6: 233390 | CC6: =CB6-CB5 -> 30 | CD6: ='[1]Reading.4.23'!CC6 -> 80 | CF6: 6080 | CG6: =CF6-CF5 -> 10 | CH6: ='[1]Reading.4.23'!CG6 -> 0 | CI6: 19773 | CJ6: =CI6-CI5 -> -3 | CK6: ='[1]Reading.4.23'!CG6 -> 0 | CM6: =BQ6+BU6+BY6+CC6+CJ6 -> 98 | CN6: =BR6+BV6+BZ6+CD6+CK6 -> 135 | CP6: 101308 | CQ6: =CP6-CP5 -> 343 | CR6: =CQ6/G6 -> 0.67920792 | CS6: ='[1]Reading.4.23'!CN6 -> 211 | CT6: ='[1]Reading.4.23'!CO4 -> % | CV6: 5215 | CW6: =CV6-CV5 -> 2 | CX6: ='[1]Reading.4.23'!CT6 -> 1 | CZ6: 881 | DA6: =CZ6-CZ5 -> 3 | DB6: ='[1]Reading.4.23'!CX6 -> 4 | DD6: 1421455 | DE6: =DD6-DD5 -> 757 | DF6: ='[1]Reading.4.23'!DB6 -> 602 | DH6: 3316131 | DI6: =DH6-DH5 -> 1866 | DJ6: ='[1]Reading.4.23'!DF6 -> 1568 | DL6: 2906591 | DM6: =DL6-DL5 -> 3208 | DN6: ='[1]Reading.4.23'!DJ6 -> 1925 | DP6: 2284919 | DQ6: =DP6-DP5 -> 31 | DR6: ='[1]Reading.4.23'!DN6 -> 32 | DT6: 3046566 | DU6: =DT6-DT5 -> 31 | DV6: ='[1]Reading.4.23'!DR6 -> 32 | DX6: 720 | DZ6: =DM6+DQ6+DU6+DX6 -> 3990 | EA6: ='[1]Reading.4.23'!DW6 -> 2709 | EC6: =C6*5.2 -> 2158 | ED6: ='[1]Reading.4.23'!C6*5.2 -> 2828.8 | EF6: 59596 | EG6: =EF6-EF5 -> 40 | EJ6: 23795 | EK6: =EJ6-EJ5 -> 33
A7: 45384 | B7: 278810 | C7: =B7-B6 -> 505 | E7: 0 | F7: 795 | G7: =C7+D7-E7+F6-F7 -> 460 | H7: ='[1]Reading.4.23'!G7 -> 539 | J7: 206914 | K7: =(J7-J6)*4.668 -> 121.368 | L7: ='[1]Reading.4.23'!K7 -> 135.372 | N7: 731150 | O7: =(N7-N6)*4.61 -> 410.29 | P7: ='[1]Reading.4.23'!O7 -> 410.29 | R7: 42700 | T7: =(R6+S6)-R7 -> 0 | U7: ='[1]Reading.4.23'!T7 -> 0 | W7: 45670.63 | X7: =(W7-W6)*4000 -> 28600 | Y7: ='[1]Reading.4.23'!X7 -> 25640 | AA7: 520030 | AB7: =AA7-AA6 -> 0 | AC7: ='[1]Reading.4.23'!AB7 -> 0 | AE7: =+X7+AB7 -> 28600 | AF7: ='[1]Reading.4.23'!AE7 -> 25640 | AG7: =989409/30 -> 32980.3 | AI7: 0.4924 | AJ7: ='[1]Reading.4.23'!AI7 -> 0.4011 | AK7: 0.638 | AM7: 259 | AN7: ='[1]Reading.4.23'!AM7 -> 211 | AO7: =10065/30 -> 335.5 | AQ7: =365*4 -> 1460 | AR7: ='[1]Reading.4.23'!AQ7 -> 1412 | AT7: 7140.23 | AU7: =(AT7-AT6)*4000 -> 3280 | AV7: =+X7/SQRT(((POWER((X7),2)+(POWER((AU7),2))))) -> 0.99348781 | AY7: ='[1]Reading.4.23'!X7 -> 25640 | AZ7: ='[1]Reading.4.23'!AB7 -> 0 | BA7: =AY7+AZ7 -> 25640 | BC7: 19 | BD7: 16.1 | BE7: 12 | BF7: 56 | BG7: 79 | BH7: ='[1]Reading.4.23'!BD7 -> 22.6 | BI7: ='[1]Reading.4.23'!BE7 -> 19 | BJ7: ='[1]Reading.4.23'!BF7 -> 52 | BL7: 526 | BN7: ='[1]Reading.4.23'!E5 -> 0 | BP7: 66319 | BQ7: =BP7-BP6 -> 18 | BR7: ='[1]Reading.4.23'!BQ7 -> 27 | BT7: 81135 | BU7: =BT7-BT6 -> 34 | BV7: ='[1]Reading.4.23'!BU7 -> 31 | BX7: 3975 | BY7: =BX7-BX6 -> 0 | BZ7: ='[1]Reading.4.23'!BY7 -> 0 | CB7: 233410 | CC7: =CB7-CB6 -> 20 | CD7: ='[1]Reading.4.23'!CC7 -> 90 | CF7: 6080 | CG7: =CF7-CF6 -> 0 | CH7: ='[1]Reading.4.23'!CG7 -> 0 | CI7: 19773 | CJ7: =CI7-CI6 -> 0 | CK7: ='[1]Reading.4.23'!CG7 -> 0 | CM7: =BQ7+BU7+BY7+CC7+CJ7 -> 72 | CN7: =BR7+BV7+BZ7+CD7+CK7 -> 148 | CP7: 101658 | CQ7: =CP7-CP6 -> 350 | CR7: =CQ7/G7 -> 0.76086957 | CS7: ='[1]Reading.4.23'!CN7 -> 232 | CT7: ='[1]Reading.4.23'!CO5 -> 0 | CV7: 5217 | CW7: =CV7-CV6 -> 2 | CX7: ='[1]Reading.4.23'!CT7 -> 2 | CZ7: 883 | DA7: =CZ7-CZ6 -> 2 | DB7: ='[1]Reading.4.23'!CX7 -> 5 | DD7: 1422161 | DE7: =DD7-DD6 -> 706 | DF7: ='[1]Reading.4.23'!DB7 -> 593 | DH7: 3317275 | DI7: =DH7-DH6 -> 1144 | DJ7: ='[1]Reading.4.23'!DF7 -> 1953 | DL7: 2910143 | DM7: =DL7-DL6 -> 3552 | DN7: ='[1]Reading.4.23'!DJ7 -> 2345 | DP7: 2284953 | DQ7: =DP7-DP6 -> 34 | DR7: ='[1]Reading.4.23'!DN7 -> 34 | DT7: 3046597 | DU7: =DT7-DT6 -> 31 | DV7: ='[1]Reading.4.23'!DR7 -> 33 | DX7: 720 | DZ7: =DM7+DQ7+DU7+DX7 -> 4337 | EA7: ='[1]Reading.4.23'!DW7 -> 3132 | EC7: =C7*5.2 -> 2626 | ED7: ='[1]Reading.4.23'!C7*5.2 -> 3218.8 | EF7: 59645 | EG7: =EF7-EF6 -> 49 | EJ7: 23812 | EK7: =EJ7-EJ6 -> 17
A8: 45385 | B8: 279392 | C8: =B8-B7 -> 582 | E8: 0 | F8: 825 | G8: =C8+D8-E8+F7-F8 -> 552 | H8: ='[1]Reading.4.23'!G8 -> 526 | J8: 206946 | K8: =(J8-J7)*4.668 -> 149.376 | L8: ='[1]Reading.4.23'!K8 -> 144.708 | N8: 731234 | O8: =(N8-N7)*4.61 -> 387.24 | P8: ='[1]Reading.4.23'!O8 -> 401.07 | R8: 42700 | T8: =(R7+S7)-R8 -> 0 | U8: ='[1]Reading.4.23'!T8 -> 0 | W8: 45677.92 | X8: =(W8-W7)*4000 -> 29160 | Y8: ='[1]Reading.4.23'!X8 -> 25760 | AA8: 520030 | AB8: =AA8-AA7 -> 0 | AC8: ='[1]Reading.4.23'!AB8 -> 0 | AE8: =+X8+AB8 -> 29160 | AF8: ='[1]Reading.4.23'!AE8 -> 25760 | AG8: =989409/30 -> 32980.3 | AI8: 0.4943 | AJ8: ='[1]Reading.4.23'!AI8 -> 0.4449 | AK8: 0.638 | AM8: 260 | AN8: ='[1]Reading.4.23'!AM8 -> 234 | AO8: =10065/30 -> 335.5 | AQ8: =387*4 -> 1548 | AR8: ='[1]Reading.4.23'!AQ8 -> 1488 | AT8: 7141.03 | AU8: =(AT8-AT7)*4000 -> 3200 | AV8: =+X8/SQRT(((POWER((X8),2)+(POWER((AU8),2))))) -> 0.99403248 | AY8: ='[1]Reading.4.23'!X8 -> 25760 | AZ8: ='[1]Reading.4.23'!AB8 -> 0 | BA8: =AY8+AZ8 -> 25760 | BC8: 19 | BD8: 16.1 | BE8: 12 | BF8: 56 | BG8: 79 | BH8: ='[1]Reading.4.23'!BD8 -> 25.2 | BI8: ='[1]Reading.4.23'!BE8 -> 20 | BJ8: ='[1]Reading.4.23'!BF8 -> 64 | BL8: 526 | BN8: ='[1]Reading.4.23'!E6 -> 0 | BP8: 66337 | BQ8: =BP8-BP7 -> 18 | BR8: ='[1]Reading.4.23'!BQ8 -> 26 | BT8: 81171 | BU8: =BT8-BT7 -> 36 | BV8: ='[1]Reading.4.23'!BU8 -> 26 | BX8: 3975 | BY8: =BX8-BX7 -> 0 | BZ8: ='[1]Reading.4.23'!BY8 -> 0 | CB8: 233440 | CC8: =CB8-CB7 -> 30 | CD8: ='[1]Reading.4.23'!CC8 -> 70 | CF8: 6090 | CG8: =CF8-CF7 -> 10 | CH8: ='[1]Reading.4.23'!CG8 -> 0 | CI8: 19773 | CJ8: =CI8-CI7 -> 0 | CK8: ='[1]Reading.4.23'!CG8 -> 0 | CM8: =BQ8+BU8+BY8+CC8+CJ8 -> 84 | CN8: =BR8+BV8+BZ8+CD8+CK8 -> 122 | CP8: 102023 | CQ8: =CP8-CP7 -> 365 | CR8: =CQ8/G8 -> 0.66123188 | CS8: ='[1]Reading.4.23'!CN8 -> 241 | CT8: ='[1]Reading.4.23'!CO6 -> 0.33814103 | CV8: 5219 | CW8: =CV8-CV7 -> 2 | CX8: ='[1]Reading.4.23'!CT8 -> 1 | CZ8: 886 | DA8: =CZ8-CZ7 -> 3 | DB8: ='[1]Reading.4.23'!CX8 -> 4 | DD8: 1422856 | DE8: =DD8-DD7 -> 695 | DF8: ='[1]Reading.4.23'!DB8 -> 704 | DH8: 3318426 | DI8: =DH8-DH7 -> 1151 | DJ8: ='[1]Reading.4.23'!DF8 -> 1739 | DL8: 2913925 | DM8: =DL8-DL7 -> 3782 | DN8: ='[1]Reading.4.23'!DJ8 -> 2679 | DP8: 2284984 | DQ8: =DP8-DP7 -> 31 | DR8: ='[1]Reading.4.23'!DN8 -> 32 | DT8: 3046629 | DU8: =DT8-DT7 -> 32 | DV8: ='[1]Reading.4.23'!DR8 -> 32 | DX8: 720 | DZ8: =DM8+DQ8+DU8+DX8 -> 4565 | EA8: ='[1]Reading.4.23'!DW8 -> 3463 | EC8: =C8*5.2 -> 3026.4 | ED8: ='[1]Reading.4.23'!C8*5.2 -> 2527.2 | EF8: 59690 | EG8: =EF8-EF7 -> 45 | EJ8: 23837 | EK8: =EJ8-EJ7 -> 25
