Workbook

Sheet TOTAL
A1: Site Name | B1: Day | C1: Month | D1: Year | E1: Total Electricity Kwh | F1: Electricity Tariff ($/Kwh) | G1: LPG (Liters) | H1: LPG $/Liters | I1: Water Utility Supply (m3) m3 | J1: Water Utility Supply (m3) $/m3 | K1: District Energy Cooling RTH | L1: District Energy Cooling $/RTH | M1: Room Nights | N1: Total Guests
A2: Amwaj Rotana - Jumeirah Beach | B2: 1 | C2: 12 | D2: 2024 | E2: ='MTD Utility Sheet'!G4/0.439 -> 14649.294 | F2: 0.439 | G2: =('MTD Utility Sheet'!I4/1.82)/0.5 -> 488 | H2: =1.82*0.5 -> 0.91 | I2: ='MTD Utility Sheet'!H4/12.38 -> 193.11793 | J2: 12.38 | K2: =IF(('MTD Utility Sheet'!F4-2866)<0,"0",('MTD Utility Sheet'!F4-2866)/(0.568+0.075)) -> 5050.0622 | L2: ='MTD Utility Sheet'!F4/K2 -> 1.2105178 | M2: ='MTD Utility Sheet'!B4*301 -> 234.78
A3: Amwaj Rotana - Jumeirah Beach | B3: =B2+1 -> 2 | C3: 12 | D3: 2024 | E3: ='MTD Utility Sheet'!G5/0.439 -> 14160.979 | F3: 0.439 | G3: =('MTD Utility Sheet'!I5/1.82)/0.5 -> 488 | H3: =1.82*0.5 -> 0.91 | I3: ='MTD Utility Sheet'!H5/12.38 -> 194.18417 | J3: 12.38 | K3: =IF(('MTD Utility Sheet'!F5-2866)<0,"0",('MTD Utility Sheet'!F5-2866)/(0.568+0.075)) -> 4322.1151 | L3: ='MTD Utility Sheet'!F5/K3 -> 1.3061013 | M3: ='MTD Utility Sheet'!B5*301 -> 207.69
A4: Amwaj Rotana - Jumeirah Beach | B4: =B3+1 -> 3 | C4: 12 | D4: 2024 | E4: ='MTD Utility Sheet'!G6/0.439 -> 14160.979 | F4: 0.439 | G4: =('MTD Utility Sheet'!I6/1.82)/0.5 -> 488 | H4: =1.82*0.5 -> 0.91 | I4: ='MTD Utility Sheet'!H6/12.38 -> 152.60097 | J4: 12.38 | K4: =IF(('MTD Utility Sheet'!F6-2866)<0,"0",('MTD Utility Sheet'!F6-2866)/(0.568+0.075)) -> 4108.8647 | L4: ='MTD Utility Sheet'!F6/K4 -> 1.3405163 | M4: ='MTD Utility Sheet'!B6*301 -> 192.64
A5: Amwaj Rotana - Jumeirah Beach | B5: =B4+1 -> 4 | C5: 12 | D5: 2024 | E5: ='MTD Utility Sheet'!G7/0.439 -> 13672.665 | F5: 0.439 | G5: =('MTD Utility Sheet'!I7/1.82)/0.5 -> 488 | H5: =1.82*0.5 -> 0.91 | I5: ='MTD Utility Sheet'!H7/12.38 -> 153.66721 | J5: 12.38 | K5: =IF(('MTD Utility Sheet'!F7-2866)<0,"0",('MTD Utility Sheet'!F7-2866)/(0.568+0.075)) -> 4407.4184 | L5: ='MTD Utility Sheet'!F7/K5 -> 1.2932673 | M5: ='MTD Utility Sheet'!B7*301 -> 216.72
A6: Amwaj Rotana - Jumeirah Beach | B6: =B5+1 -> 5 | C6: 12 | D6: 2024 | E6: ='MTD Utility Sheet'!G8/0.439 -> 13672.665 | F6: 0.439 | G6: =('MTD Utility Sheet'!I8/1.82)/0.5 -> 488 | H6: =1.82*0.5 -> 0.91 | I6: ='MTD Utility Sheet'!H8/12.38 -> 165.3958 | J6: 12.38 | K6: =IF(('MTD Utility Sheet'!F8-2866)<0,"0",('MTD Utility Sheet'!F8-2866)/(0.568+0.075)) -> 4876.6096 | L6: ='MTD Utility Sheet'!F8/K6 -> 1.2307034 | M6: ='MTD Utility Sheet'!B8*301 -> 234.78
A7: Amwaj Rotana - Jumeirah Beach | B7: =B6+1 -> 6 | C7: 12 | D7: 2024 | E7: ='MTD Utility Sheet'!G9/0.439 -> 14649.294 | F7: 0.439 | G7: =('MTD Utility Sheet'!I9/1.82)/0.5 -> 488 | H7: =1.82*0.5 -> 0.91 | I7: ='MTD Utility Sheet'!H9/12.38 -> 162.19709 | J7: 12.38 | K7: =IF(('MTD Utility Sheet'!F9-2866)<0,"0",('MTD Utility Sheet'!F9-2866)/(0.568+0.075)) -> 5755.2411 | L7: ='MTD Utility Sheet'!F9/K7 -> 1.1409809 | M7: ='MTD Utility Sheet'!B9*301 -> 255.85
A8: Amwaj Rotana - Jumeirah Beach | B8: =B7+1 -> 7 | C8: 12 | D8: 2024 | E8: ='MTD Utility Sheet'!G10/0.439 -> 14649.294 | F8: 0.439 | G8: =('MTD Utility Sheet'!I10/1.82)/0.5 -> 439.25275 | H8: =1.82*0.5 -> 0.91 | I8: ='MTD Utility Sheet'!H10/12.38 -> 188.85299 | J8: 12.38 | K8: =IF(('MTD Utility Sheet'!F10-2866)<0,"0",('MTD Utility Sheet'!F10-2866)/(0.568+0.075)) -> 5914.479 | L8: ='MTD Utility Sheet'!F10/K8 -> 1.1275735 | M8: ='MTD Utility Sheet'!B10*301 -> 243.81
A9: Amwaj Rotana - Jumeirah Beach | B9: =B8+1 -> 8 | C9: 12 | D9: 2024 | E9: ='MTD Utility Sheet'!G11/0.439 -> 14160.979 | F9: 0.439 | G9: =('MTD Utility Sheet'!I11/1.82)/0.5 -> 488 | H9: =1.82*0.5 -> 0.91 | I9: ='MTD Utility Sheet'!H11/12.38 -> 167.52827 | J9: 12.38 | K9: =IF(('MTD Utility Sheet'!F11-2866)<0,"0",('MTD Utility Sheet'!F11-2866)/(0.568+0.075)) -> 5112.6128 | L9: ='MTD Utility Sheet'!F11/K9 -> 1.2035744 | M9: ='MTD Utility Sheet'!B11*301 -> 264.88
A10: Amwaj Rotana - Jumeirah Beach | B10: =B9+1 -> 9 | C10: 12 | D10: 2024 | E10: ='MTD Utility Sheet'!G12/0.439 -> 13672.665 | F10: 0.439 | G10: =('MTD Utility Sheet'!I12/1.82)/0.5 -> 488 | H10: =1.82*0.5 -> 0.91 | I10: ='MTD Utility Sheet'!H12/12.38 -> 172.85945 | J10: 12.38 | K10: =IF(('MTD Utility Sheet'!F12-2866)<0,"0",('MTD Utility Sheet'!F12-2866)/(0.568+0.075)) -> 4629.2224 | L10: ='MTD Utility Sheet'!F12/K10 -> 1.2621105 | M10: ='MTD Utility Sheet'!B12*301 -> 258.86
A11: Amwaj Rotana - Jumeirah Beach | B11: =B10+1 -> 10 | C11: 12 | D11: 2024 | E11: ='MTD Utility Sheet'!G13/0.439 -> 15137.608 | F11: 0.439 | G11: =('MTD Utility Sheet'!I13/1.82)/0.5 -> 488 | H11: =1.82*0.5 -> 0.91 | I11: ='MTD Utility Sheet'!H13/12.38 -> 174.99192 | J11: 12.38 | K11: =IF(('MTD Utility Sheet'!F13-2866)<0,"0",('MTD Utility Sheet'!F13-2866)/(0.568+0.075)) -> 5055.7387 | L11: ='MTD Utility Sheet'!F13/K11 -> 1.2098806 | M11: ='MTD Utility Sheet'!B13*301 -> 267.89
A12: Amwaj Rotana - Jumeirah Beach | B12: =B11+1 -> 11 | C12: 12 | D12: 2024 | E12: ='MTD Utility Sheet'!G14/0.439 -> 15137.608 | F12: 0.439 | G12: =('MTD Utility Sheet'!I14/1.82)/0.5 -> 536.8022 | H12: =1.82*0.5 -> 0.91 | I12: ='MTD Utility Sheet'!H14/12.38 -> 206.979 | J12: 12.38 | K12: =IF(('MTD Utility Sheet'!F14-2866)<0,"0",('MTD Utility Sheet'!F14-2866)/(0.568+0.075)) -> 5266.1586 | L12: ='MTD Utility Sheet'!F14/K12 -> 1.1872297 | M12: ='MTD Utility Sheet'!B14*301 -> 273.91
A13: Amwaj Rotana - Jumeirah Beach | B13: =B12+1 -> 12 | C13: 12 | D13: 2024 | E13: ='MTD Utility Sheet'!G15/0.439 -> 14649.294 | F13: 0.439 | G13: =('MTD Utility Sheet'!I15/1.82)/0.5 -> 488 | H13: =1.82*0.5 -> 0.91 | I13: ='MTD Utility Sheet'!H15/12.38 -> 194.18417 | J13: 12.38 | K13: =IF(('MTD Utility Sheet'!F15-2866)<0,"0",('MTD Utility Sheet'!F15-2866)/(0.568+0.075)) -> 4984.6501 | L13: ='MTD Utility Sheet'!F15/K13 -> 1.2179651 | M13: ='MTD Utility Sheet'!B15*301 -> 291.0068
A14: Amwaj Rotana - Jumeirah Beach | B14: =B13+1 -> 13 | C14: 12 | D14: 2024 | E14: ='MTD Utility Sheet'!G16/0.439 -> 15625.923 | F14: 0.439 | G14: =('MTD Utility Sheet'!I16/1.82)/0.5 -> 488 | H14: =1.82*0.5 -> 0.91 | I14: ='MTD Utility Sheet'!H16/12.38 -> 214.44265 | J14: 12.38 | K14: =IF(('MTD Utility Sheet'!F16-2866)<0,"0",('MTD Utility Sheet'!F16-2866)/(0.568+0.075)) -> 4794.1369 | L14: ='MTD Utility Sheet'!F16/K14 -> 1.2408136 | M14: ='MTD Utility Sheet'!B16*301 -> 252.84
... A32: Amwaj Rotana - Jumeirah Beach | B32: =B31+1 -> 31 | C32: 12 | D32: 2024 | E32: ='MTD Utility Sheet'!G34/0.439 -> 14649.294 | F32: 1.439 | G32: =('MTD Utility Sheet'!I34/1.82)/0.5 -> 488 | H32: =1.82*0.5 -> 0.91 | I32: ='MTD Utility Sheet'!H34/12.38 -> 231.50242 | J32: 13.38 | K32: =IF(('MTD Utility Sheet'!F34-2866)<0,"0",('MTD Utility Sheet'!F34-2866)/(0.568+0.075)) -> 4885.1322 | L32: ='MTD Utility Sheet'!F34/K32 -> 1.2296781 | M32: ='MTD Utility Sheet'!B34*301 -> 288.96

Sheet MTD Utility Sheet
A1: Daily Utilities December-2024
B3: Occ % | C3: Out. Temp at 2PM | D3: RH % | E3: F&B Covers | F3: Chilled water | G3: Electricity | H3: Water | I3: LPG | J3: Total
A4: 1 | B4: 0.78 | C4: 27c | D4: 0.68 | E4: 1073 | F4: 6113.19 | G4: 6431.04 | H4: 2390.8 | I4: 444.08 | J4: =SUM(F4+G4+H4+I4) -> 15379.11
A5: 2 | B5: 0.69 | C5: 27c | D5: 0.57 | E5: 1012 | F5: 5645.12 | G5: 6216.67 | H5: 2404 | I5: 444.08 | J5: =SUM(F5+G5+H5+I5) -> 14709.87
A6: 3 | B6: 0.64 | C6: 27c | D6: 0.58 | E6: 854 | F6: 5508 | G6: 6216.67 | H6: 1889.2 | I6: 444.08 | J6: =SUM(F6+G6+H6+I6) -> 14057.95
A7: 4 | B7: 0.72 | C7: 27c | D7: 0.46 | E7: 757 | F7: 5699.97 | G7: 6002.3 | H7: 1902.4 | I7: 444.08 | J7: =SUM(F7+G7+H7+I7) -> 14048.75
A8: 5 | B8: 0.78 | C8: 27c | D8: 0.52 | E8: 940 | F8: 6001.66 | G8: 6002.3 | H8: 2047.6 | I8: 444.08 | J8: =SUM(F8+G8+H8+I8) -> 14495.64
A9: 6 | B9: 0.85 | C9: 28.0c. | D9: 0.58 | E9: 870 | F9: 6566.62 | G9: 6431.04 | H9: 2008 | I9: 444.08 | J9: =SUM(F9+G9+H9+I9) -> 15449.74
A10: 7 | B10: 0.81 | C10: 30c | D10: 0.67 | E10: 999 | F10: 6669.01 | G10: 6431.04 | H10: 2338 | I10: 399.72 | J10: =SUM(F10+G10+H10+I10) -> 15837.77
A11: 8 | B11: 0.88 | C11: 30c | D11: 0.51 | E11: 946 | F11: 6153.41 | G11: 6216.67 | H11: 2074 | I11: 444.08 | J11: =SUM(F11+G11+H11+I11) -> 14888.16
A12: 9 | B12: 0.86 | C12: 29c | D12: 0.53 | E12: 965 | F12: 5842.59 | G12: 6002.3 | H12: 2140 | I12: 444.08 | J12: =SUM(F12+G12+H12+I12) -> 14428.97
A13: 10 | B13: 0.89 | C13: 29c | D13: 0.58 | E13: 951 | F13: 6116.84 | G13: 6645.41 | H13: 2166.4 | I13: 444.08 | J13: =SUM(F13+G13+H13+I13) -> 15372.73
A14: 11 | B14: 0.91 | C14: 29.0c | D14: 0.53 | E14: 1020 | F14: 6252.14 | G14: 6645.41 | H14: 2562.4 | I14: 488.49 | J14: =SUM(F14+G14+H14+I14) -> 15948.44
A15: 12 | B15: 0.9668 | C15: 29c | D15: 0.57 | E15: 1164 | F15: 6071.13 | G15: 6431.04 | H15: 2404 | I15: 444.08 | J15: =SUM(F15+G15+H15+I15) -> 15350.25
... A17: 14 | B17: 0.74 | C17: 27c | D17: 0.54 | E17: 1115 | F17: 5844.42 | G17: 6431.04 | H17: 4780 | I17: 444.08 | J17: =SUM(F17+G17+H17+I17) -> 17499.54
A18: 15 | B18: 0.72 | C18: 26c | D18: 0.57 | E18: 881 | F18: 5628.67 | G18: 6216.67 | H18: 3314.8 | I18: 444.08 | J18: =SUM(F18+G18+H18+I18) -> 15604.22 | L18: =+L18:O27 -> 0
A19: 16 | B19: 0.71 | C19: 26.5c | D19: 0.6 | E19: 772 | F19: 5630.5 | G19: 6645.41 | H19: 2179.6 | I19: 488.89 | J19: =SUM(F19+G19+H19+I19) -> 14944.4
A20: 17 | B20: 0.7 | C20: 26.0c | D20: 0.53 | E20: 746 | F20: 5575.65 | G20: 6431.04 | H20: 2258.8 | I20: 621.71 | J20: =SUM(F20+G20+H20+I20) -> 14887.2
A21: 18 | B21: 0.66 | C21: 25.5c | D21: 0.55 | E21: 679 | F21: 5416.58 | G21: 6431.04 | H21: 2113.6 | I21: 444.08 | J21: =SUM(F21+G21+H21+I21) -> 14405.3
A22: 19 | B22: 0.68 | C22: 25.5c | D22: 0.8 | E22: 721 | F22: 5473.26 | G22: 6645.41 | H22: 2113.6 | I22: 444.08 | J22: =SUM(F22+G22+H22+I22) -> 14676.35
A23: 20 | B23: 0.68 | C23: 25.0c | D23: 0.62 | E23: 1050 | F23: 5376.35 | G23: 6859.78 | H23: 2285.2 | I23: 444.08 | J23: =SUM(F23+G23+H23+I23) -> 14965.41
A24: 21 | B24: 0.7 | C24: 25.0c | D24: 0.7 | E24: 1272 | F24: 5100.27 | G24: 6859.78 | H24: 2496.4 | I24: 444.08 | J24: =SUM(F24+G24+H24+I24) -> 14900.53
A25: 22 | B25: 0.72 | C25: 24.5c | D25: 0.6 | E25: 877 | F25: 5010 | G25: 6860 | H25: 2338 | I25: 444 | J25: =SUM(F25+G25+H25+I25) -> 14652
A26: 23 | B26: 0.82 | C26: 24.0c | D26: 0.82 | E26: 979 | F26: 5034.45 | G26: 6859.78 | H26: 2470 | I26: 621.71 | J26: =SUM(F26+G26+H26+I26) -> 14985.94
A27: 24 | B27: 0.85 | C27: 24.5c | D27: 0.72 | E27: 1197 | F27: 5217.28 | G27: 6859.78 | H27: 2470 | I27: 621.71 | J27: =SUM(F27+G27+H27+I27) -> 15168.77
A28: 25 | B28: 0.9468 | C28: 24.0c | D28: 0.68 | E28: 1384 | F28: 5363.55 | G28: 6431 | H28: 2800 | I28: 488.49 | J28: =SUM(F28+G28+H28+I28) -> 15083.04
A29: 26 | B29: 0.91 | C29: 23.5c | D29: 0.54 | E29: 1178 | F29: 5634.15 | G29: 6645.41 | H29: 2522.8 | I29: 488.49 | J29: =SUM(F29+G29+H29+I29) -> 15290.85
A30: 27 | B30: 0.9269 | C30: 23.5c | D30: 0.76 | E30: 1238 | F30: 5557.36 | G30: 6645.41 | H30: 2747 | I30: 488.49 | J30: =SUM(F30+G30+H30+I30) -> 15438.26
... A33: 30 | B33: 0.92 | C33: 27c | D33: 0.71 | E33: 1055 | F33: 5944.98 | G33: 6645.41 | H33: 2668 | I33: 577.3 | J33: =SUM(F33+G33+H33+I33) -> 15835.69
A34: 31 | B34: 0.96 | C34: 28c | D34: 0.68 | F34: 6007.14 | G34: 6431.04 | H34: 2866 | I34: 444.08 | J34: =SUM(F34+G34+H34+I34) -> 15748.26
A35: Total Cost | F35: =SUM(F4:F34) -> 177276.3 | G35: =SUM(G4:G34) -> 201506.12 | H35: =SUM(H4:H34) -> 76701.8 | I35: =SUM(I4:I34) -> 14832.64 | J35: =SUM(J4:J34) -> 470316.86
A36: Total Units | B36: =AVERAGE(B4:B34) -> 0.81131613 | C36: =AVERAGE(C4:C34) -> #DIV/0! | D36: =AVERAGE(D4:D34) -> 0.63 | E36: =SUM(E4:E34) -> 30476 | F36: =F35*0.38 -> 67364.994 | G36: =G35/12.9 -> 15620.629 | H36: =H35/0.92 -> 83371.522 | I36: =I35/1.76 -> 8427.6364

Sheet December-31
A1: Daily Utilities Consumption
A2: 31.12.2024
A3: District Cooling
A4: Previous Reading MWh | B4: 70753.38 | C4: Current Reading MWh | D4: 70770.56 | E4: Consumption MWH | F4: =D4-B4 -> 17.18 | G4: Consumption RTH | H4: =F4*284.35 -> 4885.133
A5: Cost Calculation
A6: Total Cost (0.568/rth) | D6: =H4*0.568 -> 2774.7555
A7: Total Fuel Surchage Cost (0.075/rth) | D7: =H4*0.075 -> 366.38497
A8: Chilled Water Demand (2,866 AED/Day) | D8: 2866
A9: Grand Total Exc. VAT | D9: =SUM(D6:H8) -> 6007.1405
A10: Electrical
A11: MDB-G1 (39299675-8) | C11: Previous Reading KWH | D11: 43423 | E11: Current Reading KWH | F11: 43430 | G11: Consumption KWH | H11: =F11-D11 -> 7
A12: MDB-G2 (39299676-6) | C12: Previous Reading KWH | D12: 72049 | E12: Current Reading KWH | F12: 72062 | G12: Consumption KWH | H12: =F12-D12 -> 13
A13: MDB-G3 (39299677-4) | C13: Previous Reading KWH | D13: 72801 | E13: Current Reading KWH | F13: 72811 | G13: Consumption KWH | H13: =F13-D13 -> 10
A14: Total Consumption KWH | H14: =SUM(H11:H13) -> 30
A15: Total Consumption * Multiplication Factor (487.20) | H15: =H14*487.2 -> 14616
A16: Cost Calculation
A17: 0-2000 kwh @ 0.230 /KWH | D17: 460
A18: 2000-4000 kwh @ 0.280 /KWH | D18: 560
A19: 4000-6000 kwh @ 0.320 /KWH | D19: 640
A20: 6000 & above @ 0.380 /KWH | D20: =H15*0.38 -> 5554.08
A21: Fuel Surcharge @ 0.060 /KWH | D21: =H15*0.06 -> 876.96
A22: Grand Total Exc. VAT | D22: =D20+D21 -> 6431.04
A23: WATER
A24: Previous Reading | B24: 309910 | C24: Present Reading | D24: 310140 | E24: Consumption m3 | F24: =D24-B24 -> 230 | G24: Consumption IG | H24: =F24*220 -> 50600
A25: Cost calculation
A26: 0-10000 @ 0.035 / IG | D26: 350
A27: 10000-20000 @ 0.04 / IG | D27: 400
A28: 20000 & above @ 0.046 / IG | D28: =(H24-20000)*0.046 -> 1407.6
A29: Fuel Surcharge @ 0.004 / IG | D29: =H24*0.004 -> 202.4
A30: Sewerage Fees | D30: =H24*0.01 -> 506
A31: Grand Total Exc. VAT | D31: =SUM(D26:H30) -> 2866
A32: LPG Gas
A33: Tank 1 (1% = 48 liters) | C33: Previous Reading % | D33: 80 | E33: Current Reading % | F33: 70 | G33: Consumption Liters | H33: =(D33-F33)*48.8 -> 488
A34: Tank 2 (1% = 48 liters) | C34: Previous Reading % | D34: 20 | E34: Current Reading % | F34: 20 | G34: Consumption Liters | H34: =(D34-F34)*48.8 -> 0
A35: Total Cost (@ 1.82 AED/Liter) | H35: =((H34+H33)*1.82)*0.5 -> 444.08
A36: Total Utilities | H36: =H35+D22+D9+D31 -> 15748.261

Sheet December-30
A1: Daily Utilities Consumption
A2: 30.12.2024
A3: District Cooling
A4: Previous Reading MWh | B4: 70736.54 | C4: Current Reading MWh | D4: 70753.38 | E4: Consumption MWH | F4: =D4-B4 -> 16.84 | G4: Consumption RTH | H4: =F4*284.35 -> 4788.454
A5: Cost Calculation
A6: Total Cost (0.568/rth) | D6: =H4*0.568 -> 2719.8419
A7: Total Fuel Surchage Cost (0.075/rth) | D7: =H4*0.075 -> 359.13405
A8: Chilled Water Demand (2,866 AED/Day) | D8: 2866
A9: Grand Total Exc. VAT | D9: =SUM(D6:H8) -> 5944.9759
A10: Electrical
A11: MDB-G1 (39299675-8) | C11: Previous Reading KWH | D11: 43416 | E11: Current Reading KWH | F11: 43423 | G11: Consumption KWH | H11: =F11-D11 -> 7
A12: MDB-G2 (39299676-6) | C12: Previous Reading KWH | D12: 72036 | E12: Current Reading KWH | F12: 72049 | G12: Consumption KWH | H12: =F12-D12 -> 13
A13: MDB-G3 (39299677-4) | C13: Previous Reading KWH | D13: 72790 | E13: Current Reading KWH | F13: 72801 | G13: Consumption KWH | H13: =F13-D13 -> 11
A14: Total Consumption KWH | H14: =SUM(H11:H13) -> 31
A15: Total Consumption * Multiplication Factor (487.20) | H15: =H14*487.2 -> 15103.2
A16: Cost Calculation
A17: 0-2000 kwh @ 0.230 /KWH | D17: 460
A18: 2000-4000 kwh @ 0.280 /KWH | D18: 560
A19: 4000-6000 kwh @ 0.320 /KWH | D19: 640
A20: 6000 & above @ 0.380 /KWH | D20: =H15*0.38 -> 5739.216
A21: Fuel Surcharge @ 0.060 /KWH | D21: =H15*0.06 -> 906.192
A22: Grand Total Exc. VAT | D22: =D20+D21 -> 6645.408
A23: WATER
A24: Previous Reading | B24: 309695 | C24: Present Reading | D24: 309910 | E24: Consumption m3 | F24: =D24-B24 -> 215 | G24: Consumption IG | H24: =F24*220 -> 47300
A25: Cost calculation
A26: 0-10000 @ 0.035 / IG | D26: 350
A27: 10000-20000 @ 0.04 / IG | D27: 400
A28: 20000 & above @ 0.046 / IG | D28: =(H24-20000)*0.046 -> 1255.8
A29: Fuel Surcharge @ 0.004 / IG | D29: =H24*0.004 -> 189.2
A30: Sewerage Fees | D30: =H24*0.01 -> 473
A31: Grand Total Exc. VAT | D31: =SUM(D26:H30) -> 2668
A32: LPG Gas
A33: Tank 1 (1% = 48 liters) | C33: Previous Reading % | D33: 80 | E33: Current Reading % | F33: 80 | G33: Consumption Liters | H33: =(D33-F33)*48.8 -> 0
A34: Tank 2 (1% = 48 liters) | C34: Previous Reading % | D34: 33 | E34: Current Reading % | F34: 20 | G34: Consumption Liters | H34: =(D34-F34)*48.8 -> 634.4
A35: Total Cost (@ 1.82 AED/Liter) | H35: =((H34+H33)*1.82)*0.5 -> 577.304
A36: Total Utilities | H36: =H35+D22+D9+D31 -> 15835.688

Sheet December-29
A1: Daily Utilities Consumption
A2: 29.12.2024
A3: District Cooling
A4: Previous Reading MWh | B4: 70721.92 | C4: Current Reading MWh | D4: 70736.54 | E4: Consumption MWH | F4: =D4-B4 -> 14.62 | G4: Consumption RTH | H4: =F4*284.35 -> 4157.197
A5: Cost Calculation
A6: Total Cost (0.568/rth) | D6: =H4*0.568 -> 2361.2879
A7: Total Fuel Surchage Cost (0.075/rth) | D7: =H4*0.075 -> 311.78977
A8: Chilled Water Demand (2,866 AED/Day) | D8: 2866
A9: Grand Total Exc. VAT | D9: =SUM(D6:H8) -> 5539.0777
A10: Electrical
A11: MDB-G1 (39299675-8) | C11: Previous Reading KWH | D11: 43410 | E11: Current Reading KWH | F11: 43416 | G11: Consumption KWH | H11: =F11-D11 -> 6
A12: MDB-G2 (39299676-6) | C12: Previous Reading KWH | D12: 72022 | E12: Current Reading KWH | F12: 72036 | G12: Consumption KWH | H12: =F12-D12 -> 14
A13: MDB-G3 (39299677-4) | C13: Previous Reading KWH | D13: 72780 | E13: Current Reading KWH | F13: 72790 | G13: Consumption KWH | H13: =F13-D13 -> 10
A14: Total Consumption KWH | H14: =SUM(H11:H13) -> 30
A15: Total Consumption * Multiplication Factor (487.20) | H15: =H14*487.2 -> 14616
A16: Cost Calculation
A17: 0-2000 kwh @ 0.230 /KWH | D17: 460
A18: 2000-4000 kwh @ 0.280 /KWH | D18: 560
A19: 4000-6000 kwh @ 0.320 /KWH | D19: 640
A20: 6000 & above @ 0.380 /KWH | D20: =H15*0.38 -> 5554.08
A21: Fuel Surcharge @ 0.060 /KWH | D21: =H15*0.06 -> 876.96
A22: Grand Total Exc. VAT | D22: =D20+D21 -> 6431.04
A23: WATER
A24: Previous Reading | B24: 309481 | C24: Present Reading | D24: 309695 | E24: Consumption m3 | F24: =D24-B24 -> 214 | G24: Consumption IG | H24: =F24*220 -> 47080
A25: Cost calculation
A26: 0-10000 @ 0.035 / IG | D26: 350
A27: 10000-20000 @ 0.04 / IG | D27: 400
A28: 20000 & above @ 0.046 / IG | D28: =(H24-20000)*0.046 -> 1245.68
A29: Fuel Surcharge @ 0.004 / IG | D29: =H24*0.004 -> 188.32
A30: Sewerage Fees | D30: =H24*0.01 -> 470.8
A31: Grand Total Exc. VAT | D31: =SUM(D26:H30) -> 2654.8
A32: LPG Gas
A33: Tank 1 (1% = 48 liters) | C33: Previous Reading % | D33: 80 | E33: Current Reading % | F33: 80 | G33: Consumption Liters | H33: =(D33-F33)*48.8 -> 0
A34: Tank 2 (1% = 48 liters) | C34: Previous Reading % | D34: 45 | E34: Current Reading % | F34: 33 | G34: Consumption Liters | H34: =(D34-F34)*48.8 -> 585.6
A35: Total Cost (@ 1.82 AED/Liter) | H35: =((H34+H33)*1.82)*0.5 -> 532.896
A36: Total Utilities | H36: =H35+D22+D9+D31 -> 15157.814

Sheet December-28
A1: Daily Utilities Consumption
A2: 28.12.2024
A3: District Cooling
A4: Previous Reading MWh | B4: 70708.42 | C4: Current Reading MWh | D4: 70721.92 | E4: Consumption MWH | F4: =D4-B4 -> 13.5 | G4: Consumption RTH | H4: =F4*284.35 -> 3838.725
A5: Cost Calculation
A6: Total Cost (0.568/rth) | D6: =H4*0.568 -> 2180.3958
A7: Total Fuel Surchage Cost (0.075/rth) | D7: =H4*0.075 -> 287.90438
A8: Chilled Water Demand (2,866 AED/Day) | D8: 2866
A9: Grand Total Exc. VAT | D9: =SUM(D6:H8) -> 5334.3002
A10: Electrical
A11: MDB-G1 (39299675-8) | C11: Previous Reading KWH | D11: 43403 | E11: Current Reading KWH | F11: 43410 | G11: Consumption KWH | H11: =F11-D11 -> 7
A12: MDB-G2 (39299676-6) | C12: Previous Reading KWH | D12: 72008 | E12: Current Reading KWH | F12: 72022 | G12: Consumption KWH | H12: =F12-D12 -> 14
A13: MDB-G3 (39299677-4) | C13: Previous Reading KWH | D13: 72770 | E13: Current Reading KWH | F13: 72780 | G13: Consumption KWH | H13: =F13-D13 -> 10
A14: Total Consumption KWH | H14: =SUM(H11:H13) -> 31
A15: Total Consumption * Multiplication Factor (487.20) | H15: =H14*487.2 -> 15103.2
A16: Cost Calculation
A17: 0-2000 kwh @ 0.230 /KWH | D17: 460
A18: 2000-4000 kwh @ 0.280 /KWH | D18: 560
A19: 4000-6000 kwh @ 0.320 /KWH | D19: 640
A20: 6000 & above @ 0.380 /KWH | D20: =H15*0.38 -> 5739.216
A21: Fuel Surcharge @ 0.060 /KWH | D21: =H15*0.06 -> 906.192
A22: Grand Total Exc. VAT | D22: =D20+D21 -> 6645.408
A23: WATER
A24: Previous Reading | B24: 309268 | C24: Present Reading | D24: 309481 | E24: Consumption m3 | F24: =D24-B24 -> 213 | G24: Consumption IG | H24: =F24*220 -> 46860
A25: Cost calculation
A26: 0-10000 @ 0.035 / IG | D26: 350
A27: 10000-20000 @ 0.04 / IG | D27: 400
A28: 20000 & above @ 0.046 / IG | D28: =(H24-20000)*0.046 -> 1235.56
A29: Fuel Surcharge @ 0.004 / IG | D29: =H24*0.004 -> 187.44
A30: Sewerage Fees | D30: =H24*0.01 -> 468.6
A31: Grand Total Exc. VAT | D31: =SUM(D26:H30) -> 2641.6
A32: LPG Gas
A33: Tank 1 (1% = 48 liters) | C33: Previous Reading % | D33: 80 | E33: Current Reading % | F33: 80 | G33: Consumption Liters | H33: =(D33-F33)*48.8 -> 0
A34: Tank 2 (1% = 48 liters) | C34: Previous Reading % | D34: 58 | E34: Current Reading % | F34: 45 | G34: Consumption Liters | H34: =(D34-F34)*48.8 -> 634.4
A35: Total Cost (@ 1.82 AED/Liter) | H35: =((H34+H33)*1.82)*0.5 -> 577.304
A36: Total Utilities | H36: =H35+D22+D9+D31 -> 15198.612

Sheet December-27
A1: Daily Utilities Consumption
A2: 27.12.2024
A3: District Cooling
A4: Previous Reading MWh | B4: 70693.7 | C4: Current Reading MWh | D4: 70708.42 | E4: Consumption MWH | F4: =D4-B4 -> 14.72 | G4: Consumption RTH | H4: =F4*284.35 -> 4185.632
A5: Cost Calculation
A6: Total Cost (0.568/rth) | D6: =H4*0.568 -> 2377.439
A7: Total Fuel Surchage Cost (0.075/rth) | D7: =H4*0.075 -> 313.9224
A8: Chilled Water Demand (2,866 AED/Day) | D8: 2866
A9: Grand Total Exc. VAT | D9: =SUM(D6:H8) -> 5557.3614
A10: Electrical
A11: MDB-G1 (39299675-8) | C11: Previous Reading KWH | D11: 43389 | E11: Current Reading KWH | F11: 43396 | G11: Consumption KWH | H11: =F11-D11 -> 7
A12: MDB-G2 (39299676-6) | C12: Previous Reading KWH | D12: 71981 | E12: Current Reading KWH | F12: 71994 | G12: Consumption KWH | H12: =F12-D12 -> 13
A13: MDB-G3 (39299677-4) | C13: Previous Reading KWH | D13: 72749 | E13: Current Reading KWH | F13: 72760 | G13: Consumption KWH | H13: =F13-D13 -> 11
A14: Total Consumption KWH | H14: =SUM(H11:H13) -> 31
A15: Total Consumption * Multiplication Factor (487.20) | H15: =H14*487.2 -> 15103.2
A16: Cost Calculation
A17: 0-2000 kwh @ 0.230 /KWH | D17: 460
A18: 2000-4000 kwh @ 0.280 /KWH | D18: 560
A19: 4000-6000 kwh @ 0.320 /KWH | D19: 640
A20: 6000 & above @ 0.380 /KWH | D20: =H15*0.38 -> 5739.216
A21: Fuel Surcharge @ 0.060 /KWH | D21: =H15*0.06 -> 906.192
A22: Grand Total Exc. VAT | D22: =D20+D21 -> 6645.408
A23: WATER
A24: Previous Reading | B24: 308839 | C24: Present Reading | D24: 309060 | E24: Consumption m3 | F24: =D24-B24 -> 221 | G24: Consumption IG | H24: =F24*220 -> 48620
A25: Cost calculation
A26: 0-10000 @ 0.035 / IG | D26: 350
A27: 10000-20000 @ 0.04 / IG | D27: 400
A28: 20000 & above @ 0.046 / IG | D28: =(H24-20000)*0.046 -> 1316.52
A29: Fuel Surcharge @ 0.004 / IG | D29: =H24*0.004 -> 194.48
A30: Sewerage Fees | D30: =H24*0.01 -> 486.2
A31: Grand Total Exc. VAT | D31: =SUM(D26:H30) -> 2747.2
A32: LPG Gas
A33: Tank 1 (1% = 48 liters) | C33: Previous Reading % | D33: 18 | E33: Current Reading % | F33: 18 | G33: Consumption Liters | H33: =(D33-F33)*48.8 -> 0
A34: Tank 2 (1% = 48 liters) | C34: Previous Reading % | D34: 80 | E34: Current Reading % | F34: 69 | G34: Consumption Liters | H34: =(D34-F34)*48.8 -> 536.8
A35: Total Cost (@ 1.82 AED/Liter) | H35: =((H34+H33)*1.82)*0.5 -> 488.488
A36: Total Utilities | H36: =H35+D22+D9+D31 -> 15438.457

Sheet December-26
A1: Daily Utilities Consumption
A2: 26.12.2024
A3: District Cooling
A4: Previous Reading MWh | B4: 70678.56 | C4: Current Reading MWh | D4: 70693.7 | E4: Consumption MWH | F4: =D4-B4 -> 15.14 | G4: Consumption RTH | H4: =F4*284.35 -> 4305.059
A5: Cost Calculation
A6: Total Cost (0.568/rth) | D6: =H4*0.568 -> 2445.2735
A7: Total Fuel Surchage Cost (0.075/rth) | D7: =H4*0.075 -> 322.87942
A8: Chilled Water Demand (2,866 AED/Day) | D8: 2866
A9: Grand Total Exc. VAT | D9: =SUM(D6:H8) -> 5634.1529
A10: Electrical
A11: MDB-G1 (39299675-8) | C11: Previous Reading KWH | D11: 43383 | E11: Current Reading KWH | F11: 43389 | G11: Consumption KWH | H11: =F11-D11 -> 6
A12: MDB-G2 (39299676-6) | C12: Previous Reading KWH | D12: 71967 | E12: Current Reading KWH | F12: 71981 | G12: Consumption KWH | H12: =F12-D12 -> 14
A13: MDB-G3 (39299677-4) | C13: Previous Reading KWH | D13: 72738 | E13: Current Reading KWH | F13: 72749 | G13: Consumption KWH | H13: =F13-D13 -> 11
A14: Total Consumption KWH | H14: =SUM(H11:H13) -> 31
A15: Total Consumption * Multiplication Factor (487.20) | H15: =H14*487.2 -> 15103.2
A16: Cost Calculation
A17: 0-2000 kwh @ 0.230 /KWH | D17: 460
A18: 2000-4000 kwh @ 0.280 /KWH | D18: 560
A19: 4000-6000 kwh @ 0.320 /KWH | D19: 640
A20: 6000 & above @ 0.380 /KWH | D20: =H15*0.38 -> 5739.216
A21: Fuel Surcharge @ 0.060 /KWH | D21: =H15*0.06 -> 906.192
A22: Grand Total Exc. VAT | D22: =D20+D21 -> 6645.408
A23: WATER
A24: Previous Reading | B24: 308635 | C24: Present Reading | D24: 308839 | E24: Consumption m3 | F24: =D24-B24 -> 204 | G24: Consumption IG | H24: =F24*220 -> 44880
A25: Cost calculation
A26: 0-10000 @ 0.035 / IG | D26: 350
A27: 10000-20000 @ 0.04 / IG | D27: 400
A28: 20000 & above @ 0.046 / IG | D28: =(H24-20000)*0.046 -> 1144.48
A29: Fuel Surcharge @ 0.004 / IG | D29: =H24*0.004 -> 179.52
A30: Sewerage Fees | D30: =H24*0.01 -> 448.8
A31: Grand Total Exc. VAT | D31: =SUM(D26:H30) -> 2522.8
A32: LPG Gas
A33: Tank 1 (1% = 48 liters) | C33: Previous Reading % | D33: 29 | E33: Current Reading % | F33: 18 | G33: Consumption Liters | H33: =(D33-F33)*48.8 -> 536.8
A34: Tank 2 (1% = 48 liters) | C34: Previous Reading % | D34: 80 | E34: Current Reading % | F34: 80 | G34: Consumption Liters | H34: =(D34-F34)*48.8 -> 0
A35: Total Cost (@ 1.82 AED/Liter) | H35: =((H34+H33)*1.82)*0.5 -> 488.488
A36: Total Utilities | H36: =H35+D22+D9+D31 -> 15290.849

Sheet December-25
A1: Daily Utilities Consumption
A2: 25.12.2024
A3: District Cooling
A4: Previous Reading MWh | B4: 70664.9 | C4: Current Reading MWh | D4: 70678.56 | E4: Consumption MWH | F4: =D4-B4 -> 13.66 | G4: Consumption RTH | H4: =F4*284.35 -> 3884.221
A5: Cost Calculation
A6: Total Cost (0.568/rth) | D6: =H4*0.568 -> 2206.2375
A7: Total Fuel Surchage Cost (0.075/rth) | D7: =H4*0.075 -> 291.31658
A8: Chilled Water Demand (2,866 AED/Day) | D8: 2866
A9: Grand Total Exc. VAT | D9: =SUM(D6:H8) -> 5363.5541
A10: Electrical
A11: MDB-G1 (39299675-8) | C11: Previous Reading KWH | D11: 43376 | E11: Current Reading KWH | F11: 43383 | G11: Consumption KWH | H11: =F11-D11 -> 7
A12: MDB-G2 (39299676-6) | C12: Previous Reading KWH | D12: 71954 | E12: Current Reading KWH | F12: 71967 | G12: Consumption KWH | H12: =F12-D12 -> 13
A13: MDB-G3 (39299677-4) | C13: Previous Reading KWH | D13: 72728 | E13: Current Reading KWH | F13: 72738 | G13: Consumption KWH | H13: =F13-D13 -> 10
A14: Total Consumption KWH | H14: =SUM(H11:H13) -> 30
A15: Total Consumption * Multiplication Factor (487.20) | H15: =H14*487.2 -> 14616
A16: Cost Calculation
A17: 0-2000 kwh @ 0.230 /KWH | D17: 460
A18: 2000-4000 kwh @ 0.280 /KWH | D18: 560
A19: 4000-6000 kwh @ 0.320 /KWH | D19: 640
A20: 6000 & above @ 0.380 /KWH | D20: =H15*0.38 -> 5554.08
A21: Fuel Surcharge @ 0.060 /KWH | D21: =H15*0.06 -> 876.96
A22: Grand Total Exc. VAT | D22: =D20+D21 -> 6431.04
A23: WATER
A24: Previous Reading | B24: 308410 | C24: Present Reading | D24: 308635 | E24: Consumption m3 | F24: =D24-B24 -> 225 | G24: Consumption IG | H24: =F24*220 -> 49500
A25: Cost calculation
A26: 0-10000 @ 0.035 / IG | D26: 350
A27: 10000-20000 @ 0.04 / IG | D27: 400
A28: 20000 & above @ 0.046 / IG | D28: =(H24-20000)*0.046 -> 1357
A29: Fuel Surcharge @ 0.004 / IG | D29: =H24*0.004 -> 198
A30: Sewerage Fees | D30: =H24*0.01 -> 495
A31: Grand Total Exc. VAT | D31: =SUM(D26:H30) -> 2800
A32: LPG Gas
A33: Tank 1 (1% = 48 liters) | C33: Previous Reading % | D33: 40 | E33: Current Reading % | F33: 29 | G33: Consumption Liters | H33: =(D33-F33)*48.8 -> 536.8
A34: Tank 2 (1% = 48 liters) | C34: Previous Reading % | D34: 80 | E34: Current Reading % | F34: 80 | G34: Consumption Liters | H34: =(D34-F34)*48.8 -> 0
A35: Total Cost (@ 1.82 AED/Liter) | H35: =((H34+H33)*1.82)*0.5 -> 488.488
A36: Total Utilities | H36: =H35+D22+D9+D31 -> 15083.082

Sheet December-24
A1: Daily Utilities Consumption
A2: 24.12.2024
A3: District Cooling
A4: Previous Reading MWh | B4: 70652.04 | C4: Current Reading MWh | D4: 70664.9 | E4: Consumption MWH | F4: =D4-B4 -> 12.86 | G4: Consumption RTH | H4: =F4*284.35 -> 3656.741
A5: Cost Calculation
A6: Total Cost (0.568/rth) | D6: =H4*0.568 -> 2077.0289
A7: Total Fuel Surchage Cost (0.075/rth) | D7: =H4*0.075 -> 274.25558
A8: Chilled Water Demand (2,866 AED/Day) | D8: 2866
A9: Grand Total Exc. VAT | D9: =SUM(D6:H8) -> 5217.2845
A10: Electrical
A11: MDB-G1 (39299675-8) | C11: Previous Reading KWH | D11: 43369 | E11: Current Reading KWH | F11: 43376 | G11: Consumption KWH | H11: =F11-D11 -> 7
A12: MDB-G2 (39299676-6) | C12: Previous Reading KWH | D12: 71940 | E12: Current Reading KWH | F12: 71954 | G12: Consumption KWH | H12: =F12-D12 -> 14
A13: MDB-G3 (39299677-4) | C13: Previous Reading KWH | D13: 72717 | E13: Current Reading KWH | F13: 72728 | G13: Consumption KWH | H13: =F13-D13 -> 11
A14: Total Consumption KWH | H14: =SUM(H11:H13) -> 32
A15: Total Consumption * Multiplication Factor (487.20) | H15: =H14*487.2 -> 15590.4
A16: Cost Calculation
A17: 0-2000 kwh @ 0.230 /KWH | D17: 460
A18: 2000-4000 kwh @ 0.280 /KWH | D18: 560
A19: 4000-6000 kwh @ 0.320 /KWH | D19: 640
A20: 6000 & above @ 0.380 /KWH | D20: =H15*0.38 -> 5924.352
A21: Fuel Surcharge @ 0.060 /KWH | D21: =H15*0.06 -> 935.424
A22: Grand Total Exc. VAT | D22: =D20+D21 -> 6859.776
A23: WATER
A24: Previous Reading | B24: 308210 | C24: Present Reading | D24: 308410 | E24: Consumption m3 | F24: =D24-B24 -> 200 | G24: Consumption IG | H24: =F24*220 -> 44000
A25: Cost calculation
A26: 0-10000 @ 0.035 / IG | D26: 350
A27: 10000-20000 @ 0.04 / IG | D27: 400
A28: 20000 & above @ 0.046 / IG | D28: =(H24-20000)*0.046 -> 1104
A29: Fuel Surcharge @ 0.004 / IG | D29: =H24*0.004 -> 176
A30: Sewerage Fees | D30: =H24*0.01 -> 440
A31: Grand Total Exc. VAT | D31: =SUM(D26:H30) -> 2470
A32: LPG Gas
A33: Tank 1 (1% = 48 liters) | C33: Previous Reading % | D33: 54 | E33: Current Reading % | F33: 40 | G33: Consumption Liters | H33: =(D33-F33)*48.8 -> 683.2
A34: Tank 2 (1% = 48 liters) | C34: Previous Reading % | D34: 80 | E34: Current Reading % | F34: 80 | G34: Consumption Liters | H34: =(D34-F34)*48.8 -> 0
A35: Total Cost (@ 1.82 AED/Liter) | H35: =((H34+H33)*1.82)*0.5 -> 621.712
A36: Total Utilities | H36: =H35+D22+D9+D31 -> 15168.772

Sheet December-23 
A1: Daily Utilities Consumption
A2: 23.12.2024
A3: District Cooling
A4: Previous Reading MWh | B4: 70640.18 | C4: Current Reading MWh | D4: 70652.04 | E4: Consumption MWH | F4: =D4-B4 -> 11.86 | G4: Consumption RTH | H4: =F4*284.35 -> 3372.391
A5: Cost Calculation
A6: Total Cost (0.568/rth) | D6: =H4*0.568 -> 1915.5181
A7: Total Fuel Surchage Cost (0.075/rth) | D7: =H4*0.075 -> 252.92933
A8: Chilled Water Demand (2,866 AED/Day) | D8: 2866
A9: Grand Total Exc. VAT | D9: =SUM(D6:H8) -> 5034.4474
A10: Electrical
A11: MDB-G1 (39299675-8) | C11: Previous Reading KWH | D11: 43369 | E11: Current Reading KWH | F11: 43376 | G11: Consumption KWH | H11: =F11-D11 -> 7
A12: MDB-G2 (39299676-6) | C12: Previous Reading KWH | D12: 71940 | E12: Current Reading KWH | F12: 71954 | G12: Consumption KWH | H12: =F12-D12 -> 14
A13: MDB-G3 (39299677-4) | C13: Previous Reading KWH | D13: 72717 | E13: Current Reading KWH | F13: 72728 | G13: Consumption KWH | H13: =F13-D13 -> 11
A14: Total Consumption KWH | H14: =SUM(H11:H13) -> 32
A15: Total Consumption * Multiplication Factor (487.20) | H15: =H14*487.2 -> 15590.4
A16: Cost Calculation
A17: 0-2000 kwh @ 0.230 /KWH | D17: 460
A18: 2000-4000 kwh @ 0.280 /KWH | D18: 560
A19: 4000-6000 kwh @ 0.320 /KWH | D19: 640
A20: 6000 & above @ 0.380 /KWH | D20: =H15*0.38 -> 5924.352
A21: Fuel Surcharge @ 0.060 /KWH | D21: =H15*0.06 -> 935.424
A22: Grand Total Exc. VAT | D22: =D20+D21 -> 6859.776
A23: WATER
A24: Previous Reading | B24: 308210 | C24: Present Reading | D24: 308410 | E24: Consumption m3 | F24: =D24-B24 -> 200 | G24: Consumption IG | H24: =F24*220 -> 44000
A25: Cost calculation
A26: 0-10000 @ 0.035 / IG | D26: 350
A27: 10000-20000 @ 0.04 / IG | D27: 400
A28: 20000 & above @ 0.046 / IG | D28: =(H24-20000)*0.046 -> 1104
A29: Fuel Surcharge @ 0.004 / IG | D29: =H24*0.004 -> 176
A30: Sewerage Fees | D30: =H24*0.01 -> 440
A31: Grand Total Exc. VAT | D31: =SUM(D26:H30) -> 2470
A32: LPG Gas
A33: Tank 1 (1% = 48 liters) | C33: Previous Reading % | D33: 54 | E33: Current Reading % | F33: 40 | G33: Consumption Liters | H33: =(D33-F33)*48.8 -> 683.2
A34: Tank 2 (1% = 48 liters) | C34: Previous Reading % | D34: 80 | E34: Current Reading % | F34: 80 | G34: Consumption Liters | H34: =(D34-F34)*48.8 -> 0
A35: Total Cost (@ 1.82 AED/Liter) | H35: =((H34+H33)*1.82)*0.5 -> 621.712
A36: Total Utilities | H36: =H35+D22+D9+D31 -> 14985.935

Sheet December-22
A1: Daily Utilities Consumption
A2: 22.12.2024
A3: District Cooling
A4: Previous Reading MWh | B4: 70628.45 | C4: Current Reading MWh | D4: 70640.18 | E4: Consumption MWH | F4: =D4-B4 -> 11.73 | G4: Consumption RTH | H4: =F4*284.35 -> 3335.4255
A5: Cost Calculation
A6: Total Cost (0.568/rth) | D6: =H4*0.568 -> 1894.5217
A7: Total Fuel Surchage Cost (0.075/rth) | D7: =H4*0.075 -> 250.15691
A8: Chilled Water Demand (2,866 AED/Day) | D8: 2866
A9: Grand Total Exc. VAT | D9: =SUM(D6:H8) -> 5010.6786
A10: Electrical
A11: MDB-G1 (39299675-8) | C11: Previous Reading KWH | D11: 43362 | E11: Current Reading KWH | F11: 43369 | G11: Consumption KWH | H11: =F11-D11 -> 7
A12: MDB-G2 (39299676-6) | C12: Previous Reading KWH | D12: 71926 | E12: Current Reading KWH | F12: 71940 | G12: Consumption KWH | H12: =F12-D12 -> 14
A13: MDB-G3 (39299677-4) | C13: Previous Reading KWH | D13: 72706 | E13: Current Reading KWH | F13: 72717 | G13: Consumption KWH | H13: =F13-D13 -> 11
A14: Total Consumption KWH | H14: =SUM(H11:H13) -> 32
A15: Total Consumption * Multiplication Factor (487.20) | H15: =H14*487.2 -> 15590.4
A16: Cost Calculation
A17: 0-2000 kwh @ 0.230 /KWH | D17: 460
A18: 2000-4000 kwh @ 0.280 /KWH | D18: 560
A19: 4000-6000 kwh @ 0.320 /KWH | D19: 640
A20: 6000 & above @ 0.380 /KWH | D20: =H15*0.38 -> 5924.352
A21: Fuel Surcharge @ 0.060 /KWH | D21: =H15*0.06 -> 935.424
A22: Grand Total Exc. VAT | D22: =D20+D21 -> 6859.776
A23: WATER
A24: Previous Reading | B24: 308020 | C24: Present Reading | D24: 308210 | E24: Consumption m3 | F24: =D24-B24 -> 190 | G24: Consumption IG | H24: =F24*220 -> 41800
A25: Cost calculation
A26: 0-10000 @ 0.035 / IG | D26: 350
A27: 10000-20000 @ 0.04 / IG | D27: 400
A28: 20000 & above @ 0.046 / IG | D28: =(H24-20000)*0.046 -> 1002.8
A29: Fuel Surcharge @ 0.004 / IG | D29: =H24*0.004 -> 167.2
A30: Sewerage Fees | D30: =H24*0.01 -> 418
A31: Grand Total Exc. VAT | D31: =SUM(D26:H30) -> 2338
A32: LPG Gas
A33: Tank 1 (1% = 48 liters) | C33: Previous Reading % | D33: 64 | E33: Current Reading % | F33: 54 | G33: Consumption Liters | H33: =(D33-F33)*48.8 -> 488
A34: Tank 2 (1% = 48 liters) | C34: Previous Reading % | D34: 80 | E34: Current Reading % | F34: 80 | G34: Consumption Liters | H34: =(D34-F34)*48.8 -> 0
A35: Total Cost (@ 1.82 AED/Liter) | H35: =((H34+H33)*1.82)*0.5 -> 444.08
A36: Total Utilities | H36: =H35+D22+D9+D31 -> 14652.535

Sheet December-21
A1: Daily Utilities Consumption
A2: 21.12.2024
A3: District Cooling
A4: Previous Reading MWh | B4: 70616.23 | C4: Current Reading MWh | D4: 70628.45 | E4: Consumption MWH | F4: =D4-B4 -> 12.22 | G4: Consumption RTH | H4: =F4*284.35 -> 3474.757
A5: Cost Calculation
A6: Total Cost (0.568/rth) | D6: =H4*0.568 -> 1973.662
A7: Total Fuel Surchage Cost (0.075/rth) | D7: =H4*0.075 -> 260.60678
A8: Chilled Water Demand (2,866 AED/Day) | D8: 2866
A9: Grand Total Exc. VAT | D9: =SUM(D6:H8) -> 5100.2688
A10: Electrical
A11: MDB-G1 (39299675-8) | C11: Previous Reading KWH | D11: 43355 | E11: Current Reading KWH | F11: 43362 | G11: Consumption KWH | H11: =F11-D11 -> 7
A12: MDB-G2 (39299676-6) | C12: Previous Reading KWH | D12: 71913 | E12: Current Reading KWH | F12: 71926 | G12: Consumption KWH | H12: =F12-D12 -> 13
A13: MDB-G3 (39299677-4) | C13: Previous Reading KWH | D13: 72694 | E13: Current Reading KWH | F13: 72706 | G13: Consumption KWH | H13: =F13-D13 -> 12
A14: Total Consumption KWH | H14: =SUM(H11:H13) -> 32
A15: Total Consumption * Multiplication Factor (487.20) | H15: =H14*487.2 -> 15590.4
A16: Cost Calculation
A17: 0-2000 kwh @ 0.230 /KWH | D17: 460
A18: 2000-4000 kwh @ 0.280 /KWH | D18: 560
A19: 4000-6000 kwh @ 0.320 /KWH | D19: 640
A20: 6000 & above @ 0.380 /KWH | D20: =H15*0.38 -> 5924.352
A21: Fuel Surcharge @ 0.060 /KWH | D21: =H15*0.06 -> 935.424
A22: Grand Total Exc. VAT | D22: =D20+D21 -> 6859.776
A23: WATER
A24: Previous Reading | B24: 307818 | C24: Present Reading | D24: 308020 | E24: Consumption m3 | F24: =D24-B24 -> 202 | G24: Consumption IG | H24: =F24*220 -> 44440
A25: Cost calculation
A26: 0-10000 @ 0.035 / IG | D26: 350
A27: 10000-20000 @ 0.04 / IG | D27: 400
A28: 20000 & above @ 0.046 / IG | D28: =(H24-20000)*0.046 -> 1124.24
A29: Fuel Surcharge @ 0.004 / IG | D29: =H24*0.004 -> 177.76
A30: Sewerage Fees | D30: =H24*0.01 -> 444.4
A31: Grand Total Exc. VAT | D31: =SUM(D26:H30) -> 2496.4
A32: LPG Gas
A33: Tank 1 (1% = 48 liters) | C33: Previous Reading % | D33: 74 | E33: Current Reading % | F33: 64 | G33: Consumption Liters | H33: =(D33-F33)*48.8 -> 488
A34: Tank 2 (1% = 48 liters) | C34: Previous Reading % | D34: 80 | E34: Current Reading % | F34: 80 | G34: Consumption Liters | H34: =(D34-F34)*48.8 -> 0
A35: Total Cost (@ 1.82 AED/Liter) | H35: =((H34+H33)*1.82)*0.5 -> 444.08
A36: Total Utilities | H36: =H35+D22+D9+D31 -> 14900.525

Sheet December-20
A1: Daily Utilities Consumption
A2: 20.12.2024
A3: District Cooling
A4: Previous Reading MWh | B4: 70602.5 | C4: Current Reading MWh | D4: 70616.23 | E4: Consumption MWH | F4: =D4-B4 -> 13.73 | G4: Consumption RTH | H4: =F4*284.35 -> 3904.1255
A5: Cost Calculation
A6: Total Cost (0.568/rth) | D6: =H4*0.568 -> 2217.5433
A7: Total Fuel Surchage Cost (0.075/rth) | D7: =H4*0.075 -> 292.80941
A8: Chilled Water Demand (2,866 AED/Day) | D8: 2866
A9: Grand Total Exc. VAT | D9: =SUM(D6:H8) -> 5376.3527
A10: Electrical
A11: MDB-G1 (39299675-8) | C11: Previous Reading KWH | D11: 43348 | E11: Current Reading KWH | F11: 43355 | G11: Consumption KWH | H11: =F11-D11 -> 7
A12: MDB-G2 (39299676-6) | C12: Previous Reading KWH | D12: 71900 | E12: Current Reading KWH | F12: 71913 | G12: Consumption KWH | H12: =F12-D12 -> 13
A13: MDB-G3 (39299677-4) | C13: Previous Reading KWH | D13: 72682 | E13: Current Reading KWH | F13: 72694 | G13: Consumption KWH | H13: =F13-D13 -> 12
A14: Total Consumption KWH | H14: =SUM(H11:H13) -> 32
A15: Total Consumption * Multiplication Factor (487.20) | H15: =H14*487.2 -> 15590.4
A16: Cost Calculation
A17: 0-2000 kwh @ 0.230 /KWH | D17: 460
A18: 2000-4000 kwh @ 0.280 /KWH | D18: 560
A19: 4000-6000 kwh @ 0.320 /KWH | D19: 640
A20: 6000 & above @ 0.380 /KWH | D20: =H15*0.38 -> 5924.352
A21: Fuel Surcharge @ 0.060 /KWH | D21: =H15*0.06 -> 935.424
A22: Grand Total Exc. VAT | D22: =D20+D21 -> 6859.776
A23: WATER
A24: Previous Reading | B24: 307632 | C24: Present Reading | D24: 307818 | E24: Consumption m3 | F24: =D24-B24 -> 186 | G24: Consumption IG | H24: =F24*220 -> 40920
A25: Cost calculation
A26: 0-10000 @ 0.035 / IG | D26: 350
A27: 10000-20000 @ 0.04 / IG | D27: 400
A28: 20000 & above @ 0.046 / IG | D28: =(H24-20000)*0.046 -> 962.32
A29: Fuel Surcharge @ 0.004 / IG | D29: =H24*0.004 -> 163.68
A30: Sewerage Fees | D30: =H24*0.01 -> 409.2
A31: Grand Total Exc. VAT | D31: =SUM(D26:H30) -> 2285.2
A32: LPG Gas
A33: Tank 1 (1% = 48 liters) | C33: Previous Reading % | D33: 84 | E33: Current Reading % | F33: 74 | G33: Consumption Liters | H33: =(D33-F33)*48.8 -> 488
A34: Tank 2 (1% = 48 liters) | C34: Previous Reading % | D34: 80 | E34: Current Reading % | F34: 80 | G34: Consumption Liters | H34: =(D34-F34)*48.8 -> 0
A35: Total Cost (@ 1.82 AED/Liter) | H35: =((H34+H33)*1.82)*0.5 -> 444.08
A36: Total Utilities | H36: =H35+D22+D9+D31 -> 14965.409

Sheet December-19
A1: Daily Utilities Consumption
A2: 19.12.2024
A3: District Cooling
A4: Previous Reading MWh | B4: 70588.24 | C4: Current Reading MWh | D4: 70602.5 | E4: Consumption MWH | F4: =D4-B4 -> 14.26 | G4: Consumption RTH | H4: =F4*284.35 -> 4054.831
A5: Cost Calculation
A6: Total Cost (0.568/rth) | D6: =H4*0.568 -> 2303.144
A7: Total Fuel Surchage Cost (0.075/rth) | D7: =H4*0.075 -> 304.11232
A8: Chilled Water Demand (2,866 AED/Day) | D8: 2866
A9: Grand Total Exc. VAT | D9: =SUM(D6:H8) -> 5473.2563
A10: Electrical
A11: MDB-G1 (39299675-8) | C11: Previous Reading KWH | D11: 43341 | E11: Current Reading KWH | F11: 43348 | G11: Consumption KWH | H11: =F11-D11 -> 7
A12: MDB-G2 (39299676-6) | C12: Previous Reading KWH | D12: 71887 | E12: Current Reading KWH | F12: 71900 | G12: Consumption KWH | H12: =F12-D12 -> 13
A13: MDB-G3 (39299677-4) | C13: Previous Reading KWH | D13: 72671 | E13: Current Reading KWH | F13: 72682 | G13: Consumption KWH | H13: =F13-D13 -> 11
A14: Total Consumption KWH | H14: =SUM(H11:H13) -> 31
A15: Total Consumption * Multiplication Factor (487.20) | H15: =H14*487.2 -> 15103.2
A16: Cost Calculation
A17: 0-2000 kwh @ 0.230 /KWH | D17: 460
A18: 2000-4000 kwh @ 0.280 /KWH | D18: 560
A19: 4000-6000 kwh @ 0.320 /KWH | D19: 640
A20: 6000 & above @ 0.380 /KWH | D20: =H15*0.38 -> 5739.216
A21: Fuel Surcharge @ 0.060 /KWH | D21: =H15*0.06 -> 906.192
A22: Grand Total Exc. VAT | D22: =D20+D21 -> 6645.408
A23: WATER
A24: Previous Reading | B24: 307459 | C24: Present Reading | D24: 307632 | E24: Consumption m3 | F24: =D24-B24 -> 173 | G24: Consumption IG | H24: =F24*220 -> 38060
A25: Cost calculation
A26: 0-10000 @ 0.035 / IG | D26: 350
A27: 10000-20000 @ 0.04 / IG | D27: 400
A28: 20000 & above @ 0.046 / IG | D28: =(H24-20000)*0.046 -> 830.76
A29: Fuel Surcharge @ 0.004 / IG | D29: =H24*0.004 -> 152.24
A30: Sewerage Fees | D30: =H24*0.01 -> 380.6
A31: Grand Total Exc. VAT | D31: =SUM(D26:H30) -> 2113.6
A32: LPG Gas
A33: Tank 1 (1% = 48 liters) | C33: Previous Reading % | D33: 70 | E33: Current Reading % | F33: 60 | G33: Consumption Liters | H33: =(D33-F33)*48.8 -> 488
A34: Tank 2 (1% = 48 liters) | C34: Previous Reading % | D34: 20 | E34: Current Reading % | F34: 20 | G34: Consumption Liters | H34: =(D34-F34)*48.8 -> 0
A35: Total Cost (@ 1.82 AED/Liter) | H35: =((H34+H33)*1.82)*0.5 -> 444.08
A36: Total Utilities | H36: =H35+D22+D9+D31 -> 14676.344

Sheet December-18
A1: Daily Utilities Consumption
A2: 18.12.2024
A3: District Cooling
A4: Previous Reading MWh | B4: 70574.29 | C4: Current Reading MWh | D4: 70588.24 | E4: Consumption MWH | F4: =D4-B4 -> 13.95 | G4: Consumption RTH | H4: =F4*284.35 -> 3966.6825
A5: Cost Calculation
A6: Total Cost (0.568/rth) | D6: =H4*0.568 -> 2253.0757
A7: Total Fuel Surchage Cost (0.075/rth) | D7: =H4*0.075 -> 297.50119
A8: Chilled Water Demand (2,866 AED/Day) | D8: 2866
A9: Grand Total Exc. VAT | D9: =SUM(D6:H8) -> 5416.5768
A10: Electrical
A11: MDB-G1 (39299675-8) | C11: Previous Reading KWH | D11: 43334 | E11: Current Reading KWH | F11: 43341 | G11: Consumption KWH | H11: =F11-D11 -> 7
A12: MDB-G2 (39299676-6) | C12: Previous Reading KWH | D12: 71875 | E12: Current Reading KWH | F12: 71887 | G12: Consumption KWH | H12: =F12-D12 -> 12
A13: MDB-G3 (39299677-4) | C13: Previous Reading KWH | D13: 72660 | E13: Current Reading KWH | F13: 72671 | G13: Consumption KWH | H13: =F13-D13 -> 11
A14: Total Consumption KWH | H14: =SUM(H11:H13) -> 30
A15: Total Consumption * Multiplication Factor (487.20) | H15: =H14*487.2 -> 14616
A16: Cost Calculation
A17: 0-2000 kwh @ 0.230 /KWH | D17: 460
A18: 2000-4000 kwh @ 0.280 /KWH | D18: 560
A19: 4000-6000 kwh @ 0.320 /KWH | D19: 640
A20: 6000 & above @ 0.380 /KWH | D20: =H15*0.38 -> 5554.08
A21: Fuel Surcharge @ 0.060 /KWH | D21: =H15*0.06 -> 876.96
A22: Grand Total Exc. VAT | D22: =D20+D21 -> 6431.04
A23: WATER
A24: Previous Reading | B24: 307286 | C24: Present Reading | D24: 307459 | E24: Consumption m3 | F24: =D24-B24 -> 173 | G24: Consumption IG | H24: =F24*220 -> 38060
A25: Cost calculation
A26: 0-10000 @ 0.035 / IG | D26: 350
A27: 10000-20000 @ 0.04 / IG | D27: 400
A28: 20000 & above @ 0.046 / IG | D28: =(H24-20000)*0.046 -> 830.76
A29: Fuel Surcharge @ 0.004 / IG | D29: =H24*0.004 -> 152.24
A30: Sewerage Fees | D30: =H24*0.01 -> 380.6
A31: Grand Total Exc. VAT | D31: =SUM(D26:H30) -> 2113.6
A32: LPG Gas
A33: Tank 1 (1% = 48 liters) | C33: Previous Reading % | D33: 80 | E33: Current Reading % | F33: 70 | G33: Consumption Liters | H33: =(D33-F33)*48.8 -> 488
A34: Tank 2 (1% = 48 liters) | C34: Previous Reading % | D34: 20 | E34: Current Reading % | F34: 20 | G34: Consumption Liters | H34: =(D34-F34)*48.8 -> 0
A35: Total Cost (@ 1.82 AED/Liter) | H35: =((H34+H33)*1.82)*0.5 -> 444.08
A36: Total Utilities | H36: =H35+D22+D9+D31 -> 14405.297

Sheet December-17
A1: Daily Utilities Consumption
A2: 17.12.2024
A3: District Cooling
A4: Previous Reading MWh | B4: 70559.47 | C4: Current Reading MWh | D4: 70574.29 | E4: Consumption MWH | F4: =D4-B4 -> 14.82 | G4: Consumption RTH | H4: =F4*284.35 -> 4214.067
A5: Cost Calculation
A6: Total Cost (0.568/rth) | D6: =H4*0.568 -> 2393.5901
A7: Total Fuel Surchage Cost (0.075/rth) | D7: =H4*0.075 -> 316.05502
A8: Chilled Water Demand (2,866 AED/Day) | D8: 2866
A9: Grand Total Exc. VAT | D9: =SUM(D6:H8) -> 5575.6451
A10: Electrical
A11: MDB-G1 (39299675-8) | C11: Previous Reading KWH | D11: 43328 | E11: Current Reading KWH | F11: 43334 | G11: Consumption KWH | H11: =F11-D11 -> 6
A12: MDB-G2 (39299676-6) | C12: Previous Reading KWH | D12: 71862 | E12: Current Reading KWH | F12: 71875 | G12: Consumption KWH | H12: =F12-D12 -> 13
A13: MDB-G3 (39299677-4) | C13: Previous Reading KWH | D13: 72649 | E13: Current Reading KWH | F13: 72660 | G13: Consumption KWH | H13: =F13-D13 -> 11
A14: Total Consumption KWH | H14: =SUM(H11:H13) -> 30
A15: Total Consumption * Multiplication Factor (487.20) | H15: =H14*487.2 -> 14616
A16: Cost Calculation
A17: 0-2000 kwh @ 0.230 /KWH | D17: 460
A18: 2000-4000 kwh @ 0.280 /KWH | D18: 560
A19: 4000-6000 kwh @ 0.320 /KWH | D19: 640
A20: 6000 & above @ 0.380 /KWH | D20: =H15*0.38 -> 5554.08
A21: Fuel Surcharge @ 0.060 /KWH | D21: =H15*0.06 -> 876.96
A22: Grand Total Exc. VAT | D22: =D20+D21 -> 6431.04
A23: WATER
A24: Previous Reading | B24: 307102 | C24: Present Reading | D24: 307286 | E24: Consumption m3 | F24: =D24-B24 -> 184 | G24: Consumption IG | H24: =F24*220 -> 40480
A25: Cost calculation
A26: 0-10000 @ 0.035 / IG | D26: 350
A27: 10000-20000 @ 0.04 / IG | D27: 400
A28: 20000 & above @ 0.046 / IG | D28: =(H24-20000)*0.046 -> 942.08
A29: Fuel Surcharge @ 0.004 / IG | D29: =H24*0.004 -> 161.92
A30: Sewerage Fees | D30: =H24*0.01 -> 404.8
A31: Grand Total Exc. VAT | D31: =SUM(D26:H30) -> 2258.8
A32: LPG Gas
A33: Tank 1 (1% = 48 liters) | C33: Previous Reading % | D33: 80 | E33: Current Reading % | F33: 80 | G33: Consumption Liters | H33: =(D33-F33)*48.8 -> 0
A34: Tank 2 (1% = 48 liters) | C34: Previous Reading % | D34: 34 | E34: Current Reading % | F34: 20 | G34: Consumption Liters | H34: =(D34-F34)*48.8 -> 683.2
A35: Total Cost (@ 1.82 AED/Liter) | H35: =((H34+H33)*1.82)*0.5 -> 621.712
A36: Total Utilities | H36: =H35+D22+D9+D31 -> 14887.197

Sheet December-16
A1: Daily Utilities Consumption
A2: 16.12.2024
A3: District Cooling
A4: Previous Reading MWh | B4: 70544.35 | C4: Current Reading MWh | D4: 70559.47 | E4: Consumption MWH | F4: =D4-B4 -> 15.12 | G4: Consumption RTH | H4: =F4*284.35 -> 4299.372
A5: Cost Calculation
A6: Total Cost (0.568/rth) | D6: =H4*0.568 -> 2442.0433
A7: Total Fuel Surchage Cost (0.075/rth) | D7: =H4*0.075 -> 322.4529
A8: Chilled Water Demand (2,866 AED/Day) | D8: 2866
A9: Grand Total Exc. VAT | D9: =SUM(D6:H8) -> 5630.4962
A10: Electrical
A11: MDB-G1 (39299675-8) | C11: Previous Reading KWH | D11: 43321 | E11: Current Reading KWH | F11: 43328 | G11: Consumption KWH | H11: =F11-D11 -> 7
A12: MDB-G2 (39299676-6) | C12: Previous Reading KWH | D12: 71849 | E12: Current Reading KWH | F12: 71862 | G12: Consumption KWH | H12: =F12-D12 -> 13
A13: MDB-G3 (39299677-4) | C13: Previous Reading KWH | D13: 72638 | E13: Current Reading KWH | F13: 72649 | G13: Consumption KWH | H13: =F13-D13 -> 11
A14: Total Consumption KWH | H14: =SUM(H11:H13) -> 31
A15: Total Consumption * Multiplication Factor (487.20) | H15: =H14*487.2 -> 15103.2
A16: Cost Calculation
A17: 0-2000 kwh @ 0.230 /KWH | D17: 460
A18: 2000-4000 kwh @ 0.280 /KWH | D18: 560
A19: 4000-6000 kwh @ 0.320 /KWH | D19: 640
A20: 6000 & above @ 0.380 /KWH | D20: =H15*0.38 -> 5739.216
A21: Fuel Surcharge @ 0.060 /KWH | D21: =H15*0.06 -> 906.192
A22: Grand Total Exc. VAT | D22: =D20+D21 -> 6645.408
A23: WATER
A24: Previous Reading | B24: 306924 | C24: Present Reading | D24: 307102 | E24: Consumption m3 | F24: =D24-B24 -> 178 | G24: Consumption IG | H24: =F24*220 -> 39160
A25: Cost calculation
A26: 0-10000 @ 0.035 / IG | D26: 350
A27: 10000-20000 @ 0.04 / IG | D27: 400
A28: 20000 & above @ 0.046 / IG | D28: =(H24-20000)*0.046 -> 881.36
A29: Fuel Surcharge @ 0.004 / IG | D29: =H24*0.004 -> 156.64
A30: Sewerage Fees | D30: =H24*0.01 -> 391.6
A31: Grand Total Exc. VAT | D31: =SUM(D26:H30) -> 2179.6
A32: LPG Gas
A33: Tank 1 (1% = 48 liters) | C33: Previous Reading % | D33: 80 | E33: Current Reading % | F33: 80 | G33: Consumption Liters | H33: =(D33-F33)*48.8 -> 0
A34: Tank 2 (1% = 48 liters) | C34: Previous Reading % | D34: 45 | E34: Current Reading % | F34: 34 | G34: Consumption Liters | H34: =(D34-F34)*48.8 -> 536.8
A35: Total Cost (@ 1.82 AED/Liter) | H35: =((H34+H33)*1.82)*0.5 -> 488.488
A36: Total Utilities | H36: =H35+D22+D9+D31 -> 14943.992

Sheet December-15
A1: Daily Utilities Consumption
A2: 15.12.2024
A3: District Cooling
A4: Previous Reading MWh | B4: 70529.24 | C4: Current Reading MWh | D4: 70544.35 | E4: Consumption MWH | F4: =D4-B4 -> 15.11 | G4: Consumption RTH | H4: =F4*284.35 -> 4296.5285
A5: Cost Calculation
A6: Total Cost (0.568/rth) | D6: =H4*0.568 -> 2440.4282
A7: Total Fuel Surchage Cost (0.075/rth) | D7: =H4*0.075 -> 322.23964
A8: Chilled Water Demand (2,866 AED/Day) | D8: 2866
A9: Grand Total Exc. VAT | D9: =SUM(D6:H8) -> 5628.6678
A10: Electrical
A11: MDB-G1 (39299675-8) | C11: Previous Reading KWH | D11: 43315 | E11: Current Reading KWH | F11: 43321 | G11: Consumption KWH | H11: =F11-D11 -> 6
A12: MDB-G2 (39299676-6) | C12: Previous Reading KWH | D12: 71837 | E12: Current Reading KWH | F12: 71849 | G12: Consumption KWH | H12: =F12-D12 -> 12
A13: MDB-G3 (39299677-4) | C13: Previous Reading KWH | D13: 72627 | E13: Current Reading KWH | F13: 72638 | G13: Consumption KWH | H13: =F13-D13 -> 11
A14: Total Consumption KWH | H14: =SUM(H11:H13) -> 29
A15: Total Consumption * Multiplication Factor (487.20) | H15: =H14*487.2 -> 14128.8
A16: Cost Calculation
A17: 0-2000 kwh @ 0.230 /KWH | D17: 460
A18: 2000-4000 kwh @ 0.280 /KWH | D18: 560
A19: 4000-6000 kwh @ 0.320 /KWH | D19: 640
A20: 6000 & above @ 0.380 /KWH | D20: =H15*0.38 -> 5368.944
A21: Fuel Surcharge @ 0.060 /KWH | D21: =H15*0.06 -> 847.728
A22: Grand Total Exc. VAT | D22: =D20+D21 -> 6216.672
A23: WATER
A24: Previous Reading | B24: 306660 | C24: Present Reading | D24: 306924 | E24: Consumption m3 | F24: =D24-B24 -> 264 | G24: Consumption IG | H24: =F24*220 -> 58080
A25: Cost calculation
A26: 0-10000 @ 0.035 / IG | D26: 350
A27: 10000-20000 @ 0.04 / IG | D27: 400
A28: 20000 & above @ 0.046 / IG | D28: =(H24-20000)*0.046 -> 1751.68
A29: Fuel Surcharge @ 0.004 / IG | D29: =H24*0.004 -> 232.32
A30: Sewerage Fees | D30: =H24*0.01 -> 580.8
A31: Grand Total Exc. VAT | D31: =SUM(D26:H30) -> 3314.8
A32: LPG Gas
A33: Tank 1 (1% = 48 liters) | C33: Previous Reading % | D33: 80 | E33: Current Reading % | F33: 80 | G33: Consumption Liters | H33: =(D33-F33)*48.8 -> 0
A34: Tank 2 (1% = 48 liters) | C34: Previous Reading % | D34: 55 | E34: Current Reading % | F34: 45 | G34: Consumption Liters | H34: =(D34-F34)*48.8 -> 488
A35: Total Cost (@ 1.82 AED/Liter) | H35: =((H34+H33)*1.82)*0.5 -> 444.08
A36: Total Utilities | H36: =H35+D22+D9+D31 -> 15604.22

Sheet December-14
A1: Daily Utilities Consumption
A2: 14.12.2024
A3: District Cooling
A4: Previous Reading MWh | B4: 70512.95 | C4: Current Reading MWh | D4: 70529.24 | E4: Consumption MWH | F4: =D4-B4 -> 16.29 | G4: Consumption RTH | H4: =F4*284.35 -> 4632.0615
A5: Cost Calculation
A6: Total Cost (0.568/rth) | D6: =H4*0.568 -> 2631.0109
A7: Total Fuel Surchage Cost (0.075/rth) | D7: =H4*0.075 -> 347.40461
A8: Chilled Water Demand (2,866 AED/Day) | D8: 2866
A9: Grand Total Exc. VAT | D9: =SUM(D6:H8) -> 5844.4155
A10: Electrical
A11: MDB-G1 (39299675-8) | C11: Previous Reading KWH | D11: 43308 | E11: Current Reading KWH | F11: 43315 | G11: Consumption KWH | H11: =F11-D11 -> 7
A12: MDB-G2 (39299676-6) | C12: Previous Reading KWH | D12: 71825 | E12: Current Reading KWH | F12: 71837 | G12: Consumption KWH | H12: =F12-D12 -> 12
A13: MDB-G3 (39299677-4) | C13: Previous Reading KWH | D13: 72616 | E13: Current Reading KWH | F13: 72627 | G13: Consumption KWH | H13: =F13-D13 -> 11
A14: Total Consumption KWH | H14: =SUM(H11:H13) -> 30
A15: Total Consumption * Multiplication Factor (487.20) | H15: =H14*487.2 -> 14616
A16: Cost Calculation
A17: 0-2000 kwh @ 0.230 /KWH | D17: 460
A18: 2000-4000 kwh @ 0.280 /KWH | D18: 560
A19: 4000-6000 kwh @ 0.320 /KWH | D19: 640
A20: 6000 & above @ 0.380 /KWH | D20: =H15*0.38 -> 5554.08
A21: Fuel Surcharge @ 0.060 /KWH | D21: =H15*0.06 -> 876.96
A22: Grand Total Exc. VAT | D22: =D20+D21 -> 6431.04
A23: WATER
A24: Previous Reading | B24: 306285 | C24: Present Reading | D24: 306660 | E24: Consumption m3 | F24: =D24-B24 -> 375 | G24: Consumption IG | H24: =F24*220 -> 82500
A25: Cost calculation
A26: 0-10000 @ 0.035 / IG | D26: 350
A27: 10000-20000 @ 0.04 / IG | D27: 400
A28: 20000 & above @ 0.046 / IG | D28: =(H24-20000)*0.046 -> 2875
A29: Fuel Surcharge @ 0.004 / IG | D29: =H24*0.004 -> 330
A30: Sewerage Fees | D30: =H24*0.01 -> 825
A31: Grand Total Exc. VAT | D31: =SUM(D26:H30) -> 4780
A32: LPG Gas
A33: Tank 1 (1% = 48 liters) | C33: Previous Reading % | D33: 80 | E33: Current Reading % | F33: 80 | G33: Consumption Liters | H33: =(D33-F33)*48.8 -> 0
A34: Tank 2 (1% = 48 liters) | C34: Previous Reading % | D34: 65 | E34: Current Reading % | F34: 55 | G34: Consumption Liters | H34: =(D34-F34)*48.8 -> 488
A35: Total Cost (@ 1.82 AED/Liter) | H35: =((H34+H33)*1.82)*0.5 -> 444.08
A36: Total Utilities | H36: =H35+D22+D9+D31 -> 17499.536

Sheet December-13
A1: Daily Utilities Consumption
A2: 13.12.2024
A3: District Cooling
A4: Previous Reading MWh | B4: 70496.09 | C4: Current Reading MWh | D4: 70512.95 | E4: Consumption MWH | F4: =D4-B4 -> 16.86 | G4: Consumption RTH | H4: =F4*284.35 -> 4794.141
A5: Cost Calculation
A6: Total Cost (0.568/rth) | D6: =H4*0.568 -> 2723.0721
A7: Total Fuel Surchage Cost (0.075/rth) | D7: =H4*0.075 -> 359.56058
A8: Chilled Water Demand (2,866 AED/Day) | D8: 2866
A9: Grand Total Exc. VAT | D9: =SUM(D6:H8) -> 5948.6327
A10: Electrical
A11: MDB-G1 (39299675-8) | C11: Previous Reading KWH | D11: 43301 | E11: Current Reading KWH | F11: 43308 | G11: Consumption KWH | H11: =F11-D11 -> 7
A12: MDB-G2 (39299676-6) | C12: Previous Reading KWH | D12: 71812 | E12: Current Reading KWH | F12: 71825 | G12: Consumption KWH | H12: =F12-D12 -> 13
A13: MDB-G3 (39299677-4) | C13: Previous Reading KWH | D13: 72604 | E13: Current Reading KWH | F13: 72616 | G13: Consumption KWH | H13: =F13-D13 -> 12
A14: Total Consumption KWH | H14: =SUM(H11:H13) -> 32
A15: Total Consumption * Multiplication Factor (487.20) | H15: =H14*487.2 -> 15590.4
A16: Cost Calculation
A17: 0-2000 kwh @ 0.230 /KWH | D17: 460
A18: 2000-4000 kwh @ 0.280 /KWH | D18: 560
A19: 4000-6000 kwh @ 0.320 /KWH | D19: 640
A20: 6000 & above @ 0.380 /KWH | D20: =H15*0.38 -> 5924.352
A21: Fuel Surcharge @ 0.060 /KWH | D21: =H15*0.06 -> 935.424
A22: Grand Total Exc. VAT | D22: =D20+D21 -> 6859.776
A23: WATER
A24: Previous Reading | B24: 306071 | C24: Present Reading | D24: 306285 | E24: Consumption m3 | F24: =D24-B24 -> 214 | G24: Consumption IG | H24: =F24*220 -> 47080
A25: Cost calculation
A26: 0-10000 @ 0.035 / IG | D26: 350
A27: 10000-20000 @ 0.04 / IG | D27: 400
A28: 20000 & above @ 0.046 / IG | D28: =(H24-20000)*0.046 -> 1245.68
A29: Fuel Surcharge @ 0.004 / IG | D29: =H24*0.004 -> 188.32
A30: Sewerage Fees | D30: =H24*0.01 -> 470.8
A31: Grand Total Exc. VAT | D31: =SUM(D26:H30) -> 2654.8
A32: LPG Gas
A33: Tank 1 (1% = 48 liters) | C33: Previous Reading % | D33: 80 | E33: Current Reading % | F33: 80 | G33: Consumption Liters | H33: =(D33-F33)*48.8 -> 0
A34: Tank 2 (1% = 48 liters) | C34: Previous Reading % | D34: 75 | E34: Current Reading % | F34: 65 | G34: Consumption Liters | H34: =(D34-F34)*48.8 -> 488
A35: Total Cost (@ 1.82 AED/Liter) | H35: =((H34+H33)*1.82)*0.5 -> 444.08
A36: Total Utilities | H36: =H35+D22+D9+D31 -> 15907.289

Sheet December-12
A1: Daily Utilities Consumption
A2: 12.12.2024
A3: District Cooling
A4: Previous Reading MWh | B4: 70478.56 | C4: Current Reading MWh | D4: 70496.09 | E4: Consumption MWH | F4: =D4-B4 -> 17.53 | G4: Consumption RTH | H4: =F4*284.35 -> 4984.6555
A5: Cost Calculation
A6: Total Cost (0.568/rth) | D6: =H4*0.568 -> 2831.2843
A7: Total Fuel Surchage Cost (0.075/rth) | D7: =H4*0.075 -> 373.84916
A8: Chilled Water Demand (2,866 AED/Day) | D8: 2866
A9: Grand Total Exc. VAT | D9: =SUM(D6:H8) -> 6071.1335
A10: Electrical
A11: MDB-G1 (39299675-8) | C11: Previous Reading KWH | D11: 43294 | E11: Current Reading KWH | F11: 43301 | G11: Consumption KWH | H11: =F11-D11 -> 7
A12: MDB-G2 (39299676-6) | C12: Previous Reading KWH | D12: 71800 | E12: Current Reading KWH | F12: 71812 | G12: Consumption KWH | H12: =F12-D12 -> 12
A13: MDB-G3 (39299677-4) | C13: Previous Reading KWH | D13: 72593 | E13: Current Reading KWH | F13: 72604 | G13: Consumption KWH | H13: =F13-D13 -> 11
A14: Total Consumption KWH | H14: =SUM(H11:H13) -> 30
A15: Total Consumption * Multiplication Factor (487.20) | H15: =H14*487.2 -> 14616
A16: Cost Calculation
A17: 0-2000 kwh @ 0.230 /KWH | D17: 460
A18: 2000-4000 kwh @ 0.280 /KWH | D18: 560
A19: 4000-6000 kwh @ 0.320 /KWH | D19: 640
A20: 6000 & above @ 0.380 /KWH | D20: =H15*0.38 -> 5554.08
A21: Fuel Surcharge @ 0.060 /KWH | D21: =H15*0.06 -> 876.96
A22: Grand Total Exc. VAT | D22: =D20+D21 -> 6431.04
A23: WATER
A24: Previous Reading | B24: 305876 | C24: Present Reading | D24: 306071 | E24: Consumption m3 | F24: =D24-B24 -> 195 | G24: Consumption IG | H24: =F24*220 -> 42900
A25: Cost calculation
A26: 0-10000 @ 0.035 / IG | D26: 350
A27: 10000-20000 @ 0.04 / IG | D27: 400
A28: 20000 & above @ 0.046 / IG | D28: =(H24-20000)*0.046 -> 1053.4
A29: Fuel Surcharge @ 0.004 / IG | D29: =H24*0.004 -> 171.6
A30: Sewerage Fees | D30: =H24*0.01 -> 429
A31: Grand Total Exc. VAT | D31: =SUM(D26:H30) -> 2404
A32: LPG Gas
A33: Tank 1 (1% = 48 liters) | C33: Previous Reading % | D33: 80 | E33: Current Reading % | F33: 80 | G33: Consumption Liters | H33: =(D33-F33)*48.8 -> 0
A34: Tank 2 (1% = 48 liters) | C34: Previous Reading % | D34: 85 | E34: Current Reading % | F34: 75 | G34: Consumption Liters | H34: =(D34-F34)*48.8 -> 488
A35: Total Cost (@ 1.82 AED/Liter) | H35: =((H34+H33)*1.82)*0.5 -> 444.08
A36: Total Utilities | H36: =H35+D22+D9+D31 -> 15350.253

Sheet December-11
A1: Daily Utilities Consumption
A2: 11.12.2024
A3: District Cooling
