Workbook

Sheet Total
A1: Site Name | B1: Day | C1: Month | D1: Year | E1: Total Electricity Kwh | F1: Electricity Tariff ($/Kwh) | G1: Natural Gas (m3) | H1: Natural Gas $/m3 | I1: Water Utility Supply (m3) m3 | J1: Water Utility Supply (m3) $/m3 | K1: District Energy Cooling RTH | L1: District Energy Cooling $/RTH | M1: Room Nights | N1: Total Guests
A2: Pearl Rotana Capital Centre | B2: 1 | C2: 4 | D2: 2025 | E2: =Submetering!E2+Submetering!F2+Submetering!G2 -> 15574 | F2: 0.2 | G2: ='Apr 2025'!T5 -> 33.7824 | H2: 16.875 | I2: =Submetering!H2 -> 87 | J2: 7.84 | K2: ='Apr 2025'!X5 -> 6458.275 | L2: 0.3449 | M2: =Submetering!N2 -> 199.9935 | N2: =Submetering!O2 -> 285
A3: Pearl Rotana Capital Centre | B3: =B2+1 -> 2 | C3: 4 | D3: 2025 | E3: =Submetering!E3+Submetering!F3+Submetering!G3 -> 15261 | F3: 0.2 | G3: ='Apr 2025'!T6 -> 32.7267 | H3: 16.875 | I3: =Submetering!H3 -> 92 | J3: 7.84 | K3: ='Apr 2025'!X6 -> 6522.93 | L3: 0.3449 | M3: =Submetering!N3 -> 264.0015 | N3: =Submetering!O3 -> 338
A4: Pearl Rotana Capital Centre | B4: =B3+1 -> 3 | C4: 4 | D4: 2025 | E4: =Submetering!E4+Submetering!F4+Submetering!G4 -> 15661 | F4: 0.2 | G4: ='Apr 2025'!T7 -> 28.5039 | H4: 16.875 | I4: =Submetering!H4 -> 106 | J4: 7.84 | K4: ='Apr 2025'!X7 -> 7184.93 | L4: 0.3449 | M4: =Submetering!N4 -> 260.001 | N4: =Submetering!O4 -> 332
A5: Pearl Rotana Capital Centre | B5: =B4+1 -> 4 | C5: 4 | D5: 2025 | E5: =Submetering!E5+Submetering!F5+Submetering!G5 -> 16296 | F5: 0.2 | G5: ='Apr 2025'!T8 -> 43.2837 | H5: 16.875 | I5: =Submetering!H5 -> 110 | J5: 7.84 | K5: ='Apr 2025'!X8 -> 7460.585 | L5: 0.3449 | M5: =Submetering!N5 -> 251.1495 | N5: =Submetering!O5 -> 327
A6: Pearl Rotana Capital Centre | B6: =B5+1 -> 5 | C6: 4 | D6: 2025 | E6: =Submetering!E6+Submetering!F6+Submetering!G6 -> 15620 | F6: 0.2 | G6: ='Apr 2025'!T9 -> 31.671 | H6: 16.875 | I6: =Submetering!H6 -> 111 | J6: 7.84 | K6: ='Apr 2025'!X9 -> 7031.93 | L6: 0.3449 | M6: =Submetering!N6 -> 210.987 | N6: =Submetering!O6 -> 262
A7: Pearl Rotana Capital Centre | B7: =B6+1 -> 6 | C7: 4 | D7: 2025 | E7: =Submetering!E7+Submetering!F7+Submetering!G7 -> 15746 | F7: 0.2 | G7: ='Apr 2025'!T10 -> 33.7824 | H7: 16.875 | I7: =Submetering!H7 -> 87 | J7: 7.84 | K7: ='Apr 2025'!X10 -> 7233.93 | L7: 0.3449 | M7: =Submetering!N7 -> 252 | N7: =Submetering!O7 -> 270
A8: Pearl Rotana Capital Centre | B8: =B7+1 -> 7 | C8: 4 | D8: 2025 | E8: =Submetering!E8+Submetering!F8+Submetering!G8 -> 15413 | F8: 0.2 | G8: ='Apr 2025'!T11 -> 39.0609 | H8: 16.875 | I8: =Submetering!H8 -> 91 | J8: 7.84 | K8: ='Apr 2025'!X11 -> 7329.24 | L8: 0.3449 | M8: =Submetering!N8 -> 300.006 | N8: =Submetering!O8 -> 326
A9: Pearl Rotana Capital Centre | B9: =B8+1 -> 8 | C9: 4 | D9: 2025 | E9: =Submetering!E9+Submetering!F9+Submetering!G9 -> 15974 | F9: 0.2 | G9: ='Apr 2025'!T12 -> 38.0052 | H9: 16.875 | I9: =Submetering!H9 -> 95 | J9: 7.84 | K9: ='Apr 2025'!X12 -> 7476.895 | L9: 0.3449 | M9: =Submetering!N9 -> 315 | N9: =Submetering!O9 -> 353
A10: Pearl Rotana Capital Centre | B10: =B9+1 -> 9 | C10: 4 | D10: 2025 | E10: =Submetering!E10+Submetering!F10+Submetering!G10 -> 16641 | F10: 0.2 | G10: ='Apr 2025'!T13 -> 40.1166 | H10: 16.875 | I10: =Submetering!H10 -> 92 | J10: 7.84 | K10: ='Apr 2025'!X13 -> 7326.24 | L10: 0.3449 | M10: =Submetering!N10 -> 315 | N10: =Submetering!O10 -> 355
A11: Pearl Rotana Capital Centre | B11: =B10+1 -> 10 | C11: 4 | D11: 2025 | E11: =Submetering!E11+Submetering!F11+Submetering!G11 -> 15136 | F11: 0.2 | G11: ='Apr 2025'!T14 -> 35.8938 | H11: 16.875 | I11: =Submetering!H11 -> 105 | J11: 7.84 | K11: ='Apr 2025'!X14 -> 7390.24 | L11: 0.3449 | M11: =Submetering!N11 -> 300.006 | N11: =Submetering!O11 -> 359
A12: Pearl Rotana Capital Centre | B12: =B11+1 -> 11 | C12: 4 | D12: 2025 | E12: =Submetering!E12+Submetering!F12+Submetering!G12 -> 14980 | F12: 0.2 | G12: ='Apr 2025'!T15 -> 39.0609 | H12: 16.875 | I12: =Submetering!H12 -> 89 | J12: 7.84 | K12: ='Apr 2025'!X15 -> 6448.585 | L12: 0.3449 | M12: =Submetering!N12 -> 253.9845 | N12: =Submetering!O12 -> 350
A13: Pearl Rotana Capital Centre | B13: =B12+1 -> 12 | C13: 4 | D13: 2025 | E13: =Submetering!E13+Submetering!F13+Submetering!G13 -> 15481 | F13: 0.2 | G13: ='Apr 2025'!T16 -> 34.8381 | H13: 16.875 | I13: =Submetering!H13 -> 92 | J13: 7.84 | K13: ='Apr 2025'!X16 -> 7369.585 | L13: 0.3449 | M13: =Submetering!N13 -> 178.0695 | N13: =Submetering!O13 -> 246
A14: Pearl Rotana Capital Centre | B14: =B13+1 -> 13 | C14: 4 | D14: 2025 | E14: =Submetering!E14+Submetering!F14+Submetering!G14 -> 15125 | F14: 0.2 | G14: ='Apr 2025'!T17 -> 36.9495 | H14: 16.875 | I14: =Submetering!H14 -> 84 | J14: 7.84 | K14: ='Apr 2025'!X17 -> 7721.585 | L14: 0.3449 | M14: =Submetering!N14 -> 198.9855 | N14: =Submetering!O14 -> 239
... A31: Pearl Rotana Capital Centre | B31: =B30+1 -> 30 | C31: 4 | D31: 2025 | E31: =Submetering!E31+Submetering!F31+Submetering!G31 -> 15138 | F31: 0.2 | G31: ='Apr 2025'!T34 -> 35.8938 | H31: 16.875 | I31: =Submetering!H31 -> 97 | J31: 7.84 | K31: ='Apr 2025'!X34 -> 8586.895 | L31: 0.3449 | M31: =Submetering!N31 -> 301.9905 | N31: =Submetering!O31 -> 369

Sheet Submetering
A1: Site Name | B1: Day | C1: Month | D1: Year | E1: MDB#2 | F1: MDB#3 | G1: MDB#1 Façade | H1: Water | I1: Gas Meter#1 GF Kitchen | J1: Gas Meter#2 1st floor Kitchen | K1: District Cooling | L1: District Cooling ETS | M1: Water Main Kitchen | N1: Room Nights | O1: Total Guests
A2: Pearl Rotana Capital Centre | B2: 1 | C2: 4 | D2: 2025 | E2: ='Apr 2025'!C5 -> 7905 | F2: ='Apr 2025'!E5 -> 7542 | G2: ='Apr 2025'!G5 -> 127 | H2: ='Apr 2025'!K5 -> 87 | I2: ='Apr 2025'!N5 -> 18 | J2: ='Apr 2025'!P5 -> 14 | K2: ='Apr 2025'!X5 -> 6458.275 | L2: ='Apr 2025'!AC5 -> 7880 | M2: ='Apr 2025'!AS5 -> 4 | N2: ='Apr 2025'!AE5*315 -> 199.9935 | O2: ='Apr 2025'!AF5 -> 285
A3: Pearl Rotana Capital Centre | B3: =B2+1 -> 2 | C3: 4 | D3: 2025 | E3: ='Apr 2025'!C6 -> 7923 | F3: ='Apr 2025'!E6 -> 7211 | G3: ='Apr 2025'!G6 -> 127 | H3: ='Apr 2025'!K6 -> 92 | I3: ='Apr 2025'!N6 -> 17 | J3: ='Apr 2025'!P6 -> 14 | K3: ='Apr 2025'!X6 -> 6522.93 | L3: ='Apr 2025'!AC6 -> 8229 | M3: ='Apr 2025'!AS6 -> 7 | N3: ='Apr 2025'!AE6*315 -> 264.0015 | O3: ='Apr 2025'!AF6 -> 338
A4: Pearl Rotana Capital Centre | B4: =B3+1 -> 3 | C4: 4 | D4: 2025 | E4: ='Apr 2025'!C7 -> 8163 | F4: ='Apr 2025'!E7 -> 7376 | G4: ='Apr 2025'!G7 -> 122 | H4: ='Apr 2025'!K7 -> 106 | I4: ='Apr 2025'!N7 -> 18 | J4: ='Apr 2025'!P7 -> 10 | K4: ='Apr 2025'!X7 -> 7184.93 | L4: ='Apr 2025'!AC7 -> 8891 | M4: ='Apr 2025'!AS7 -> 5 | N4: ='Apr 2025'!AE7*315 -> 260.001 | O4: ='Apr 2025'!AF7 -> 332
A5: Pearl Rotana Capital Centre | B5: =B4+1 -> 4 | C5: 4 | D5: 2025 | E5: ='Apr 2025'!C8 -> 8492 | F5: ='Apr 2025'!E8 -> 7678 | G5: ='Apr 2025'!G8 -> 126 | H5: ='Apr 2025'!K8 -> 110 | I5: ='Apr 2025'!N8 -> 20 | J5: ='Apr 2025'!P8 -> 20 | K5: ='Apr 2025'!X8 -> 7460.585 | L5: ='Apr 2025'!AC8 -> 9451 | M5: ='Apr 2025'!AS8 -> 7 | N5: ='Apr 2025'!AE8*315 -> 251.1495 | O5: ='Apr 2025'!AF8 -> 327
A6: Pearl Rotana Capital Centre | B6: =B5+1 -> 5 | C6: 4 | D6: 2025 | E6: ='Apr 2025'!C9 -> 7835 | F6: ='Apr 2025'!E9 -> 7661 | G6: ='Apr 2025'!G9 -> 124 | H6: ='Apr 2025'!K9 -> 111 | I6: ='Apr 2025'!N9 -> 19 | J6: ='Apr 2025'!P9 -> 12 | K6: ='Apr 2025'!X9 -> 7031.93 | L6: ='Apr 2025'!AC9 -> 8738 | M6: ='Apr 2025'!AS9 -> 5 | N6: ='Apr 2025'!AE9*315 -> 210.987 | O6: ='Apr 2025'!AF9 -> 262
A7: Pearl Rotana Capital Centre | B7: =B6+1 -> 6 | C7: 4 | D7: 2025 | E7: ='Apr 2025'!C10 -> 7974 | F7: ='Apr 2025'!E10 -> 7646 | G7: ='Apr 2025'!G10 -> 126 | H7: ='Apr 2025'!K10 -> 87 | I7: ='Apr 2025'!N10 -> 19 | J7: ='Apr 2025'!P10 -> 12 | K7: ='Apr 2025'!X10 -> 7233.93 | L7: ='Apr 2025'!AC10 -> 8940 | M7: ='Apr 2025'!AS10 -> 5 | N7: ='Apr 2025'!AE10*315 -> 252 | O7: ='Apr 2025'!AF10 -> 270
A8: Pearl Rotana Capital Centre | B8: =B7+1 -> 7 | C8: 4 | D8: 2025 | E8: ='Apr 2025'!C11 -> 7850 | F8: ='Apr 2025'!E11 -> 7433 | G8: ='Apr 2025'!G11 -> 130 | H8: ='Apr 2025'!K11 -> 91 | I8: ='Apr 2025'!N11 -> 20 | J8: ='Apr 2025'!P11 -> 19 | K8: ='Apr 2025'!X11 -> 7329.24 | L8: ='Apr 2025'!AC11 -> 9604 | M8: ='Apr 2025'!AS11 -> 7 | N8: ='Apr 2025'!AE11*315 -> 300.006 | O8: ='Apr 2025'!AF11 -> 326
A9: Pearl Rotana Capital Centre | B9: =B8+1 -> 8 | C9: 4 | D9: 2025 | E9: ='Apr 2025'!C12 -> 8007 | F9: ='Apr 2025'!E12 -> 7839 | G9: ='Apr 2025'!G12 -> 128 | H9: ='Apr 2025'!K12 -> 95 | I9: ='Apr 2025'!N12 -> 20 | J9: ='Apr 2025'!P12 -> 16 | K9: ='Apr 2025'!X12 -> 7476.895 | L9: ='Apr 2025'!AC12 -> 10036 | M9: ='Apr 2025'!AS12 -> 5 | N9: ='Apr 2025'!AE12*315 -> 315 | O9: ='Apr 2025'!AF12 -> 353
A10: Pearl Rotana Capital Centre | B10: =B9+1 -> 9 | C10: 4 | D10: 2025 | E10: ='Apr 2025'!C13 -> 8382 | F10: ='Apr 2025'!E13 -> 8141 | G10: ='Apr 2025'!G13 -> 118 | H10: ='Apr 2025'!K13 -> 92 | I10: ='Apr 2025'!N13 -> 21 | J10: ='Apr 2025'!P13 -> 15 | K10: ='Apr 2025'!X13 -> 7326.24 | L10: ='Apr 2025'!AC13 -> 9601 | M10: ='Apr 2025'!AS13 -> 5 | N10: ='Apr 2025'!AE13*315 -> 315 | O10: ='Apr 2025'!AF13 -> 355
A11: Pearl Rotana Capital Centre | B11: =B10+1 -> 10 | C11: 4 | D11: 2025 | E11: ='Apr 2025'!C14 -> 7695 | F11: ='Apr 2025'!E14 -> 7321 | G11: ='Apr 2025'!G14 -> 120 | H11: ='Apr 2025'!K14 -> 105 | I11: ='Apr 2025'!N14 -> 20 | J11: ='Apr 2025'!P14 -> 16 | K11: ='Apr 2025'!X14 -> 7390.24 | L11: ='Apr 2025'!AC14 -> 9665 | M11: ='Apr 2025'!AS14 -> 5 | N11: ='Apr 2025'!AE14*315 -> 300.006 | O11: ='Apr 2025'!AF14 -> 359
A12: Pearl Rotana Capital Centre | B12: =B11+1 -> 11 | C12: 4 | D12: 2025 | E12: ='Apr 2025'!C15 -> 7719 | F12: ='Apr 2025'!E15 -> 7134 | G12: ='Apr 2025'!G15 -> 127 | H12: ='Apr 2025'!K15 -> 89 | I12: ='Apr 2025'!N15 -> 20 | J12: ='Apr 2025'!P15 -> 17 | K12: ='Apr 2025'!X15 -> 6448.585 | L12: ='Apr 2025'!AC15 -> 8439 | M12: ='Apr 2025'!AS15 -> 6 | N12: ='Apr 2025'!AE15*315 -> 253.9845 | O12: ='Apr 2025'!AF15 -> 350
A13: Pearl Rotana Capital Centre | B13: =B12+1 -> 12 | C13: 4 | D13: 2025 | E13: ='Apr 2025'!C16 -> 7955 | F13: ='Apr 2025'!E16 -> 7399 | G13: ='Apr 2025'!G16 -> 127 | H13: ='Apr 2025'!K16 -> 92 | I13: ='Apr 2025'!N16 -> 17 | J13: ='Apr 2025'!P16 -> 14 | K13: ='Apr 2025'!X16 -> 7369.585 | L13: ='Apr 2025'!AC16 -> 9360 | M13: ='Apr 2025'!AS16 -> 6 | N13: ='Apr 2025'!AE16*315 -> 178.0695 | O13: ='Apr 2025'!AF16 -> 246
A14: Pearl Rotana Capital Centre | B14: =B13+1 -> 13 | C14: 4 | D14: 2025 | E14: ='Apr 2025'!C17 -> 7692 | F14: ='Apr 2025'!E17 -> 7307 | G14: ='Apr 2025'!G17 -> 126 | H14: ='Apr 2025'!K17 -> 84 | I14: ='Apr 2025'!N17 -> 18 | J14: ='Apr 2025'!P17 -> 10 | K14: ='Apr 2025'!X17 -> 7721.585 | L14: ='Apr 2025'!AC17 -> 9712 | M14: ='Apr 2025'!AS17 -> 4 | N14: ='Apr 2025'!AE17*315 -> 198.9855 | O14: ='Apr 2025'!AF17 -> 239
... A31: Pearl Rotana Capital Centre | B31: =B30+1 -> 30 | C31: 4 | D31: 2025 | E31: ='Apr 2025'!C34 -> 7820 | F31: ='Apr 2025'!E34 -> 7199 | G31: ='Apr 2025'!G34 -> 119 | H31: ='Apr 2025'!K34 -> 97 | I31: ='Apr 2025'!N34 -> 18 | J31: ='Apr 2025'!P34 -> 15 | K31: ='Apr 2025'!X34 -> 8586.895 | L31: ='Apr 2025'!AC34 -> 11146 | M31: ='Apr 2025'!AS34 -> 8 | N31: ='Apr 2025'!AE34*315 -> 301.9905 | O31: ='Apr 2025'!AF34 -> 369

Sheet Apr 2025
A1: PEARL ROTANA CAPITAL CENTRE UTILITIES CONSUMPTION - APRIL 2025
A2: DATE | B2: Electricity | J2: Water | M2: SNG Gas | V2: District Cooling | AE2: Additional Info | AG2: Additional Meter
B3: MDB #2 | D3: MDB #3 | F3: MDB #1 Façade | H3: Total ELE Cons. KW | I3: Electricity AED | J3: Hotel Reading | K3: Water Cons. M3 | L3: Water AED | M3: Gas Meter #1 G Floor Kitchen | O3: Gas Meter #2 1st Floor Kitchen | Q3: Total Gas Cons. M3 | R3: PRS Meter Reading | S3: PRS Meter Cons. M3 | T3: Meter factor (1.05570) | U3: Gas AED | V3: Hotel BTU Meter Energy Reading | W3: District Cooling Cons. MWH | X3: District Cooling Cons. Ton Hour | Y3: District Cooling Cons. AED | Z3: District Cooling Fixed Charge | AA3: District Cooling Total AED | AB3: ETS Energy Bulk Meter Reading | AC3: ETS Cons. Ton Hours | AD3: ETS Cons. MWH | AE3: Hotel Occupancy % | AF3: Adl. & Chl. | AG3: Blue Sky tower Chilled water | AI3: Electricity MDB-1 | AL3: Electricity MDB-E | AO3: Electricity-MCC Panel Chilled water Secondary Pumps | AR3: Water - Main kitchen | AU3: Water - Swimming Pool | AX3: Water - Bottling Plant
B4: Reading | C4: Cons. | D4: Reading | E4: Cons. | F4: Reading | G4: Cons. | M4: Reading | N4: Cons. | O4: Reading | P4: Cons. | AG4: Meter Reading | AH4: Cons. MWH | AI4: Meter Reading | AJ4: Cons. KWH | AK4: AED | AL4: Meter Reading | AM4: Cons. KWH | AN4: AED | AO4: Meter Reading | AP4: Cons. KWH | AQ4: AED | AR4: Meter Reading | AS4: Cons. M3 | AT4: AED | AU4: Meter Reading | AV4: Cons. M3 | AW4: AED | AX4: Meter Reading | AY4: Cons. M3 | AZ4: AED
A5: 45717 | B5: 21721732 | C5: 7905 | D5: 22406884 | E5: 7542 | F5: 496217 | G5: 127 | H5: =C5+E5+G5 -> 15574 | I5: =H5*0.2 -> 3114.8 | J5: 114963 | K5: 87 | L5: =K5*7.84 -> 682.08 | M5: 42392 | N5: 18 | O5: 25649 | P5: 14 | Q5: =N5+P5 -> 32 | R5: 63960 | S5: 32 | T5: =S5*1.0557 -> 33.7824 | U5: =IF(ISBLANK(M5),"0",T5*11.05+216.66) -> 589.95552 | V5: 78633 | W5: 28 | X5: =(AD5-AH5)*284.345 -> 6458.275 | Y5: =(AD5-AH5)*284.345*0.3449 -> 2227.459 | Z5: =IF(ISBLANK(V5),"0",1570*1608.73/12/30*0.65) -> 4560.3027 | AA5: =Y5+Z5 -> 6787.7617 | AB5: 1371537 | AC5: 7880 | AD5: =IF(ISBLANK(V5),"0 ",AC5/284.345) -> 27.712814 | AE5: 0.6349 | AF5: 285 | AG5: 21059 | AH5: 5 | AI5: 15224395 | AJ5: 4514 | AK5: =AJ5*0.2 -> 902.8 | AL5: 6966464 | AM5: 2114 | AN5: =AM5*0.2 -> 422.8 | AO5: 262705 | AP5: 564 | AQ5: =AP5*0.2 -> 112.8 | AR5: 9019 | AS5: 4 | AT5: =AS5*7.84 -> 31.36 | AU5: 3373 | AV5: 1 | AW5: =AV5*7.84 -> 7.84 | AX5: 208 | AY5: 1 | AZ5: =AY5*7.84 -> 7.84
A6: 45718 | B6: 21729655 | C6: =IF(ISBLANK(B6),"0",B6-B5) -> 7923 | D6: 22414095 | E6: =IF(ISBLANK(D6),"0",D6-D5) -> 7211 | F6: 496344 | G6: =IF(ISBLANK(F6),"0",F6-F5) -> 127 | H6: =C6+E6+G6 -> 15261 | I6: =H6*0.2 -> 3052.2 | J6: 115055 | K6: =IF(ISBLANK(J6),"0",J6-J5) -> 92 | L6: =K6*7.84 -> 721.28 | M6: 42409 | N6: =IF(ISBLANK(M6),"0",M6-M5) -> 17 | O6: 25663 | P6: =IF(ISBLANK(O6),"0",O6-O5) -> 14 | Q6: =N6+P6 -> 31 | R6: 63991 | S6: =IF(ISBLANK(R6),"0",R6-R5) -> 31 | T6: =S6*1.0557 -> 32.7267 | U6: =IF(ISBLANK(M6),"0",T6*11.05+216.66) -> 578.29003 | V6: 78659 | W6: =IF(ISBLANK(V6),"0",V6-V5) -> 26 | X6: =(AD6-AH6)*284.345 -> 6522.93 | Y6: =(AD6-AH6)*284.345*0.3449 -> 2249.7586 | Z6: =IF(ISBLANK(V6),"0",1570*1608.73/12/30*0.65) -> 4560.3027 | AA6: =Y6+Z6 -> 6810.0612 | AB6: 1379766 | AC6: =IF(ISBLANK(AB6),"0 ",AB6-AB5) -> 8229 | AD6: =IF(ISBLANK(V6),"0 ",AC6/284.345) -> 28.940196 | AE6: 0.8381 | AF6: 338 | AG6: 21065 | AH6: =IF(ISBLANK(V6),"0 ",AG6-AG5) -> 6 | AI6: 15229888 | AJ6: =IF(ISBLANK(AI6),"0",AI6-AI5) -> 5493 | AK6: =AJ6*0.2 -> 1098.6 | AL6: 6968699 | AM6: =IF(ISBLANK(AL6),"0",AL6-AL5) -> 2235 | AN6: =AM6*0.2 -> 447 | AO6: 263109 | AP6: =IF(ISBLANK(AO6),"0",AO6-AO5) -> 404 | AQ6: =AP6*0.2 -> 80.8 | AR6: 9026 | AS6: =IF(ISBLANK(AR6),"0",AR6-AR5) -> 7 | AT6: =AS6*7.84 -> 54.88 | AU6: 3374 | AV6: =IF(ISBLANK(AU6),"0",AU6-AU5) -> 1 | AW6: =AV6*7.84 -> 7.84 | AX6: 209 | AY6: =IF(ISBLANK(AX6),"0",AX6-AX5) -> 1 | AZ6: =AY6*7.84 -> 7.84
A7: 45719 | B7: 21737818 | C7: =IF(ISBLANK(B7),"0",B7-B6) -> 8163 | D7: 22421471 | E7: =IF(ISBLANK(D7),"0",D7-D6) -> 7376 | F7: 496466 | G7: =IF(ISBLANK(F7),"0",F7-F6) -> 122 | H7: =C7+E7+G7 -> 15661 | I7: =H7*0.2 -> 3132.2 | J7: 115161 | K7: =IF(ISBLANK(J7),"0",J7-J6) -> 106 | L7: =K7*7.84 -> 831.04 | M7: 42427 | N7: =IF(ISBLANK(M7),"0",M7-M6) -> 18 | O7: 25673 | P7: =IF(ISBLANK(O7),"0",O7-O6) -> 10 | Q7: =N7+P7 -> 28 | R7: 64018 | S7: =IF(ISBLANK(R7),"0",R7-R6) -> 27 | T7: =S7*1.0557 -> 28.5039 | U7: =IF(ISBLANK(M7),"0",T7*11.05+216.66) -> 531.6281 | V7: 78689 | W7: =IF(ISBLANK(V7),"0",V7-V6) -> 30 | X7: =(AD7-AH7)*284.345 -> 7184.93 | Y7: =(AD7-AH7)*284.345*0.3449 -> 2478.0824 | Z7: =IF(ISBLANK(V7),"0",1570*1608.73/12/30*0.65) -> 4560.3027 | AA7: =Y7+Z7 -> 7038.385 | AB7: 1388657 | AC7: =IF(ISBLANK(AB7),"0 ",AB7-AB6) -> 8891 | AD7: =IF(ISBLANK(V7),"0 ",AC7/284.345) -> 31.268354 | AE7: 0.8254 | AF7: 332 | AG7: 21071 | AH7: =IF(ISBLANK(V7),"0 ",AG7-AG6) -> 6 | AI7: 15235480 | AJ7: =IF(ISBLANK(AI7),"0",AI7-AI6) -> 5592 | AK7: =AJ7*0.2 -> 1118.4 | AL7: 6970944 | AM7: =IF(ISBLANK(AL7),"0",AL7-AL6) -> 2245 | AN7: =AM7*0.2 -> 449 | AO7: 263564 | AP7: =IF(ISBLANK(AO7),"0",AO7-AO6) -> 455 | AQ7: =AP7*0.2 -> 91 | AR7: 9031 | AS7: =IF(ISBLANK(AR7),"0",AR7-AR6) -> 5 | AT7: =AS7*7.84 -> 39.2 | AU7: 3375 | AV7: =IF(ISBLANK(AU7),"0",AU7-AU6) -> 1 | AW7: =AV7*7.84 -> 7.84 | AX7: 210 | AY7: =IF(ISBLANK(AX7),"0",AX7-AX6) -> 1 | AZ7: =AY7*7.84 -> 7.84
A8: 45720 | B8: 21746310 | C8: =IF(ISBLANK(B8),"0",B8-B7) -> 8492 | D8: 22429149 | E8: =IF(ISBLANK(D8),"0",D8-D7) -> 7678 | F8: 496592 | G8: =IF(ISBLANK(F8),"0",F8-F7) -> 126 | H8: =C8+E8+G8 -> 16296 | I8: =H8*0.2 -> 3259.2 | J8: 115271 | K8: =IF(ISBLANK(J8),"0",J8-J7) -> 110 | L8: =K8*7.84 -> 862.4 | M8: 42447 | N8: =IF(ISBLANK(M8),"0",M8-M7) -> 20 | O8: 25693 | P8: =IF(ISBLANK(O8),"0",O8-O7) -> 20 | Q8: =N8+P8 -> 40 | R8: 64059 | S8: =IF(ISBLANK(R8),"0",R8-R7) -> 41 | T8: =S8*1.0557 -> 43.2837 | U8: =IF(ISBLANK(M8),"0",T8*11.05+216.66) -> 694.94489 | V8: 78720 | W8: =IF(ISBLANK(V8),"0",V8-V7) -> 31 | X8: =(AD8-AH8)*284.345 -> 7460.585 | Y8: =(AD8-AH8)*284.345*0.3449 -> 2573.1558 | Z8: =IF(ISBLANK(V8),"0",1570*1608.73/12/30*0.65) -> 4560.3027 | AA8: =Y8+Z8 -> 7133.4584 | AB8: 1398108 | AC8: =IF(ISBLANK(AB8),"0 ",AB8-AB7) -> 9451 | AD8: =IF(ISBLANK(V8),"0 ",AC8/284.345) -> 33.237792 | AE8: 0.7973 | AF8: 327 | AG8: 21078 | AH8: =IF(ISBLANK(V8),"0 ",AG8-AG7) -> 7 | AI8: 15241152 | AJ8: =IF(ISBLANK(AI8),"0",AI8-AI7) -> 5672 | AK8: =AJ8*0.2 -> 1134.4 | AL8: 6973244 | AM8: =IF(ISBLANK(AL8),"0",AL8-AL7) -> 2300 | AN8: =AM8*0.2 -> 460 | AO8: 264072 | AP8: =IF(ISBLANK(AO8),"0",AO8-AO7) -> 508 | AQ8: =AP8*0.2 -> 101.6 | AR8: 9038 | AS8: =IF(ISBLANK(AR8),"0",AR8-AR7) -> 7 | AT8: =AS8*7.84 -> 54.88 | AU8: 3378 | AV8: =IF(ISBLANK(AU8),"0",AU8-AU7) -> 3 | AW8: =AV8*7.84 -> 23.52 | AX8: 210 | AY8: =IF(ISBLANK(AX8),"0",AX8-AX7) -> 0 | AZ8: =AY8*7.84 -> 0
A9: 45721 | B9: 21754145 | C9: =IF(ISBLANK(B9),"0",B9-B8) -> 7835 | D9: 22436810 | E9: =IF(ISBLANK(D9),"0",D9-D8) -> 7661 | F9: 496716 | G9: =IF(ISBLANK(F9),"0",F9-F8) -> 124 | H9: =C9+E9+G9 -> 15620 | I9: =H9*0.2 -> 3124 | J9: 115382 | K9: =IF(ISBLANK(J9),"0",J9-J8) -> 111 | L9: =K9*7.84 -> 870.24 | M9: 42466 | N9: =IF(ISBLANK(M9),"0",M9-M8) -> 19 | O9: 25705 | P9: =IF(ISBLANK(O9),"0",O9-O8) -> 12 | Q9: =N9+P9 -> 31 | R9: 64089 | S9: =IF(ISBLANK(R9),"0",R9-R8) -> 30 | T9: =S9*1.0557 -> 31.671 | U9: =IF(ISBLANK(M9),"0",T9*11.05+216.66) -> 566.62455 | V9: 78750 | W9: =IF(ISBLANK(V9),"0",V9-V8) -> 30 | X9: =(AD9-AH9)*284.345 -> 7031.93 | Y9: =(AD9-AH9)*284.345*0.3449 -> 2425.3127 | Z9: =IF(ISBLANK(V9),"0",1570*1608.73/12/30*0.65) -> 4560.3027 | AA9: =Y9+Z9 -> 6985.6153 | AB9: 1406846 | AC9: =IF(ISBLANK(AB9),"0 ",AB9-AB8) -> 8738 | AD9: =IF(ISBLANK(V9),"0 ",AC9/284.345) -> 30.730275 | AE9: 0.6698 | AF9: 262 | AG9: 21084 | AH9: =IF(ISBLANK(V9),"0 ",AG9-AG8) -> 6 | AI9: 15245585 | AJ9: =IF(ISBLANK(AI9),"0",AI9-AI8) -> 4433 | AK9: =AJ9*0.2 -> 886.6 | AL9: 6975289 | AM9: =IF(ISBLANK(AL9),"0",AL9-AL8) -> 2045 | AN9: =AM9*0.2 -> 409 | AO9: 264462 | AP9: =IF(ISBLANK(AO9),"0",AO9-AO8) -> 390 | AQ9: =AP9*0.2 -> 78 | AR9: 9043 | AS9: =IF(ISBLANK(AR9),"0",AR9-AR8) -> 5 | AT9: =AS9*7.84 -> 39.2 | AU9: 3382 | AV9: =IF(ISBLANK(AU9),"0",AU9-AU8) -> 4 | AW9: =AV9*7.84 -> 31.36 | AX9: 211 | AY9: =IF(ISBLANK(AX9),"0",AX9-AX8) -> 1 | AZ9: =AY9*7.84 -> 7.84
A10: 45722 | B10: 21762119 | C10: =IF(ISBLANK(B10),"0",B10-B9) -> 7974 | D10: 22444456 | E10: =IF(ISBLANK(D10),"0",D10-D9) -> 7646 | F10: 496842 | G10: =IF(ISBLANK(F10),"0",F10-F9) -> 126 | H10: =C10+E10+G10 -> 15746 | I10: =H10*0.2 -> 3149.2 | J10: 115469 | K10: =IF(ISBLANK(J10),"0",J10-J9) -> 87 | L10: =K10*7.84 -> 682.08 | M10: 42485 | N10: =IF(ISBLANK(M10),"0",M10-M9) -> 19 | O10: 25717 | P10: =IF(ISBLANK(O10),"0",O10-O9) -> 12 | Q10: =N10+P10 -> 31 | R10: 64121 | S10: =IF(ISBLANK(R10),"0",R10-R9) -> 32 | T10: =S10*1.0557 -> 33.7824 | U10: =IF(ISBLANK(M10),"0",T10*11.05+216.66) -> 589.95552 | V10: 78780 | W10: =IF(ISBLANK(V10),"0",V10-V9) -> 30 | X10: =(AD10-AH10)*284.345 -> 7233.93 | Y10: =(AD10-AH10)*284.345*0.3449 -> 2494.9825 | Z10: =IF(ISBLANK(V10),"0",1570*1608.73/12/30*0.65) -> 4560.3027 | AA10: =Y10+Z10 -> 7055.2851 | AB10: 1415786 | AC10: =IF(ISBLANK(AB10),"0 ",AB10-AB9) -> 8940 | AD10: =IF(ISBLANK(V10),"0 ",AC10/284.345) -> 31.440679 | AE10: 0.8 | AF10: 270 | AG10: 21090 | AH10: =IF(ISBLANK(V10),"0 ",AG10-AG9) -> 6 | AI10: 15250125 | AJ10: =IF(ISBLANK(AI10),"0",AI10-AI9) -> 4540 | AK10: =AJ10*0.2 -> 908 | AL10: 6977418 | AM10: =IF(ISBLANK(AL10),"0",AL10-AL9) -> 2129 | AN10: =AM10*0.2 -> 425.8 | AO10: 264814 | AP10: =IF(ISBLANK(AO10),"0",AO10-AO9) -> 352 | AQ10: =AP10*0.2 -> 70.4 | AR10: 9048 | AS10: =IF(ISBLANK(AR10),"0",AR10-AR9) -> 5 | AT10: =AS10*7.84 -> 39.2 | AU10: 3384 | AV10: =IF(ISBLANK(AU10),"0",AU10-AU9) -> 2 | AW10: =AV10*7.84 -> 15.68 | AX10: 212 | AY10: =IF(ISBLANK(AX10),"0",AX10-AX9) -> 1 | AZ10: =AY10*7.84 -> 7.84
A11: 45723 | B11: 21769969 | C11: =IF(ISBLANK(B11),"0",B11-B10) -> 7850 | D11: 22451889 | E11: =IF(ISBLANK(D11),"0",D11-D10) -> 7433 | F11: 496972 | G11: =IF(ISBLANK(F11),"0",F11-F10) -> 130 | H11: =C11+E11+G11 -> 15413 | I11: =H11*0.2 -> 3082.6 | J11: 115560 | K11: =IF(ISBLANK(J11),"0",J11-J10) -> 91 | L11: =K11*7.84 -> 713.44 | M11: 42505 | N11: =IF(ISBLANK(M11),"0",M11-M10) -> 20 | O11: 25736 | P11: =IF(ISBLANK(O11),"0",O11-O10) -> 19 | Q11: =N11+P11 -> 39 | R11: 64158 | S11: =IF(ISBLANK(R11),"0",R11-R10) -> 37 | T11: =S11*1.0557 -> 39.0609 | U11: =IF(ISBLANK(M11),"0",T11*11.05+216.66) -> 648.28295 | V11: 78810 | W11: =IF(ISBLANK(V11),"0",V11-V10) -> 30 | X11: =(AD11-AH11)*284.345 -> 7329.24 | Y11: =(AD11-AH11)*284.345*0.3449 -> 2527.8549 | Z11: =IF(ISBLANK(V11),"0",1570*1608.73/12/30*0.65) -> 4560.3027 | AA11: =Y11+Z11 -> 7088.1576 | AB11: 1425390 | AC11: =IF(ISBLANK(AB11),"0 ",AB11-AB10) -> 9604 | AD11: =IF(ISBLANK(V11),"0 ",AC11/284.345) -> 33.775871 | AE11: 0.9524 | AF11: 326 | AG11: 21098 | AH11: =IF(ISBLANK(V11),"0 ",AG11-AG10) -> 8 | AI11: 15255759 | AJ11: =IF(ISBLANK(AI11),"0",AI11-AI10) -> 5634 | AK11: =AJ11*0.2 -> 1126.8 | AL11: 6979656 | AM11: =IF(ISBLANK(AL11),"0",AL11-AL10) -> 2238 | AN11: =AM11*0.2 -> 447.6 | AO11: 265164 | AP11: =IF(ISBLANK(AO11),"0",AO11-AO10) -> 350 | AQ11: =AP11*0.2 -> 70 | AR11: 9055 | AS11: =IF(ISBLANK(AR11),"0",AR11-AR10) -> 7 | AT11: =AS11*7.84 -> 54.88 | AU11: 3385 | AV11: =IF(ISBLANK(AU11),"0",AU11-AU10) -> 1 | AW11: =AV11*7.84 -> 7.84 | AX11: 213 | AY11: =IF(ISBLANK(AX11),"0",AX11-AX10) -> 1 | AZ11: =AY11*7.84 -> 7.84
A12: 45724 | B12: 21777976 | C12: =IF(ISBLANK(B12),"0",B12-B11) -> 8007 | D12: 22459728 | E12: =IF(ISBLANK(D12),"0",D12-D11) -> 7839 | F12: 497100 | G12: =IF(ISBLANK(F12),"0",F12-F11) -> 128 | H12: =C12+E12+G12 -> 15974 | I12: =H12*0.2 -> 3194.8 | J12: 115655 | K12: =IF(ISBLANK(J12),"0",J12-J11) -> 95 | L12: =K12*7.84 -> 744.8 | M12: 42525 | N12: =IF(ISBLANK(M12),"0",M12-M11) -> 20 | O12: 25752 | P12: =IF(ISBLANK(O12),"0",O12-O11) -> 16 | Q12: =N12+P12 -> 36 | R12: 64194 | S12: =IF(ISBLANK(R12),"0",R12-R11) -> 36 | T12: =S12*1.0557 -> 38.0052 | U12: =IF(ISBLANK(M12),"0",T12*11.05+216.66) -> 636.61746 | V12: 78841 | W12: =IF(ISBLANK(V12),"0",V12-V11) -> 31 | X12: =(AD12-AH12)*284.345 -> 7476.895 | Y12: =(AD12-AH12)*284.345*0.3449 -> 2578.7811 | Z12: =IF(ISBLANK(V12),"0",1570*1608.73/12/30*0.65) -> 4560.3027 | AA12: =Y12+Z12 -> 7139.0838 | AB12: 1435426 | AC12: =IF(ISBLANK(AB12),"0 ",AB12-AB11) -> 10036 | AD12: =IF(ISBLANK(V12),"0 ",AC12/284.345) -> 35.295152 | AE12: 1 | AF12: 353 | AG12: 21107 | AH12: =IF(ISBLANK(V12),"0 ",AG12-AG11) -> 9 | AI12: 15261521 | AJ12: =IF(ISBLANK(AI12),"0",AI12-AI11) -> 5762 | AK12: =AJ12*0.2 -> 1152.4 | AL12: 6981955 | AM12: =IF(ISBLANK(AL12),"0",AL12-AL11) -> 2299 | AN12: =AM12*0.2 -> 459.8 | AO12: 265941 | AP12: =IF(ISBLANK(AO12),"0",AO12-AO11) -> 777 | AQ12: =AP12*0.2 -> 155.4 | AR12: 9060 | AS12: =IF(ISBLANK(AR12),"0",AR12-AR11) -> 5 | AT12: =AS12*7.84 -> 39.2 | AU12: 3386 | AV12: =IF(ISBLANK(AU12),"0",AU12-AU11) -> 1 | AW12: =AV12*7.84 -> 7.84 | AX12: 214 | AY12: =IF(ISBLANK(AX12),"0",AX12-AX11) -> 1 | AZ12: =AY12*7.84 -> 7.84
A13: 45725 | B13: 21786358 | C13: =IF(ISBLANK(B13),"0",B13-B12) -> 8382 | D13: 22467869 | E13: =IF(ISBLANK(D13),"0",D13-D12) -> 8141 | F13: 497218 | G13: =IF(ISBLANK(F13),"0",F13-F12) -> 118 | H13: =C13+E13+G13 -> 16641 | I13: =H13*0.2 -> 3328.2 | J13: 115747 | K13: =IF(ISBLANK(J13),"0",J13-J12) -> 92 | L13: =K13*7.84 -> 721.28 | M13: 42546 | N13: =IF(ISBLANK(M13),"0",M13-M12) -> 21 | O13: 25767 | P13: =IF(ISBLANK(O13),"0",O13-O12) -> 15 | Q13: =N13+P13 -> 36 | R13: 64232 | S13: =IF(ISBLANK(R13),"0",R13-R12) -> 38 | T13: =S13*1.0557 -> 40.1166 | U13: =IF(ISBLANK(M13),"0",T13*11.05+216.66) -> 659.94843 | V13: 78873 | W13: =IF(ISBLANK(V13),"0",V13-V12) -> 32 | X13: =(AD13-AH13)*284.345 -> 7326.24 | Y13: =(AD13-AH13)*284.345*0.3449 -> 2526.8202 | Z13: =IF(ISBLANK(V13),"0",1570*1608.73/12/30*0.65) -> 4560.3027 | AA13: =Y13+Z13 -> 7087.1229 | AB13: 1445027 | AC13: =IF(ISBLANK(AB13),"0 ",AB13-AB12) -> 9601 | AD13: =IF(ISBLANK(V13),"0 ",AC13/284.345) -> 33.76532 | AE13: 1 | AF13: 355 | AG13: 21115 | AH13: =IF(ISBLANK(V13),"0 ",AG13-AG12) -> 8 | AI13: 15267375 | AJ13: =IF(ISBLANK(AI13),"0",AI13-AI12) -> 5854 | AK13: =AJ13*0.2 -> 1170.8 | AL13: 6984318 | AM13: =IF(ISBLANK(AL13),"0",AL13-AL12) -> 2363 | AN13: =AM13*0.2 -> 472.6 | AO13: 266556 | AP13: =IF(ISBLANK(AO13),"0",AO13-AO12) -> 615 | AQ13: =AP13*0.2 -> 123 | AR13: 9065 | AS13: =IF(ISBLANK(AR13),"0",AR13-AR12) -> 5 | AT13: =AS13*7.84 -> 39.2 | AU13: 3387 | AV13: =IF(ISBLANK(AU13),"0",AU13-AU12) -> 1 | AW13: =AV13*7.84 -> 7.84 | AX13: 215 | AY13: =IF(ISBLANK(AX13),"0",AX13-AX12) -> 1 | AZ13: =AY13*7.84 -> 7.84
A14: 45726 | B14: 21794053 | C14: =IF(ISBLANK(B14),"0",B14-B13) -> 7695 | D14: 22475190 | E14: =IF(ISBLANK(D14),"0",D14-D13) -> 7321 | F14: 497338 | G14: =IF(ISBLANK(F14),"0",F14-F13) -> 120 | H14: =C14+E14+G14 -> 15136 | I14: =H14*0.2 -> 3027.2 | J14: 115852 | K14: =IF(ISBLANK(J14),"0",J14-J13) -> 105 | L14: =K14*7.84 -> 823.2 | M14: 42566 | N14: =IF(ISBLANK(M14),"0",M14-M13) -> 20 | O14: 25783 | P14: =IF(ISBLANK(O14),"0",O14-O13) -> 16 | Q14: =N14+P14 -> 36 | R14: 64266 | S14: =IF(ISBLANK(R14),"0",R14-R13) -> 34 | T14: =S14*1.0557 -> 35.8938 | U14: =IF(ISBLANK(M14),"0",T14*11.05+216.66) -> 613.28649 | V14: 78904 | W14: =IF(ISBLANK(V14),"0",V14-V13) -> 31 | X14: =(AD14-AH14)*284.345 -> 7390.24 | Y14: =(AD14-AH14)*284.345*0.3449 -> 2548.8938 | Z14: =IF(ISBLANK(V14),"0",1570*1608.73/12/30*0.65) -> 4560.3027 | AA14: =Y14+Z14 -> 7109.1965 | AB14: 1454692 | AC14: =IF(ISBLANK(AB14),"0 ",AB14-AB13) -> 9665 | AD14: =IF(ISBLANK(V14),"0 ",AC14/284.345) -> 33.990399 | AE14: 0.9524 | AF14: 359 | AG14: 21123 | AH14: =IF(ISBLANK(V14),"0 ",AG14-AG13) -> 8 | AI14: 15272821 | AJ14: =IF(ISBLANK(AI14),"0",AI14-AI13) -> 5446 | AK14: =AJ14*0.2 -> 1089.2 | AL14: 6986477 | AM14: =IF(ISBLANK(AL14),"0",AL14-AL13) -> 2159 | AN14: =AM14*0.2 -> 431.8 | AO14: 267128 | AP14: =IF(ISBLANK(AO14),"0",AO14-AO13) -> 572 | AQ14: =AP14*0.2 -> 114.4 | AR14: 9070 | AS14: =IF(ISBLANK(AR14),"0",AR14-AR13) -> 5 | AT14: =AS14*7.84 -> 39.2 | AU14: 3390 | AV14: =IF(ISBLANK(AU14),"0",AU14-AU13) -> 3 | AW14: =AV14*7.84 -> 23.52 | AX14: 216 | AY14: =IF(ISBLANK(AX14),"0",AX14-AX13) -> 1 | AZ14: =AY14*7.84 -> 7.84
A15: 45727 | B15: 21801772 | C15: =IF(ISBLANK(B15),"0",B15-B14) -> 7719 | D15: 22482324 | E15: =IF(ISBLANK(D15),"0",D15-D14) -> 7134 | F15: 497465 | G15: =IF(ISBLANK(F15),"0",F15-F14) -> 127 | H15: =C15+E15+G15 -> 14980 | I15: =H15*0.2 -> 2996 | J15: 115941 | K15: =IF(ISBLANK(J15),"0",J15-J14) -> 89 | L15: =K15*7.84 -> 697.76 | M15: 42586 | N15: =IF(ISBLANK(M15),"0",M15-M14) -> 20 | O15: 25800 | P15: =IF(ISBLANK(O15),"0",O15-O14) -> 17 | Q15: =N15+P15 -> 37 | R15: 64303 | S15: =IF(ISBLANK(R15),"0",R15-R14) -> 37 | T15: =S15*1.0557 -> 39.0609 | U15: =IF(ISBLANK(M15),"0",T15*11.05+216.66) -> 648.28295 | V15: 78933 | W15: =IF(ISBLANK(V15),"0",V15-V14) -> 29 | X15: =(AD15-AH15)*284.345 -> 6448.585 | Y15: =(AD15-AH15)*284.345*0.3449 -> 2224.117 | Z15: =IF(ISBLANK(V15),"0",1570*1608.73/12/30*0.65) -> 4560.3027 | AA15: =Y15+Z15 -> 6784.4196 | AB15: 1463131 | AC15: =IF(ISBLANK(AB15),"0 ",AB15-AB14) -> 8439 | AD15: =IF(ISBLANK(V15),"0 ",AC15/284.345) -> 29.678735 | AE15: 0.8063 | AF15: 350 | AG15: 21130 | AH15: =IF(ISBLANK(V15),"0 ",AG15-AG14) -> 7 | AI15: 15278144 | AJ15: =IF(ISBLANK(AI15),"0",AI15-AI14) -> 5323 | AK15: =AJ15*0.2 -> 1064.6 | AL15: 6988653 | AM15: =IF(ISBLANK(AL15),"0",AL15-AL14) -> 2176 | AN15: =AM15*0.2 -> 435.2 | AO15: 267607 | AP15: =IF(ISBLANK(AO15),"0",AO15-AO14) -> 479 | AQ15: =AP15*0.2 -> 95.8 | AR15: 9076 | AS15: =IF(ISBLANK(AR15),"0",AR15-AR14) -> 6 | AT15: =AS15*7.84 -> 47.04 | AU15: 3391 | AV15: =IF(ISBLANK(AU15),"0",AU15-AU14) -> 1 | AW15: =AV15*7.84 -> 7.84 | AX15: 217 | AY15: =IF(ISBLANK(AX15),"0",AX15-AX14) -> 1 | AZ15: =AY15*7.84 -> 7.84
A16: 45728 | B16: 21809727 | C16: =IF(ISBLANK(B16),"0",B16-B15) -> 7955 | D16: 22489723 | E16: =IF(ISBLANK(D16),"0",D16-D15) -> 7399 | F16: 497592 | G16: =IF(ISBLANK(F16),"0",F16-F15) -> 127 | H16: =C16+E16+G16 -> 15481 | I16: =H16*0.2 -> 3096.2 | J16: 116033 | K16: =IF(ISBLANK(J16),"0",J16-J15) -> 92 | L16: =K16*7.84 -> 721.28 | M16: 42603 | N16: =IF(ISBLANK(M16),"0",M16-M15) -> 17 | O16: 25814 | P16: =IF(ISBLANK(O16),"0",O16-O15) -> 14 | Q16: =N16+P16 -> 31 | R16: 64336 | S16: =IF(ISBLANK(R16),"0",R16-R15) -> 33 | T16: =S16*1.0557 -> 34.8381 | U16: =IF(ISBLANK(M16),"0",T16*11.05+216.66) -> 601.62101 | V16: 78963 | W16: =IF(ISBLANK(V16),"0",V16-V15) -> 30 | X16: =(AD16-AH16)*284.345 -> 7369.585 | Y16: =(AD16-AH16)*284.345*0.3449 -> 2541.7699 | Z16: =IF(ISBLANK(V16),"0",1570*1608.73/12/30*0.65) -> 4560.3027 | AA16: =Y16+Z16 -> 7102.0725 | AB16: 1472491 | AC16: =IF(ISBLANK(AB16),"0 ",AB16-AB15) -> 9360 | AD16: =IF(ISBLANK(V16),"0 ",AC16/284.345) -> 32.917758 | AE16: 0.5653 | AF16: 246 | AG16: 21137 | AH16: =IF(ISBLANK(V16),"0 ",AG16-AG15) -> 7 | AI16: 15282614 | AJ16: =IF(ISBLANK(AI16),"0",AI16-AI15) -> 4470 | AK16: =AJ16*0.2 -> 894 | AL16: 6990757 | AM16: =IF(ISBLANK(AL16),"0",AL16-AL15) -> 2104 | AN16: =AM16*0.2 -> 420.8 | AO16: 267940 | AP16: =IF(ISBLANK(AO16),"0",AO16-AO15) -> 333 | AQ16: =AP16*0.2 -> 66.6 | AR16: 9082 | AS16: =IF(ISBLANK(AR16),"0",AR16-AR15) -> 6 | AT16: =AS16*7.84 -> 47.04 | AU16: 3392 | AV16: =IF(ISBLANK(AU16),"0",AU16-AU15) -> 1 | AW16: =AV16*7.84 -> 7.84 | AX16: 218 | AY16: =IF(ISBLANK(AX16),"0",AX16-AX15) -> 1 | AZ16: =AY16*7.84 -> 7.84
A17: 45729 | B17: 21817419 | C17: =IF(ISBLANK(B17),"0",B17-B16) -> 7692 | D17: 22497030 | E17: =IF(ISBLANK(D17),"0",D17-D16) -> 7307 | F17: 497718 | G17: =IF(ISBLANK(F17),"0",F17-F16) -> 126 | H17: =C17+E17+G17 -> 15125 | I17: =H17*0.2 -> 3025 | J17: 116117 | K17: =IF(ISBLANK(J17),"0",J17-J16) -> 84 | L17: =K17*7.84 -> 658.56 | M17: 42621 | N17: =IF(ISBLANK(M17),"0",M17-M16) -> 18 | O17: 25824 | P17: =IF(ISBLANK(O17),"0",O17-O16) -> 10 | Q17: =N17+P17 -> 28 | R17: 64371 | S17: =IF(ISBLANK(R17),"0",R17-R16) -> 35 | T17: =S17*1.0557 -> 36.9495 | U17: =IF(ISBLANK(M17),"0",T17*11.05+216.66) -> 624.95198 | V17: 78995 | W17: =IF(ISBLANK(V17),"0",V17-V16) -> 32 | X17: =(AD17-AH17)*284.345 -> 7721.585 | Y17: =(AD17-AH17)*284.345*0.3449 -> 2663.1747 | Z17: =IF(ISBLANK(V17),"0",1570*1608.73/12/30*0.65) -> 4560.3027 | AA17: =Y17+Z17 -> 7223.4773 | AB17: 1482203 | AC17: =IF(ISBLANK(AB17),"0 ",AB17-AB16) -> 9712 | AD17: =IF(ISBLANK(V17),"0 ",AC17/284.345) -> 34.155691 | AE17: 0.6317 | AF17: 239 | AG17: 21144 | AH17: =IF(ISBLANK(V17),"0 ",AG17-AG16) -> 7 | AI17: 15286965 | AJ17: =IF(ISBLANK(AI17),"0",AI17-AI16) -> 4351 | AK17: =AJ17*0.2 -> 870.2 | AL17: 6992780 | AM17: =IF(ISBLANK(AL17),"0",AL17-AL16) -> 2023 | AN17: =AM17*0.2 -> 404.6 | AO17: 268323 | AP17: =IF(ISBLANK(AO17),"0",AO17-AO16) -> 383 | AQ17: =AP17*0.2 -> 76.6 | AR17: 9086 | AS17: =IF(ISBLANK(AR17),"0",AR17-AR16) -> 4 | AT17: =AS17*7.84 -> 31.36 | AU17: 3394 | AV17: =IF(ISBLANK(AU17),"0",AU17-AU16) -> 2 | AW17: =AV17*7.84 -> 15.68 | AX17: 219 | AY17: =IF(ISBLANK(AX17),"0",AX17-AX16) -> 1 | AZ17: =AY17*7.84 -> 7.84
... A34: 45746 | B34: 21952067 | C34: =IF(ISBLANK(B34),"0",B34-B33) -> 7820 | D34: 22621600 | E34: =IF(ISBLANK(D34),"0",D34-D33) -> 7199 | F34: 499782 | G34: =IF(ISBLANK(F34),"0",F34-F33) -> 119 | H34: =C34+E34+G34 -> 15138 | I34: =H34*0.2 -> 3027.6 | J34: 117820 | K34: =IF(ISBLANK(J34),"0",J34-J33) -> 97 | L34: =K34*7.84 -> 760.48 | M34: 42946 | N34: =IF(ISBLANK(M34),"0",M34-M33) -> 18 | O34: 26118 | P34: =IF(ISBLANK(O34),"0",O34-O33) -> 15 | Q34: =N34+P34 -> 33 | R34: 64984 | S34: =IF(ISBLANK(R34),"0",R34-R33) -> 34 | T34: =S34*1.0557 -> 35.8938 | U34: =IF(ISBLANK(M34),"0",T34*11.05+216.66) -> 613.28649 | V34: 79533 | W34: =IF(ISBLANK(V34),"0",V34-V33) -> 35 | X34: =(AD34-AH34)*284.345 -> 8586.895 | Y34: =(AD34-AH34)*284.345*0.3449 -> 2961.6201 | Z34: =IF(ISBLANK(V34),"0",1570*1608.73/12/30*0.65) -> 4560.3027 | AA34: =Y34+Z34 -> 7521.9228 | AB34: 1650250 | AC34: =IF(ISBLANK(AB34),"0 ",AB34-AB33) -> 11146 | AD34: =IF(ISBLANK(V34),"0 ",AC34/284.345) -> 39.198861 | AE34: 0.9587 | AF34: 369 | AG34: 21277 | AH34: =IF(ISBLANK(V34),"0 ",AG34-AG33) -> 9 | AI34: 15377869 | AJ34: =IF(ISBLANK(AI34),"0",AI34-AI33) -> 5673 | AK34: =AJ34*0.2 -> 1134.6 | AL34: 7030693 | AM34: =IF(ISBLANK(AL34),"0",AL34-AL33) -> 2232 | AN34: =AM34*0.2 -> 446.4 | AO34: 277010 | AP34: =IF(ISBLANK(AO34),"0",AO34-AO33) -> 595 | AQ34: =AP34*0.2 -> 119 | AR34: 9193 | AS34: =IF(ISBLANK(AR34),"0",AR34-AR33) -> 8 | AT34: =AS34*7.84 -> 62.72 | AU34: 3414 | AV34: =IF(ISBLANK(AU34),"0",AU34-AU33) -> 0 | AW34: =AV34*7.84 -> 0 | AX34: 236 | AY34: =IF(ISBLANK(AX34),"0",AX34-AX33) -> 1 | AZ34: =AY34*7.84 -> 7.84
C35: =SUM(C5:C34) -> 238240 | E35: =SUM(E5:E34) -> 222258 | G35: =SUM(G5:G34) -> 3692 | H35: =SUM(H5:H34) -> 464190 | I35: =H35*0.2 -> 92838 | K35: =SUM(K5:K34) -> 2944 | L35: =K35*7.84 -> 23080.96 | N35: =SUM(N5:N34) -> 572 | P35: =SUM(P5:P34) -> 483 | Q35: =SUM(Q5:Q34) -> 1055 | S35: =SUM(S5:S34) -> 1056 | T35: =SUM(T5:T34) -> 1114.8192 | U35: =SUM(U5:U34) -> 18818.552 | W35: =SUM(W5:W34) -> 928 | X35: =SUM(X5:X34) -> 223184.06 | Y35: =SUM(Y5:Y34) -> 76976.184 | Z35: =SUM(Z5:Z34) -> 136809.08 | AA35: =SUM(AA5:AA34) -> 213785.26 | AC35: =SUM(AC5:AC34) -> 286593 | AD35: =SUM(AD5:AD34) -> 1007.9059 | AE35: =AVERAGE(AE5:AE34) -> 0.86838 | AF35: =SUM(AF5:AF34) -> 10166 | AH35: =SUM(AH5:AH34) -> 223 | AJ35: =SUM(AJ5:AJ34) -> 157988 | AK35: =SUM(AK5:AK34) -> 31597.6 | AM35: =SUM(AM5:AM34) -> 66343 | AN35: =SUM(AN5:AN34) -> 13268.6 | AP35: =SUM(AP5:AP34) -> 14869 | AQ35: =SUM(AQ5:AQ34) -> 2973.8 | AS35: =SUM(AS5:AS34) -> 178 | AT35: =SUM(AT5:AT34) -> 1395.52 | AV35: =SUM(AV5:AV34) -> 42 | AW35: =SUM(AW5:AW34) -> 329.28 | AY35: =SUM(AY5:AY34) -> 29 | AZ35: =SUM(AZ5:AZ34) -> 227.36
V36: AVT Charges should be Zero in the DC invoice - Please notify if not
B37: Electricity | D37: AED | G37: KW | J37: Water | L37: AED | M37: M3 | O37: Gas | R37: AED | T37: M3 | V37: Chilled Water | X37: AED | Z37: Ton Hour | AG37: =136809.08*4 -> 547236.32 | AH37: CHW Fixed Charges YTD 2025
B38: Actual April 2025 | D38: =I35 -> 92838 | G38: =D38/0.2 -> 464190 | J38: =B38 -> Actual April 2025 | L38: =L35 -> 23080.96 | M38: =K35 -> 2944 | O38: =B38 -> Actual April 2025 | R38: =U35 -> 18818.552 | T38: =T35 -> 1114.8192 | V38: =B38 -> Actual April 2025 | X38: =AA35 -> 213785.26 | Z38: =X35 -> 223184.06 | AD38: =AC35 -> 286593 | AE38: =AD38-X35 -> 63408.935 | AG38: =131547.55*4 -> 526190.2 | AH38: CHW Fixed Charges YTD 2024
B39: Budget April 2025 | D39: 95917.5 | G39: =D39/0.2 -> 479587.5 | J39: =B39 -> Budget April 2025 | L39: 27360.552 | M39: =L39/7.84 -> 3489.8663 | O39: =B39 -> Budget April 2025 | R39: 20507.862 | T39: =(R39-6500)/11.05 -> 1267.6798 | V39: =B39 -> Budget April 2025 | X39: 208953.54 | Z39: =AG39/0.3449 -> 209175.01 | AG39: =X39-136809.08 -> 72144.459 | AH39: CHW Consumption Charges (Budgeted 2025 MTD)
B40: Actual April 2024 | D40: 88856.6 | G40: =D40/0.2 -> 444283 | J40: =B40 -> Actual April 2024 | L40: 22391.04 | M40: =L40/7.84 -> 2856 | O40: =B40 -> Actual April 2024 | R40: 17317.05 | T40: =(R40-6500)/11.05 -> 978.91855 | V40: =B40 -> Actual April 2024 | X40: 197947.65 | Z40: =AG40/0.3442 -> 192911.39 | AG40: =X40-131547.55 -> 66400.1 | AH40: CHW Consumption Charges (Actual 2024 MTD)
B41: Actual YTD 2025 | D41: =D38+280684 -> 373522 | G41: =D41/0.2 -> 1867610 | J41: =B41 -> Actual YTD 2025 | L41: =L38+69619.2 -> 92700.16 | M41: =L41/7.84 -> 11824 | O41: =B41 -> Actual YTD 2025 | R41: =R38+54282.54 -> 73101.092 | T41: =(R41-6500)*4/11.05 -> 24108.993 | V41: =B41 -> Actual YTD 2025 | X41: =X38+563641.22 -> 777426.48 | Z41: =AG41/0.3449 -> 667411.32 | AG41: =X41-AG37 -> 230190.16 | AH41: CHW Consumption Charges (Actual 2025 YTD)
B42: Budget YTD 2025 | D42: =D39+269136 -> 365053.5 | G42: =D42/0.2 -> 1825267.5 | J42: =B42 -> Budget YTD 2025 | L42: =L39+77439.47 -> 104800.02 | M42: =L42/7.84 -> 13367.35 | O42: =B42 -> Budget YTD 2025 | R42: =R39+56580.16 -> 77088.022 | T42: =(R42-6500)*4/11.05 -> 25552.225 | V42: =B42 -> Budget YTD 2025 | X42: =X39+581622.31 -> 790575.85 | Z42: =AG42/0.3449 -> 705536.47 | AG42: =X42-AG37 -> 243339.53 | AH42: CHW Consumption Charges (Budgeted 2025 YTD)
B43: Actual YTD 2024 | D43: 350300.8 | G43: =D43/0.2 -> 1751504 | J43: =B43 -> Actual YTD 2024 | L43: 95365.76 | M43: =L43/7.84 -> 12164 | O43: =B43 -> Actual YTD 2024 | R43: 70420.61 | T43: =(R43-6500)*4/11.05 -> 23138.682 | V43: =B43 -> Actual YTD 2024 | X43: 749893.76 | Z43: =AG43/0.3442 -> 649923.18 | AG43: =X43-AG38 -> 223703.56 | AH43: CHW Consumption Charges (Actual 2024 YTD)
H44: 45748 | I44: =TODAY() -> 45778 | J44: 30
A45: Monthly Budget | D45: Daily Budget | I45: MTD Average | N45: MTD Budget | U45: MTD Actual | Z45: YTD Budget | AD45: YTD Actual | AG45: Savings | AH45: Exceeds
A46: Electricity | B46: =D39 -> 95917.5 | D46: Electricity | G46: =B46/30 -> 3197.25 | I46: Electricity | L46: =I35/J44 -> 3094.6 | N46: Electricity | R46: =G46*J44 -> 95917.5 | U46: Electricity | W46: =I35 -> 92838 | Y46: =R46-W46 -> 3079.5 | Z46: Electricity | AB46: =R46+269136 -> 365053.5 | AD46: Electricity | AF46: =W46+280684 -> 373522 | AG46: =AB46-AF46 -> -8468.5 | AH46: =AF46-AB46 -> 8468.5
A47: Water | B47: =L39 -> 27360.552 | D47: Water | G47: =B47/30 -> 912.0184 | I47: Water | L47: =L35/J44 -> 769.36533 | N47: Water | R47: =G47*J44 -> 27360.552 | U47: Water | W47: =L35 -> 23080.96 | Y47: =R47-W47 -> 4279.592 | Z47: Water | AB47: =R47+77439.47 -> 104800.02 | AD47: Water | AF47: =W47+69619.2 -> 92700.16 | AG47: =AB47-AF47 -> 12099.862 | AH47: =AF47-AB47 -> -12099.862
A48: Gas | B48: =R39 -> 20507.862 | D48: Gas | G48: =B48/30 -> 683.5954 | I48: Gas | L48: =U35/J44 -> 627.28507 | N48: Gas | R48: =G48*J44 -> 20507.862 | U48: Gas | W48: =U35 -> 18818.552 | Y48: =R48-W48 -> 1689.3099 | Z48: Gas | AB48: =R48+56580.16 -> 77088.022 | AD48: Gas | AF48: =W48+54282.54 -> 73101.092 | AG48: =AB48-AF48 -> 3986.9299 | AH48: =AF48-AB48 -> -3986.9299
A49: Chilled Water | B49: =X39 -> 208953.54 | D49: Chilled Water | G49: =B49/30 -> 6965.118 | I49: Chilled Water | L49: =AA35/J44 -> 7126.1755 | N49: Chilled Water | R49: =G49*J44 -> 208953.54 | U49: Chilled Water | W49: =AA35 -> 213785.26 | Y49: =R49-W49 -> -4831.7251 | Z49: Chilled Water | AB49: =R49+581622.31 -> 790575.85 | AD49: Chilled Water | AF49: =W49+563641.22 -> 777426.48 | AG49: =AB49-AF49 -> 13149.365 | AH49: =AF49-AB49 -> -13149.365
B50: =SUM(B46:B49) -> 352739.45 | R50: =SUM(R46:S49) -> 352739.45 | W50: =SUM(W46:X49) -> 348522.78 | Y50: =R50-W50 -> 4216.6769 | AA50: Total Energy cost | AB50: =SUM(AB46:AB49) -> 1337517.4 | AF50: =SUM(AF46:AF49) -> 1316749.7 | AG50: =AB50-AF50 -> 20767.657
B51: =B50*X51 -> 4216.6769 | X51: =1-(W50/R50) -> 0.011954083 | AF51: =1-(AF50/AB50) -> 0.015527018
A53: Actual Last Year | D53: Average Daily Consumption Last Year | I53: MTD Average Last Year | N53: MTD Actual | U53: MTD Actual Vs Last Year | Z53: MTD Fcst | AA53: YTD Fcst | AD53: MTD Saving Fcst Vs LY | AE53: YTD Saving Fcst Vs LY
A54: Electricity | B54: =D40 -> 88856.6 | D54: Electricity | G54: =B54/30 -> 2961.8867 | I54: Electricity | L54: =G54*J44 -> 88856.6 | N54: Electricity | R54: =W46 -> 92838 | U54: Electricity | W54: =L54-R54 -> -3981.4 | Z54: =L46*30 -> 92838 | AA54: =Z54+280684 -> 373522 | AD54: =D40-Z54 -> -3981.4 | AE54: =D43-AA54 -> -23221.2
A55: Water | B55: =L40 -> 22391.04 | D55: Water | G55: =B55/30 -> 746.368 | I55: Water | L55: =G55*J44 -> 22391.04 | N55: Water | R55: =W47 -> 23080.96 | U55: Water | W55: =L55-R55 -> -689.92 | Z55: =L47*30 -> 23080.96 | AA55: =Z55+69619.2 -> 92700.16 | AD55: =L40-Z55 -> -689.92 | AE55: =L43-AA55 -> 2665.6
A56: Gas | B56: =R40 -> 17317.05 | D56: Gas | G56: =B56/30 -> 577.235 | I56: Gas | L56: =G56*J44 -> 17317.05 | N56: Gas | R56: =W48 -> 18818.552 | U56: Gas | W56: =L56-R56 -> -1501.5022 | Z56: =L48*30 -> 18818.552 | AA56: =Z56+54282.54 -> 73101.092 | AD56: =R40-Z56 -> -1501.5022 | AE56: =R43-AA56 -> -2680.4822
A57: Chilled Water | B57: =X40 -> 197947.65 | D57: Chilled Water | G57: =B57/30 -> 6598.255 | I57: Chilled Water | L57: =G57*J44 -> 197947.65 | N57: Chilled Water | R57: =W49 -> 213785.26 | U57: Chilled Water | W57: =L57-R57 -> -15837.614 | Z57: =L49*30 -> 213785.26 | AA57: =Z57+563641.22 -> 777426.48 | AD57: =X40-Z57 -> -15837.614 | AE57: =X43-AA57 -> -27532.724
...
