Workbook

Sheet Total
A1: Site Name | B1: Day | C1: Month | D1: Year | E1: Total Electricity Kwh | F1: Electricity Tariff ($/Kwh) | G1: Water Utility Supply (m3) m3 | H1: Water Utility Supply (m3) $/m3 | I1: LPG (Liters) | J1: LPG $/Liters | K1: District Energy Cooling RTH | L1: District Energy Cooling $/RTH | M1: Room Nights | N1: Total Guests
A2: Capital Centre Arjaan | B2: 1 | C2: 4 | D2: 2025 | E2: =IF('APR 2025'!R5>=0,'APR 2025'!R5,0) -> 11487.574 | F2: 0.2 | G2: =IF('APR 2025'!X5>=0,'APR 2025'!X5,0) -> 72 | H2: 7.84 | I2: =IF('APR 2025'!AA5>=0,'APR 2025'!AA5,0) -> 44.452016 | J2: 2.77 | K2: =IF('APR 2025'!AF5>=0,'APR 2025'!AF5,0) -> 3412.14 | L2: 0.3449 | M2: ='APR 2025'!AM5*259 -> 236.0008 | N2: ='APR 2025'!AN5 -> 304
A3: Capital Centre Arjaan | B3: =B2+1 -> 2 | C3: 4 | D3: 2025 | E3: =IF('APR 2025'!R6>=0,'APR 2025'!R6,0) -> 11210.792 | F3: 0.2 | G3: =IF('APR 2025'!X6>=0,'APR 2025'!X6,0) -> 76 | H3: 7.84 | I3: =IF('APR 2025'!AA6>=0,'APR 2025'!AA6,0) -> 44.452016 | J3: 2.77 | K3: =IF('APR 2025'!AF6>=0,'APR 2025'!AF6,0) -> 3412.14 | L3: 0.3449 | M3: ='APR 2025'!AM6*259 -> 239.9894 | N3: ='APR 2025'!AN6 -> 307
A4: Capital Centre Arjaan | B4: =B3+1 -> 3 | C4: 4 | D4: 2025 | E4: =IF('APR 2025'!R7>=0,'APR 2025'!R7,0) -> 10603.521 | F4: 0.2 | G4: =IF('APR 2025'!X7>=0,'APR 2025'!X7,0) -> 52 | H4: 7.84 | I4: =IF('APR 2025'!AA7>=0,'APR 2025'!AA7,0) -> 44.452016 | J4: 2.77 | K4: =IF('APR 2025'!AF7>=0,'APR 2025'!AF7,0) -> 3412.14 | L4: 0.3449 | M4: ='APR 2025'!AM7*259 -> 244.9881 | N4: ='APR 2025'!AN7 -> 317
A5: Capital Centre Arjaan | B5: =B4+1 -> 4 | C5: 4 | D5: 2025 | E5: =IF('APR 2025'!R8>=0,'APR 2025'!R8,0) -> 10877.314 | F5: 0.2 | G5: =IF('APR 2025'!X8>=0,'APR 2025'!X8,0) -> 68 | H5: 7.84 | I5: =IF('APR 2025'!AA8>=0,'APR 2025'!AA8,0) -> 88.904032 | J5: 2.77 | K5: =IF('APR 2025'!AF8>=0,'APR 2025'!AF8,0) -> 3696.485 | L5: 0.3449 | M5: ='APR 2025'!AM8*259 -> 216.006 | N5: ='APR 2025'!AN8 -> 270
A6: Capital Centre Arjaan | B6: =B5+1 -> 5 | C6: 4 | D6: 2025 | E6: =IF('APR 2025'!R9>=0,'APR 2025'!R9,0) -> 10445.744 | F6: 0.2 | G6: =IF('APR 2025'!X9>=0,'APR 2025'!X9,0) -> 75 | H6: 7.84 | I6: =IF('APR 2025'!AA9>=0,'APR 2025'!AA9,0) -> 44.452016 | J6: 2.77 | K6: =IF('APR 2025'!AF9>=0,'APR 2025'!AF9,0) -> 5402.555 | L6: 0.3449 | M6: ='APR 2025'!AM9*259 -> 226.9876 | N6: ='APR 2025'!AN9 -> 278
A7: Capital Centre Arjaan | B7: =B6+1 -> 6 | C7: 4 | D7: 2025 | E7: =IF('APR 2025'!R10>=0,'APR 2025'!R10,0) -> 11374.638 | F7: 0.2 | G7: =IF('APR 2025'!X10>=0,'APR 2025'!X10,0) -> 55 | H7: 7.84 | I7: =IF('APR 2025'!AA10>=0,'APR 2025'!AA10,0) -> 88.904032 | J7: 2.77 | K7: =IF('APR 2025'!AF10>=0,'APR 2025'!AF10,0) -> 5402.555 | L7: 0.3449 | M7: ='APR 2025'!AM10*259 -> 259 | N7: ='APR 2025'!AN10 -> 310
A8: Capital Centre Arjaan | B8: =B7+1 -> 7 | C8: 4 | D8: 2025 | E8: =IF('APR 2025'!R11>=0,'APR 2025'!R11,0) -> 11698.051 | F8: 0.2 | G8: =IF('APR 2025'!X11>=0,'APR 2025'!X11,0) -> 69 | H8: 7.84 | I8: =IF('APR 2025'!AA11>=0,'APR 2025'!AA11,0) -> 44.452016 | J8: 2.77 | K8: =IF('APR 2025'!AF11>=0,'APR 2025'!AF11,0) -> 5402.555 | L8: 0.3449 | M8: ='APR 2025'!AM11*259 -> 259 | N8: ='APR 2025'!AN11 -> 308
A9: Capital Centre Arjaan | B9: =B8+1 -> 8 | C9: 4 | D9: 2025 | E9: =IF('APR 2025'!R12>=0,'APR 2025'!R12,0) -> 11383.282 | F9: 0.2 | G9: =IF('APR 2025'!X12>=0,'APR 2025'!X12,0) -> 44 | H9: 7.84 | I9: =IF('APR 2025'!AA12>=0,'APR 2025'!AA12,0) -> 44.452016 | J9: 2.77 | K9: =IF('APR 2025'!AF12>=0,'APR 2025'!AF12,0) -> 5118.21 | L9: 0.3449 | M9: ='APR 2025'!AM12*259 -> 259 | N9: ='APR 2025'!AN12 -> 306
A10: Capital Centre Arjaan | B10: =B9+1 -> 9 | C10: 4 | D10: 2025 | E10: =IF('APR 2025'!R13>=0,'APR 2025'!R13,0) -> 11558.181 | F10: 0.2 | G10: =IF('APR 2025'!X13>=0,'APR 2025'!X13,0) -> 65 | H10: 7.84 | I10: =IF('APR 2025'!AA13>=0,'APR 2025'!AA13,0) -> 44.452016 | J10: 2.77 | K10: =IF('APR 2025'!AF13>=0,'APR 2025'!AF13,0) -> 5118.21 | L10: 0.3449 | M10: ='APR 2025'!AM13*259 -> 255.0114 | N10: ='APR 2025'!AN13 -> 295
A11: Capital Centre Arjaan | B11: =B10+1 -> 10 | C11: 4 | D11: 2025 | E11: =IF('APR 2025'!R14>=0,'APR 2025'!R14,0) -> 11749.271 | F11: 0.2 | G11: =IF('APR 2025'!X14>=0,'APR 2025'!X14,0) -> 53 | H11: 7.84 | I11: =IF('APR 2025'!AA14>=0,'APR 2025'!AA14,0) -> 44.452016 | J11: 2.77 | K11: =IF('APR 2025'!AF14>=0,'APR 2025'!AF14,0) -> 5402.555 | L11: 0.3449 | M11: ='APR 2025'!AM14*259 -> 226.0034 | N11: ='APR 2025'!AN14 -> 273
A12: Capital Centre Arjaan | B12: =B11+1 -> 11 | C12: 4 | D12: 2025 | E12: =IF('APR 2025'!R15>=0,'APR 2025'!R15,0) -> 11543.207 | F12: 0.2 | G12: =IF('APR 2025'!X15>=0,'APR 2025'!X15,0) -> 77 | H12: 7.84 | I12: =IF('APR 2025'!AA15>=0,'APR 2025'!AA15,0) -> 44.452016 | J12: 2.77 | K12: =IF('APR 2025'!AF15>=0,'APR 2025'!AF15,0) -> 5118.21 | L12: 0.3449 | M12: ='APR 2025'!AM15*259 -> 193.991 | N12: ='APR 2025'!AN15 -> 228
A13: Capital Centre Arjaan | B13: =B12+1 -> 12 | C13: 4 | D13: 2025 | E13: =IF('APR 2025'!R16>=0,'APR 2025'!R16,0) -> 11224.52 | F13: 0.2 | G13: =IF('APR 2025'!X16>=0,'APR 2025'!X16,0) -> 52 | H13: 7.84 | I13: =IF('APR 2025'!AA16>=0,'APR 2025'!AA16,0) -> 88.904032 | J13: 2.77 | K13: =IF('APR 2025'!AF16>=0,'APR 2025'!AF16,0) -> 5402.555 | L13: 0.3449 | M13: ='APR 2025'!AM16*259 -> 196.9954 | N13: ='APR 2025'!AN16 -> 234
A14: Capital Centre Arjaan | B14: =B13+1 -> 13 | C14: 4 | D14: 2025 | E14: =IF('APR 2025'!R17>=0,'APR 2025'!R17,0) -> 11075.555 | F14: 0.2 | G14: =IF('APR 2025'!X17>=0,'APR 2025'!X17,0) -> 82 | H14: 7.84 | I14: =IF('APR 2025'!AA17>=0,'APR 2025'!AA17,0) -> 88.904032 | J14: 2.77 | K14: =IF('APR 2025'!AF17>=0,'APR 2025'!AF17,0) -> 4265.175 | L14: 0.3449 | M14: ='APR 2025'!AM17*259 -> 196.9954 | N14: ='APR 2025'!AN17 -> 234
... A31: Capital Centre Arjaan | B31: =B30+1 -> 30 | C31: 4 | D31: 2025 | E31: =IF('APR 2025'!R34>=0,'APR 2025'!R34,0) -> 10941.615 | F31: 0.2 | G31: =IF('APR 2025'!X34>=0,'APR 2025'!X34,0) -> 64 | H31: 7.84 | I31: =IF('APR 2025'!AA34>=0,'APR 2025'!AA34,0) -> 88.904032 | J31: 2.77 | K31: =IF('APR 2025'!AF34>=0,'APR 2025'!AF34,0) -> 3412.14 | L31: 0.3449 | M31: ='APR 2025'!AM34*259 -> 249.0026 | N31: ='APR 2025'!AN34 -> 300

Sheet APR 2025
A1: CAPITAL CENTRE ARJAAN UTILITIES CONSUMPTION - April 2025.
A2: DATE | B2: Electricity | T2: Water | Z2: LP Gas | AD2: District Cooling | AM2: Additional Info
B3: MDB #2 | D3: MDB #3 | G3: MDB #1 MDB-E | J3: MDB #1 SMDB Kitchen | L3: MDB #1 Fire Pump #1 | O3: MDB #1 Fire Pump #2 | R3: Total ELE Cons. KW | S3: Electricity AED | T3: Hotel Reading | U3: Water Cons. M3 | V3: Irrigation water BHP | W3: Water Cons. M3 | X3: Total Water Cons. M3 | Y3: Water AED | Z3: 1st Floor Kitchen | AB3: Gas AED | AC3: Gas Cylinder purchased (50 litres) | AD3: Hotel BTU Meter Energy Reading | AE3: District Cooling Cons. MWH | AF3: District Cooling Cons. Ton Hour | AG3: District Cooling Cons. AED | AH3: District Cooling Fixed Charge | AI3: District Cooling Total AED | AJ3: Bulk ETS Energy Meter Reading | AK3: ETS Cons. Ton Hours | AL3: ETS Cons. MWH | AM3: Hotel Occupancy % | AN3: Adl. & Chl.
B4: Reading | C4: Cons. | D4: Reading | E4: Cons. | F4: Hotel share 94.38 % | G4: Reading | H4: Cons. | I4: Hotel share 65.36 % | J4: Reading | K4: Cons. | L4: Reading | M4: Cons. | N4: Hotel share 50 % | O4: Reading | P4: Cons. | Q4: Hotel share 50 % | V4: To be deducted from Hotel Meter. | Z4: No of Cylinder | AA4: Cons. Ltrs
A5: 45748 | B5: 9930792 | C5: 2422 | D5: 24169280 | E5: 6074 | F5: =E5*0.9438 -> 5732.6412 | G5: 15655606 | H5: 3398 | I5: =H5*0.6536 -> 2220.9328 | J5: 3786744 | K5: 1112 | L5: 1665 | M5: 0 | N5: =M5*0.5 -> 0 | O5: 973 | P5: 0 | Q5: =P5*0.5 -> 0 | R5: =C5+F5+I5+K5+N5+Q5 -> 11487.574 | S5: =R5*0.2 -> 2297.5148 | T5: 85276 | U5: 79 | V5: 37475 | W5: 7 | X5: =U5-W5 -> 72 | Y5: =X5*7.84 -> 564.48 | Z5: 1 | AA5: =Z5*22.6796*1.96 -> 44.452016 | AB5: =AA5*2.7659 -> 122.94983 | AC5: 4 | AD5: 83058 | AE5: 12 | AF5: =IF(ISBLANK(AD5),"0 ",AE5*284.345) -> 3412.14 | AG5: =AF5*0.3449 -> 1176.8471 | AH5: =IF(ISBLANK(AD5),"0",1754*1608.73/12/30*0.66) -> 5173.1394 | AI5: =AG5+AH5 -> 6349.9865 | AJ5: 2748093 | AK5: 6226 | AL5: =IF(ISBLANK(AK5),"0 ",AK5/284.345) -> 21.895936 | AM5: 0.9112 | AN5: 304
A6: 45749 | B6: 9933217 | C6: =IF(ISBLANK(B6),"0",B6-B5) -> 2425 | D6: 24174930 | E6: =IF(ISBLANK(D6),"0",D6-D5) -> 5650 | F6: =E6*0.9438 -> 5332.47 | G6: 15659140 | H6: =IF(ISBLANK(G6),"0",G6-G5) -> 3534 | I6: =H6*0.6536 -> 2309.8224 | J6: 3787887 | K6: =IF(ISBLANK(J6),"0",J6-J5) -> 1143 | L6: 1665 | M6: =IF(ISBLANK(L6),"0",L6-L5) -> 0 | N6: =M6*0.5 -> 0 | O6: 974 | P6: =IF(ISBLANK(O6),"0",O6-O5) -> 1 | Q6: =P6*0.5 -> 0.5 | R6: =C6+F6+I6+K6+N6+Q6 -> 11210.792 | S6: =R6*0.2 -> 2242.1585 | T6: 85362 | U6: =IF(ISBLANK(T6),"0",T6-T5) -> 86 | V6: 37485 | W6: =IF(ISBLANK(V6),"0",V6-V5) -> 10 | X6: =U6-W6 -> 76 | Y6: =X6*7.84 -> 595.84 | Z6: 1 | AA6: =Z6*22.6796*1.96 -> 44.452016 | AB6: =AA6*2.7659 -> 122.94983 | AC6: 0 | AD6: 83070 | AE6: =IF(ISBLANK(AD6),"0",AD6-AD5) -> 12 | AF6: =IF(ISBLANK(AD6),"0 ",AE6*284.345) -> 3412.14 | AG6: =AF6*0.3449 -> 1176.8471 | AH6: =IF(ISBLANK(AD6),"0",1754*1608.73/12/30*0.66) -> 5173.1394 | AI6: =AG6+AH6 -> 6349.9865 | AJ6: 2754743 | AK6: =IF(ISBLANK(AJ6),"0",AJ6-AJ5) -> 6650 | AL6: =IF(ISBLANK(AK6),"0 ",AK6/284.345) -> 23.387083 | AM6: 0.9266 | AN6: 307
A7: 45750 | B7: 9935612 | C7: =IF(ISBLANK(B7),"0",B7-B6) -> 2395 | D7: 24180047 | E7: =IF(ISBLANK(D7),"0",D7-D6) -> 5117 | F7: =E7*0.9438 -> 4829.4246 | G7: 15662653 | H7: =IF(ISBLANK(G7),"0",G7-G6) -> 3513 | I7: =H7*0.6536 -> 2296.0968 | J7: 3788970 | K7: =IF(ISBLANK(J7),"0",J7-J6) -> 1083 | L7: 1665 | M7: =IF(ISBLANK(L7),"0",L7-L6) -> 0 | N7: =M7*0.5 -> 0 | O7: 974 | P7: =IF(ISBLANK(O7),"0",O7-O6) -> 0 | Q7: =P7*0.5 -> 0 | R7: =C7+F7+I7+K7+N7+Q7 -> 10603.521 | S7: =R7*0.2 -> 2120.7043 | T7: 85421 | U7: =IF(ISBLANK(T7),"0",T7-T6) -> 59 | V7: 37492 | W7: =IF(ISBLANK(V7),"0",V7-V6) -> 7 | X7: =U7-W7 -> 52 | Y7: =X7*7.84 -> 407.68 | Z7: 1 | AA7: =Z7*22.6796*1.96 -> 44.452016 | AB7: =AA7*2.7659 -> 122.94983 | AC7: 0 | AD7: 82869 | AE7: 12 | AF7: =IF(ISBLANK(AD7),"0 ",AE7*284.345) -> 3412.14 | AG7: =AF7*0.3449 -> 1176.8471 | AH7: =IF(ISBLANK(AD7),"0",1754*1608.73/12/30*0.66) -> 5173.1394 | AI7: =AG7+AH7 -> 6349.9865 | AJ7: 2761796 | AK7: =IF(ISBLANK(AJ7),"0",AJ7-AJ6) -> 7053 | AL7: =IF(ISBLANK(AK7),"0 ",AK7/284.345) -> 24.804375 | AM7: 0.9459 | AN7: 317
A8: 45751 | B8: 9938027 | C8: =IF(ISBLANK(B8),"0",B8-B7) -> 2415 | D8: 24185364 | E8: =IF(ISBLANK(D8),"0",D8-D7) -> 5317 | F8: =E8*0.9438 -> 5018.1846 | G8: 15666189 | H8: =IF(ISBLANK(G8),"0",G8-G7) -> 3536 | I8: =H8*0.6536 -> 2311.1296 | J8: 3790103 | K8: =IF(ISBLANK(J8),"0",J8-J7) -> 1133 | L8: 1665 | M8: =IF(ISBLANK(L8),"0",L8-L7) -> 0 | N8: =M8*0.5 -> 0 | O8: 974 | P8: =IF(ISBLANK(O8),"0",O8-O7) -> 0 | Q8: =P8*0.5 -> 0 | R8: =C8+F8+I8+K8+N8+Q8 -> 10877.314 | S8: =R8*0.2 -> 2175.4628 | T8: 85499 | U8: =IF(ISBLANK(T8),"0",T8-T7) -> 78 | V8: 37502 | W8: =IF(ISBLANK(V8),"0",V8-V7) -> 10 | X8: =U8-W8 -> 68 | Y8: =X8*7.84 -> 533.12 | Z8: 2 | AA8: =Z8*22.6796*1.96 -> 88.904032 | AB8: =AA8*2.7659 -> 245.89966 | AC8: 0 | AD8: 82882 | AE8: =IF(ISBLANK(AD8),"0",AD8-AD7) -> 13 | AF8: =IF(ISBLANK(AD8),"0 ",AE8*284.345) -> 3696.485 | AG8: =AF8*0.3449 -> 1274.9177 | AH8: =IF(ISBLANK(AD8),"0",1754*1608.73/12/30*0.66) -> 5173.1394 | AI8: =AG8+AH8 -> 6448.0571 | AJ8: 2769229 | AK8: =IF(ISBLANK(AJ8),"0",AJ8-AJ7) -> 7433 | AL8: =IF(ISBLANK(AK8),"0 ",AK8/284.345) -> 26.14078 | AM8: 0.834 | AN8: 270
A9: 45752 | B9: 9940316 | C9: =IF(ISBLANK(B9),"0",B9-B8) -> 2289 | D9: 24190470 | E9: =IF(ISBLANK(D9),"0",D9-D8) -> 5106 | F9: =E9*0.9438 -> 4819.0428 | G9: 15669592 | H9: =IF(ISBLANK(G9),"0",G9-G8) -> 3403 | I9: =H9*0.6536 -> 2224.2008 | J9: 3791196 | K9: =IF(ISBLANK(J9),"0",J9-J8) -> 1093 | L9: 1693 | M9: =IF(ISBLANK(L9),"0",L9-L8) -> 28 | N9: =M9*0.5 -> 14 | O9: 987 | P9: =IF(ISBLANK(O9),"0",O9-O8) -> 13 | Q9: =P9*0.5 -> 6.5 | R9: =C9+F9+I9+K9+N9+Q9 -> 10445.744 | S9: =R9*0.2 -> 2089.1487 | T9: 85581 | U9: =IF(ISBLANK(T9),"0",T9-T8) -> 82 | V9: 37509 | W9: =IF(ISBLANK(V9),"0",V9-V8) -> 7 | X9: =U9-W9 -> 75 | Y9: =X9*7.84 -> 588 | Z9: 1 | AA9: =Z9*22.6796*1.96 -> 44.452016 | AB9: =AA9*2.7659 -> 122.94983 | AC9: 5 | AD9: 82901 | AE9: =IF(ISBLANK(AD9),"0",AD9-AD8) -> 19 | AF9: =IF(ISBLANK(AD9),"0 ",AE9*284.345) -> 5402.555 | AG9: =AF9*0.3449 -> 1863.3412 | AH9: =IF(ISBLANK(AD9),"0",1754*1608.73/12/30*0.66) -> 5173.1394 | AI9: =AG9+AH9 -> 7036.4807 | AJ9: 2776967 | AK9: =IF(ISBLANK(AJ9),"0",AJ9-AJ8) -> 7738 | AL9: =IF(ISBLANK(AK9),"0 ",AK9/284.345) -> 27.21342 | AM9: 0.8764 | AN9: 278
A10: 45753 | B10: 9942697 | C10: =IF(ISBLANK(B10),"0",B10-B9) -> 2381 | D10: 24196359 | E10: =IF(ISBLANK(D10),"0",D10-D9) -> 5889 | F10: =E10*0.9438 -> 5558.0382 | G10: 15673092 | H10: =IF(ISBLANK(G10),"0",G10-G9) -> 3500 | I10: =H10*0.6536 -> 2287.6 | J10: 3792344 | K10: =IF(ISBLANK(J10),"0",J10-J9) -> 1148 | L10: 1693 | M10: =IF(ISBLANK(L10),"0",L10-L9) -> 0 | N10: =M10*0.5 -> 0 | O10: 987 | P10: =IF(ISBLANK(O10),"0",O10-O9) -> 0 | Q10: =P10*0.5 -> 0 | R10: =C10+F10+I10+K10+N10+Q10 -> 11374.638 | S10: =R10*0.2 -> 2274.9276 | T10: 85647 | U10: =IF(ISBLANK(T10),"0",T10-T9) -> 66 | V10: 37520 | W10: =IF(ISBLANK(V10),"0",V10-V9) -> 11 | X10: =U10-W10 -> 55 | Y10: =X10*7.84 -> 431.2 | Z10: 2 | AA10: =Z10*22.6796*1.96 -> 88.904032 | AB10: =AA10*2.7659 -> 245.89966 | AC10: 0 | AD10: 82920 | AE10: =IF(ISBLANK(AD10),"0",AD10-AD9) -> 19 | AF10: =IF(ISBLANK(AD10),"0 ",AE10*284.345) -> 5402.555 | AG10: =AF10*0.3449 -> 1863.3412 | AH10: =IF(ISBLANK(AD10),"0",1754*1608.73/12/30*0.66) -> 5173.1394 | AI10: =AG10+AH10 -> 7036.4807 | AJ10: 2784864 | AK10: =IF(ISBLANK(AJ10),"0",AJ10-AJ9) -> 7897 | AL10: =IF(ISBLANK(AK10),"0 ",AK10/284.345) -> 27.7726 | AM10: 1 | AN10: 310
A11: 45754 | B11: 9944995 | C11: =IF(ISBLANK(B11),"0",B11-B10) -> 2298 | D11: 24202662 | E11: =IF(ISBLANK(D11),"0",D11-D10) -> 6303 | F11: =E11*0.9438 -> 5948.7714 | G11: 15676642 | H11: =IF(ISBLANK(G11),"0",G11-G10) -> 3550 | I11: =H11*0.6536 -> 2320.28 | J11: 3793475 | K11: =IF(ISBLANK(J11),"0",J11-J10) -> 1131 | L11: 1693 | M11: =IF(ISBLANK(L11),"0",L11-L10) -> 0 | N11: =M11*0.5 -> 0 | O11: 987 | P11: =IF(ISBLANK(O11),"0",O11-O10) -> 0 | Q11: =P11*0.5 -> 0 | R11: =C11+F11+I11+K11+N11+Q11 -> 11698.051 | S11: =R11*0.2 -> 2339.6103 | T11: 85723 | U11: =IF(ISBLANK(T11),"0",T11-T10) -> 76 | V11: 37527 | W11: =IF(ISBLANK(V11),"0",V11-V10) -> 7 | X11: =U11-W11 -> 69 | Y11: =X11*7.84 -> 540.96 | Z11: 1 | AA11: =Z11*22.6796*1.96 -> 44.452016 | AB11: =AA11*2.7659 -> 122.94983 | AC11: 0 | AD11: 82939 | AE11: =IF(ISBLANK(AD11),"0",AD11-AD10) -> 19 | AF11: =IF(ISBLANK(AD11),"0 ",AE11*284.345) -> 5402.555 | AG11: =AF11*0.3449 -> 1863.3412 | AH11: =IF(ISBLANK(AD11),"0",1754*1608.73/12/30*0.66) -> 5173.1394 | AI11: =AG11+AH11 -> 7036.4807 | AJ11: 2792860 | AK11: =IF(ISBLANK(AJ11),"0",AJ11-AJ10) -> 7996 | AL11: =IF(ISBLANK(AK11),"0 ",AK11/284.345) -> 28.120769 | AM11: 1 | AN11: 308
A12: 45755 | B12: 9947201 | C12: =IF(ISBLANK(B12),"0",B12-B11) -> 2206 | D12: 24208799 | E12: =IF(ISBLANK(D12),"0",D12-D11) -> 6137 | F12: =E12*0.9438 -> 5792.1006 | G12: 15680123 | H12: =IF(ISBLANK(G12),"0",G12-G11) -> 3481 | I12: =H12*0.6536 -> 2275.1816 | J12: 3794585 | K12: =IF(ISBLANK(J12),"0",J12-J11) -> 1110 | L12: 1693 | M12: =IF(ISBLANK(L12),"0",L12-L11) -> 0 | N12: =M12*0.5 -> 0 | O12: 987 | P12: =IF(ISBLANK(O12),"0",O12-O11) -> 0 | Q12: =P12*0.5 -> 0 | R12: =C12+F12+I12+K12+N12+Q12 -> 11383.282 | S12: =R12*0.2 -> 2276.6564 | T12: 85782 | U12: =IF(ISBLANK(T12),"0",T12-T11) -> 59 | V12: 37542 | W12: =IF(ISBLANK(V12),"0",V12-V11) -> 15 | X12: =U12-W12 -> 44 | Y12: =X12*7.84 -> 344.96 | Z12: 1 | AA12: =Z12*22.6796*1.96 -> 44.452016 | AB12: =AA12*2.7659 -> 122.94983 | AC12: 0 | AD12: 82957 | AE12: =IF(ISBLANK(AD12),"0",AD12-AD11) -> 18 | AF12: =IF(ISBLANK(AD12),"0 ",AE12*284.345) -> 5118.21 | AG12: =AF12*0.3449 -> 1765.2706 | AH12: =IF(ISBLANK(AD12),"0",1754*1608.73/12/30*0.66) -> 5173.1394 | AI12: =AG12+AH12 -> 6938.4101 | AJ12: 2800705 | AK12: =IF(ISBLANK(AJ12),"0",AJ12-AJ11) -> 7845 | AL12: =IF(ISBLANK(AK12),"0 ",AK12/284.345) -> 27.589724 | AM12: 1 | AN12: 306
A13: 45756 | B13: 9949471 | C13: =IF(ISBLANK(B13),"0",B13-B12) -> 2270 | D13: 24215017 | E13: =IF(ISBLANK(D13),"0",D13-D12) -> 6218 | F13: =E13*0.9438 -> 5868.5484 | G13: 15683646 | H13: =IF(ISBLANK(G13),"0",G13-G12) -> 3523 | I13: =H13*0.6536 -> 2302.6328 | J13: 3795702 | K13: =IF(ISBLANK(J13),"0",J13-J12) -> 1117 | L13: 1693 | M13: =IF(ISBLANK(L13),"0",L13-L12) -> 0 | N13: =M13*0.5 -> 0 | O13: 987 | P13: =IF(ISBLANK(O13),"0",O13-O12) -> 0 | Q13: =P13*0.5 -> 0 | R13: =C13+F13+I13+K13+N13+Q13 -> 11558.181 | S13: =R13*0.2 -> 2311.6362 | T13: 85854 | U13: =IF(ISBLANK(T13),"0",T13-T12) -> 72 | V13: 37549 | W13: =IF(ISBLANK(V13),"0",V13-V12) -> 7 | X13: =U13-W13 -> 65 | Y13: =X13*7.84 -> 509.6 | Z13: 1 | AA13: =Z13*22.6796*1.96 -> 44.452016 | AB13: =AA13*2.7659 -> 122.94983 | AC13: 5 | AD13: 82975 | AE13: =IF(ISBLANK(AD13),"0",AD13-AD12) -> 18 | AF13: =IF(ISBLANK(AD13),"0 ",AE13*284.345) -> 5118.21 | AG13: =AF13*0.3449 -> 1765.2706 | AH13: =IF(ISBLANK(AD13),"0",1754*1608.73/12/30*0.66) -> 5173.1394 | AI13: =AG13+AH13 -> 6938.4101 | AJ13: 2808326 | AK13: =IF(ISBLANK(AJ13),"0",AJ13-AJ12) -> 7621 | AL13: =IF(ISBLANK(AK13),"0 ",AK13/284.345) -> 26.801948 | AM13: 0.9846 | AN13: 295
A14: 45757 | B14: 9951795 | C14: =IF(ISBLANK(B14),"0",B14-B13) -> 2324 | D14: 24221344 | E14: =IF(ISBLANK(D14),"0",D14-D13) -> 6327 | F14: =E14*0.9438 -> 5971.4226 | G14: 15687229 | H14: =IF(ISBLANK(G14),"0",G14-G13) -> 3583 | I14: =H14*0.6536 -> 2341.8488 | J14: 3796814 | K14: =IF(ISBLANK(J14),"0",J14-J13) -> 1112 | L14: 1693 | M14: =IF(ISBLANK(L14),"0",L14-L13) -> 0 | N14: =M14*0.5 -> 0 | O14: 987 | P14: =IF(ISBLANK(O14),"0",O14-O13) -> 0 | Q14: =P14*0.5 -> 0 | R14: =C14+F14+I14+K14+N14+Q14 -> 11749.271 | S14: =R14*0.2 -> 2349.8543 | T14: 85914 | U14: =IF(ISBLANK(T14),"0",T14-T13) -> 60 | V14: 37556 | W14: =IF(ISBLANK(V14),"0",V14-V13) -> 7 | X14: =U14-W14 -> 53 | Y14: =X14*7.84 -> 415.52 | Z14: 1 | AA14: =Z14*22.6796*1.96 -> 44.452016 | AB14: =AA14*2.7659 -> 122.94983 | AC14: 4 | AD14: 82994 | AE14: =IF(ISBLANK(AD14),"0",AD14-AD13) -> 19 | AF14: =IF(ISBLANK(AD14),"0 ",AE14*284.345) -> 5402.555 | AG14: =AF14*0.3449 -> 1863.3412 | AH14: =IF(ISBLANK(AD14),"0",1754*1608.73/12/30*0.66) -> 5173.1394 | AI14: =AG14+AH14 -> 7036.4807 | AJ14: 2815752 | AK14: =IF(ISBLANK(AJ14),"0",AJ14-AJ13) -> 7426 | AL14: =IF(ISBLANK(AK14),"0 ",AK14/284.345) -> 26.116162 | AM14: 0.8726 | AN14: 273
A15: 45758 | B15: 9954082 | C15: =IF(ISBLANK(B15),"0",B15-B14) -> 2287 | D15: 24227567 | E15: =IF(ISBLANK(D15),"0",D15-D14) -> 6223 | F15: =E15*0.9438 -> 5873.2674 | G15: 15690754 | H15: =IF(ISBLANK(G15),"0",G15-G14) -> 3525 | I15: =H15*0.6536 -> 2303.94 | J15: 3797893 | K15: =IF(ISBLANK(J15),"0",J15-J14) -> 1079 | L15: 1693 | M15: =IF(ISBLANK(L15),"0",L15-L14) -> 0 | N15: =M15*0.5 -> 0 | O15: 987 | P15: =IF(ISBLANK(O15),"0",O15-O14) -> 0 | Q15: =P15*0.5 -> 0 | R15: =C15+F15+I15+K15+N15+Q15 -> 11543.207 | S15: =R15*0.2 -> 2308.6415 | T15: 86005 | U15: =IF(ISBLANK(T15),"0",T15-T14) -> 91 | V15: 37570 | W15: =IF(ISBLANK(V15),"0",V15-V14) -> 14 | X15: =U15-W15 -> 77 | Y15: =X15*7.84 -> 603.68 | Z15: 1 | AA15: =Z15*22.6796*1.96 -> 44.452016 | AB15: =AA15*2.7659 -> 122.94983 | AC15: 0 | AD15: 83012 | AE15: =IF(ISBLANK(AD15),"0",AD15-AD14) -> 18 | AF15: =IF(ISBLANK(AD15),"0 ",AE15*284.345) -> 5118.21 | AG15: =AF15*0.3449 -> 1765.2706 | AH15: =IF(ISBLANK(AD15),"0",1754*1608.73/12/30*0.66) -> 5173.1394 | AI15: =AG15+AH15 -> 6938.4101 | AJ15: 2822978 | AK15: =IF(ISBLANK(AJ15),"0",AJ15-AJ14) -> 7226 | AL15: =IF(ISBLANK(AK15),"0 ",AK15/284.345) -> 25.412791 | AM15: 0.749 | AN15: 228
A16: 45759 | B16: 9956432 | C16: =IF(ISBLANK(B16),"0",B16-B15) -> 2350 | D16: 24233385 | E16: =IF(ISBLANK(D16),"0",D16-D15) -> 5818 | F16: =E16*0.9438 -> 5491.0284 | G16: 15694224 | H16: =IF(ISBLANK(G16),"0",G16-G15) -> 3470 | I16: =H16*0.6536 -> 2267.992 | J16: 3798998 | K16: =IF(ISBLANK(J16),"0",J16-J15) -> 1105 | L16: 1706 | M16: =IF(ISBLANK(L16),"0",L16-L15) -> 13 | N16: =M16*0.5 -> 6.5 | O16: 995 | P16: =IF(ISBLANK(O16),"0",O16-O15) -> 8 | Q16: =P16*0.5 -> 4 | R16: =C16+F16+I16+K16+N16+Q16 -> 11224.52 | S16: =R16*0.2 -> 2244.9041 | T16: 86064 | U16: =IF(ISBLANK(T16),"0",T16-T15) -> 59 | V16: 37577 | W16: =IF(ISBLANK(V16),"0",V16-V15) -> 7 | X16: =U16-W16 -> 52 | Y16: =X16*7.84 -> 407.68 | Z16: 2 | AA16: =Z16*22.6796*1.96 -> 88.904032 | AB16: =AA16*2.7659 -> 245.89966 | AC16: 0 | AD16: 83031 | AE16: =IF(ISBLANK(AD16),"0",AD16-AD15) -> 19 | AF16: =IF(ISBLANK(AD16),"0 ",AE16*284.345) -> 5402.555 | AG16: =AF16*0.3449 -> 1863.3412 | AH16: =IF(ISBLANK(AD16),"0",1754*1608.73/12/30*0.66) -> 5173.1394 | AI16: =AG16+AH16 -> 7036.4807 | AJ16: 2830242 | AK16: =IF(ISBLANK(AJ16),"0",AJ16-AJ15) -> 7264 | AL16: =IF(ISBLANK(AK16),"0 ",AK16/284.345) -> 25.546431 | AM16: 0.7606 | AN16: 234
A17: 45760 | B17: 9958782 | C17: =IF(ISBLANK(B17),"0",B17-B16) -> 2350 | D17: 24239078 | E17: =IF(ISBLANK(D17),"0",D17-D16) -> 5693 | F17: =E17*0.9438 -> 5373.0534 | G17: 15697655 | H17: =IF(ISBLANK(G17),"0",G17-G16) -> 3431 | I17: =H17*0.6536 -> 2242.5016 | J17: 3800108 | K17: =IF(ISBLANK(J17),"0",J17-J16) -> 1110 | L17: 1706 | M17: =IF(ISBLANK(L17),"0",L17-L16) -> 0 | N17: =M17*0.5 -> 0 | O17: 995 | P17: =IF(ISBLANK(O17),"0",O17-O16) -> 0 | Q17: =P17*0.5 -> 0 | R17: =C17+F17+I17+K17+N17+Q17 -> 11075.555 | S17: =R17*0.2 -> 2215.111 | T17: 86165 | U17: =IF(ISBLANK(T17),"0",T17-T16) -> 101 | V17: 37596 | W17: =IF(ISBLANK(V17),"0",V17-V16) -> 19 | X17: =U17-W17 -> 82 | Y17: =X17*7.84 -> 642.88 | Z17: 2 | AA17: =Z17*22.6796*1.96 -> 88.904032 | AB17: =AA17*2.7659 -> 245.89966 | AC17: 6 | AD17: 83046 | AE17: =IF(ISBLANK(AD17),"0",AD17-AD16) -> 15 | AF17: =IF(ISBLANK(AD17),"0 ",AE17*284.345) -> 4265.175 | AG17: =AF17*0.3449 -> 1471.0589 | AH17: =IF(ISBLANK(AD17),"0",1754*1608.73/12/30*0.66) -> 5173.1394 | AI17: =AG17+AH17 -> 6644.1983 | AJ17: 2838396 | AK17: =IF(ISBLANK(AJ17),"0",AJ17-AJ16) -> 8154 | AL17: =IF(ISBLANK(AK17),"0 ",AK17/284.345) -> 28.676432 | AM17: 0.7606 | AN17: 234
A18: 45761 | B18: 9961178 | C18: =IF(ISBLANK(B18),"0",B18-B17) -> 2396 | D18: 24244542 | E18: =IF(ISBLANK(D18),"0",D18-D17) -> 5464 | F18: =E18*0.9438 -> 5156.9232 | G18: 15701274 | H18: =IF(ISBLANK(G18),"0",G18-G17) -> 3619 | I18: =H18*0.6536 -> 2365.3784 | J18: 3801206 | K18: =IF(ISBLANK(J18),"0",J18-J17) -> 1098 | L18: 1706 | M18: =IF(ISBLANK(L18),"0",L18-L17) -> 0 | N18: =M18*0.5 -> 0 | O18: 995 | P18: =IF(ISBLANK(O18),"0",O18-O17) -> 0 | Q18: =P18*0.5 -> 0 | R18: =C18+F18+I18+K18+N18+Q18 -> 11016.302 | S18: =R18*0.2 -> 2203.2603 | T18: 86282 | U18: =IF(ISBLANK(T18),"0",T18-T17) -> 117 | V18: 37596 | W18: =IF(ISBLANK(V18),"0",V18-V17) -> 0 | X18: =U18-W18 -> 117 | Y18: =X18*7.84 -> 917.28 | Z18: 2 | AA18: =Z18*22.6796*1.96 -> 88.904032 | AB18: =AA18*2.7659 -> 245.89966 | AC18: 4 | AD18: 83061 | AE18: =IF(ISBLANK(AD18),"0",AD18-AD17) -> 15 | AF18: =IF(ISBLANK(AD18),"0 ",AE18*284.345) -> 4265.175 | AG18: =AF18*0.3449 -> 1471.0589 | AH18: =IF(ISBLANK(AD18),"0",1754*1608.73/12/30*0.66) -> 5173.1394 | AI18: =AG18+AH18 -> 6644.1983 | AJ18: 2847617 | AK18: =IF(ISBLANK(AJ18),"0",AJ18-AJ17) -> 9221 | AL18: =IF(ISBLANK(AK18),"0 ",AK18/284.345) -> 32.428916 | AM18: 0.9189 | AN18: 286
A19: 45762 | B19: 9963629 | C19: =IF(ISBLANK(B19),"0",B19-B18) -> 2451 | D19: 24250802 | E19: =IF(ISBLANK(D19),"0",D19-D18) -> 6260 | F19: =E19*0.9438 -> 5908.188 | G19: 15704838 | H19: =IF(ISBLANK(G19),"0",G19-G18) -> 3564 | I19: =H19*0.6536 -> 2329.4304 | J19: 3802326 | K19: =IF(ISBLANK(J19),"0",J19-J18) -> 1120 | L19: 1706 | M19: =IF(ISBLANK(L19),"0",L19-L18) -> 0 | N19: =M19*0.5 -> 0 | O19: 995 | P19: =IF(ISBLANK(O19),"0",O19-O18) -> 0 | Q19: =P19*0.5 -> 0 | R19: =C19+F19+I19+K19+N19+Q19 -> 11808.618 | S19: =R19*0.2 -> 2361.7237 | T19: 86391 | U19: =IF(ISBLANK(T19),"0",T19-T18) -> 109 | V19: 37610 | W19: =IF(ISBLANK(V19),"0",V19-V18) -> 14 | X19: =U19-W19 -> 95 | Y19: =X19*7.84 -> 744.8 | Z19: 2 | AA19: =Z19*22.6796*1.96 -> 88.904032 | AB19: =AA19*2.7659 -> 245.89966 | AC19: 0 | AD19: 83076 | AE19: =IF(ISBLANK(AD19),"0",AD19-AD18) -> 15 | AF19: =IF(ISBLANK(AD19),"0 ",AE19*284.345) -> 4265.175 | AG19: =AF19*0.3449 -> 1471.0589 | AH19: =IF(ISBLANK(AD19),"0",1754*1608.73/12/30*0.66) -> 5173.1394 | AI19: =AG19+AH19 -> 6644.1983 | AJ19: 2856813 | AK19: =IF(ISBLANK(AJ19),"0",AJ19-AJ18) -> 9196 | AL19: =IF(ISBLANK(AK19),"0 ",AK19/284.345) -> 32.340994 | AM19: 0.9884 | AN19: 306
... A27: 45770 | B27: 9982952 | C27: =IF(ISBLANK(B27),"0",B27-B26) -> 2356 | D27: 24298878 | E27: =IF(ISBLANK(D27),"0",D27-D26) -> 5724 | F27: =E27*0.9438 -> 5402.3112 | G27: 15732987 | H27: =IF(ISBLANK(G27),"0",G27-G26) -> 3604 | I27: =H27*0.6536 -> 2355.5744 | J27: 3811465 | K27: =IF(ISBLANK(J27),"0",J27-J26) -> 1136 | L27: 1719 | M27: =IF(ISBLANK(L27),"0",L27-L26) -> 0 | N27: =M27*0.5 -> 0 | O27: 1003 | P27: =IF(ISBLANK(O27),"0",O27-O26) -> 0 | Q27: =P27*0.5 -> 0 | R27: =C27+F27+I27+K27+N27+Q27 -> 11249.886 | S27: =R27*0.2 -> 2249.9771 | T27: 86946 | U27: =IF(ISBLANK(T27),"0",T27-T26) -> 48 | V27: 37719 | W27: =IF(ISBLANK(V27),"0",V27-V26) -> 13 | X27: =U27-W27 -> 35 | Y27: =X27*7.84 -> 274.4 | Z27: 2 | AA27: =Z27*22.6796*1.96 -> 88.904032 | AB27: =AA27*2.7659 -> 245.89966 | AC27: 0 | AD27: 83191 | AE27: =IF(ISBLANK(AD27),"0",AD27-AD26) -> 15 | AF27: =IF(ISBLANK(AD27),"0 ",AE27*284.345) -> 4265.175 | AG27: =AF27*0.3449 -> 1471.0589 | AH27: =IF(ISBLANK(AD27),"0",1754*1608.73/12/30*0.66) -> 5173.1394 | AI27: =AG27+AH27 -> 6644.1983 | AJ27: 2917494 | AK27: =IF(ISBLANK(AJ27),"0",AJ27-AJ26) -> 8638 | AL27: =IF(ISBLANK(AK27),"0 ",AK27/284.345) -> 30.378589 | AM27: 0.9498 | AN27: 246
A28: 45771 | B28: 9985304 | C28: =IF(ISBLANK(B28),"0",B28-B27) -> 2352 | D28: 24304301 | E28: =IF(ISBLANK(D28),"0",D28-D27) -> 5423 | F28: =E28*0.9438 -> 5118.2274 | G28: 15736594 | H28: =IF(ISBLANK(G28),"0",G28-G27) -> 3607 | I28: =H28*0.6536 -> 2357.5352 | J28: 3812574 | K28: =IF(ISBLANK(J28),"0",J28-J27) -> 1109 | L28: 1719 | M28: 0 | N28: =M28*0.5 -> 0 | O28: 1003 | P28: =IF(ISBLANK(O28),"0",O28-O27) -> 0 | Q28: =P28*0.5 -> 0 | R28: =C28+F28+I28+K28+N28+Q28 -> 10936.763 | S28: =R28*0.2 -> 2187.3525 | T28: 87045 | U28: =IF(ISBLANK(T28),"0",T28-T27) -> 99 | V28: 37738 | W28: =IF(ISBLANK(V28),"0",V28-V27) -> 19 | X28: =U28-W28 -> 80 | Y28: =X28*7.84 -> 627.2 | Z28: 1 | AA28: =Z28*22.6796*1.96 -> 44.452016 | AB28: =AA28*2.7659 -> 122.94983 | AC28: 5 | AD28: 83206 | AE28: =IF(ISBLANK(AD28),"0",AD28-AD27) -> 15 | AF28: =IF(ISBLANK(AD28),"0 ",AE28*284.345) -> 4265.175 | AG28: =AF28*0.3449 -> 1471.0589 | AH28: =IF(ISBLANK(AD28),"0",1754*1608.73/12/30*0.66) -> 5173.1394 | AI28: =AG28+AH28 -> 6644.1983 | AJ28: 2925873 | AK28: =IF(ISBLANK(AJ28),"0",AJ28-AJ27) -> 8379 | AL28: =IF(ISBLANK(AK28),"0 ",AK28/284.345) -> 29.467724 | AM28: 0.9653 | AN28: 250
A29: 45772 | B29: 9987790 | C29: =IF(ISBLANK(B29),"0",B29-B28) -> 2486 | D29: 24309860 | E29: =IF(ISBLANK(D29),"0",D29-D28) -> 5559 | F29: =E29*0.9438 -> 5246.5842 | G29: 15740195 | H29: =IF(ISBLANK(G29),"0",G29-G28) -> 3601 | I29: =H29*0.6536 -> 2353.6136 | J29: 3813703 | K29: =IF(ISBLANK(J29),"0",J29-J28) -> 1129 | L29: 1719 | M29: =IF(ISBLANK(L29),"0",L29-L28) -> 0 | N29: =M29*0.5 -> 0 | O29: 1003 | P29: =IF(ISBLANK(O29),"0",O29-O28) -> 0 | Q29: =P29*0.5 -> 0 | R29: =C29+F29+I29+K29+N29+Q29 -> 11215.198 | S29: =R29*0.2 -> 2243.0396 | T29: 87112 | U29: =IF(ISBLANK(T29),"0",T29-T28) -> 67 | V29: 37741 | W29: =IF(ISBLANK(V29),"0",V29-V28) -> 3 | X29: =U29-W29 -> 64 | Y29: =X29*7.84 -> 501.76 | Z29: 2 | AA29: =Z29*22.6796*1.96 -> 88.904032 | AB29: =AA29*2.7659 -> 245.89966 | AC29: 0 | AD29: 83221 | AE29: =IF(ISBLANK(AD29),"0",AD29-AD28) -> 15 | AF29: =IF(ISBLANK(AD29),"0 ",AE29*284.345) -> 4265.175 | AG29: =AF29*0.3449 -> 1471.0589 | AH29: =IF(ISBLANK(AD29),"0",1754*1608.73/12/30*0.66) -> 5173.1394 | AI29: =AG29+AH29 -> 6644.1983 | AJ29: 2934581 | AK29: =IF(ISBLANK(AJ29),"0",AJ29-AJ28) -> 8708 | AL29: =IF(ISBLANK(AK29),"0 ",AK29/284.345) -> 30.624769 | AM29: 0.9807 | AN29: 319
A30: 45773 | B30: 9990350 | C30: =IF(ISBLANK(B30),"0",B30-B29) -> 2560 | D30: 24315481 | E30: =IF(ISBLANK(D30),"0",D30-D29) -> 5621 | F30: =E30*0.9438 -> 5305.0998 | G30: 15743772 | H30: =IF(ISBLANK(G30),"0",G30-G29) -> 3577 | I30: =H30*0.6536 -> 2337.9272 | J30: 3814876 | K30: =IF(ISBLANK(J30),"0",J30-J29) -> 1173 | L30: 1734 | M30: =IF(ISBLANK(L30),"0",L30-L29) -> 15 | N30: =M30*0.5 -> 7.5 | O30: 1010 | P30: =IF(ISBLANK(O30),"0",O30-O29) -> 7 | Q30: =P30*0.5 -> 3.5 | R30: =C30+F30+I30+K30+N30+Q30 -> 11387.027 | S30: =R30*0.2 -> 2277.4054 | T30: 87199 | U30: =IF(ISBLANK(T30),"0",T30-T29) -> 87 | V30: 37764 | W30: =IF(ISBLANK(V30),"0",V30-V29) -> 23 | X30: =U30-W30 -> 64 | Y30: =X30*7.84 -> 501.76 | Z30: 2 | AA30: =Z30*22.6796*1.96 -> 88.904032 | AB30: =AA30*2.7659 -> 245.89966 | AC30: 0 | AD30: 83236 | AE30: =IF(ISBLANK(AD30),"0",AD30-AD29) -> 15 | AF30: =IF(ISBLANK(AD30),"0 ",AE30*284.345) -> 4265.175 | AG30: =AF30*0.3449 -> 1471.0589 | AH30: =IF(ISBLANK(AD30),"0",1754*1608.73/12/30*0.66) -> 5173.1394 | AI30: =AG30+AH30 -> 6644.1983 | AJ30: 2943167 | AK30: =IF(ISBLANK(AJ30),"0",AJ30-AJ29) -> 8586 | AL30: =IF(ISBLANK(AK30),"0 ",AK30/284.345) -> 30.195713 | AM30: 0.9923 | AN30: 313
A31: 45774 | B31: 9992865 | C31: =IF(ISBLANK(B31),"0",B31-B30) -> 2515 | D31: 24321078 | E31: =IF(ISBLANK(D31),"0",D31-D30) -> 5597 | F31: =E31*0.9438 -> 5282.4486 | G31: 15747263 | H31: =IF(ISBLANK(G31),"0",G31-G30) -> 3491 | I31: =H31*0.6536 -> 2281.7176 | J31: 3816000 | K31: =IF(ISBLANK(J31),"0",J31-J30) -> 1124 | L31: 1734 | M31: =IF(ISBLANK(L31),"0",L31-L30) -> 0 | N31: =M31*0.5 -> 0 | O31: 1010 | P31: =IF(ISBLANK(O31),"0",O31-O30) -> 0 | Q31: =P31*0.5 -> 0 | R31: =C31+F31+I31+K31+N31+Q31 -> 11203.166 | S31: =R31*0.2 -> 2240.6332 | T31: 87266 | U31: =IF(ISBLANK(T31),"0",T31-T30) -> 67 | V31: 37764 | W31: =IF(ISBLANK(V31),"0",V31-V30) -> 0 | X31: =U31-W31 -> 67 | Y31: =X31*7.84 -> 525.28 | Z31: 2 | AA31: =Z31*22.6796*1.96 -> 88.904032 | AB31: =AA31*2.7659 -> 245.89966 | AC31: 5 | AD31: 83251 | AE31: =IF(ISBLANK(AD31),"0",AD31-AD30) -> 15 | AF31: =IF(ISBLANK(AD31),"0 ",AE31*284.345) -> 4265.175 | AG31: =AF31*0.3449 -> 1471.0589 | AH31: =IF(ISBLANK(AD31),"0",1754*1608.73/12/30*0.66) -> 5173.1394 | AI31: =AG31+AH31 -> 6644.1983 | AJ31: 2952252 | AK31: =IF(ISBLANK(AJ31),"0",AJ31-AJ30) -> 9085 | AL31: =IF(ISBLANK(AK31),"0 ",AK31/284.345) -> 31.950623 | AM31: 0.9575 | AN31: 289
A32: 45775 | B32: 9995305 | C32: =IF(ISBLANK(B32),"0",B32-B31) -> 2440 | D32: 24326841 | E32: =IF(ISBLANK(D32),"0",D32-D31) -> 5763 | F32: =E32*0.9438 -> 5439.1194 | G32: 15750894 | H32: =IF(ISBLANK(G32),"0",G32-G31) -> 3631 | I32: =H32*0.6536 -> 2373.2216 | J32: 3816768 | K32: =IF(ISBLANK(J32),"0",J32-J31) -> 768 | L32: 1734 | M32: =IF(ISBLANK(L32),"0",L32-L31) -> 0 | N32: =M32*0.5 -> 0 | O32: 1010 | P32: =IF(ISBLANK(O32),"0",O32-O31) -> 0 | Q32: =P32*0.5 -> 0 | R32: =C32+F32+I32+K32+N32+Q32 -> 11020.341 | S32: =R32*0.2 -> 2204.0682 | T32: 87378 | U32: =IF(ISBLANK(T32),"0",T32-T31) -> 112 | V32: 37793 | W32: =IF(ISBLANK(V32),"0",V32-V31) -> 29 | X32: =U32-W32 -> 83 | Y32: =X32*7.84 -> 650.72 | Z32: 1 | AA32: =Z32*22.6796*1.96 -> 44.452016 | AB32: =AA32*2.7659 -> 122.94983 | AC32: 0 | AD32: 83263 | AE32: =IF(ISBLANK(AD32),"0",AD32-AD31) -> 12 | AF32: =IF(ISBLANK(AD32),"0 ",AE32*284.345) -> 3412.14 | AG32: =AF32*0.3449 -> 1176.8471 | AH32: =IF(ISBLANK(AD32),"0",1754*1608.73/12/30*0.66) -> 5173.1394 | AI32: =AG32+AH32 -> 6349.9865 | AJ32: 2961607 | AK32: =IF(ISBLANK(AJ32),"0",AJ32-AJ31) -> 9355 | AL32: =IF(ISBLANK(AK32),"0 ",AK32/284.345) -> 32.900174 | AM32: 0.973 | AN32: 298
A33: 45776 | B33: 9997659 | C33: =IF(ISBLANK(B33),"0",B33-B32) -> 2354 | D33: 24332465 | E33: =IF(ISBLANK(D33),"0",D33-D32) -> 5624 | F33: =E33*0.9438 -> 5307.9312 | G33: 15754523 | H33: =IF(ISBLANK(G33),"0",G33-G32) -> 3629 | I33: =H33*0.6536 -> 2371.9144 | J33: 3817575 | K33: =IF(ISBLANK(J33),"0",J33-J32) -> 807 | L33: 1734 | M33: =IF(ISBLANK(L33),"0",L33-L32) -> 0 | N33: =M33*0.5 -> 0 | O33: 1010 | P33: =IF(ISBLANK(O33),"0",O33-O32) -> 0 | Q33: =P33*0.5 -> 0 | R33: =C33+F33+I33+K33+N33+Q33 -> 10840.846 | S33: =R33*0.2 -> 2168.1691 | T33: 87519 | U33: =IF(ISBLANK(T33),"0",T33-T32) -> 141 | V33: 37810 | W33: =IF(ISBLANK(V33),"0",V33-V32) -> 17 | X33: =U33-W33 -> 124 | Y33: =X33*7.84 -> 972.16 | Z33: 2 | AA33: =Z33*22.6796*1.96 -> 88.904032 | AB33: =AA33*2.7659 -> 245.89966 | AC33: 0 | AD33: 83275 | AE33: =IF(ISBLANK(AD33),"0",AD33-AD32) -> 12 | AF33: =IF(ISBLANK(AD33),"0 ",AE33*284.345) -> 3412.14 | AG33: =AF33*0.3449 -> 1176.8471 | AH33: =IF(ISBLANK(AD33),"0",1754*1608.73/12/30*0.66) -> 5173.1394 | AI33: =AG33+AH33 -> 6349.9865 | AJ33: 2971402 | AK33: =IF(ISBLANK(AJ33),"0",AJ33-AJ32) -> 9795 | AL33: =IF(ISBLANK(AK33),"0 ",AK33/284.345) -> 34.44759 | AM33: 0.9653 | AN33: 301
A34: 45777 | B34: 10000097 | C34: =IF(ISBLANK(B34),"0",B34-B33) -> 2438 | D34: 24338183 | E34: =IF(ISBLANK(D34),"0",D34-D33) -> 5718 | F34: =E34*0.9438 -> 5396.6484 | G34: 15758097 | H34: =IF(ISBLANK(G34),"0",G34-G33) -> 3574 | I34: =H34*0.6536 -> 2335.9664 | J34: 3818346 | K34: =IF(ISBLANK(J34),"0",J34-J33) -> 771 | L34: 1734 | M34: =IF(ISBLANK(L34),"0",L34-L33) -> 0 | N34: =M34*0.5 -> 0 | O34: 1010 | P34: =IF(ISBLANK(O34),"0",O34-O33) -> 0 | Q34: =P34*0.5 -> 0 | R34: =C34+F34+I34+K34+N34+Q34 -> 10941.615 | S34: =R34*0.2 -> 2188.323 | T34: 87596 | U34: =IF(ISBLANK(T34),"0",T34-T33) -> 77 | V34: 37823 | W34: =IF(ISBLANK(V34),"0",V34-V33) -> 13 | X34: =U34-W34 -> 64 | Y34: =X34*7.84 -> 501.76 | Z34: 2 | AA34: =Z34*22.6796*1.96 -> 88.904032 | AB34: =AA34*2.7659 -> 245.89966 | AC34: 5 | AD34: 83287 | AE34: =IF(ISBLANK(AD34),"0",AD34-AD33) -> 12 | AF34: =IF(ISBLANK(AD34),"0 ",AE34*284.345) -> 3412.14 | AG34: =AF34*0.3449 -> 1176.8471 | AH34: =IF(ISBLANK(AD34),"0",1754*1608.73/12/30*0.66) -> 5173.1394 | AI34: =AG34+AH34 -> 6349.9865 | AJ34: 2981178 | AK34: =IF(ISBLANK(AJ34),"0",AJ34-AJ33) -> 9776 | AL34: =IF(ISBLANK(AK34),"0 ",AK34/284.345) -> 34.38077 | AM34: 0.9614 | AN34: 300
C35: =SUM(C5:C34) -> 71727 | F35: =SUM(F5:F34) -> 165143.29 | I35: =SUM(I5:I34) -> 69209.05 | K35: =SUM(K5:K34) -> 32714 | N35: =SUM(N5:N34) -> 34.5 | Q35: =SUM(Q5:Q34) -> 18.5 | R35: =SUM(R5:R34) -> 338846.34 | S35: =R35*0.2 -> 67769.269 | U35: =SUM(U5:U34) -> 2399 | W35: =SUM(W5:W34) -> 355 | X35: =SUM(X5:X34) -> 2044 | Y35: =SUM(Y5:Y34) -> 16024.96 | Z35: =SUM(Z5:Z34) -> 46 | AA35: =SUM(AA5:AA34) -> 2044.7927 | AB35: =SUM(AB5:AB34) -> 5655.6922 | AC35: =SUM(AC5:AC34) -> 53 | AE35: =SUM(AE5:AE34) -> 454 | AF35: =SUM(AF5:AF34) -> 129092.63 | AG35: =SUM(AG5:AG34) -> 44524.048 | AH35: =SUM(AH5:AH34) -> 155194.18 | AI35: =SUM(AI5:AI34) -> 199718.23 | AK35: =SUM(AK5:AK34) -> 239311 | AL35: =SUM(AL5:AL34) -> 841.62197 | AM35: =AVERAGE(AM5:AM34) -> 0.92599667 | AN35: =SUM(AN5:AN34) -> 8679
AD36: AVT Charges should be Zero in the DC invoice - Please notify if not
B37: Electricity | G37: AED | K37: KW | T37: Water | V37: AED | X37: M3 | Z37: Gas | AA37: AED | AB37: Litres | AD37: District Cooling | AF37: AED | AH37: Ton Hour
B38: Actual April 2025 | G38: =S35 -> 67769.269 | K38: =G38/0.2 -> 338846.34 | T38: =B38 -> Actual April 2025 | V38: =Y35 -> 16024.96 | X38: =X35 -> 2044 | Z38: =T38 -> Actual April 2025 | AA38: =AB35 -> 5655.6922 | AB38: =AA38/1.2551 -> 4506.1686 | AD38: =T38 -> Actual April 2025 | AF38: =AI35 -> 199718.23 | AH38: =AF35 -> 129092.63 | AI38: =(AD38-#REF!)/0.3428 -> #VALUE! | AP38: 149225.58
B39: Budget April 2025 | G39: 73255.35 | K39: =G39/0.2 -> 366276.75 | T39: =B39 -> Budget April 2025 | V39: 15955.064 | X39: =V39/7.84 -> 2035.0847 | Z39: =T39 -> Budget April 2025 | AA39: 4843.4275 | AB39: =AA39/1.2551 -> 3858.9973 | AD39: =T39 -> Budget April 2025 | AF39: 204200.26 | AH39: =AP39/0.3449 -> 142087.78 | AI39: =(AD39-AF35)/0.3428 -> #VALUE! | AP39: =AF39-AH35 -> 49006.074 | AQ39: CHW Consumption Charges (Budget 2025 MTD)
B40: Actual YTD 2025 | G40: =G38+212523.64 -> 280292.91 | K40: =G40/0.2 -> 1401464.5 | T40: =B40 -> Actual YTD 2025 | V40: =V38+39599.84 -> 55624.8 | X40: =V40/7.84 -> 7095 | Z40: =T40 -> Actual YTD 2025 | AA40: =AA38+11930.98 -> 17586.672 | AB40: =AA40/1.2551 -> 14012.168 | AD40: =T40 -> Actual YTD 2025 | AF40: =AF38+555709.42 -> 755427.65 | AH40: =AP40/0.3449 -> 1740311.6 | AP40: =AF40-AP45 -> 600233.47 | AQ40: CHW Consumption Charges (Actual 2025 YTD)
B41: Budget YTD 2025 | G41: =221940.81+G39 -> 295196.16 | K41: =G41/0.2 -> 1475980.8 | T41: =B41 -> Budget YTD 2025 | V41: =42738.51+V39 -> 58693.574 | X41: =V41/7.84 -> 7486.4253 | Z41: =T41 -> Budget YTD 2025 | AA41: =13299.29+AA39 -> 18142.718 | AB41: =AA41/1.2551 -> 14455.197 | AD41: =T41 -> Budget YTD 2025 | AF41: =573908.57+AF39 -> 778108.83 | AH41: =AP41/0.3449 -> 1806073.2 | AI41: =(AD41-AF37)/0.3428 -> #VALUE! | AP41: =AF41-AP45 -> 622914.65 | AQ41: CHW Consumption Charges (Budget 2025 YTD)
B42: Actual April 2024 | G42: 68841.94 | K42: =G42/0.2 -> 344209.7 | T42: =B42 -> Actual April 2024 | V42: 13829.76 | X42: =V42/7.84 -> 1764 | Z42: =T42 -> Actual April 2024 | AA42: 2604 | AB42: =AA42/0.8571 -> 3038.1519 | AD42: =T42 -> Actual April 2024 | AF42: 193444.73 | AH42: =AP42/0.3442 -> 145145.61 | AI42: =(AD42-AF38)/0.3428 -> #VALUE! | AP42: =AF42-AP47 -> 49959.12 | AQ42: CHW Consumption Charges (Actual 2024 MTD)
B43: Actual YTD 2024 | G43: 289440.84 | K43: =G43/0.2 -> 1447204.2 | T43: =B43 -> Actual YTD 2024 | V43: 53335.52 | X43: =V43/7.84 -> 6803 | Z43: =T43 -> Actual YTD 2024 | AA43: 13419.07 | AB43: =AA43/0.8571 -> 15656.364 | AD43: =T43 -> Actual YTD 2024 | AF43: 738900.12 | AH43: =AP43/0.3442 -> 1713174.1 | AI43: =(AD43-AF39)/0.3428 -> #VALUE! | AP43: =AF43-AP46 -> 589674.54 | AQ43: CHW Consumption Charges (Actual 2024 YTD)
G44: 45748 | I44: 45777 | J44: 30
A45: Monthly Budget | D45: Daily Budget | I45: MTD Average | N45: MTD Budget | U45: MTD Actual | Y45: YTD Budget | AD45: YTD Actual | AG45: Savings | AH45: Exceeds | AP45: =155194.18 -> 155194.18 | AQ45: CHW Fixed Charges YTD 2025
A46: Electricity | B46: =G39 -> 73255.35 | D46: Electricity | G46: =B46/30 -> 2441.845 | I46: Electricity | L46: =S35/J44 -> 2258.9756 | N46: Electricity | S46: =G46*J44 -> 73255.35 | U46: Electricity | W46: =S35 -> 67769.269 | X46: =S46-W46 -> 5486.0818 | Y46: Electricity | AA46: =S46+G41 -> 368451.51 | AD46: Electricity | AF46: =W46+G40 -> 348062.18 | AG46: =AA46-AF46 -> 20389.334 | AH46: =AF46-AA46 -> -20389.334 | AP46: =149225.58 -> 149225.58 | AQ46: CHW Fixed Charges YTD 2024
A47: Water | B47: =V39 -> 15955.064 | D47: Water | G47: =B47/30 -> 531.83547 | I47: Water | L47: =Y35/J44 -> 534.16533 | N47: Water | S47: =G47*J44 -> 15955.064 | U47: Water | W47: =Y35 -> 16024.96 | X47: =S47-W47 -> -69.895789 | Y47: Water | AA47: =S47+V41 -> 74648.638 | AD47: Water | AF47: =W47+V40 -> 71649.76 | AG47: =AA47-AF47 -> 2998.8784 | AH47: =AF47-AA47 -> -2998.8784 | AP47: =143485.61 -> 143485.61
...
