Workbook

Sheet TOTAL
A1: Site Name | B1: Day | C1: Month | D1: Year | E1: Total Electricity Kwh | F1: Electricity Tariff ($/Kwh) | G1: LPG (Liters) | H1: LPG $/Liters | I1: Water Utility Supply (m3) m3 | J1: Water Utility Supply (m3) $/m3 | K1: District Energy Cooling RTH | L1: District Energy Cooling $/RTH | M1: Room Nights | N1: Total Guests
A2: Amwaj Rotana - Jumeirah Beach | B2: 1 | C2: 10 | D2: 2024 | E2: ='MTD Utility Sheet'!G4/0.439 -> 16114.214 | F2: 0.439 | G2: =('MTD Utility Sheet'!I4/1.82)/0.5 -> 488 | H2: =1.82*0.5 -> 0.91 | I2: ='MTD Utility Sheet'!H4/12.38 -> 209.11147 | J2: 12.38 | K2: =IF(('MTD Utility Sheet'!F4-2866)<0,"0",('MTD Utility Sheet'!F4-2866)/(0.568+0.075)) -> 11226.143 | L2: ='MTD Utility Sheet'!F4/K2 -> 0.89829694 | M2: ='MTD Utility Sheet'!B4*301 -> 240.8
A3: Amwaj Rotana - Jumeirah Beach | B3: =B2+1 -> 2 | C3: 10 | D3: 2024 | E3: ='MTD Utility Sheet'!G5/0.439 -> 16114.214 | F3: 0.439 | G3: =('MTD Utility Sheet'!I5/1.82)/0.5 -> 390.3956 | H3: =1.82*0.5 -> 0.91 | I3: ='MTD Utility Sheet'!H5/12.38 -> 196.31664 | J3: 12.38 | K3: =IF(('MTD Utility Sheet'!F5-2866)<0,"0",('MTD Utility Sheet'!F5-2866)/(0.568+0.075)) -> 12261.166 | L3: ='MTD Utility Sheet'!F5/K3 -> 0.87674611 | M3: ='MTD Utility Sheet'!B5*301 -> 238.994
A4: Amwaj Rotana - Jumeirah Beach | B4: =B3+1 -> 3 | C4: 10 | D4: 2024 | E4: ='MTD Utility Sheet'!G6/0.439 -> 16114.214 | F4: 0.439 | G4: =('MTD Utility Sheet'!I6/1.82)/0.5 -> 536.8022 | H4: =1.82*0.5 -> 0.91 | I4: ='MTD Utility Sheet'!H6/12.38 -> 205.91276 | J4: 12.38 | K4: =IF(('MTD Utility Sheet'!F6-2866)<0,"0",('MTD Utility Sheet'!F6-2866)/(0.568+0.075)) -> 13117.061 | L4: ='MTD Utility Sheet'!F6/K4 -> 0.86149407 | M4: ='MTD Utility Sheet'!B6*301 -> 230.9874
A5: Amwaj Rotana - Jumeirah Beach | B5: =B4+1 -> 4 | C5: 10 | D5: 2024 | E5: ='MTD Utility Sheet'!G7/0.439 -> 15625.923 | F5: 0.439 | G5: =('MTD Utility Sheet'!I7/1.82)/0.5 -> 390.10989 | H5: =1.82*0.5 -> 0.91 | I5: ='MTD Utility Sheet'!H7/12.38 -> 180.3231 | J5: 12.38 | K5: =IF(('MTD Utility Sheet'!F7-2866)<0,"0",('MTD Utility Sheet'!F7-2866)/(0.568+0.075)) -> 13429.844 | L5: ='MTD Utility Sheet'!F7/K5 -> 0.8564053 | M5: ='MTD Utility Sheet'!B7*301 -> #VALUE!
A6: Amwaj Rotana - Jumeirah Beach | B6: =B5+1 -> 5 | C6: 10 | D6: 2024 | E6: ='MTD Utility Sheet'!G8/0.439 -> 16114.214 | F6: 0.439 | G6: =('MTD Utility Sheet'!I8/1.82)/0.5 -> 390.3956 | H6: =1.82*0.5 -> 0.91 | I6: ='MTD Utility Sheet'!H8/12.38 -> 180.3231 | J6: 12.38 | K6: =IF(('MTD Utility Sheet'!F8-2866)<0,"0",('MTD Utility Sheet'!F8-2866)/(0.568+0.075)) -> 11345.568 | L6: ='MTD Utility Sheet'!F8/K6 -> 0.89560966 | M6: ='MTD Utility Sheet'!B8*301 -> 258.86
A7: Amwaj Rotana - Jumeirah Beach | B7: =B6+1 -> 6 | C7: 10 | D7: 2024 | E7: ='MTD Utility Sheet'!G9/0.439 -> 15625.923 | F7: 0.439 | G7: =('MTD Utility Sheet'!I9/1.82)/0.5 -> 390.3956 | H7: =1.82*0.5 -> 0.91 | I7: ='MTD Utility Sheet'!H9/12.38 -> 190.98546 | J7: 12.38 | K7: =IF(('MTD Utility Sheet'!F9-2866)<0,"0",('MTD Utility Sheet'!F9-2866)/(0.568+0.075)) -> 10859.331 | L7: ='MTD Utility Sheet'!F9/K7 -> 0.90692049 | M7: ='MTD Utility Sheet'!B9*301 -> 252.84
A8: Amwaj Rotana - Jumeirah Beach | B8: =B7+1 -> 7 | C8: 10 | D8: 2024 | E8: ='MTD Utility Sheet'!G10/0.439 -> 15137.608 | F8: 0.439 | G8: =('MTD Utility Sheet'!I10/1.82)/0.5 -> 390.3956 | H8: =1.82*0.5 -> 0.91 | I8: ='MTD Utility Sheet'!H10/12.38 -> 195.2504 | J8: 12.38 | K8: =IF(('MTD Utility Sheet'!F10-2866)<0,"0",('MTD Utility Sheet'!F10-2866)/(0.568+0.075)) -> 10105.801 | L8: ='MTD Utility Sheet'!F10/K8 -> 0.92659949 | M8: ='MTD Utility Sheet'!B10*301 -> 264.88
A9: Amwaj Rotana - Jumeirah Beach | B9: =B8+1 -> 8 | C9: 10 | D9: 2024 | E9: ='MTD Utility Sheet'!G11/0.439 -> 15625.923 | F9: 0.439 | G9: =('MTD Utility Sheet'!I11/1.82)/0.5 -> 488 | H9: =1.82*0.5 -> 0.91 | I9: ='MTD Utility Sheet'!H11/12.38 -> 183.52181 | J9: 12.38 | K9: =IF(('MTD Utility Sheet'!F11-2866)<0,"0",('MTD Utility Sheet'!F11-2866)/(0.568+0.075)) -> 10302.006 | L9: ='MTD Utility Sheet'!F11/K9 -> 0.92119824 | M9: ='MTD Utility Sheet'!B11*301 -> 261.87
A10: Amwaj Rotana - Jumeirah Beach | B10: =B9+1 -> 9 | C10: 10 | D10: 2024 | E10: ='MTD Utility Sheet'!G12/0.439 -> 15137.608 | F10: 0.439 | G10: =('MTD Utility Sheet'!I12/1.82)/0.5 -> 390.3956 | H10: =1.82*0.5 -> 0.91 | I10: ='MTD Utility Sheet'!H12/12.38 -> 198.44911 | J10: 12.38 | K10: =IF(('MTD Utility Sheet'!F12-2866)<0,"0",('MTD Utility Sheet'!F12-2866)/(0.568+0.075)) -> 10478.305 | L10: ='MTD Utility Sheet'!F12/K10 -> 0.91651752 | M10: ='MTD Utility Sheet'!B12*301 -> 264.88
A11: Amwaj Rotana - Jumeirah Beach | B11: =B10+1 -> 10 | C11: 10 | D11: 2024 | E11: ='MTD Utility Sheet'!G13/0.439 -> 15137.608 | F11: 0.439 | G11: =('MTD Utility Sheet'!I13/1.82)/0.5 -> 341.6044 | H11: =1.82*0.5 -> 0.91 | I11: ='MTD Utility Sheet'!H13/12.38 -> 205.91276 | J11: 12.38 | K11: =IF(('MTD Utility Sheet'!F13-2866)<0,"0",('MTD Utility Sheet'!F13-2866)/(0.568+0.075)) -> 11428.025 | L11: ='MTD Utility Sheet'!F13/K11 -> 0.89378699 | M11: ='MTD Utility Sheet'!B13*301 -> 270.9
A12: Amwaj Rotana - Jumeirah Beach | B12: =B11+1 -> 11 | C12: 10 | D12: 2024 | E12: ='MTD Utility Sheet'!G14/0.439 -> 16114.214 | F12: 0.439 | G12: =('MTD Utility Sheet'!I14/1.82)/0.5 -> 390.3956 | H12: =1.82*0.5 -> 0.91 | I12: ='MTD Utility Sheet'!H14/12.38 -> 204.84653 | J12: 12.38 | K12: =IF(('MTD Utility Sheet'!F14-2866)<0,"0",('MTD Utility Sheet'!F14-2866)/(0.568+0.075)) -> 10051.773 | L12: ='MTD Utility Sheet'!F14/K12 -> 0.92812383 | M12: ='MTD Utility Sheet'!B14*301 -> 282.94
A13: Amwaj Rotana - Jumeirah Beach | B13: =B12+1 -> 12 | C13: 10 | D13: 2024 | E13: ='MTD Utility Sheet'!G15/0.439 -> 15137.608 | F13: 0.439 | G13: =('MTD Utility Sheet'!I15/1.82)/0.5 -> 341.6044 | H13: =1.82*0.5 -> 0.91 | I13: ='MTD Utility Sheet'!H15/12.38 -> 186.72052 | J13: 12.38 | K13: =IF(('MTD Utility Sheet'!F15-2866)<0,"0",('MTD Utility Sheet'!F15-2866)/(0.568+0.075)) -> 10947.481 | L13: ='MTD Utility Sheet'!F15/K13 -> 0.9047954 | M13: ='MTD Utility Sheet'!B15*301 -> 266.084
A14: Amwaj Rotana - Jumeirah Beach | B14: =B13+1 -> 13 | C14: 10 | D14: 2024 | E14: ='MTD Utility Sheet'!G16/0.439 -> 15137.608 | F14: 0.439 | G14: =('MTD Utility Sheet'!I16/1.82)/0.5 -> 488 | H14: =1.82*0.5 -> 0.91 | I14: ='MTD Utility Sheet'!H16/12.38 -> 194.18417 | J14: 12.38 | K14: =IF(('MTD Utility Sheet'!F16-2866)<0,"0",('MTD Utility Sheet'!F16-2866)/(0.568+0.075)) -> 10341.804 | L14: ='MTD Utility Sheet'!F16/K14 -> 0.92012766 | M14: ='MTD Utility Sheet'!B16*301 -> 266.987
... A32: Amwaj Rotana - Jumeirah Beach | B32: =B31+1 -> 31 | C32: 10 | D32: 2024 | E32: ='MTD Utility Sheet'!G34/0.439 -> 14649.294 | F32: 1.439 | G32: =('MTD Utility Sheet'!I34/1.82)/0.5 -> 439.1978 | H32: =1.82*0.5 -> 0.91 | I32: ='MTD Utility Sheet'!H34/12.38 -> 293.3441 | J32: 13.38 | K32: =IF(('MTD Utility Sheet'!F34-2866)<0,"0",('MTD Utility Sheet'!F34-2866)/(0.568+0.075)) -> 8777.8849 | L32: ='MTD Utility Sheet'!F34/K32 -> 0.96950234 | M32: ='MTD Utility Sheet'!B34*301 -> 294.98

Sheet MTD Utility Sheet
A1: Daily Utilities October-2024
B3: Occ % | C3: Out. Temp at 2PM | D3: RH % | E3: F&B Covers | F3: Chilled water | G3: Electricity | H3: Water | I3: LPG | J3: Total
A4: 1 | B4: 0.8 | C4: 37.0c | D4: 0.68 | E4: 1176 | F4: 10084.41 | G4: 7074.14 | H4: 2588.8 | I4: 444.08 | J4: =SUM(F4+G4+H4+I4) -> 20191.43
A5: 2 | B5: 0.794 | C5: 38.0c | D5: 0.74 | E5: 1170 | F5: 10749.93 | G5: 7074.14 | H5: 2430.4 | I5: 355.26 | J5: =SUM(F5+G5+H5+I5) -> 20609.73
A6: 3 | B6: 0.7674 | C6: 38.0c | D6: 0.79 | E6: 1278 | F6: 11300.27 | G6: 7074.14 | H6: 2549.2 | I6: 488.49 | J6: =SUM(F6+G6+H6+I6) -> 21412.1
A7: 4 | B7: 83..72% | C7: 37c | D7: 0.68 | E7: 1295 | F7: 11501.39 | G7: 6859.78 | H7: 2232.4 | I7: 355 | J7: =SUM(F7+G7+H7+I7) -> 20948.57
A8: 5 | B8: 0.86 | C8: 36c | D8: 0.72 | E8: 1383 | F8: 10161.2 | G8: 7074.14 | H8: 2232.4 | I8: 355.26 | J8: =SUM(F8+G8+H8+I8) -> 19823
A9: 6 | B9: 0.84 | C9: 36c | D9: 0.68 | E9: 1296 | F9: 9848.55 | G9: 6859.78 | H9: 2364.4 | I9: 355.26 | J9: =SUM(F9+G9+H9+I9) -> 19427.99
A10: 7 | B10: 0.88 | C10: 38c | D10: 0.64 | E10: 1310 | F10: 9364.03 | G10: 6645.41 | H10: 2417.2 | I10: 355.26 | J10: =SUM(F10+G10+H10+I10) -> 18781.9
A11: 8 | B11: 0.87 | C11: 39c | D11: 0.58 | E11: 1315 | F11: 9490.19 | G11: 6859.78 | H11: 2272 | I11: 444.08 | J11: =SUM(F11+G11+H11+I11) -> 19066.05
A12: 9 | B12: 0.88 | C12: 37c | D12: 0.68 | E12: 1220 | F12: 9603.55 | G12: 6645.41 | H12: 2456.8 | I12: 355.26 | J12: =SUM(F12+G12+H12+I12) -> 19061.02
A13: 10 | B13: 0.9 | C13: 38.0c | D13: 0.81 | E13: 1377 | F13: 10214.22 | G13: 6645.41 | H13: 2549.2 | I13: 310.86 | J13: =SUM(F13+G13+H13+I13) -> 19719.69
A14: 11 | B14: 0.94 | C14: 37.0c | D14: 0.72 | E14: 1404 | F14: 9329.29 | G14: 7074.14 | H14: 2536 | I14: 355.26 | J14: =SUM(F14+G14+H14+I14) -> 19294.69
A15: 12 | B15: 0.884 | C15: 38c | D15: 0.64 | E15: 1394 | F15: 9905.23 | G15: 6645.41 | H15: 2311.6 | I15: 310.86 | J15: =SUM(F15+G15+H15+I15) -> 19173.1
A16: 13 | B16: 0.887 | C16: 36c | D16: 0.68 | E16: 1294 | F16: 9515.78 | G16: 6645.41 | H16: 2404 | I16: 444.08 | J16: =SUM(F16+G16+H16+I16) -> 19009.27
A17: 14 | B17: 0.97 | C17: 39c | D17: 0.58 | E17: 1287 | F17: 8877.68 | G17: 6431.04 | H17: 2509.6 | I17: 444.08 | J17: =SUM(F17+G17+H17+I17) -> 18262.4
A18: 15 | B18: 0.966 | C18: 38c | D18: 0.62 | E18: 1289 | F18: 9122.68 | G18: 6859.78 | H18: 2470 | I18: 444.08 | J18: =SUM(F18+G18+H18+I18) -> 18896.54
A19: 16 | B19: 0.98 | C19: 37c | D19: 0.68 | E19: 1288 | F19: 9133.65 | G19: 6645.41 | H19: 2958.4 | I19: 444.08 | J19: =SUM(F19+G19+H19+I19) -> 19181.54
... A33: 30 | B33: 1 | C33: 36.5c | D33: 0.79 | E33: 1469 | F33: 8182.9 | G33: 6645.41 | H33: 2932 | I33: 355.26 | J33: =SUM(F33+G33+H33+I33) -> 18115.57
A34: 31 | B34: 0.98 | C34: 35c | D34: 0.68 | F34: 8510.18 | G34: 6431.04 | H34: 3631.6 | I34: 399.67 | J34: =SUM(F34+G34+H34+I34) -> 18972.49
A35: Total Cost | F35: =SUM(F4:F34) -> 304047.03 | G35: =SUM(G4:G34) -> 210295.05 | H35: =SUM(H4:H34) -> 80120.8 | I35: =SUM(I4:I34) -> 12345.04 | J35: =SUM(J4:J34) -> 606807.92
A36: Total Units | B36: =AVERAGE(B4:B34) -> 0.90362333 | C36: =AVERAGE(C4:C34) -> #DIV/0! | D36: =AVERAGE(D4:D34) -> 0.67967742 | E36: =SUM(E4:E34) -> 40503 | F36: =F35*0.38 -> 115537.87 | G36: =G35/12.9 -> 16301.942 | H36: =H35/0.92 -> 87087.826 | I36: =I35/1.76 -> 7014.2273

Sheet October-31
A1: Daily Utilities Consumption
A2: 31.10.2024
A3: District Cooling
A4: Previous Reading MWh | B4: 69399.61 | C4: Current Reading MWh | D4: 69430.48 | E4: Consumption MWH | F4: =D4-B4 -> 30.87 | G4: Consumption RTH | H4: =F4*284.35 -> 8777.8845
A5: Cost Calculation
A6: Total Cost (0.568/rth) | D6: =H4*0.568 -> 4985.8384
A7: Total Fuel Surchage Cost (0.075/rth) | D7: =H4*0.075 -> 658.34134
A8: Chilled Water Demand (2,866 AED/Day) | D8: 2866
A9: Grand Total Exc. VAT | D9: =SUM(D6:H8) -> 8510.1797
A10: Electrical
A11: MDB-G1 (39299675-8) | C11: Previous Reading KWH | D11: 43002 | E11: Current Reading KWH | F11: 43009 | G11: Consumption KWH | H11: =F11-D11 -> 7
A12: MDB-G2 (39299676-6) | C12: Previous Reading KWH | D12: 71270 | E12: Current Reading KWH | F12: 71282 | G12: Consumption KWH | H12: =F12-D12 -> 12
A13: MDB-G3 (39299677-4) | C13: Previous Reading KWH | D13: 72137 | E13: Current Reading KWH | F13: 72148 | G13: Consumption KWH | H13: =F13-D13 -> 11
A14: Total Consumption KWH | H14: =SUM(H11:H13) -> 30
A15: Total Consumption * Multiplication Factor (487.20) | H15: =H14*487.2 -> 14616
A16: Cost Calculation
A17: 0-2000 kwh @ 0.230 /KWH | D17: 460
A18: 2000-4000 kwh @ 0.280 /KWH | D18: 560
A19: 4000-6000 kwh @ 0.320 /KWH | D19: 640
A20: 6000 & above @ 0.380 /KWH | D20: =H15*0.38 -> 5554.08
A21: Fuel Surcharge @ 0.060 /KWH | D21: =H15*0.06 -> 876.96
A22: Grand Total Exc. VAT | D22: =D20+D21 -> 6431.04
A23: WATER
A24: Previous Reading | B24: 297400 | C24: Present Reading | D24: 297688 | E24: Consumption m3 | F24: =D24-B24 -> 288 | G24: Consumption IG | H24: =F24*220 -> 63360
A25: Cost calculation
A26: 0-10000 @ 0.035 / IG | D26: 350
A27: 10000-20000 @ 0.04 / IG | D27: 400
A28: 20000 & above @ 0.046 / IG | D28: =(H24-20000)*0.046 -> 1994.56
A29: Fuel Surcharge @ 0.004 / IG | D29: =H24*0.004 -> 253.44
A30: Sewerage Fees | D30: =H24*0.01 -> 633.6
A31: Grand Total Exc. VAT | D31: =SUM(D26:H30) -> 3631.6
A32: LPG Gas
A33: Tank 1 (1% = 48 liters) | C33: Previous Reading % | D33: 80 | E33: Current Reading % | F33: 80 | G33: Consumption Liters | H33: =(D33-F33)*48.8 -> 0
A34: Tank 2 (1% = 48 liters) | C34: Previous Reading % | D34: 84 | E34: Current Reading % | F34: 75 | G34: Consumption Liters | H34: =(D34-F34)*48.8 -> 439.2
A35: Total Cost (@ 1.82 AED/Liter) | H35: =((H34+H33)*1.82)*0.5 -> 399.672
A36: Total Utilities | H36: =H35+D22+D9+D31 -> 18972.492

Sheet October-30
A1: Daily Utilities Consumption
A2: 30.10.2024
A3: District Cooling
A4: Previous Reading MWh | B4: 69370.53 | C4: Current Reading MWh | D4: 69399.61 | E4: Consumption MWH | F4: =D4-B4 -> 29.08 | G4: Consumption RTH | H4: =F4*284.35 -> 8268.898
A5: Cost Calculation
A6: Total Cost (0.568/rth) | D6: =H4*0.568 -> 4696.7341
A7: Total Fuel Surchage Cost (0.075/rth) | D7: =H4*0.075 -> 620.16735
A8: Chilled Water Demand (2,866 AED/Day) | D8: 2866
A9: Grand Total Exc. VAT | D9: =SUM(D6:H8) -> 8182.9014
A10: Electrical
A11: MDB-G1 (39299675-8) | C11: Previous Reading KWH | D11: 42995 | E11: Current Reading KWH | F11: 43002 | G11: Consumption KWH | H11: =F11-D11 -> 7
A12: MDB-G2 (39299676-6) | C12: Previous Reading KWH | D12: 71257 | E12: Current Reading KWH | F12: 71270 | G12: Consumption KWH | H12: =F12-D12 -> 13
A13: MDB-G3 (39299677-4) | C13: Previous Reading KWH | D13: 72126 | E13: Current Reading KWH | F13: 72137 | G13: Consumption KWH | H13: =F13-D13 -> 11
A14: Total Consumption KWH | H14: =SUM(H11:H13) -> 31
A15: Total Consumption * Multiplication Factor (487.20) | H15: =H14*487.2 -> 15103.2
A16: Cost Calculation
A17: 0-2000 kwh @ 0.230 /KWH | D17: 460
A18: 2000-4000 kwh @ 0.280 /KWH | D18: 560
A19: 4000-6000 kwh @ 0.320 /KWH | D19: 640
A20: 6000 & above @ 0.380 /KWH | D20: =H15*0.38 -> 5739.216
A21: Fuel Surcharge @ 0.060 /KWH | D21: =H15*0.06 -> 906.192
A22: Grand Total Exc. VAT | D22: =D20+D21 -> 6645.408
A23: WATER
A24: Previous Reading | B24: 297165 | C24: Present Reading | D24: 297400 | E24: Consumption m3 | F24: =D24-B24 -> 235 | G24: Consumption IG | H24: =F24*220 -> 51700
A25: Cost calculation
A26: 0-10000 @ 0.035 / IG | D26: 350
A27: 10000-20000 @ 0.04 / IG | D27: 400
A28: 20000 & above @ 0.046 / IG | D28: =(H24-20000)*0.046 -> 1458.2
A29: Fuel Surcharge @ 0.004 / IG | D29: =H24*0.004 -> 206.8
A30: Sewerage Fees | D30: =H24*0.01 -> 517
A31: Grand Total Exc. VAT | D31: =SUM(D26:H30) -> 2932
A32: LPG Gas
A33: Tank 1 (1% = 48 liters) | C33: Previous Reading % | D33: 80 | E33: Current Reading % | F33: 80 | G33: Consumption Liters | H33: =(D33-F33)*48.8 -> 0
A34: Tank 2 (1% = 48 liters) | C34: Previous Reading % | D34: 38 | E34: Current Reading % | F34: 30 | G34: Consumption Liters | H34: =(D34-F34)*48.8 -> 390.4
A35: Total Cost (@ 1.82 AED/Liter) | H35: =((H34+H33)*1.82)*0.5 -> 355.264
A36: Total Utilities | H36: =H35+D22+D9+D31 -> 18115.573

Sheet October-29
A1: Daily Utilities Consumption
A2: 29.10.2024
A3: District Cooling
A4: Previous Reading MWh | B4: 69338.46 | C4: Current Reading MWh | D4: 69370.53 | E4: Consumption MWH | F4: =D4-B4 -> 32.07 | G4: Consumption RTH | H4: =F4*284.35 -> 9119.1045
A5: Cost Calculation
A6: Total Cost (0.568/rth) | D6: =H4*0.568 -> 5179.6514
A7: Total Fuel Surchage Cost (0.075/rth) | D7: =H4*0.075 -> 683.93284
A8: Chilled Water Demand (2,866 AED/Day) | D8: 2866
A9: Grand Total Exc. VAT | D9: =SUM(D6:H8) -> 8729.5842
A10: Electrical
A11: MDB-G1 (39299675-8) | C11: Previous Reading KWH | D11: 42987 | E11: Current Reading KWH | F11: 42995 | G11: Consumption KWH | H11: =F11-D11 -> 8
A12: MDB-G2 (39299676-6) | C12: Previous Reading KWH | D12: 71244 | E12: Current Reading KWH | F12: 71257 | G12: Consumption KWH | H12: =F12-D12 -> 13
A13: MDB-G3 (39299677-4) | C13: Previous Reading KWH | D13: 72115 | E13: Current Reading KWH | F13: 72126 | G13: Consumption KWH | H13: =F13-D13 -> 11
A14: Total Consumption KWH | H14: =SUM(H11:H13) -> 32
A15: Total Consumption * Multiplication Factor (487.20) | H15: =H14*487.2 -> 15590.4
A16: Cost Calculation
A17: 0-2000 kwh @ 0.230 /KWH | D17: 460
A18: 2000-4000 kwh @ 0.280 /KWH | D18: 560
A19: 4000-6000 kwh @ 0.320 /KWH | D19: 640
A20: 6000 & above @ 0.380 /KWH | D20: =H15*0.38 -> 5924.352
A21: Fuel Surcharge @ 0.060 /KWH | D21: =H15*0.06 -> 935.424
A22: Grand Total Exc. VAT | D22: =D20+D21 -> 6859.776
A23: WATER
A24: Previous Reading | B24: 296945 | C24: Present Reading | D24: 297165 | E24: Consumption m3 | F24: =D24-B24 -> 220 | G24: Consumption IG | H24: =F24*220 -> 48400
A25: Cost calculation
A26: 0-10000 @ 0.035 / IG | D26: 350
A27: 10000-20000 @ 0.04 / IG | D27: 400
A28: 20000 & above @ 0.046 / IG | D28: =(H24-20000)*0.046 -> 1306.4
A29: Fuel Surcharge @ 0.004 / IG | D29: =H24*0.004 -> 193.6
A30: Sewerage Fees | D30: =H24*0.01 -> 484
A31: Grand Total Exc. VAT | D31: =SUM(D26:H30) -> 2734
A32: LPG Gas
A33: Tank 1 (1% = 48 liters) | C33: Previous Reading % | D33: 80 | E33: Current Reading % | F33: 80 | G33: Consumption Liters | H33: =(D33-F33)*48.8 -> 0
A34: Tank 2 (1% = 48 liters) | C34: Previous Reading % | D34: 48 | E34: Current Reading % | F34: 38 | G34: Consumption Liters | H34: =(D34-F34)*48.8 -> 488
A35: Total Cost (@ 1.82 AED/Liter) | H35: =((H34+H33)*1.82)*0.5 -> 444.08
A36: Total Utilities | H36: =H35+D22+D9+D31 -> 18767.44

Sheet October-28
A1: Daily Utilities Consumption
A2: 28.10.2024
A3: District Cooling
A4: Previous Reading MWh | B4: 69304.87 | C4: Current Reading MWh | D4: 69338.46 | E4: Consumption MWH | F4: =D4-B4 -> 33.59 | G4: Consumption RTH | H4: =F4*284.35 -> 9551.3165
A5: Cost Calculation
A6: Total Cost (0.568/rth) | D6: =H4*0.568 -> 5425.1478
A7: Total Fuel Surchage Cost (0.075/rth) | D7: =H4*0.075 -> 716.34874
A8: Chilled Water Demand (2,866 AED/Day) | D8: 2866
A9: Grand Total Exc. VAT | D9: =SUM(D6:H8) -> 9007.4965
A10: Electrical
A11: MDB-G1 (39299675-8) | C11: Previous Reading KWH | D11: 42980 | E11: Current Reading KWH | F11: 42987 | G11: Consumption KWH | H11: =F11-D11 -> 7
A12: MDB-G2 (39299676-6) | C12: Previous Reading KWH | D12: 71231 | E12: Current Reading KWH | F12: 71244 | G12: Consumption KWH | H12: =F12-D12 -> 13
A13: MDB-G3 (39299677-4) | C13: Previous Reading KWH | D13: 72104 | E13: Current Reading KWH | F13: 72115 | G13: Consumption KWH | H13: =F13-D13 -> 11
A14: Total Consumption KWH | H14: =SUM(H11:H13) -> 31
A15: Total Consumption * Multiplication Factor (487.20) | H15: =H14*487.2 -> 15103.2
A16: Cost Calculation
A17: 0-2000 kwh @ 0.230 /KWH | D17: 460
A18: 2000-4000 kwh @ 0.280 /KWH | D18: 560
A19: 4000-6000 kwh @ 0.320 /KWH | D19: 640
A20: 6000 & above @ 0.380 /KWH | D20: =H15*0.38 -> 5739.216
A21: Fuel Surcharge @ 0.060 /KWH | D21: =H15*0.06 -> 906.192
A22: Grand Total Exc. VAT | D22: =D20+D21 -> 6645.408
A23: WATER
A24: Previous Reading | B24: 296725 | C24: Present Reading | D24: 296945 | E24: Consumption m3 | F24: =D24-B24 -> 220 | G24: Consumption IG | H24: =F24*220 -> 48400
A25: Cost calculation
A26: 0-10000 @ 0.035 / IG | D26: 350
A27: 10000-20000 @ 0.04 / IG | D27: 400
A28: 20000 & above @ 0.046 / IG | D28: =(H24-20000)*0.046 -> 1306.4
A29: Fuel Surcharge @ 0.004 / IG | D29: =H24*0.004 -> 193.6
A30: Sewerage Fees | D30: =H24*0.01 -> 484
A31: Grand Total Exc. VAT | D31: =SUM(D26:H30) -> 2734
A32: LPG Gas
A33: Tank 1 (1% = 48 liters) | C33: Previous Reading % | D33: 80 | E33: Current Reading % | F33: 80 | G33: Consumption Liters | H33: =(D33-F33)*48.8 -> 0
A34: Tank 2 (1% = 48 liters) | C34: Previous Reading % | D34: 57 | E34: Current Reading % | F34: 48 | G34: Consumption Liters | H34: =(D34-F34)*48.8 -> 439.2
A35: Total Cost (@ 1.82 AED/Liter) | H35: =((H34+H33)*1.82)*0.5 -> 399.672
A36: Total Utilities | H36: =H35+D22+D9+D31 -> 18786.577

Sheet October-27
A1: Daily Utilities Consumption
A2: 27.10.2024
A3: District Cooling
A4: Previous Reading MWh | B4: 69265.44 | C4: Current Reading MWh | D4: 69304.87 | E4: Consumption MWH | F4: =D4-B4 -> 39.43 | G4: Consumption RTH | H4: =F4*284.35 -> 11211.92
A5: Cost Calculation
A6: Total Cost (0.568/rth) | D6: =H4*0.568 -> 6368.3708
A7: Total Fuel Surchage Cost (0.075/rth) | D7: =H4*0.075 -> 840.89404
A8: Chilled Water Demand (2,866 AED/Day) | D8: 2866
A9: Grand Total Exc. VAT | D9: =SUM(D6:H8) -> 10075.265
A10: Electrical
A11: MDB-G1 (39299675-8) | C11: Previous Reading KWH | D11: 42973 | E11: Current Reading KWH | F11: 42980 | G11: Consumption KWH | H11: =F11-D11 -> 7
A12: MDB-G2 (39299676-6) | C12: Previous Reading KWH | D12: 71219 | E12: Current Reading KWH | F12: 71231 | G12: Consumption KWH | H12: =F12-D12 -> 12
A13: MDB-G3 (39299677-4) | C13: Previous Reading KWH | D13: 72092 | E13: Current Reading KWH | F13: 72104 | G13: Consumption KWH | H13: =F13-D13 -> 12
A14: Total Consumption KWH | H14: =SUM(H11:H13) -> 31
A15: Total Consumption * Multiplication Factor (487.20) | H15: =H14*487.2 -> 15103.2
A16: Cost Calculation
A17: 0-2000 kwh @ 0.230 /KWH | D17: 460
A18: 2000-4000 kwh @ 0.280 /KWH | D18: 560
A19: 4000-6000 kwh @ 0.320 /KWH | D19: 640
A20: 6000 & above @ 0.380 /KWH | D20: =H15*0.38 -> 5739.216
A21: Fuel Surcharge @ 0.060 /KWH | D21: =H15*0.06 -> 906.192
A22: Grand Total Exc. VAT | D22: =D20+D21 -> 6645.408
A23: WATER
A24: Previous Reading | B24: 296513 | C24: Present Reading | D24: 296725 | E24: Consumption m3 | F24: =D24-B24 -> 212 | G24: Consumption IG | H24: =F24*220 -> 46640
A25: Cost calculation
A26: 0-10000 @ 0.035 / IG | D26: 350
A27: 10000-20000 @ 0.04 / IG | D27: 400
A28: 20000 & above @ 0.046 / IG | D28: =(H24-20000)*0.046 -> 1225.44
A29: Fuel Surcharge @ 0.004 / IG | D29: =H24*0.004 -> 186.56
A30: Sewerage Fees | D30: =H24*0.01 -> 466.4
A31: Grand Total Exc. VAT | D31: =SUM(D26:H30) -> 2628.4
A32: LPG Gas
A33: Tank 1 (1% = 48 liters) | C33: Previous Reading % | D33: 80 | E33: Current Reading % | F33: 80 | G33: Consumption Liters | H33: =(D33-F33)*48.8 -> 0
A34: Tank 2 (1% = 48 liters) | C34: Previous Reading % | D34: 65 | E34: Current Reading % | F34: 57 | G34: Consumption Liters | H34: =(D34-F34)*48.8 -> 390.4
A35: Total Cost (@ 1.82 AED/Liter) | H35: =((H34+H33)*1.82)*0.5 -> 355.264
A36: Total Utilities | H36: =H35+D22+D9+D31 -> 19704.337

Sheet October-26
A1: Daily Utilities Consumption
A2: 26.10.2024
A3: District Cooling
A4: Previous Reading MWh | B4: 69224.19 | C4: Current Reading MWh | D4: 69265.44 | E4: Consumption MWH | F4: =D4-B4 -> 41.25 | G4: Consumption RTH | H4: =F4*284.35 -> 11729.438
A5: Cost Calculation
A6: Total Cost (0.568/rth) | D6: =H4*0.568 -> 6662.3205
A7: Total Fuel Surchage Cost (0.075/rth) | D7: =H4*0.075 -> 879.70781
A8: Chilled Water Demand (2,866 AED/Day) | D8: 2866
A9: Grand Total Exc. VAT | D9: =SUM(D6:H8) -> 10408.028
A10: Electrical
A11: MDB-G1 (39299675-8) | C11: Previous Reading KWH | D11: 42966 | E11: Current Reading KWH | F11: 42973 | G11: Consumption KWH | H11: =F11-D11 -> 7
A12: MDB-G2 (39299676-6) | C12: Previous Reading KWH | D12: 71206 | E12: Current Reading KWH | F12: 71219 | G12: Consumption KWH | H12: =F12-D12 -> 13
A13: MDB-G3 (39299677-4) | C13: Previous Reading KWH | D13: 72080 | E13: Current Reading KWH | F13: 72092 | G13: Consumption KWH | H13: =F13-D13 -> 12
A14: Total Consumption KWH | H14: =SUM(H11:H13) -> 32
A15: Total Consumption * Multiplication Factor (487.20) | H15: =H14*487.2 -> 15590.4
A16: Cost Calculation
A17: 0-2000 kwh @ 0.230 /KWH | D17: 460
A18: 2000-4000 kwh @ 0.280 /KWH | D18: 560
A19: 4000-6000 kwh @ 0.320 /KWH | D19: 640
A20: 6000 & above @ 0.380 /KWH | D20: =H15*0.38 -> 5924.352
A21: Fuel Surcharge @ 0.060 /KWH | D21: =H15*0.06 -> 935.424
A22: Grand Total Exc. VAT | D22: =D20+D21 -> 6859.776
A23: WATER
A24: Previous Reading | B24: 296304 | C24: Present Reading | D24: 296513 | E24: Consumption m3 | F24: =D24-B24 -> 209 | G24: Consumption IG | H24: =F24*220 -> 45980
A25: Cost calculation
A26: 0-10000 @ 0.035 / IG | D26: 350
A27: 10000-20000 @ 0.04 / IG | D27: 400
A28: 20000 & above @ 0.046 / IG | D28: =(H24-20000)*0.046 -> 1195.08
A29: Fuel Surcharge @ 0.004 / IG | D29: =H24*0.004 -> 183.92
A30: Sewerage Fees | D30: =H24*0.01 -> 459.8
A31: Grand Total Exc. VAT | D31: =SUM(D26:H30) -> 2588.8
A32: LPG Gas
A33: Tank 1 (1% = 48 liters) | C33: Previous Reading % | D33: 80 | E33: Current Reading % | F33: 80 | G33: Consumption Liters | H33: =(D33-F33)*48.8 -> 0
A34: Tank 2 (1% = 48 liters) | C34: Previous Reading % | D34: 75 | E34: Current Reading % | F34: 65 | G34: Consumption Liters | H34: =(D34-F34)*48.8 -> 488
A35: Total Cost (@ 1.82 AED/Liter) | H35: =((H34+H33)*1.82)*0.5 -> 444.08
A36: Total Utilities | H36: =H35+D22+D9+D31 -> 20300.684

Sheet October-25
A1: Daily Utilities Consumption
A2: 25.10.2024
A3: District Cooling
A4: Previous Reading MWh | B4: 69184.75 | C4: Current Reading MWh | D4: 69224.19 | E4: Consumption MWH | F4: =D4-B4 -> 39.44 | G4: Consumption RTH | H4: =F4*284.35 -> 11214.764
A5: Cost Calculation
A6: Total Cost (0.568/rth) | D6: =H4*0.568 -> 6369.986
A7: Total Fuel Surchage Cost (0.075/rth) | D7: =H4*0.075 -> 841.1073
A8: Chilled Water Demand (2,866 AED/Day) | D8: 2866
A9: Grand Total Exc. VAT | D9: =SUM(D6:H8) -> 10077.093
A10: Electrical
A11: MDB-G1 (39299675-8) | C11: Previous Reading KWH | D11: 42958 | E11: Current Reading KWH | F11: 42966 | G11: Consumption KWH | H11: =F11-D11 -> 8
A12: MDB-G2 (39299676-6) | C12: Previous Reading KWH | D12: 71194 | E12: Current Reading KWH | F12: 71206 | G12: Consumption KWH | H12: =F12-D12 -> 12
A13: MDB-G3 (39299677-4) | C13: Previous Reading KWH | D13: 72069 | E13: Current Reading KWH | F13: 72080 | G13: Consumption KWH | H13: =F13-D13 -> 11
A14: Total Consumption KWH | H14: =SUM(H11:H13) -> 31
A15: Total Consumption * Multiplication Factor (487.20) | H15: =H14*487.2 -> 15103.2
A16: Cost Calculation
A17: 0-2000 kwh @ 0.230 /KWH | D17: 460
A18: 2000-4000 kwh @ 0.280 /KWH | D18: 560
A19: 4000-6000 kwh @ 0.320 /KWH | D19: 640
A20: 6000 & above @ 0.380 /KWH | D20: =H15*0.38 -> 5739.216
A21: Fuel Surcharge @ 0.060 /KWH | D21: =H15*0.06 -> 906.192
A22: Grand Total Exc. VAT | D22: =D20+D21 -> 6645.408
A23: WATER
A24: Previous Reading | B24: 296100 | C24: Present Reading | D24: 296304 | E24: Consumption m3 | F24: =D24-B24 -> 204 | G24: Consumption IG | H24: =F24*220 -> 44880
A25: Cost calculation
A26: 0-10000 @ 0.035 / IG | D26: 350
A27: 10000-20000 @ 0.04 / IG | D27: 400
A28: 20000 & above @ 0.046 / IG | D28: =(H24-20000)*0.046 -> 1144.48
A29: Fuel Surcharge @ 0.004 / IG | D29: =H24*0.004 -> 179.52
A30: Sewerage Fees | D30: =H24*0.01 -> 448.8
A31: Grand Total Exc. VAT | D31: =SUM(D26:H30) -> 2522.8
A32: LPG Gas
A33: Tank 1 (1% = 48 liters) | C33: Previous Reading % | D33: 80 | E33: Current Reading % | F33: 80 | G33: Consumption Liters | H33: =(D33-F33)*48.8 -> 0
A34: Tank 2 (1% = 48 liters) | C34: Previous Reading % | D34: 84 | E34: Current Reading % | F34: 75 | G34: Consumption Liters | H34: =(D34-F34)*48.8 -> 439.2
A35: Total Cost (@ 1.82 AED/Liter) | H35: =((H34+H33)*1.82)*0.5 -> 399.672
A36: Total Utilities | H36: =H35+D22+D9+D31 -> 19644.973

Sheet October-24
A1: Daily Utilities Consumption
A2: 24.10.2024
A3: District Cooling
A4: Previous Reading MWh | B4: 69148.32 | C4: Current Reading MWh | D4: 69184.75 | E4: Consumption MWH | F4: =D4-B4 -> 36.43 | G4: Consumption RTH | H4: =F4*284.35 -> 10358.87
A5: Cost Calculation
A6: Total Cost (0.568/rth) | D6: =H4*0.568 -> 5883.8384
A7: Total Fuel Surchage Cost (0.075/rth) | D7: =H4*0.075 -> 776.91529
A8: Chilled Water Demand (2,866 AED/Day) | D8: 2866
A9: Grand Total Exc. VAT | D9: =SUM(D6:H8) -> 9526.7537
A10: Electrical
A11: MDB-G1 (39299675-8) | C11: Previous Reading KWH | D11: 42951 | E11: Current Reading KWH | F11: 42958 | G11: Consumption KWH | H11: =F11-D11 -> 7
A12: MDB-G2 (39299676-6) | C12: Previous Reading KWH | D12: 71181 | E12: Current Reading KWH | F12: 71194 | G12: Consumption KWH | H12: =F12-D12 -> 13
A13: MDB-G3 (39299677-4) | C13: Previous Reading KWH | D13: 72058 | E13: Current Reading KWH | F13: 72069 | G13: Consumption KWH | H13: =F13-D13 -> 11
A14: Total Consumption KWH | H14: =SUM(H11:H13) -> 31
A15: Total Consumption * Multiplication Factor (487.20) | H15: =H14*487.2 -> 15103.2
A16: Cost Calculation
A17: 0-2000 kwh @ 0.230 /KWH | D17: 460
A18: 2000-4000 kwh @ 0.280 /KWH | D18: 560
A19: 4000-6000 kwh @ 0.320 /KWH | D19: 640
A20: 6000 & above @ 0.380 /KWH | D20: =H15*0.38 -> 5739.216
A21: Fuel Surcharge @ 0.060 /KWH | D21: =H15*0.06 -> 906.192
A22: Grand Total Exc. VAT | D22: =D20+D21 -> 6645.408
A23: WATER
A24: Previous Reading | B24: 295885 | C24: Present Reading | D24: 296100 | E24: Consumption m3 | F24: =D24-B24 -> 215 | G24: Consumption IG | H24: =F24*220 -> 47300
A25: Cost calculation
A26: 0-10000 @ 0.035 / IG | D26: 350
A27: 10000-20000 @ 0.04 / IG | D27: 400
A28: 20000 & above @ 0.046 / IG | D28: =(H24-20000)*0.046 -> 1255.8
A29: Fuel Surcharge @ 0.004 / IG | D29: =H24*0.004 -> 189.2
A30: Sewerage Fees | D30: =H24*0.01 -> 473
A31: Grand Total Exc. VAT | D31: =SUM(D26:H30) -> 2668
A32: LPG Gas
A33: Tank 1 (1% = 48 liters) | C33: Previous Reading % | D33: 80 | E33: Current Reading % | F33: 80 | G33: Consumption Liters | H33: =(D33-F33)*48.8 -> 0
A34: Tank 2 (1% = 48 liters) | C34: Previous Reading % | D34: 80 | E34: Current Reading % | F34: 72 | G34: Consumption Liters | H34: =(D34-F34)*48.8 -> 390.4
A35: Total Cost (@ 1.82 AED/Liter) | H35: =((H34+H33)*1.82)*0.5 -> 355.264
A36: Total Utilities | H36: =H35+D22+D9+D31 -> 19195.426

Sheet October-23
A1: Daily Utilities Consumption
A2: 23.10.2024
A3: District Cooling
A4: Previous Reading MWh | B4: 69110.4 | C4: Current Reading MWh | D4: 69148.32 | E4: Consumption MWH | F4: =D4-B4 -> 37.92 | G4: Consumption RTH | H4: =F4*284.35 -> 10782.552
A5: Cost Calculation
A6: Total Cost (0.568/rth) | D6: =H4*0.568 -> 6124.4895
A7: Total Fuel Surchage Cost (0.075/rth) | D7: =H4*0.075 -> 808.6914
A8: Chilled Water Demand (2,866 AED/Day) | D8: 2866
A9: Grand Total Exc. VAT | D9: =SUM(D6:H8) -> 9799.1809
A10: Electrical
A11: MDB-G1 (39299675-8) | C11: Previous Reading KWH | D11: 42943 | E11: Current Reading KWH | F11: 42951 | G11: Consumption KWH | H11: =F11-D11 -> 8
A12: MDB-G2 (39299676-6) | C12: Previous Reading KWH | D12: 71169 | E12: Current Reading KWH | F12: 71181 | G12: Consumption KWH | H12: =F12-D12 -> 12
A13: MDB-G3 (39299677-4) | C13: Previous Reading KWH | D13: 72046 | E13: Current Reading KWH | F13: 72058 | G13: Consumption KWH | H13: =F13-D13 -> 12
A14: Total Consumption KWH | H14: =SUM(H11:H13) -> 32
A15: Total Consumption * Multiplication Factor (487.20) | H15: =H14*487.2 -> 15590.4
A16: Cost Calculation
A17: 0-2000 kwh @ 0.230 /KWH | D17: 460
A18: 2000-4000 kwh @ 0.280 /KWH | D18: 560
A19: 4000-6000 kwh @ 0.320 /KWH | D19: 640
A20: 6000 & above @ 0.380 /KWH | D20: =H15*0.38 -> 5924.352
A21: Fuel Surcharge @ 0.060 /KWH | D21: =H15*0.06 -> 935.424
A22: Grand Total Exc. VAT | D22: =D20+D21 -> 6859.776
A23: WATER
A24: Previous Reading | B24: 295664 | C24: Present Reading | D24: 295885 | E24: Consumption m3 | F24: =D24-B24 -> 221 | G24: Consumption IG | H24: =F24*220 -> 48620
A25: Cost calculation
A26: 0-10000 @ 0.035 / IG | D26: 350
A27: 10000-20000 @ 0.04 / IG | D27: 400
A28: 20000 & above @ 0.046 / IG | D28: =(H24-20000)*0.046 -> 1316.52
A29: Fuel Surcharge @ 0.004 / IG | D29: =H24*0.004 -> 194.48
A30: Sewerage Fees | D30: =H24*0.01 -> 486.2
A31: Grand Total Exc. VAT | D31: =SUM(D26:H30) -> 2747.2
A32: LPG Gas
A33: Tank 1 (1% = 48 liters) | C33: Previous Reading % | D33: 28 | E33: Current Reading % | F33: 19 | G33: Consumption Liters | H33: =(D33-F33)*48.8 -> 439.2
A34: Tank 2 (1% = 48 liters) | C34: Previous Reading % | D34: 80 | E34: Current Reading % | F34: 80 | G34: Consumption Liters | H34: =(D34-F34)*48.8 -> 0
A35: Total Cost (@ 1.82 AED/Liter) | H35: =((H34+H33)*1.82)*0.5 -> 399.672
A36: Total Utilities | H36: =H35+D22+D9+D31 -> 19805.829

Sheet October-22
A1: Daily Utilities Consumption
A2: 22.10.2024
A3: District Cooling
A4: Previous Reading MWh | B4: 69070.13 | C4: Current Reading MWh | D4: 69110.4 | E4: Consumption MWH | F4: =D4-B4 -> 40.27 | G4: Consumption RTH | H4: =F4*284.35 -> 11450.774
A5: Cost Calculation
A6: Total Cost (0.568/rth) | D6: =H4*0.568 -> 6504.0399
A7: Total Fuel Surchage Cost (0.075/rth) | D7: =H4*0.075 -> 858.80809
A8: Chilled Water Demand (2,866 AED/Day) | D8: 2866
A9: Grand Total Exc. VAT | D9: =SUM(D6:H8) -> 10228.848
A10: Electrical
A11: MDB-G1 (39299675-8) | C11: Previous Reading KWH | D11: 42936 | E11: Current Reading KWH | F11: 42943 | G11: Consumption KWH | H11: =F11-D11 -> 7
A12: MDB-G2 (39299676-6) | C12: Previous Reading KWH | D12: 71156 | E12: Current Reading KWH | F12: 71169 | G12: Consumption KWH | H12: =F12-D12 -> 13
A13: MDB-G3 (39299677-4) | C13: Previous Reading KWH | D13: 72035 | E13: Current Reading KWH | F13: 72046 | G13: Consumption KWH | H13: =F13-D13 -> 11
A14: Total Consumption KWH | H14: =SUM(H11:H13) -> 31
A15: Total Consumption * Multiplication Factor (487.20) | H15: =H14*487.2 -> 15103.2
A16: Cost Calculation
A17: 0-2000 kwh @ 0.230 /KWH | D17: 460
A18: 2000-4000 kwh @ 0.280 /KWH | D18: 560
A19: 4000-6000 kwh @ 0.320 /KWH | D19: 640
A20: 6000 & above @ 0.380 /KWH | D20: =H15*0.38 -> 5739.216
A21: Fuel Surcharge @ 0.060 /KWH | D21: =H15*0.06 -> 906.192
A22: Grand Total Exc. VAT | D22: =D20+D21 -> 6645.408
A23: WATER
A24: Previous Reading | B24: 295455 | C24: Present Reading | D24: 295664 | E24: Consumption m3 | F24: =D24-B24 -> 209 | G24: Consumption IG | H24: =F24*220 -> 45980
A25: Cost calculation
A26: 0-10000 @ 0.035 / IG | D26: 350
A27: 10000-20000 @ 0.04 / IG | D27: 400
A28: 20000 & above @ 0.046 / IG | D28: =(H24-20000)*0.046 -> 1195.08
A29: Fuel Surcharge @ 0.004 / IG | D29: =H24*0.004 -> 183.92
A30: Sewerage Fees | D30: =H24*0.01 -> 459.8
A31: Grand Total Exc. VAT | D31: =SUM(D26:H30) -> 2588.8
A32: LPG Gas
A33: Tank 1 (1% = 48 liters) | C33: Previous Reading % | D33: 36 | E33: Current Reading % | F33: 28 | G33: Consumption Liters | H33: =(D33-F33)*48.8 -> 390.4
A34: Tank 2 (1% = 48 liters) | C34: Previous Reading % | D34: 80 | E34: Current Reading % | F34: 80 | G34: Consumption Liters | H34: =(D34-F34)*48.8 -> 0
A35: Total Cost (@ 1.82 AED/Liter) | H35: =((H34+H33)*1.82)*0.5 -> 355.264
A36: Total Utilities | H36: =H35+D22+D9+D31 -> 19818.32

Sheet October-21
A1: Daily Utilities Consumption
A2: 21.10.2024
A3: District Cooling
A4: Previous Reading MWh | B4: 69029 | C4: Current Reading MWh | D4: 69070.13 | E4: Consumption MWH | F4: =D4-B4 -> 41.13 | G4: Consumption RTH | H4: =F4*284.35 -> 11695.316
A5: Cost Calculation
A6: Total Cost (0.568/rth) | D6: =H4*0.568 -> 6642.9392
A7: Total Fuel Surchage Cost (0.075/rth) | D7: =H4*0.075 -> 877.14866
A8: Chilled Water Demand (2,866 AED/Day) | D8: 2866
A9: Grand Total Exc. VAT | D9: =SUM(D6:H8) -> 10386.088
A10: Electrical
A11: MDB-G1 (39299675-8) | C11: Previous Reading KWH | D11: 42928 | E11: Current Reading KWH | F11: 42936 | G11: Consumption KWH | H11: =F11-D11 -> 8
A12: MDB-G2 (39299676-6) | C12: Previous Reading KWH | D12: 71143 | E12: Current Reading KWH | F12: 71156 | G12: Consumption KWH | H12: =F12-D12 -> 13
A13: MDB-G3 (39299677-4) | C13: Previous Reading KWH | D13: 72024 | E13: Current Reading KWH | F13: 72035 | G13: Consumption KWH | H13: =F13-D13 -> 11
A14: Total Consumption KWH | H14: =SUM(H11:H13) -> 32
A15: Total Consumption * Multiplication Factor (487.20) | H15: =H14*487.2 -> 15590.4
A16: Cost Calculation
A17: 0-2000 kwh @ 0.230 /KWH | D17: 460
A18: 2000-4000 kwh @ 0.280 /KWH | D18: 560
A19: 4000-6000 kwh @ 0.320 /KWH | D19: 640
A20: 6000 & above @ 0.380 /KWH | D20: =H15*0.38 -> 5924.352
A21: Fuel Surcharge @ 0.060 /KWH | D21: =H15*0.06 -> 935.424
A22: Grand Total Exc. VAT | D22: =D20+D21 -> 6859.776
A23: WATER
A24: Previous Reading | B24: 295253 | C24: Present Reading | D24: 295455 | E24: Consumption m3 | F24: =D24-B24 -> 202 | G24: Consumption IG | H24: =F24*220 -> 44440
A25: Cost calculation
A26: 0-10000 @ 0.035 / IG | D26: 350
A27: 10000-20000 @ 0.04 / IG | D27: 400
A28: 20000 & above @ 0.046 / IG | D28: =(H24-20000)*0.046 -> 1124.24
A29: Fuel Surcharge @ 0.004 / IG | D29: =H24*0.004 -> 177.76
A30: Sewerage Fees | D30: =H24*0.01 -> 444.4
A31: Grand Total Exc. VAT | D31: =SUM(D26:H30) -> 2496.4
A32: LPG Gas
A33: Tank 1 (1% = 48 liters) | C33: Previous Reading % | D33: 45 | E33: Current Reading % | F33: 36 | G33: Consumption Liters | H33: =(D33-F33)*48.8 -> 439.2
A34: Tank 2 (1% = 48 liters) | C34: Previous Reading % | D34: 80 | E34: Current Reading % | F34: 80 | G34: Consumption Liters | H34: =(D34-F34)*48.8 -> 0
A35: Total Cost (@ 1.82 AED/Liter) | H35: =((H34+H33)*1.82)*0.5 -> 399.672
A36: Total Utilities | H36: =H35+D22+D9+D31 -> 20141.936

Sheet October-20
A1: Daily Utilities Consumption
A2: 20.10.2024
A3: District Cooling
A4: Previous Reading MWh | B4: 68987.93 | C4: Current Reading MWh | D4: 69029 | E4: Consumption MWH | F4: =D4-B4 -> 41.07 | G4: Consumption RTH | H4: =F4*284.35 -> 11678.255
A5: Cost Calculation
A6: Total Cost (0.568/rth) | D6: =H4*0.568 -> 6633.2486
A7: Total Fuel Surchage Cost (0.075/rth) | D7: =H4*0.075 -> 875.86909
A8: Chilled Water Demand (2,866 AED/Day) | D8: 2866
A9: Grand Total Exc. VAT | D9: =SUM(D6:H8) -> 10375.118
A10: Electrical
A11: MDB-G1 (39299675-8) | C11: Previous Reading KWH | D11: 42921 | E11: Current Reading KWH | F11: 42928 | G11: Consumption KWH | H11: =F11-D11 -> 7
A12: MDB-G2 (39299676-6) | C12: Previous Reading KWH | D12: 71130 | E12: Current Reading KWH | F12: 71143 | G12: Consumption KWH | H12: =F12-D12 -> 13
A13: MDB-G3 (39299677-4) | C13: Previous Reading KWH | D13: 72013 | E13: Current Reading KWH | F13: 72024 | G13: Consumption KWH | H13: =F13-D13 -> 11
A14: Total Consumption KWH | H14: =SUM(H11:H13) -> 31
A15: Total Consumption * Multiplication Factor (487.20) | H15: =H14*487.2 -> 15103.2
A16: Cost Calculation
A17: 0-2000 kwh @ 0.230 /KWH | D17: 460
A18: 2000-4000 kwh @ 0.280 /KWH | D18: 560
A19: 4000-6000 kwh @ 0.320 /KWH | D19: 640
A20: 6000 & above @ 0.380 /KWH | D20: =H15*0.38 -> 5739.216
A21: Fuel Surcharge @ 0.060 /KWH | D21: =H15*0.06 -> 906.192
A22: Grand Total Exc. VAT | D22: =D20+D21 -> 6645.408
A23: WATER
A24: Previous Reading | B24: 295038 | C24: Present Reading | D24: 295253 | E24: Consumption m3 | F24: =D24-B24 -> 215 | G24: Consumption IG | H24: =F24*220 -> 47300
A25: Cost calculation
A26: 0-10000 @ 0.035 / IG | D26: 350
A27: 10000-20000 @ 0.04 / IG | D27: 400
A28: 20000 & above @ 0.046 / IG | D28: =(H24-20000)*0.046 -> 1255.8
A29: Fuel Surcharge @ 0.004 / IG | D29: =H24*0.004 -> 189.2
A30: Sewerage Fees | D30: =H24*0.01 -> 473
A31: Grand Total Exc. VAT | D31: =SUM(D26:H30) -> 2668
A32: LPG Gas
A33: Tank 1 (1% = 48 liters) | C33: Previous Reading % | D33: 55 | E33: Current Reading % | F33: 45 | G33: Consumption Liters | H33: =(D33-F33)*48.8 -> 488
A34: Tank 2 (1% = 48 liters) | C34: Previous Reading % | D34: 80 | E34: Current Reading % | F34: 80 | G34: Consumption Liters | H34: =(D34-F34)*48.8 -> 0
A35: Total Cost (@ 1.82 AED/Liter) | H35: =((H34+H33)*1.82)*0.5 -> 444.08
A36: Total Utilities | H36: =H35+D22+D9+D31 -> 20132.606

Sheet October-19
A1: Daily Utilities Consumption
A2: 19.10.2024
A3: District Cooling
A4: Previous Reading MWh | B4: 68946.64 | C4: Current Reading MWh | D4: 68987.93 | E4: Consumption MWH | F4: =D4-B4 -> 41.29 | G4: Consumption RTH | H4: =F4*284.35 -> 11740.811
A5: Cost Calculation
A6: Total Cost (0.568/rth) | D6: =H4*0.568 -> 6668.7809
A7: Total Fuel Surchage Cost (0.075/rth) | D7: =H4*0.075 -> 880.56086
A8: Chilled Water Demand (2,866 AED/Day) | D8: 2866
A9: Grand Total Exc. VAT | D9: =SUM(D6:H8) -> 10415.342
A10: Electrical
A11: MDB-G1 (39299675-8) | C11: Previous Reading KWH | D11: 42914 | E11: Current Reading KWH | F11: 42921 | G11: Consumption KWH | H11: =F11-D11 -> 7
A12: MDB-G2 (39299676-6) | C12: Previous Reading KWH | D12: 71117 | E12: Current Reading KWH | F12: 71130 | G12: Consumption KWH | H12: =F12-D12 -> 13
A13: MDB-G3 (39299677-4) | C13: Previous Reading KWH | D13: 72001 | E13: Current Reading KWH | F13: 72013 | G13: Consumption KWH | H13: =F13-D13 -> 12
A14: Total Consumption KWH | H14: =SUM(H11:H13) -> 32
A15: Total Consumption * Multiplication Factor (487.20) | H15: =H14*487.2 -> 15590.4
A16: Cost Calculation
A17: 0-2000 kwh @ 0.230 /KWH | D17: 460
A18: 2000-4000 kwh @ 0.280 /KWH | D18: 560
A19: 4000-6000 kwh @ 0.320 /KWH | D19: 640
A20: 6000 & above @ 0.380 /KWH | D20: =H15*0.38 -> 5924.352
A21: Fuel Surcharge @ 0.060 /KWH | D21: =H15*0.06 -> 935.424
A22: Grand Total Exc. VAT | D22: =D20+D21 -> 6859.776
A23: WATER
A24: Previous Reading | B24: 294829 | C24: Present Reading | D24: 295038 | E24: Consumption m3 | F24: =D24-B24 -> 209 | G24: Consumption IG | H24: =F24*220 -> 45980
A25: Cost calculation
A26: 0-10000 @ 0.035 / IG | D26: 350
A27: 10000-20000 @ 0.04 / IG | D27: 400
A28: 20000 & above @ 0.046 / IG | D28: =(H24-20000)*0.046 -> 1195.08
A29: Fuel Surcharge @ 0.004 / IG | D29: =H24*0.004 -> 183.92
A30: Sewerage Fees | D30: =H24*0.01 -> 459.8
A31: Grand Total Exc. VAT | D31: =SUM(D26:H30) -> 2588.8
A32: LPG Gas
A33: Tank 1 (1% = 48 liters) | C33: Previous Reading % | D33: 65 | E33: Current Reading % | F33: 55 | G33: Consumption Liters | H33: =(D33-F33)*48.8 -> 488
A34: Tank 2 (1% = 48 liters) | C34: Previous Reading % | D34: 80 | E34: Current Reading % | F34: 80 | G34: Consumption Liters | H34: =(D34-F34)*48.8 -> 0
A35: Total Cost (@ 1.82 AED/Liter) | H35: =((H34+H33)*1.82)*0.5 -> 444.08
A36: Total Utilities | H36: =H35+D22+D9+D31 -> 20307.998

Sheet October-18
A1: Daily Utilities Consumption
A2: 18.10.2024
A3: District Cooling
A4: Previous Reading MWh | B4: 68905.26 | C4: Current Reading MWh | D4: 68946.64 | E4: Consumption MWH | F4: =D4-B4 -> 41.38 | G4: Consumption RTH | H4: =F4*284.35 -> 11766.403
A5: Cost Calculation
A6: Total Cost (0.568/rth) | D6: =H4*0.568 -> 6683.3169
A7: Total Fuel Surchage Cost (0.075/rth) | D7: =H4*0.075 -> 882.48023
A8: Chilled Water Demand (2,866 AED/Day) | D8: 2866
A9: Grand Total Exc. VAT | D9: =SUM(D6:H8) -> 10431.797
A10: Electrical
A11: MDB-G1 (39299675-8) | C11: Previous Reading KWH | D11: 42906 | E11: Current Reading KWH | F11: 42914 | G11: Consumption KWH | H11: =F11-D11 -> 8
A12: MDB-G2 (39299676-6) | C12: Previous Reading KWH | D12: 71104 | E12: Current Reading KWH | F12: 71117 | G12: Consumption KWH | H12: =F12-D12 -> 13
A13: MDB-G3 (39299677-4) | C13: Previous Reading KWH | D13: 71989 | E13: Current Reading KWH | F13: 72001 | G13: Consumption KWH | H13: =F13-D13 -> 12
A14: Total Consumption KWH | H14: =SUM(H11:H13) -> 33
A15: Total Consumption * Multiplication Factor (487.20) | H15: =H14*487.2 -> 16077.6
A16: Cost Calculation
A17: 0-2000 kwh @ 0.230 /KWH | D17: 460
A18: 2000-4000 kwh @ 0.280 /KWH | D18: 560
A19: 4000-6000 kwh @ 0.320 /KWH | D19: 640
A20: 6000 & above @ 0.380 /KWH | D20: =H15*0.38 -> 6109.488
A21: Fuel Surcharge @ 0.060 /KWH | D21: =H15*0.06 -> 964.656
A22: Grand Total Exc. VAT | D22: =D20+D21 -> 7074.144
A23: WATER
A24: Previous Reading | B24: 294619 | C24: Present Reading | D24: 294829 | E24: Consumption m3 | F24: =D24-B24 -> 210 | G24: Consumption IG | H24: =F24*220 -> 46200
A25: Cost calculation
A26: 0-10000 @ 0.035 / IG | D26: 350
A27: 10000-20000 @ 0.04 / IG | D27: 400
A28: 20000 & above @ 0.046 / IG | D28: =(H24-20000)*0.046 -> 1205.2
A29: Fuel Surcharge @ 0.004 / IG | D29: =H24*0.004 -> 184.8
A30: Sewerage Fees | D30: =H24*0.01 -> 462
A31: Grand Total Exc. VAT | D31: =SUM(D26:H30) -> 2602
A32: LPG Gas
A33: Tank 1 (1% = 48 liters) | C33: Previous Reading % | D33: 75 | E33: Current Reading % | F33: 65 | G33: Consumption Liters | H33: =(D33-F33)*48.8 -> 488
A34: Tank 2 (1% = 48 liters) | C34: Previous Reading % | D34: 80 | E34: Current Reading % | F34: 80 | G34: Consumption Liters | H34: =(D34-F34)*48.8 -> 0
A35: Total Cost (@ 1.82 AED/Liter) | H35: =((H34+H33)*1.82)*0.5 -> 444.08
A36: Total Utilities | H36: =H35+D22+D9+D31 -> 20552.021

Sheet October-17
A1: Daily Utilities Consumption
A2: 17.10.2024
A3: District Cooling
A4: Previous Reading MWh | B4: 68867.93 | C4: Current Reading MWh | D4: 68905.26 | E4: Consumption MWH | F4: =D4-B4 -> 37.33 | G4: Consumption RTH | H4: =F4*284.35 -> 10614.786
A5: Cost Calculation
A6: Total Cost (0.568/rth) | D6: =H4*0.568 -> 6029.1982
A7: Total Fuel Surchage Cost (0.075/rth) | D7: =H4*0.075 -> 796.10891
A8: Chilled Water Demand (2,866 AED/Day) | D8: 2866
A9: Grand Total Exc. VAT | D9: =SUM(D6:H8) -> 9691.3071
A10: Electrical
A11: MDB-G1 (39299675-8) | C11: Previous Reading KWH | D11: 42898 | E11: Current Reading KWH | F11: 42906 | G11: Consumption KWH | H11: =F11-D11 -> 8
A12: MDB-G2 (39299676-6) | C12: Previous Reading KWH | D12: 71091 | E12: Current Reading KWH | F12: 71104 | G12: Consumption KWH | H12: =F12-D12 -> 13
A13: MDB-G3 (39299677-4) | C13: Previous Reading KWH | D13: 71978 | E13: Current Reading KWH | F13: 71989 | G13: Consumption KWH | H13: =F13-D13 -> 11
A14: Total Consumption KWH | H14: =SUM(H11:H13) -> 32
A15: Total Consumption * Multiplication Factor (487.20) | H15: =H14*487.2 -> 15590.4
A16: Cost Calculation
A17: 0-2000 kwh @ 0.230 /KWH | D17: 460
A18: 2000-4000 kwh @ 0.280 /KWH | D18: 560
A19: 4000-6000 kwh @ 0.320 /KWH | D19: 640
A20: 6000 & above @ 0.380 /KWH | D20: =H15*0.38 -> 5924.352
A21: Fuel Surcharge @ 0.060 /KWH | D21: =H15*0.06 -> 935.424
A22: Grand Total Exc. VAT | D22: =D20+D21 -> 6859.776
A23: WATER
A24: Previous Reading | B24: 294401 | C24: Present Reading | D24: 294619 | E24: Consumption m3 | F24: =D24-B24 -> 218 | G24: Consumption IG | H24: =F24*220 -> 47960
A25: Cost calculation
A26: 0-10000 @ 0.035 / IG | D26: 350
A27: 10000-20000 @ 0.04 / IG | D27: 400
A28: 20000 & above @ 0.046 / IG | D28: =(H24-20000)*0.046 -> 1286.16
A29: Fuel Surcharge @ 0.004 / IG | D29: =H24*0.004 -> 191.84
A30: Sewerage Fees | D30: =H24*0.01 -> 479.6
A31: Grand Total Exc. VAT | D31: =SUM(D26:H30) -> 2707.6
A32: LPG Gas
A33: Tank 1 (1% = 48 liters) | C33: Previous Reading % | D33: 85 | E33: Current Reading % | F33: 75 | G33: Consumption Liters | H33: =(D33-F33)*48.8 -> 488
A34: Tank 2 (1% = 48 liters) | C34: Previous Reading % | D34: 80 | E34: Current Reading % | F34: 80 | G34: Consumption Liters | H34: =(D34-F34)*48.8 -> 0
A35: Total Cost (@ 1.82 AED/Liter) | H35: =((H34+H33)*1.82)*0.5 -> 444.08
A36: Total Utilities | H36: =H35+D22+D9+D31 -> 19702.763

Sheet October-16
A1: Daily Utilities Consumption
A2: 16.10.2024
A3: District Cooling
A4: Previous Reading MWh | B4: 68833.65 | C4: Current Reading MWh | D4: 68867.93 | E4: Consumption MWH | F4: =D4-B4 -> 34.28 | G4: Consumption RTH | H4: =F4*284.35 -> 9747.518
A5: Cost Calculation
A6: Total Cost (0.568/rth) | D6: =H4*0.568 -> 5536.5902
A7: Total Fuel Surchage Cost (0.075/rth) | D7: =H4*0.075 -> 731.06385
A8: Chilled Water Demand (2,866 AED/Day) | D8: 2866
A9: Grand Total Exc. VAT | D9: =SUM(D6:H8) -> 9133.6541
A10: Electrical
A11: MDB-G1 (39299675-8) | C11: Previous Reading KWH | D11: 42891 | E11: Current Reading KWH | F11: 42898 | G11: Consumption KWH | H11: =F11-D11 -> 7
A12: MDB-G2 (39299676-6) | C12: Previous Reading KWH | D12: 71078 | E12: Current Reading KWH | F12: 71091 | G12: Consumption KWH | H12: =F12-D12 -> 13
A13: MDB-G3 (39299677-4) | C13: Previous Reading KWH | D13: 71967 | E13: Current Reading KWH | F13: 71978 | G13: Consumption KWH | H13: =F13-D13 -> 11
A14: Total Consumption KWH | H14: =SUM(H11:H13) -> 31
A15: Total Consumption * Multiplication Factor (487.20) | H15: =H14*487.2 -> 15103.2
A16: Cost Calculation
A17: 0-2000 kwh @ 0.230 /KWH | D17: 460
A18: 2000-4000 kwh @ 0.280 /KWH | D18: 560
A19: 4000-6000 kwh @ 0.320 /KWH | D19: 640
A20: 6000 & above @ 0.380 /KWH | D20: =H15*0.38 -> 5739.216
A21: Fuel Surcharge @ 0.060 /KWH | D21: =H15*0.06 -> 906.192
A22: Grand Total Exc. VAT | D22: =D20+D21 -> 6645.408
A23: WATER
A24: Previous Reading | B24: 294164 | C24: Present Reading | D24: 294401 | E24: Consumption m3 | F24: =D24-B24 -> 237 | G24: Consumption IG | H24: =F24*220 -> 52140
A25: Cost calculation
A26: 0-10000 @ 0.035 / IG | D26: 350
A27: 10000-20000 @ 0.04 / IG | D27: 400
A28: 20000 & above @ 0.046 / IG | D28: =(H24-20000)*0.046 -> 1478.44
A29: Fuel Surcharge @ 0.004 / IG | D29: =H24*0.004 -> 208.56
A30: Sewerage Fees | D30: =H24*0.01 -> 521.4
A31: Grand Total Exc. VAT | D31: =SUM(D26:H30) -> 2958.4
A32: LPG Gas
A33: Tank 1 (1% = 48 liters) | C33: Previous Reading % | D33: 80 | E33: Current Reading % | F33: 80 | G33: Consumption Liters | H33: =(D33-F33)*48.8 -> 0
A34: Tank 2 (1% = 48 liters) | C34: Previous Reading % | D34: 28 | E34: Current Reading % | F34: 18 | G34: Consumption Liters | H34: =(D34-F34)*48.8 -> 488
A35: Total Cost (@ 1.82 AED/Liter) | H35: =((H34+H33)*1.82)*0.5 -> 444.08
A36: Total Utilities | H36: =H35+D22+D9+D31 -> 19181.542

Sheet October-15
A1: Daily Utilities Consumption
A2: 15.10.2024
A3: District Cooling
A4: Previous Reading MWh | B4: 68799.43 | C4: Current Reading MWh | D4: 68833.65 | E4: Consumption MWH | F4: =D4-B4 -> 34.22 | G4: Consumption RTH | H4: =F4*284.35 -> 9730.457
A5: Cost Calculation
A6: Total Cost (0.568/rth) | D6: =H4*0.568 -> 5526.8996
A7: Total Fuel Surchage Cost (0.075/rth) | D7: =H4*0.075 -> 729.78428
A8: Chilled Water Demand (2,866 AED/Day) | D8: 2866
A9: Grand Total Exc. VAT | D9: =SUM(D6:H8) -> 9122.6839
A10: Electrical
A11: MDB-G1 (39299675-8) | C11: Previous Reading KWH | D11: 42883 | E11: Current Reading KWH | F11: 42891 | G11: Consumption KWH | H11: =F11-D11 -> 8
A12: MDB-G2 (39299676-6) | C12: Previous Reading KWH | D12: 71065 | E12: Current Reading KWH | F12: 71078 | G12: Consumption KWH | H12: =F12-D12 -> 13
A13: MDB-G3 (39299677-4) | C13: Previous Reading KWH | D13: 71956 | E13: Current Reading KWH | F13: 71967 | G13: Consumption KWH | H13: =F13-D13 -> 11
A14: Total Consumption KWH | H14: =SUM(H11:H13) -> 32
A15: Total Consumption * Multiplication Factor (487.20) | H15: =H14*487.2 -> 15590.4
A16: Cost Calculation
A17: 0-2000 kwh @ 0.230 /KWH | D17: 460
A18: 2000-4000 kwh @ 0.280 /KWH | D18: 560
A19: 4000-6000 kwh @ 0.320 /KWH | D19: 640
A20: 6000 & above @ 0.380 /KWH | D20: =H15*0.38 -> 5924.352
A21: Fuel Surcharge @ 0.060 /KWH | D21: =H15*0.06 -> 935.424
A22: Grand Total Exc. VAT | D22: =D20+D21 -> 6859.776
A23: WATER
A24: Previous Reading | B24: 293964 | C24: Present Reading | D24: 294164 | E24: Consumption m3 | F24: =D24-B24 -> 200 | G24: Consumption IG | H24: =F24*220 -> 44000
A25: Cost calculation
A26: 0-10000 @ 0.035 / IG | D26: 350
A27: 10000-20000 @ 0.04 / IG | D27: 400
A28: 20000 & above @ 0.046 / IG | D28: =(H24-20000)*0.046 -> 1104
A29: Fuel Surcharge @ 0.004 / IG | D29: =H24*0.004 -> 176
A30: Sewerage Fees | D30: =H24*0.01 -> 440
A31: Grand Total Exc. VAT | D31: =SUM(D26:H30) -> 2470
A32: LPG Gas
A33: Tank 1 (1% = 48 liters) | C33: Previous Reading % | D33: 80 | E33: Current Reading % | F33: 80 | G33: Consumption Liters | H33: =(D33-F33)*48.8 -> 0
A34: Tank 2 (1% = 48 liters) | C34: Previous Reading % | D34: 38 | E34: Current Reading % | F34: 28 | G34: Consumption Liters | H34: =(D34-F34)*48.8 -> 488
A35: Total Cost (@ 1.82 AED/Liter) | H35: =((H34+H33)*1.82)*0.5 -> 444.08
A36: Total Utilities | H36: =H35+D22+D9+D31 -> 18896.54

Sheet October-14
A1: Daily Utilities Consumption
A2: 14.10.2024
A3: District Cooling
A4: Previous Reading MWh | B4: 68766.55 | C4: Current Reading MWh | D4: 68799.43 | E4: Consumption MWH | F4: =D4-B4 -> 32.88 | G4: Consumption RTH | H4: =F4*284.35 -> 9349.428
A5: Cost Calculation
A6: Total Cost (0.568/rth) | D6: =H4*0.568 -> 5310.4751
A7: Total Fuel Surchage Cost (0.075/rth) | D7: =H4*0.075 -> 701.2071
A8: Chilled Water Demand (2,866 AED/Day) | D8: 2866
A9: Grand Total Exc. VAT | D9: =SUM(D6:H8) -> 8877.6822
A10: Electrical
A11: MDB-G1 (39299675-8) | C11: Previous Reading KWH | D11: 42876 | E11: Current Reading KWH | F11: 42883 | G11: Consumption KWH | H11: =F11-D11 -> 7
A12: MDB-G2 (39299676-6) | C12: Previous Reading KWH | D12: 71053 | E12: Current Reading KWH | F12: 71065 | G12: Consumption KWH | H12: =F12-D12 -> 12
A13: MDB-G3 (39299677-4) | C13: Previous Reading KWH | D13: 71945 | E13: Current Reading KWH | F13: 71956 | G13: Consumption KWH | H13: =F13-D13 -> 11
A14: Total Consumption KWH | H14: =SUM(H11:H13) -> 30
A15: Total Consumption * Multiplication Factor (487.20) | H15: =H14*487.2 -> 14616
A16: Cost Calculation
A17: 0-2000 kwh @ 0.230 /KWH | D17: 460
A18: 2000-4000 kwh @ 0.280 /KWH | D18: 560
A19: 4000-6000 kwh @ 0.320 /KWH | D19: 640
A20: 6000 & above @ 0.380 /KWH | D20: =H15*0.38 -> 5554.08
A21: Fuel Surcharge @ 0.060 /KWH | D21: =H15*0.06 -> 876.96
A22: Grand Total Exc. VAT | D22: =D20+D21 -> 6431.04
A23: WATER
A24: Previous Reading | B24: 293761 | C24: Present Reading | D24: 293964 | E24: Consumption m3 | F24: =D24-B24 -> 203 | G24: Consumption IG | H24: =F24*220 -> 44660
A25: Cost calculation
A26: 0-10000 @ 0.035 / IG | D26: 350
A27: 10000-20000 @ 0.04 / IG | D27: 400
A28: 20000 & above @ 0.046 / IG | D28: =(H24-20000)*0.046 -> 1134.36
A29: Fuel Surcharge @ 0.004 / IG | D29: =H24*0.004 -> 178.64
A30: Sewerage Fees | D30: =H24*0.01 -> 446.6
A31: Grand Total Exc. VAT | D31: =SUM(D26:H30) -> 2509.6
A32: LPG Gas
A33: Tank 1 (1% = 48 liters) | C33: Previous Reading % | D33: 80 | E33: Current Reading % | F33: 80 | G33: Consumption Liters | H33: =(D33-F33)*48.8 -> 0
A34: Tank 2 (1% = 48 liters) | C34: Previous Reading % | D34: 48 | E34: Current Reading % | F34: 38 | G34: Consumption Liters | H34: =(D34-F34)*48.8 -> 488
A35: Total Cost (@ 1.82 AED/Liter) | H35: =((H34+H33)*1.82)*0.5 -> 444.08
A36: Total Utilities | H36: =H35+D22+D9+D31 -> 18262.402

Sheet October-13
A1: Daily Utilities Consumption
A2: 13.10.2024
A3: District Cooling
A4: Previous Reading MWh | B4: 68730.18 | C4: Current Reading MWh | D4: 68766.55 | E4: Consumption MWH | F4: =D4-B4 -> 36.37 | G4: Consumption RTH | H4: =F4*284.35 -> 10341.81
A5: Cost Calculation
A6: Total Cost (0.568/rth) | D6: =H4*0.568 -> 5874.1478
A7: Total Fuel Surchage Cost (0.075/rth) | D7: =H4*0.075 -> 775.63571
A8: Chilled Water Demand (2,866 AED/Day) | D8: 2866
A9: Grand Total Exc. VAT | D9: =SUM(D6:H8) -> 9515.7835
A10: Electrical
A11: MDB-G1 (39299675-8) | C11: Previous Reading KWH | D11: 42868 | E11: Current Reading KWH | F11: 42876 | G11: Consumption KWH | H11: =F11-D11 -> 8
A12: MDB-G2 (39299676-6) | C12: Previous Reading KWH | D12: 71041 | E12: Current Reading KWH | F12: 71053 | G12: Consumption KWH | H12: =F12-D12 -> 12
A13: MDB-G3 (39299677-4) | C13: Previous Reading KWH | D13: 71934 | E13: Current Reading KWH | F13: 71945 | G13: Consumption KWH | H13: =F13-D13 -> 11
A14: Total Consumption KWH | H14: =SUM(H11:H13) -> 31
A15: Total Consumption * Multiplication Factor (487.20) | H15: =H14*487.2 -> 15103.2
A16: Cost Calculation
A17: 0-2000 kwh @ 0.230 /KWH | D17: 460
A18: 2000-4000 kwh @ 0.280 /KWH | D18: 560
A19: 4000-6000 kwh @ 0.320 /KWH | D19: 640
A20: 6000 & above @ 0.380 /KWH | D20: =H15*0.38 -> 5739.216
A21: Fuel Surcharge @ 0.060 /KWH | D21: =H15*0.06 -> 906.192
A22: Grand Total Exc. VAT | D22: =D20+D21 -> 6645.408
A23: WATER
A24: Previous Reading | B24: 293566 | C24: Present Reading | D24: 293761 | E24: Consumption m3 | F24: =D24-B24 -> 195 | G24: Consumption IG | H24: =F24*220 -> 42900
A25: Cost calculation
A26: 0-10000 @ 0.035 / IG | D26: 350
A27: 10000-20000 @ 0.04 / IG | D27: 400
A28: 20000 & above @ 0.046 / IG | D28: =(H24-20000)*0.046 -> 1053.4
A29: Fuel Surcharge @ 0.004 / IG | D29: =H24*0.004 -> 171.6
A30: Sewerage Fees | D30: =H24*0.01 -> 429
A31: Grand Total Exc. VAT | D31: =SUM(D26:H30) -> 2404
A32: LPG Gas
A33: Tank 1 (1% = 48 liters) | C33: Previous Reading % | D33: 80 | E33: Current Reading % | F33: 80 | G33: Consumption Liters | H33: =(D33-F33)*48.8 -> 0
A34: Tank 2 (1% = 48 liters) | C34: Previous Reading % | D34: 58 | E34: Current Reading % | F34: 48 | G34: Consumption Liters | H34: =(D34-F34)*48.8 -> 488
A35: Total Cost (@ 1.82 AED/Liter) | H35: =((H34+H33)*1.82)*0.5 -> 444.08
A36: Total Utilities | H36: =H35+D22+D9+D31 -> 19009.272

Sheet October-12
A1: Daily Utilities Consumption
A2: 12.10.2024
A3: District Cooling
A4: Previous Reading MWh | B4: 68691.68 | C4: Current Reading MWh | D4: 68730.18 | E4: Consumption MWH | F4: =D4-B4 -> 38.5 | G4: Consumption RTH | H4: =F4*284.35 -> 10947.475
A5: Cost Calculation
A6: Total Cost (0.568/rth) | D6: =H4*0.568 -> 6218.1658
A7: Total Fuel Surchage Cost (0.075/rth) | D7: =H4*0.075 -> 821.06062
A8: Chilled Water Demand (2,866 AED/Day) | D8: 2866
A9: Grand Total Exc. VAT | D9: =SUM(D6:H8) -> 9905.2264
A10: Electrical
A11: MDB-G1 (39299675-8) | C11: Previous Reading KWH | D11: 42861 | E11: Current Reading KWH | F11: 42868 | G11: Consumption KWH | H11: =F11-D11 -> 7
A12: MDB-G2 (39299676-6) | C12: Previous Reading KWH | D12: 71028 | E12: Current Reading KWH | F12: 71041 | G12: Consumption KWH | H12: =F12-D12 -> 13
A13: MDB-G3 (39299677-4) | C13: Previous Reading KWH | D13: 71923 | E13: Current Reading KWH | F13: 71934 | G13: Consumption KWH | H13: =F13-D13 -> 11
A14: Total Consumption KWH | H14: =SUM(H11:H13) -> 31
A15: Total Consumption * Multiplication Factor (487.20) | H15: =H14*487.2 -> 15103.2
A16: Cost Calculation
A17: 0-2000 kwh @ 0.230 /KWH | D17: 460
A18: 2000-4000 kwh @ 0.280 /KWH | D18: 560
A19: 4000-6000 kwh @ 0.320 /KWH | D19: 640
A20: 6000 & above @ 0.380 /KWH | D20: =H15*0.38 -> 5739.216
A21: Fuel Surcharge @ 0.060 /KWH | D21: =H15*0.06 -> 906.192
A22: Grand Total Exc. VAT | D22: =D20+D21 -> 6645.408
A23: WATER
A24: Previous Reading | B24: 293378 | C24: Present Reading | D24: 293566 | E24: Consumption m3 | F24: =D24-B24 -> 188 | G24: Consumption IG | H24: =F24*220 -> 41360
A25: Cost calculation
A26: 0-10000 @ 0.035 / IG | D26: 350
A27: 10000-20000 @ 0.04 / IG | D27: 400
A28: 20000 & above @ 0.046 / IG | D28: =(H24-20000)*0.046 -> 982.56
A29: Fuel Surcharge @ 0.004 / IG | D29: =H24*0.004 -> 165.44
A30: Sewerage Fees | D30: =H24*0.01 -> 413.6
A31: Grand Total Exc. VAT | D31: =SUM(D26:H30) -> 2311.6
A32: LPG Gas
A33: Tank 1 (1% = 48 liters) | C33: Previous Reading % | D33: 65 | E33: Current Reading % | F33: 58 | G33: Consumption Liters | H33: =(D33-F33)*48.8 -> 341.6
A34: Tank 2 (1% = 48 liters) | C34: Previous Reading % | D34: 80 | E34: Current Reading % | F34: 80 | G34: Consumption Liters | H34: =(D34-F34)*48.8 -> 0
A35: Total Cost (@ 1.82 AED/Liter) | H35: =((H34+H33)*1.82)*0.5 -> 310.856
A36: Total Utilities | H36: =H35+D22+D9+D31 -> 19173.09

Sheet October-11
A1: Daily Utilities Consumption
A2: 11.10.2024
A3: District Cooling
A4: Previous Reading MWh | B4: 68656.33 | C4: Current Reading MWh | D4: 68691.68 | E4: Consumption MWH | F4: =D4-B4 -> 35.35 | G4: Consumption RTH | H4: =F4*284.35 -> 10051.772
A5: Cost Calculation
A6: Total Cost (0.568/rth) | D6: =H4*0.568 -> 5709.4068
A7: Total Fuel Surchage Cost (0.075/rth) | D7: =H4*0.075 -> 753.88294
A8: Chilled Water Demand (2,866 AED/Day) | D8: 2866
A9: Grand Total Exc. VAT | D9: =SUM(D6:H8) -> 9329.2897
A10: Electrical
A11: MDB-G1 (39299675-8) | C11: Previous Reading KWH | D11: 42853 | E11: Current Reading KWH | F11: 42861 | G11: Consumption KWH | H11: =F11-D11 -> 8
A12: MDB-G2 (39299676-6) | C12: Previous Reading KWH | D12: 71015 | E12: Current Reading KWH | F12: 71028 | G12: Consumption KWH | H12: =F12-D12 -> 13
A13: MDB-G3 (39299677-4) | C13: Previous Reading KWH | D13: 71911 | E13: Current Reading KWH | F13: 71923 | G13: Consumption KWH | H13: =F13-D13 -> 12
A14: Total Consumption KWH | H14: =SUM(H11:H13) -> 33
A15: Total Consumption * Multiplication Factor (487.20) | H15: =H14*487.2 -> 16077.6
A16: Cost Calculation
A17: 0-2000 kwh @ 0.230 /KWH | D17: 460
A18: 2000-4000 kwh @ 0.280 /KWH | D18: 560
A19: 4000-6000 kwh @ 0.320 /KWH | D19: 640
A20: 6000 & above @ 0.380 /KWH | D20: =H15*0.38 -> 6109.488
A21: Fuel Surcharge @ 0.060 /KWH | D21: =H15*0.06 -> 964.656
A22: Grand Total Exc. VAT | D22: =D20+D21 -> 7074.144
A23: WATER
