Workbook

Sheet TOTAL
A1: Site Name | B1: Day | C1: Month | D1: Year | E1: Total Electricity Kwh | F1: Electricity Tariff ($/Kwh) | G1: LPG (Liters) | H1: LPG $/Liters | I1: Water Utility Supply (m3) m3 | J1: Water Utility Supply (m3) $/m3 | K1: District Energy Cooling RTH | L1: District Energy Cooling $/RTH | M1: Room Nights | N1: Total Guests
A2: Amwaj Rotana - Jumeirah Beach | B2: 1 | C2: 11 | D2: 2024 | E2: ='MTD Utility Sheet'!G4/0.439 -> 14649.294 | F2: 0.439 | G2: =('MTD Utility Sheet'!I4/1.82)/0.5 -> 488 | H2: =1.82*0.5 -> 0.91 | I2: ='MTD Utility Sheet'!H4/12.38 -> 276.28433 | J2: 12.38 | K2: =IF(('MTD Utility Sheet'!F4-2866)<0,"0",('MTD Utility Sheet'!F4-2866)/(0.568+0.075)) -> 9190.1866 | L2: ='MTD Utility Sheet'!F4/K2 -> 0.95485439 | M2: ='MTD Utility Sheet'!B4*301 -> 294.98
A3: Amwaj Rotana - Jumeirah Beach | B3: =B2+1 -> 2 | C3: 11 | D3: 2024 | E3: ='MTD Utility Sheet'!G5/0.439 -> 15625.923 | F3: 0.439 | G3: =('MTD Utility Sheet'!I5/1.82)/0.5 -> 439.1978 | H3: =1.82*0.5 -> 0.91 | I3: ='MTD Utility Sheet'!H5/12.38 -> 211.24394 | J3: 12.38 | K3: =IF(('MTD Utility Sheet'!F5-2866)<0,"0",('MTD Utility Sheet'!F5-2866)/(0.568+0.075)) -> 10011.96 | L3: ='MTD Utility Sheet'!F5/K3 -> 0.92925765 | M3: ='MTD Utility Sheet'!B5*301 -> 289.9834
A4: Amwaj Rotana - Jumeirah Beach | B4: =B3+1 -> 3 | C4: 11 | D4: 2024 | E4: ='MTD Utility Sheet'!G6/0.439 -> 15625.923 | F4: 0.439 | G4: =('MTD Utility Sheet'!I6/1.82)/0.5 -> 488 | H4: =1.82*0.5 -> 0.91 | I4: ='MTD Utility Sheet'!H6/12.38 -> 209.11147 | J4: 12.38 | K4: =IF(('MTD Utility Sheet'!F6-2866)<0,"0",('MTD Utility Sheet'!F6-2866)/(0.568+0.075)) -> 9980.6843 | L4: ='MTD Utility Sheet'!F6/K4 -> 0.93015466 | M4: ='MTD Utility Sheet'!B6*301 -> 294.98
A5: Amwaj Rotana - Jumeirah Beach | B5: =B4+1 -> 4 | C5: 11 | D5: 2024 | E5: ='MTD Utility Sheet'!G7/0.439 -> 15137.608 | F5: 0.439 | G5: =('MTD Utility Sheet'!I7/1.82)/0.5 -> 439.1978 | H5: =1.82*0.5 -> 0.91 | I5: ='MTD Utility Sheet'!H7/12.38 -> 210.17771 | J5: 12.38 | K5: =IF(('MTD Utility Sheet'!F7-2866)<0,"0",('MTD Utility Sheet'!F7-2866)/(0.568+0.075)) -> 10011.96 | L5: ='MTD Utility Sheet'!F7/K5 -> 0.92925765 | M5: ='MTD Utility Sheet'!B7*301 -> 272.0137
A6: Amwaj Rotana - Jumeirah Beach | B6: =B5+1 -> 5 | C6: 11 | D6: 2024 | E6: ='MTD Utility Sheet'!G8/0.439 -> 14649.294 | F6: 0.439 | G6: =('MTD Utility Sheet'!I8/1.82)/0.5 -> 488 | H6: =1.82*0.5 -> 0.91 | I6: ='MTD Utility Sheet'!H8/12.38 -> 217.64136 | J6: 12.38 | K6: =IF(('MTD Utility Sheet'!F8-2866)<0,"0",('MTD Utility Sheet'!F8-2866)/(0.568+0.075)) -> 9173.126 | L6: ='MTD Utility Sheet'!F8/K6 -> 0.95543439 | M6: ='MTD Utility Sheet'!B8*301 -> 287.9968
A7: Amwaj Rotana - Jumeirah Beach | B7: =B6+1 -> 6 | C7: 11 | D7: 2024 | E7: ='MTD Utility Sheet'!G9/0.439 -> 15137.608 | F7: 0.439 | G7: =('MTD Utility Sheet'!I9/1.82)/0.5 -> 488 | H7: =1.82*0.5 -> 0.91 | I7: ='MTD Utility Sheet'!H9/12.38 -> 219.77383 | J7: 12.38 | K7: =IF(('MTD Utility Sheet'!F9-2866)<0,"0",('MTD Utility Sheet'!F9-2866)/(0.568+0.075)) -> 10071.68 | L7: ='MTD Utility Sheet'!F9/K7 -> 0.92756028 | M7: ='MTD Utility Sheet'!B9*301 -> 300.0067
A8: Amwaj Rotana - Jumeirah Beach | B8: =B7+1 -> 7 | C8: 11 | D8: 2024 | E8: ='MTD Utility Sheet'!G10/0.439 -> 14649.294 | F8: 0.439 | G8: =('MTD Utility Sheet'!I10/1.82)/0.5 -> 439.1978 | H8: =1.82*0.5 -> 0.91 | I8: ='MTD Utility Sheet'!H10/12.38 -> 189.91922 | J8: 12.38 | K8: =IF(('MTD Utility Sheet'!F10-2866)<0,"0",('MTD Utility Sheet'!F10-2866)/(0.568+0.075)) -> 9457.4806 | L8: ='MTD Utility Sheet'!F10/K8 -> 0.94604054 | M8: ='MTD Utility Sheet'!B10*301 -> 301
A9: Amwaj Rotana - Jumeirah Beach | B9: =B8+1 -> 8 | C9: 11 | D9: 2024 | E9: ='MTD Utility Sheet'!G11/0.439 -> 15137.608 | F9: 0.439 | G9: =('MTD Utility Sheet'!I11/1.82)/0.5 -> 439.1978 | H9: =1.82*0.5 -> 0.91 | I9: ='MTD Utility Sheet'!H11/12.38 -> 196.31664 | J9: 12.38 | K9: =IF(('MTD Utility Sheet'!F11-2866)<0,"0",('MTD Utility Sheet'!F11-2866)/(0.568+0.075)) -> 8854.6656 | L9: ='MTD Utility Sheet'!F11/K9 -> 0.96667117 | M9: ='MTD Utility Sheet'!B11*301 -> 301
A10: Amwaj Rotana - Jumeirah Beach | B10: =B9+1 -> 9 | C10: 11 | D10: 2024 | E10: ='MTD Utility Sheet'!G12/0.439 -> 15137.608 | F10: 0.439 | G10: =('MTD Utility Sheet'!I12/1.82)/0.5 -> 585.6044 | H10: =1.82*0.5 -> 0.91 | I10: ='MTD Utility Sheet'!H12/12.38 -> 180.3231 | J10: 12.38 | K10: =IF(('MTD Utility Sheet'!F12-2866)<0,"0",('MTD Utility Sheet'!F12-2866)/(0.568+0.075)) -> 8894.4635 | L10: ='MTD Utility Sheet'!F12/K10 -> 0.96522292 | M10: ='MTD Utility Sheet'!B12*301 -> 301
A11: Amwaj Rotana - Jumeirah Beach | B11: =B10+1 -> 10 | C11: 11 | D11: 2024 | E11: ='MTD Utility Sheet'!G13/0.439 -> 14649.294 | F11: 0.439 | G11: =('MTD Utility Sheet'!I13/1.82)/0.5 -> 488 | H11: =1.82*0.5 -> 0.91 | I11: ='MTD Utility Sheet'!H13/12.38 -> 224.03877 | J11: 12.38 | K11: =IF(('MTD Utility Sheet'!F13-2866)<0,"0",('MTD Utility Sheet'!F13-2866)/(0.568+0.075)) -> 8675.521 | L11: ='MTD Utility Sheet'!F13/K11 -> 0.9733548 | M11: ='MTD Utility Sheet'!B13*301 -> 301
A12: Amwaj Rotana - Jumeirah Beach | B12: =B11+1 -> 11 | C12: 11 | D12: 2024 | E12: ='MTD Utility Sheet'!G14/0.439 -> 15625.923 | F12: 0.439 | G12: =('MTD Utility Sheet'!I14/1.82)/0.5 -> 488 | H12: =1.82*0.5 -> 0.91 | I12: ='MTD Utility Sheet'!H14/12.38 -> 202.71405 | J12: 12.38 | K12: =IF(('MTD Utility Sheet'!F14-2866)<0,"0",('MTD Utility Sheet'!F14-2866)/(0.568+0.075)) -> 9440.4199 | L12: ='MTD Utility Sheet'!F14/K12 -> 0.94658819 | M12: ='MTD Utility Sheet'!B14*301 -> 301
A13: Amwaj Rotana - Jumeirah Beach | B13: =B12+1 -> 12 | C13: 11 | D13: 2024 | E13: ='MTD Utility Sheet'!G15/0.439 -> 15137.608 | F13: 0.439 | G13: =('MTD Utility Sheet'!I15/1.82)/0.5 -> 585.6044 | H13: =1.82*0.5 -> 0.91 | I13: ='MTD Utility Sheet'!H15/12.38 -> 196.31664 | J13: 12.38 | K13: =IF(('MTD Utility Sheet'!F15-2866)<0,"0",('MTD Utility Sheet'!F15-2866)/(0.568+0.075)) -> 9264.1213 | L13: ='MTD Utility Sheet'!F15/K13 -> 0.95236555 | M13: ='MTD Utility Sheet'!B15*301 -> 301
A14: Amwaj Rotana - Jumeirah Beach | B14: =B13+1 -> 13 | C14: 11 | D14: 2024 | E14: ='MTD Utility Sheet'!G16/0.439 -> 14649.294 | F14: 0.439 | G14: =('MTD Utility Sheet'!I16/1.82)/0.5 -> 585.6044 | H14: =1.82*0.5 -> 0.91 | I14: ='MTD Utility Sheet'!H16/12.38 -> 181.38934 | J14: 12.38 | K14: =IF(('MTD Utility Sheet'!F16-2866)<0,"0",('MTD Utility Sheet'!F16-2866)/(0.568+0.075)) -> 8721.0109 | L14: ='MTD Utility Sheet'!F16/K14 -> 0.97163163 | M14: ='MTD Utility Sheet'!B16*301 -> 290.0135
... A32: Amwaj Rotana - Jumeirah Beach | B32: =B31+1 -> 31 | C32: 11 | D32: 2024 | E32: ='MTD Utility Sheet'!G34/0.439 -> 0 | F32: 1.439 | G32: =('MTD Utility Sheet'!I34/1.82)/0.5 -> 0 | H32: =1.82*0.5 -> 0.91 | I32: ='MTD Utility Sheet'!H34/12.38 -> 0 | J32: 13.38 | K32: =IF(('MTD Utility Sheet'!F34-2866)<0,"0",('MTD Utility Sheet'!F34-2866)/(0.568+0.075)) -> 0 | L32: ='MTD Utility Sheet'!F34/K32 -> #DIV/0! | M32: ='MTD Utility Sheet'!B34*301 -> 0

Sheet MTD Utility Sheet
A1: Daily Utilities November-2024
B3: Occ % | C3: Out. Temp at 2PM | D3: RH % | E3: F&B Covers | F3: Chilled water | G3: Electricity | H3: Water | I3: LPG | J3: Total
A4: 1 | B4: 0.98 | C4: 35.0c | D4: 0.73 | E4: 1479 | F4: 8775.29 | G4: 6431.04 | H4: 3420.4 | I4: 444.08 | J4: =SUM(F4+G4+H4+I4) -> 19070.81
A5: 2 | B5: 0.9634 | C5: 35.5c | D5: 0.94 | E5: 1547 | F5: 9303.69 | G5: 6859.78 | H5: 2615.2 | I5: 399.67 | J5: =SUM(F5+G5+H5+I5) -> 19178.34
A6: 3 | B6: 0.98 | C6: 35.0c | D6: 0.99 | E6: 1382 | F6: 9283.58 | G6: 6859.78 | H6: 2588.8 | I6: 444.08 | J6: =SUM(F6+G6+H6+I6) -> 19176.24
A7: 4 | B7: 0.9037 | C7: 35.5c | D7: 0.95 | E7: 1159 | F7: 9303.69 | G7: 6645.41 | H7: 2602 | I7: 399.67 | J7: =SUM(F7+G7+H7+I7) -> 18950.77
A8: 5 | B8: 0.9568 | C8: 34.0c | D8: 0.85 | E8: 1272 | F8: 8764.32 | G8: 6431.04 | H8: 2694.4 | I8: 444.08 | J8: =SUM(F8+G8+H8+I8) -> 18333.84
A9: 6 | B9: 0.9967 | C9: 34.5c | D9: 0.84 | E9: 1266 | F9: 9342.09 | G9: 6645.41 | H9: 2720.8 | I9: 444.08 | J9: =SUM(F9+G9+H9+I9) -> 19152.38
A10: 7 | B10: 1 | C10: 34c | D10: 0.68 | E10: 1466 | F10: 8947.16 | G10: 6431.04 | H10: 2351.2 | I10: 399.67 | J10: =SUM(F10+G10+H10+I10) -> 18129.07
A11: 8 | B11: 1 | C11: 34c | D11: 0.72 | E11: 1422 | F11: 8559.55 | G11: 6645.41 | H11: 2430.4 | I11: 399.67 | J11: =SUM(F11+G11+H11+I11) -> 18035.03
A12: 9 | B12: 1 | C12: 34.5c | D12: 0.81 | E12: 1425 | F12: 8585.14 | G12: 6645.41 | H12: 2232.4 | I12: 532.9 | J12: =SUM(F12+G12+H12+I12) -> 17995.85
A13: 10 | B13: 1 | C13: 34.0c | D13: 0.93 | E13: 1421 | F13: 8444.36 | G13: 6431.04 | H13: 2773.6 | I13: 444.08 | J13: =SUM(F13+G13+H13+I13) -> 18093.08
A14: 11 | B14: 1 | C14: 34.0c | D14: 0.97 | E14: 1399 | F14: 8936.19 | G14: 6859.78 | H14: 2509.6 | I14: 444.08 | J14: =SUM(F14+G14+H14+I14) -> 18749.65
A15: 12 | B15: 1 | C15: 33.5c | D15: 0.71 | E15: 1219 | F15: 8822.83 | G15: 6645.41 | H15: 2430.4 | I15: 532.9 | J15: =SUM(F15+G15+H15+I15) -> 18431.54
... A33: 30 | B33: 0.89 | C33: 28c | D33: 0.67 | E33: 1223 | F33: 6557.48 | G33: 6645.41 | H33: 2575.6 | I33: 488.49 | J33: =SUM(F33+G33+H33+I33) -> 16266.98
A34: 31 | J34: =SUM(F34+G34+H34+I34) -> 0
A35: Total Cost | F35: =SUM(F4:F34) -> 242565.28 | G35: =SUM(G4:G34) -> 198290.45 | H35: =SUM(H4:H34) -> 77545.2 | I35: =SUM(I4:I34) -> 13366.83 | J35: =SUM(J4:J34) -> 531767.76
A36: Total Units | B36: =AVERAGE(B4:B34) -> 0.92212 | C36: =AVERAGE(C4:C34) -> #DIV/0! | D36: =AVERAGE(D4:D34) -> 0.75966667 | E36: =SUM(E4:E34) -> 37648 | F36: =F35*0.38 -> 92174.806 | G36: =G35/12.9 -> 15371.353 | H36: =H35/0.92 -> 84288.261 | I36: =I35/1.76 -> 7594.7898

Sheet November-30
A1: Daily Utilities Consumption
A2: 30.11.2024
A3: District Cooling
A4: Previous Reading MWh | B4: 70266.71 | C4: Current Reading MWh | D4: 70286.9 | E4: Consumption MWH | F4: =D4-B4 -> 20.19 | G4: Consumption RTH | H4: =F4*284.35 -> 5741.0265
A5: Cost Calculation
A6: Total Cost (0.568/rth) | D6: =H4*0.568 -> 3260.9031
A7: Total Fuel Surchage Cost (0.075/rth) | D7: =H4*0.075 -> 430.57699
A8: Chilled Water Demand (2,866 AED/Day) | D8: 2866
A9: Grand Total Exc. VAT | D9: =SUM(D6:H8) -> 6557.48
A10: Electrical
A11: MDB-G1 (39299675-8) | C11: Previous Reading KWH | D11: 43212 | E11: Current Reading KWH | F11: 43219 | G11: Consumption KWH | H11: =F11-D11 -> 7
A12: MDB-G2 (39299676-6) | C12: Previous Reading KWH | D12: 71655 | E12: Current Reading KWH | F12: 71668 | G12: Consumption KWH | H12: =F12-D12 -> 13
A13: MDB-G3 (39299677-4) | C13: Previous Reading KWH | D13: 72466 | E13: Current Reading KWH | F13: 72477 | G13: Consumption KWH | H13: =F13-D13 -> 11
A14: Total Consumption KWH | H14: =SUM(H11:H13) -> 31
A15: Total Consumption * Multiplication Factor (487.20) | H15: =H14*487.2 -> 15103.2
A16: Cost Calculation
A17: 0-2000 kwh @ 0.230 /KWH | D17: 460
A18: 2000-4000 kwh @ 0.280 /KWH | D18: 560
A19: 4000-6000 kwh @ 0.320 /KWH | D19: 640
A20: 6000 & above @ 0.380 /KWH | D20: =H15*0.38 -> 5739.216
A21: Fuel Surcharge @ 0.060 /KWH | D21: =H15*0.06 -> 906.192
A22: Grand Total Exc. VAT | D22: =D20+D21 -> 6645.408
A23: WATER
A24: Previous Reading | B24: 303714 | C24: Present Reading | D24: 303922 | E24: Consumption m3 | F24: =D24-B24 -> 208 | G24: Consumption IG | H24: =F24*220 -> 45760
A25: Cost calculation
A26: 0-10000 @ 0.035 / IG | D26: 350
A27: 10000-20000 @ 0.04 / IG | D27: 400
A28: 20000 & above @ 0.046 / IG | D28: =(H24-20000)*0.046 -> 1184.96
A29: Fuel Surcharge @ 0.004 / IG | D29: =H24*0.004 -> 183.04
A30: Sewerage Fees | D30: =H24*0.01 -> 457.6
A31: Grand Total Exc. VAT | D31: =SUM(D26:H30) -> 2575.6
A32: LPG Gas
A33: Tank 1 (1% = 48 liters) | C33: Previous Reading % | D33: 80 | E33: Current Reading % | F33: 80 | G33: Consumption Liters | H33: =(D33-F33)*48.8 -> 0
A34: Tank 2 (1% = 48 liters) | C34: Previous Reading % | D34: 60 | E34: Current Reading % | F34: 49 | G34: Consumption Liters | H34: =(D34-F34)*48.8 -> 536.8
A35: Total Cost (@ 1.82 AED/Liter) | H35: =((H34+H33)*1.82)*0.5 -> 488.488
A36: Total Utilities | H36: =H35+D22+D9+D31 -> 16266.976

Sheet November-29
A1: Daily Utilities Consumption
A2: 29.11.2024
A3: District Cooling
A4: Previous Reading MWh | B4: 70244.15 | C4: Current Reading MWh | D4: 70266.71 | E4: Consumption MWH | F4: =D4-B4 -> 22.56 | G4: Consumption RTH | H4: =F4*284.35 -> 6414.936
A5: Cost Calculation
A6: Total Cost (0.568/rth) | D6: =H4*0.568 -> 3643.6836
A7: Total Fuel Surchage Cost (0.075/rth) | D7: =H4*0.075 -> 481.1202
A8: Chilled Water Demand (2,866 AED/Day) | D8: 2866
A9: Grand Total Exc. VAT | D9: =SUM(D6:H8) -> 6990.8038
A10: Electrical
A11: MDB-G1 (39299675-8) | C11: Previous Reading KWH | D11: 43205 | E11: Current Reading KWH | F11: 43212 | G11: Consumption KWH | H11: =F11-D11 -> 7
A12: MDB-G2 (39299676-6) | C12: Previous Reading KWH | D12: 71641 | E12: Current Reading KWH | F12: 71655 | G12: Consumption KWH | H12: =F12-D12 -> 14
A13: MDB-G3 (39299677-4) | C13: Previous Reading KWH | D13: 72455 | E13: Current Reading KWH | F13: 72466 | G13: Consumption KWH | H13: =F13-D13 -> 11
A14: Total Consumption KWH | H14: =SUM(H11:H13) -> 32
A15: Total Consumption * Multiplication Factor (487.20) | H15: =H14*487.2 -> 15590.4
A16: Cost Calculation
A17: 0-2000 kwh @ 0.230 /KWH | D17: 460
A18: 2000-4000 kwh @ 0.280 /KWH | D18: 560
A19: 4000-6000 kwh @ 0.320 /KWH | D19: 640
A20: 6000 & above @ 0.380 /KWH | D20: =H15*0.38 -> 5924.352
A21: Fuel Surcharge @ 0.060 /KWH | D21: =H15*0.06 -> 935.424
A22: Grand Total Exc. VAT | D22: =D20+D21 -> 6859.776
A23: WATER
A24: Previous Reading | B24: 303520 | C24: Present Reading | D24: 303714 | E24: Consumption m3 | F24: =D24-B24 -> 194 | G24: Consumption IG | H24: =F24*220 -> 42680
A25: Cost calculation
A26: 0-10000 @ 0.035 / IG | D26: 350
A27: 10000-20000 @ 0.04 / IG | D27: 400
A28: 20000 & above @ 0.046 / IG | D28: =(H24-20000)*0.046 -> 1043.28
A29: Fuel Surcharge @ 0.004 / IG | D29: =H24*0.004 -> 170.72
A30: Sewerage Fees | D30: =H24*0.01 -> 426.8
A31: Grand Total Exc. VAT | D31: =SUM(D26:H30) -> 2390.8
A32: LPG Gas
A33: Tank 1 (1% = 48 liters) | C33: Previous Reading % | D33: 80 | E33: Current Reading % | F33: 80 | G33: Consumption Liters | H33: =(D33-F33)*48.8 -> 0
A34: Tank 2 (1% = 48 liters) | C34: Previous Reading % | D34: 70 | E34: Current Reading % | F34: 60 | G34: Consumption Liters | H34: =(D34-F34)*48.8 -> 488
A35: Total Cost (@ 1.82 AED/Liter) | H35: =((H34+H33)*1.82)*0.5 -> 444.08
A36: Total Utilities | H36: =H35+D22+D9+D31 -> 16685.46

Sheet November-28
A1: Daily Utilities Consumption
A2: 28.11.2024
A3: District Cooling
A4: Previous Reading MWh | B4: 70216.71 | C4: Current Reading MWh | D4: 70244.15 | E4: Consumption MWH | F4: =D4-B4 -> 27.44 | G4: Consumption RTH | H4: =F4*284.35 -> 7802.564
A5: Cost Calculation
A6: Total Cost (0.568/rth) | D6: =H4*0.568 -> 4431.8564
A7: Total Fuel Surchage Cost (0.075/rth) | D7: =H4*0.075 -> 585.1923
A8: Chilled Water Demand (2,866 AED/Day) | D8: 2866
A9: Grand Total Exc. VAT | D9: =SUM(D6:H8) -> 7883.0487
A10: Electrical
A11: MDB-G1 (39299675-8) | C11: Previous Reading KWH | D11: 43198 | E11: Current Reading KWH | F11: 43205 | G11: Consumption KWH | H11: =F11-D11 -> 7
A12: MDB-G2 (39299676-6) | C12: Previous Reading KWH | D12: 71629 | E12: Current Reading KWH | F12: 71641 | G12: Consumption KWH | H12: =F12-D12 -> 12
A13: MDB-G3 (39299677-4) | C13: Previous Reading KWH | D13: 72444 | E13: Current Reading KWH | F13: 72455 | G13: Consumption KWH | H13: =F13-D13 -> 11
A14: Total Consumption KWH | H14: =SUM(H11:H13) -> 30
A15: Total Consumption * Multiplication Factor (487.20) | H15: =H14*487.2 -> 14616
A16: Cost Calculation
A17: 0-2000 kwh @ 0.230 /KWH | D17: 460
A18: 2000-4000 kwh @ 0.280 /KWH | D18: 560
A19: 4000-6000 kwh @ 0.320 /KWH | D19: 640
A20: 6000 & above @ 0.380 /KWH | D20: =H15*0.38 -> 5554.08
A21: Fuel Surcharge @ 0.060 /KWH | D21: =H15*0.06 -> 876.96
A22: Grand Total Exc. VAT | D22: =D20+D21 -> 6431.04
A23: WATER
A24: Previous Reading | B24: 303328 | C24: Present Reading | D24: 303520 | E24: Consumption m3 | F24: =D24-B24 -> 192 | G24: Consumption IG | H24: =F24*220 -> 42240
A25: Cost calculation
A26: 0-10000 @ 0.035 / IG | D26: 350
A27: 10000-20000 @ 0.04 / IG | D27: 400
A28: 20000 & above @ 0.046 / IG | D28: =(H24-20000)*0.046 -> 1023.04
A29: Fuel Surcharge @ 0.004 / IG | D29: =H24*0.004 -> 168.96
A30: Sewerage Fees | D30: =H24*0.01 -> 422.4
A31: Grand Total Exc. VAT | D31: =SUM(D26:H30) -> 2364.4
A32: LPG Gas
A33: Tank 1 (1% = 48 liters) | C33: Previous Reading % | D33: 17 | E33: Current Reading % | F33: 17 | G33: Consumption Liters | H33: =(D33-F33)*48.8 -> 0
A34: Tank 2 (1% = 48 liters) | C34: Previous Reading % | D34: 80 | E34: Current Reading % | F34: 70 | G34: Consumption Liters | H34: =(D34-F34)*48.8 -> 488
A35: Total Cost (@ 1.82 AED/Liter) | H35: =((H34+H33)*1.82)*0.5 -> 444.08
A36: Total Utilities | H36: =H35+D22+D9+D31 -> 17122.569

Sheet November-27
A1: Daily Utilities Consumption
A2: 27.11.2024
A3: District Cooling
A4: Previous Reading MWh | B4: 70192.98 | C4: Current Reading MWh | D4: 70216.71 | E4: Consumption MWH | F4: =D4-B4 -> 23.73 | G4: Consumption RTH | H4: =F4*284.35 -> 6747.6255
A5: Cost Calculation
A6: Total Cost (0.568/rth) | D6: =H4*0.568 -> 3832.6513
A7: Total Fuel Surchage Cost (0.075/rth) | D7: =H4*0.075 -> 506.07191
A8: Chilled Water Demand (2,866 AED/Day) | D8: 2866
A9: Grand Total Exc. VAT | D9: =SUM(D6:H8) -> 7204.7232
A10: Electrical
A11: MDB-G1 (39299675-8) | C11: Previous Reading KWH | D11: 43190 | E11: Current Reading KWH | F11: 43198 | G11: Consumption KWH | H11: =F11-D11 -> 8
A12: MDB-G2 (39299676-6) | C12: Previous Reading KWH | D12: 71617 | E12: Current Reading KWH | F12: 71629 | G12: Consumption KWH | H12: =F12-D12 -> 12
A13: MDB-G3 (39299677-4) | C13: Previous Reading KWH | D13: 72434 | E13: Current Reading KWH | F13: 72444 | G13: Consumption KWH | H13: =F13-D13 -> 10
A14: Total Consumption KWH | H14: =SUM(H11:H13) -> 30
A15: Total Consumption * Multiplication Factor (487.20) | H15: =H14*487.2 -> 14616
A16: Cost Calculation
A17: 0-2000 kwh @ 0.230 /KWH | D17: 460
A18: 2000-4000 kwh @ 0.280 /KWH | D18: 560
A19: 4000-6000 kwh @ 0.320 /KWH | D19: 640
A20: 6000 & above @ 0.380 /KWH | D20: =H15*0.38 -> 5554.08
A21: Fuel Surcharge @ 0.060 /KWH | D21: =H15*0.06 -> 876.96
A22: Grand Total Exc. VAT | D22: =D20+D21 -> 6431.04
A23: WATER
A24: Previous Reading | B24: 303145 | C24: Present Reading | D24: 303328 | E24: Consumption m3 | F24: =D24-B24 -> 183 | G24: Consumption IG | H24: =F24*220 -> 40260
A25: Cost calculation
A26: 0-10000 @ 0.035 / IG | D26: 350
A27: 10000-20000 @ 0.04 / IG | D27: 400
A28: 20000 & above @ 0.046 / IG | D28: =(H24-20000)*0.046 -> 931.96
A29: Fuel Surcharge @ 0.004 / IG | D29: =H24*0.004 -> 161.04
A30: Sewerage Fees | D30: =H24*0.01 -> 402.6
A31: Grand Total Exc. VAT | D31: =SUM(D26:H30) -> 2245.6
A32: LPG Gas
A33: Tank 1 (1% = 48 liters) | C33: Previous Reading % | D33: 27 | E33: Current Reading % | F33: 17 | G33: Consumption Liters | H33: =(D33-F33)*48.8 -> 488
A34: Tank 2 (1% = 48 liters) | C34: Previous Reading % | D34: 80 | E34: Current Reading % | F34: 80 | G34: Consumption Liters | H34: =(D34-F34)*48.8 -> 0
A35: Total Cost (@ 1.82 AED/Liter) | H35: =((H34+H33)*1.82)*0.5 -> 444.08
A36: Total Utilities | H36: =H35+D22+D9+D31 -> 16325.443

Sheet November-26
A1: Daily Utilities Consumption
A2: 26.11.2024
A3: District Cooling
A4: Previous Reading MWh | B4: 70168.27 | C4: Current Reading MWh | D4: 70192.98 | E4: Consumption MWH | F4: =D4-B4 -> 24.71 | G4: Consumption RTH | H4: =F4*284.35 -> 7026.2885
A5: Cost Calculation
A6: Total Cost (0.568/rth) | D6: =H4*0.568 -> 3990.9319
A7: Total Fuel Surchage Cost (0.075/rth) | D7: =H4*0.075 -> 526.97164
A8: Chilled Water Demand (2,866 AED/Day) | D8: 2866
A9: Grand Total Exc. VAT | D9: =SUM(D6:H8) -> 7383.9035
A10: Electrical
A11: MDB-G1 (39299675-8) | C11: Previous Reading KWH | D11: 43183 | E11: Current Reading KWH | F11: 43190 | G11: Consumption KWH | H11: =F11-D11 -> 7
A12: MDB-G2 (39299676-6) | C12: Previous Reading KWH | D12: 71604 | E12: Current Reading KWH | F12: 71617 | G12: Consumption KWH | H12: =F12-D12 -> 13
A13: MDB-G3 (39299677-4) | C13: Previous Reading KWH | D13: 72424 | E13: Current Reading KWH | F13: 72434 | G13: Consumption KWH | H13: =F13-D13 -> 10
A14: Total Consumption KWH | H14: =SUM(H11:H13) -> 30
A15: Total Consumption * Multiplication Factor (487.20) | H15: =H14*487.2 -> 14616
A16: Cost Calculation
A17: 0-2000 kwh @ 0.230 /KWH | D17: 460
A18: 2000-4000 kwh @ 0.280 /KWH | D18: 560
A19: 4000-6000 kwh @ 0.320 /KWH | D19: 640
A20: 6000 & above @ 0.380 /KWH | D20: =H15*0.38 -> 5554.08
A21: Fuel Surcharge @ 0.060 /KWH | D21: =H15*0.06 -> 876.96
A22: Grand Total Exc. VAT | D22: =D20+D21 -> 6431.04
A23: WATER
A24: Previous Reading | B24: 302949 | C24: Present Reading | D24: 303145 | E24: Consumption m3 | F24: =D24-B24 -> 196 | G24: Consumption IG | H24: =F24*220 -> 43120
A25: Cost calculation
A26: 0-10000 @ 0.035 / IG | D26: 350
A27: 10000-20000 @ 0.04 / IG | D27: 400
A28: 20000 & above @ 0.046 / IG | D28: =(H24-20000)*0.046 -> 1063.52
A29: Fuel Surcharge @ 0.004 / IG | D29: =H24*0.004 -> 172.48
A30: Sewerage Fees | D30: =H24*0.01 -> 431.2
A31: Grand Total Exc. VAT | D31: =SUM(D26:H30) -> 2417.2
A32: LPG Gas
A33: Tank 1 (1% = 48 liters) | C33: Previous Reading % | D33: 37 | E33: Current Reading % | F33: 27 | G33: Consumption Liters | H33: =(D33-F33)*48.8 -> 488
A34: Tank 2 (1% = 48 liters) | C34: Previous Reading % | D34: 80 | E34: Current Reading % | F34: 80 | G34: Consumption Liters | H34: =(D34-F34)*48.8 -> 0
A35: Total Cost (@ 1.82 AED/Liter) | H35: =((H34+H33)*1.82)*0.5 -> 444.08
A36: Total Utilities | H36: =H35+D22+D9+D31 -> 16676.224

Sheet November-25
A1: Daily Utilities Consumption
A2: 25.11.2024
A3: District Cooling
A4: Previous Reading MWh | B4: 70142.67 | C4: Current Reading MWh | D4: 70168.27 | E4: Consumption MWH | F4: =D4-B4 -> 25.6 | G4: Consumption RTH | H4: =F4*284.35 -> 7279.36
A5: Cost Calculation
A6: Total Cost (0.568/rth) | D6: =H4*0.568 -> 4134.6765
A7: Total Fuel Surchage Cost (0.075/rth) | D7: =H4*0.075 -> 545.952
A8: Chilled Water Demand (2,866 AED/Day) | D8: 2866
A9: Grand Total Exc. VAT | D9: =SUM(D6:H8) -> 7546.6285
A10: Electrical
A11: MDB-G1 (39299675-8) | C11: Previous Reading KWH | D11: 43176 | E11: Current Reading KWH | F11: 43183 | G11: Consumption KWH | H11: =F11-D11 -> 7
A12: MDB-G2 (39299676-6) | C12: Previous Reading KWH | D12: 71591 | E12: Current Reading KWH | F12: 71604 | G12: Consumption KWH | H12: =F12-D12 -> 13
A13: MDB-G3 (39299677-4) | C13: Previous Reading KWH | D13: 72413 | E13: Current Reading KWH | F13: 72424 | G13: Consumption KWH | H13: =F13-D13 -> 11
A14: Total Consumption KWH | H14: =SUM(H11:H13) -> 31
A15: Total Consumption * Multiplication Factor (487.20) | H15: =H14*487.2 -> 15103.2
A16: Cost Calculation
A17: 0-2000 kwh @ 0.230 /KWH | D17: 460
A18: 2000-4000 kwh @ 0.280 /KWH | D18: 560
A19: 4000-6000 kwh @ 0.320 /KWH | D19: 640
A20: 6000 & above @ 0.380 /KWH | D20: =H15*0.38 -> 5739.216
A21: Fuel Surcharge @ 0.060 /KWH | D21: =H15*0.06 -> 906.192
A22: Grand Total Exc. VAT | D22: =D20+D21 -> 6645.408
A23: WATER
A24: Previous Reading | B24: 302739 | C24: Present Reading | D24: 302949 | E24: Consumption m3 | F24: =D24-B24 -> 210 | G24: Consumption IG | H24: =F24*220 -> 46200
A25: Cost calculation
A26: 0-10000 @ 0.035 / IG | D26: 350
A27: 10000-20000 @ 0.04 / IG | D27: 400
A28: 20000 & above @ 0.046 / IG | D28: =(H24-20000)*0.046 -> 1205.2
A29: Fuel Surcharge @ 0.004 / IG | D29: =H24*0.004 -> 184.8
A30: Sewerage Fees | D30: =H24*0.01 -> 462
A31: Grand Total Exc. VAT | D31: =SUM(D26:H30) -> 2602
A32: LPG Gas
A33: Tank 1 (1% = 48 liters) | C33: Previous Reading % | D33: 47 | E33: Current Reading % | F33: 37 | G33: Consumption Liters | H33: =(D33-F33)*48.8 -> 488
A34: Tank 2 (1% = 48 liters) | C34: Previous Reading % | D34: 80 | E34: Current Reading % | F34: 80 | G34: Consumption Liters | H34: =(D34-F34)*48.8 -> 0
A35: Total Cost (@ 1.82 AED/Liter) | H35: =((H34+H33)*1.82)*0.5 -> 444.08
A36: Total Utilities | H36: =H35+D22+D9+D31 -> 17238.116

Sheet November-24
A1: Daily Utilities Consumption
A2: 24.11.2024
A3: District Cooling
A4: Previous Reading MWh | B4: 70115.36 | C4: Current Reading MWh | D4: 70142.67 | E4: Consumption MWH | F4: =D4-B4 -> 27.31 | G4: Consumption RTH | H4: =F4*284.35 -> 7765.5985
A5: Cost Calculation
A6: Total Cost (0.568/rth) | D6: =H4*0.568 -> 4410.8599
A7: Total Fuel Surchage Cost (0.075/rth) | D7: =H4*0.075 -> 582.41989
A8: Chilled Water Demand (2,866 AED/Day) | D8: 2866
A9: Grand Total Exc. VAT | D9: =SUM(D6:H8) -> 7859.2798
A10: Electrical
A11: MDB-G1 (39299675-8) | C11: Previous Reading KWH | D11: 43170 | E11: Current Reading KWH | F11: 43176 | G11: Consumption KWH | H11: =F11-D11 -> 6
A12: MDB-G2 (39299676-6) | C12: Previous Reading KWH | D12: 71578 | E12: Current Reading KWH | F12: 71591 | G12: Consumption KWH | H12: =F12-D12 -> 13
A13: MDB-G3 (39299677-4) | C13: Previous Reading KWH | D13: 72403 | E13: Current Reading KWH | F13: 72413 | G13: Consumption KWH | H13: =F13-D13 -> 10
A14: Total Consumption KWH | H14: =SUM(H11:H13) -> 29
A15: Total Consumption * Multiplication Factor (487.20) | H15: =H14*487.2 -> 14128.8
A16: Cost Calculation
A17: 0-2000 kwh @ 0.230 /KWH | D17: 460
A18: 2000-4000 kwh @ 0.280 /KWH | D18: 560
A19: 4000-6000 kwh @ 0.320 /KWH | D19: 640
A20: 6000 & above @ 0.380 /KWH | D20: =H15*0.38 -> 5368.944
A21: Fuel Surcharge @ 0.060 /KWH | D21: =H15*0.06 -> 847.728
A22: Grand Total Exc. VAT | D22: =D20+D21 -> 6216.672
A23: WATER
A24: Previous Reading | B24: 302535 | C24: Present Reading | D24: 302739 | E24: Consumption m3 | F24: =D24-B24 -> 204 | G24: Consumption IG | H24: =F24*220 -> 44880
A25: Cost calculation
A26: 0-10000 @ 0.035 / IG | D26: 350
A27: 10000-20000 @ 0.04 / IG | D27: 400
A28: 20000 & above @ 0.046 / IG | D28: =(H24-20000)*0.046 -> 1144.48
A29: Fuel Surcharge @ 0.004 / IG | D29: =H24*0.004 -> 179.52
A30: Sewerage Fees | D30: =H24*0.01 -> 448.8
A31: Grand Total Exc. VAT | D31: =SUM(D26:H30) -> 2522.8
A32: LPG Gas
A33: Tank 1 (1% = 48 liters) | C33: Previous Reading % | D33: 57 | E33: Current Reading % | F33: 47 | G33: Consumption Liters | H33: =(D33-F33)*48.8 -> 488
A34: Tank 2 (1% = 48 liters) | C34: Previous Reading % | D34: 80 | E34: Current Reading % | F34: 80 | G34: Consumption Liters | H34: =(D34-F34)*48.8 -> 0
A35: Total Cost (@ 1.82 AED/Liter) | H35: =((H34+H33)*1.82)*0.5 -> 444.08
A36: Total Utilities | H36: =H35+D22+D9+D31 -> 17042.832

Sheet November-23
A1: Daily Utilities Consumption
A2: 23.11.2024
A3: District Cooling
A4: Previous Reading MWh | B4: 70087.78 | C4: Current Reading MWh | D4: 70115.36 | E4: Consumption MWH | F4: =D4-B4 -> 27.58 | G4: Consumption RTH | H4: =F4*284.35 -> 7842.373
A5: Cost Calculation
A6: Total Cost (0.568/rth) | D6: =H4*0.568 -> 4454.4679
A7: Total Fuel Surchage Cost (0.075/rth) | D7: =H4*0.075 -> 588.17798
A8: Chilled Water Demand (2,866 AED/Day) | D8: 2866
A9: Grand Total Exc. VAT | D9: =SUM(D6:H8) -> 7908.6458
A10: Electrical
A11: MDB-G1 (39299675-8) | C11: Previous Reading KWH | D11: 43163 | E11: Current Reading KWH | F11: 43170 | G11: Consumption KWH | H11: =F11-D11 -> 7
A12: MDB-G2 (39299676-6) | C12: Previous Reading KWH | D12: 71565 | E12: Current Reading KWH | F12: 71578 | G12: Consumption KWH | H12: =F12-D12 -> 13
A13: MDB-G3 (39299677-4) | C13: Previous Reading KWH | D13: 72391 | E13: Current Reading KWH | F13: 72403 | G13: Consumption KWH | H13: =F13-D13 -> 12
A14: Total Consumption KWH | H14: =SUM(H11:H13) -> 32
A15: Total Consumption * Multiplication Factor (487.20) | H15: =H14*487.2 -> 15590.4
A16: Cost Calculation
A17: 0-2000 kwh @ 0.230 /KWH | D17: 460
A18: 2000-4000 kwh @ 0.280 /KWH | D18: 560
A19: 4000-6000 kwh @ 0.320 /KWH | D19: 640
A20: 6000 & above @ 0.380 /KWH | D20: =H15*0.38 -> 5924.352
A21: Fuel Surcharge @ 0.060 /KWH | D21: =H15*0.06 -> 935.424
A22: Grand Total Exc. VAT | D22: =D20+D21 -> 6859.776
A23: WATER
A24: Previous Reading | B24: 302313 | C24: Present Reading | D24: 302535 | E24: Consumption m3 | F24: =D24-B24 -> 222 | G24: Consumption IG | H24: =F24*220 -> 48840
A25: Cost calculation
A26: 0-10000 @ 0.035 / IG | D26: 350
A27: 10000-20000 @ 0.04 / IG | D27: 400
A28: 20000 & above @ 0.046 / IG | D28: =(H24-20000)*0.046 -> 1326.64
A29: Fuel Surcharge @ 0.004 / IG | D29: =H24*0.004 -> 195.36
A30: Sewerage Fees | D30: =H24*0.01 -> 488.4
A31: Grand Total Exc. VAT | D31: =SUM(D26:H30) -> 2760.4
A32: LPG Gas
A33: Tank 1 (1% = 48 liters) | C33: Previous Reading % | D33: 67 | E33: Current Reading % | F33: 57 | G33: Consumption Liters | H33: =(D33-F33)*48.8 -> 488
A34: Tank 2 (1% = 48 liters) | C34: Previous Reading % | D34: 80 | E34: Current Reading % | F34: 80 | G34: Consumption Liters | H34: =(D34-F34)*48.8 -> 0
A35: Total Cost (@ 1.82 AED/Liter) | H35: =((H34+H33)*1.82)*0.5 -> 444.08
A36: Total Utilities | H36: =H35+D22+D9+D31 -> 17972.902

Sheet November-22
A1: Daily Utilities Consumption
A2: 22.11.2024
A3: District Cooling
A4: Previous Reading MWh | B4: 70062.37 | C4: Current Reading MWh | D4: 70087.78 | E4: Consumption MWH | F4: =D4-B4 -> 25.41 | G4: Consumption RTH | H4: =F4*284.35 -> 7225.3335
A5: Cost Calculation
A6: Total Cost (0.568/rth) | D6: =H4*0.568 -> 4103.9894
A7: Total Fuel Surchage Cost (0.075/rth) | D7: =H4*0.075 -> 541.90001
A8: Chilled Water Demand (2,866 AED/Day) | D8: 2866
A9: Grand Total Exc. VAT | D9: =SUM(D6:H8) -> 7511.8894
A10: Electrical
A11: MDB-G1 (39299675-8) | C11: Previous Reading KWH | D11: 43156 | E11: Current Reading KWH | F11: 43163 | G11: Consumption KWH | H11: =F11-D11 -> 7
A12: MDB-G2 (39299676-6) | C12: Previous Reading KWH | D12: 71552 | E12: Current Reading KWH | F12: 71565 | G12: Consumption KWH | H12: =F12-D12 -> 13
A13: MDB-G3 (39299677-4) | C13: Previous Reading KWH | D13: 72380 | E13: Current Reading KWH | F13: 72391 | G13: Consumption KWH | H13: =F13-D13 -> 11
A14: Total Consumption KWH | H14: =SUM(H11:H13) -> 31
A15: Total Consumption * Multiplication Factor (487.20) | H15: =H14*487.2 -> 15103.2
A16: Cost Calculation
A17: 0-2000 kwh @ 0.230 /KWH | D17: 460
A18: 2000-4000 kwh @ 0.280 /KWH | D18: 560
A19: 4000-6000 kwh @ 0.320 /KWH | D19: 640
A20: 6000 & above @ 0.380 /KWH | D20: =H15*0.38 -> 5739.216
A21: Fuel Surcharge @ 0.060 /KWH | D21: =H15*0.06 -> 906.192
A22: Grand Total Exc. VAT | D22: =D20+D21 -> 6645.408
A23: WATER
A24: Previous Reading | B24: 301941 | C24: Present Reading | D24: 302313 | E24: Consumption m3 | F24: =D24-B24 -> 372 | G24: Consumption IG | H24: =F24*220 -> 81840
A25: Cost calculation
A26: 0-10000 @ 0.035 / IG | D26: 350
A27: 10000-20000 @ 0.04 / IG | D27: 400
A28: 20000 & above @ 0.046 / IG | D28: =(H24-20000)*0.046 -> 2844.64
A29: Fuel Surcharge @ 0.004 / IG | D29: =H24*0.004 -> 327.36
A30: Sewerage Fees | D30: =H24*0.01 -> 818.4
A31: Grand Total Exc. VAT | D31: =SUM(D26:H30) -> 4740.4
A32: LPG Gas
A33: Tank 1 (1% = 48 liters) | C33: Previous Reading % | D33: 75 | E33: Current Reading % | F33: 67 | G33: Consumption Liters | H33: =(D33-F33)*48.8 -> 390.4
A34: Tank 2 (1% = 48 liters) | C34: Previous Reading % | D34: 80 | E34: Current Reading % | F34: 80 | G34: Consumption Liters | H34: =(D34-F34)*48.8 -> 0
A35: Total Cost (@ 1.82 AED/Liter) | H35: =((H34+H33)*1.82)*0.5 -> 355.264
A36: Total Utilities | H36: =H35+D22+D9+D31 -> 19252.961

Sheet November-21
A1: Daily Utilities Consumption
A2: 21.11.2024
A3: District Cooling
A4: Previous Reading MWh | B4: 70038 | C4: Current Reading MWh | D4: 70062.37 | E4: Consumption MWH | F4: =D4-B4 -> 24.37 | G4: Consumption RTH | H4: =F4*284.35 -> 6929.6095
A5: Cost Calculation
A6: Total Cost (0.568/rth) | D6: =H4*0.568 -> 3936.0182
A7: Total Fuel Surchage Cost (0.075/rth) | D7: =H4*0.075 -> 519.72071
A8: Chilled Water Demand (2,866 AED/Day) | D8: 2866
A9: Grand Total Exc. VAT | D9: =SUM(D6:H8) -> 7321.7389
A10: Electrical
A11: MDB-G1 (39299675-8) | C11: Previous Reading KWH | D11: 43149 | E11: Current Reading KWH | F11: 43156 | G11: Consumption KWH | H11: =F11-D11 -> 7
A12: MDB-G2 (39299676-6) | C12: Previous Reading KWH | D12: 71539 | E12: Current Reading KWH | F12: 71552 | G12: Consumption KWH | H12: =F12-D12 -> 13
A13: MDB-G3 (39299677-4) | C13: Previous Reading KWH | D13: 72369 | E13: Current Reading KWH | F13: 72380 | G13: Consumption KWH | H13: =F13-D13 -> 11
A14: Total Consumption KWH | H14: =SUM(H11:H13) -> 31
A15: Total Consumption * Multiplication Factor (487.20) | H15: =H14*487.2 -> 15103.2
A16: Cost Calculation
A17: 0-2000 kwh @ 0.230 /KWH | D17: 460
A18: 2000-4000 kwh @ 0.280 /KWH | D18: 560
A19: 4000-6000 kwh @ 0.320 /KWH | D19: 640
A20: 6000 & above @ 0.380 /KWH | D20: =H15*0.38 -> 5739.216
A21: Fuel Surcharge @ 0.060 /KWH | D21: =H15*0.06 -> 906.192
A22: Grand Total Exc. VAT | D22: =D20+D21 -> 6645.408
A23: WATER
A24: Previous Reading | B24: 301757 | C24: Present Reading | D24: 301941 | E24: Consumption m3 | F24: =D24-B24 -> 184 | G24: Consumption IG | H24: =F24*220 -> 40480
A25: Cost calculation
A26: 0-10000 @ 0.035 / IG | D26: 350
A27: 10000-20000 @ 0.04 / IG | D27: 400
A28: 20000 & above @ 0.046 / IG | D28: =(H24-20000)*0.046 -> 942.08
A29: Fuel Surcharge @ 0.004 / IG | D29: =H24*0.004 -> 161.92
A30: Sewerage Fees | D30: =H24*0.01 -> 404.8
A31: Grand Total Exc. VAT | D31: =SUM(D26:H30) -> 2258.8
A32: LPG Gas
A33: Tank 1 (1% = 48 liters) | C33: Previous Reading % | D33: 85 | E33: Current Reading % | F33: 75 | G33: Consumption Liters | H33: =(D33-F33)*48.8 -> 488
A34: Tank 2 (1% = 48 liters) | C34: Previous Reading % | D34: 80 | E34: Current Reading % | F34: 80 | G34: Consumption Liters | H34: =(D34-F34)*48.8 -> 0
A35: Total Cost (@ 1.82 AED/Liter) | H35: =((H34+H33)*1.82)*0.5 -> 444.08
A36: Total Utilities | H36: =H35+D22+D9+D31 -> 16670.027

Sheet November-20
A1: Daily Utilities Consumption
A2: 20.11.2024
A3: District Cooling
A4: Previous Reading MWh | B4: 70015.54 | C4: Current Reading MWh | D4: 70038 | E4: Consumption MWH | F4: =D4-B4 -> 22.46 | G4: Consumption RTH | H4: =F4*284.35 -> 6386.501
A5: Cost Calculation
A6: Total Cost (0.568/rth) | D6: =H4*0.568 -> 3627.5326
A7: Total Fuel Surchage Cost (0.075/rth) | D7: =H4*0.075 -> 478.98758
A8: Chilled Water Demand (2,866 AED/Day) | D8: 2866
A9: Grand Total Exc. VAT | D9: =SUM(D6:H8) -> 6972.5201
A10: Electrical
A11: MDB-G1 (39299675-8) | C11: Previous Reading KWH | D11: 43142 | E11: Current Reading KWH | F11: 43149 | G11: Consumption KWH | H11: =F11-D11 -> 7
A12: MDB-G2 (39299676-6) | C12: Previous Reading KWH | D12: 71526 | E12: Current Reading KWH | F12: 71539 | G12: Consumption KWH | H12: =F12-D12 -> 13
A13: MDB-G3 (39299677-4) | C13: Previous Reading KWH | D13: 72358 | E13: Current Reading KWH | F13: 72369 | G13: Consumption KWH | H13: =F13-D13 -> 11
A14: Total Consumption KWH | H14: =SUM(H11:H13) -> 31
A15: Total Consumption * Multiplication Factor (487.20) | H15: =H14*487.2 -> 15103.2
A16: Cost Calculation
A17: 0-2000 kwh @ 0.230 /KWH | D17: 460
A18: 2000-4000 kwh @ 0.280 /KWH | D18: 560
A19: 4000-6000 kwh @ 0.320 /KWH | D19: 640
A20: 6000 & above @ 0.380 /KWH | D20: =H15*0.38 -> 5739.216
A21: Fuel Surcharge @ 0.060 /KWH | D21: =H15*0.06 -> 906.192
A22: Grand Total Exc. VAT | D22: =D20+D21 -> 6645.408
A23: WATER
A24: Previous Reading | B24: 301582 | C24: Present Reading | D24: 301757 | E24: Consumption m3 | F24: =D24-B24 -> 175 | G24: Consumption IG | H24: =F24*220 -> 38500
A25: Cost calculation
A26: 0-10000 @ 0.035 / IG | D26: 350
A27: 10000-20000 @ 0.04 / IG | D27: 400
A28: 20000 & above @ 0.046 / IG | D28: =(H24-20000)*0.046 -> 851
A29: Fuel Surcharge @ 0.004 / IG | D29: =H24*0.004 -> 154
A30: Sewerage Fees | D30: =H24*0.01 -> 385
A31: Grand Total Exc. VAT | D31: =SUM(D26:H30) -> 2140
A32: LPG Gas
A33: Tank 1 (1% = 48 liters) | C33: Previous Reading % | D33: 80 | E33: Current Reading % | F33: 70 | G33: Consumption Liters | H33: =(D33-F33)*48.8 -> 488
A34: Tank 2 (1% = 48 liters) | C34: Previous Reading % | D34: 26 | E34: Current Reading % | F34: 26 | G34: Consumption Liters | H34: =(D34-F34)*48.8 -> 0
A35: Total Cost (@ 1.82 AED/Liter) | H35: =((H34+H33)*1.82)*0.5 -> 444.08
A36: Total Utilities | H36: =H35+D22+D9+D31 -> 16202.008

Sheet November-19
A1: Daily Utilities Consumption
A2: 19.11.2024
A3: District Cooling
A4: Previous Reading MWh | B4: 69992.29 | C4: Current Reading MWh | D4: 70015.54 | E4: Consumption MWH | F4: =D4-B4 -> 23.25 | G4: Consumption RTH | H4: =F4*284.35 -> 6611.1375
A5: Cost Calculation
A6: Total Cost (0.568/rth) | D6: =H4*0.568 -> 3755.1261
A7: Total Fuel Surchage Cost (0.075/rth) | D7: =H4*0.075 -> 495.83531
A8: Chilled Water Demand (2,866 AED/Day) | D8: 2866
A9: Grand Total Exc. VAT | D9: =SUM(D6:H8) -> 7116.9614
A10: Electrical
A11: MDB-G1 (39299675-8) | C11: Previous Reading KWH | D11: 43135 | E11: Current Reading KWH | F11: 43142 | G11: Consumption KWH | H11: =F11-D11 -> 7
A12: MDB-G2 (39299676-6) | C12: Previous Reading KWH | D12: 71513 | E12: Current Reading KWH | F12: 71526 | G12: Consumption KWH | H12: =F12-D12 -> 13
A13: MDB-G3 (39299677-4) | C13: Previous Reading KWH | D13: 72348 | E13: Current Reading KWH | F13: 72358 | G13: Consumption KWH | H13: =F13-D13 -> 10
A14: Total Consumption KWH | H14: =SUM(H11:H13) -> 30
A15: Total Consumption * Multiplication Factor (487.20) | H15: =H14*487.2 -> 14616
A16: Cost Calculation
A17: 0-2000 kwh @ 0.230 /KWH | D17: 460
A18: 2000-4000 kwh @ 0.280 /KWH | D18: 560
A19: 4000-6000 kwh @ 0.320 /KWH | D19: 640
A20: 6000 & above @ 0.380 /KWH | D20: =H15*0.38 -> 5554.08
A21: Fuel Surcharge @ 0.060 /KWH | D21: =H15*0.06 -> 876.96
A22: Grand Total Exc. VAT | D22: =D20+D21 -> 6431.04
A23: WATER
A24: Previous Reading | B24: 301398 | C24: Present Reading | D24: 301582 | E24: Consumption m3 | F24: =D24-B24 -> 184 | G24: Consumption IG | H24: =F24*220 -> 40480
A25: Cost calculation
A26: 0-10000 @ 0.035 / IG | D26: 350
A27: 10000-20000 @ 0.04 / IG | D27: 400
A28: 20000 & above @ 0.046 / IG | D28: =(H24-20000)*0.046 -> 942.08
A29: Fuel Surcharge @ 0.004 / IG | D29: =H24*0.004 -> 161.92
A30: Sewerage Fees | D30: =H24*0.01 -> 404.8
A31: Grand Total Exc. VAT | D31: =SUM(D26:H30) -> 2258.8
A32: LPG Gas
A33: Tank 1 (1% = 48 liters) | C33: Previous Reading % | D33: 80 | E33: Current Reading % | F33: 80 | G33: Consumption Liters | H33: =(D33-F33)*48.8 -> 0
A34: Tank 2 (1% = 48 liters) | C34: Previous Reading % | D34: 37 | E34: Current Reading % | F34: 26 | G34: Consumption Liters | H34: =(D34-F34)*48.8 -> 536.8
A35: Total Cost (@ 1.82 AED/Liter) | H35: =((H34+H33)*1.82)*0.5 -> 488.488
A36: Total Utilities | H36: =H35+D22+D9+D31 -> 16295.289

Sheet November-18
A1: Daily Utilities Consumption
A2: 18.11.2024
A3: District Cooling
A4: Previous Reading MWh | B4: 69969.52 | C4: Current Reading MWh | D4: 69992.29 | E4: Consumption MWH | F4: =D4-B4 -> 22.77 | G4: Consumption RTH | H4: =F4*284.35 -> 6474.6495
A5: Cost Calculation
A6: Total Cost (0.568/rth) | D6: =H4*0.568 -> 3677.6009
A7: Total Fuel Surchage Cost (0.075/rth) | D7: =H4*0.075 -> 485.59871
A8: Chilled Water Demand (2,866 AED/Day) | D8: 2866
A9: Grand Total Exc. VAT | D9: =SUM(D6:H8) -> 7029.1996
A10: Electrical
A11: MDB-G1 (39299675-8) | C11: Previous Reading KWH | D11: 43128 | E11: Current Reading KWH | F11: 43135 | G11: Consumption KWH | H11: =F11-D11 -> 7
A12: MDB-G2 (39299676-6) | C12: Previous Reading KWH | D12: 71500 | E12: Current Reading KWH | F12: 71513 | G12: Consumption KWH | H12: =F12-D12 -> 13
A13: MDB-G3 (39299677-4) | C13: Previous Reading KWH | D13: 72337 | E13: Current Reading KWH | F13: 72348 | G13: Consumption KWH | H13: =F13-D13 -> 11
A14: Total Consumption KWH | H14: =SUM(H11:H13) -> 31
A15: Total Consumption * Multiplication Factor (487.20) | H15: =H14*487.2 -> 15103.2
A16: Cost Calculation
A17: 0-2000 kwh @ 0.230 /KWH | D17: 460
A18: 2000-4000 kwh @ 0.280 /KWH | D18: 560
A19: 4000-6000 kwh @ 0.320 /KWH | D19: 640
A20: 6000 & above @ 0.380 /KWH | D20: =H15*0.38 -> 5739.216
A21: Fuel Surcharge @ 0.060 /KWH | D21: =H15*0.06 -> 906.192
A22: Grand Total Exc. VAT | D22: =D20+D21 -> 6645.408
A23: WATER
A24: Previous Reading | B24: 301213 | C24: Present Reading | D24: 301398 | E24: Consumption m3 | F24: =D24-B24 -> 185 | G24: Consumption IG | H24: =F24*220 -> 40700
A25: Cost calculation
A26: 0-10000 @ 0.035 / IG | D26: 350
A27: 10000-20000 @ 0.04 / IG | D27: 400
A28: 20000 & above @ 0.046 / IG | D28: =(H24-20000)*0.046 -> 952.2
A29: Fuel Surcharge @ 0.004 / IG | D29: =H24*0.004 -> 162.8
A30: Sewerage Fees | D30: =H24*0.01 -> 407
A31: Grand Total Exc. VAT | D31: =SUM(D26:H30) -> 2272
A32: LPG Gas
A33: Tank 1 (1% = 48 liters) | C33: Previous Reading % | D33: 80 | E33: Current Reading % | F33: 80 | G33: Consumption Liters | H33: =(D33-F33)*48.8 -> 0
A34: Tank 2 (1% = 48 liters) | C34: Previous Reading % | D34: 48 | E34: Current Reading % | F34: 37 | G34: Consumption Liters | H34: =(D34-F34)*48.8 -> 536.8
A35: Total Cost (@ 1.82 AED/Liter) | H35: =((H34+H33)*1.82)*0.5 -> 488.488
A36: Total Utilities | H36: =H35+D22+D9+D31 -> 16435.096

Sheet November-17
A1: Daily Utilities Consumption
A2: 17.11.2024
A3: District Cooling
A4: Previous Reading MWh | B4: 69945.98 | C4: Current Reading MWh | D4: 69969.52 | E4: Consumption MWH | F4: =D4-B4 -> 23.54 | G4: Consumption RTH | H4: =F4*284.35 -> 6693.599
A5: Cost Calculation
A6: Total Cost (0.568/rth) | D6: =H4*0.568 -> 3801.9642
A7: Total Fuel Surchage Cost (0.075/rth) | D7: =H4*0.075 -> 502.01993
A8: Chilled Water Demand (2,866 AED/Day) | D8: 2866
A9: Grand Total Exc. VAT | D9: =SUM(D6:H8) -> 7169.9842
A10: Electrical
A11: MDB-G1 (39299675-8) | C11: Previous Reading KWH | D11: 43121 | E11: Current Reading KWH | F11: 43128 | G11: Consumption KWH | H11: =F11-D11 -> 7
A12: MDB-G2 (39299676-6) | C12: Previous Reading KWH | D12: 71487 | E12: Current Reading KWH | F12: 71500 | G12: Consumption KWH | H12: =F12-D12 -> 13
A13: MDB-G3 (39299677-4) | C13: Previous Reading KWH | D13: 72326 | E13: Current Reading KWH | F13: 72337 | G13: Consumption KWH | H13: =F13-D13 -> 11
A14: Total Consumption KWH | H14: =SUM(H11:H13) -> 31
A15: Total Consumption * Multiplication Factor (487.20) | H15: =H14*487.2 -> 15103.2
A16: Cost Calculation
A17: 0-2000 kwh @ 0.230 /KWH | D17: 460
A18: 2000-4000 kwh @ 0.280 /KWH | D18: 560
A19: 4000-6000 kwh @ 0.320 /KWH | D19: 640
A20: 6000 & above @ 0.380 /KWH | D20: =H15*0.38 -> 5739.216
A21: Fuel Surcharge @ 0.060 /KWH | D21: =H15*0.06 -> 906.192
A22: Grand Total Exc. VAT | D22: =D20+D21 -> 6645.408
A23: WATER
A24: Previous Reading | B24: 301003 | C24: Present Reading | D24: 301213 | E24: Consumption m3 | F24: =D24-B24 -> 210 | G24: Consumption IG | H24: =F24*220 -> 46200
A25: Cost calculation
A26: 0-10000 @ 0.035 / IG | D26: 350
A27: 10000-20000 @ 0.04 / IG | D27: 400
A28: 20000 & above @ 0.046 / IG | D28: =(H24-20000)*0.046 -> 1205.2
A29: Fuel Surcharge @ 0.004 / IG | D29: =H24*0.004 -> 184.8
A30: Sewerage Fees | D30: =H24*0.01 -> 462
A31: Grand Total Exc. VAT | D31: =SUM(D26:H30) -> 2602
A32: LPG Gas
A33: Tank 1 (1% = 48 liters) | C33: Previous Reading % | D33: 80 | E33: Current Reading % | F33: 80 | G33: Consumption Liters | H33: =(D33-F33)*48.8 -> 0
A34: Tank 2 (1% = 48 liters) | C34: Previous Reading % | D34: 59 | E34: Current Reading % | F34: 48 | G34: Consumption Liters | H34: =(D34-F34)*48.8 -> 536.8
A35: Total Cost (@ 1.82 AED/Liter) | H35: =((H34+H33)*1.82)*0.5 -> 488.488
A36: Total Utilities | H36: =H35+D22+D9+D31 -> 16905.88

Sheet November-16
A1: Daily Utilities Consumption
A2: 16.11.2024
A3: District Cooling
A4: Previous Reading MWh | B4: 69918.26 | C4: Current Reading MWh | D4: 69945.98 | E4: Consumption MWH | F4: =D4-B4 -> 27.72 | G4: Consumption RTH | H4: =F4*284.35 -> 7882.182
A5: Cost Calculation
A6: Total Cost (0.568/rth) | D6: =H4*0.568 -> 4477.0794
A7: Total Fuel Surchage Cost (0.075/rth) | D7: =H4*0.075 -> 591.16365
A8: Chilled Water Demand (2,866 AED/Day) | D8: 2866
A9: Grand Total Exc. VAT | D9: =SUM(D6:H8) -> 7934.243
A10: Electrical
A11: MDB-G1 (39299675-8) | C11: Previous Reading KWH | D11: 43115 | E11: Current Reading KWH | F11: 43121 | G11: Consumption KWH | H11: =F11-D11 -> 6
A12: MDB-G2 (39299676-6) | C12: Previous Reading KWH | D12: 71473 | E12: Current Reading KWH | F12: 71487 | G12: Consumption KWH | H12: =F12-D12 -> 14
A13: MDB-G3 (39299677-4) | C13: Previous Reading KWH | D13: 72314 | E13: Current Reading KWH | F13: 72326 | G13: Consumption KWH | H13: =F13-D13 -> 12
A14: Total Consumption KWH | H14: =SUM(H11:H13) -> 32
A15: Total Consumption * Multiplication Factor (487.20) | H15: =H14*487.2 -> 15590.4
A16: Cost Calculation
A17: 0-2000 kwh @ 0.230 /KWH | D17: 460
A18: 2000-4000 kwh @ 0.280 /KWH | D18: 560
A19: 4000-6000 kwh @ 0.320 /KWH | D19: 640
A20: 6000 & above @ 0.380 /KWH | D20: =H15*0.38 -> 5924.352
A21: Fuel Surcharge @ 0.060 /KWH | D21: =H15*0.06 -> 935.424
A22: Grand Total Exc. VAT | D22: =D20+D21 -> 6859.776
A23: WATER
A24: Previous Reading | B24: 300780 | C24: Present Reading | D24: 301003 | E24: Consumption m3 | F24: =D24-B24 -> 223 | G24: Consumption IG | H24: =F24*220 -> 49060
A25: Cost calculation
A26: 0-10000 @ 0.035 / IG | D26: 350
A27: 10000-20000 @ 0.04 / IG | D27: 400
A28: 20000 & above @ 0.046 / IG | D28: =(H24-20000)*0.046 -> 1336.76
A29: Fuel Surcharge @ 0.004 / IG | D29: =H24*0.004 -> 196.24
A30: Sewerage Fees | D30: =H24*0.01 -> 490.6
A31: Grand Total Exc. VAT | D31: =SUM(D26:H30) -> 2773.6
A32: LPG Gas
A33: Tank 1 (1% = 48 liters) | C33: Previous Reading % | D33: 80 | E33: Current Reading % | F33: 80 | G33: Consumption Liters | H33: =(D33-F33)*48.8 -> 0
A34: Tank 2 (1% = 48 liters) | C34: Previous Reading % | D34: 68 | E34: Current Reading % | F34: 59 | G34: Consumption Liters | H34: =(D34-F34)*48.8 -> 439.2
A35: Total Cost (@ 1.82 AED/Liter) | H35: =((H34+H33)*1.82)*0.5 -> 399.672
A36: Total Utilities | H36: =H35+D22+D9+D31 -> 17967.291

Sheet November-15
A1: Daily Utilities Consumption
A2: 15.11.2024
A3: District Cooling
A4: Previous Reading MWh | B4: 69890.28 | C4: Current Reading MWh | D4: 69918.26 | E4: Consumption MWH | F4: =D4-B4 -> 27.98 | G4: Consumption RTH | H4: =F4*284.35 -> 7956.113
A5: Cost Calculation
A6: Total Cost (0.568/rth) | D6: =H4*0.568 -> 4519.0722
A7: Total Fuel Surchage Cost (0.075/rth) | D7: =H4*0.075 -> 596.70847
A8: Chilled Water Demand (2,866 AED/Day) | D8: 2866
A9: Grand Total Exc. VAT | D9: =SUM(D6:H8) -> 7981.7807
A10: Electrical
A11: MDB-G1 (39299675-8) | C11: Previous Reading KWH | D11: 43108 | E11: Current Reading KWH | F11: 43115 | G11: Consumption KWH | H11: =F11-D11 -> 7
A12: MDB-G2 (39299676-6) | C12: Previous Reading KWH | D12: 71460 | E12: Current Reading KWH | F12: 71473 | G12: Consumption KWH | H12: =F12-D12 -> 13
A13: MDB-G3 (39299677-4) | C13: Previous Reading KWH | D13: 72303 | E13: Current Reading KWH | F13: 72314 | G13: Consumption KWH | H13: =F13-D13 -> 11
A14: Total Consumption KWH | H14: =SUM(H11:H13) -> 31
A15: Total Consumption * Multiplication Factor (487.20) | H15: =H14*487.2 -> 15103.2
A16: Cost Calculation
A17: 0-2000 kwh @ 0.230 /KWH | D17: 460
A18: 2000-4000 kwh @ 0.280 /KWH | D18: 560
A19: 4000-6000 kwh @ 0.320 /KWH | D19: 640
A20: 6000 & above @ 0.380 /KWH | D20: =H15*0.38 -> 5739.216
A21: Fuel Surcharge @ 0.060 /KWH | D21: =H15*0.06 -> 906.192
A22: Grand Total Exc. VAT | D22: =D20+D21 -> 6645.408
A23: WATER
A24: Previous Reading | B24: 300567 | C24: Present Reading | D24: 300780 | E24: Consumption m3 | F24: =D24-B24 -> 213 | G24: Consumption IG | H24: =F24*220 -> 46860
A25: Cost calculation
A26: 0-10000 @ 0.035 / IG | D26: 350
A27: 10000-20000 @ 0.04 / IG | D27: 400
A28: 20000 & above @ 0.046 / IG | D28: =(H24-20000)*0.046 -> 1235.56
A29: Fuel Surcharge @ 0.004 / IG | D29: =H24*0.004 -> 187.44
A30: Sewerage Fees | D30: =H24*0.01 -> 468.6
A31: Grand Total Exc. VAT | D31: =SUM(D26:H30) -> 2641.6
A32: LPG Gas
A33: Tank 1 (1% = 48 liters) | C33: Previous Reading % | D33: 80 | E33: Current Reading % | F33: 80 | G33: Consumption Liters | H33: =(D33-F33)*48.8 -> 0
A34: Tank 2 (1% = 48 liters) | C34: Previous Reading % | D34: 77 | E34: Current Reading % | F34: 68 | G34: Consumption Liters | H34: =(D34-F34)*48.8 -> 439.2
A35: Total Cost (@ 1.82 AED/Liter) | H35: =((H34+H33)*1.82)*0.5 -> 399.672
A36: Total Utilities | H36: =H35+D22+D9+D31 -> 17668.461

Sheet November-14
A1: Daily Utilities Consumption
A2: 14.11.2024
A3: District Cooling
A4: Previous Reading MWh | B4: 69858.64 | C4: Current Reading MWh | D4: 69890.28 | E4: Consumption MWH | F4: =D4-B4 -> 31.64 | G4: Consumption RTH | H4: =F4*284.35 -> 8996.834
A5: Cost Calculation
A6: Total Cost (0.568/rth) | D6: =H4*0.568 -> 5110.2017
A7: Total Fuel Surchage Cost (0.075/rth) | D7: =H4*0.075 -> 674.76255
A8: Chilled Water Demand (2,866 AED/Day) | D8: 2866
A9: Grand Total Exc. VAT | D9: =SUM(D6:H8) -> 8650.9643
A10: Electrical
A11: MDB-G1 (39299675-8) | C11: Previous Reading KWH | D11: 43101 | E11: Current Reading KWH | F11: 43108 | G11: Consumption KWH | H11: =F11-D11 -> 7
A12: MDB-G2 (39299676-6) | C12: Previous Reading KWH | D12: 71447 | E12: Current Reading KWH | F12: 71460 | G12: Consumption KWH | H12: =F12-D12 -> 13
A13: MDB-G3 (39299677-4) | C13: Previous Reading KWH | D13: 72292 | E13: Current Reading KWH | F13: 72303 | G13: Consumption KWH | H13: =F13-D13 -> 11
A14: Total Consumption KWH | H14: =SUM(H11:H13) -> 31
A15: Total Consumption * Multiplication Factor (487.20) | H15: =H14*487.2 -> 15103.2
A16: Cost Calculation
A17: 0-2000 kwh @ 0.230 /KWH | D17: 460
A18: 2000-4000 kwh @ 0.280 /KWH | D18: 560
A19: 4000-6000 kwh @ 0.320 /KWH | D19: 640
A20: 6000 & above @ 0.380 /KWH | D20: =H15*0.38 -> 5739.216
A21: Fuel Surcharge @ 0.060 /KWH | D21: =H15*0.06 -> 906.192
A22: Grand Total Exc. VAT | D22: =D20+D21 -> 6645.408
A23: WATER
A24: Previous Reading | B24: 300375 | C24: Present Reading | D24: 300567 | E24: Consumption m3 | F24: =D24-B24 -> 192 | G24: Consumption IG | H24: =F24*220 -> 42240
A25: Cost calculation
A26: 0-10000 @ 0.035 / IG | D26: 350
A27: 10000-20000 @ 0.04 / IG | D27: 400
A28: 20000 & above @ 0.046 / IG | D28: =(H24-20000)*0.046 -> 1023.04
A29: Fuel Surcharge @ 0.004 / IG | D29: =H24*0.004 -> 168.96
A30: Sewerage Fees | D30: =H24*0.01 -> 422.4
A31: Grand Total Exc. VAT | D31: =SUM(D26:H30) -> 2364.4
A32: LPG Gas
A33: Tank 1 (1% = 48 liters) | C33: Previous Reading % | D33: 23 | E33: Current Reading % | F33: 23 | G33: Consumption Liters | H33: =(D33-F33)*48.8 -> 0
A34: Tank 2 (1% = 48 liters) | C34: Previous Reading % | D34: 68 | E34: Current Reading % | F34: 59 | G34: Consumption Liters | H34: =(D34-F34)*48.8 -> 439.2
A35: Total Cost (@ 1.82 AED/Liter) | H35: =((H34+H33)*1.82)*0.5 -> 399.672
A36: Total Utilities | H36: =H35+D22+D9+D31 -> 18060.444

Sheet November-13
A1: Daily Utilities Consumption
A2: 13.11.2024
A3: District Cooling
A4: Previous Reading MWh | B4: 69827.97 | C4: Current Reading MWh | D4: 69858.64 | E4: Consumption MWH | F4: =D4-B4 -> 30.67 | G4: Consumption RTH | H4: =F4*284.35 -> 8721.0145
A5: Cost Calculation
A6: Total Cost (0.568/rth) | D6: =H4*0.568 -> 4953.5362
A7: Total Fuel Surchage Cost (0.075/rth) | D7: =H4*0.075 -> 654.07609
A8: Chilled Water Demand (2,866 AED/Day) | D8: 2866
A9: Grand Total Exc. VAT | D9: =SUM(D6:H8) -> 8473.6123
A10: Electrical
A11: MDB-G1 (39299675-8) | C11: Previous Reading KWH | D11: 43094 | E11: Current Reading KWH | F11: 43101 | G11: Consumption KWH | H11: =F11-D11 -> 7
A12: MDB-G2 (39299676-6) | C12: Previous Reading KWH | D12: 71435 | E12: Current Reading KWH | F12: 71447 | G12: Consumption KWH | H12: =F12-D12 -> 12
A13: MDB-G3 (39299677-4) | C13: Previous Reading KWH | D13: 72281 | E13: Current Reading KWH | F13: 72292 | G13: Consumption KWH | H13: =F13-D13 -> 11
A14: Total Consumption KWH | H14: =SUM(H11:H13) -> 30
A15: Total Consumption * Multiplication Factor (487.20) | H15: =H14*487.2 -> 14616
A16: Cost Calculation
A17: 0-2000 kwh @ 0.230 /KWH | D17: 460
A18: 2000-4000 kwh @ 0.280 /KWH | D18: 560
A19: 4000-6000 kwh @ 0.320 /KWH | D19: 640
A20: 6000 & above @ 0.380 /KWH | D20: =H15*0.38 -> 5554.08
A21: Fuel Surcharge @ 0.060 /KWH | D21: =H15*0.06 -> 876.96
A22: Grand Total Exc. VAT | D22: =D20+D21 -> 6431.04
A23: WATER
A24: Previous Reading | B24: 300192 | C24: Present Reading | D24: 300375 | E24: Consumption m3 | F24: =D24-B24 -> 183 | G24: Consumption IG | H24: =F24*220 -> 40260
A25: Cost calculation
A26: 0-10000 @ 0.035 / IG | D26: 350
A27: 10000-20000 @ 0.04 / IG | D27: 400
A28: 20000 & above @ 0.046 / IG | D28: =(H24-20000)*0.046 -> 931.96
A29: Fuel Surcharge @ 0.004 / IG | D29: =H24*0.004 -> 161.04
A30: Sewerage Fees | D30: =H24*0.01 -> 402.6
A31: Grand Total Exc. VAT | D31: =SUM(D26:H30) -> 2245.6
A32: LPG Gas
A33: Tank 1 (1% = 48 liters) | C33: Previous Reading % | D33: 23 | E33: Current Reading % | F33: 23 | G33: Consumption Liters | H33: =(D33-F33)*48.8 -> 0
A34: Tank 2 (1% = 48 liters) | C34: Previous Reading % | D34: 80 | E34: Current Reading % | F34: 68 | G34: Consumption Liters | H34: =(D34-F34)*48.8 -> 585.6
A35: Total Cost (@ 1.82 AED/Liter) | H35: =((H34+H33)*1.82)*0.5 -> 532.896
A36: Total Utilities | H36: =H35+D22+D9+D31 -> 17683.148

Sheet November-12
A1: Daily Utilities Consumption
A2: 12.11.2024
A3: District Cooling
A4: Previous Reading MWh | B4: 69795.39 | C4: Current Reading MWh | D4: 69827.97 | E4: Consumption MWH | F4: =D4-B4 -> 32.58 | G4: Consumption RTH | H4: =F4*284.35 -> 9264.123
A5: Cost Calculation
A6: Total Cost (0.568/rth) | D6: =H4*0.568 -> 5262.0219
A7: Total Fuel Surchage Cost (0.075/rth) | D7: =H4*0.075 -> 694.80923
A8: Chilled Water Demand (2,866 AED/Day) | D8: 2866
A9: Grand Total Exc. VAT | D9: =SUM(D6:H8) -> 8822.8311
A10: Electrical
A11: MDB-G1 (39299675-8) | C11: Previous Reading KWH | D11: 43087 | E11: Current Reading KWH | F11: 43094 | G11: Consumption KWH | H11: =F11-D11 -> 7
A12: MDB-G2 (39299676-6) | C12: Previous Reading KWH | D12: 71422 | E12: Current Reading KWH | F12: 71435 | G12: Consumption KWH | H12: =F12-D12 -> 13
A13: MDB-G3 (39299677-4) | C13: Previous Reading KWH | D13: 72270 | E13: Current Reading KWH | F13: 72281 | G13: Consumption KWH | H13: =F13-D13 -> 11
A14: Total Consumption KWH | H14: =SUM(H11:H13) -> 31
A15: Total Consumption * Multiplication Factor (487.20) | H15: =H14*487.2 -> 15103.2
A16: Cost Calculation
A17: 0-2000 kwh @ 0.230 /KWH | D17: 460
A18: 2000-4000 kwh @ 0.280 /KWH | D18: 560
A19: 4000-6000 kwh @ 0.320 /KWH | D19: 640
A20: 6000 & above @ 0.380 /KWH | D20: =H15*0.38 -> 5739.216
A21: Fuel Surcharge @ 0.060 /KWH | D21: =H15*0.06 -> 906.192
A22: Grand Total Exc. VAT | D22: =D20+D21 -> 6645.408
A23: WATER
A24: Previous Reading | B24: 299995 | C24: Present Reading | D24: 300192 | E24: Consumption m3 | F24: =D24-B24 -> 197 | G24: Consumption IG | H24: =F24*220 -> 43340
A25: Cost calculation
A26: 0-10000 @ 0.035 / IG | D26: 350
A27: 10000-20000 @ 0.04 / IG | D27: 400
A28: 20000 & above @ 0.046 / IG | D28: =(H24-20000)*0.046 -> 1073.64
A29: Fuel Surcharge @ 0.004 / IG | D29: =H24*0.004 -> 173.36
A30: Sewerage Fees | D30: =H24*0.01 -> 433.4
A31: Grand Total Exc. VAT | D31: =SUM(D26:H30) -> 2430.4
A32: LPG Gas
A33: Tank 1 (1% = 48 liters) | C33: Previous Reading % | D33: 35 | E33: Current Reading % | F33: 23 | G33: Consumption Liters | H33: =(D33-F33)*48.8 -> 585.6
A34: Tank 2 (1% = 48 liters) | C34: Previous Reading % | D34: 80 | E34: Current Reading % | F34: 80 | G34: Consumption Liters | H34: =(D34-F34)*48.8 -> 0
A35: Total Cost (@ 1.82 AED/Liter) | H35: =((H34+H33)*1.82)*0.5 -> 532.896
A36: Total Utilities | H36: =H35+D22+D9+D31 -> 18431.535

Sheet November-11
A1: Daily Utilities Consumption
A2: 11.11.2024
A3: District Cooling
A4: Previous Reading MWh | B4: 69762.19 | C4: Current Reading MWh | D4: 69795.39 | E4: Consumption MWH | F4: =D4-B4 -> 33.2 | G4: Consumption RTH | H4: =F4*284.35 -> 9440.42
A5: Cost Calculation
A6: Total Cost (0.568/rth) | D6: =H4*0.568 -> 5362.1586
A7: Total Fuel Surchage Cost (0.075/rth) | D7: =H4*0.075 -> 708.0315
A8: Chilled Water Demand (2,866 AED/Day) | D8: 2866
A9: Grand Total Exc. VAT | D9: =SUM(D6:H8) -> 8936.1901
A10: Electrical
A11: MDB-G1 (39299675-8) | C11: Previous Reading KWH | D11: 43080 | E11: Current Reading KWH | F11: 43087 | G11: Consumption KWH | H11: =F11-D11 -> 7
A12: MDB-G2 (39299676-6) | C12: Previous Reading KWH | D12: 71408 | E12: Current Reading KWH | F12: 71422 | G12: Consumption KWH | H12: =F12-D12 -> 14
A13: MDB-G3 (39299677-4) | C13: Previous Reading KWH | D13: 72259 | E13: Current Reading KWH | F13: 72270 | G13: Consumption KWH | H13: =F13-D13 -> 11
A14: Total Consumption KWH | H14: =SUM(H11:H13) -> 32
A15: Total Consumption * Multiplication Factor (487.20) | H15: =H14*487.2 -> 15590.4
A16: Cost Calculation
A17: 0-2000 kwh @ 0.230 /KWH | D17: 460
A18: 2000-4000 kwh @ 0.280 /KWH | D18: 560
A19: 4000-6000 kwh @ 0.320 /KWH | D19: 640
A20: 6000 & above @ 0.380 /KWH | D20: =H15*0.38 -> 5924.352
A21: Fuel Surcharge @ 0.060 /KWH | D21: =H15*0.06 -> 935.424
A22: Grand Total Exc. VAT | D22: =D20+D21 -> 6859.776
A23: WATER
A24: Previous Reading | B24: 299792 | C24: Present Reading | D24: 299995 | E24: Consumption m3 | F24: =D24-B24 -> 203 | G24: Consumption IG | H24: =F24*220 -> 44660
A25: Cost calculation
A26: 0-10000 @ 0.035 / IG | D26: 350
A27: 10000-20000 @ 0.04 / IG | D27: 400
A28: 20000 & above @ 0.046 / IG | D28: =(H24-20000)*0.046 -> 1134.36
A29: Fuel Surcharge @ 0.004 / IG | D29: =H24*0.004 -> 178.64
A30: Sewerage Fees | D30: =H24*0.01 -> 446.6
A31: Grand Total Exc. VAT | D31: =SUM(D26:H30) -> 2509.6
A32: LPG Gas
A33: Tank 1 (1% = 48 liters) | C33: Previous Reading % | D33: 45 | E33: Current Reading % | F33: 35 | G33: Consumption Liters | H33: =(D33-F33)*48.8 -> 488
A34: Tank 2 (1% = 48 liters) | C34: Previous Reading % | D34: 80 | E34: Current Reading % | F34: 80 | G34: Consumption Liters | H34: =(D34-F34)*48.8 -> 0
A35: Total Cost (@ 1.82 AED/Liter) | H35: =((H34+H33)*1.82)*0.5 -> 444.08
A36: Total Utilities | H36: =H35+D22+D9+D31 -> 18749.646

Sheet November-10
A1: Daily Utilities Consumption
A2: 10.11.2024
A3: District Cooling
A4: Previous Reading MWh | B4: 69731.68 | C4: Current Reading MWh | D4: 69762.19 | E4: Consumption MWH | F4: =D4-B4 -> 30.51 | G4: Consumption RTH | H4: =F4*284.35 -> 8675.5185
A5: Cost Calculation
A6: Total Cost (0.568/rth) | D6: =H4*0.568 -> 4927.6945
A7: Total Fuel Surchage Cost (0.075/rth) | D7: =H4*0.075 -> 650.66389
A8: Chilled Water Demand (2,866 AED/Day) | D8: 2866
A9: Grand Total Exc. VAT | D9: =SUM(D6:H8) -> 8444.3584
A10: Electrical
A11: MDB-G1 (39299675-8) | C11: Previous Reading KWH | D11: 43073 | E11: Current Reading KWH | F11: 43080 | G11: Consumption KWH | H11: =F11-D11 -> 7
A12: MDB-G2 (39299676-6) | C12: Previous Reading KWH | D12: 71396 | E12: Current Reading KWH | F12: 71408 | G12: Consumption KWH | H12: =F12-D12 -> 12
A13: MDB-G3 (39299677-4) | C13: Previous Reading KWH | D13: 72248 | E13: Current Reading KWH | F13: 72259 | G13: Consumption KWH | H13: =F13-D13 -> 11
A14: Total Consumption KWH | H14: =SUM(H11:H13) -> 30
A15: Total Consumption * Multiplication Factor (487.20) | H15: =H14*487.2 -> 14616
A16: Cost Calculation
A17: 0-2000 kwh @ 0.230 /KWH | D17: 460
A18: 2000-4000 kwh @ 0.280 /KWH | D18: 560
A19: 4000-6000 kwh @ 0.320 /KWH | D19: 640
A20: 6000 & above @ 0.380 /KWH | D20: =H15*0.38 -> 5554.08
A21: Fuel Surcharge @ 0.060 /KWH | D21: =H15*0.06 -> 876.96
A22: Grand Total Exc. VAT | D22: =D20+D21 -> 6431.04
A23: WATER
A24: Previous Reading | B24: 299569 | C24: Present Reading | D24: 299792 | E24: Consumption m3 | F24: =D24-B24 -> 223 | G24: Consumption IG | H24: =F24*220 -> 49060
A25: Cost calculation
A26: 0-10000 @ 0.035 / IG | D26: 350
A27: 10000-20000 @ 0.04 / IG | D27: 400
A28: 20000 & above @ 0.046 / IG | D28: =(H24-20000)*0.046 -> 1336.76
A29: Fuel Surcharge @ 0.004 / IG | D29: =H24*0.004 -> 196.24
A30: Sewerage Fees | D30: =H24*0.01 -> 490.6
A31: Grand Total Exc. VAT | D31: =SUM(D26:H30) -> 2773.6
A32: LPG Gas
A33: Tank 1 (1% = 48 liters) | C33: Previous Reading % | D33: 55 | E33: Current Reading % | F33: 45 | G33: Consumption Liters | H33: =(D33-F33)*48.8 -> 488
A34: Tank 2 (1% = 48 liters) | C34: Previous Reading % | D34: 80 | E34: Current Reading % | F34: 80 | G34: Consumption Liters | H34: =(D34-F34)*48.8 -> 0
