Workbook
Name شت8: 'cost.5.25'!$H$18

Sheet Total
A1: Site Name | B1: Day | C1: Month | D1: Year | E1: Total Electricity Kwh | F1: Electricity Tariff ($/Kwh) | G1: LPG (Liters) | H1: LPG $/Liters | I1: Total Fuel Oil (Liter) | J1: Fuel Oil $/Liter | K1: Water Utility Supply (m3) m3 | L1: Water Utility Supply (m3) $/m3 | M1: Room Nights | N1: Total Guests
A2: Grand Rotana Sharm El Sheikh | B2: 1 | C2: 5 | D2: 2025 | E2: ='cost.5.25'!J8 -> 37560 | F2: 1.49 | G2: ='cost.5.25'!AN8 -> 934.352 | H2: ='cost.5.25'!AS8/'cost.5.25'!AN8 -> 3.8028413 | I2: ='cost.5.25'!O8 -> 0 | J2: ='cost.5.25'!T8/'cost.5.25'!O8 -> #DIV/0! | K2: ='cost.5.25'!V8 -> 704 | L2: ='cost.5.25'!Z8/'cost.5.25'!V8 -> 5.1 | M2: ='cost.5.25'!F8 -> 453.9906
A3: Grand Rotana Sharm El Sheikh | B3: =B2+1 -> 2 | C3: 5 | D3: 2025 | E3: ='cost.5.25'!J9 -> 37720 | F3: 1.49 | G3: ='cost.5.25'!AN9 -> 1097.848 | H3: ='cost.5.25'!AS9/'cost.5.25'!AN9 -> 3.8344705 | I3: ='cost.5.25'!O9 -> 0 | J3: ='cost.5.25'!T9/'cost.5.25'!O9 -> #DIV/0! | K3: ='cost.5.25'!V9 -> 712 | L3: ='cost.5.25'!Z9/'cost.5.25'!V9 -> 5.1 | M3: ='cost.5.25'!F9 -> 453.9906
A4: Grand Rotana Sharm El Sheikh | B4: =B3+1 -> 3 | C4: 5 | D4: 2025 | E4: ='cost.5.25'!J10 -> 37240 | F4: 1.49 | G4: ='cost.5.25'!AN10 -> 808.316 | H4: ='cost.5.25'!AS10/'cost.5.25'!AN10 -> 3.7720995 | I4: ='cost.5.25'!O10 -> 0 | J4: ='cost.5.25'!T10/'cost.5.25'!O10 -> #DIV/0! | K4: ='cost.5.25'!V10 -> 576 | L4: ='cost.5.25'!Z10/'cost.5.25'!V10 -> 5.1 | M4: ='cost.5.25'!F10 -> 453.9906
A5: Grand Rotana Sharm El Sheikh | B5: =B4+1 -> 4 | C5: 5 | D5: 2025 | E5: ='cost.5.25'!J11 -> 37240 | F5: 1.49 | G5: ='cost.5.25'!AN11 -> 892.514 | H5: ='cost.5.25'!AS11/'cost.5.25'!AN11 -> 3.797783 | I5: ='cost.5.25'!O11 -> 0 | J5: ='cost.5.25'!T11/'cost.5.25'!O11 -> #DIV/0! | K5: ='cost.5.25'!V11 -> 719 | L5: ='cost.5.25'!Z11/'cost.5.25'!V11 -> 5.1 | M5: ='cost.5.25'!F11 -> 390.9758
A6: Grand Rotana Sharm El Sheikh | B6: =B5+1 -> 5 | C6: 5 | D6: 2025 | E6: ='cost.5.25'!J12 -> 32320 | F6: 1.49 | G6: ='cost.5.25'!AN12 -> 915.97 | H6: ='cost.5.25'!AS12/'cost.5.25'!AN12 -> 3.8056791 | I6: ='cost.5.25'!O12 -> 0 | J6: ='cost.5.25'!T12/'cost.5.25'!O12 -> #DIV/0! | K6: ='cost.5.25'!V12 -> 688 | L6: ='cost.5.25'!Z12/'cost.5.25'!V12 -> 5.1 | M6: ='cost.5.25'!F12 -> 377.9836
A7: Grand Rotana Sharm El Sheikh | B7: =B6+1 -> 6 | C7: 5 | D7: 2025 | E7: ='cost.5.25'!J13 -> 35720 | F7: 1.49 | G7: ='cost.5.25'!AN13 -> 851.256 | H7: ='cost.5.25'!AS13/'cost.5.25'!AN13 -> 3.8069906 | I7: ='cost.5.25'!O13 -> 0 | J7: ='cost.5.25'!T13/'cost.5.25'!O13 -> #DIV/0! | K7: ='cost.5.25'!V13 -> 644 | L7: ='cost.5.25'!Z13/'cost.5.25'!V13 -> 5.1 | M7: ='cost.5.25'!F13 -> 347.0022
A8: Grand Rotana Sharm El Sheikh | B8: =B7+1 -> 7 | C8: 5 | D8: 2025 | E8: ='cost.5.25'!J14 -> 39120 | F8: 1.49 | G8: ='cost.5.25'!AN14 -> 893.094 | H8: ='cost.5.25'!AS14/'cost.5.25'!AN14 -> 3.8118513 | I8: ='cost.5.25'!O14 -> 0 | J8: ='cost.5.25'!T14/'cost.5.25'!O14 -> #DIV/0! | K8: ='cost.5.25'!V14 -> 707 | L8: ='cost.5.25'!Z14/'cost.5.25'!V14 -> 5.1 | M8: ='cost.5.25'!F14 -> 442.103
A9: Grand Rotana Sharm El Sheikh | B9: =B8+1 -> 8 | C9: 5 | D9: 2025 | E9: ='cost.5.25'!J15 -> 38960 | F9: 1.49 | G9: ='cost.5.25'!AN15 -> 980.684 | H9: ='cost.5.25'!AS15/'cost.5.25'!AN15 -> 3.8045407 | I9: ='cost.5.25'!O15 -> 0 | J9: ='cost.5.25'!T15/'cost.5.25'!O15 -> #DIV/0! | K9: ='cost.5.25'!V15 -> 692 | L9: ='cost.5.25'!Z15/'cost.5.25'!V15 -> 5.1 | M9: ='cost.5.25'!F15 -> 417.0128
A10: Grand Rotana Sharm El Sheikh | B10: =B9+1 -> 9 | C10: 5 | D10: 2025 | E10: ='cost.5.25'!J16 -> 0 | F10: 1.49 | G10: ='cost.5.25'!AN16 -> 0 | H10: ='cost.5.25'!AS16/'cost.5.25'!AN16 -> #DIV/0! | I10: ='cost.5.25'!O16 -> 0 | J10: ='cost.5.25'!T16/'cost.5.25'!O16 -> #DIV/0! | K10: ='cost.5.25'!V16 -> 0 | L10: ='cost.5.25'!Z16/'cost.5.25'!V16 -> #DIV/0! | M10: ='cost.5.25'!F16 -> 0
A11: Grand Rotana Sharm El Sheikh | B11: =B10+1 -> 10 | C11: 5 | D11: 2025 | E11: ='cost.5.25'!J17 -> 0 | F11: 1.49 | G11: ='cost.5.25'!AN17 -> 0 | H11: ='cost.5.25'!AS17/'cost.5.25'!AN17 -> #DIV/0! | I11: ='cost.5.25'!O17 -> 0 | J11: ='cost.5.25'!T17/'cost.5.25'!O17 -> #DIV/0! | K11: ='cost.5.25'!V17 -> 0 | L11: ='cost.5.25'!Z17/'cost.5.25'!V17 -> #DIV/0! | M11: ='cost.5.25'!F17 -> 0
A12: Grand Rotana Sharm El Sheikh | B12: =B11+1 -> 11 | C12: 5 | D12: 2025 | E12: ='cost.5.25'!J18 -> 0 | F12: 1.49 | G12: ='cost.5.25'!AN18 -> 0 | H12: ='cost.5.25'!AS18/'cost.5.25'!AN18 -> #DIV/0! | I12: ='cost.5.25'!O18 -> 0 | J12: ='cost.5.25'!T18/'cost.5.25'!O18 -> #DIV/0! | K12: ='cost.5.25'!V18 -> 0 | L12: ='cost.5.25'!Z18/'cost.5.25'!V18 -> #DIV/0! | M12: ='cost.5.25'!F18 -> 0
A13: Grand Rotana Sharm El Sheikh | B13: =B12+1 -> 12 | C13: 5 | D13: 2025 | E13: ='cost.5.25'!J19 -> 0 | F13: 1.49 | G13: ='cost.5.25'!AN19 -> 0 | H13: ='cost.5.25'!AS19/'cost.5.25'!AN19 -> #DIV/0! | I13: ='cost.5.25'!O19 -> 0 | J13: ='cost.5.25'!T19/'cost.5.25'!O19 -> #DIV/0! | K13: ='cost.5.25'!V19 -> 0 | L13: ='cost.5.25'!Z19/'cost.5.25'!V19 -> #DIV/0! | M13: ='cost.5.25'!F19 -> 0
A14: Grand Rotana Sharm El Sheikh | B14: =B13+1 -> 13 | C14: 5 | D14: 2025 | E14: ='cost.5.25'!J20 -> 0 | F14: 1.49 | G14: ='cost.5.25'!AN20 -> 0 | H14: ='cost.5.25'!AS20/'cost.5.25'!AN20 -> #DIV/0! | I14: ='cost.5.25'!O20 -> 0 | J14: ='cost.5.25'!T20/'cost.5.25'!O20 -> #DIV/0! | K14: ='cost.5.25'!V20 -> 0 | L14: ='cost.5.25'!Z20/'cost.5.25'!V20 -> #DIV/0! | M14: ='cost.5.25'!F20 -> 0
... A31: Grand Rotana Sharm El Sheikh | B31: =B30+1 -> 30 | C31: 5 | D31: 2025 | E31: ='cost.5.25'!J37 -> 0 | F31: 1.49 | G31: ='cost.5.25'!AN37 -> 0 | H31: ='cost.5.25'!AS37/'cost.5.25'!AN37 -> #DIV/0! | I31: ='cost.5.25'!O37 -> 0 | J31: ='cost.5.25'!T37/'cost.5.25'!O37 -> #DIV/0! | K31: ='cost.5.25'!V37 -> 0 | L31: ='cost.5.25'!Z37/'cost.5.25'!V37 -> #DIV/0! | M31: ='cost.5.25'!F37 -> 0
A32: Grand Rotana Sharm El Sheikh | B32: =B31+1 -> 31 | C32: 5 | D32: 2025 | I32: ='cost.5.25'!O39 -> 0 | J32: ='cost.5.25'!T39/'cost.5.25'!O39 -> #DIV/0!

Sheet Daily Consumption
A1: Date: | B1: =TODAY()-1 -> 45786
A2: Energy Consumption
L3: Month To Date Energy Cost per Occupied Room
B4: Today | F4: Month To Date
B5: Actual | C5: Budget | D5: Act Vs Bdgt | E5: Forecast | F5: Actual | G5: Budget | H5: Act Vs Bdgt | I5: Act Vs Forcast | J5: Forecast
A7: Occupied Rooms | B7: =VLOOKUP(B1,'Reading.5.25'!A5:EL36,39,FALSE) -> 0 | C7: 286 | D7: =B7-C7 -> -286 | E7: 399.48 | F7: ='Reading.5.25'!AM37 -> 3337.0492 | G7: =C7*DAY(B1) -> 2574 | H7: =(F7-G7)/F7 -> 0.22865986 | I7: =(F7-J7)/F7 -> -0.077394963 | J7: =E7*DAY(B1) -> 3595.32
A8: Occupancy | B8: =VLOOKUP(B1,'Reading.5.25'!A5:EL36,35,FALSE) -> 0 | C8: 0.545 | D8: =B8-C8 -> -0.545 | E8: 0.759 | F8: ='Reading.5.25'!AI37 -> 0.793025 | G8: =C8 -> 0.545 | H8: =F8-G8 -> 0.248025 | I8: =F8-J8 -> 0.034025 | J8: 0.759
A10: Electricity - KWH | B10: =VLOOKUP(B1,'Reading.5.25'!A5:EL36,31,FALSE) -> 0 | C10: ='Reading.5.25'!AG6 -> 38659.097 | D10: =B10-C10 -> -38659.097 | E10: 39000 | F10: ='Reading.5.25'!AE37 -> 295880 | G10: =C10*DAY(B1) -> 347931.87 | H10: =(F10-G10)/F10 -> -0.17592224 | I10: =(F10-J10)/F10 -> -0.18629174 | J10: =+E10*DAY(B1) -> 351000
A11: Fuel - Liter | B11: =VLOOKUP(B1,'Reading.5.25'!A5:EL36,20,FALSE) -> 0 | C11: ='cost.5.25'!P8 -> 0 | D11: =B11-C11 -> 0 | E11: 0 | F11: ='Reading.5.25'!T37 -> 0 | G11: =C11*DAY(B1) -> 0 | H11: =F11-G11 -> 0 | I11: =F11-J11 -> 0 | J11: 0
A13: Boilers Gas - Cu.Mt. | B13: =VLOOKUP(B1,'Reading.5.25'!A5:EL36,15,FALSE) -> 0 | C13: ='cost.5.25'!AD8 -> 522.72581 | D13: =B13-C13 -> -522.72581 | E13: 722 | F13: ='Reading.5.25'!O37 -> 5306.11 | G13: =C13*DAY(B1) -> 4704.5323 | H13: =(F13-G13)/F13 -> 0.11337453 | I13: =(F13-J13)/F13 -> -0.22462595 | J13: =E13*DAY(B1) -> 6498
A14: Kitchens Gas - Cu. Mt. | B14: =VLOOKUP(B1,'Reading.5.25'!A5:EL36,11,FALSE) -> 0 | C14: ='cost.5.25'!AJ8 -> 174.24194 | D14: =B14-C14 -> -174.24194 | E14: 240 | F14: ='Reading.5.25'!K37 -> 2067.924 | G14: =C14*DAY(B1) -> 1568.1774 | H14: =(F14-G14)/F14 -> 0.24166584 | I14: =(F14-J14)/F14 -> -0.044525814 | J14: =E14*DAY(B1) -> 2160
H15: =F15-G15 -> 0
A16: Water To Staff House - Cu.Mt. | B16: =VLOOKUP(B1,'Reading.5.25'!A2:EL36,88,FALSE) -> 0 | C16: 0 | D16: =B16-C16 -> 0 | E16: 0 | F16: 0 | G16: 0 | H16: =F16-G16 -> 0 | J16: 0
A17: Laundry Water - Cu.Mt. | B17: =VLOOKUP(B1,'Reading.5.25'!A5:EL36,73,FALSE) -> 0 | C17: 0 | D17: =-B17-C17 -> 0 | E17: 0 | F17: ='Reading.5.25'!BU37 -> 453 | G17: 0 | H17: =F17-G17 -> 453 | J17: 0
A18: Kitchen Water - Cu.Mt. | B18: =VLOOKUP(B1,'Reading.5.25'!A5:EL36,69,FALSE) -> 0 | C18: 0 | D18: =B18-C18 -> 0 | E18: 0 | F18: ='Reading.5.25'!BQ37 -> 328 | G18: 0 | H18: =F18-G18 -> 328 | J18: 0
A19: Hotel Water - Cu.Mt. | B19: =VLOOKUP(B1,'Reading.5.25'!A5:EL36,6,FALSE) -> 0 | C19: ='cost.5.25'!W8 -> 607.90323 | D19: =B19-C19 -> -607.90323 | E19: 660 | F19: ='cost.5.25'!V39 -> 5442 | G19: ='cost.5.25'!W39 -> 4863.2258 | H19: =(F19-G19)/F19 -> 0.10635321 | I19: =(F19-J19)/F19 -> -0.091510474 | J19: =E19*DAY(B1) -> 5940
A21: Total Energy Cost - L.E. | B21: =VLOOKUP(B1,'cost.5.25'!B8:BI37,56,FALSE) -> 0 | C21: ='cost.5.25'!BD8 -> 86204.29 | D21: =B21-C21 -> -86204.29 | E21: =(E10*1.94)+(E19*5.1)+((E13+E14)*5) -> 83836 | F21: =+(F10*1.94)+((F13+F14)*5)+(F19*5.1) -> 638631.57 | G21: =C21*DAY(B1) -> 775838.61 | H21: =(F21-G21)/F21 -> -0.21484538 | I21: =(F21-J21)/F21 -> -0.18146994 | J21: =+(J10*1.94)+((J13+J14)*5)+(J19*5.1) -> 754524
A22: Energy Cost per Occupied Room | B22: =B21/B7 -> #DIV/0! | C22: =C21/C7 -> 301.4136 | D22: =B22-C22 -> #DIV/0! | E22: =E21/E7 -> 209.86282 | F22: =F21/F7 -> 191.37613 | G22: =G21/G7 -> 301.4136 | H22: =(F22-G22)/F22 -> -0.57498011 | I22: =(F22-J22)/F22 -> -0.096598718 | J22: =J21/J7 -> 209.86282
A23: Energy Cost per Available Room | B23: =B21/526 -> 0 | C23: =C21/526 -> 163.88648 | D23: =B23-C23 -> -163.88648 | E23: =E21/526 -> 159.38403 | F23: =F21/(526*DAY(B1)) -> 134.90316 | G23: =G21/(DAY(B1)*526) -> 163.88648 | H23: =(F23-G23)/F23 -> -0.21484538 | I23: =(F23-J23)/F23 -> -0.18146994 | J23: =J21/(526*DAY(B1)) -> 159.38403
A45: Month To Date Electricity Consumption | E45: Month To Date Energy Consumption | L45: Month To Date Kitchens' Gas Consumption
E46: Laundry Performance | L46: Kitchens Performance
A47: Electricity Maximum Demand KW | B47: Today | E47: Target | F47: Last Year | H47: Elec.(Kw)/Room | I47: Today | J47: MTD | K47: Budgeted | L47: Act. LE | M47: Budget LE | N47: Act Vs Bdg | O47: % Budget | P47: forcast | Q47: Act Vs Fos | R47: %forcast
B48: Actual | C48: Last Period | E48: This Period | F48: This Period | I48: =B10/B7 -> #DIV/0! | J48: =F10/F7 -> 88.66516 | K48: =C10/C7 -> 135.17167 | L48: ='cost.5.25'!M39 -> 574007.2 | M48: ='cost.5.25'!K39 -> 643545.29 | N48: =L48-M48 -> -69538.09 | O48: =(L48/M48)-1 -> -0.1080547 | P48: =J10*1.94 -> 680940 | Q48: =L48-P48 -> -106932.8 | R48: =(L48/P48)-1 -> -0.15703704
B49: ='Reading.5.25'!AQ37 -> 2056 | C49: ='Reading.5.25'!AQ38 -> 2216 | E49: 2180 | F49: 2120
A51: Weather Temperature ⁰C | B51: Today | E51: Month To Date | H51: Water(l)/Room | I51: Today | J51: MTD | K51: Budgeted | L51: Act. LE | M51: Budget LE | N51: Diff | O51: % | P51: forcast | Q51: Act Vs Fos | R51: % forcast
B52: Actual | C52: Last year | E52: Actual | F52: Last Year | I52: =B19/B7 -> #DIV/0! | J52: =F19/F7 -> 1.6307821 | K52: =C19/C7 -> 2.1255358 | L52: ='cost.5.25'!Z39 -> 27754.2 | M52: ='cost.5.25'!X39 -> 24803.097 | N52: =L52-M52 -> 2951.1032 | O52: =(L52/M52)-1 -> 0.11898124 | P52: =J19*5.1 -> 30294 | Q52: =L52-P52 -> -2539.8 | R52: =(L52/P52)-1 -> -0.083838384
B53: =VLOOKUP(B1,'Reading.5.25'!A5:EL36,55,FALSE) -> 0 | C53: =VLOOKUP(B1,'Reading.5.25'!A5:EL36,59,FALSE) -> 0 | E53: ='Reading.5.25'!BC37 -> 28.375 | F53: ='Reading.5.25'!BG37 -> 80
A54: Humidity % | B54: =VLOOKUP(B1,'Reading.5.25'!A5:EL36,58,FALSE) -> 0 | C54: 60 | E54: ='Reading.5.25'!BF37 -> 23.75 | F54: =VLOOKUP(B1,'Reading.5.25'!A5:EL36,62,FALSE) -> 0 | H54: Energy - MTD | I54: Energy - forcast | J54: Diff | K54: % | P54: Ro. Production | R54: =VLOOKUP(B1,'Reading.5.25'!A5:EL36,3,FALSE) -> 0
H55: =+F21 -> 638631.57 | I55: =+J21 -> 754524 | J55: =+H55-I55 -> -115892.43 | K55: =+(H55/I55)-1 -> -0.15359674 | P55: Hotel consumption | R55: =+B19 -> 0
A56: Comments: | P56: Diff. | R56: =+R54-R55 -> 0

Sheet Reading.5.25
A1: 1 | B1: 2 | C1: 3 | D1: 4 | E1: 5 | F1: 6 | G1: 7 | H1: 8 | I1: 9 | J1: 10 | K1: 11 | L1: 12 | M1: 13 | N1: 14 | O1: 15 | P1: 16 | Q1: 17 | R1: 18 | S1: 19 | T1: 20 | U1: 21 | V1: 22 | W1: 23 | X1: 24 | Y1: 25 | Z1: 26 | AA1: 27 | AB1: 28 | AC1: 29 | AD1: 30 | AE1: 31 | AF1: 32 | AG1: 33 | AH1: 34 | AI1: 35 | AJ1: 36 | AK1: 37 | AL1: 38 | AM1: 39 | AN1: 40 | AO1: 41 | AP1: 42 | AQ1: 43 | AR1: 44 | AS1: 45 | AT1: 46 | AU1: 47 | AV1: 48 | AW1: 49 | AX1: 50 | AY1: 51 | AZ1: 52 | BA1: 53 | BB1: 54 | BC1: 55 | BD1: 56 | BE1: 57 | BF1: 58 | BG1: 59 | BH1: 60 | BI1: 61 | BJ1: 62 | BK1: 63 | BL1: 64 | BM1: 65 | BN1: 66 | BO1: 67 | BP1: 68 | BQ1: 69 | BR1: 70 | BS1: 71 | BT1: 72 | BU1: 73 | BV1: 74 | BW1: 75 | BX1: 76 | BY1: 77 | BZ1: 78 | CA1: 79 | CB1: 80 | CC1: 81 | CD1: 82 | CE1: 83 | CF1: 84 | CG1: 85 | CH1: 86 | CI1: 87 | CJ1: 88 | CK1: 89 | CL1: 90 | CM1: 91 | CN1: 92 | CO1: 93 | CP1: 94 | CQ1: 95 | CR1: 96 | CS1: 97 | CT1: 98 | CU1: 99 | CV1: 100 | CW1: 101 | CX1: 102 | CY1: 103 | CZ1: 104 | DA1: 105 | DB1: 106 | DC1: 107 | DD1: 108 | DE1: 109 | DF1: 110 | DG1: 111 | DH1: 112 | DI1: 113 | DJ1: 114 | DK1: 115 | DL1: 116 | DM1: 117 | DN1: 118 | DO1: 119 | DP1: 120 | DQ1: 121 | DR1: 122 | DS1: 123 | DT1: 124 | DU1: 125 | DV1: 126 | DW1: 127 | DX1: 128 | DY1: 129 | DZ1: 130 | EA1: 131 | EB1: 132 | EC1: 133 | ED1: 134 | EE1: 135 | EF1: 136 | EG1: 137 | EH1: 138 | EI1: 139 | EJ1: 140 | EK1: 141 | EL1: 142
B2: WATER | J2: KITCHEN GAS | N2: BOILER GAS | R2: FUEL | W2: ELECTRICITY | AA2: GENERATORS | AE2: TOTAL KWH | AI2: Occupancy % | AM2: Rooms Occupied | AQ2: Max. Demand | AT2: Power Factor | AY2: More Data | BC2: Weather Temperature | BL2: Available Rooms | BN2: Water Sold Last Year | BP2: Kitchen Water | BT2: Laundry Water | BX2: Fountain Water | CB2: S. Pool Water | CF2: Heated Pool Water | CI2: Staff Houses Water | CM2: Total Facilities Cons. | CP2: STP | CV2: Dishwasher | CZ2: Staff Kitchen | DD2: Laundry Electricity | DH2: Kit. Equip. Electricity | DL2: Chiller 1 | DP2: Chiller 2 | DT2: Chiller 3 | DX2: Chilled Pumps KWH | DZ2: Total Chillers | EC2: RO Plant | EF2: Staff Kitchen Gas | EJ2: Rotary Oven Gas | EN2: Water Counter Reading | ES2: Jockey Pump | ET2: Consumption
A4: Date | B4: Reading | C4: Product. | D4: Sold | E4: Tanks Level | F4: Counters reading | G4: Consump. This Year | H4: Last Year | J4: Reading | K4: Consump. This Year | L4: Last Year | N4: Reading | O4: Consump. This Year | P4: Last Year | R4: Reading | S4: Add | T4: Consump. This Year | U4: Last Year | W4: Reading | X4: Consump. This Year | Y4: Consump. Last Year | AA4: Reading | AB4: Consump. This Year | AC4: Consump. Last Year | AE4: This Year | AF4: Last Year | AG4: Budget | AI4: This Year | AJ4: Last Year | AK4: Budget | AM4: This Year | AN4: Last Year | AO4: Budget | AQ4: This Year KW | AR4: Last Year KW | AT4: KVAR Reading | AU4: KVAR Cons. | AV4: Cos Ø | AY4: Last Year OCT 2023 | BC4: This Year - May 2025 | BG4: Last Year - May 2024 | BP4: Counter Reading | BQ4: Consumption This year | BR4: Consumption Last Year | BT4: Counter Reading | BU4: Consumption | BV4: Consumption Last Year | BX4: Counter Reading | BY4: Consumption | BZ4: Consumption Last Year | CB4: Counter Reading | CC4: Consumption | CD4: Consumption Last Year | CF4: Counter Reading | CG4: Consumption | CH4: Consumption Last Year | CI4: Counter Reading | CJ4: Consumption | CK4: Consumption Last Year | CM4: This Year | CN4: Last Year | CP4: Counter Reading | CQ4: Recycled Water this Year | CR4: % | CS4: Reccycled Water Last Year | CT4: % | CV4: Counter Reading | CW4: Cons. | CX4: Cons. Last Year | CZ4: Counter Reading | DA4: Cons. | DB4: Cons. Last Year | DD4: Counter Reading | DE4: Cons. | DF4: Cons. Last Year | DH4: Counter Reading | DI4: Cons. | DJ4: Cons. Last Year | DL4: Counter Reading | DM4: Cons. | DN4: Cons. Last Year | DP4: Counter Reading | DQ4: Cons. | DR4: Cons. Last Year | DT4: Counter Reading | DU4: Cons. | DV4: Cons. Last Year | DZ4: Cons. | EA4: Cons. Last Year | EC4: KWH This Year | ED4: KWH Last Year | EF4: Counter Reading | EG4: Cons. | EH4: Cons. Last Year | EJ4: Counter Reading | EK4: Cons. | EL4: Cons. Last Year | EN4: C1 | EO4: C2 | EP4: C3 | EQ4: Total
B5: 522960 | E5: 740 | G5: =F5+ET5 -> 0 | J5: 225832 | N5: 774830 | R5: 65800 | W5: 49176.42 | AA5: 536130 | AT5: 7598.27 | BL5: 526 | BP5: 81741 | BT5: 97835 | BX5: 4317 | CB5: 250320 | CF5: 9535 | CI5: 19771 | CP5: 100020 | CV5: 465 | CZ5: 2547 | DD5: 1768697 | DH5: 4002500 | DL5: 3419475 | DP5: 2948741 | DT5: 3592467 | DX5: 720 | EF5: 71926 | EJ5: 33433 | EN5: 41654 | EO5: 42689 | EP5: 40428 | ES5: 7950
A6: 45778 | B6: 523691 | C6: =B6-B5 -> 731 | E6: 785 | F6: =EQ6 -> 670 | G6: =F6+ET6 -> 704 | H6: ='[1]Reading.4.24'!G6 -> 505 | J6: 225886 | K6: =(J6-J5)*4.668 -> 252.072 | L6: ='[1]Reading.4.24'!K6 -> 112.032 | N6: 774978 | O6: =(N6-N5)*4.61 -> 682.28 | P6: ='[1]Reading.4.24'!O6 -> 391.85 | R6: 65800 | T6: =(R5+S5)-R6 -> 0 | U6: ='[1]Reading.4.24'!T6 -> 0 | W6: 49185.81 | X6: =(W6-W5)*4000 -> 37560 | Y6: ='[1]Reading.4.24'!X6 -> 27720 | AA6: 536130 | AB6: =AA6-AA5 -> 0 | AC6: ='[1]Reading.4.24'!AB6 -> 0 | AE6: =+X6+AB6 -> 37560 | AF6: ='[1]Reading.4.24'!AE6 -> 27720 | AG6: =1198432/31 -> 38659.097 | AI6: 0.8631 | AJ6: ='[1]Reading.4.24'!AI6 -> 0.5209 | AK6: 0.545 | AM6: =AI6*526 -> 453.9906 | AN6: ='[1]Reading.4.24'!AM6 -> 274 | AO6: =8880/31 -> 286.45161 | AQ6: =514*4 -> 2056 | AR6: ='[1]Reading.4.24'!AQ6 -> 1460 | AT6: 7599.69 | AU6: =(AT6-AT5)*4000 -> 5680 | AV6: =+X6/SQRT(((POWER((X6),2)+(POWER((AU6),2))))) -> 0.988758 | AY6: ='[1]Reading.4.24'!X6 -> 27720 | AZ6: ='[1]Reading.4.24'!Y6 -> 25200 | BA6: =AY6+AZ6 -> 52920 | BC6: 27 | BD6: 38 | BE6: 50 | BF6: 25 | BG6: 80 | BH6: ='[1]Reading.4.24'!BD6 -> 16.1 | BI6: ='[1]Reading.4.24'!BE6 -> 12 | BJ6: ='[1]Reading.4.24'!BF6 -> 56 | BL6: 526 | BN6: ='Reading.5.24'!BN4 -> 0 | BP6: 81780 | BQ6: =BP6-BP5 -> 39 | BR6: ='[1]Reading.4.24'!BQ6 -> 30 | BT6: 97888 | BU6: =BT6-BT5 -> 53 | BV6: ='[1]Reading.4.24'!BU6 -> 30 | BX6: 4317 | BY6: =BX6-BX5 -> 0 | BZ6: ='[1]Reading.4.24'!BY6 -> 11 | CB6: 250360 | CC6: =CB6-CB5 -> 40 | CD6: ='[1]Reading.4.24'!CC6 -> 30 | CF6: 9545 | CG6: =CF6-CF5 -> 10 | CH6: ='[1]Reading.4.24'!CG6 -> 10 | CI6: 19771 | CJ6: =CI6-CI5 -> 0 | CK6: ='[1]Reading.4.24'!CJ6 -> -3 | CM6: =BQ6+BU6+BY6+CC6+CJ6 -> 132 | CN6: =BR6+BV6+BZ6+CD6+CK6 -> 98 | CP6: 100570 | CQ6: =CP6-CP5 -> 550 | CR6: =CQ6/G6 -> 0.78125 | CS6: ='[1]Reading.4.24'!CN6 -> 135 | CT6: ='[1]Reading.4.24'!CR6 -> 0.67920792 | CV6: 466 | CW6: =CV6-CV5 -> 1 | CX6: ='[1]Reading.4.24'!CW6 -> 2 | CZ6: 2550 | DA6: =CZ6-CZ5 -> 3 | DB6: ='[1]Reading.4.24'!DA6 -> 3 | DD6: 1769802 | DE6: =DD6-DD5 -> 1105 | DF6: ='[1]Reading.4.24'!DE6 -> 757 | DH6: 4004282 | DI6: =DH6-DH5 -> 1782 | DJ6: ='[1]Reading.4.24'!DI6 -> 1866 | DL6: 3421750 | DM6: =DL6-DL5 -> 2275 | DN6: ='[1]Reading.4.24'!DM6 -> 3208 | DP6: 2951324 | DQ6: =DP6-DP5 -> 2583 | DR6: ='[1]Reading.4.24'!DQ6 -> 31 | DT6: 3593676 | DU6: =DT6-DT5 -> 1209 | DV6: ='[1]Reading.4.24'!DU6 -> 31 | DX6: 720 | DZ6: =DM6+DQ6+DU6+DX6 -> 6787 | EA6: ='Reading.5.24'!DZ6 -> 4474 | EC6: =C6*5.2 -> 3801.2 | ED6: ='[1]Reading.4.24'!EC6 -> 2158 | EF6: 72006 | EG6: =EF6-EF5 -> 80 | EH6: ='[1]Reading.4.24'!EG6 -> 40 | EJ6: 33464 | EK6: =EJ6-EJ5 -> 31 | EL6: ='[1]Reading.4.24'!EK6 -> 33 | EN6: 41654 | EO6: 43359 | EP6: 40428 | EQ6: =(EN6-EN5)+(EO6-EO5)+(EP6-EP5) -> 670 | ES6: 7984 | ET6: =+ES6-ES5 -> 34
A7: 45779 | B7: 524424 | C7: =B7-B6 -> 733 | E7: 785 | F7: =EQ7 -> 677 | G7: =F7+ET7 -> 712 | H7: ='Reading.5.24'!G7 -> 552 | J7: 225977 | K7: =(J7-J6)*4.668 -> 424.788 | L7: ='Reading.5.24'!K7 -> 177.384 | N7: 775124 | O7: =(N7-N6)*4.61 -> 673.06 | P7: ='Reading.5.24'!O7 -> 461 | R7: 65800 | T7: =(R6+S6)-R7 -> 0 | U7: ='Reading.5.24'!T7 -> 0 | W7: 49195.24 | X7: =(W7-W6)*4000 -> 37720 | Y7: ='Reading.5.24'!X7 -> 37120 | AA7: 536130 | AB7: =AA7-AA6 -> 0 | AC7: ='Reading.5.24'!AB7 -> 0 | AE7: =+X7+AB7 -> 37720 | AF7: ='Reading.5.24'!AE7 -> 37120 | AG7: =1198432/31 -> 38659.097 | AI7: 0.8631 | AJ7: ='Reading.5.24'!AI7 -> 0.7351 | AK7: 0.545 | AM7: =AI7*526 -> 453.9906 | AN7: ='Reading.5.24'!AM7 -> 371 | AO7: =8880/31 -> 286.45161 | AQ7: =514*4 -> 2056 | AR7: ='Reading.5.24'!AQ7 -> 1804 | AT7: 7601 | AU7: =(AT7-AT6)*4000 -> 5240 | AV7: =+X7/SQRT(((POWER((X7),2)+(POWER((AU7),2))))) -> 0.9904883 | AY7: ='Reading.5.24'!X7 -> 37120 | AZ7: ='Reading.5.24'!Y7 -> 32920 | BA7: =AY7+AZ7 -> 70040 | BC7: 27 | BD7: 38 | BE7: 50 | BF7: 25 | BG7: 80 | BH7: ='Reading.5.24'!BD7 -> 16.1 | BI7: ='Reading.5.24'!BE7 -> 12 | BJ7: ='Reading.5.24'!BF7 -> 56 | BL7: 526 | BN7: ='Reading.5.24'!BN5 -> 0 | BP7: 81822 | BQ7: =BP7-BP6 -> 42 | BR7: ='Reading.5.24'!BQ7 -> 32 | BT7: 97947 | BU7: =BT7-BT6 -> 59 | BV7: ='Reading.5.24'!BU7 -> 38 | BX7: 4317 | BY7: =BX7-BX6 -> 0 | BZ7: ='Reading.5.24'!BY7 -> 0 | CB7: 250400 | CC7: =CB7-CB6 -> 40 | CD7: ='Reading.5.24'!CC7 -> 40 | CF7: 9560 | CG7: =CF7-CF6 -> 15 | CH7: ='Reading.5.24'!CG7 -> 10 | CI7: 19771 | CJ7: =CI7-CI6 -> 0 | CK7: ='Reading.5.24'!CJ7 -> 0 | CM7: =BQ7+BU7+BY7+CC7+CJ7 -> 141 | CN7: =BR7+BV7+BZ7+CD7+CK7 -> 110 | CP7: 101100 | CQ7: =CP7-CP6 -> 530 | CR7: =CQ7/G7 -> 0.74438202 | CS7: ='Reading.5.24'!CN7 -> 131 | CT7: ='Reading.5.24'!CO7 -> 0 | CV7: 468 | CW7: =CV7-CV6 -> 2 | CX7: ='Reading.5.24'!CW7 -> 1 | CZ7: 2555 | DA7: =CZ7-CZ6 -> 5 | DB7: ='Reading.5.24'!DA7 -> 3 | DD7: 1770749 | DE7: =DD7-DD6 -> 947 | DF7: ='Reading.5.24'!DE7 -> 744 | DH7: 4006293 | DI7: =DH7-DH6 -> 2011 | DJ7: ='Reading.5.24'!DI7 -> 1936 | DL7: 3423324 | DM7: =DL7-DL6 -> 1574 | DN7: ='Reading.5.24'!DM7 -> 34 | DP7: 2952552 | DQ7: =DP7-DP6 -> 1228 | DR7: ='Reading.5.24'!DQ7 -> 1988 | DT7: 3594869 | DU7: =DT7-DT6 -> 1193 | DV7: ='Reading.5.24'!DU7 -> 2463 | DX7: 720 | DZ7: =DM7+DQ7+DU7+DX7 -> 4715 | EA7: ='Reading.5.24'!DZ7 -> 5205 | EC7: =C7*5.2 -> 3811.6 | ED7: ='Reading.5.24'!EC7 -> 2584.4 | EF7: 72084 | EG7: =EF7-EF6 -> 78 | EH7: ='Reading.5.24'!EG7 -> 54 | EJ7: 33492 | EK7: =EJ7-EJ6 -> 28 | EL7: ='Reading.5.24'!EK7 -> 22 | EN7: 41886 | EO7: 43394 | EP7: 40838 | EQ7: =(EN7-EN6)+(EO7-EO6)+(EP7-EP6) -> 677 | ES7: 8019 | ET7: =+ES7-ES6 -> 35
A8: 45780 | B8: 525157 | C8: =B8-B7 -> 733 | E8: 785 | F8: =EQ8 -> 544 | G8: =F8+ET8 -> 576 | H8: ='Reading.5.24'!G8 -> 591 | J8: 226004 | K8: =(J8-J7)*4.668 -> 126.036 | L8: ='Reading.5.24'!K8 -> 214.728 | N8: 775272 | O8: =(N8-N7)*4.61 -> 682.28 | P8: ='Reading.5.24'!O8 -> 451.78 | R8: 65800 | T8: =(R7+S7)-R8 -> 0 | U8: ='Reading.5.24'!T8 -> 0 | W8: 49204.55 | X8: =(W8-W7)*4000 -> 37240 | Y8: ='Reading.5.24'!X8 -> 36800 | AA8: 536130 | AB8: =AA8-AA7 -> 0 | AC8: ='Reading.5.24'!AB8 -> 0 | AE8: =+X8+AB8 -> 37240 | AF8: ='Reading.5.24'!AE8 -> 36800 | AG8: =1198432/31 -> 38659.097 | AI8: 0.8631 | AJ8: ='Reading.5.24'!AI8 -> 0.7529 | AK8: 0.545 | AM8: =AI8*526 -> 453.9906 | AN8: ='Reading.5.24'!AM8 -> 396 | AO8: =8880/31 -> 286.45161 | AQ8: =514*4 -> 2056 | AR8: ='Reading.5.24'!AQ8 -> 1900 | AT8: 7602.51 | AU8: =(AT8-AT7)*4000 -> 6040 | AV8: =+X8/SQRT(((POWER((X8),2)+(POWER((AU8),2))))) -> 0.98710095 | AY8: ='Reading.5.24'!X8 -> 36800 | AZ8: ='Reading.5.24'!Y8 -> 37280 | BA8: =AY8+AZ8 -> 74080 | BC8: 27 | BD8: 38 | BE8: 50 | BF8: 25 | BG8: 80 | BH8: ='Reading.5.24'!BD8 -> 17 | BI8: ='Reading.5.24'!BE8 -> 14 | BJ8: ='Reading.5.24'!BF8 -> 48 | BL8: 526 | BN8: ='Reading.5.24'!BN6 -> Sold | BP8: 81863 | BQ8: =BP8-BP7 -> 41 | BR8: ='Reading.5.24'!BQ8 -> 35 | BT8: 98000 | BU8: =BT8-BT7 -> 53 | BV8: ='Reading.5.24'!BU8 -> 40 | BX8: 4317 | BY8: =BX8-BX7 -> 0 | BZ8: ='Reading.5.24'!BY8 -> 0 | CB8: 250440 | CC8: =CB8-CB7 -> 40 | CD8: ='Reading.5.24'!CC8 -> 30 | CF8: 9575 | CG8: =CF8-CF7 -> 15 | CH8: ='Reading.5.24'!CG8 -> 5 | CI8: 19771 | CJ8: =CI8-CI7 -> 0 | CK8: ='Reading.5.24'!CJ8 -> 0 | CM8: =BQ8+BU8+BY8+CC8+CJ8 -> 134 | CN8: =BR8+BV8+BZ8+CD8+CK8 -> 105 | CP8: 101690 | CQ8: =CP8-CP7 -> 590 | CR8: =CQ8/G8 -> 1.0243056 | CS8: ='Reading.5.24'!CN8 -> 157 | CT8: ='Reading.5.24'!CO8 -> 0 | CV8: 470 | CW8: =CV8-CV7 -> 2 | CX8: ='Reading.5.24'!CW8 -> 2 | CZ8: 2559 | DA8: =CZ8-CZ7 -> 4 | DB8: ='Reading.5.24'!DA8 -> 5 | DD8: 1771665 | DE8: =DD8-DD7 -> 916 | DF8: ='Reading.5.24'!DE8 -> 810 | DH8: 4008224 | DI8: =DH8-DH7 -> 1931 | DJ8: ='Reading.5.24'!DI8 -> 1903 | DL8: 3424919 | DM8: =DL8-DL7 -> 1595 | DN8: ='Reading.5.24'!DM8 -> 33 | DP8: 2954025 | DQ8: =DP8-DP7 -> 1473 | DR8: ='Reading.5.24'!DQ8 -> 1973 | DT8: 3596112 | DU8: =DT8-DT7 -> 1243 | DV8: ='Reading.5.24'!DU8 -> 2614 | DX8: 720 | DZ8: =DM8+DQ8+DU8+DX8 -> 5031 | EA8: ='Reading.5.24'!DZ8 -> 5340 | EC8: =C8*5.2 -> 3811.6 | ED8: ='Reading.5.24'!EC8 -> 3073.2 | EF8: 72174 | EG8: =EF8-EF7 -> 90 | EH8: ='Reading.5.24'!EG8 -> 61 | EJ8: 33518 | EK8: =EJ8-EJ7 -> 26 | EL8: ='Reading.5.24'!EK8 -> 24 | EN8: 42123 | EO8: 43395 | EP8: 41144 | EQ8: =(EN8-EN7)+(EO8-EO7)+(EP8-EP7) -> 544 | ES8: 8051 | ET8: =+ES8-ES7 -> 32
A9: 45781 | B9: 525696 | C9: =B9-B8 -> 539 | E9: 825 | F9: =EQ9 -> 685 | G9: =F9+ET9 -> 719 | H9: ='Reading.5.24'!G9 -> 617 | J9: 226052 | K9: =(J9-J8)*4.668 -> 224.064 | L9: ='Reading.5.24'!K9 -> 186.72 | N9: 775417 | O9: =(N9-N8)*4.61 -> 668.45 | P9: ='Reading.5.24'!O9 -> 553.2 | R9: 65800 | T9: =(R8+S8)-R9 -> 0 | U9: ='Reading.5.24'!T9 -> 0 | W9: 49213.86 | X9: =(W9-W8)*4000 -> 37240 | Y9: ='Reading.5.24'!X9 -> 34880 | AA9: 536130 | AB9: =AA9-AA8 -> 0 | AC9: ='Reading.5.24'!AB9 -> 0 | AE9: =+X9+AB9 -> 37240 | AF9: ='Reading.5.24'!AE9 -> 34880 | AG9: =1198432/31 -> 38659.097 | AI9: 0.7433 | AJ9: ='Reading.5.24'!AI9 -> 0.6179 | AK9: 0.545 | AM9: =AI9*526 -> 390.9758 | AN9: ='Reading.5.24'!AM9 -> 325 | AO9: =8880/31 -> 286.45161 | AQ9: =514*4 -> 2056 | AR9: ='Reading.5.24'!AQ9 -> 1900 | AT9: 7603.86 | AU9: =(AT9-AT8)*4000 -> 5400 | AV9: =+X9/SQRT(((POWER((X9),2)+(POWER((AU9),2))))) -> 0.98964966 | AY9: ='Reading.5.24'!X9 -> 34880 | AZ9: ='Reading.5.24'!Y9 -> 34080 | BA9: =AY9+AZ9 -> 68960 | BC9: 27 | BD9: 38 | BE9: 50 | BF9: 25 | BG9: 80 | BH9: ='Reading.5.24'!BD9 -> 18 | BI9: ='Reading.5.24'!BE9 -> 14 | BJ9: ='Reading.5.24'!BF9 -> 52 | BL9: 526 | BN9: ='Reading.5.24'!BN7 -> 0 | BP9: 81899 | BQ9: =BP9-BP8 -> 36 | BR9: ='Reading.5.24'!BQ9 -> 31 | BT9: 98066 | BU9: =BT9-BT8 -> 66 | BV9: ='Reading.5.24'!BU9 -> 33 | BX9: 4317 | BY9: =BX9-BX8 -> 0 | BZ9: ='Reading.5.24'!BY9 -> 0 | CB9: 250480 | CC9: =CB9-CB8 -> 40 | CD9: ='Reading.5.24'!CC9 -> 40 | CF9: 9585 | CG9: =CF9-CF8 -> 10 | CH9: ='Reading.5.24'!CG9 -> 5 | CI9: 19771 | CJ9: =CI9-CI8 -> 0 | CK9: ='Reading.5.24'!CJ9 -> 0 | CM9: =BQ9+BU9+BY9+CC9+CJ9 -> 142 | CN9: =BR9+BV9+BZ9+CD9+CK9 -> 104 | CP9: 102230 | CQ9: =CP9-CP8 -> 540 | CR9: =CQ9/G9 -> 0.75104312 | CS9: ='Reading.5.24'!CN9 -> 312 | CT9: ='Reading.5.24'!CO9 -> 0 | CV9: 471 | CW9: =CV9-CV8 -> 1 | CX9: ='Reading.5.24'!CW9 -> 2 | CZ9: 2563 | DA9: =CZ9-CZ8 -> 4 | DB9: ='Reading.5.24'!DA9 -> 5 | DD9: 1772567 | DE9: =DD9-DD8 -> 902 | DF9: ='Reading.5.24'!DE9 -> 1116 | DH9: 4010194 | DI9: =DH9-DH8 -> 1970 | DJ9: ='Reading.5.24'!DI9 -> 1821 | DL9: 3426463 | DM9: =DL9-DL8 -> 1544 | DN9: ='Reading.5.24'!DM9 -> 15 | DP9: 2955419 | DQ9: =DP9-DP8 -> 1394 | DR9: ='Reading.5.24'!DQ9 -> 1907 | DT9: 3597401 | DU9: =DT9-DT8 -> 1289 | DV9: ='Reading.5.24'!DU9 -> 2409 | DX9: 720 | DZ9: =DM9+DQ9+DU9+DX9 -> 4947 | EA9: ='Reading.5.24'!DZ9 -> 5051 | EC9: =C9*5.2 -> 2802.8 | ED9: ='Reading.5.24'!EC9 -> 3208.4 | EF9: 72248 | EG9: =EF9-EF8 -> 74 | EH9: ='Reading.5.24'!EG9 -> 60 | EJ9: 33543 | EK9: =EJ9-EJ8 -> 25 | EL9: ='Reading.5.24'!EK9 -> 23 | EN9: 42595 | EO9: 43400 | EP9: 41352 | EQ9: =(EN9-EN8)+(EO9-EO8)+(EP9-EP8) -> 685 | ES9: 8085 | ET9: =+ES9-ES8 -> 34
A10: 45782 | B10: 526432 | C10: =B10-B9 -> 736 | E10: 880 | F10: =EQ10 -> 655 | G10: =F10+ET10 -> 688 | H10: ='Reading.5.24'!G10 -> 506 | J10: 226107 | K10: =(J10-J9)*4.668 -> 256.74 | L10: ='Reading.5.24'!K10 -> 196.056 | N10: 775560 | O10: =(N10-N9)*4.61 -> 659.23 | P10: ='Reading.5.24'!O10 -> 534.76 | R10: 65800 | T10: =(R9+S9)-R10 -> 0 | U10: ='Reading.5.24'!T10 -> 0 | W10: 49221.94 | X10: =(W10-W9)*4000 -> 32320 | Y10: ='Reading.5.24'!X10 -> 36240 | AA10: 536130 | AB10: =AA10-AA9 -> 0 | AC10: ='Reading.5.24'!AB10 -> 0 | AE10: =+X10+AB10 -> 32320 | AF10: ='Reading.5.24'!AE10 -> 36240 | AG10: =1198432/31 -> 38659.097 | AI10: 0.7186 | AJ10: ='Reading.5.24'!AI10 -> 0.557 | AK10: 0.545 | AM10: =AI10*526 -> 377.9836 | AN10: ='Reading.5.24'!AM10 -> 293 | AO10: =8880/31 -> 286.45161 | AQ10: =514*4 -> 2056 | AR10: ='Reading.5.24'!AQ10 -> 1900 | AT10: 7605.27 | AU10: =(AT10-AT9)*4000 -> 5640 | AV10: =+X10/SQRT(((POWER((X10),2)+(POWER((AU10),2))))) -> 0.98511316 | AY10: ='Reading.5.24'!X10 -> 36240 | AZ10: ='Reading.5.24'!Y10 -> 37760 | BA10: =AY10+AZ10 -> 74000 | BC10: 27 | BD10: 38 | BE10: 50 | BF10: 25 | BG10: 80 | BH10: ='Reading.5.24'!BD10 -> 17 | BI10: ='Reading.5.24'!BE10 -> 14 | BJ10: ='Reading.5.24'!BF10 -> 50 | BL10: 526 | BN10: ='Reading.5.24'!BN8 -> 0 | BP10: 81944 | BQ10: =BP10-BP9 -> 45 | BR10: ='Reading.5.24'!BQ10 -> 33 | BT10: 98125 | BU10: =BT10-BT9 -> 59 | BV10: ='Reading.5.24'!BU10 -> 43 | BX10: 4317 | BY10: =BX10-BX9 -> 0 | BZ10: ='Reading.5.24'!BY10 -> 0 | CB10: 250580 | CC10: =CB10-CB9 -> 100 | CD10: ='Reading.5.24'!CC10 -> 40 | CF10: 9595 | CG10: =CF10-CF9 -> 10 | CH10: ='Reading.5.24'!CG10 -> 5 | CI10: 19771 | CJ10: =CI10-CI9 -> 0 | CK10: ='Reading.5.24'!CJ10 -> 0 | CM10: =BQ10+BU10+BY10+CC10+CJ10 -> 204 | CN10: =BR10+BV10+BZ10+CD10+CK10 -> 116 | CP10: 102770 | CQ10: =CP10-CP9 -> 540 | CR10: =CQ10/G10 -> 0.78488372 | CS10: ='Reading.5.24'!CN10 -> 184 | CT10: ='Reading.5.24'!CO10 -> 0 | CV10: 473 | CW10: =CV10-CV9 -> 2 | CX10: ='Reading.5.24'!CW10 -> 1 | CZ10: 2568 | DA10: =CZ10-CZ9 -> 5 | DB10: ='Reading.5.24'!DA10 -> 4 | DD10: 1773398 | DE10: =DD10-DD9 -> 831 | DF10: ='Reading.5.24'!DE10 -> 1106 | DH10: 4012159 | DI10: =DH10-DH9 -> 1965 | DJ10: ='Reading.5.24'!DI10 -> 1915 | DL10: 3428012 | DM10: =DL10-DL9 -> 1549 | DN10: ='Reading.5.24'!DM10 -> 29 | DP10: 2956718 | DQ10: =DP10-DP9 -> 1299 | DR10: ='Reading.5.24'!DQ10 -> 709 | DT10: 3598590 | DU10: =DT10-DT9 -> 1189 | DV10: ='Reading.5.24'!DU10 -> 3500 | DX10: 720 | DZ10: =DM10+DQ10+DU10+DX10 -> 4757 | EA10: ='Reading.5.24'!DZ10 -> 4958 | EC10: =C10*5.2 -> 3827.2 | ED10: ='Reading.5.24'!EC10 -> 2631.2 | EF10: 72324 | EG10: =EF10-EF9 -> 76 | EH10: ='Reading.5.24'!EG10 -> 46 | EJ10: 33570 | EK10: =EJ10-EJ9 -> 27 | EL10: ='Reading.5.24'!EK10 -> 26 | EN10: 42918 | EO10: 43401 | EP10: 41683 | EQ10: =(EN10-EN9)+(EO10-EO9)+(EP10-EP9) -> 655 | ES10: 8118 | ET10: =+ES10-ES9 -> 33
A11: 45783 | B11: 527024 | C11: =B11-B10 -> 592 | E11: 860 | F11: =EQ11 -> 610 | G11: =F11+ET11 -> 644 | H11: ='Reading.5.24'!G11 -> 570 | J11: 226159 | K11: =(J11-J10)*4.668 -> 242.736 | L11: ='Reading.5.24'!K11 -> 154.044 | N11: 775692 | O11: =(N11-N10)*4.61 -> 608.52 | P11: ='Reading.5.24'!O11 -> 507.1 | R11: 65800 | T11: =(R10+S10)-R11 -> 0 | U11: ='Reading.5.24'!T11 -> 0 | W11: 49230.87 | X11: =(W11-W10)*4000 -> 35720 | Y11: ='Reading.5.24'!X11 -> 32200 | AA11: 536130 | AB11: =AA11-AA10 -> 0 | AC11: ='Reading.5.24'!AB11 -> 0 | AE11: =+X11+AB11 -> 35720 | AF11: ='Reading.5.24'!AE11 -> 32200 | AG11: =1198432/31 -> 38659.097 | AI11: 0.6597 | AJ11: ='Reading.5.24'!AI11 -> 0.4468 | AK11: 0.545 | AM11: =AI11*526 -> 347.0022 | AN11: ='Reading.5.24'!AM11 -> 235 | AO11: =8880/31 -> 286.45161 | AQ11: =514*4 -> 2056 | AR11: ='Reading.5.24'!AQ11 -> 1900 | AT11: 7606.71 | AU11: =(AT11-AT10)*4000 -> 5760 | AV11: =+X11/SQRT(((POWER((X11),2)+(POWER((AU11),2))))) -> 0.98724673 | AY11: ='Reading.5.24'!X11 -> 32200 | AZ11: ='Reading.5.24'!Y11 -> 37840 | BA11: =AY11+AZ11 -> 70040 | BC11: 27 | BD11: 38 | BE11: 50 | BF11: 25 | BG11: 80 | BH11: ='Reading.5.24'!BD11 -> 17 | BI11: ='Reading.5.24'!BE11 -> 14 | BJ11: ='Reading.5.24'!BF11 -> 50 | BL11: 526 | BN11: ='Reading.5.24'!BN9 -> 0 | BP11: 81989 | BQ11: =BP11-BP10 -> 45 | BR11: ='Reading.5.24'!BQ11 -> 33 | BT11: 98177 | BU11: =BT11-BT10 -> 52 | BV11: ='Reading.5.24'!BU11 -> 42 | BX11: 4317 | BY11: =BX11-BX10 -> 0 | BZ11: ='Reading.5.24'!BY11 -> 8 | CB11: 250620 | CC11: =CB11-CB10 -> 40 | CD11: ='Reading.5.24'!CC11 -> 30 | CF11: 9605 | CG11: =CF11-CF10 -> 10 | CH11: ='Reading.5.24'!CG11 -> 10 | CI11: 19771 | CJ11: =CI11-CI10 -> 0 | CK11: ='Reading.5.24'!CJ11 -> 0 | CM11: =BQ11+BU11+BY11+CC11+CJ11 -> 137 | CN11: =BR11+BV11+BZ11+CD11+CK11 -> 113 | CP11: 103330 | CQ11: =CP11-CP10 -> 560 | CR11: =CQ11/G11 -> 0.86956522 | CS11: ='Reading.5.24'!CN11 -> 121 | CT11: ='Reading.5.24'!CO11 -> 0 | CV11: 475 | CW11: =CV11-CV10 -> 2 | CX11: ='Reading.5.24'!CW11 -> 0 | CZ11: 2573 | DA11: =CZ11-CZ10 -> 5 | DB11: ='Reading.5.24'!DA11 -> 5 | DD11: 1774287 | DE11: =DD11-DD10 -> 889 | DF11: ='Reading.5.24'!DE11 -> 848 | DH11: 4014124 | DI11: =DH11-DH10 -> 1965 | DJ11: ='Reading.5.24'!DI11 -> 1724 | DL11: 3429523 | DM11: =DL11-DL10 -> 1511 | DN11: ='Reading.5.24'!DM11 -> 2756 | DP11: 2958102 | DQ11: =DP11-DP10 -> 1384 | DR11: ='Reading.5.24'!DQ11 -> -34 | DT11: 3599710 | DU11: =DT11-DT10 -> 1120 | DV11: ='Reading.5.24'!DU11 -> 1064 | DX11: 720 | DZ11: =DM11+DQ11+DU11+DX11 -> 4735 | EA11: ='Reading.5.24'!DZ11 -> 4506 | EC11: =C11*5.2 -> 3078.4 | ED11: ='Reading.5.24'!EC11 -> 3094 | EF11: 72400 | EG11: =EF11-EF10 -> 76 | EH11: ='Reading.5.24'!EG11 -> 24 | EJ11: 33597 | EK11: =EJ11-EJ10 -> 27 | EL11: ='Reading.5.24'!EK11 -> 22 | EN11: 43209 | EO11: 43401 | EP11: 42002 | EQ11: =(EN11-EN10)+(EO11-EO10)+(EP11-EP10) -> 610 | ES11: 8152 | ET11: =+ES11-ES10 -> 34
A12: 45784 | B12: 527698 | C12: =B12-B11 -> 674 | E12: 860 | F12: =EQ12 -> 674 | G12: =F12+ET12 -> 707 | H12: ='Reading.5.24'!G12 -> 620 | J12: 226217 | K12: =(J12-J11)*4.668 -> 270.744 | L12: ='Reading.5.24'!K12 -> 177.384 | N12: 775827 | O12: =(N12-N11)*4.61 -> 622.35 | P12: ='Reading.5.24'!O12 -> 525.54 | R12: 65800 | T12: =(R11+S11)-R12 -> 0 | U12: ='Reading.5.24'!T12 -> 0 | W12: 49240.65 | X12: =(W12-W11)*4000 -> 39120 | Y12: ='Reading.5.24'!X12 -> 30880 | AA12: 536130 | AB12: =AA12-AA11 -> 0 | AC12: ='Reading.5.24'!AB12 -> 0 | AE12: =+X12+AB12 -> 39120 | AF12: ='Reading.5.24'!AE12 -> 30880 | AG12: =1198432/31 -> 38659.097 | AI12: 0.8405 | AJ12: ='Reading.5.24'!AI12 -> 0.4373 | AK12: 0.545 | AM12: =AI12*526 -> 442.103 | AN12: ='Reading.5.24'!AM12 -> 230 | AO12: =8880/31 -> 286.45161 | AQ12: =514*4 -> 2056 | AR12: ='Reading.5.24'!AQ12 -> 1900 | AT12: 7608.1 | AU12: =(AT12-AT11)*4000 -> 5560 | AV12: =+X12/SQRT(((POWER((X12),2)+(POWER((AU12),2))))) -> 0.99005047 | AY12: ='Reading.5.24'!X12 -> 30880 | AZ12: ='Reading.5.24'!Y12 -> 35840 | BA12: =AY12+AZ12 -> 66720 | BC12: 32 | BD12: 22 | BE12: 50 | BF12: 20 | BG12: 80 | BH12: ='Reading.5.24'!BD12 -> 21 | BI12: ='Reading.5.24'!BE12 -> 17 | BJ12: ='Reading.5.24'!BF12 -> 50 | BL12: 526 | BN12: ='Reading.5.24'!BN10 -> 0 | BP12: 82026 | BQ12: =BP12-BP11 -> 37 | BR12: ='Reading.5.24'!BQ12 -> 32 | BT12: 98233 | BU12: =BT12-BT11 -> 56 | BV12: ='Reading.5.24'!BU12 -> 43 | BX12: 4317 | BY12: =BX12-BX11 -> 0 | BZ12: ='Reading.5.24'!BY12 -> 0 | CB12: 250660 | CC12: =CB12-CB11 -> 40 | CD12: ='Reading.5.24'!CC12 -> 100 | CF12: 9620 | CG12: =CF12-CF11 -> 15 | CH12: ='Reading.5.24'!CG12 -> 5 | CI12: 19771 | CJ12: =CI12-CI11 -> 0 | CK12: ='Reading.5.24'!CJ12 -> 0 | CM12: =BQ12+BU12+BY12+CC12+CJ12 -> 133 | CN12: =BR12+BV12+BZ12+CD12+CK12 -> 175 | CP12: 103850 | CQ12: =CP12-CP11 -> 520 | CR12: =CQ12/G12 -> 0.73550212 | CS12: ='Reading.5.24'!CN12 -> 138 | CT12: ='Reading.5.24'!CO12 -> 0 | CV12: 477 | CW12: =CV12-CV11 -> 2 | CX12: ='Reading.5.24'!CW12 -> 1 | CZ12: 2576 | DA12: =CZ12-CZ11 -> 3 | DB12: ='Reading.5.24'!DA12 -> 6 | DD12: 1775170 | DE12: =DD12-DD11 -> 883 | DF12: ='Reading.5.24'!DE12 -> 890 | DH12: 4015584 | DI12: =DH12-DH11 -> 1460 | DJ12: ='Reading.5.24'!DI12 -> 1910 | DL12: 3431546 | DM12: =DL12-DL11 -> 2023 | DN12: ='Reading.5.24'!DM12 -> 3592 | DP12: 2959770 | DQ12: =DP12-DP11 -> 1668 | DR12: ='Reading.5.24'!DQ12 -> 33 | DT12: 3600982 | DU12: =DT12-DT11 -> 1272 | DV12: ='Reading.5.24'!DU12 -> 32 | DX12: 720 | DZ12: =DM12+DQ12+DU12+DX12 -> 5683 | EA12: ='Reading.5.24'!DZ12 -> 4377 | EC12: =C12*5.2 -> 3504.8 | ED12: ='Reading.5.24'!EC12 -> 3224 | EF12: 72483 | EG12: =EF12-EF11 -> 83 | EH12: ='Reading.5.24'!EG12 -> 49 | EJ12: 33622 | EK12: =EJ12-EJ11 -> 25 | EL12: ='Reading.5.24'!EK12 -> 24 | EN12: 43209 | EO12: 43732 | EP12: 42345 | EQ12: =(EN12-EN11)+(EO12-EO11)+(EP12-EP11) -> 674 | ES12: 8185 | ET12: =+ES12-ES11 -> 33
A13: 45785 | B13: 528333 | C13: =B13-B12 -> 635 | E13: 860 | F13: =EQ13 -> 659 | G13: =F13+ET13 -> 692 | H13: ='Reading.5.24'!G13 -> 489 | J13: 226275 | K13: =(J13-J12)*4.668 -> 270.744 | L13: ='Reading.5.24'!K13 -> 205.392 | N13: 775981 | O13: =(N13-N12)*4.61 -> 709.94 | P13: ='Reading.5.24'!O13 -> 456.39 | R13: 65800 | T13: =(R12+S12)-R13 -> 0 | U13: ='Reading.5.24'!T13 -> 0 | W13: 49250.39 | X13: =(W13-W12)*4000 -> 38960 | Y13: ='Reading.5.24'!X13 -> 31680 | AA13: 536130 | AB13: =AA13-AA12 -> 0 | AC13: ='Reading.5.24'!AB13 -> 0 | AE13: =+X13+AB13 -> 38960 | AF13: ='Reading.5.24'!AE13 -> 31680 | AG13: =1198432/31 -> 38659.097 | AI13: 0.7928 | AJ13: ='Reading.5.24'!AI13 -> 0.4696 | AK13: 0.545 | AM13: =AI13*526 -> 417.0128 | AN13: ='Reading.5.24'!AM13 -> 247 | AO13: =8880/31 -> 286.45161 | AQ13: =514*4 -> 2056 | AR13: ='Reading.5.24'!AQ13 -> 1900 | AT13: 7609.44 | AU13: =(AT13-AT12)*4000 -> 5360 | AV13: =+X13/SQRT(((POWER((X13),2)+(POWER((AU13),2))))) -> 0.99066854 | AY13: ='Reading.5.24'!X13 -> 31680 | AZ13: ='Reading.5.24'!Y13 -> 34360 | BA13: =AY13+AZ13 -> 66040 | BC13: 33 | BD13: 23 | BE13: 50 | BF13: 20 | BG13: 80 | BH13: ='Reading.5.24'!BD13 -> 21 | BI13: ='Reading.5.24'!BE13 -> 17 | BJ13: ='Reading.5.24'!BF13 -> 49 | BL13: 526 | BN13: ='Reading.5.24'!BN11 -> 0 | BP13: 82069 | BQ13: =BP13-BP12 -> 43 | BR13: ='Reading.5.24'!BQ13 -> 30 | BT13: 98288 | BU13: =BT13-BT12 -> 55 | BV13: ='Reading.5.24'!BU13 -> 35 | BX13: 4317 | BY13: =BX13-BX12 -> 0 | BZ13: ='Reading.5.24'!BY13 -> 0 | CB13: 250710 | CC13: =CB13-CB12 -> 50 | CD13: ='Reading.5.24'!CC13 -> 40 | CF13: 9635 | CG13: =CF13-CF12 -> 15 | CH13: ='Reading.5.24'!CG13 -> 5 | CI13: 19771 | CJ13: =CI13-CI12 -> 0 | CK13: ='Reading.5.24'!CJ13 -> 0 | CM13: =BQ13+BU13+BY13+CC13+CJ13 -> 148 | CN13: =BR13+BV13+BZ13+CD13+CK13 -> 105 | CP13: 104440 | CQ13: =CP13-CP12 -> 590 | CR13: =CQ13/G13 -> 0.85260116 | CS13: ='Reading.5.24'!CN13 -> 118 | CT13: ='Reading.5.24'!CO13 -> 0 | CV13: 478 | CW13: =CV13-CV12 -> 1 | CX13: ='Reading.5.24'!CW13 -> 0 | CZ13: 2581 | DA13: =CZ13-CZ12 -> 5 | DB13: ='Reading.5.24'!DA13 -> 4 | DD13: 1776274 | DE13: =DD13-DD12 -> 1104 | DF13: ='Reading.5.24'!DE13 -> 702 | DH13: 4017364 | DI13: =DH13-DH12 -> 1780 | DJ13: ='Reading.5.24'!DI13 -> 1710 | DL13: 3433112 | DM13: =DL13-DL12 -> 1566 | DN13: ='Reading.5.24'!DM13 -> 3912 | DP13: 2961865 | DQ13: =DP13-DP12 -> 2095 | DR13: ='Reading.5.24'!DQ13 -> 34 | DT13: 3602097 | DU13: =DT13-DT12 -> 1115 | DV13: ='Reading.5.24'!DU13 -> 33 | DX13: 720 | DZ13: =DM13+DQ13+DU13+DX13 -> 5496 | EA13: ='Reading.5.24'!DZ13 -> 4699 | EC13: =C13*5.2 -> 3302 | ED13: ='Reading.5.24'!EC13 -> 2542.8 | EF13: 72557 | EG13: =EF13-EF12 -> 74 | EH13: ='Reading.5.24'!EG13 -> 51 | EJ13: 33648 | EK13: =EJ13-EJ12 -> 26 | EL13: ='Reading.5.24'!EK13 -> 21 | EN13: 43209 | EO13: 44391 | EP13: 42345 | EQ13: =(EN13-EN12)+(EO13-EO12)+(EP13-EP12) -> 659 | ES13: 8218 | ET13: =+ES13-ES12 -> 33
A14: 45786
A15: 45787
A16: 45788
A17: 45789
A18: 45790
A19: 45791
A20: 45792
A21: 45793
A22: 45794
A23: 45795
A24: 45796
A25: 45797
... A36: 45808
C37: =AVERAGE(C6:C36) -> 671.625 | G37: =SUM(G6:G36) -> 5442 | H37: =SUM(H6:H36) -> 4450 | K37: =SUM(K6:K36) -> 2067.924 | L37: =SUM(L6:L36) -> 1423.74 | O37: =SUM(O6:O36) -> 5306.11 | P37: =SUM(P6:P36) -> 3881.62 | S37: =SUM(S6:S36) -> 0 | T37: =SUM(T6:T36) -> 0 | U37: =SUM(U6:U36) -> 0 | X37: =SUM(X6:X36) -> 295880 | Y37: =SUM(Y6:Y36) -> 267520 | AB37: =SUM(AB6:AB36) -> 0 | AC37: =SUM(AC6:AC36) -> 0 | AE37: =SUM(AE6:AE36) -> 295880 | AF37: =SUM(AF6:AF36) -> 267520 | AG37: =SUM(AG6:AG36) -> 309272.77 | AI37: =AVERAGE(AI6:AI36) -> 0.793025 | AJ37: =AVERAGE(AJ6:AJ36) -> 0.5671875 | AK37: =AVERAGE(AK6:AK36) -> 0.545 | AM37: =SUM(AM6:AM36) -> 3337.0492 | AN37: =SUM(AN6:AN36) -> 2371 | AO37: =SUM(AO6:AO36) -> 2291.6129 | AQ37: =MAX(AQ6:AQ36) -> 2056 | AR37: =MAX(AR6:AR36) -> 1900 | AV37: =AVERAGE(AV6:AV36) -> 0.98863448 | AY37: =SUM(AY6:AY36) -> 267520 | AZ37: =SUM(AZ6:AZ36) -> 275280 | BA37: =SUM(BA6:BA36) -> 542800 | BC37: =AVERAGE(BC6:BC36) -> 28.375 | BD37: =AVERAGE(BD6:BD36) -> 34.125 | BE37: =AVERAGE(BE6:BE36) -> 50 | BF37: =AVERAGE(BF6:BF36) -> 23.75 | BG37: =AVERAGE(BG6:BG36) -> 80 | BH37: =AVERAGE(BH6:BH36) -> 17.9 | BI37: =AVERAGE(BI6:BI36) -> 14.25 | BJ37: =AVERAGE(BJ6:BJ36) -> 51.375 | BL37: =SUM(BL6:BL36) -> 4208 | BN37: =SUM(BN6:BN36) -> 0 | BQ37: =SUM(BQ6:BQ36) -> 328 | BR37: =SUM(BR6:BR36) -> 256 | BU37: =SUM(BU6:BU36) -> 453 | BV37: =SUM(BV6:BV36) -> 304 | BY37: =SUM(BY6:BY36) -> 0 | BZ37: =SUM(BZ6:BZ36) -> 19 | CC37: =SUM(CC6:CC36) -> 390 | CD37: =SUM(CD6:CD36) -> 350 | CG37: =SUM(CG6:CG36) -> 100 | CH37: =SUM(CH6:CH36) -> 55 | CJ37: =SUM(CJ6:CJ36) -> 0 | CK37: =SUM(CK6:CK36) -> -3 | CM37: =SUM(CM6:CM36) -> 1171 | CN37: =SUM(CN6:CN36) -> 926 | CQ37: =SUM(CQ6:CQ36) -> 4420 | CR37: =AVERAGE(CR13:CR36) -> 0.85260116 | CS37: ='[1]Reading.4.24'!CN35 -> 123 | CT37: ='[1]Reading.4.24'!CO35 -> #REF! | CW37: =SUM(CW6:CW36) -> 13 | CX37: ='[1]Reading.4.24'!CT37 -> 0.52997602 | DA37: =SUM(DA6:DA36) -> 34 | DB37: =SUM(DB6:DB36) -> 35 | DE37: =SUM(DE6:DE36) -> 7577 | DF37: =SUM(DF6:DF36) -> 6973 | DI37: =SUM(DI6:DI36) -> 14864 | DJ37: =SUM(DJ6:DJ36) -> 14785 | DM37: =SUM(DM6:DM36) -> 13637 | DN37: =SUM(DN6:DN36) -> 13579 | DQ37: =SUM(DQ6:DQ36) -> 13124 | DR37: =SUM(DR6:DR36) -> 6641 | DU37: =SUM(DU6:DU36) -> 9630 | DV37: =SUM(DV6:DV36) -> 12146 | DZ37: =SUM(DZ6:DZ36) -> 42151 | EA37: =SUM(EA6:EA36) -> 38610 | EC37: =SUM(EC6:EC36) -> 27939.6 | ED37: =SUM(ED6:ED36) -> 22516 | EG37: =SUM(EG6:EG36) -> 631 | EH37: =SUM(EH6:EH36) -> 385 | EK37: =SUM(EK6:EK36) -> 215 | EL37: =SUM(EL6:EL36) -> 195
C38: Average/Day | AP38: Last Period Max. Demand: | AQ38: 2216 | CQ38: 0
C39: =SUM(C6:C36) -> 5373 | AP39: This Period Max. Demand: | AQ39: 2160
B40: =+B31-B30 -> 0 | U40: ENERGY COST / OCCUPIED ROOM - LAST YEAR = | AB40: ='[1]cost.4.25'!BG38 -> 131.93838 | AC40: L.E. | AF40: OCCUPANCY - LAST YEAR = | AJ40: =AJ37 -> 0.5671875 | AM40: KWH / OCCUPIED ROOM - LAST YEAR | AR40: =AF37/AN37 -> 112.83003 | AY40: https://www.wunderground.com/history/monthly/eg/sharm-el-shiekh/HESH/date/2024-10
U41: ENERGY COST / OCCUPIED ROOM - THIS YEAR = | AB41: ='[1]cost.4.25'!BI38 -> 168.59449 | AC41: L.E. | AF41: OCCUPANCY - THIS YEAR = | AJ41: =AI37 -> 0.793025 | AM41: KWH / OCCU[PIED ROOM - THIS YEAR | AR41: =AE37/AM37 -> 88.66516 | BA41: 7598.27
N42: =X37*2 -> 591760 | U42: ENERGY COST / OCCUPIED ROOM - BUDGET = | AB42: ='[1]cost.4.25'!BH38 -> 334.74341 | AC42: L.E. | AF42: OCCUPANCY - BUDGET= | AJ42: =AK37 -> 0.545 | AM42: KWH / OCCUPIED ROOM - BUDGET | AR42: =AG37/AO37 -> 134.95856 | CC42: =229975+25 -> 230000
AM44: KWH / AVAILABLE ROOM - LAST YEAR | AR44: =AF37/BL37 -> 63.574144
AM45: KWH / AVAILABLE ROOM - THIS YEAR | AR45: =AE37/BL37 -> 70.313688
AM46: KWH / AVAILABLE ROOM - BUDGET | AR46: =AG37/BL37 -> 73.496382
DM81: .
BQ151: .

Sheet Sheet4

Sheet cost.5.25
H1: =H8*31 -> 6616.2857 | K1: =K8*31 -> 2493738 | P1: =P8*31 -> 0 | R1: =R8*31 -> 0 | W1: =W8*31 -> 18845 | X1: =X8*31 -> 96112 | AD1: =AD8*31 -> 16204.5 | AJ1: =AJ8*31 -> 5401.5 | AP1: =AP8*31 -> 21606 | AQ1: =AQ8*31 -> 82483
A2: Energy Cost May 2025 | AV2: Energy Cost - May 2024
B3: 1 | C3: 2 | D3: 3 | E3: 4 | F3: 5 | G3: 6 | H3: 7 | I3: 8 | J3: 9 | K3: 10 | L3: 11 | M3: 12 | N3: 13 | O3: 14 | P3: 15 | Q3: 16 | R3: 17 | S3: 18 | T3: 19 | U3: 20 | V3: 21 | W3: 22 | X3: 23 | Y3: 24 | Z3: 25 | AA3: 26 | AB3: 27 | AC3: 28 | AD3: 29 | AE3: 30 | AF3: 31 | AG3: 32 | AH3: 33 | AI3: 34 | AJ3: 35 | AK3: 36 | AL3: 37 | AM3: 38 | AN3: 39 | AO3: 40 | AP3: 41 | AQ3: 42 | AR3: 43 | AS3: 44 | AT3: 45 | AU3: 46 | AV3: 47 | AW3: 48 | AX3: 49 | AY3: 50 | AZ3: 51 | BA3: 52 | BB3: 53 | BC3: 54 | BD3: 55 | BE3: 56 | BF3: 57 | BG3: 58 | BH3: 59 | BI3: 60
J5: ELECTRICITY | O5: FUEL | V5: WATER | AB5: NATURAL GAS | AV5: ELECTRICITY | AX5: WATER | AZ5: NATURAL GAS | BC5: LAST YEAR TOTAL ENERGY L.E. | BD5: BUDGET TOTAL ENERGY L.E. | BE5: ACTUAL TOTAL ENERGY L.E. | BG5: ENERGY LAST YEAR / OCCUPIED ROOM | BH5: ENERGY BUDGET / OCCUPIED ROOM | BI5: ENERGY ACTUAL / OCCUPIED ROOM
B6: DATE | D6: Occ. | F6: Occupied Rooms | H6: Occupied Rooms Budget | J6: CONSUMP. KWH | K6: BUDGET L.E. | L6: LAST YEAR ACTUAL L.E. | M6: ACTUAL L.E. | O6: CONSUMP. LITRE | P6: BUDGET LITRE | Q6: GENERATOR KWH | R6: BUDGET L.E. | S6: LAST YEAR ACTUAL L.E. | T6: ACTUAL L.E. | V6: CONSUMP. M³ | W6: BUDGET M³ | X6: BUDGET L.E. | Y6: LAST YEAR ACTUAL L.E. | Z6: ACTUAL L.E. | AB6: BOILER CONSUMP. M³ | AC6: BOILER COST L.E. | AD6: BOILER BUDGET CONSUMP. M³ | AE6: BOILER BUDGET COST L.E. | AF6: BOILER CONSUMP. LAST YEAR M³ | AG6: BOILER COST LAST YEAR L.E. | AH6: KITCHEN CONSUMP. M³ | AI6: KITCHEN COST L.E. | AJ6: KITCHEN BUDGET CONSUMP. M³ | AK6: KITCHEN BUDGET COST L.E. | AL6: KITCHEN CONSUMP. LAST YEAR M³ | AM6: KITCHEN COST LAST YEAR L.E. | AN6: TOTAL CONSUMP. M³ | AO6: TOTAL CONSUMP. LAST YEAR M³ | AP6: BUDGET TOTAL CONSUMP. M³ | AQ6: BUDGET L.E. | AR6: LAST YEAR ACTUAL L.E. | AS6: ACTUAL L.E. | AV6: KWH / Occupied Room | AW6: L.E. / Occupied Room | AX6: Cu.Mt. / Occupied Room | AY6: L.E. / Occupied Room | AZ6: Cu.Mt. / Occupied Room | BA6: L.E. / Occupied Room
B8: 45778 | D8: ='Reading.5.25'!AI6 -> 0.8631 | F8: ='Reading.5.25'!AM6 -> 453.9906 | H8: =5976/28 -> 213.42857 | J8: ='Reading.5.25'!X6 -> 37560 | K8: =2493738/31 -> 80443.161 | L8: ='Cost.4.24'!M7 -> 0 | M8: =J8*1.94 -> 72866.4 | O8: ='Reading.5.25'!T6 -> 0 | P8: =0/31 -> 0 | Q8: ='Reading.5.25'!AB6 -> 0 | R8: =0/30 -> 0 | S8: ='Cost.4.24'!T7 -> 0 | T8: =O8*7.55 -> 0 | V8: ='Reading.5.25'!G6 -> 704 | W8: =18845/31 -> 607.90323 | X8: =96112/31 -> 3100.3871 | Y8: ='Cost.4.24'!Z7 -> 0 | Z8: ='Reading.5.25'!G6*5.1 -> 3590.4 | AB8: ='Reading.5.25'!O6 -> 682.28 | AC8: =AB8*3.73 -> 2544.9044 | AD8: =((21606/4)*3)/31 -> 522.72581 | AE8: =((92472/4)*3)/31 -> 2237.2258 | AF8: ='Cost.4.24'!AB7 -> 0 | AG8: ='Cost.4.24'!AC7 -> 0 | AH8: ='Reading.5.25'!K6 -> 252.072 | AI8: =AH8*4 -> 1008.288 | AJ8: =(21606/4)/31 -> 174.24194 | AK8: =(96112/4)/31 -> 775.09677 | AL8: ='Cost.4.24'!AH7 -> 0 | AM8: ='Cost.4.24'!AI7 -> 0 | AN8: =AB8+AH8 -> 934.352 | AO8: =AF8+AL8 -> 0 | AP8: =AD8+AJ8 -> 696.96774 | AQ8: =82483/31 -> 2660.7419 | AR8: ='Cost.4.24'!AS7 -> 0 | AS8: =AC8+AI8 -> 3553.1924 | AV8: ='Reading.5.25'!AE6/'cost.5.25'!F8 -> 82.732991 | AW8: =(M8+T8)/F8 -> 160.502 | AX8: =V8/F8 -> 1.5506929 | AY8: =Z8/F8 -> 7.9085338 | AZ8: =AN8/F8 -> 2.0580867 | BA8: =AS8/F8 -> 7.826577 | BC8: ='Cost.4.24'!BE7 -> 0 | BD8: =K8+R8+X8+AQ8 -> 86204.29 | BE8: =M8+T8+Z8+AS8 -> 80009.992 | BG8: ='Cost.4.24'!BI7 -> 0 | BH8: =BD8/H8 -> 403.9023 | BI8: =BE8/F8 -> 176.23711
B9: 45779 | D9: ='Reading.5.25'!AI7 -> 0.8631 | F9: ='Reading.5.25'!AM7 -> 453.9906 | H9: =5976/28 -> 213.42857 | J9: ='Reading.5.25'!X7 -> 37720 | K9: =2493738/31 -> 80443.161 | L9: ='Cost.4.24'!M8 -> 38530.8 | M9: =J9*1.94 -> 73176.8 | O9: ='Reading.5.25'!T7 -> 0 | P9: =0/31 -> 0 | Q9: ='Reading.5.25'!AB7 -> 0 | R9: =0/30 -> 0 | S9: ='Cost.4.24'!T8 -> 0 | T9: =O9*7.55 -> 0 | V9: ='Reading.5.25'!G7 -> 712 | W9: =18845/31 -> 607.90323 | X9: =96112/31 -> 3100.3871 | Y9: ='Cost.4.24'!Z8 -> 2454.3 | Z9: ='Reading.5.25'!G7*5.1 -> 3631.2 | AB9: ='Reading.5.25'!O7 -> 673.06 | AC9: =AB9*3.73 -> 2510.5138 | AD9: =((21606/4)*3)/31 -> 522.72581 | AE9: =((92472/4)*3)/31 -> 2237.2258 | AF9: ='Cost.4.24'!AB8 -> 391.85 | AG9: ='Cost.4.24'!AC8 -> 1461.6005 | AH9: ='Reading.5.25'!K7 -> 424.788 | AI9: =AH9*4 -> 1699.152 | AJ9: =(21606/4)/31 -> 174.24194 | AK9: =(96112/4)/31 -> 775.09677 | AL9: ='Cost.4.24'!AH8 -> 112.032 | AM9: ='Cost.4.24'!AI8 -> 417.87936 | AN9: =AB9+AH9 -> 1097.848 | AO9: =AF9+AL9 -> 503.882 | AP9: =AD9+AJ9 -> 696.96774 | AQ9: =82483/31 -> 2660.7419 | AR9: ='Cost.4.24'!AS8 -> 1879.4799 | AS9: =AC9+AI9 -> 4209.6658 | AV9: ='Reading.5.25'!AE7/'cost.5.25'!F9 -> 83.085421 | AW9: =(M9+T9)/F9 -> 161.18572 | AX9: =V9/F9 -> 1.5683144 | AY9: =Z9/F9 -> 7.9984035 | AZ9: =AN9/F9 -> 2.4182175 | BA9: =AS9/F9 -> 9.2725836 | BC9: ='Cost.4.24'!BE8 -> 42864.58 | BD9: =K9+R9+X9+AQ9 -> 86204.29 | BE9: =M9+T9+Z9+AS9 -> 81017.666 | BG9: ='Cost.4.24'!BI8 -> 156.44007 | BH9: =BD9/H9 -> 403.9023 | BI9: =BE9/F9 -> 178.4567
B10: 45780 | D10: ='Reading.5.25'!AI8 -> 0.8631 | F10: ='Reading.5.25'!AM8 -> 453.9906 | H10: =5976/28 -> 213.42857 | J10: ='Reading.5.25'!X8 -> 37240 | K10: =2493738/31 -> 80443.161 | L10: ='Cost.4.24'!M9 -> 39754 | M10: =J10*1.94 -> 72245.6 | O10: ='Reading.5.25'!T8 -> 0 | P10: =0/31 -> 0 | Q10: ='Reading.5.25'!AB8 -> 0 | R10: =0/30 -> 0 | S10: ='Cost.4.24'!T9 -> 0 | T10: =O10*7.55 -> 0 | V10: ='Reading.5.25'!G8 -> 576 | W10: =18845/31 -> 607.90323 | X10: =96112/31 -> 3100.3871 | Y10: ='Cost.4.24'!Z9 -> 2235.6 | Z10: ='Reading.5.25'!G8*5.1 -> 2937.6 | AB10: ='Reading.5.25'!O8 -> 682.28 | AC10: =AB10*3.73 -> 2544.9044 | AD10: =((21606/4)*3)/31 -> 522.72581 | AE10: =((92472/4)*3)/31 -> 2237.2258 | AF10: ='Cost.4.24'!AB9 -> 410.29 | AG10: ='Cost.4.24'!AC9 -> 1530.3817 | AH10: ='Reading.5.25'!K8 -> 126.036 | AI10: =AH10*4 -> 504.144 | AJ10: =(21606/4)/31 -> 174.24194 | AK10: =(96112/4)/31 -> 775.09677 | AL10: ='Cost.4.24'!AH9 -> 121.368 | AM10: ='Cost.4.24'!AI9 -> 452.70264 | AN10: =AB10+AH10 -> 808.316 | AO10: =AF10+AL10 -> 531.658 | AP10: =AD10+AJ10 -> 696.96774 | AQ10: =82483/31 -> 2660.7419 | AR10: ='Cost.4.24'!AS9 -> 1983.0843 | AS10: =AC10+AI10 -> 3049.0484 | AV10: ='Reading.5.25'!AE8/'cost.5.25'!F10 -> 82.02813 | AW10: =(M10+T10)/F10 -> 159.13457 | AX10: =V10/F10 -> 1.2687487 | AY10: =Z10/F10 -> 6.4706186 | AZ10: =AN10/F10 -> 1.7804686 | BA10: =AS10/F10 -> 6.7161047 | BC10: ='Cost.4.24'!BE9 -> 43972.684 | BD10: =K10+R10+X10+AQ10 -> 86204.29 | BE10: =M10+T10+Z10+AS10 -> 78232.248 | BG10: ='Cost.4.24'!BI9 -> 169.7787 | BH10: =BD10/H10 -> 403.9023 | BI10: =BE10/F10 -> 172.3213
B11: 45781 | D11: ='Reading.5.25'!AI9 -> 0.7433 | F11: ='Reading.5.25'!AM9 -> 390.9758 | H11: =5976/28 -> 213.42857 | J11: ='Reading.5.25'!X9 -> 37240 | K11: =2493738/31 -> 80443.161 | L11: ='Cost.4.24'!M10 -> 40532.4 | M11: =J11*1.94 -> 72245.6 | O11: ='Reading.5.25'!T9 -> 0 | P11: =0/31 -> 0 | Q11: ='Reading.5.25'!AB9 -> 0 | R11: =0/30 -> 0 | S11: ='Cost.4.24'!T10 -> 0 | T11: =O11*7.55 -> 0 | V11: ='Reading.5.25'!G9 -> 719 | W11: =18845/31 -> 607.90323 | X11: =96112/31 -> 3100.3871 | Y11: ='Cost.4.24'!Z10 -> 2682.72 | Z11: ='Reading.5.25'!G9*5.1 -> 3666.9 | AB11: ='Reading.5.25'!O9 -> 668.45 | AC11: =AB11*3.73 -> 2493.3185 | AD11: =((21606/4)*3)/31 -> 522.72581 | AE11: =((92472/4)*3)/31 -> 2237.2258 | AF11: ='Cost.4.24'!AB10 -> 387.24 | AG11: ='Cost.4.24'!AC10 -> 1444.4052 | AH11: ='Reading.5.25'!K9 -> 224.064 | AI11: =AH11*4 -> 896.256 | AJ11: =(21606/4)/31 -> 174.24194 | AK11: =(96112/4)/31 -> 775.09677 | AL11: ='Cost.4.24'!AH10 -> 149.376 | AM11: ='Cost.4.24'!AI10 -> 557.17248 | AN11: =AB11+AH11 -> 892.514 | AO11: =AF11+AL11 -> 536.616 | AP11: =AD11+AJ11 -> 696.96774 | AQ11: =82483/31 -> 2660.7419 | AR11: ='Cost.4.24'!AS10 -> 2001.5777 | AS11: =AC11+AI11 -> 3389.5745 | AV11: ='Reading.5.25'!AE9/'cost.5.25'!F11 -> 95.248862 | AW11: =(M11+T11)/F11 -> 184.78279 | AX11: =V11/F11 -> 1.8389885 | AY11: =Z11/F11 -> 9.3788414 | AZ11: =AN11/F11 -> 2.2827858 | BA11: =AS11/F11 -> 8.6695251 | BC11: ='Cost.4.24'!BE10 -> 45216.698 | BD11: =K11+R11+X11+AQ11 -> 86204.29 | BE11: =M11+T11+Z11+AS11 -> 79302.074 | BG11: ='Cost.4.24'!BI10 -> 173.91038 | BH11: =BD11/H11 -> 403.9023 | BI11: =BE11/F11 -> 202.83116
B12: 45782 | D12: ='Reading.5.25'!AI10 -> 0.7186 | F12: ='Reading.5.25'!AM10 -> 377.9836 | H12: =5976/28 -> 213.42857 | J12: ='Reading.5.25'!X10 -> 32320 | K12: =2493738/31 -> 80443.161 | L12: ='Cost.4.24'!M11 -> 39198 | M12: =J12*1.94 -> 62700.8 | O12: ='Reading.5.25'!T10 -> 0 | P12: =0/31 -> 0 | Q12: ='Reading.5.25'!AB10 -> 0 | R12: =0/30 -> 0 | S12: ='Cost.4.24'!T11 -> 0 | T12: =O12*7.55 -> 0 | V12: ='Reading.5.25'!G10 -> 688 | W12: =18845/31 -> 607.90323 | X12: =96112/31 -> 3100.3871 | Y12: ='Cost.4.24'!Z11 -> 2522.34 | Z12: ='Reading.5.25'!G10*5.1 -> 3508.8 | AB12: ='Reading.5.25'!O10 -> 659.23 | AC12: =AB12*3.73 -> 2458.9279 | AD12: =((21606/4)*3)/31 -> 522.72581 | AE12: =((92472/4)*3)/31 -> 2237.2258 | AF12: ='Cost.4.24'!AB11 -> 368.8 | AG12: ='Cost.4.24'!AC11 -> 1375.624 | AH12: ='Reading.5.25'!K10 -> 256.74 | AI12: =AH12*4 -> 1026.96 | AJ12: =(21606/4)/31 -> 174.24194 | AK12: =(96112/4)/31 -> 775.09677 | AL12: ='Cost.4.24'!AH11 -> 158.712 | AM12: ='Cost.4.24'!AI11 -> 591.99576 | AN12: =AB12+AH12 -> 915.97 | AO12: =AF12+AL12 -> 527.512 | AP12: =AD12+AJ12 -> 696.96774 | AQ12: =82483/31 -> 2660.7419 | AR12: ='Cost.4.24'!AS11 -> 1967.6198 | AS12: =AC12+AI12 -> 3485.8879 | AV12: ='Reading.5.25'!AE10/'cost.5.25'!F12 -> 85.506355 | AW12: =(M12+T12)/F12 -> 165.88233 | AX12: =V12/F12 -> 1.8201848 | AY12: =Z12/F12 -> 9.2829424 | AZ12: =AN12/F12 -> 2.4233062 | BA12: =AS12/F12 -> 9.2223258 | BC12: ='Cost.4.24'!BE11 -> 43687.96 | BD12: =K12+R12+X12+AQ12 -> 86204.29 | BE12: =M12+T12+Z12+AS12 -> 69695.488 | BG12: ='Cost.4.24'!BI11 -> 152.7551 | BH12: =BD12/H12 -> 403.9023 | BI12: =BE12/F12 -> 184.3876
B13: 45783 | D13: ='Reading.5.25'!AI11 -> 0.6597 | F13: ='Reading.5.25'!AM11 -> 347.0022 | H13: =5976/28 -> 213.42857 | J13: ='Reading.5.25'!X11 -> 35720 | K13: =2493738/31 -> 80443.161 | L13: ='Cost.4.24'!M12 -> 41811.2 | M13: =J13*1.94 -> 69296.8 | O13: ='Reading.5.25'!T11 -> 0 | P13: =0/31 -> 0 | Q13: ='Reading.5.25'!AB11 -> 0 | R13: =0/30 -> 0 | S13: ='Cost.4.24'!T12 -> 0 | T13: =O13*7.55 -> 0 | V13: ='Reading.5.25'!G11 -> 644 | W13: =18845/31 -> 607.90323 | X13: =96112/31 -> 3100.3871 | Y13: ='Cost.4.24'!Z12 -> 2668.14 | Z13: ='Reading.5.25'!G11*5.1 -> 3284.4 | AB13: ='Reading.5.25'!O11 -> 608.52 | AC13: =AB13*3.73 -> 2269.7796 | AD13: =((21606/4)*3)/31 -> 522.72581 | AE13: =((92472/4)*3)/31 -> 2237.2258 | AF13: ='Cost.4.24'!AB12 -> 414.9 | AG13: ='Cost.4.24'!AC12 -> 1547.577 | AH13: ='Reading.5.25'!K11 -> 242.736 | AI13: =AH13*4 -> 970.944 | AJ13: =(21606/4)/31 -> 174.24194 | AK13: =(96112/4)/31 -> 775.09677 | AL13: ='Cost.4.24'!AH12 -> 158.712 | AM13: ='Cost.4.24'!AI12 -> 591.99576 | AN13: =AB13+AH13 -> 851.256 | AO13: =AF13+AL13 -> 573.612 | AP13: =AD13+AJ13 -> 696.96774 | AQ13: =82483/31 -> 2660.7419 | AR13: ='Cost.4.24'!AS12 -> 2139.5728 | AS13: =AC13+AI13 -> 3240.7236 | AV13: ='Reading.5.25'!AE11/'cost.5.25'!F13 -> 102.93883 | AW13: =(M13+T13)/F13 -> 199.70133 | AX13: =V13/F13 -> 1.855896 | AY13: =Z13/F13 -> 9.4650697 | AZ13: =AN13/F13 -> 2.4531718 | BA13: =AS13/F13 -> 9.3392019 | BC13: ='Cost.4.24'!BE12 -> 46618.913 | BD13: =K13+R13+X13+AQ13 -> 86204.29 | BE13: =M13+T13+Z13+AS13 -> 75821.924 | BG13: ='Cost.4.24'!BI12 -> 184.26448 | BH13: =BD13/H13 -> 403.9023 | BI13: =BE13/F13 -> 218.5056
B14: 45784 | D14: ='Reading.5.25'!AI12 -> 0.8405 | F14: ='Reading.5.25'!AM12 -> 442.103 | H14: =5976/28 -> 213.42857 | J14: ='Reading.5.25'!X12 -> 39120 | K14: =2493738/31 -> 80443.161 | L14: ='Cost.4.24'!M13 -> 41922.4 | M14: =J14*1.94 -> 75892.8 | O14: ='Reading.5.25'!T12 -> 0 | P14: =0/31 -> 0 | Q14: ='Reading.5.25'!AB12 -> 0 | R14: =0/30 -> 0 | S14: ='Cost.4.24'!T13 -> 0 | T14: =O14*7.55 -> 0 | V14: ='Reading.5.25'!G12 -> 707 | W14: =18845/31 -> 607.90323 | X14: =96112/31 -> 3100.3871 | Y14: ='Cost.4.24'!Z13 -> 2551.5 | Z14: ='Reading.5.25'!G12*5.1 -> 3605.7 | AB14: ='Reading.5.25'!O12 -> 622.35 | AC14: =AB14*3.73 -> 2321.3655 | AD14: =((21606/4)*3)/31 -> 522.72581 | AE14: =((92472/4)*3)/31 -> 2237.2258 | AF14: ='Cost.4.24'!AB13 -> 428.73 | AG14: ='Cost.4.24'!AC13 -> 1599.1629 | AH14: ='Reading.5.25'!K12 -> 270.744 | AI14: =AH14*4 -> 1082.976 | AJ14: =(21606/4)/31 -> 174.24194 | AK14: =(96112/4)/31 -> 775.09677 | AL14: ='Cost.4.24'!AH13 -> 149.376 | AM14: ='Cost.4.24'!AI13 -> 557.17248 | AN14: =AB14+AH14 -> 893.094 | AO14: =AF14+AL14 -> 578.106 | AP14: =AD14+AJ14 -> 696.96774 | AQ14: =82483/31 -> 2660.7419 | AR14: ='Cost.4.24'!AS13 -> 2156.3354 | AS14: =AC14+AI14 -> 3404.3415 | AV14: ='Reading.5.25'!AE12/'cost.5.25'!F14 -> 88.486167 | AW14: =(M14+T14)/F14 -> 171.66316 | AX14: =V14/F14 -> 1.5991749 | AY14: =Z14/F14 -> 8.1557917 | AZ14: =AN14/F14 -> 2.0201039 | BA14: =AS14/F14 -> 7.7003357 | BC14: ='Cost.4.24'!BE13 -> 46630.235 | BD14: =K14+R14+X14+AQ14 -> 86204.29 | BE14: =M14+T14+Z14+AS14 -> 82902.841 | BG14: ='Cost.4.24'!BI13 -> 170.80672 | BH14: =BD14/H14 -> 403.9023 | BI14: =BE14/F14 -> 187.51929
B15: 45785 | D15: ='Reading.5.25'!AI13 -> 0.7928 | F15: ='Reading.5.25'!AM13 -> 417.0128 | H15: =5976/28 -> 213.42857 | J15: ='Reading.5.25'!X13 -> 38960 | K15: =2493738/31 -> 80443.161 | L15: ='Cost.4.24'!M14 -> 39865.2 | M15: =J15*1.94 -> 75582.4 | O15: ='Reading.5.25'!T13 -> 0 | P15: =0/31 -> 0 | Q15: ='Reading.5.25'!AB13 -> 0 | R15: =0/30 -> 0 | S15: ='Cost.4.24'!T14 -> 0 | T15: =O15*7.55 -> 0 | V15: ='Reading.5.25'!G13 -> 692 | W15: =18845/31 -> 607.90323 | X15: =96112/31 -> 3100.3871 | Y15: ='Cost.4.24'!Z14 -> 2468.88 | Z15: ='Reading.5.25'!G13*5.1 -> 3529.2 | AB15: ='Reading.5.25'!O13 -> 709.94 | AC15: =AB15*3.73 -> 2648.0762 | AD15: =((21606/4)*3)/31 -> 522.72581 | AE15: =((92472/4)*3)/31 -> 2237.2258 | AF15: ='Cost.4.24'!AB14 -> 414.9 | AG15: ='Cost.4.24'!AC14 -> 1547.577 | AH15: ='Reading.5.25'!K13 -> 270.744 | AI15: =AH15*4 -> 1082.976 | AJ15: =(21606/4)/31 -> 174.24194 | AK15: =(96112/4)/31 -> 775.09677 | AL15: ='Cost.4.24'!AH14 -> 158.712 | AM15: ='Cost.4.24'!AI14 -> 591.99576 | AN15: =AB15+AH15 -> 980.684 | AO15: =AF15+AL15 -> 573.612 | AP15: =AD15+AJ15 -> 696.96774 | AQ15: =82483/31 -> 2660.7419 | AR15: ='Cost.4.24'!AS14 -> 2139.5728 | AS15: =AC15+AI15 -> 3731.0522 | AV15: ='Reading.5.25'!AE13/'cost.5.25'!F15 -> 93.426389 | AW15: =(M15+T15)/F15 -> 181.24719 | AX15: =V15/F15 -> 1.6594215 | AY15: =Z15/F15 -> 8.4630496 | AZ15: =AN15/F15 -> 2.351688 | BA15: =AS15/F15 -> 8.9470928 | BC15: ='Cost.4.24'!BE14 -> 44473.653 | BD15: =K15+R15+X15+AQ15 -> 86204.29 | BE15: =M15+T15+Z15+AS15 -> 82842.652 | BG15: ='Cost.4.24'!BI14 -> 177.89461 | BH15: =BD15/H15 -> 403.9023 | BI15: =BE15/F15 -> 198.65734
B16: 45786
B17: 45787
B18: 45788
B19: 45789
B20: 45790
B21: 45791
B22: 45792
B23: 45793
B24: 45794
B25: 45795
B26: 45796
B27: 45797
... B38: 45808
B39: TOTAL | D39: =AVERAGE(D8:D37) -> 0.793025 | F39: =SUM(F8:F37) -> 3337.0492 | H39: =+SUM(H8:H37) -> 1707.4286 | J39: =SUM(J8:J37) -> 295880 | K39: =SUM(K8:K37) -> 643545.29 | L39: =SUM(L8:L37) -> 281614 | M39: =SUM(M8:M37) -> 574007.2 | O39: =SUM(O8:O37) -> 0 | P39: =SUM(P8:P37) -> 0 | Q39: =SUM(Q8:Q37) -> 0 | R39: =SUM(R8:R37) -> 0 | S39: =SUM(S8:S37) -> 0 | T39: =SUM(T8:T37) -> 0 | V39: =SUM(V8:V37) -> 5442 | W39: =SUM(W8:W37) -> 4863.2258 | X39: =SUM(X8:X37) -> 24803.097 | Y39: =SUM(Y8:Y37) -> 17583.48 | Z39: =SUM(Z8:Z37) -> 27754.2 | AB39: =SUM(AB8:AB37) -> 5306.11 | AC39: =SUM(AC8:AC37) -> 19791.79 | AD39: =SUM(AD8:AD37) -> 4181.8065 | AE39: =SUM(AE8:AE37) -> 17897.806 | AF39: =SUM(AF8:AF37) -> 2816.71 | AG39: =SUM(AG8:AG37) -> 10506.328 | AH39: =SUM(AH8:AH37) -> 2067.924 | AI39: =SUM(AI8:AI37) -> 8271.696 | ... AS39: =SUM(AS8:AS37) -> 28063.486 | AV39: =AVERAGE(AV8:AV37) -> 89.181643 | AW39: =AVERAGE(AW8:AW37) -> 173.01239 | AX39: =AVERAGE(AX8:AX37) -> 1.6451777 | AY39: =AVERAGE(AY8:AY37) -> 8.3904063 | AZ39: =AVERAGE(AZ8:AZ37) -> 2.2234785 | BA39: =AVERAGE(BA8:BA37) -> 8.4617183 | BC39: =SUM(BC8:BC37) -> 313464.72 | BD39: =SUM(BD8:BD37) -> 689634.32 | BE39: =SUM(BE8:BE37) -> 629824.89 | BG39: =BC39/'Reading.5.25'!AN37 -> 132.20781 | BH39: =AVERAGE(BH8:BH37) -> 403.9023 | BI39: =AVERAGE(BI8:BI37) -> 189.86451

Sheet Domestic Water
A5: Engineering Department
A6: Domestic Water Parameters | L6: Month : | M6: May | N6: 2025
A8: Day | B8: Hardness | D8: Alkalinity | G8: Chloride | H8: PH | I8: Conductivity | J8: TDS | K8: Fe | L8: CL | M8: T ºc | N8: Production
