Workbook

Sheet Total
A1: Site Name | B1: Day | C1: Month | D1: Year | E1: Total Electricity Kwh | F1: Electricity Tariff ($/Kwh) | G1: Natural Gas (m3) | H1: Natural Gas $/m3 | I1: Water Utility Supply (m3) m3 | J1: Water Utility Supply (m3) $/m3 | K1: District Energy Cooling RTH | L1: District Energy Cooling $/RTH | M1: Room Nights | N1: Total Guests
A2: Pearl Rotana Capital Centre | B2: 1 | C2: 4 | D2: 2024 | E2: =Submetering!E2+Submetering!F2+Submetering!G2 -> 14928 | F2: 0.2 | G2: ='Apr 2024'!T5 -> 30.6153 | H2: 16.875 | I2: =Submetering!H2 -> 86 | J2: 7.84 | K2: ='Apr 2024'!X5 -> 5686.9 | L2: 0.3442 | M2: =Submetering!N2 -> 242.0145 | N2: =Submetering!O2 -> 336
A3: Pearl Rotana Capital Centre | B3: =B2+1 -> 2 | C3: 4 | D3: 2024 | E3: =Submetering!E3+Submetering!F3+Submetering!G3 -> 14950 | F3: 0.2 | G3: ='Apr 2024'!T6 -> 35.8938 | H3: 16.875 | I3: =Submetering!H3 -> 100 | J3: 7.84 | K3: ='Apr 2024'!X6 -> 5402.555 | L3: 0.3442 | M3: =Submetering!N3 -> 252 | N3: =Submetering!O3 -> 360
A4: Pearl Rotana Capital Centre | B4: =B3+1 -> 3 | C4: 4 | D4: 2024 | E4: =Submetering!E4+Submetering!F4+Submetering!G4 -> 14962 | F4: 0.2 | G4: ='Apr 2024'!T7 -> 33.7824 | H4: 16.875 | I4: =Submetering!H4 -> 99 | J4: 7.84 | K4: ='Apr 2024'!X7 -> 5686.9 | L4: 0.3442 | M4: =Submetering!N4 -> 235.998 | N4: =Submetering!O4 -> 333
A5: Pearl Rotana Capital Centre | B5: =B4+1 -> 4 | C5: 4 | D5: 2024 | E5: =Submetering!E5+Submetering!F5+Submetering!G5 -> 14882 | F5: 0.2 | G5: ='Apr 2024'!T8 -> 33.7824 | H5: 16.875 | I5: =Submetering!H5 -> 88 | J5: 7.84 | K5: ='Apr 2024'!X8 -> 5971.245 | L5: 0.3442 | M5: =Submetering!N5 -> 194.0085 | N5: =Submetering!O5 -> 293
A6: Pearl Rotana Capital Centre | B6: =B5+1 -> 5 | C6: 4 | D6: 2024 | E6: =Submetering!E6+Submetering!F6+Submetering!G6 -> 14448 | F6: 0.2 | G6: ='Apr 2024'!T9 -> 35.8938 | H6: 16.875 | I6: =Submetering!H6 -> 106 | J6: 7.84 | K6: ='Apr 2024'!X9 -> 5971.245 | L6: 0.3442 | M6: =Submetering!N6 -> 189 | N6: =Submetering!O6 -> 320
A7: Pearl Rotana Capital Centre | B7: =B6+1 -> 6 | C7: 4 | D7: 2024 | E7: =Submetering!E7+Submetering!F7+Submetering!G7 -> 14678 | F7: 0.2 | G7: ='Apr 2024'!T10 -> 34.8381 | H7: 16.875 | I7: =Submetering!H7 -> 81 | J7: 7.84 | K7: ='Apr 2024'!X10 -> 5686.9 | L7: 0.3442 | M7: =Submetering!N7 -> 147.0105 | N7: =Submetering!O7 -> 241
A8: Pearl Rotana Capital Centre | B8: =B7+1 -> 7 | C8: 4 | D8: 2024 | E8: =Submetering!E8+Submetering!F8+Submetering!G8 -> 14593 | F8: 0.2 | G8: ='Apr 2024'!T11 -> 30.6153 | H8: 16.875 | I8: =Submetering!H8 -> 82 | J8: 7.84 | K8: ='Apr 2024'!X11 -> 5686.9 | L8: 0.3442 | M8: =Submetering!N8 -> 162.0045 | N8: =Submetering!O8 -> 281
A9: Pearl Rotana Capital Centre | B9: =B8+1 -> 8 | C9: 4 | D9: 2024 | E9: =Submetering!E9+Submetering!F9+Submetering!G9 -> 14282 | F9: 0.2 | G9: ='Apr 2024'!T12 -> 31.671 | H9: 16.875 | I9: =Submetering!H9 -> 52 | J9: 7.84 | K9: ='Apr 2024'!X12 -> 5686.9 | L9: 0.3442 | M9: =Submetering!N9 -> 164.997 | N9: =Submetering!O9 -> 298
A10: Pearl Rotana Capital Centre | B10: =B9+1 -> 9 | C10: 4 | D10: 2024 | E10: =Submetering!E10+Submetering!F10+Submetering!G10 -> 14857 | F10: 0.2 | G10: ='Apr 2024'!T13 -> 29.5596 | H10: 16.875 | I10: =Submetering!H10 -> 75 | J10: 7.84 | K10: ='Apr 2024'!X13 -> 6255.59 | L10: 0.3442 | M10: =Submetering!N10 -> 176.9985 | N10: =Submetering!O10 -> 323
A11: Pearl Rotana Capital Centre | B11: =B10+1 -> 10 | C11: 4 | D11: 2024 | E11: =Submetering!E11+Submetering!F11+Submetering!G11 -> 14513 | F11: 0.2 | G11: ='Apr 2024'!T14 -> 29.5596 | H11: 16.875 | I11: =Submetering!H11 -> 93 | J11: 7.84 | K11: ='Apr 2024'!X14 -> 6824.28 | L11: 0.3442 | M11: =Submetering!N11 -> 210.0105 | N11: =Submetering!O11 -> 372
A12: Pearl Rotana Capital Centre | B12: =B11+1 -> 11 | C12: 4 | D12: 2024 | E12: =Submetering!E12+Submetering!F12+Submetering!G12 -> 14921 | F12: 0.2 | G12: ='Apr 2024'!T15 -> 30.6153 | H12: 16.875 | I12: =Submetering!H12 -> 102 | J12: 7.84 | K12: ='Apr 2024'!X15 -> 7108.625 | L12: 0.3442 | M12: =Submetering!N12 -> 273.987 | N12: =Submetering!O12 -> 480
A13: Pearl Rotana Capital Centre | B13: =B12+1 -> 12 | C13: 4 | D13: 2024 | E13: =Submetering!E13+Submetering!F13+Submetering!G13 -> 15025 | F13: 0.2 | G13: ='Apr 2024'!T16 -> 32.7267 | H13: 16.875 | I13: =Submetering!H13 -> 113 | J13: 7.84 | K13: ='Apr 2024'!X16 -> 7392.97 | L13: 0.3442 | M13: =Submetering!N13 -> 230.9895 | N13: =Submetering!O13 -> 403
A14: Pearl Rotana Capital Centre | B14: =B13+1 -> 13 | C14: 4 | D14: 2024 | E14: =Submetering!E14+Submetering!F14+Submetering!G14 -> 14392 | F14: 0.2 | G14: ='Apr 2024'!T17 -> 33.7824 | H14: 16.875 | I14: =Submetering!H14 -> 102 | J14: 7.84 | K14: ='Apr 2024'!X17 -> 6255.59 | L14: 0.3442 | M14: =Submetering!N14 -> 135.9855 | N14: =Submetering!O14 -> 217
... A31: Pearl Rotana Capital Centre | B31: =B30+1 -> 30 | C31: 4 | D31: 2024 | E31: =Submetering!E31+Submetering!F31+Submetering!G31 -> 15139 | F31: 0.2 | G31: ='Apr 2024'!T34 -> 34.8381 | H31: 16.875 | I31: =Submetering!H31 -> 105 | J31: 7.84 | K31: ='Apr 2024'!X34 -> 8814.695 | L31: 0.3442 | M31: =Submetering!N31 -> 315 | N31: =Submetering!O31 -> 355

Sheet Submetering
A1: Site Name | B1: Day | C1: Month | D1: Year | E1: MDB#2 | F1: MDB#3 | G1: MDB#1 Façade | H1: Water | I1: Gas Meter#1 GF Kitchen | J1: Gas Meter#2 1st floor Kitchen | K1: District Cooling | L1: District Cooling ETS | M1: Water Main Kitchen | N1: Room Nights | O1: Total Guests
A2: Pearl Rotana Capital Centre | B2: 1 | C2: 4 | D2: 2025 | E2: ='Apr 2024'!C5 -> 7825 | F2: ='Apr 2024'!E5 -> 6969 | G2: ='Apr 2024'!G5 -> 134 | H2: ='Apr 2024'!K5 -> 86 | I2: ='Apr 2024'!N5 -> 17 | J2: ='Apr 2024'!P5 -> 13 | K2: ='Apr 2024'!X5 -> 5686.9 | L2: ='Apr 2024'!AC5 -> 6479 | M2: ='Apr 2024'!AP5 -> 9 | N2: ='Apr 2024'!AD5*315 -> 242.0145 | O2: ='Apr 2024'!AE5 -> 336
A3: Pearl Rotana Capital Centre | B3: =B2+1 -> 2 | C3: 4 | D3: 2025 | E3: ='Apr 2024'!C6 -> 7905 | F3: ='Apr 2024'!E6 -> 6910 | G3: ='Apr 2024'!G6 -> 135 | H3: ='Apr 2024'!K6 -> 100 | I3: ='Apr 2024'!N6 -> 18 | J3: ='Apr 2024'!P6 -> 18 | K3: ='Apr 2024'!X6 -> 5402.555 | L3: ='Apr 2024'!AC6 -> 6538 | M3: ='Apr 2024'!AP6 -> 9 | N3: ='Apr 2024'!AD6*315 -> 252 | O3: ='Apr 2024'!AE6 -> 360
A4: Pearl Rotana Capital Centre | B4: =B3+1 -> 3 | C4: 4 | D4: 2025 | E4: ='Apr 2024'!C7 -> 7884 | F4: ='Apr 2024'!E7 -> 6944 | G4: ='Apr 2024'!G7 -> 134 | H4: ='Apr 2024'!K7 -> 99 | I4: ='Apr 2024'!N7 -> 17 | J4: ='Apr 2024'!P7 -> 16 | K4: ='Apr 2024'!X7 -> 5686.9 | L4: ='Apr 2024'!AC7 -> 6789 | M4: ='Apr 2024'!AP7 -> 10 | N4: ='Apr 2024'!AD7*315 -> 235.998 | O4: ='Apr 2024'!AE7 -> 333
A5: Pearl Rotana Capital Centre | B5: =B4+1 -> 4 | C5: 4 | D5: 2025 | E5: ='Apr 2024'!C8 -> 7822 | F5: ='Apr 2024'!E8 -> 6924 | G5: ='Apr 2024'!G8 -> 136 | H5: ='Apr 2024'!K8 -> 88 | I5: ='Apr 2024'!N8 -> 17 | J5: ='Apr 2024'!P8 -> 15 | K5: ='Apr 2024'!X8 -> 5971.245 | L5: ='Apr 2024'!AC8 -> 6964 | M5: ='Apr 2024'!AP8 -> 9 | N5: ='Apr 2024'!AD8*315 -> 194.0085 | O5: ='Apr 2024'!AE8 -> 293
A6: Pearl Rotana Capital Centre | B6: =B5+1 -> 5 | C6: 4 | D6: 2025 | E6: ='Apr 2024'!C9 -> 7517 | F6: ='Apr 2024'!E9 -> 6795 | G6: ='Apr 2024'!G9 -> 136 | H6: ='Apr 2024'!K9 -> 106 | I6: ='Apr 2024'!N9 -> 19 | J6: ='Apr 2024'!P9 -> 16 | K6: ='Apr 2024'!X9 -> 5971.245 | L6: ='Apr 2024'!AC9 -> 6613 | M6: ='Apr 2024'!AP9 -> 9 | N6: ='Apr 2024'!AD9*315 -> 189 | O6: ='Apr 2024'!AE9 -> 320
A7: Pearl Rotana Capital Centre | B7: =B6+1 -> 6 | C7: 4 | D7: 2025 | E7: ='Apr 2024'!C10 -> 7644 | F7: ='Apr 2024'!E10 -> 6897 | G7: ='Apr 2024'!G10 -> 137 | H7: ='Apr 2024'!K10 -> 81 | I7: ='Apr 2024'!N10 -> 18 | J7: ='Apr 2024'!P10 -> 15 | K7: ='Apr 2024'!X10 -> 5686.9 | L7: ='Apr 2024'!AC10 -> 6620 | M7: ='Apr 2024'!AP10 -> 8 | N7: ='Apr 2024'!AD10*315 -> 147.0105 | O7: ='Apr 2024'!AE10 -> 241
A8: Pearl Rotana Capital Centre | B8: =B7+1 -> 7 | C8: 4 | D8: 2025 | E8: ='Apr 2024'!C11 -> 7647 | F8: ='Apr 2024'!E11 -> 6809 | G8: ='Apr 2024'!G11 -> 137 | H8: ='Apr 2024'!K11 -> 82 | I8: ='Apr 2024'!N11 -> 16 | J8: ='Apr 2024'!P11 -> 15 | K8: ='Apr 2024'!X11 -> 5686.9 | L8: ='Apr 2024'!AC11 -> 6551 | M8: ='Apr 2024'!AP11 -> 9 | N8: ='Apr 2024'!AD11*315 -> 162.0045 | O8: ='Apr 2024'!AE11 -> 281
A9: Pearl Rotana Capital Centre | B9: =B8+1 -> 8 | C9: 4 | D9: 2025 | E9: ='Apr 2024'!C12 -> 7514 | F9: ='Apr 2024'!E12 -> 6632 | G9: ='Apr 2024'!G12 -> 136 | H9: ='Apr 2024'!K12 -> 52 | I9: ='Apr 2024'!N12 -> 18 | J9: ='Apr 2024'!P12 -> 13 | K9: ='Apr 2024'!X12 -> 5686.9 | L9: ='Apr 2024'!AC12 -> 6842 | M9: ='Apr 2024'!AP12 -> 8 | N9: ='Apr 2024'!AD12*315 -> 164.997 | O9: ='Apr 2024'!AE12 -> 298
A10: Pearl Rotana Capital Centre | B10: =B9+1 -> 9 | C10: 4 | D10: 2025 | E10: ='Apr 2024'!C13 -> 7880 | F10: ='Apr 2024'!E13 -> 6841 | G10: ='Apr 2024'!G13 -> 136 | H10: ='Apr 2024'!K13 -> 75 | I10: ='Apr 2024'!N13 -> 16 | J10: ='Apr 2024'!P13 -> 13 | K10: ='Apr 2024'!X13 -> 6255.59 | L10: ='Apr 2024'!AC13 -> 7118 | M10: ='Apr 2024'!AP13 -> 10 | N10: ='Apr 2024'!AD13*315 -> 176.9985 | O10: ='Apr 2024'!AE13 -> 323
A11: Pearl Rotana Capital Centre | B11: =B10+1 -> 10 | C11: 4 | D11: 2025 | E11: ='Apr 2024'!C14 -> 7653 | F11: ='Apr 2024'!E14 -> 6722 | G11: ='Apr 2024'!G14 -> 138 | H11: ='Apr 2024'!K14 -> 93 | I11: ='Apr 2024'!N14 -> 17 | J11: ='Apr 2024'!P14 -> 12 | K11: ='Apr 2024'!X14 -> 6824.28 | L11: ='Apr 2024'!AC14 -> 7431 | M11: ='Apr 2024'!AP14 -> 8 | N11: ='Apr 2024'!AD14*315 -> 210.0105 | O11: ='Apr 2024'!AE14 -> 372
A12: Pearl Rotana Capital Centre | B12: =B11+1 -> 11 | C12: 4 | D12: 2025 | E12: ='Apr 2024'!C15 -> 7943 | F12: ='Apr 2024'!E15 -> 6869 | G12: ='Apr 2024'!G15 -> 109 | H12: ='Apr 2024'!K15 -> 102 | I12: ='Apr 2024'!N15 -> 17 | J12: ='Apr 2024'!P15 -> 11 | K12: ='Apr 2024'!X15 -> 7108.625 | L12: ='Apr 2024'!AC15 -> 8322 | M12: ='Apr 2024'!AP15 -> 7 | N12: ='Apr 2024'!AD15*315 -> 273.987 | O12: ='Apr 2024'!AE15 -> 480
A13: Pearl Rotana Capital Centre | B13: =B12+1 -> 12 | C13: 4 | D13: 2025 | E13: ='Apr 2024'!C16 -> 7962 | F13: ='Apr 2024'!E16 -> 6927 | G13: ='Apr 2024'!G16 -> 136 | H13: ='Apr 2024'!K16 -> 113 | I13: ='Apr 2024'!N16 -> 18 | J13: ='Apr 2024'!P16 -> 14 | K13: ='Apr 2024'!X16 -> 7392.97 | L13: ='Apr 2024'!AC16 -> 8448 | M13: ='Apr 2024'!AP16 -> 9 | N13: ='Apr 2024'!AD16*315 -> 230.9895 | O13: ='Apr 2024'!AE16 -> 403
A14: Pearl Rotana Capital Centre | B14: =B13+1 -> 13 | C14: 4 | D14: 2025 | E14: ='Apr 2024'!C17 -> 7581 | F14: ='Apr 2024'!E17 -> 6700 | G14: ='Apr 2024'!G17 -> 111 | H14: ='Apr 2024'!K17 -> 102 | I14: ='Apr 2024'!N17 -> 19 | J14: ='Apr 2024'!P17 -> 12 | K14: ='Apr 2024'!X17 -> 6255.59 | L14: ='Apr 2024'!AC17 -> 7369 | M14: ='Apr 2024'!AP17 -> 9 | N14: ='Apr 2024'!AD17*315 -> 135.9855 | O14: ='Apr 2024'!AE17 -> 217
... A31: Pearl Rotana Capital Centre | B31: =B30+1 -> 30 | C31: 4 | D31: 2025 | E31: ='Apr 2024'!C34 -> 8103 | F31: ='Apr 2024'!E34 -> 6915 | G31: ='Apr 2024'!G34 -> 121 | H31: ='Apr 2024'!K34 -> 105 | I31: ='Apr 2024'!N34 -> 20 | J31: ='Apr 2024'!P34 -> 14 | K31: ='Apr 2024'!X34 -> 8814.695 | L31: ='Apr 2024'!AC34 -> 10444 | M31: ='Apr 2024'!AP34 -> 12 | N31: ='Apr 2024'!AD34*315 -> 315 | O31: ='Apr 2024'!AE34 -> 355

Sheet Apr 2024
A1: PEARL ROTANA CAPITAL CENTRE UTILITIES CONSUMPTION - APRIL 2024
A2: DATE | B2: Electricity | J2: Water | M2: SNG Gas | V2: District Cooling | AD2: Additional Info | AF2: Additional Meter
B3: MDB #2 | D3: MDB #3 | F3: MDB #1 Façade | H3: Total ELE Cons. KW | I3: Electricity AED | J3: Hotel Reading | K3: Water Cons. M3 | L3: Water AED | M3: Gas Meter #1 G Floor Kitchen | O3: Gas Meter #2 1st Floor Kitchen | Q3: Total Gas Cons. M3 | R3: PRS Meter Reading | S3: PRS Meter Cons. M3 | T3: Meter factor (1.05570) | U3: Gas AED | V3: Hotel BTU Meter Energy Reading | W3: District Cooling Cons. MWH | X3: District Cooling Cons. Ton Hour | Y3: District Cooling Cons. AED | Z3: District Cooling Fixed Charge | AA3: District Cooling Total AED | AB3: ETS Energy Meter Reading | AC3: ETS Cons. | AD3: Hotel Occupancy % | AE3: Adl. & Chl. | AF3: Electricity MDB-1 | AI3: Electricity MDB-E | AL3: Electricity-MCC Panel Chilled water Secondary Pumps | AO3: Water - Main kitchen | AR3: Water - Swimming Pool | AU3: Water - Bottling Plant
B4: Reading | C4: Cons. | D4: Reading | E4: Cons. | F4: Reading | G4: Cons. | M4: Reading | N4: Cons. | O4: Reading | P4: Cons. | AF4: Meter Reading | AG4: Cons. KWH | AH4: AED | AI4: Meter Reading | AJ4: Cons. KWH | AK4: AED | AL4: Meter Reading | AM4: Cons. KWH | AN4: AED | AO4: Meter Reading | AP4: Cons. M3 | AQ4: AED | AR4: Meter Reading | AS4: Cons. M3 | AT4: AED | AU4: Meter Reading | AV4: Cons. M3 | AW4: AED
A5: 45383 | B5: 18913332 | C5: 7825 | D5: 19846902 | E5: 6969 | F5: 451713 | G5: 134 | H5: =C5+E5+G5 -> 14928 | I5: =H5*0.2 -> 2985.6 | J5: 78237 | K5: 86 | L5: =K5*7.84 -> 674.24 | M5: 35334 | N5: 17 | O5: 20207 | P5: 13 | Q5: =N5+P5 -> 30 | R5: 51673 | S5: 29 | T5: =S5*1.0557 -> 30.6153 | U5: =IF(ISBLANK(M5),"0",T5*11.05+216.666) -> 554.96507 | V5: 67153 | W5: 20 | X5: =IF(ISBLANK(V5),"0 ",W5*284.345) -> 5686.9 | Y5: =X5*0.3442 -> 1957.431 | Z5: =IF(ISBLANK(V5),"0",1570*1546.86/12/30*0.65) -> 4384.9184 | AA5: =Y5+Z5 -> 6342.3494 | AB5: 6078457 | AC5: 6479 | AD5: 0.7683 | AE5: 336 | AF5: 13304033 | AG5: 4962 | AH5: =AG5*0.2 -> 992.4 | AI5: 6180196 | AJ5: 2179 | AK5: =AJ5*0.2 -> 435.8 | AL5: 120357 | AM5: 225 | AN5: =AM5*0.2 -> 45 | AO5: 6070 | AP5: 9 | AQ5: =AP5*7.84 -> 70.56 | AR5: 2756 | AS5: 1 | AT5: =AS5*7.84 -> 7.84 | AU5: 110 | AV5: 1 | AW5: =AV5*7.84 -> 7.84
A6: 45384 | B6: 18921237 | C6: =IF(ISBLANK(B6),"0",B6-B5) -> 7905 | D6: 19853812 | E6: =IF(ISBLANK(D6),"0",D6-D5) -> 6910 | F6: 451848 | G6: =IF(ISBLANK(F6),"0",F6-F5) -> 135 | H6: =C6+E6+G6 -> 14950 | I6: =H6*0.2 -> 2990 | J6: 78337 | K6: =IF(ISBLANK(J6),"0",J6-J5) -> 100 | L6: =K6*7.84 -> 784 | M6: 35352 | N6: =IF(ISBLANK(M6),"0",M6-M5) -> 18 | O6: 20225 | P6: =IF(ISBLANK(O6),"0",O6-O5) -> 18 | Q6: =N6+P6 -> 36 | R6: 51707 | S6: =IF(ISBLANK(R6),"0",R6-R5) -> 34 | T6: =S6*1.0557 -> 35.8938 | U6: =IF(ISBLANK(M6),"0",T6*11.05+216.666) -> 613.29249 | V6: 67172 | W6: =IF(ISBLANK(V6)," ",V6-V5) -> 19 | X6: =IF(ISBLANK(V6),"0 ",W6*284.345) -> 5402.555 | Y6: =X6*0.3442 -> 1859.5594 | Z6: =IF(ISBLANK(V6),"0",1570*1546.86/12/30*0.65) -> 4384.9184 | AA6: =Y6+Z6 -> 6244.4778 | AB6: 6084995 | AC6: =IF(ISBLANK(AB6),"0 ",AB6-AB5) -> 6538 | AD6: 0.8 | AE6: 360 | AF6: 13308961 | AG6: =IF(ISBLANK(AF6),"0",AF6-AF5) -> 4928 | AH6: =AG6*0.2 -> 985.6 | AI6: 6182373 | AJ6: =IF(ISBLANK(AI6),"0",AI6-AI5) -> 2177 | AK6: =AJ6*0.2 -> 435.4 | AL6: 120582 | AM6: =IF(ISBLANK(AL6),"0",AL6-AL5) -> 225 | AN6: =AM6*0.2 -> 45 | AO6: 6079 | AP6: =IF(ISBLANK(AO6),"0",AO6-AO5) -> 9 | AQ6: =AP6*7.84 -> 70.56 | AR6: 2757 | AS6: =IF(ISBLANK(AR6),"0",AR6-AR5) -> 1 | AT6: =AS6*7.84 -> 7.84 | AU6: 111 | AV6: =IF(ISBLANK(AU6),"0",AU6-AU5) -> 1 | AW6: =AV6*7.84 -> 7.84
A7: 45385 | B7: 18929121 | C7: =IF(ISBLANK(B7),"0",B7-B6) -> 7884 | D7: 19860756 | E7: =IF(ISBLANK(D7),"0",D7-D6) -> 6944 | F7: 451982 | G7: =IF(ISBLANK(F7),"0",F7-F6) -> 134 | H7: =C7+E7+G7 -> 14962 | I7: =H7*0.2 -> 2992.4 | J7: 78436 | K7: =IF(ISBLANK(J7),"0",J7-J6) -> 99 | L7: =K7*7.84 -> 776.16 | M7: 35369 | N7: =IF(ISBLANK(M7),"0",M7-M6) -> 17 | O7: 20241 | P7: =IF(ISBLANK(O7),"0",O7-O6) -> 16 | Q7: =N7+P7 -> 33 | R7: 51739 | S7: =IF(ISBLANK(R7),"0",R7-R6) -> 32 | T7: =S7*1.0557 -> 33.7824 | U7: =IF(ISBLANK(M7),"0",T7*11.05+216.666) -> 589.96152 | V7: 67192 | W7: =IF(ISBLANK(V7)," ",V7-V6) -> 20 | X7: =IF(ISBLANK(V7),"0 ",W7*284.345) -> 5686.9 | Y7: =X7*0.3442 -> 1957.431 | Z7: =IF(ISBLANK(V7),"0",1570*1546.86/12/30*0.65) -> 4384.9184 | AA7: =Y7+Z7 -> 6342.3494 | AB7: 6091784 | AC7: =IF(ISBLANK(AB7),"0 ",AB7-AB6) -> 6789 | AD7: 0.7492 | AE7: 333 | AF7: 13313933 | AG7: =IF(ISBLANK(AF7),"0",AF7-AF6) -> 4972 | AH7: =AG7*0.2 -> 994.4 | AI7: 6184539 | AJ7: =IF(ISBLANK(AI7),"0",AI7-AI6) -> 2166 | AK7: =AJ7*0.2 -> 433.2 | AL7: 120824 | AM7: =IF(ISBLANK(AL7),"0",AL7-AL6) -> 242 | AN7: =AM7*0.2 -> 48.4 | AO7: 6089 | AP7: =IF(ISBLANK(AO7),"0",AO7-AO6) -> 10 | AQ7: =AP7*7.84 -> 78.4 | AR7: 2758 | AS7: =IF(ISBLANK(AR7),"0",AR7-AR6) -> 1 | AT7: =AS7*7.84 -> 7.84 | AU7: 112 | AV7: =IF(ISBLANK(AU7),"0",AU7-AU6) -> 1 | AW7: =AV7*7.84 -> 7.84
A8: 45386 | B8: 18936943 | C8: =IF(ISBLANK(B8),"0",B8-B7) -> 7822 | D8: 19867680 | E8: =IF(ISBLANK(D8),"0",D8-D7) -> 6924 | F8: 452118 | G8: =IF(ISBLANK(F8),"0",F8-F7) -> 136 | H8: =C8+E8+G8 -> 14882 | I8: =H8*0.2 -> 2976.4 | J8: 78524 | K8: =IF(ISBLANK(J8),"0",J8-J7) -> 88 | L8: =K8*7.84 -> 689.92 | M8: 35386 | N8: =IF(ISBLANK(M8),"0",M8-M7) -> 17 | O8: 20256 | P8: =IF(ISBLANK(O8),"0",O8-O7) -> 15 | Q8: =N8+P8 -> 32 | R8: 51771 | S8: =IF(ISBLANK(R8),"0",R8-R7) -> 32 | T8: =S8*1.0557 -> 33.7824 | U8: =IF(ISBLANK(M8),"0",T8*11.05+216.666) -> 589.96152 | V8: 67213 | W8: =IF(ISBLANK(V8)," ",V8-V7) -> 21 | X8: =IF(ISBLANK(V8),"0 ",W8*284.345) -> 5971.245 | Y8: =X8*0.3442 -> 2055.3025 | Z8: =IF(ISBLANK(V8),"0",1570*1546.86/12/30*0.65) -> 4384.9184 | AA8: =Y8+Z8 -> 6440.2209 | AB8: 6098748 | AC8: =IF(ISBLANK(AB8),"0 ",AB8-AB7) -> 6964 | AD8: 0.6159 | AE8: 293 | AF8: 13318859 | AG8: =IF(ISBLANK(AF8),"0",AF8-AF7) -> 4926 | AH8: =AG8*0.2 -> 985.2 | AI8: 6186663 | AJ8: =IF(ISBLANK(AI8),"0",AI8-AI7) -> 2124 | AK8: =AJ8*0.2 -> 424.8 | AL8: 121065 | AM8: =IF(ISBLANK(AL8),"0",AL8-AL7) -> 241 | AN8: =AM8*0.2 -> 48.2 | AO8: 6098 | AP8: =IF(ISBLANK(AO8),"0",AO8-AO7) -> 9 | AQ8: =AP8*7.84 -> 70.56 | AR8: 2760 | AS8: =IF(ISBLANK(AR8),"0",AR8-AR7) -> 2 | AT8: =AS8*7.84 -> 15.68 | AU8: 113 | AV8: =IF(ISBLANK(AU8),"0",AU8-AU7) -> 1 | AW8: =AV8*7.84 -> 7.84
A9: 45387 | B9: 18944460 | C9: =IF(ISBLANK(B9),"0",B9-B8) -> 7517 | D9: 19874475 | E9: =IF(ISBLANK(D9),"0",D9-D8) -> 6795 | F9: 452254 | G9: =IF(ISBLANK(F9),"0",F9-F8) -> 136 | H9: =C9+E9+G9 -> 14448 | I9: =H9*0.2 -> 2889.6 | J9: 78630 | K9: =IF(ISBLANK(J9),"0",J9-J8) -> 106 | L9: =K9*7.84 -> 831.04 | M9: 35405 | N9: =IF(ISBLANK(M9),"0",M9-M8) -> 19 | O9: 20272 | P9: =IF(ISBLANK(O9),"0",O9-O8) -> 16 | Q9: =N9+P9 -> 35 | R9: 51805 | S9: =IF(ISBLANK(R9),"0",R9-R8) -> 34 | T9: =S9*1.0557 -> 35.8938 | U9: =IF(ISBLANK(M9),"0",T9*11.05+216.666) -> 613.29249 | V9: 67234 | W9: =IF(ISBLANK(V9)," ",V9-V8) -> 21 | X9: =IF(ISBLANK(V9),"0 ",W9*284.345) -> 5971.245 | Y9: =X9*0.3442 -> 2055.3025 | Z9: =IF(ISBLANK(V9),"0",1570*1546.86/12/30*0.65) -> 4384.9184 | AA9: =Y9+Z9 -> 6440.2209 | AB9: 6105361 | AC9: =IF(ISBLANK(AB9),"0 ",AB9-AB8) -> 6613 | AD9: 0.6 | AE9: 320 | AF9: 13323579 | AG9: =IF(ISBLANK(AF9),"0",AF9-AF8) -> 4720 | AH9: =AG9*0.2 -> 944 | AI9: 6188748 | AJ9: =IF(ISBLANK(AI9),"0",AI9-AI8) -> 2085 | AK9: =AJ9*0.2 -> 417 | AL9: 121298 | AM9: =IF(ISBLANK(AL9),"0",AL9-AL8) -> 233 | AN9: =AM9*0.2 -> 46.6 | AO9: 6107 | AP9: =IF(ISBLANK(AO9),"0",AO9-AO8) -> 9 | AQ9: =AP9*7.84 -> 70.56 | AR9: 2761 | AS9: =IF(ISBLANK(AR9),"0",AR9-AR8) -> 1 | AT9: =AS9*7.84 -> 7.84 | AU9: 114 | AV9: =IF(ISBLANK(AU9),"0",AU9-AU8) -> 1 | AW9: =AV9*7.84 -> 7.84
A10: 45388 | B10: 18952104 | C10: =IF(ISBLANK(B10),"0",B10-B9) -> 7644 | D10: 19881372 | E10: =IF(ISBLANK(D10),"0",D10-D9) -> 6897 | F10: 452391 | G10: =IF(ISBLANK(F10),"0",F10-F9) -> 137 | H10: =C10+E10+G10 -> 14678 | I10: =H10*0.2 -> 2935.6 | J10: 78711 | K10: =IF(ISBLANK(J10),"0",J10-J9) -> 81 | L10: =K10*7.84 -> 635.04 | M10: 35423 | N10: =IF(ISBLANK(M10),"0",M10-M9) -> 18 | O10: 20287 | P10: =IF(ISBLANK(O10),"0",O10-O9) -> 15 | Q10: =N10+P10 -> 33 | R10: 51838 | S10: =IF(ISBLANK(R10),"0",R10-R9) -> 33 | T10: =S10*1.0557 -> 34.8381 | U10: =IF(ISBLANK(M10),"0",T10*11.05+216.666) -> 601.62701 | V10: 67254 | W10: =IF(ISBLANK(V10)," ",V10-V9) -> 20 | X10: =IF(ISBLANK(V10),"0 ",W10*284.345) -> 5686.9 | Y10: =X10*0.3442 -> 1957.431 | Z10: =IF(ISBLANK(V10),"0",1570*1546.86/12/30*0.65) -> 4384.9184 | AA10: =Y10+Z10 -> 6342.3494 | AB10: 6111981 | AC10: =IF(ISBLANK(AB10),"0 ",AB10-AB9) -> 6620 | AD10: 0.4667 | AE10: 241 | AF10: 13327680 | AG10: =IF(ISBLANK(AF10),"0",AF10-AF9) -> 4101 | AH10: =AG10*0.2 -> 820.2 | AI10: 6190746 | AJ10: =IF(ISBLANK(AI10),"0",AI10-AI9) -> 1998 | AK10: =AJ10*0.2 -> 399.6 | AL10: 121524 | AM10: =IF(ISBLANK(AL10),"0",AL10-AL9) -> 226 | AN10: =AM10*0.2 -> 45.2 | AO10: 6115 | AP10: =IF(ISBLANK(AO10),"0",AO10-AO9) -> 8 | AQ10: =AP10*7.84 -> 62.72 | AR10: 2762 | AS10: =IF(ISBLANK(AR10),"0",AR10-AR9) -> 1 | AT10: =AS10*7.84 -> 7.84 | AU10: 115 | AV10: =IF(ISBLANK(AU10),"0",AU10-AU9) -> 1 | AW10: =AV10*7.84 -> 7.84
A11: 45389 | B11: 18959751 | C11: =IF(ISBLANK(B11),"0",B11-B10) -> 7647 | D11: 19888181 | E11: =IF(ISBLANK(D11),"0",D11-D10) -> 6809 | F11: 452528 | G11: =IF(ISBLANK(F11),"0",F11-F10) -> 137 | H11: =C11+E11+G11 -> 14593 | I11: =H11*0.2 -> 2918.6 | J11: 78793 | K11: =IF(ISBLANK(J11),"0",J11-J10) -> 82 | L11: =K11*7.84 -> 642.88 | M11: 35439 | N11: =IF(ISBLANK(M11),"0",M11-M10) -> 16 | O11: 20302 | P11: =IF(ISBLANK(O11),"0",O11-O10) -> 15 | Q11: =N11+P11 -> 31 | R11: 51867 | S11: =IF(ISBLANK(R11),"0",R11-R10) -> 29 | T11: =S11*1.0557 -> 30.6153 | U11: =IF(ISBLANK(M11),"0",T11*11.05+216.666) -> 554.96507 | V11: 67274 | W11: =IF(ISBLANK(V11)," ",V11-V10) -> 20 | X11: =IF(ISBLANK(V11),"0 ",W11*284.345) -> 5686.9 | Y11: =X11*0.3442 -> 1957.431 | Z11: =IF(ISBLANK(V11),"0",1570*1546.86/12/30*0.65) -> 4384.9184 | AA11: =Y11+Z11 -> 6342.3494 | AB11: 6118532 | AC11: =IF(ISBLANK(AB11),"0 ",AB11-AB10) -> 6551 | AD11: 0.5143 | AE11: 281 | AF11: 13331777 | AG11: =IF(ISBLANK(AF11),"0",AF11-AF10) -> 4097 | AH11: =AG11*0.2 -> 819.4 | AI11: 6192750 | AJ11: =IF(ISBLANK(AI11),"0",AI11-AI10) -> 2004 | AK11: =AJ11*0.2 -> 400.8 | AL11: 121743 | AM11: =IF(ISBLANK(AL11),"0",AL11-AL10) -> 219 | AN11: =AM11*0.2 -> 43.8 | AO11: 6124 | AP11: =IF(ISBLANK(AO11),"0",AO11-AO10) -> 9 | AQ11: =AP11*7.84 -> 70.56 | AR11: 2763 | AS11: =IF(ISBLANK(AR11),"0",AR11-AR10) -> 1 | AT11: =AS11*7.84 -> 7.84 | AU11: 115 | AV11: =IF(ISBLANK(AU11),"0",AU11-AU10) -> 0 | AW11: =AV11*7.84 -> 0
A12: 45390 | B12: 18967265 | C12: =IF(ISBLANK(B12),"0",B12-B11) -> 7514 | D12: 19894813 | E12: =IF(ISBLANK(D12),"0",D12-D11) -> 6632 | F12: 452664 | G12: =IF(ISBLANK(F12),"0",F12-F11) -> 136 | H12: =C12+E12+G12 -> 14282 | I12: =H12*0.2 -> 2856.4 | J12: 78845 | K12: =IF(ISBLANK(J12),"0",J12-J11) -> 52 | L12: =K12*7.84 -> 407.68 | M12: 35457 | N12: =IF(ISBLANK(M12),"0",M12-M11) -> 18 | O12: 20315 | P12: =IF(ISBLANK(O12),"0",O12-O11) -> 13 | Q12: =N12+P12 -> 31 | R12: 51897 | S12: =IF(ISBLANK(R12),"0",R12-R11) -> 30 | T12: =S12*1.0557 -> 31.671 | U12: =IF(ISBLANK(M12),"0",T12*11.05+216.666) -> 566.63055 | V12: 67294 | W12: =IF(ISBLANK(V12)," ",V12-V11) -> 20 | X12: =IF(ISBLANK(V12),"0 ",W12*284.345) -> 5686.9 | Y12: =X12*0.3442 -> 1957.431 | Z12: =IF(ISBLANK(V12),"0",1570*1546.86/12/30*0.65) -> 4384.9184 | AA12: =Y12+Z12 -> 6342.3494 | AB12: 6125374 | AC12: =IF(ISBLANK(AB12),"0 ",AB12-AB11) -> 6842 | AD12: 0.5238 | AE12: 298 | AF12: 13335771 | AG12: =IF(ISBLANK(AF12),"0",AF12-AF11) -> 3994 | AH12: =AG12*0.2 -> 798.8 | AI12: 6194674 | AJ12: =IF(ISBLANK(AI12),"0",AI12-AI11) -> 1924 | AK12: =AJ12*0.2 -> 384.8 | AL12: 121969 | AM12: =IF(ISBLANK(AL12),"0",AL12-AL11) -> 226 | AN12: =AM12*0.2 -> 45.2 | AO12: 6132 | AP12: =IF(ISBLANK(AO12),"0",AO12-AO11) -> 8 | AQ12: =AP12*7.84 -> 62.72 | AR12: 2765 | AS12: =IF(ISBLANK(AR12),"0",AR12-AR11) -> 2 | AT12: =AS12*7.84 -> 15.68 | AU12: 116 | AV12: =IF(ISBLANK(AU12),"0",AU12-AU11) -> 1 | AW12: =AV12*7.84 -> 7.84
A13: 45391 | B13: 18975145 | C13: =IF(ISBLANK(B13),"0",B13-B12) -> 7880 | D13: 19901654 | E13: =IF(ISBLANK(D13),"0",D13-D12) -> 6841 | F13: 452800 | G13: =IF(ISBLANK(F13),"0",F13-F12) -> 136 | H13: =C13+E13+G13 -> 14857 | I13: =H13*0.2 -> 2971.4 | J13: 78920 | K13: =IF(ISBLANK(J13),"0",J13-J12) -> 75 | L13: =K13*7.84 -> 588 | M13: 35473 | N13: =IF(ISBLANK(M13),"0",M13-M12) -> 16 | O13: 20328 | P13: =IF(ISBLANK(O13),"0",O13-O12) -> 13 | Q13: =N13+P13 -> 29 | R13: 51925 | S13: =IF(ISBLANK(R13),"0",R13-R12) -> 28 | T13: =S13*1.0557 -> 29.5596 | U13: =IF(ISBLANK(M13),"0",T13*11.05+216.666) -> 543.29958 | V13: 67316 | W13: =IF(ISBLANK(V13)," ",V13-V12) -> 22 | X13: =IF(ISBLANK(V13),"0 ",W13*284.345) -> 6255.59 | Y13: =X13*0.3442 -> 2153.1741 | Z13: =IF(ISBLANK(V13),"0",1570*1546.86/12/30*0.65) -> 4384.9184 | AA13: =Y13+Z13 -> 6538.0925 | AB13: 6132492 | AC13: =IF(ISBLANK(AB13),"0 ",AB13-AB12) -> 7118 | AD13: 0.5619 | AE13: 323 | AF13: 13339881 | AG13: =IF(ISBLANK(AF13),"0",AF13-AF12) -> 4110 | AH13: =AG13*0.2 -> 822 | AI13: 6196661 | AJ13: =IF(ISBLANK(AI13),"0",AI13-AI12) -> 1987 | AK13: =AJ13*0.2 -> 397.4 | AL13: 122213 | AM13: =IF(ISBLANK(AL13),"0",AL13-AL12) -> 244 | AN13: =AM13*0.2 -> 48.8 | AO13: 6142 | AP13: =IF(ISBLANK(AO13),"0",AO13-AO12) -> 10 | AQ13: =AP13*7.84 -> 78.4 | AR13: 2766 | AS13: =IF(ISBLANK(AR13),"0",AR13-AR12) -> 1 | AT13: =AS13*7.84 -> 7.84 | AU13: 117 | AV13: =IF(ISBLANK(AU13),"0",AU13-AU12) -> 1 | AW13: =AV13*7.84 -> 7.84
A14: 45392 | B14: 18982798 | C14: =IF(ISBLANK(B14),"0",B14-B13) -> 7653 | D14: 19908376 | E14: =IF(ISBLANK(D14),"0",D14-D13) -> 6722 | F14: 452938 | G14: =IF(ISBLANK(F14),"0",F14-F13) -> 138 | H14: =C14+E14+G14 -> 14513 | I14: =H14*0.2 -> 2902.6 | J14: 79013 | K14: =IF(ISBLANK(J14),"0",J14-J13) -> 93 | L14: =K14*7.84 -> 729.12 | M14: 35490 | N14: =IF(ISBLANK(M14),"0",M14-M13) -> 17 | O14: 20340 | P14: =IF(ISBLANK(O14),"0",O14-O13) -> 12 | Q14: =N14+P14 -> 29 | R14: 51953 | S14: =IF(ISBLANK(R14),"0",R14-R13) -> 28 | T14: =S14*1.0557 -> 29.5596 | U14: =IF(ISBLANK(M14),"0",T14*11.05+216.666) -> 543.29958 | V14: 67340 | W14: =IF(ISBLANK(V14)," ",V14-V13) -> 24 | X14: =IF(ISBLANK(V14),"0 ",W14*284.345) -> 6824.28 | Y14: =X14*0.3442 -> 2348.9172 | Z14: =IF(ISBLANK(V14),"0",1570*1546.86/12/30*0.65) -> 4384.9184 | AA14: =Y14+Z14 -> 6733.8356 | AB14: 6139923 | AC14: =IF(ISBLANK(AB14),"0 ",AB14-AB13) -> 7431 | AD14: 0.6667 | AE14: 372 | AF14: 13343827 | AG14: =IF(ISBLANK(AF14),"0",AF14-AF13) -> 3946 | AH14: =AG14*0.2 -> 789.2 | AI14: 6198638 | AJ14: =IF(ISBLANK(AI14),"0",AI14-AI13) -> 1977 | AK14: =AJ14*0.2 -> 395.4 | AL14: 122486 | AM14: =IF(ISBLANK(AL14),"0",AL14-AL13) -> 273 | AN14: =AM14*0.2 -> 54.6 | AO14: 6150 | AP14: =IF(ISBLANK(AO14),"0",AO14-AO13) -> 8 | AQ14: =AP14*7.84 -> 62.72 | AR14: 2766 | AS14: =IF(ISBLANK(AR14),"0",AR14-AR13) -> 0 | AT14: =AS14*7.84 -> 0 | AU14: 118 | AV14: =IF(ISBLANK(AU14),"0",AU14-AU13) -> 1 | AW14: =AV14*7.84 -> 7.84
A15: 45393 | B15: 18990741 | C15: =IF(ISBLANK(B15),"0",B15-B14) -> 7943 | D15: 19915245 | E15: =IF(ISBLANK(D15),"0",D15-D14) -> 6869 | F15: 453047 | G15: =IF(ISBLANK(F15),"0",F15-F14) -> 109 | H15: =C15+E15+G15 -> 14921 | I15: =H15*0.2 -> 2984.2 | J15: 79115 | K15: =IF(ISBLANK(J15),"0",J15-J14) -> 102 | L15: =K15*7.84 -> 799.68 | M15: 35507 | N15: =IF(ISBLANK(M15),"0",M15-M14) -> 17 | O15: 20351 | P15: =IF(ISBLANK(O15),"0",O15-O14) -> 11 | Q15: =N15+P15 -> 28 | R15: 51982 | S15: =IF(ISBLANK(R15),"0",R15-R14) -> 29 | T15: =S15*1.0557 -> 30.6153 | U15: =IF(ISBLANK(M15),"0",T15*11.05+216.666) -> 554.96507 | V15: 67365 | W15: =IF(ISBLANK(V15)," ",V15-V14) -> 25 | X15: =IF(ISBLANK(V15),"0 ",W15*284.345) -> 7108.625 | Y15: =X15*0.3442 -> 2446.7887 | Z15: =IF(ISBLANK(V15),"0",1570*1546.86/12/30*0.65) -> 4384.9184 | AA15: =Y15+Z15 -> 6831.7071 | AB15: 6148245 | AC15: =IF(ISBLANK(AB15),"0 ",AB15-AB14) -> 8322 | AD15: 0.8698 | AE15: 480 | AF15: 13347892 | AG15: =IF(ISBLANK(AF15),"0",AF15-AF14) -> 4065 | AH15: =AG15*0.2 -> 813 | AI15: 6200742 | AJ15: =IF(ISBLANK(AI15),"0",AI15-AI14) -> 2104 | AK15: =AJ15*0.2 -> 420.8 | AL15: 122811 | AM15: =IF(ISBLANK(AL15),"0",AL15-AL14) -> 325 | AN15: =AM15*0.2 -> 65 | AO15: 6157 | AP15: =IF(ISBLANK(AO15),"0",AO15-AO14) -> 7 | AQ15: =AP15*7.84 -> 54.88 | AR15: 2768 | AS15: =IF(ISBLANK(AR15),"0",AR15-AR14) -> 2 | AT15: =AS15*7.84 -> 15.68 | AU15: 119 | AV15: =IF(ISBLANK(AU15),"0",AU15-AU14) -> 1 | AW15: =AV15*7.84 -> 7.84
A16: 45394 | B16: 18998703 | C16: =IF(ISBLANK(B16),"0",B16-B15) -> 7962 | D16: 19922172 | E16: =IF(ISBLANK(D16),"0",D16-D15) -> 6927 | F16: 453183 | G16: =IF(ISBLANK(F16),"0",F16-F15) -> 136 | H16: =C16+E16+G16 -> 15025 | I16: =H16*0.2 -> 3005 | J16: 79228 | K16: =IF(ISBLANK(J16),"0",J16-J15) -> 113 | L16: =K16*7.84 -> 885.92 | M16: 35525 | N16: =IF(ISBLANK(M16),"0",M16-M15) -> 18 | O16: 20365 | P16: =IF(ISBLANK(O16),"0",O16-O15) -> 14 | Q16: =N16+P16 -> 32 | R16: 52013 | S16: =IF(ISBLANK(R16),"0",R16-R15) -> 31 | T16: =S16*1.0557 -> 32.7267 | U16: =IF(ISBLANK(M16),"0",T16*11.05+216.666) -> 578.29604 | V16: 67391 | W16: =IF(ISBLANK(V16)," ",V16-V15) -> 26 | X16: =IF(ISBLANK(V16),"0 ",W16*284.345) -> 7392.97 | Y16: =X16*0.3442 -> 2544.6603 | Z16: =IF(ISBLANK(V16),"0",1570*1546.86/12/30*0.65) -> 4384.9184 | AA16: =Y16+Z16 -> 6929.5787 | AB16: 6156693 | AC16: =IF(ISBLANK(AB16),"0 ",AB16-AB15) -> 8448 | AD16: 0.7333 | AE16: 403 | AF16: 13352072 | AG16: =IF(ISBLANK(AF16),"0",AF16-AF15) -> 4180 | AH16: =AG16*0.2 -> 836 | AI16: 6202839 | AJ16: =IF(ISBLANK(AI16),"0",AI16-AI15) -> 2097 | AK16: =AJ16*0.2 -> 419.4 | AL16: 123157 | AM16: =IF(ISBLANK(AL16),"0",AL16-AL15) -> 346 | AN16: =AM16*0.2 -> 69.2 | AO16: 6166 | AP16: =IF(ISBLANK(AO16),"0",AO16-AO15) -> 9 | AQ16: =AP16*7.84 -> 70.56 | AR16: 2770 | AS16: =IF(ISBLANK(AR16),"0",AR16-AR15) -> 2 | AT16: =AS16*7.84 -> 15.68 | AU16: 120 | AV16: =IF(ISBLANK(AU16),"0",AU16-AU15) -> 1 | AW16: =AV16*7.84 -> 7.84
A17: 45395 | B17: 19006284 | C17: =IF(ISBLANK(B17),"0",B17-B16) -> 7581 | D17: 19928872 | E17: =IF(ISBLANK(D17),"0",D17-D16) -> 6700 | F17: 453294 | G17: =IF(ISBLANK(F17),"0",F17-F16) -> 111 | H17: =C17+E17+G17 -> 14392 | I17: =H17*0.2 -> 2878.4 | J17: 79330 | K17: =IF(ISBLANK(J17),"0",J17-J16) -> 102 | L17: =K17*7.84 -> 799.68 | M17: 35544 | N17: =IF(ISBLANK(M17),"0",M17-M16) -> 19 | O17: 20377 | P17: =IF(ISBLANK(O17),"0",O17-O16) -> 12 | Q17: =N17+P17 -> 31 | R17: 52045 | S17: =IF(ISBLANK(R17),"0",R17-R16) -> 32 | T17: =S17*1.0557 -> 33.7824 | U17: =IF(ISBLANK(M17),"0",T17*11.05+216.666) -> 589.96152 | V17: 67413 | W17: =IF(ISBLANK(V17)," ",V17-V16) -> 22 | X17: =IF(ISBLANK(V17),"0 ",W17*284.345) -> 6255.59 | Y17: =X17*0.3442 -> 2153.1741 | Z17: =IF(ISBLANK(V17),"0",1570*1546.86/12/30*0.65) -> 4384.9184 | AA17: =Y17+Z17 -> 6538.0925 | AB17: 6164062 | AC17: =IF(ISBLANK(AB17),"0 ",AB17-AB16) -> 7369 | AD17: 0.4317 | AE17: 217 | AF17: 13356161 | AG17: =IF(ISBLANK(AF17),"0",AF17-AF16) -> 4089 | AH17: =AG17*0.2 -> 817.8 | AI17: 6204852 | AJ17: =IF(ISBLANK(AI17),"0",AI17-AI16) -> 2013 | AK17: =AJ17*0.2 -> 402.6 | AL17: 123417 | AM17: =IF(ISBLANK(AL17),"0",AL17-AL16) -> 260 | AN17: =AM17*0.2 -> 52 | AO17: 6175 | AP17: =IF(ISBLANK(AO17),"0",AO17-AO16) -> 9 | AQ17: =AP17*7.84 -> 70.56 | AR17: 2771 | AS17: =IF(ISBLANK(AR17),"0",AR17-AR16) -> 1 | AT17: =AS17*7.84 -> 7.84 | AU17: 121 | AV17: =IF(ISBLANK(AU17),"0",AU17-AU16) -> 1 | AW17: =AV17*7.84 -> 7.84
... A34: 45412 | B34: 19141379 | C34: =IF(ISBLANK(B34),"0",B34-B33) -> 8103 | D34: 20044452 | E34: =IF(ISBLANK(D34),"0",D34-D33) -> 6915 | F34: 455471 | G34: =IF(ISBLANK(F34),"0",F34-F33) -> 121 | H34: =C34+E34+G34 -> 15139 | I34: =H34*0.2 -> 3027.8 | J34: 81007 | K34: =IF(ISBLANK(J34),"0",J34-J33) -> 105 | L34: =K34*7.84 -> 823.2 | M34: 35855 | N34: =IF(ISBLANK(M34),"0",M34-M33) -> 20 | O34: 20612 | P34: =IF(ISBLANK(O34),"0",O34-O33) -> 14 | Q34: =N34+P34 -> 34 | R34: 52577 | S34: =IF(ISBLANK(R34),"0",R34-R33) -> 33 | T34: =S34*1.0557 -> 34.8381 | U34: =IF(ISBLANK(M34),"0",T34*11.05+216.666) -> 601.62701 | V34: 67835 | W34: =IF(ISBLANK(V34)," ",V34-V33) -> 31 | X34: =IF(ISBLANK(V34),"0 ",W34*284.345) -> 8814.695 | Y34: =X34*0.3442 -> 3034.018 | Z34: =IF(ISBLANK(V34),"0",1570*1546.86/12/30*0.65) -> 4384.9184 | AA34: =Y34+Z34 -> 7418.9364 | AB34: 6306651 | AC34: =IF(ISBLANK(AB34),"0 ",AB34-AB33) -> 10444 | AD34: 1 | AE34: 355 | AF34: 13441394 | AG34: =IF(ISBLANK(AF34),"0",AF34-AF33) -> 5658 | AH34: =AG34*0.2 -> 1131.6 | AI34: 6241763 | AJ34: =IF(ISBLANK(AI34),"0",AI34-AI33) -> 2255 | AK34: =AJ34*0.2 -> 451 | AL34: 128704 | AM34: =IF(ISBLANK(AL34),"0",AL34-AL33) -> 430 | AN34: =AM34*0.2 -> 86 | AO34: 6340 | AP34: =IF(ISBLANK(AO34),"0",AO34-AO33) -> 12 | AQ34: =AP34*7.84 -> 94.08 | AR34: 2791 | AS34: =IF(ISBLANK(AR34),"0",AR34-AR33) -> 1 | AT34: =AS34*7.84 -> 7.84 | AU34: 137 | AV34: =IF(ISBLANK(AU34),"0",AU34-AU33) -> 1 | AW34: =AV34*7.84 -> 7.84
C35: =SUM(C5:C34) -> 235872 | E35: =SUM(E5:E34) -> 204519 | G35: =SUM(G5:G34) -> 3892 | H35: =SUM(H5:H34) -> 444283 | I35: =H35*0.2 -> 88856.6 | K35: =SUM(K5:K34) -> 2856 | L35: =K35*7.84 -> 22391.04 | N35: =SUM(N5:N34) -> 538 | P35: =SUM(P5:P34) -> 418 | Q35: =SUM(Q5:Q34) -> 956 | S35: =SUM(S5:S34) -> 933 | T35: =SUM(T5:T34) -> 984.9681 | U35: =SUM(U5:U34) -> 17383.878 | W35: =SUM(W5:W34) -> 702 | X35: =SUM(X5:X34) -> 199610.19 | Y35: =SUM(Y5:Y34) -> 68705.827 | Z35: =SUM(Z5:Z34) -> 131547.55 | AA35: =SUM(AA5:AA34) -> 200253.38 | AC35: =SUM(AC5:AC34) -> 234673 | AD35: =AVERAGE(AD5:AD34) -> 0.76201 | AE35: =SUM(AE5:AE34) -> 10203 | AG35: =SUM(AG5:AG34) -> 142323 | AH35: =SUM(AH5:AH34) -> 28464.6 | AJ35: =SUM(AJ5:AJ34) -> 63746 | AK35: =SUM(AK5:AK34) -> 12749.2 | AM35: =SUM(AM5:AM34) -> 8572 | AN35: =SUM(AN5:AN34) -> 1714.4 | AP35: =SUM(AP5:AP34) -> 279 | AQ35: =SUM(AQ5:AQ34) -> 2187.36 | AS35: =SUM(AS5:AS34) -> 36 | AT35: =SUM(AT5:AT34) -> 282.24 | AV35: =SUM(AV5:AV34) -> 28 | AW35: =SUM(AW5:AW34) -> 219.52
V36: AVT Charges should be Zero in the DC invoice - Please notify if not
B37: Electricity | D37: AED | G37: KW | J37: Water | L37: AED | M37: M3 | O37: Gas | R37: AED | T37: M3 | V37: Chilled Water | X37: AED | Z37: Ton Hour | AG37: =131547.55*4 -> 526190.2 | AH37: CHW Fixed Charges YTD 2024
B38: Actual April 2024 | D38: =I35 -> 88856.6 | G38: =D38/0.2 -> 444283 | J38: =B38 -> Actual April 2024 | L38: =L35 -> 22391.04 | M38: =K35 -> 2856 | O38: =B38 -> Actual April 2024 | R38: =U35 -> 17383.878 | T38: =T35 -> 984.9681 | V38: =B38 -> Actual April 2024 | X38: =AA35 -> 200253.38 | Z38: =X35 -> 199610.19 | AD38: =AC35 -> 234673 | AE38: =AD38-X35 -> 35062.81 | AG38: =126488.42*4 -> 505953.68 | AH38: CHW Fixed Charges YTD 2023
B39: Budget April 2024 | D39: 96390 | G39: =D39/0.2 -> 481950 | J39: =B39 -> Budget April 2024 | L39: 27770.25 | M39: =L39/7.84 -> 3542.1237 | O39: =B39 -> Budget April 2024 | R39: 18465.23 | T39: =(R39-6500)/11.05 -> 1082.8262 | V39: =B39 -> Budget April 2024 | X39: 190126.08 | Z39: =AG39/0.3442 -> 170187.48 | AG39: =X39-131547.55 -> 58578.53 | AH39: CHW Consumption Charges (Budgeted 2024 MTD)
B40: Actual April 2023 | D40: 88634.8 | G40: =D40/0.2 -> 443174 | J40: =B40 -> Actual April 2023 | L40: 21834.4 | M40: =L40/7.84 -> 2785 | O40: =B40 -> Actual April 2023 | R40: 16226.35 | T40: =(R40-6500)/11.05 -> 880.21267 | V40: =B40 -> Actual April 2023 | X40: 182094.27 | Z40: =AG40/0.3435 -> 161880.2 | AG40: =X40-126488.42 -> 55605.85 | AH40: CHW Consumption Charges (Actual 2023 MTD)
B41: Actual YTD 2024 | D41: =D38+261444.2 -> 350300.8 | G41: =D41/0.2 -> 1751504 | J41: =B41 -> Actual YTD 2024 | L41: =L38+72974.72 -> 95365.76 | M41: =L41/7.84 -> 12164 | O41: =B41 -> Actual YTD 2024 | R41: =R38+53103.56 -> 70487.438 | T41: =(R41-6500*4)/11.05 -> 4026.0124 | V41: =B41 -> Actual YTD 2024 | X41: =X38+551946.11 -> 752199.49 | Z41: =AG41/0.3442 -> 656621.99 | AG41: =X41-AG37 -> 226009.29 | AH41: CHW Consumption Charges (Actual 2024 YTD)
B42: Budget YTD 2024 | D42: =D39+286618.5 -> 383008.5 | G42: =D42/0.2 -> 1915042.5 | J42: =B42 -> Budget YTD 2024 | L42: =L39+73011.82 -> 100782.07 | M42: =L42/7.84 -> 12854.856 | O42: =B42 -> Budget YTD 2024 | R42: =R39+55046.56 -> 73511.79 | T42: =(R42-6500*4)/11.05 -> 4299.7095 | V42: =B42 -> Budget YTD 2024 | X42: =X39+558585.27 -> 748711.35 | Z42: =AG42/0.3442 -> 646487.94 | AG42: =X42-AG37 -> 222521.15 | AH42: CHW Consumption Charges (Budgeted 2024 YTD)
B43: Actual YTD 2023 | D43: 369445.4 | G43: =D43/0.2 -> 1847227 | J43: =B43 -> Actual YTD 2023 | L43: 84875.84 | M43: =L43/7.84 -> 10826 | O43: =B43 -> Actual YTD 2023 | R43: 64267.32 | T43: =(R43-6500*4)/11.05 -> 3463.1059 | V43: =B43 -> Actual YTD 2023 | X43: 712572.77 | Z43: =AG43/0.3435 -> 601511.18 | AG43: =X43-AG38 -> 206619.09 | AH43: CHW Consumption Charges (Actual 2023 YTD)
H44: 45383 | I44: =TODAY() -> 45798 | J44: 30
A45: Monthly Budget | D45: Daily Budget | I45: MTD Average | N45: MTD Budget | U45: MTD Actual | Z45: YTD Budget | AD45: YTD Actual | AG45: Savings | AH45: Exceeds
A46: Electricity | B46: =D39 -> 96390 | D46: Electricity | G46: =B46/30 -> 3213 | I46: Electricity | L46: =I35/J44 -> 2961.8867 | N46: Electricity | R46: =G46*J44 -> 96390 | U46: Electricity | W46: =I35 -> 88856.6 | Y46: =R46-W46 -> 7533.4 | Z46: Electricity | AB46: =R46+286618.5 -> 383008.5 | AD46: Electricity | AF46: =W46+261444.2 -> 350300.8 | AG46: =AB46-AF46 -> 32707.7 | AH46: =AF46-AB46 -> -32707.7
A47: Water | B47: =L39 -> 27770.25 | D47: Water | G47: =B47/30 -> 925.675 | I47: Water | L47: =L35/J44 -> 746.368 | N47: Water | R47: =G47*J44 -> 27770.25 | U47: Water | W47: =L35 -> 22391.04 | Y47: =R47-W47 -> 5379.21 | Z47: Water | AB47: =R47+73011.82 -> 100782.07 | AD47: Water | AF47: =W47+72974.72 -> 95365.76 | AG47: =AB47-AF47 -> 5416.31 | AH47: =AF47-AB47 -> -5416.31
A48: Gas | B48: =R39 -> 18465.23 | D48: Gas | G48: =B48/30 -> 615.50767 | I48: Gas | L48: =U35/J44 -> 579.46258 | N48: Gas | R48: =G48*J44 -> 18465.23 | U48: Gas | W48: =U35 -> 17383.878 | Y48: =R48-W48 -> 1081.3525 | Z48: Gas | AB48: =R48+55046.56 -> 73511.79 | AD48: Gas | AF48: =W48+53103.56 -> 70487.438 | AG48: =AB48-AF48 -> 3024.3525 | AH48: =AF48-AB48 -> -3024.3525
A49: Chilled Water | B49: =X39 -> 190126.08 | D49: Chilled Water | G49: =B49/30 -> 6337.536 | I49: Chilled Water | L49: =AA35/J44 -> 6675.1127 | N49: Chilled Water | R49: =G49*J44 -> 190126.08 | U49: Chilled Water | W49: =AA35 -> 200253.38 | Y49: =R49-W49 -> -10127.3 | Z49: Chilled Water | AB49: =R49+558585.27 -> 748711.35 | AD49: Chilled Water | AF49: =W49+551946.11 -> 752199.49 | AG49: =AB49-AF49 -> -3488.1399 | AH49: =AF49-AB49 -> 3488.1399
B50: =SUM(B46:B49) -> 332751.56 | R50: =SUM(R46:S49) -> 332751.56 | W50: =SUM(W46:X49) -> 328884.9 | Y50: =R50-W50 -> 3866.6626 | AA50: Total Energy cost | AB50: =SUM(AB46:AB49) -> 1306013.7 | AF50: =SUM(AF46:AF49) -> 1268353.5 | AG50: =AB50-AF50 -> 37660.223
B51: =B50*X51 -> 3866.6626 | X51: =1-(W50/R50) -> 0.011620269 | AF51: =1-(AF50/AB50) -> 0.028836009
A53: Actual Last Year | D53: Average Daily Consumption Last Year | I53: MTD Average Last Year | N53: MTD Actual | U53: MTD Actual Vs Last Year | Z53: MTD Fcst | AA53: YTD Fcst | AD53: MTD Saving Fcst Vs LY | AE53: YTD Saving Fcst Vs LY
A54: Electricity | B54: =D40 -> 88634.8 | D54: Electricity | G54: =B54/30 -> 2954.4933 | I54: Electricity | L54: =G54*J44 -> 88634.8 | N54: Electricity | R54: =W46 -> 88856.6 | U54: Electricity | W54: =L54-R54 -> -221.8 | Z54: =L46*30 -> 88856.6 | AA54: =Z54+261444.2 -> 350300.8 | AD54: =D40-Z54 -> -221.8 | AE54: =D43-AA54 -> 19144.6
A55: Water | B55: =L40 -> 21834.4 | D55: Water | G55: =B55/30 -> 727.81333 | I55: Water | L55: =G55*J44 -> 21834.4 | N55: Water | R55: =W47 -> 22391.04 | U55: Water | W55: =L55-R55 -> -556.64 | Z55: =L47*30 -> 22391.04 | AA55: =Z55+72974.72 -> 95365.76 | AD55: =L40-Z55 -> -556.64 | AE55: =L43-AA55 -> -10489.92
A56: Gas | B56: =R40 -> 16226.35 | D56: Gas | G56: =B56/30 -> 540.87833 | I56: Gas | L56: =G56*J44 -> 16226.35 | N56: Gas | R56: =W48 -> 17383.878 | U56: Gas | W56: =L56-R56 -> -1157.5275 | Z56: =L48*30 -> 17383.878 | AA56: =Z56+53103.56 -> 70487.438 | AD56: =R40-Z56 -> -1157.5275 | AE56: =R43-AA56 -> -6220.1175
A57: Chilled Water | B57: =X40 -> 182094.27 | D57: Chilled Water | G57: =B57/30 -> 6069.809 | I57: Chilled Water | L57: =G57*J44 -> 182094.27 | N57: Chilled Water | R57: =W49 -> 200253.38 | U57: Chilled Water | W57: =L57-R57 -> -18159.11 | Z57: =L49*30 -> 200253.38 | AA57: =Z57+551946.11 -> 752199.49 | AD57: =X40-Z57 -> -18159.11 | AE57: =Z43-AA57 -> -150688.31
...
