Workbook

Sheet TOTAL
A1: Site Name | B1: Day | C1: Month | D1: Year | E1: Total Electricity Kwh | F1: Electricity Tariff ($/Kwh) | G1: LPG (Liters) | H1: LPG $/Liters | I1: Water Utility Supply (m3) m3 | J1: Water Utility Supply (m3) $/m3 | K1: District Energy Cooling RTH | L1: District Energy Cooling $/RTH | M1: Room Nights | N1: Total Guests
A2: Amwaj Rotana - Jumeirah Beach | B2: 1 | C2: 5 | D2: 2025 | E2: ='MTD Utility Sheet'!G4/0.439 -> 15625.923 | F2: 0.439 | G2: =('MTD Utility Sheet'!I4/1.82)/0.5 -> 536.8022 | H2: 1.75 | I2: ='MTD Utility Sheet'!H4/12.38 -> 282.65913 | J2: 12.38 | K2: =IF(('MTD Utility Sheet'!F4-2866)<0,"0",('MTD Utility Sheet'!F4-2866)/(0.568+0.075)) -> 9335.21 | L2: ='MTD Utility Sheet'!F4/K2 -> 0.9500097 | M2: ='MTD Utility Sheet'!B4*301 -> 292.9934
A3: Amwaj Rotana - Jumeirah Beach | B3: =B2+1 -> 2 | C3: 5 | D3: 2025 | E3: ='MTD Utility Sheet'!G5/0.439 -> 15137.608 | F3: 0.439 | G3: =('MTD Utility Sheet'!I5/1.82)/0.5 -> 536.35165 | H3: 1.75 | I3: ='MTD Utility Sheet'!H5/12.38 -> 269.75767 | J3: 12.38 | K3: =IF(('MTD Utility Sheet'!F5-2866)<0,"0",('MTD Utility Sheet'!F5-2866)/(0.568+0.075)) -> 9463.1726 | L3: ='MTD Utility Sheet'!F5/K3 -> 0.94585826 | M3: ='MTD Utility Sheet'!B5*301 -> 299.0134
A4: Amwaj Rotana - Jumeirah Beach | B4: =B3+1 -> 3 | C4: 5 | D4: 2025 | E4: ='MTD Utility Sheet'!G6/0.439 -> 16114.214 | F4: 0.439 | G4: =('MTD Utility Sheet'!I6/1.82)/0.5 -> 634.3956 | H4: 1.75 | I4: ='MTD Utility Sheet'!H6/12.38 -> 274.44911 | J4: 12.38 | K4: =IF(('MTD Utility Sheet'!F6-2866)<0,"0",('MTD Utility Sheet'!F6-2866)/(0.568+0.075)) -> 9446.112 | L4: ='MTD Utility Sheet'!F6/K4 -> 0.94640525 | M4: ='MTD Utility Sheet'!B6*301 -> 297.99
A5: Amwaj Rotana - Jumeirah Beach | B5: =B4+1 -> 4 | C5: 5 | D5: 2025 | E5: ='MTD Utility Sheet'!G7/0.439 -> 15625.923 | F5: 0.439 | G5: =('MTD Utility Sheet'!I7/1.82)/0.5 -> 585.6044 | H5: 1.75 | I5: ='MTD Utility Sheet'!H7/12.38 -> 277.96769 | J5: 12.38 | K5: =IF(('MTD Utility Sheet'!F7-2866)<0,"0",('MTD Utility Sheet'!F7-2866)/(0.568+0.075)) -> 8649.9222 | L5: ='MTD Utility Sheet'!F7/K5 -> 0.97433246 | M5: ='MTD Utility Sheet'!B7*301 -> 301
A6: Amwaj Rotana - Jumeirah Beach | B6: =B5+1 -> 5 | C6: 5 | D6: 2025 | E6: ='MTD Utility Sheet'!G8/0.439 -> 15625.923 | F6: 0.439 | G6: =('MTD Utility Sheet'!I8/1.82)/0.5 -> 585.6044 | H6: 1.75 | I6: ='MTD Utility Sheet'!H8/12.38 -> 274.44911 | J6: 12.38 | K6: =IF(('MTD Utility Sheet'!F8-2866)<0,"0",('MTD Utility Sheet'!F8-2866)/(0.568+0.075)) -> 8692.5816 | L6: ='MTD Utility Sheet'!F8/K6 -> 0.97270642 | M6: ='MTD Utility Sheet'!B8*301 -> 274.9936
A7: Amwaj Rotana - Jumeirah Beach | B7: =B6+1 -> 6 | C7: 5 | D7: 2025 | E7: ='MTD Utility Sheet'!G9/0.439 -> 16114.214 | F7: 0.439 | G7: =('MTD Utility Sheet'!I9/1.82)/0.5 -> 536.8022 | H7: 1.75 | I7: ='MTD Utility Sheet'!H9/12.38 -> 254.5105 | J7: 12.38 | K7: =IF(('MTD Utility Sheet'!F9-2866)<0,"0",('MTD Utility Sheet'!F9-2866)/(0.568+0.075)) -> 10191.104 | L7: ='MTD Utility Sheet'!F9/K7 -> 0.92422566 | M7: ='MTD Utility Sheet'!B9*301 -> 296.9666
A8: Amwaj Rotana - Jumeirah Beach | B8: =B7+1 -> 7 | C8: 5 | D8: 2025 | E8: ='MTD Utility Sheet'!G10/0.439 -> 15137.608 | F8: 0.439 | G8: =('MTD Utility Sheet'!I10/1.82)/0.5 -> 536.35165 | H8: 1.75 | I8: ='MTD Utility Sheet'!H10/12.38 -> 263.89338 | J8: 12.38 | K8: =IF(('MTD Utility Sheet'!F10-2866)<0,"0",('MTD Utility Sheet'!F10-2866)/(0.568+0.075)) -> 8922.9082 | L8: ='MTD Utility Sheet'!F10/K8 -> 0.96419573 | M8: ='MTD Utility Sheet'!B10*301 -> 292.0001
A9: Amwaj Rotana - Jumeirah Beach | B9: =B8+1 -> 8 | C9: 5 | D9: 2025 | E9: ='MTD Utility Sheet'!G11/0.439 -> 15625.923 | F9: 0.439 | G9: =('MTD Utility Sheet'!I11/1.82)/0.5 -> 390.3956 | H9: 1.75 | I9: ='MTD Utility Sheet'!H11/12.38 -> 256.85622 | J9: 12.38 | K9: =IF(('MTD Utility Sheet'!F11-2866)<0,"0",('MTD Utility Sheet'!F11-2866)/(0.568+0.075)) -> 9241.0886 | L9: ='MTD Utility Sheet'!F11/K9 -> 0.95313662 | M9: ='MTD Utility Sheet'!B11*301 -> 295.0703
A10: Amwaj Rotana - Jumeirah Beach | B10: =B9+1 -> 9 | C10: 5 | D10: 2025 | E10: ='MTD Utility Sheet'!G12/0.439 -> 15137.608 | F10: 0.439 | G10: =('MTD Utility Sheet'!I12/1.82)/0.5 -> 488 | H10: 1.75 | I10: ='MTD Utility Sheet'!H12/12.38 -> 263.89338 | J10: 12.38 | K10: =IF(('MTD Utility Sheet'!F12-2866)<0,"0",('MTD Utility Sheet'!F12-2866)/(0.568+0.075)) -> 9119.098 | L10: ='MTD Utility Sheet'!F12/K10 -> 0.95728547 | M10: ='MTD Utility Sheet'!B12*301 -> 296.0034
A11: Amwaj Rotana - Jumeirah Beach | B11: =B10+1 -> 10 | C11: 5 | D11: 2025 | E11: ='MTD Utility Sheet'!G13/0.439 -> 16114.214 | F11: 0.439 | G11: =('MTD Utility Sheet'!I13/1.82)/0.5 -> 488 | H11: 1.75 | I11: ='MTD Utility Sheet'!H13/12.38 -> 268.58481 | J11: 12.38 | K11: =IF(('MTD Utility Sheet'!F13-2866)<0,"0",('MTD Utility Sheet'!F13-2866)/(0.568+0.075)) -> 10162.675 | L11: ='MTD Utility Sheet'!F13/K11 -> 0.92501236 | M11: ='MTD Utility Sheet'!B13*301 -> 279.9902
A12: Amwaj Rotana - Jumeirah Beach | B12: =B11+1 -> 11 | C12: 5 | D12: 2025 | E12: ='MTD Utility Sheet'!G14/0.439 -> 15137.608 | F12: 0.439 | G12: =('MTD Utility Sheet'!I14/1.82)/0.5 -> 585.6044 | H12: 1.75 | I12: ='MTD Utility Sheet'!H14/12.38 -> 267.41195 | J12: 12.38 | K12: =IF(('MTD Utility Sheet'!F14-2866)<0,"0",('MTD Utility Sheet'!F14-2866)/(0.568+0.075)) -> 10327.589 | L12: ='MTD Utility Sheet'!F14/K12 -> 0.9205091 | M12: ='MTD Utility Sheet'!B14*301 -> 270.9903
A13: Amwaj Rotana - Jumeirah Beach | B13: =B12+1 -> 12 | C13: 5 | D13: 2025 | E13: ='MTD Utility Sheet'!G15/0.439 -> 15137.608 | F13: 0.439 | G13: =('MTD Utility Sheet'!I15/1.82)/0.5 -> 488 | H13: 1.75 | I13: ='MTD Utility Sheet'!H15/12.38 -> 248.6462 | J13: 12.38 | K13: =IF(('MTD Utility Sheet'!F15-2866)<0,"0",('MTD Utility Sheet'!F15-2866)/(0.568+0.075)) -> 9303.9347 | L13: ='MTD Utility Sheet'!F15/K13 -> 0.95104172 | M13: ='MTD Utility Sheet'!B15*301 -> 272.0137
A14: Amwaj Rotana - Jumeirah Beach | B14: =B13+1 -> 13 | C14: 5 | D14: 2025 | E14: ='MTD Utility Sheet'!G16/0.439 -> 15625.923 | F14: 0.439 | G14: =('MTD Utility Sheet'!I16/1.82)/0.5 -> 488 | H14: 1.75 | I14: ='MTD Utility Sheet'!H16/12.38 -> 240.43619 | J14: 12.38 | K14: =IF(('MTD Utility Sheet'!F16-2866)<0,"0",('MTD Utility Sheet'!F16-2866)/(0.568+0.075)) -> 9087.8227 | L14: ='MTD Utility Sheet'!F16/K14 -> 0.95836707 | M14: ='MTD Utility Sheet'!B16*301 -> 264.0071
... A31: Amwaj Rotana - Jumeirah Beach | B31: =B30+1 -> 30 | C31: 5 | D31: 2025 | E31: ='MTD Utility Sheet'!G33/0.439 -> 15625.923 | F31: 0.439 | G31: =('MTD Utility Sheet'!I33/1.82)/0.5 -> 488 | H31: 1.75 | I31: ='MTD Utility Sheet'!H33/12.38 -> 256.85622 | J31: 12.38 | K31: =IF(('MTD Utility Sheet'!F33-2866)<0,"0",('MTD Utility Sheet'!F33-2866)/(0.568+0.075)) -> 12147.434 | L31: ='MTD Utility Sheet'!F33/K31 -> 0.8789346 | M31: ='MTD Utility Sheet'!B33*301 -> 288.96
A32: Amwaj Rotana - Jumeirah Beach | B32: =B31+1 -> 31 | C32: 5 | D32: 2025 | E32: ='MTD Utility Sheet'!G34/0.439 -> 16114.214 | F32: 1.439 | G32: =('MTD Utility Sheet'!I34/1.82)*2 -> 487.91209 | H32: 1.75 | I32: ='MTD Utility Sheet'!H34/12.38 -> 259.18578 | J32: 13.38 | K32: =IF(('MTD Utility Sheet'!F34-2866)<0,"0",('MTD Utility Sheet'!F34-2866)/(0.568+0.075)) -> 11982.504 | L32: ='MTD Utility Sheet'!F34/K32 -> 0.88218206 | M32: ='MTD Utility Sheet'!B34*301 -> 301

Sheet MTD Utility Sheet
A1: Daily Utilities May -2025
B3: Occ % | C3: Out. Temp at 2PM | D3: RH % | E3: F&B Covers | F3: Chilled water | G3: Electricity | H3: Water | I3: LPG | J3: Total
A4: 1 | B4: 0.9734 | C4: 38.5c | D4: 0.74 | E4: 1571 | F4: 8868.54 | G4: 6859.78 | H4: 3499.32 | I4: 488.49 | J4: =SUM(F4+G4+H4+I4) -> 19716.13
A5: 2 | B5: 0.9934 | C5: 38.0c | D5: 0.79 | E5: 1985 | F5: 8950.82 | G5: 6645.41 | H5: 3339.6 | I5: 488.08 | J5: =SUM(F5+G5+H5+I5) -> 19423.91
A6: 3 | B6: 0.99 | C6: 39.0c | D6: 0.72 | E6: 1638 | F6: 8939.85 | G6: 7074.14 | H6: 3397.68 | I6: 577.3 | J6: =SUM(F6+G6+H6+I6) -> 19988.97
A7: 4 | B7: 1 | C7: 40.5c | D7: 0.63 | E7: 1637 | F7: 8427.9 | G7: 6859.78 | H7: 3441.24 | I7: 532.9 | J7: =SUM(F7+G7+H7+I7) -> 19261.82
A8: 5 | B8: 0.9136 | C8: 38.5c | D8: 0.66 | E8: 1415 | F8: 8455.33 | G8: 6859.78 | H8: 3397.68 | I8: 532.9 | J8: =SUM(F8+G8+H8+I8) -> 19245.69
A9: 6 | B9: 0.9866 | C9: 38.0c | D9: 0.62 | E9: 1424 | F9: 9418.88 | G9: 7074.14 | H9: 3150.84 | I9: 488.49 | J9: =SUM(F9+G9+H9+I9) -> 20132.35
A10: 7 | B10: 0.9701 | C10: 36.0c | D10: 0.6 | E10: 1482 | F10: 8603.43 | G10: 6645.41 | H10: 3267 | I10: 488.08 | J10: =SUM(F10+G10+H10+I10) -> 19003.92
A11: 8 | B11: 0.9803 | C11: 38.0c | D11: 0.65 | E11: 1323 | F11: 8808.02 | G11: 6859.78 | H11: 3179.88 | I11: 355.26 | J11: =SUM(F11+G11+H11+I11) -> 19202.94
A12: 9 | B12: 0.9834 | C12: 38.5c | D12: 0.85 | E12: 1323 | F12: 8729.58 | G12: 6645.41 | H12: 3267 | I12: 444.08 | J12: =SUM(F12+G12+H12+I12) -> 19086.07
A13: 10 | B13: 0.9302 | C13: 38.0c | D13: 0.8 | E13: 1399 | F13: 9400.6 | G13: 7074.14 | H13: 3325.08 | I13: 444.08 | J13: =SUM(F13+G13+H13+I13) -> 20243.9
A14: 11 | B14: 0.9003 | C14: 39.0c | D14: 0.78 | E14: 1309 | F14: 9506.64 | G14: 6645.41 | H14: 3310.56 | I14: 532.9 | J14: =SUM(F14+G14+H14+I14) -> 19995.51
A15: 12 | B15: 0.9037 | C15: 40.0c | D15: 0.65 | E15: 1413 | F15: 8848.43 | G15: 6645.41 | H15: 3078.24 | I15: 444.08 | J15: =SUM(F15+G15+H15+I15) -> 19016.16
... A17: 14 | B17: 0.8837 | C17: 38.0c | D17: 0.6 | E17: 1313 | F17: 8736.9 | G17: 6431.04 | H17: 2802.36 | I17: 355.26 | J17: =SUM(F17+G17+H17+I17) -> 18325.56
A18: 15 | B18: 0.8904 | C18: 40.0c | D18: 0.55 | E18: 1233 | F18: 9331.12 | G18: 6859.78 | H18: 2991.12 | I18: 355.26 | J18: =SUM(F18+G18+H18+I18) -> 19537.28 | L18: =+L18:O27 -> 0
A19: 16 | B19: 0.9801 | C19: 40.0c | D19: 0.86 | E19: 1199 | F19: 9325.63 | G19: 7074.14 | H19: 2933.04 | I19: 399.67 | J19: =SUM(F19+G19+H19+I19) -> 19732.48
A20: 17 | B20: 0.99 | C20: 39.0c | D20: 0.77 | E20: 1348 | F20: 10166.68 | G20: 7074.14 | H20: 2991.12 | I20: 488.89 | J20: =SUM(F20+G20+H20+I20) -> 20720.83
A21: 18 | B21: 0.97 | C21: 39.5c | D21: 0.86 | E21: 1496 | F21: 9274.44 | G21: 6859.78 | H21: 3092.76 | I21: 577.3 | J21: =SUM(F21+G21+H21+I21) -> 19804.28
A22: 19 | B22: 0.8638 | C22: 39.0c | D22: 0.93 | E22: 1389 | F22: 10093.55 | G22: 6645.41 | H22: 2599.08 | I22: 444.08 | J22: =SUM(F22+G22+H22+I22) -> 19782.12
A23: 20 | B23: 0.8835 | C23: 40.0c | D23: 0.86 | E23: 1197 | F23: 10110 | G23: 6645.41 | H23: 2657.16 | I23: 532.9 | J23: =SUM(F23+G23+H23+I23) -> 19945.47
A24: 21 | B24: 0.82 | C24: 42c | D24: 0.82 | E24: 1249 | F24: 10046.01 | G24: 7074.14 | H24: 2889.48 | I24: 444.08 | J24: =SUM(F24+G24+H24+I24) -> 20453.71
A25: 22 | B25: 0.86 | C25: 44c | D25: 0.78 | E25: 1230 | F25: 10477.51 | G25: 6645.41 | H25: 2657.16 | I25: 444.08 | J25: =SUM(F25+G25+H25+I25) -> 20224.16
A26: 23 | B26: 0.98 | C26: 45c | D26: 0.67 | E26: 1404 | F26: 9638.28 | G26: 7288.51 | H26: 2933.04 | I26: 444.08 | J26: =SUM(F26+G26+H26+I26) -> 20303.91
A27: 24 | B27: 0.96 | C27: 47c | D27: 0.68 | E27: 1485 | F27: 9541.38 | G27: 6645.41 | H27: 3165.36 | I27: 444.08 | J27: =SUM(F27+G27+H27+I27) -> 19796.23
A28: 25 | B28: 0.98 | C28: 46c | D28: 0.72 | E28: 1481 | F28: 9819.29 | G28: 7074.14 | H28: 2831.4 | I28: 444.08 | J28: =SUM(F28+G28+H28+I28) -> 20168.91
A29: 26 | B29: 0.8667 | C29: 47c | D29: 0.7 | E29: 1369 | F29: 10870.61 | G29: 6859.78 | H29: 3383.16 | I29: 444.08 | J29: =SUM(F29+G29+H29+I29) -> 21557.63
A30: 27 | B30: 0.8306 | C30: 46c | D30: 0.72 | E30: 1305 | F30: 10298.33 | G30: 6645.41 | H30: 2802.36 | I30: 444.08 | J30: =SUM(F30+G30+H30+I30) -> 20190.18
... A34: 31 | B34: 1 | C34: 42c | D34: 0.67 | E34: 1553 | F34: 10570.75 | G34: 7074.14 | H34: 3208.72 | I34: 444 | J34: =SUM(F34+G34+H34+I34) -> 21297.61
A35: Total Cost | F35: =SUM(F4:F34) -> 295669.26 | G35: =SUM(G4:G34) -> 212653.08 | H35: =SUM(H4:H34) -> 95918.92 | I35: =SUM(I4:I34) -> 14343.29 | J35: =SUM(J4:J34) -> 618584.55
A36: Total Units | B36: =AVERAGE(B4:B34) -> 0.93744839 | C36: =AVERAGE(C4:C34) -> #DIV/0! | D36: =AVERAGE(D4:D34) -> 0.72967742 | E36: =SUM(E4:E34) -> 43871 | F36: =F35*0.38 -> 112354.32 | G36: =G35/12.9 -> 16484.735 | H36: =H35/0.92 -> 104259.7 | I36: =I35/1.76 -> 8149.5966

Sheet May 31
A1: Daily Utilities Consumption
A2: 31.05.2025
A3: District Cooling
A4: Previous Reading MWh | B4: 72942.96 | C4: Current Reading MWh | D4: 74074.15 | E4: Consumption MWH | F4: =D4-B4 -> 1131.19 | G4: Consumption RTH | H4: =F4*284.35 -> 321653.88
A6: Total Cost (0.568/rth) | D6: =H4*0.568 -> 182699.4
A7: Total Fuel Surchage Cost (0.075/rth) | D7: =H4*0.075 -> 24124.041
A8: Chilled Water Demand (2,866 AED/Day) | D8: 2866
A9: Grand Total Exc. VAT | D9: =SUM(D6:H8) -> 209689.44
A10: Electrical
A11: MDB-G1 (39299675-8) | C11: Previous Reading KWH | D11: 44240 | E11: Current Reading KWH | F11: 44469 | G11: Consumption KWH | H11: =F11-D11 -> 229
A12: MDB-G2 (39299676-6) | C12: Previous Reading KWH | D12: 73637 | E12: Current Reading KWH | F12: 74048 | G12: Consumption KWH | H12: =F12-D12 -> 411
A13: MDB-G3 (39299677-4) | C13: Previous Reading KWH | D13: 74116 | E13: Current Reading KWH | F13: 74468 | G13: Consumption KWH | H13: =F13-D13 -> 352
H14: =SUM(H11:H13) -> 992
A15: Total Consumption * Multiplication Factor (487.20) | H15: =H14*487.2 -> 483302.4
A16: Cost Calculation
A17: 0-2000 kwh @ 0.230 /KWH | D17: 460
A18: 2000-4000 kwh @ 0.280 /KWH | D18: 560
A19: 4000-6000 kwh @ 0.320 /KWH | D19: 640
A20: 6000 & above @ 0.380 /KWH | D20: =H15*0.38 -> 183654.91
A21: Fuel Surcharge @ 0.060 /KWH | D21: =H15*0.06 -> 28998.144
A22: Grand Total Exc. VAT | D22: =D20+D21 -> 212653.06
A23: WATER
A24: Previous Reading | B24: 335340 | C24: Present Reading | D24: 341946 | E24: Consumption m3 | F24: =D24-B24 -> 6606 | G24: Consumption IG | H24: =F24*220 -> 1453320
A25: Cost calculation
A26: 0-10000 @ 0.035 / IG | D26: 350
A27: 10000-20000 @ 0.04 / IG | D27: 400
A28: 20000 & above @ 0.046 / IG | D28: =(H24-20000)*0.046 -> 65932.72
A29: Fuel Surcharge @ 0.005 / IG | D29: =H24*0.005 -> 7266.6
A30: Sewerage Fees | D30: =(H24*0.015)+170 -> 21969.8
A31: Grand Total Exc. VAT | D31: =SUM(D26:H30) -> 95919.12
A32: LPG Gas
A33: Tank 1 (1% = 48 liters) | C33: Previous Reading % | D33: 80 | E33: Current Reading % | F33: 80 | G33: Consumption Liters | H33: =(D33-F33)*48.8 -> 0
A34: Tank 2 (1% = 48 liters) | C34: Previous Reading % | D34: 65 | E34: Current Reading % | F34: 55 | G34: Consumption Liters | H34: =(D34-F34)*48.8 -> 488
A35: 322908 | H35: =((H34+H33)*1.82)*0.5 -> 444.08
A36: Total Utilities | H36: =H35+D22+D9+D31 -> 518705.7

Sheet May 30
A1: Daily Utilities Consumption
A2: 30.05.2025
A3: District Cooling
A4: Previous Reading MWh | B4: 73989.29 | C4: Current Reading MWh | D4: 74032.01 | E4: Consumption MWH | F4: =D4-B4 -> 42.72 | G4: Consumption RTH | H4: =F4*284.35 -> 12147.432
A6: Total Cost (0.568/rth) | D6: =H4*0.568 -> 6899.7414
A7: Total Fuel Surchage Cost (0.075/rth) | D7: =H4*0.075 -> 911.0574
A8: Chilled Water Demand (2,866 AED/Day) | D8: 2866
A9: Grand Total Exc. VAT | D9: =SUM(D6:H8) -> 10676.799
A10: Electrical
A11: MDB-G1 (39299675-8) | C11: Previous Reading KWH | D11: 44455 | E11: Current Reading KWH | F11: 44462 | G11: Consumption KWH | H11: =F11-D11 -> 7
A12: MDB-G2 (39299676-6) | C12: Previous Reading KWH | D12: 74020 | E12: Current Reading KWH | F12: 74034 | G12: Consumption KWH | H12: =F12-D12 -> 14
A13: MDB-G3 (39299677-4) | C13: Previous Reading KWH | D13: 74445 | E13: Current Reading KWH | F13: 74456 | G13: Consumption KWH | H13: =F13-D13 -> 11
H14: =SUM(H11:H13) -> 32
A15: Total Consumption * Multiplication Factor (487.20) | H15: =H14*487.2 -> 15590.4
A16: Cost Calculation
A17: 0-2000 kwh @ 0.230 /KWH | D17: 460
A18: 2000-4000 kwh @ 0.280 /KWH | D18: 560
A19: 4000-6000 kwh @ 0.320 /KWH | D19: 640
A20: 6000 & above @ 0.380 /KWH | D20: =H15*0.38 -> 5924.352
A21: Fuel Surcharge @ 0.060 /KWH | D21: =H15*0.06 -> 935.424
A22: Grand Total Exc. VAT | D22: =D20+D21 -> 6859.776
A23: WATER
A24: Previous Reading | B24: 341506 | C24: Present Reading | D24: 341725 | E24: Consumption m3 | F24: =D24-B24 -> 219 | G24: Consumption IG | H24: =F24*220 -> 48180
A25: Cost calculation
A26: 0-10000 @ 0.035 / IG | D26: 350
A27: 10000-20000 @ 0.04 / IG | D27: 400
A28: 20000 & above @ 0.046 / IG | D28: =(H24-20000)*0.046 -> 1296.28
A29: Fuel Surcharge @ 0.005 / IG | D29: =H24*0.005 -> 240.9
A30: Sewerage Fees | D30: =(H24*0.015)+170 -> 892.7
A31: Grand Total Exc. VAT | D31: =SUM(D26:H30) -> 3179.88
A32: LPG Gas
A33: Tank 1 (1% = 48 liters) | C33: Previous Reading % | D33: 80 | E33: Current Reading % | F33: 80 | G33: Consumption Liters | H33: =(D33-F33)*48.8 -> 0
A34: Tank 2 (1% = 48 liters) | C34: Previous Reading % | D34: 75 | E34: Current Reading % | F34: 65 | G34: Consumption Liters | H34: =(D34-F34)*48.8 -> 488
A35: 322908 | H35: =((H34+H33)*1.82)*0.5 -> 444.08
A36: Total Utilities | H36: =H35+D22+D9+D31 -> 21160.535

Sheet May 29
A1: Daily Utilities Consumption
A2: 29.05.2025
A3: District Cooling
A4: Previous Reading MWh | B4: 73947.69 | C4: Current Reading MWh | D4: 73989.29 | E4: Consumption MWH | F4: =D4-B4 -> 41.6 | G4: Consumption RTH | H4: =F4*284.35 -> 11828.96
A6: Total Cost (0.568/rth) | D6: =H4*0.568 -> 6718.8493
A7: Total Fuel Surchage Cost (0.075/rth) | D7: =H4*0.075 -> 887.172
A8: Chilled Water Demand (2,866 AED/Day) | D8: 2866
A9: Grand Total Exc. VAT | D9: =SUM(D6:H8) -> 10472.021
A10: Electrical
A11: MDB-G1 (39299675-8) | C11: Previous Reading KWH | D11: 44448 | E11: Current Reading KWH | F11: 44455 | G11: Consumption KWH | H11: =F11-D11 -> 7
A12: MDB-G2 (39299676-6) | C12: Previous Reading KWH | D12: 74006 | E12: Current Reading KWH | F12: 74020 | G12: Consumption KWH | H12: =F12-D12 -> 14
A13: MDB-G3 (39299677-4) | C13: Previous Reading KWH | D13: 74434 | E13: Current Reading KWH | F13: 74445 | G13: Consumption KWH | H13: =F13-D13 -> 11
H14: =SUM(H11:H13) -> 32
A15: Total Consumption * Multiplication Factor (487.20) | H15: =H14*487.2 -> 15590.4
A16: Cost Calculation
A17: 0-2000 kwh @ 0.230 /KWH | D17: 460
A18: 2000-4000 kwh @ 0.280 /KWH | D18: 560
A19: 4000-6000 kwh @ 0.320 /KWH | D19: 640
A20: 6000 & above @ 0.380 /KWH | D20: =H15*0.38 -> 5924.352
A21: Fuel Surcharge @ 0.060 /KWH | D21: =H15*0.06 -> 935.424
A22: Grand Total Exc. VAT | D22: =D20+D21 -> 6859.776
A23: WATER
A24: Previous Reading | B24: 341292 | C24: Present Reading | D24: 341506 | E24: Consumption m3 | F24: =D24-B24 -> 214 | G24: Consumption IG | H24: =F24*220 -> 47080
A25: Cost calculation
A26: 0-10000 @ 0.035 / IG | D26: 350
A27: 10000-20000 @ 0.04 / IG | D27: 400
A28: 20000 & above @ 0.046 / IG | D28: =(H24-20000)*0.046 -> 1245.68
A29: Fuel Surcharge @ 0.005 / IG | D29: =H24*0.005 -> 235.4
A30: Sewerage Fees | D30: =(H24*0.015)+170 -> 876.2
A31: Grand Total Exc. VAT | D31: =SUM(D26:H30) -> 3107.28
A32: LPG Gas
A33: Tank 1 (1% = 48 liters) | C33: Previous Reading % | D33: 80 | E33: Current Reading % | F33: 80 | G33: Consumption Liters | H33: =(D33-F33)*48.8 -> 0
A34: Tank 2 (1% = 48 liters) | C34: Previous Reading % | D34: 85 | E34: Current Reading % | F34: 75 | G34: Consumption Liters | H34: =(D34-F34)*48.8 -> 488
A35: 322908 | H35: =((H34+H33)*1.82)*0.5 -> 444.08
A36: Total Utilities | H36: =H35+D22+D9+D31 -> 20883.157

Sheet May 28
A1: Daily Utilities Consumption
A2: 28.05.2025
A3: District Cooling
A4: Previous Reading MWh | B4: 73905.65 | C4: Current Reading MWh | D4: 73947.69 | E4: Consumption MWH | F4: =D4-B4 -> 42.04 | G4: Consumption RTH | H4: =F4*284.35 -> 11954.074
A6: Total Cost (0.568/rth) | D6: =H4*0.568 -> 6789.914
A7: Total Fuel Surchage Cost (0.075/rth) | D7: =H4*0.075 -> 896.55555
A8: Chilled Water Demand (2,866 AED/Day) | D8: 2866
A9: Grand Total Exc. VAT | D9: =SUM(D6:H8) -> 10552.47
A10: Electrical
A11: MDB-G1 (39299675-8) | C11: Previous Reading KWH | D11: 44440 | E11: Current Reading KWH | F11: 44448 | G11: Consumption KWH | H11: =F11-D11 -> 8
A12: MDB-G2 (39299676-6) | C12: Previous Reading KWH | D12: 73992 | E12: Current Reading KWH | F12: 74006 | G12: Consumption KWH | H12: =F12-D12 -> 14
A13: MDB-G3 (39299677-4) | C13: Previous Reading KWH | D13: 74422 | E13: Current Reading KWH | F13: 74434 | G13: Consumption KWH | H13: =F13-D13 -> 12
H14: =SUM(H11:H13) -> 34
A15: Total Consumption * Multiplication Factor (487.20) | H15: =H14*487.2 -> 16564.8
A16: Cost Calculation
A17: 0-2000 kwh @ 0.230 /KWH | D17: 460
A18: 2000-4000 kwh @ 0.280 /KWH | D18: 560
A19: 4000-6000 kwh @ 0.320 /KWH | D19: 640
A20: 6000 & above @ 0.380 /KWH | D20: =H15*0.38 -> 6294.624
A21: Fuel Surcharge @ 0.060 /KWH | D21: =H15*0.06 -> 993.888
A22: Grand Total Exc. VAT | D22: =D20+D21 -> 7288.512
A23: WATER
A24: Previous Reading | B24: 341081 | C24: Present Reading | D24: 341292 | E24: Consumption m3 | F24: =D24-B24 -> 211 | G24: Consumption IG | H24: =F24*220 -> 46420
A25: Cost calculation
A26: 0-10000 @ 0.035 / IG | D26: 350
A27: 10000-20000 @ 0.04 / IG | D27: 400
A28: 20000 & above @ 0.046 / IG | D28: =(H24-20000)*0.046 -> 1215.32
A29: Fuel Surcharge @ 0.005 / IG | D29: =H24*0.005 -> 232.1
A30: Sewerage Fees | D30: =(H24*0.015)+170 -> 866.3
A31: Grand Total Exc. VAT | D31: =SUM(D26:H30) -> 3063.72
A32: LPG Gas
A33: Tank 1 (1% = 48 liters) | C33: Previous Reading % | D33: 25 | E33: Current Reading % | F33: 25 | G33: Consumption Liters | H33: =(D33-F33)*48.8 -> 0
A34: Tank 2 (1% = 48 liters) | C34: Previous Reading % | D34: 80 | E34: Current Reading % | F34: 69 | G34: Consumption Liters | H34: =(D34-F34)*48.8 -> 536.8
A35: 322908 | H35: =((H34+H33)*1.82)*0.5 -> 488.488
A36: Total Utilities | H36: =H35+D22+D9+D31 -> 21393.19

Sheet May 27
A1: Daily Utilities Consumption
A2: 27.05.2025
A3: District Cooling
A4: Previous Reading MWh | B4: 73865 | C4: Current Reading MWh | D4: 73905.65 | E4: Consumption MWH | F4: =D4-B4 -> 40.65 | G4: Consumption RTH | H4: =F4*284.35 -> 11558.827
A6: Total Cost (0.568/rth) | D6: =H4*0.568 -> 6565.414
A7: Total Fuel Surchage Cost (0.075/rth) | D7: =H4*0.075 -> 866.91206
A8: Chilled Water Demand (2,866 AED/Day) | D8: 2866
A9: Grand Total Exc. VAT | D9: =SUM(D6:H8) -> 10298.326
A10: Electrical
A11: MDB-G1 (39299675-8) | C11: Previous Reading KWH | D11: 44433 | E11: Current Reading KWH | F11: 44440 | G11: Consumption KWH | H11: =F11-D11 -> 7
A12: MDB-G2 (39299676-6) | C12: Previous Reading KWH | D12: 73979 | E12: Current Reading KWH | F12: 73992 | G12: Consumption KWH | H12: =F12-D12 -> 13
A13: MDB-G3 (39299677-4) | C13: Previous Reading KWH | D13: 74411 | E13: Current Reading KWH | F13: 74422 | G13: Consumption KWH | H13: =F13-D13 -> 11
H14: =SUM(H11:H13) -> 31
A15: Total Consumption * Multiplication Factor (487.20) | H15: =H14*487.2 -> 15103.2
A16: Cost Calculation
A17: 0-2000 kwh @ 0.230 /KWH | D17: 460
A18: 2000-4000 kwh @ 0.280 /KWH | D18: 560
A19: 4000-6000 kwh @ 0.320 /KWH | D19: 640
A20: 6000 & above @ 0.380 /KWH | D20: =H15*0.38 -> 5739.216
A21: Fuel Surcharge @ 0.060 /KWH | D21: =H15*0.06 -> 906.192
A22: Grand Total Exc. VAT | D22: =D20+D21 -> 6645.408
A23: WATER
A24: Previous Reading | B24: 340888 | C24: Present Reading | D24: 341081 | E24: Consumption m3 | F24: =D24-B24 -> 193 | G24: Consumption IG | H24: =F24*220 -> 42460
A25: Cost calculation
A26: 0-10000 @ 0.035 / IG | D26: 350
A27: 10000-20000 @ 0.04 / IG | D27: 400
A28: 20000 & above @ 0.046 / IG | D28: =(H24-20000)*0.046 -> 1033.16
A29: Fuel Surcharge @ 0.005 / IG | D29: =H24*0.005 -> 212.3
A30: Sewerage Fees | D30: =(H24*0.015)+170 -> 806.9
A31: Grand Total Exc. VAT | D31: =SUM(D26:H30) -> 2802.36
A32: LPG Gas
A33: Tank 1 (1% = 48 liters) | C33: Previous Reading % | D33: 35 | E33: Current Reading % | F33: 25 | G33: Consumption Liters | H33: =(D33-F33)*48.8 -> 488
A34: Tank 2 (1% = 48 liters) | C34: Previous Reading % | D34: 80 | E34: Current Reading % | F34: 80 | G34: Consumption Liters | H34: =(D34-F34)*48.8 -> 0
A35: 322908 | H35: =((H34+H33)*1.82)*0.5 -> 444.08
A36: Total Utilities | H36: =H35+D22+D9+D31 -> 20190.174

Sheet May 26
A1: Daily Utilities Consumption
A2: 26.05.2025
A3: District Cooling
A4: Previous Reading MWh | B4: 73821.22 | C4: Current Reading MWh | D4: 73865 | E4: Consumption MWH | F4: =D4-B4 -> 43.78 | G4: Consumption RTH | H4: =F4*284.35 -> 12448.843
A6: Total Cost (0.568/rth) | D6: =H4*0.568 -> 7070.9428
A7: Total Fuel Surchage Cost (0.075/rth) | D7: =H4*0.075 -> 933.66322
A8: Chilled Water Demand (2,866 AED/Day) | D8: 2866
A9: Grand Total Exc. VAT | D9: =SUM(D6:H8) -> 10870.606
A10: Electrical
A11: MDB-G1 (39299675-8) | C11: Previous Reading KWH | D11: 44426 | E11: Current Reading KWH | F11: 44433 | G11: Consumption KWH | H11: =F11-D11 -> 7
A12: MDB-G2 (39299676-6) | C12: Previous Reading KWH | D12: 73966 | E12: Current Reading KWH | F12: 73979 | G12: Consumption KWH | H12: =F12-D12 -> 13
A13: MDB-G3 (39299677-4) | C13: Previous Reading KWH | D13: 74399 | E13: Current Reading KWH | F13: 74411 | G13: Consumption KWH | H13: =F13-D13 -> 12
H14: =SUM(H11:H13) -> 32
A15: Total Consumption * Multiplication Factor (487.20) | H15: =H14*487.2 -> 15590.4
A16: Cost Calculation
A17: 0-2000 kwh @ 0.230 /KWH | D17: 460
A18: 2000-4000 kwh @ 0.280 /KWH | D18: 560
A19: 4000-6000 kwh @ 0.320 /KWH | D19: 640
A20: 6000 & above @ 0.380 /KWH | D20: =H15*0.38 -> 5924.352
A21: Fuel Surcharge @ 0.060 /KWH | D21: =H15*0.06 -> 935.424
A22: Grand Total Exc. VAT | D22: =D20+D21 -> 6859.776
A23: WATER
A24: Previous Reading | B24: 340655 | C24: Present Reading | D24: 340888 | E24: Consumption m3 | F24: =D24-B24 -> 233 | G24: Consumption IG | H24: =F24*220 -> 51260
A25: Cost calculation
A26: 0-10000 @ 0.035 / IG | D26: 350
A27: 10000-20000 @ 0.04 / IG | D27: 400
A28: 20000 & above @ 0.046 / IG | D28: =(H24-20000)*0.046 -> 1437.96
A29: Fuel Surcharge @ 0.005 / IG | D29: =H24*0.005 -> 256.3
A30: Sewerage Fees | D30: =(H24*0.015)+170 -> 938.9
A31: Grand Total Exc. VAT | D31: =SUM(D26:H30) -> 3383.16
A32: LPG Gas
A33: Tank 1 (1% = 48 liters) | C33: Previous Reading % | D33: 45 | E33: Current Reading % | F33: 35 | G33: Consumption Liters | H33: =(D33-F33)*48.8 -> 488
A34: Tank 2 (1% = 48 liters) | C34: Previous Reading % | D34: 80 | E34: Current Reading % | F34: 80 | G34: Consumption Liters | H34: =(D34-F34)*48.8 -> 0
A35: 322908 | H35: =((H34+H33)*1.82)*0.5 -> 444.08
A36: Total Utilities | H36: =H35+D22+D9+D31 -> 21557.622

Sheet May 25
A1: Daily Utilities Consumption
A2: 25.05.2025
A3: District Cooling
A4: Previous Reading MWh | B4: 73783.19 | C4: Current Reading MWh | D4: 73821.22 | E4: Consumption MWH | F4: =D4-B4 -> 38.03 | G4: Consumption RTH | H4: =F4*284.35 -> 10813.83
A6: Total Cost (0.568/rth) | D6: =H4*0.568 -> 6142.2557
A7: Total Fuel Surchage Cost (0.075/rth) | D7: =H4*0.075 -> 811.03729
A8: Chilled Water Demand (2,866 AED/Day) | D8: 2866
A9: Grand Total Exc. VAT | D9: =SUM(D6:H8) -> 9819.293
A10: Electrical
A11: MDB-G1 (39299675-8) | C11: Previous Reading KWH | D11: 44418 | E11: Current Reading KWH | F11: 44426 | G11: Consumption KWH | H11: =F11-D11 -> 8
A12: MDB-G2 (39299676-6) | C12: Previous Reading KWH | D12: 73953 | E12: Current Reading KWH | F12: 73966 | G12: Consumption KWH | H12: =F12-D12 -> 13
A13: MDB-G3 (39299677-4) | C13: Previous Reading KWH | D13: 74387 | E13: Current Reading KWH | F13: 74399 | G13: Consumption KWH | H13: =F13-D13 -> 12
H14: =SUM(H11:H13) -> 33
A15: Total Consumption * Multiplication Factor (487.20) | H15: =H14*487.2 -> 16077.6
A16: Cost Calculation
A17: 0-2000 kwh @ 0.230 /KWH | D17: 460
A18: 2000-4000 kwh @ 0.280 /KWH | D18: 560
A19: 4000-6000 kwh @ 0.320 /KWH | D19: 640
A20: 6000 & above @ 0.380 /KWH | D20: =H15*0.38 -> 6109.488
A21: Fuel Surcharge @ 0.060 /KWH | D21: =H15*0.06 -> 964.656
A22: Grand Total Exc. VAT | D22: =D20+D21 -> 7074.144
A23: WATER
A24: Previous Reading | B24: 340460 | C24: Present Reading | D24: 340655 | E24: Consumption m3 | F24: =D24-B24 -> 195 | G24: Consumption IG | H24: =F24*220 -> 42900
A25: Cost calculation
A26: 0-10000 @ 0.035 / IG | D26: 350
A27: 10000-20000 @ 0.04 / IG | D27: 400
A28: 20000 & above @ 0.046 / IG | D28: =(H24-20000)*0.046 -> 1053.4
A29: Fuel Surcharge @ 0.005 / IG | D29: =H24*0.005 -> 214.5
A30: Sewerage Fees | D30: =(H24*0.015)+170 -> 813.5
A31: Grand Total Exc. VAT | D31: =SUM(D26:H30) -> 2831.4
A32: LPG Gas
A33: Tank 1 (1% = 48 liters) | C33: Previous Reading % | D33: 55 | E33: Current Reading % | F33: 45 | G33: Consumption Liters | H33: =(D33-F33)*48.8 -> 488
A34: Tank 2 (1% = 48 liters) | C34: Previous Reading % | D34: 80 | E34: Current Reading % | F34: 80 | G34: Consumption Liters | H34: =(D34-F34)*48.8 -> 0
A35: 322908 | H35: =((H34+H33)*1.82)*0.5 -> 444.08
A36: Total Utilities | H36: =H35+D22+D9+D31 -> 20168.917

Sheet May 24
A1: Daily Utilities Consumption
A2: 24.05.2025
A3: District Cooling
A4: Previous Reading MWh | B4: 73746.68 | C4: Current Reading MWh | D4: 73783.19 | E4: Consumption MWH | F4: =D4-B4 -> 36.51 | G4: Consumption RTH | H4: =F4*284.35 -> 10381.619
A6: Total Cost (0.568/rth) | D6: =H4*0.568 -> 5896.7593
A7: Total Fuel Surchage Cost (0.075/rth) | D7: =H4*0.075 -> 778.62139
A8: Chilled Water Demand (2,866 AED/Day) | D8: 2866
A9: Grand Total Exc. VAT | D9: =SUM(D6:H8) -> 9541.3807
A10: Electrical
A11: MDB-G1 (39299675-8) | C11: Previous Reading KWH | D11: 44411 | E11: Current Reading KWH | F11: 44418 | G11: Consumption KWH | H11: =F11-D11 -> 7
A12: MDB-G2 (39299676-6) | C12: Previous Reading KWH | D12: 73940 | E12: Current Reading KWH | F12: 73953 | G12: Consumption KWH | H12: =F12-D12 -> 13
A13: MDB-G3 (39299677-4) | C13: Previous Reading KWH | D13: 74376 | E13: Current Reading KWH | F13: 74387 | G13: Consumption KWH | H13: =F13-D13 -> 11
H14: =SUM(H11:H13) -> 31
A15: Total Consumption * Multiplication Factor (487.20) | H15: =H14*487.2 -> 15103.2
A16: Cost Calculation
A17: 0-2000 kwh @ 0.230 /KWH | D17: 460
A18: 2000-4000 kwh @ 0.280 /KWH | D18: 560
A19: 4000-6000 kwh @ 0.320 /KWH | D19: 640
A20: 6000 & above @ 0.380 /KWH | D20: =H15*0.38 -> 5739.216
A21: Fuel Surcharge @ 0.060 /KWH | D21: =H15*0.06 -> 906.192
A22: Grand Total Exc. VAT | D22: =D20+D21 -> 6645.408
A23: WATER
A24: Previous Reading | B24: 340242 | C24: Present Reading | D24: 340460 | E24: Consumption m3 | F24: =D24-B24 -> 218 | G24: Consumption IG | H24: =F24*220 -> 47960
A25: Cost calculation
A26: 0-10000 @ 0.035 / IG | D26: 350
A27: 10000-20000 @ 0.04 / IG | D27: 400
A28: 20000 & above @ 0.046 / IG | D28: =(H24-20000)*0.046 -> 1286.16
A29: Fuel Surcharge @ 0.005 / IG | D29: =H24*0.005 -> 239.8
A30: Sewerage Fees | D30: =(H24*0.015)+170 -> 889.4
A31: Grand Total Exc. VAT | D31: =SUM(D26:H30) -> 3165.36
A32: LPG Gas
A33: Tank 1 (1% = 48 liters) | C33: Previous Reading % | D33: 65 | E33: Current Reading % | F33: 55 | G33: Consumption Liters | H33: =(D33-F33)*48.8 -> 488
A34: Tank 2 (1% = 48 liters) | C34: Previous Reading % | D34: 80 | E34: Current Reading % | F34: 80 | G34: Consumption Liters | H34: =(D34-F34)*48.8 -> 0
A35: 322908 | H35: =((H34+H33)*1.82)*0.5 -> 444.08
A36: Total Utilities | H36: =H35+D22+D9+D31 -> 19796.229

Sheet May 23
A1: Daily Utilities Consumption
A2: 23.05.2025
A3: District Cooling
A4: Previous Reading MWh | B4: 73709.64 | C4: Current Reading MWh | D4: 73746.68 | E4: Consumption MWH | F4: =D4-B4 -> 37.04 | G4: Consumption RTH | H4: =F4*284.35 -> 10532.324
A6: Total Cost (0.568/rth) | D6: =H4*0.568 -> 5982.36
A7: Total Fuel Surchage Cost (0.075/rth) | D7: =H4*0.075 -> 789.9243
A8: Chilled Water Demand (2,866 AED/Day) | D8: 2866
A9: Grand Total Exc. VAT | D9: =SUM(D6:H8) -> 9638.2843
A10: Electrical
A11: MDB-G1 (39299675-8) | C11: Previous Reading KWH | D11: 44403 | E11: Current Reading KWH | F11: 44411 | G11: Consumption KWH | H11: =F11-D11 -> 8
A12: MDB-G2 (39299676-6) | C12: Previous Reading KWH | D12: 73926 | E12: Current Reading KWH | F12: 73940 | G12: Consumption KWH | H12: =F12-D12 -> 14
A13: MDB-G3 (39299677-4) | C13: Previous Reading KWH | D13: 74364 | E13: Current Reading KWH | F13: 74376 | G13: Consumption KWH | H13: =F13-D13 -> 12
H14: =SUM(H11:H13) -> 34
A15: Total Consumption * Multiplication Factor (487.20) | H15: =H14*487.2 -> 16564.8
A16: Cost Calculation
A17: 0-2000 kwh @ 0.230 /KWH | D17: 460
A18: 2000-4000 kwh @ 0.280 /KWH | D18: 560
A19: 4000-6000 kwh @ 0.320 /KWH | D19: 640
A20: 6000 & above @ 0.380 /KWH | D20: =H15*0.38 -> 6294.624
A21: Fuel Surcharge @ 0.060 /KWH | D21: =H15*0.06 -> 993.888
A22: Grand Total Exc. VAT | D22: =D20+D21 -> 7288.512
A23: WATER
A24: Previous Reading | B24: 340040 | C24: Present Reading | D24: 340242 | E24: Consumption m3 | F24: =D24-B24 -> 202 | G24: Consumption IG | H24: =F24*220 -> 44440
A25: Cost calculation
A26: 0-10000 @ 0.035 / IG | D26: 350
A27: 10000-20000 @ 0.04 / IG | D27: 400
A28: 20000 & above @ 0.046 / IG | D28: =(H24-20000)*0.046 -> 1124.24
A29: Fuel Surcharge @ 0.005 / IG | D29: =H24*0.005 -> 222.2
A30: Sewerage Fees | D30: =(H24*0.015)+170 -> 836.6
A31: Grand Total Exc. VAT | D31: =SUM(D26:H30) -> 2933.04
A32: LPG Gas
A33: Tank 1 (1% = 48 liters) | C33: Previous Reading % | D33: 75 | E33: Current Reading % | F33: 65 | G33: Consumption Liters | H33: =(D33-F33)*48.8 -> 488
A34: Tank 2 (1% = 48 liters) | C34: Previous Reading % | D34: 80 | E34: Current Reading % | F34: 80 | G34: Consumption Liters | H34: =(D34-F34)*48.8 -> 0
A35: 322908 | H35: =((H34+H33)*1.82)*0.5 -> 444.08
A36: Total Utilities | H36: =H35+D22+D9+D31 -> 20303.916

Sheet May 22
A1: Daily Utilities Consumption
A2: 22.05.2025
A3: District Cooling
A4: Previous Reading MWh | B4: 73668.01 | C4: Current Reading MWh | D4: 73709.64 | E4: Consumption MWH | F4: =D4-B4 -> 41.63 | G4: Consumption RTH | H4: =F4*284.35 -> 11837.491
A6: Total Cost (0.568/rth) | D6: =H4*0.568 -> 6723.6946
A7: Total Fuel Surchage Cost (0.075/rth) | D7: =H4*0.075 -> 887.81179
A8: Chilled Water Demand (2,866 AED/Day) | D8: 2866
A9: Grand Total Exc. VAT | D9: =SUM(D6:H8) -> 10477.506
A10: Electrical
A11: MDB-G1 (39299675-8) | C11: Previous Reading KWH | D11: 44396 | E11: Current Reading KWH | F11: 44403 | G11: Consumption KWH | H11: =F11-D11 -> 7
A12: MDB-G2 (39299676-6) | C12: Previous Reading KWH | D12: 73913 | E12: Current Reading KWH | F12: 73926 | G12: Consumption KWH | H12: =F12-D12 -> 13
A13: MDB-G3 (39299677-4) | C13: Previous Reading KWH | D13: 74353 | E13: Current Reading KWH | F13: 74364 | G13: Consumption KWH | H13: =F13-D13 -> 11
H14: =SUM(H11:H13) -> 31
A15: Total Consumption * Multiplication Factor (487.20) | H15: =H14*487.2 -> 15103.2
A16: Cost Calculation
A17: 0-2000 kwh @ 0.230 /KWH | D17: 460
A18: 2000-4000 kwh @ 0.280 /KWH | D18: 560
A19: 4000-6000 kwh @ 0.320 /KWH | D19: 640
A20: 6000 & above @ 0.380 /KWH | D20: =H15*0.38 -> 5739.216
A21: Fuel Surcharge @ 0.060 /KWH | D21: =H15*0.06 -> 906.192
A22: Grand Total Exc. VAT | D22: =D20+D21 -> 6645.408
A23: WATER
A24: Previous Reading | B24: 339857 | C24: Present Reading | D24: 340040 | E24: Consumption m3 | F24: =D24-B24 -> 183 | G24: Consumption IG | H24: =F24*220 -> 40260
A25: Cost calculation
A26: 0-10000 @ 0.035 / IG | D26: 350
A27: 10000-20000 @ 0.04 / IG | D27: 400
A28: 20000 & above @ 0.046 / IG | D28: =(H24-20000)*0.046 -> 931.96
A29: Fuel Surcharge @ 0.005 / IG | D29: =H24*0.005 -> 201.3
A30: Sewerage Fees | D30: =(H24*0.015)+170 -> 773.9
A31: Grand Total Exc. VAT | D31: =SUM(D26:H30) -> 2657.16
A32: LPG Gas
A33: Tank 1 (1% = 48 liters) | C33: Previous Reading % | D33: 85 | E33: Current Reading % | F33: 75 | G33: Consumption Liters | H33: =(D33-F33)*48.8 -> 488
A34: Tank 2 (1% = 48 liters) | C34: Previous Reading % | D34: 80 | E34: Current Reading % | F34: 80 | G34: Consumption Liters | H34: =(D34-F34)*48.8 -> 0
A35: 322908 | H35: =((H34+H33)*1.82)*0.5 -> 444.08
A36: Total Utilities | H36: =H35+D22+D9+D31 -> 20224.154

Sheet May 21
A1: Daily Utilities Consumption
A2: 21.05.2025
A3: District Cooling
A4: Previous Reading MWh | B4: 73628.74 | C4: Current Reading MWh | D4: 73668.01 | E4: Consumption MWH | F4: =D4-B4 -> 39.27 | G4: Consumption RTH | H4: =F4*284.35 -> 11166.424
A6: Total Cost (0.568/rth) | D6: =H4*0.568 -> 6342.5291
A7: Total Fuel Surchage Cost (0.075/rth) | D7: =H4*0.075 -> 837.48184
A8: Chilled Water Demand (2,866 AED/Day) | D8: 2866
A9: Grand Total Exc. VAT | D9: =SUM(D6:H8) -> 10046.011
A10: Electrical
A11: MDB-G1 (39299675-8) | C11: Previous Reading KWH | D11: 44388 | E11: Current Reading KWH | F11: 44396 | G11: Consumption KWH | H11: =F11-D11 -> 8
A12: MDB-G2 (39299676-6) | C12: Previous Reading KWH | D12: 73900 | E12: Current Reading KWH | F12: 73913 | G12: Consumption KWH | H12: =F12-D12 -> 13
A13: MDB-G3 (39299677-4) | C13: Previous Reading KWH | D13: 74341 | E13: Current Reading KWH | F13: 74353 | G13: Consumption KWH | H13: =F13-D13 -> 12
H14: =SUM(H11:H13) -> 33
A15: Total Consumption * Multiplication Factor (487.20) | H15: =H14*487.2 -> 16077.6
A16: Cost Calculation
A17: 0-2000 kwh @ 0.230 /KWH | D17: 460
A18: 2000-4000 kwh @ 0.280 /KWH | D18: 560
A19: 4000-6000 kwh @ 0.320 /KWH | D19: 640
A20: 6000 & above @ 0.380 /KWH | D20: =H15*0.38 -> 6109.488
A21: Fuel Surcharge @ 0.060 /KWH | D21: =H15*0.06 -> 964.656
A22: Grand Total Exc. VAT | D22: =D20+D21 -> 7074.144
A23: WATER
A24: Previous Reading | B24: 339658 | C24: Present Reading | D24: 339857 | E24: Consumption m3 | F24: =D24-B24 -> 199 | G24: Consumption IG | H24: =F24*220 -> 43780
A25: Cost calculation
A26: 0-10000 @ 0.035 / IG | D26: 350
A27: 10000-20000 @ 0.04 / IG | D27: 400
A28: 20000 & above @ 0.046 / IG | D28: =(H24-20000)*0.046 -> 1093.88
A29: Fuel Surcharge @ 0.005 / IG | D29: =H24*0.005 -> 218.9
A30: Sewerage Fees | D30: =(H24*0.015)+170 -> 826.7
A31: Grand Total Exc. VAT | D31: =SUM(D26:H30) -> 2889.48
A32: LPG Gas
A33: Tank 1 (1% = 48 liters) | C33: Previous Reading % | D33: 78 | E33: Current Reading % | F33: 68 | G33: Consumption Liters | H33: =(D33-F33)*48.8 -> 488
A34: Tank 2 (1% = 48 liters) | C34: Previous Reading % | D34: 17 | E34: Current Reading % | F34: 17 | G34: Consumption Liters | H34: =(D34-F34)*48.8 -> 0
A35: 322908 | H35: =((H34+H33)*1.82)*0.5 -> 444.08
A36: Total Utilities | H36: =H35+D22+D9+D31 -> 20453.715

Sheet May 20
A1: Daily Utilities Consumption
A2: 20.05.2025
A3: District Cooling
A4: Previous Reading MWh | B4: 73589.12 | C4: Current Reading MWh | D4: 73628.74 | E4: Consumption MWH | F4: =D4-B4 -> 39.62 | G4: Consumption RTH | H4: =F4*284.35 -> 11265.947
A6: Total Cost (0.568/rth) | D6: =H4*0.568 -> 6399.0579
A7: Total Fuel Surchage Cost (0.075/rth) | D7: =H4*0.075 -> 844.94603
A8: Chilled Water Demand (2,866 AED/Day) | D8: 2866
A9: Grand Total Exc. VAT | D9: =SUM(D6:H8) -> 10110.004
A10: Electrical
A11: MDB-G1 (39299675-8) | C11: Previous Reading KWH | D11: 44381 | E11: Current Reading KWH | F11: 44388 | G11: Consumption KWH | H11: =F11-D11 -> 7
A12: MDB-G2 (39299676-6) | C12: Previous Reading KWH | D12: 73887 | E12: Current Reading KWH | F12: 73900 | G12: Consumption KWH | H12: =F12-D12 -> 13
A13: MDB-G3 (39299677-4) | C13: Previous Reading KWH | D13: 74330 | E13: Current Reading KWH | F13: 74341 | G13: Consumption KWH | H13: =F13-D13 -> 11
H14: =SUM(H11:H13) -> 31
A15: Total Consumption * Multiplication Factor (487.20) | H15: =H14*487.2 -> 15103.2
A16: Cost Calculation
A17: 0-2000 kwh @ 0.230 /KWH | D17: 460
A18: 2000-4000 kwh @ 0.280 /KWH | D18: 560
A19: 4000-6000 kwh @ 0.320 /KWH | D19: 640
A20: 6000 & above @ 0.380 /KWH | D20: =H15*0.38 -> 5739.216
A21: Fuel Surcharge @ 0.060 /KWH | D21: =H15*0.06 -> 906.192
A22: Grand Total Exc. VAT | D22: =D20+D21 -> 6645.408
A23: WATER
A24: Previous Reading | B24: 339475 | C24: Present Reading | D24: 339658 | E24: Consumption m3 | F24: =D24-B24 -> 183 | G24: Consumption IG | H24: =F24*220 -> 40260
A25: Cost calculation
A26: 0-10000 @ 0.035 / IG | D26: 350
A27: 10000-20000 @ 0.04 / IG | D27: 400
A28: 20000 & above @ 0.046 / IG | D28: =(H24-20000)*0.046 -> 931.96
A29: Fuel Surcharge @ 0.005 / IG | D29: =H24*0.005 -> 201.3
A30: Sewerage Fees | D30: =(H24*0.015)+170 -> 773.9
A31: Grand Total Exc. VAT | D31: =SUM(D26:H30) -> 2657.16
A32: LPG Gas
A33: Tank 1 (1% = 48 liters) | C33: Previous Reading % | D33: 78 | E33: Current Reading % | F33: 78 | G33: Consumption Liters | H33: =(D33-F33)*48.8 -> 0
A34: Tank 2 (1% = 48 liters) | C34: Previous Reading % | D34: 29 | E34: Current Reading % | F34: 17 | G34: Consumption Liters | H34: =(D34-F34)*48.8 -> 585.6
A35: 322908 | H35: =((H34+H33)*1.82)*0.5 -> 532.896
A36: Total Utilities | H36: =H35+D22+D9+D31 -> 19945.468

Sheet May 19
A1: Daily Utilities Consumption
A2: 19.05.2025
A3: District Cooling
A4: Previous Reading MWh | B4: 73549.59 | C4: Current Reading MWh | D4: 73589.12 | E4: Consumption MWH | F4: =D4-B4 -> 39.53 | G4: Consumption RTH | H4: =F4*284.35 -> 11240.355
A6: Total Cost (0.568/rth) | D6: =H4*0.568 -> 6384.5219
A7: Total Fuel Surchage Cost (0.075/rth) | D7: =H4*0.075 -> 843.02666
A8: Chilled Water Demand (2,866 AED/Day) | D8: 2866
A9: Grand Total Exc. VAT | D9: =SUM(D6:H8) -> 10093.549
A10: Electrical
A11: MDB-G1 (39299675-8) | C11: Previous Reading KWH | D11: 44374 | E11: Current Reading KWH | F11: 44381 | G11: Consumption KWH | H11: =F11-D11 -> 7
A12: MDB-G2 (39299676-6) | C12: Previous Reading KWH | D12: 73874 | E12: Current Reading KWH | F12: 73887 | G12: Consumption KWH | H12: =F12-D12 -> 13
A13: MDB-G3 (39299677-4) | C13: Previous Reading KWH | D13: 74319 | E13: Current Reading KWH | F13: 74330 | G13: Consumption KWH | H13: =F13-D13 -> 11
H14: =SUM(H11:H13) -> 31
A15: Total Consumption * Multiplication Factor (487.20) | H15: =H14*487.2 -> 15103.2
A16: Cost Calculation
A17: 0-2000 kwh @ 0.230 /KWH | D17: 460
A18: 2000-4000 kwh @ 0.280 /KWH | D18: 560
A19: 4000-6000 kwh @ 0.320 /KWH | D19: 640
A20: 6000 & above @ 0.380 /KWH | D20: =H15*0.38 -> 5739.216
A21: Fuel Surcharge @ 0.060 /KWH | D21: =H15*0.06 -> 906.192
A22: Grand Total Exc. VAT | D22: =D20+D21 -> 6645.408
A23: WATER
A24: Previous Reading | B24: 339296 | C24: Present Reading | D24: 339475 | E24: Consumption m3 | F24: =D24-B24 -> 179 | G24: Consumption IG | H24: =F24*220 -> 39380
A25: Cost calculation
A26: 0-10000 @ 0.035 / IG | D26: 350
A27: 10000-20000 @ 0.04 / IG | D27: 400
A28: 20000 & above @ 0.046 / IG | D28: =(H24-20000)*0.046 -> 891.48
A29: Fuel Surcharge @ 0.005 / IG | D29: =H24*0.005 -> 196.9
A30: Sewerage Fees | D30: =(H24*0.015)+170 -> 760.7
A31: Grand Total Exc. VAT | D31: =SUM(D26:H30) -> 2599.08
A32: LPG Gas
A33: Tank 1 (1% = 48 liters) | C33: Previous Reading % | D33: 78 | E33: Current Reading % | F33: 78 | G33: Consumption Liters | H33: =(D33-F33)*48.8 -> 0
A34: Tank 2 (1% = 48 liters) | C34: Previous Reading % | D34: 39 | E34: Current Reading % | F34: 29 | G34: Consumption Liters | H34: =(D34-F34)*48.8 -> 488
A35: 322908 | H35: =((H34+H33)*1.82)*0.5 -> 444.08
A36: Total Utilities | H36: =H35+D22+D9+D31 -> 19782.117

Sheet May 18
A1: Daily Utilities Consumption
A2: 18.05.2025
A3: District Cooling
A4: Previous Reading MWh | B4: 73514.54 | C4: Current Reading MWh | D4: 73549.59 | E4: Consumption MWH | F4: =D4-B4 -> 35.05 | G4: Consumption RTH | H4: =F4*284.35 -> 9966.4675
A6: Total Cost (0.568/rth) | D6: =H4*0.568 -> 5660.9535
A7: Total Fuel Surchage Cost (0.075/rth) | D7: =H4*0.075 -> 747.48506
A8: Chilled Water Demand (2,866 AED/Day) | D8: 2866
A9: Grand Total Exc. VAT | D9: =SUM(D6:H8) -> 9274.4386
A10: Electrical
A11: MDB-G1 (39299675-8) | C11: Previous Reading KWH | D11: 44366 | E11: Current Reading KWH | F11: 44374 | G11: Consumption KWH | H11: =F11-D11 -> 8
A12: MDB-G2 (39299676-6) | C12: Previous Reading KWH | D12: 73861 | E12: Current Reading KWH | F12: 73874 | G12: Consumption KWH | H12: =F12-D12 -> 13
A13: MDB-G3 (39299677-4) | C13: Previous Reading KWH | D13: 74308 | E13: Current Reading KWH | F13: 74319 | G13: Consumption KWH | H13: =F13-D13 -> 11
H14: =SUM(H11:H13) -> 32
A15: Total Consumption * Multiplication Factor (487.20) | H15: =H14*487.2 -> 15590.4
A16: Cost Calculation
A17: 0-2000 kwh @ 0.230 /KWH | D17: 460
A18: 2000-4000 kwh @ 0.280 /KWH | D18: 560
A19: 4000-6000 kwh @ 0.320 /KWH | D19: 640
A20: 6000 & above @ 0.380 /KWH | D20: =H15*0.38 -> 5924.352
A21: Fuel Surcharge @ 0.060 /KWH | D21: =H15*0.06 -> 935.424
A22: Grand Total Exc. VAT | D22: =D20+D21 -> 6859.776
A23: WATER
A24: Previous Reading | B24: 339083 | C24: Present Reading | D24: 339296 | E24: Consumption m3 | F24: =D24-B24 -> 213 | G24: Consumption IG | H24: =F24*220 -> 46860
A25: Cost calculation
A26: 0-10000 @ 0.035 / IG | D26: 350
A27: 10000-20000 @ 0.04 / IG | D27: 400
A28: 20000 & above @ 0.046 / IG | D28: =(H24-20000)*0.046 -> 1235.56
A29: Fuel Surcharge @ 0.005 / IG | D29: =H24*0.005 -> 234.3
A30: Sewerage Fees | D30: =(H24*0.015)+170 -> 872.9
A31: Grand Total Exc. VAT | D31: =SUM(D26:H30) -> 3092.76
A32: LPG Gas
A33: Tank 1 (1% = 48 liters) | C33: Previous Reading % | D33: 78 | E33: Current Reading % | F33: 78 | G33: Consumption Liters | H33: =(D33-F33)*48.8 -> 0
A34: Tank 2 (1% = 48 liters) | C34: Previous Reading % | D34: 52 | E34: Current Reading % | F34: 39 | G34: Consumption Liters | H34: =(D34-F34)*48.8 -> 634.4
A35: 322908 | H35: =((H34+H33)*1.82)*0.5 -> 577.304
A36: Total Utilities | H36: =H35+D22+D9+D31 -> 19804.279

Sheet May 17
A1: Daily Utilities Consumption
A2: 17.05.2025
A3: District Cooling
A4: Previous Reading MWh | B4: 73474.61 | C4: Current Reading MWh | D4: 73514.54 | E4: Consumption MWH | F4: =D4-B4 -> 39.93 | G4: Consumption RTH | H4: =F4*284.35 -> 11354.095
A6: Total Cost (0.568/rth) | D6: =H4*0.568 -> 6449.1262
A7: Total Fuel Surchage Cost (0.075/rth) | D7: =H4*0.075 -> 851.55716
A8: Chilled Water Demand (2,866 AED/Day) | D8: 2866
A9: Grand Total Exc. VAT | D9: =SUM(D6:H8) -> 10166.683
A10: Electrical
A11: MDB-G1 (39299675-8) | C11: Previous Reading KWH | D11: 44359 | E11: Current Reading KWH | F11: 44366 | G11: Consumption KWH | H11: =F11-D11 -> 7
A12: MDB-G2 (39299676-6) | C12: Previous Reading KWH | D12: 73847 | E12: Current Reading KWH | F12: 73861 | G12: Consumption KWH | H12: =F12-D12 -> 14
A13: MDB-G3 (39299677-4) | C13: Previous Reading KWH | D13: 74296 | E13: Current Reading KWH | F13: 74308 | G13: Consumption KWH | H13: =F13-D13 -> 12
H14: =SUM(H11:H13) -> 33
A15: Total Consumption * Multiplication Factor (487.20) | H15: =H14*487.2 -> 16077.6
A16: Cost Calculation
A17: 0-2000 kwh @ 0.230 /KWH | D17: 460
A18: 2000-4000 kwh @ 0.280 /KWH | D18: 560
A19: 4000-6000 kwh @ 0.320 /KWH | D19: 640
A20: 6000 & above @ 0.380 /KWH | D20: =H15*0.38 -> 6109.488
A21: Fuel Surcharge @ 0.060 /KWH | D21: =H15*0.06 -> 964.656
A22: Grand Total Exc. VAT | D22: =D20+D21 -> 7074.144
A23: WATER
A24: Previous Reading | B24: 338877 | C24: Present Reading | D24: 339083 | E24: Consumption m3 | F24: =D24-B24 -> 206 | G24: Consumption IG | H24: =F24*220 -> 45320
A25: Cost calculation
A26: 0-10000 @ 0.035 / IG | D26: 350
A27: 10000-20000 @ 0.04 / IG | D27: 400
A28: 20000 & above @ 0.046 / IG | D28: =(H24-20000)*0.046 -> 1164.72
A29: Fuel Surcharge @ 0.005 / IG | D29: =H24*0.005 -> 226.6
A30: Sewerage Fees | D30: =(H24*0.015)+170 -> 849.8
A31: Grand Total Exc. VAT | D31: =SUM(D26:H30) -> 2991.12
A32: LPG Gas
A33: Tank 1 (1% = 48 liters) | C33: Previous Reading % | D33: 78 | E33: Current Reading % | F33: 78 | G33: Consumption Liters | H33: =(D33-F33)*48.8 -> 0
A34: Tank 2 (1% = 48 liters) | C34: Previous Reading % | D34: 63 | E34: Current Reading % | F34: 52 | G34: Consumption Liters | H34: =(D34-F34)*48.8 -> 536.8
A35: 322908 | H35: =((H34+H33)*1.82)*0.5 -> 488.488
A36: Total Utilities | H36: =H35+D22+D9+D31 -> 20720.435

Sheet May 16
A1: Daily Utilities Consumption
A2: 16.05.2025
A3: District Cooling
A4: Previous Reading MWh | B4: 73439.28 | C4: Current Reading MWh | D4: 73474.61 | E4: Consumption MWH | F4: =D4-B4 -> 35.33 | G4: Consumption RTH | H4: =F4*284.35 -> 10046.086
A6: Total Cost (0.568/rth) | D6: =H4*0.568 -> 5706.1766
A7: Total Fuel Surchage Cost (0.075/rth) | D7: =H4*0.075 -> 753.45641
A8: Chilled Water Demand (2,866 AED/Day) | D8: 2866
A9: Grand Total Exc. VAT | D9: =SUM(D6:H8) -> 9325.633
A10: Electrical
A11: MDB-G1 (39299675-8) | C11: Previous Reading KWH | D11: 44351 | E11: Current Reading KWH | F11: 44359 | G11: Consumption KWH | H11: =F11-D11 -> 8
A12: MDB-G2 (39299676-6) | C12: Previous Reading KWH | D12: 73833 | E12: Current Reading KWH | F12: 73847 | G12: Consumption KWH | H12: =F12-D12 -> 14
A13: MDB-G3 (39299677-4) | C13: Previous Reading KWH | D13: 74285 | E13: Current Reading KWH | F13: 74296 | G13: Consumption KWH | H13: =F13-D13 -> 11
H14: =SUM(H11:H13) -> 33
A15: Total Consumption * Multiplication Factor (487.20) | H15: =H14*487.2 -> 16077.6
A16: Cost Calculation
A17: 0-2000 kwh @ 0.230 /KWH | D17: 460
A18: 2000-4000 kwh @ 0.280 /KWH | D18: 560
A19: 4000-6000 kwh @ 0.320 /KWH | D19: 640
A20: 6000 & above @ 0.380 /KWH | D20: =H15*0.38 -> 6109.488
A21: Fuel Surcharge @ 0.060 /KWH | D21: =H15*0.06 -> 964.656
A22: Grand Total Exc. VAT | D22: =D20+D21 -> 7074.144
A23: WATER
A24: Previous Reading | B24: 338675 | C24: Present Reading | D24: 338877 | E24: Consumption m3 | F24: =D24-B24 -> 202 | G24: Consumption IG | H24: =F24*220 -> 44440
A25: Cost calculation
A26: 0-10000 @ 0.035 / IG | D26: 350
A27: 10000-20000 @ 0.04 / IG | D27: 400
A28: 20000 & above @ 0.046 / IG | D28: =(H24-20000)*0.046 -> 1124.24
A29: Fuel Surcharge @ 0.005 / IG | D29: =H24*0.005 -> 222.2
A30: Sewerage Fees | D30: =(H24*0.015)+170 -> 836.6
A31: Grand Total Exc. VAT | D31: =SUM(D26:H30) -> 2933.04
A32: LPG Gas
A33: Tank 1 (1% = 48 liters) | C33: Previous Reading % | D33: 78 | E33: Current Reading % | F33: 78 | G33: Consumption Liters | H33: =(D33-F33)*48.8 -> 0
A34: Tank 2 (1% = 48 liters) | C34: Previous Reading % | D34: 72 | E34: Current Reading % | F34: 63 | G34: Consumption Liters | H34: =(D34-F34)*48.8 -> 439.2
A35: 322908 | H35: =((H34+H33)*1.82)*0.5 -> 399.672
A36: Total Utilities | H36: =H35+D22+D9+D31 -> 19732.489

Sheet May 15
A1: Daily Utilities Consumption
A2: 15.05.2025
A3: District Cooling
A4: Previous Reading MWh | B4: 73403.92 | C4: Current Reading MWh | D4: 73439.28 | E4: Consumption MWH | F4: =D4-B4 -> 35.36 | G4: Consumption RTH | H4: =F4*284.35 -> 10054.616
A6: Total Cost (0.568/rth) | D6: =H4*0.568 -> 5711.0219
A7: Total Fuel Surchage Cost (0.075/rth) | D7: =H4*0.075 -> 754.0962
A8: Chilled Water Demand (2,866 AED/Day) | D8: 2866
A9: Grand Total Exc. VAT | D9: =SUM(D6:H8) -> 9331.1181
A10: Electrical
A11: MDB-G1 (39299675-8) | C11: Previous Reading KWH | D11: 44344 | E11: Current Reading KWH | F11: 44351 | G11: Consumption KWH | H11: =F11-D11 -> 7
A12: MDB-G2 (39299676-6) | C12: Previous Reading KWH | D12: 73820 | E12: Current Reading KWH | F12: 73833 | G12: Consumption KWH | H12: =F12-D12 -> 13
A13: MDB-G3 (39299677-4) | C13: Previous Reading KWH | D13: 74273 | E13: Current Reading KWH | F13: 74285 | G13: Consumption KWH | H13: =F13-D13 -> 12
H14: =SUM(H11:H13) -> 32
A15: Total Consumption * Multiplication Factor (487.20) | H15: =H14*487.2 -> 15590.4
A16: Cost Calculation
A17: 0-2000 kwh @ 0.230 /KWH | D17: 460
A18: 2000-4000 kwh @ 0.280 /KWH | D18: 560
A19: 4000-6000 kwh @ 0.320 /KWH | D19: 640
A20: 6000 & above @ 0.380 /KWH | D20: =H15*0.38 -> 5924.352
A21: Fuel Surcharge @ 0.060 /KWH | D21: =H15*0.06 -> 935.424
A22: Grand Total Exc. VAT | D22: =D20+D21 -> 6859.776
A23: WATER
A24: Previous Reading | B24: 338469 | C24: Present Reading | D24: 338675 | E24: Consumption m3 | F24: =D24-B24 -> 206 | G24: Consumption IG | H24: =F24*220 -> 45320
A25: Cost calculation
A26: 0-10000 @ 0.035 / IG | D26: 350
A27: 10000-20000 @ 0.04 / IG | D27: 400
A28: 20000 & above @ 0.046 / IG | D28: =(H24-20000)*0.046 -> 1164.72
A29: Fuel Surcharge @ 0.005 / IG | D29: =H24*0.005 -> 226.6
A30: Sewerage Fees | D30: =(H24*0.015)+170 -> 849.8
A31: Grand Total Exc. VAT | D31: =SUM(D26:H30) -> 2991.12
A32: LPG Gas
A33: Tank 1 (1% = 48 liters) | C33: Previous Reading % | D33: 78 | E33: Current Reading % | F33: 78 | G33: Consumption Liters | H33: =(D33-F33)*48.8 -> 0
A34: Tank 2 (1% = 48 liters) | C34: Previous Reading % | D34: 80 | E34: Current Reading % | F34: 72 | G34: Consumption Liters | H34: =(D34-F34)*48.8 -> 390.4
A35: 322908 | H35: =((H34+H33)*1.82)*0.5 -> 355.264
A36: Total Utilities | H36: =H35+D22+D9+D31 -> 19537.278

Sheet May 14
A1: Daily Utilities Consumption
A2: 14.05.2025
A3: District Cooling
A4: Previous Reading MWh | B4: 73371.81 | C4: Current Reading MWh | D4: 73403.92 | E4: Consumption MWH | F4: =D4-B4 -> 32.11 | G4: Consumption RTH | H4: =F4*284.35 -> 9130.4785
A6: Total Cost (0.568/rth) | D6: =H4*0.568 -> 5186.1118
A7: Total Fuel Surchage Cost (0.075/rth) | D7: =H4*0.075 -> 684.78589
A8: Chilled Water Demand (2,866 AED/Day) | D8: 2866
A9: Grand Total Exc. VAT | D9: =SUM(D6:H8) -> 8736.8977
A10: Electrical
A11: MDB-G1 (39299675-8) | C11: Previous Reading KWH | D11: 44337 | E11: Current Reading KWH | F11: 44344 | G11: Consumption KWH | H11: =F11-D11 -> 7
A12: MDB-G2 (39299676-6) | C12: Previous Reading KWH | D12: 73807 | E12: Current Reading KWH | F12: 73820 | G12: Consumption KWH | H12: =F12-D12 -> 13
A13: MDB-G3 (39299677-4) | C13: Previous Reading KWH | D13: 74263 | E13: Current Reading KWH | F13: 74273 | G13: Consumption KWH | H13: =F13-D13 -> 10
H14: =SUM(H11:H13) -> 30
A15: Total Consumption * Multiplication Factor (487.20) | H15: =H14*487.2 -> 14616
A16: Cost Calculation
A17: 0-2000 kwh @ 0.230 /KWH | D17: 460
A18: 2000-4000 kwh @ 0.280 /KWH | D18: 560
A19: 4000-6000 kwh @ 0.320 /KWH | D19: 640
A20: 6000 & above @ 0.380 /KWH | D20: =H15*0.38 -> 5554.08
A21: Fuel Surcharge @ 0.060 /KWH | D21: =H15*0.06 -> 876.96
A22: Grand Total Exc. VAT | D22: =D20+D21 -> 6431.04
A23: WATER
A24: Previous Reading | B24: 338276 | C24: Present Reading | D24: 338469 | E24: Consumption m3 | F24: =D24-B24 -> 193 | G24: Consumption IG | H24: =F24*220 -> 42460
A25: Cost calculation
A26: 0-10000 @ 0.035 / IG | D26: 350
A27: 10000-20000 @ 0.04 / IG | D27: 400
A28: 20000 & above @ 0.046 / IG | D28: =(H24-20000)*0.046 -> 1033.16
A29: Fuel Surcharge @ 0.005 / IG | D29: =H24*0.005 -> 212.3
A30: Sewerage Fees | D30: =(H24*0.015)+170 -> 806.9
A31: Grand Total Exc. VAT | D31: =SUM(D26:H30) -> 2802.36
A32: LPG Gas
A33: Tank 1 (1% = 48 liters) | C33: Previous Reading % | D33: 28 | E33: Current Reading % | F33: 28 | G33: Consumption Liters | H33: =(D33-F33)*48.8 -> 0
A34: Tank 2 (1% = 48 liters) | C34: Previous Reading % | D34: 68 | E34: Current Reading % | F34: 60 | G34: Consumption Liters | H34: =(D34-F34)*48.8 -> 390.4
A35: 322908 | H35: =((H34+H33)*1.82)*0.5 -> 355.264
A36: Total Utilities | H36: =H35+D22+D9+D31 -> 18325.562

Sheet May 13
A1: Daily Utilities Consumption
A2: 13.05.2025
A3: District Cooling
A4: Previous Reading MWh | B4: 73339.85 | C4: Current Reading MWh | D4: 73371.81 | E4: Consumption MWH | F4: =D4-B4 -> 31.96 | G4: Consumption RTH | H4: =F4*284.35 -> 9087.826
A6: Total Cost (0.568/rth) | D6: =H4*0.568 -> 5161.8852
A7: Total Fuel Surchage Cost (0.075/rth) | D7: =H4*0.075 -> 681.58695
A8: Chilled Water Demand (2,866 AED/Day) | D8: 2866
A9: Grand Total Exc. VAT | D9: =SUM(D6:H8) -> 8709.4721
A10: Electrical
A11: MDB-G1 (39299675-8) | C11: Previous Reading KWH | D11: 44329 | E11: Current Reading KWH | F11: 44337 | G11: Consumption KWH | H11: =F11-D11 -> 8
A12: MDB-G2 (39299676-6) | C12: Previous Reading KWH | D12: 73795 | E12: Current Reading KWH | F12: 73807 | G12: Consumption KWH | H12: =F12-D12 -> 12
A13: MDB-G3 (39299677-4) | C13: Previous Reading KWH | D13: 74251 | E13: Current Reading KWH | F13: 74263 | G13: Consumption KWH | H13: =F13-D13 -> 12
H14: =SUM(H11:H13) -> 32
A15: Total Consumption * Multiplication Factor (487.20) | H15: =H14*487.2 -> 15590.4
A16: Cost Calculation
A17: 0-2000 kwh @ 0.230 /KWH | D17: 460
A18: 2000-4000 kwh @ 0.280 /KWH | D18: 560
A19: 4000-6000 kwh @ 0.320 /KWH | D19: 640
A20: 6000 & above @ 0.380 /KWH | D20: =H15*0.38 -> 5924.352
A21: Fuel Surcharge @ 0.060 /KWH | D21: =H15*0.06 -> 935.424
A22: Grand Total Exc. VAT | D22: =D20+D21 -> 6859.776
A23: WATER
A24: Previous Reading | B24: 338071 | C24: Present Reading | D24: 338276 | E24: Consumption m3 | F24: =D24-B24 -> 205 | G24: Consumption IG | H24: =F24*220 -> 45100
A25: Cost calculation
A26: 0-10000 @ 0.035 / IG | D26: 350
A27: 10000-20000 @ 0.04 / IG | D27: 400
A28: 20000 & above @ 0.046 / IG | D28: =(H24-20000)*0.046 -> 1154.6
A29: Fuel Surcharge @ 0.005 / IG | D29: =H24*0.005 -> 225.5
A30: Sewerage Fees | D30: =(H24*0.015)+170 -> 846.5
A31: Grand Total Exc. VAT | D31: =SUM(D26:H30) -> 2976.6
A32: LPG Gas
A33: Tank 1 (1% = 48 liters) | C33: Previous Reading % | D33: 28 | E33: Current Reading % | F33: 28 | G33: Consumption Liters | H33: =(D33-F33)*48.8 -> 0
A34: Tank 2 (1% = 48 liters) | C34: Previous Reading % | D34: 78 | E34: Current Reading % | F34: 68 | G34: Consumption Liters | H34: =(D34-F34)*48.8 -> 488
A35: 322908 | H35: =((H34+H33)*1.82)*0.5 -> 444.08
A36: Total Utilities | H36: =H35+D22+D9+D31 -> 18989.928

Sheet May 12
A1: Daily Utilities Consumption
A2: 12.05.2025
A3: District Cooling
A4: Previous Reading MWh | B4: 73307.13 | C4: Current Reading MWh | D4: 73339.85 | E4: Consumption MWH | F4: =D4-B4 -> 32.72 | G4: Consumption RTH | H4: =F4*284.35 -> 9303.932
A6: Total Cost (0.568/rth) | D6: =H4*0.568 -> 5284.6334
A7: Total Fuel Surchage Cost (0.075/rth) | D7: =H4*0.075 -> 697.7949
A8: Chilled Water Demand (2,866 AED/Day) | D8: 2866
A9: Grand Total Exc. VAT | D9: =SUM(D6:H8) -> 8848.4283
A10: Electrical
A11: MDB-G1 (39299675-8) | C11: Previous Reading KWH | D11: 44322 | E11: Current Reading KWH | F11: 44329 | G11: Consumption KWH | H11: =F11-D11 -> 7
A12: MDB-G2 (39299676-6) | C12: Previous Reading KWH | D12: 73782 | E12: Current Reading KWH | F12: 73795 | G12: Consumption KWH | H12: =F12-D12 -> 13
A13: MDB-G3 (39299677-4) | C13: Previous Reading KWH | D13: 74240 | E13: Current Reading KWH | F13: 74251 | G13: Consumption KWH | H13: =F13-D13 -> 11
H14: =SUM(H11:H13) -> 31
A15: Total Consumption * Multiplication Factor (487.20) | H15: =H14*487.2 -> 15103.2
A16: Cost Calculation
A17: 0-2000 kwh @ 0.230 /KWH | D17: 460
A18: 2000-4000 kwh @ 0.280 /KWH | D18: 560
A19: 4000-6000 kwh @ 0.320 /KWH | D19: 640
A20: 6000 & above @ 0.380 /KWH | D20: =H15*0.38 -> 5739.216
A21: Fuel Surcharge @ 0.060 /KWH | D21: =H15*0.06 -> 906.192
A22: Grand Total Exc. VAT | D22: =D20+D21 -> 6645.408
A23: WATER
A24: Previous Reading | B24: 337859 | C24: Present Reading | D24: 338071 | E24: Consumption m3 | F24: =D24-B24 -> 212 | G24: Consumption IG | H24: =F24*220 -> 46640
A25: Cost calculation
A26: 0-10000 @ 0.035 / IG | D26: 350
A27: 10000-20000 @ 0.04 / IG | D27: 400
A28: 20000 & above @ 0.046 / IG | D28: =(H24-20000)*0.046 -> 1225.44
A29: Fuel Surcharge @ 0.005 / IG | D29: =H24*0.005 -> 233.2
A30: Sewerage Fees | D30: =(H24*0.015)+170 -> 869.6
A31: Grand Total Exc. VAT | D31: =SUM(D26:H30) -> 3078.24
A32: LPG Gas
A33: Tank 1 (1% = 48 liters) | C33: Previous Reading % | D33: 38 | E33: Current Reading % | F33: 28 | G33: Consumption Liters | H33: =(D33-F33)*48.8 -> 488
A34: Tank 2 (1% = 48 liters) | C34: Previous Reading % | D34: 78 | E34: Current Reading % | F34: 78 | G34: Consumption Liters | H34: =(D34-F34)*48.8 -> 0
A35: 322908 | H35: =((H34+H33)*1.82)*0.5 -> 444.08
A36: Total Utilities | H36: =H35+D22+D9+D31 -> 19016.156

Sheet May 11
A1: Daily Utilities Consumption
A2: 11.05.2025
A3: District Cooling
A4: Previous Reading MWh | B4: 73270.81 | C4: Current Reading MWh | D4: 73307.13 | E4: Consumption MWH | F4: =D4-B4 -> 36.32 | G4: Consumption RTH | H4: =F4*284.35 -> 10327.592
A6: Total Cost (0.568/rth) | D6: =H4*0.568 -> 5866.0723
A7: Total Fuel Surchage Cost (0.075/rth) | D7: =H4*0.075 -> 774.5694
A8: Chilled Water Demand (2,866 AED/Day) | D8: 2866
A9: Grand Total Exc. VAT | D9: =SUM(D6:H8) -> 9506.6417
A10: Electrical
A11: MDB-G1 (39299675-8) | C11: Previous Reading KWH | D11: 44315 | E11: Current Reading KWH | F11: 44322 | G11: Consumption KWH | H11: =F11-D11 -> 7
A12: MDB-G2 (39299676-6) | C12: Previous Reading KWH | D12: 73769 | E12: Current Reading KWH | F12: 73782 | G12: Consumption KWH | H12: =F12-D12 -> 13
A13: MDB-G3 (39299677-4) | C13: Previous Reading KWH | D13: 74229 | E13: Current Reading KWH | F13: 74240 | G13: Consumption KWH | H13: =F13-D13 -> 11
H14: =SUM(H11:H13) -> 31
A15: Total Consumption * Multiplication Factor (487.20) | H15: =H14*487.2 -> 15103.2
A16: Cost Calculation
A17: 0-2000 kwh @ 0.230 /KWH | D17: 460
