Workbook

Sheet May 2025
A1: CAPITAL CENTRE ARJAAN UTILITIES CONSUMPTION - April 2025.
A2: DATE | B2: Electricity | T2: Water | Z2: LP Gas | AD2: District Cooling | AM2: Additional Info
B3: MDB #2 | D3: MDB #3 | G3: MDB #1 MDB-E | J3: MDB #1 SMDB Kitchen | L3: MDB #1 Fire Pump #1 | O3: MDB #1 Fire Pump #2 | R3: Total ELE Cons. KW | S3: Electricity AED | T3: Hotel Reading | U3: Water Cons. M3 | V3: Irrigation water BHP | W3: Water Cons. M3 | X3: Total Water Cons. M3 | Y3: Water AED | Z3: 1st Floor Kitchen | AB3: Gas AED | AC3: Gas Cylinder purchased (50 litres) | AD3: Hotel BTU Meter Energy Reading | AE3: District Cooling Cons. MWH | AF3: District Cooling Cons. Ton Hour | AG3: District Cooling Cons. AED | AH3: District Cooling Fixed Charge | AI3: District Cooling Total AED | AJ3: Bulk ETS Energy Meter Reading | AK3: ETS Cons. Ton Hours | AL3: ETS Cons. MWH | AM3: Hotel Occupancy % | AN3: Adl. & Chl.
B4: Reading | C4: Cons. | D4: Reading | E4: Cons. | F4: Hotel share 94.38 % | G4: Reading | H4: Cons. | I4: Hotel share 65.36 % | J4: Reading | K4: Cons. | L4: Reading | M4: Cons. | N4: Hotel share 50 % | O4: Reading | P4: Cons. | Q4: Hotel share 50 % | V4: To be deducted from Hotel Meter. | Z4: No of Cylinder | AA4: Cons. Ltrs
A5: 45778 | B5: 10002567 | C5: 2470 | D5: 24343877 | E5: 5694 | F5: =E5*0.9438 -> 5373.9972 | G5: 15761758 | H5: 3661 | I5: =H5*0.6536 -> 2392.8296 | J5: 3819110 | K5: 764 | L5: 1734 | M5: 0 | N5: =M5*0.5 -> 0 | O5: 1010 | P5: 0 | Q5: =P5*0.5 -> 0 | R5: =C5+F5+I5+K5+N5+Q5 -> 11000.827 | S5: =R5*0.2 -> 2200.1654 | T5: 87679 | U5: 83 | V5: 37836 | W5: 13 | X5: =U5-W5 -> 70 | Y5: =X5*7.84 -> 548.8 | Z5: 1 | AA5: =Z5*22.6796*1.96 -> 44.452016 | AB5: =AA5*2.7659 -> 122.94983 | AC5: 0 | AD5: 83299 | AE5: =AL5*0.66 -> 23.085899 | AF5: =IF(ISBLANK(AD5),"0 ",AE5*284.345) -> 6564.36 | AG5: =AF5*0.3449 -> 2264.0478 | AH5: =IF(ISBLANK(AD5),"0",1754*1608.73/12/31*0.66) -> 5006.264 | AI5: =AG5+AH5 -> 7270.3117 | AJ5: 2991124 | AK5: 9946 | AL5: =IF(ISBLANK(AK5),"0 ",AK5/284.345) -> 34.978635 | AM5: 0.9923 | AN5: 316
A6: 45779 | B6: 10005062 | C6: =IF(ISBLANK(B6),"0",B6-B5) -> 2495 | D6: 24349679 | E6: =IF(ISBLANK(D6),"0",D6-D5) -> 5802 | F6: =E6*0.9438 -> 5475.9276 | G6: 15765347 | H6: =IF(ISBLANK(G6),"0",G6-G5) -> 3589 | I6: =H6*0.6536 -> 2345.7704 | J6: 3819908 | K6: =IF(ISBLANK(J6),"0",J6-J5) -> 798 | L6: 1734 | M6: =IF(ISBLANK(L6),"0",L6-L5) -> 0 | N6: =M6*0.5 -> 0 | O6: 1010 | P6: =IF(ISBLANK(O6),"0",O6-O5) -> 0 | Q6: =P6*0.5 -> 0 | R6: =C6+F6+I6+K6+N6+Q6 -> 11114.698 | S6: =R6*0.2 -> 2222.9396 | T6: 87749 | U6: =IF(ISBLANK(T6),"0",T6-T5) -> 70 | V6: 37853 | W6: =IF(ISBLANK(V6),"0",V6-V5) -> 17 | X6: =U6-W6 -> 53 | Y6: =X6*7.84 -> 415.52 | Z6: 1 | AA6: =Z6*22.6796*1.96 -> 44.452016 | AB6: =AA6*2.7659 -> 122.94983 | AC6: 0 | AD6: 83311 | AE6: =AL6*0.66 -> 22.909494 | AF6: =IF(ISBLANK(AD6),"0 ",AE6*284.345) -> 6514.2 | AG6: =AF6*0.3449 -> 2246.7476 | AH6: =IF(ISBLANK(AD6),"0",1754*1608.73/12/31*0.66) -> 5006.264 | AI6: =AG6+AH6 -> 7253.0116 | AJ6: 3000994 | AK6: =IF(ISBLANK(AJ6),"0",AJ6-AJ5) -> 9870 | AL6: =IF(ISBLANK(AK6),"0 ",AK6/284.345) -> 34.711354 | AM6: 0.9768 | AN6: 316
A7: 45780 | B7: 10007561 | C7: =IF(ISBLANK(B7),"0",B7-B6) -> 2499 | D7: 24355168 | E7: =IF(ISBLANK(D7),"0",D7-D6) -> 5489 | F7: =E7*0.9438 -> 5180.5182 | G7: 15768851 | H7: =IF(ISBLANK(G7),"0",G7-G6) -> 3504 | I7: =H7*0.6536 -> 2290.2144 | J7: 3820752 | K7: =IF(ISBLANK(J7),"0",J7-J6) -> 844 | L7: 1749 | M7: =IF(ISBLANK(L7),"0",L7-L6) -> 15 | N7: =M7*0.5 -> 7.5 | O7: 1018 | P7: =IF(ISBLANK(O7),"0",O7-O6) -> 8 | Q7: =P7*0.5 -> 4 | R7: =C7+F7+I7+K7+N7+Q7 -> 10825.233 | S7: =R7*0.2 -> 2165.0465 | T7: 87838 | U7: =IF(ISBLANK(T7),"0",T7-T6) -> 89 | V7: 37866 | W7: =IF(ISBLANK(V7),"0",V7-V6) -> 13 | X7: =U7-W7 -> 76 | Y7: =X7*7.84 -> 595.84 | Z7: 1 | AA7: =Z7*22.6796*1.96 -> 44.452016 | AB7: =AA7*2.7659 -> 122.94983 | AC7: 5 | AD7: 83323 | AE7: =AL7*0.66 -> 21.328808 | AF7: =IF(ISBLANK(AD7),"0 ",AE7*284.345) -> 6064.74 | AG7: =AF7*0.3449 -> 2091.7288 | AH7: =IF(ISBLANK(AD7),"0",1754*1608.73/12/31*0.66) -> 5006.264 | AI7: =AG7+AH7 -> 7097.9928 | AJ7: 3010183 | AK7: =IF(ISBLANK(AJ7),"0",AJ7-AJ6) -> 9189 | AL7: =IF(ISBLANK(AK7),"0 ",AK7/284.345) -> 32.316376 | AM7: 0.9614 | AN7: 303
A8: 45781 | B8: 10010080 | C8: =IF(ISBLANK(B8),"0",B8-B7) -> 2519 | D8: 24360957 | E8: =IF(ISBLANK(D8),"0",D8-D7) -> 5789 | F8: =E8*0.9438 -> 5463.6582 | G8: 15772436 | H8: =IF(ISBLANK(G8),"0",G8-G7) -> 3585 | I8: =H8*0.6536 -> 2343.156 | J8: 3821591 | K8: =IF(ISBLANK(J8),"0",J8-J7) -> 839 | L8: 1749 | M8: =IF(ISBLANK(L8),"0",L8-L7) -> 0 | N8: =M8*0.5 -> 0 | O8: 1018 | P8: =IF(ISBLANK(O8),"0",O8-O7) -> 0 | Q8: =P8*0.5 -> 0 | R8: =C8+F8+I8+K8+N8+Q8 -> 11164.814 | S8: =R8*0.2 -> 2232.9628 | T8: 87924 | U8: =IF(ISBLANK(T8),"0",T8-T7) -> 86 | V8: 37882 | W8: =IF(ISBLANK(V8),"0",V8-V7) -> 16 | X8: =U8-W8 -> 70 | Y8: =X8*7.84 -> 548.8 | Z8: 1 | AA8: =Z8*22.6796*1.96 -> 44.452016 | AB8: =AA8*2.7659 -> 122.94983 | AC8: 0 | AD8: 83335 | AE8: =AL8*0.66 -> 22.187624 | AF8: =IF(ISBLANK(AD8),"0 ",AE8*284.345) -> 6308.94 | AG8: =AF8*0.3449 -> 2175.9534 | AH8: =IF(ISBLANK(AD8),"0",1754*1608.73/12/31*0.66) -> 5006.264 | AI8: =AG8+AH8 -> 7182.2174 | AJ8: 3019742 | AK8: =IF(ISBLANK(AJ8),"0",AJ8-AJ7) -> 9559 | AL8: =IF(ISBLANK(AK8),"0 ",AK8/284.345) -> 33.617612 | AM8: 0.9768 | AN8: 288
A9: 45782 | B9: 10012453 | C9: =IF(ISBLANK(B9),"0",B9-B8) -> 2373 | D9: 24366655 | E9: =IF(ISBLANK(D9),"0",D9-D8) -> 5698 | F9: =E9*0.9438 -> 5377.7724 | G9: 15776065 | H9: =IF(ISBLANK(G9),"0",G9-G8) -> 3629 | I9: =H9*0.6536 -> 2371.9144 | J9: 3822432 | K9: =IF(ISBLANK(J9),"0",J9-J8) -> 841 | L9: 1749 | M9: =IF(ISBLANK(L9),"0",L9-L8) -> 0 | N9: =M9*0.5 -> 0 | O9: 1018 | P9: =IF(ISBLANK(O9),"0",O9-O8) -> 0 | Q9: =P9*0.5 -> 0 | R9: =C9+F9+I9+K9+N9+Q9 -> 10963.687 | S9: =R9*0.2 -> 2192.7374 | T9: 87989 | U9: =IF(ISBLANK(T9),"0",T9-T8) -> 65 | V9: 37894 | W9: =IF(ISBLANK(V9),"0",V9-V8) -> 12 | X9: =U9-W9 -> 53 | Y9: =X9*7.84 -> 415.52 | Z9: 1 | AA9: =Z9*22.6796*1.96 -> 44.452016 | AB9: =AA9*2.7659 -> 122.94983 | AC9: 0 | AD9: 83347 | AE9: =AL9*0.66 -> 23.081257 | AF9: =IF(ISBLANK(AD9),"0 ",AE9*284.345) -> 6563.04 | AG9: =AF9*0.3449 -> 2263.5925 | AH9: =IF(ISBLANK(AD9),"0",1754*1608.73/12/31*0.66) -> 5006.264 | AI9: =AG9+AH9 -> 7269.8565 | AJ9: 3029686 | AK9: =IF(ISBLANK(AJ9),"0",AJ9-AJ8) -> 9944 | AL9: =IF(ISBLANK(AK9),"0 ",AK9/284.345) -> 34.971601 | AM9: 0.9768 | AN9: 292
A10: 45783 | B10: 10014789 | C10: =IF(ISBLANK(B10),"0",B10-B9) -> 2336 | D10: 24372190 | E10: =IF(ISBLANK(D10),"0",D10-D9) -> 5535 | F10: =E10*0.9438 -> 5223.933 | G10: 15779695 | H10: =IF(ISBLANK(G10),"0",G10-G9) -> 3630 | I10: =H10*0.6536 -> 2372.568 | J10: 3823279 | K10: =IF(ISBLANK(J10),"0",J10-J9) -> 847 | L10: 1749 | M10: =IF(ISBLANK(L10),"0",L10-L9) -> 0 | N10: =M10*0.5 -> 0 | O10: 1018 | P10: =IF(ISBLANK(O10),"0",O10-O9) -> 0 | Q10: =P10*0.5 -> 0 | R10: =C10+F10+I10+K10+N10+Q10 -> 10779.501 | S10: =R10*0.2 -> 2155.9002 | T10: 88068 | U10: =IF(ISBLANK(T10),"0",T10-T9) -> 79 | V10: 37916 | W10: =IF(ISBLANK(V10),"0",V10-V9) -> 22 | X10: =U10-W10 -> 57 | Y10: =X10*7.84 -> 446.88 | Z10: 1 | AA10: =Z10*22.6796*1.96 -> 44.452016 | AB10: =AA10*2.7659 -> 122.94983 | AC10: 0 | AD10: 83359 | AE10: =AL10*0.66 -> 24.740861 | AF10: =IF(ISBLANK(AD10),"0 ",AE10*284.345) -> 7034.94 | AG10: =AF10*0.3449 -> 2426.3508 | AH10: =IF(ISBLANK(AD10),"0",1754*1608.73/12/31*0.66) -> 5006.264 | AI10: =AG10+AH10 -> 7432.6148 | AJ10: 3040345 | AK10: =IF(ISBLANK(AJ10),"0",AJ10-AJ9) -> 10659 | AL10: =IF(ISBLANK(AK10),"0 ",AK10/284.345) -> 37.486152 | AM10: 0.9807 | AN10: 296
A11: 45784 | B11: 10017152 | C11: =IF(ISBLANK(B11),"0",B11-B10) -> 2363 | D11: 24378110 | E11: =IF(ISBLANK(D11),"0",D11-D10) -> 5920 | F11: =E11*0.9438 -> 5587.296 | G11: 15783305 | H11: =IF(ISBLANK(G11),"0",G11-G10) -> 3610 | I11: =H11*0.6536 -> 2359.496 | J11: 3824097 | K11: =IF(ISBLANK(J11),"0",J11-J10) -> 818 | L11: 1749 | M11: =IF(ISBLANK(L11),"0",L11-L10) -> 0 | N11: =M11*0.5 -> 0 | O11: 1018 | P11: =IF(ISBLANK(O11),"0",O11-O10) -> 0 | Q11: =P11*0.5 -> 0 | R11: =C11+F11+I11+K11+N11+Q11 -> 11127.792 | S11: =R11*0.2 -> 2225.5584 | T11: 88121 | U11: =IF(ISBLANK(T11),"0",T11-T10) -> 53 | V11: 37929 | W11: =IF(ISBLANK(V11),"0",V11-V10) -> 13 | X11: =U11-W11 -> 40 | Y11: =X11*7.84 -> 313.6 | Z11: 1 | AA11: =Z11*22.6796*1.96 -> 44.452016 | AB11: =AA11*2.7659 -> 122.94983 | AC11: 5 | AD11: 83371 | AE11: =AL11*0.66 -> 20.576764 | AF11: =IF(ISBLANK(AD11),"0 ",AE11*284.345) -> 5850.9 | AG11: =AF11*0.3449 -> 2017.9754 | AH11: =IF(ISBLANK(AD11),"0",1754*1608.73/12/31*0.66) -> 5006.264 | AI11: =AG11+AH11 -> 7024.2394 | AJ11: 3049210 | AK11: =IF(ISBLANK(AJ11),"0",AJ11-AJ10) -> 8865 | AL11: =IF(ISBLANK(AK11),"0 ",AK11/284.345) -> 31.176915 | AM11: 0.9614 | AN11: 296
A12: 45785 | B12: 10019454 | C12: =IF(ISBLANK(B12),"0",B12-B11) -> 2302 | D12: 24384391 | E12: =IF(ISBLANK(D12),"0",D12-D11) -> 6281 | F12: =E12*0.9438 -> 5928.0078 | G12: 15786684 | H12: =IF(ISBLANK(G12),"0",G12-G11) -> 3379 | I12: =H12*0.6536 -> 2208.5144 | J12: 3824983 | K12: =IF(ISBLANK(J12),"0",J12-J11) -> 886 | L12: 1749 | M12: =IF(ISBLANK(L12),"0",L12-L11) -> 0 | N12: =M12*0.5 -> 0 | O12: 1018 | P12: =IF(ISBLANK(O12),"0",O12-O11) -> 0 | Q12: =P12*0.5 -> 0 | R12: =C12+F12+I12+K12+N12+Q12 -> 11324.522 | S12: =R12*0.2 -> 2264.9044 | T12: 88194 | U12: =IF(ISBLANK(T12),"0",T12-T11) -> 73 | V12: 37942 | W12: =IF(ISBLANK(V12),"0",V12-V11) -> 13 | X12: =U12-W12 -> 60 | Y12: =X12*7.84 -> 470.4 | Z12: 1 | AA12: =Z12*22.6796*1.96 -> 44.452016 | AB12: =AA12*2.7659 -> 122.94983 | AC12: 0 | AD12: 83383 | AE12: =AL12*0.66 -> 19.490478 | AF12: =IF(ISBLANK(AD12),"0 ",AE12*284.345) -> 5542.02 | AG12: =AF12*0.3449 -> 1911.4427 | AH12: =IF(ISBLANK(AD12),"0",1754*1608.73/12/31*0.66) -> 5006.264 | AI12: =AG12+AH12 -> 6917.7067 | AJ12: 3057607 | AK12: =IF(ISBLANK(AJ12),"0",AJ12-AJ11) -> 8397 | AL12: =IF(ISBLANK(AK12),"0 ",AK12/284.345) -> 29.531027 | AM12: 0.8378 | AN12: 259
A13: 45786 | B13: 10021738 | C13: =IF(ISBLANK(B13),"0",B13-B12) -> 2284 | D13: 24390759 | E13: =IF(ISBLANK(D13),"0",D13-D12) -> 6368 | F13: =E13*0.9438 -> 6010.1184 | G13: 15789707 | H13: =IF(ISBLANK(G13),"0",G13-G12) -> 3023 | I13: =H13*0.6536 -> 1975.8328 | J13: 3825827 | K13: =IF(ISBLANK(J13),"0",J13-J12) -> 844 | L13: 1749 | M13: =IF(ISBLANK(L13),"0",L13-L12) -> 0 | N13: =M13*0.5 -> 0 | O13: 1018 | P13: =IF(ISBLANK(O13),"0",O13-O12) -> 0 | Q13: =P13*0.5 -> 0 | R13: =C13+F13+I13+K13+N13+Q13 -> 11113.951 | S13: =R13*0.2 -> 2222.7902 | T13: 88267 | U13: =IF(ISBLANK(T13),"0",T13-T12) -> 73 | V13: 37963 | W13: =IF(ISBLANK(V13),"0",V13-V12) -> 21 | X13: =U13-W13 -> 52 | Y13: =X13*7.84 -> 407.68 | Z13: 1 | AA13: =Z13*22.6796*1.96 -> 44.452016 | AB13: =AA13*2.7659 -> 122.94983 | AC13: 0 | AD13: 83395 | AE13: =AL13*0.66 -> 20.105576 | AF13: =IF(ISBLANK(AD13),"0 ",AE13*284.345) -> 5716.92 | AG13: =AF13*0.3449 -> 1971.7657 | AH13: =IF(ISBLANK(AD13),"0",1754*1608.73/12/31*0.66) -> 5006.264 | AI13: =AG13+AH13 -> 6978.0297 | AJ13: 3066269 | AK13: =IF(ISBLANK(AJ13),"0",AJ13-AJ12) -> 8662 | AL13: =IF(ISBLANK(AK13),"0 ",AK13/284.345) -> 30.462994 | AM13: 0.81 | AN13: 254
A14: 45787 | B14: 10024121 | C14: =IF(ISBLANK(B14),"0",B14-B13) -> 2383 | D14: 24396717 | E14: =IF(ISBLANK(D14),"0",D14-D13) -> 5958 | F14: =E14*0.9438 -> 5623.1604 | G14: 15792599 | H14: =IF(ISBLANK(G14),"0",G14-G13) -> 2892 | I14: =H14*0.6536 -> 1890.2112 | J14: 3826696 | K14: =IF(ISBLANK(J14),"0",J14-J13) -> 869 | L14: 1762 | M14: =IF(ISBLANK(L14),"0",L14-L13) -> 13 | N14: =M14*0.5 -> 6.5 | O14: 1028 | P14: =IF(ISBLANK(O14),"0",O14-O13) -> 10 | Q14: =P14*0.5 -> 5 | R14: =C14+F14+I14+K14+N14+Q14 -> 10776.872 | S14: =R14*0.2 -> 2155.3743 | T14: 88339 | U14: =IF(ISBLANK(T14),"0",T14-T13) -> 72 | V14: 37976 | W14: =IF(ISBLANK(V14),"0",V14-V13) -> 13 | X14: =U14-W14 -> 59 | Y14: =X14*7.84 -> 462.56 | Z14: 2 | AA14: =Z14*22.6796*1.96 -> 88.904032 | AB14: =AA14*2.7659 -> 245.89966 | AC14: 0 | AD14: 83407 | AE14: =AL14*0.66 -> 20.711389 | AF14: =IF(ISBLANK(AD14),"0 ",AE14*284.345) -> 5889.18 | AG14: =AF14*0.3449 -> 2031.1782 | AH14: =IF(ISBLANK(AD14),"0",1754*1608.73/12/31*0.66) -> 5006.264 | AI14: =AG14+AH14 -> 7037.4422 | AJ14: 3075192 | AK14: =IF(ISBLANK(AJ14),"0",AJ14-AJ13) -> 8923 | AL14: =IF(ISBLANK(AK14),"0 ",AK14/284.345) -> 31.380893 | AM14: 0.81 | AN14: 212
A15: 45788 | B15: 10026533 | C15: =IF(ISBLANK(B15),"0",B15-B14) -> 2412 | D15: 24402674 | E15: =IF(ISBLANK(D15),"0",D15-D14) -> 5957 | F15: =E15*0.9438 -> 5622.2166 | G15: 15795473 | H15: =IF(ISBLANK(G15),"0",G15-G14) -> 2874 | I15: =H15*0.6536 -> 1878.4464 | J15: 3827549 | K15: =IF(ISBLANK(J15),"0",J15-J14) -> 853 | L15: 1762 | M15: =IF(ISBLANK(L15),"0",L15-L14) -> 0 | N15: =M15*0.5 -> 0 | O15: 1028 | P15: =IF(ISBLANK(O15),"0",O15-O14) -> 0 | Q15: =P15*0.5 -> 0 | R15: =C15+F15+I15+K15+N15+Q15 -> 10765.663 | S15: =R15*0.2 -> 2153.1326 | T15: 88408 | U15: =IF(ISBLANK(T15),"0",T15-T14) -> 69 | V15: 37990 | W15: =IF(ISBLANK(V15),"0",V15-V14) -> 14 | X15: =U15-W15 -> 55 | Y15: =X15*7.84 -> 431.2 | Z15: 1 | AA15: =Z15*22.6796*1.96 -> 44.452016 | AB15: =AA15*2.7659 -> 122.94983 | AC15: 0 | AD15: 83419 | AE15: =AL15*0.66 -> 22.187624 | AF15: =IF(ISBLANK(AD15),"0 ",AE15*284.345) -> 6308.94 | AG15: =AF15*0.3449 -> 2175.9534 | AH15: =IF(ISBLANK(AD15),"0",1754*1608.73/12/31*0.66) -> 5006.264 | AI15: =AG15+AH15 -> 7182.2174 | AJ15: 3084751 | AK15: =IF(ISBLANK(AJ15),"0",AJ15-AJ14) -> 9559 | AL15: =IF(ISBLANK(AK15),"0 ",AK15/284.345) -> 33.617612 | AM15: 0.8069 | AN15: 238
A16: 45789 | B16: 10028897 | C16: =IF(ISBLANK(B16),"0",B16-B15) -> 2364 | D16: 24408717 | E16: =IF(ISBLANK(D16),"0",D16-D15) -> 6043 | F16: =E16*0.9438 -> 5703.3834 | G16: 15798211 | H16: =IF(ISBLANK(G16),"0",G16-G15) -> 2738 | I16: =H16*0.6536 -> 1789.5568 | J16: 3828375 | K16: =IF(ISBLANK(J16),"0",J16-J15) -> 826 | L16: 1762 | M16: =IF(ISBLANK(L16),"0",L16-L15) -> 0 | N16: =M16*0.5 -> 0 | O16: 1028 | P16: =IF(ISBLANK(O16),"0",O16-O15) -> 0 | Q16: =P16*0.5 -> 0 | R16: =C16+F16+I16+K16+N16+Q16 -> 10682.94 | S16: =R16*0.2 -> 2136.588 | T16: 88476 | U16: =IF(ISBLANK(T16),"0",T16-T15) -> 68 | V16: 38003 | W16: =IF(ISBLANK(V16),"0",V16-V15) -> 13 | X16: =U16-W16 -> 55 | Y16: =X16*7.84 -> 431.2 | Z16: 1 | AA16: =Z16*22.6796*1.96 -> 44.452016 | AB16: =AA16*2.7659 -> 122.94983 | AC16: 5 | AD16: 83431 | AE16: =AL16*0.66 -> 21.47736 | AF16: =IF(ISBLANK(AD16),"0 ",AE16*284.345) -> 6106.98 | AG16: =AF16*0.3449 -> 2106.2974 | AH16: =IF(ISBLANK(AD16),"0",1754*1608.73/12/31*0.66) -> 5006.264 | AI16: =AG16+AH16 -> 7112.5614 | AJ16: 3094004 | AK16: =IF(ISBLANK(AJ16),"0",AJ16-AJ15) -> 9253 | AL16: =IF(ISBLANK(AK16),"0 ",AK16/284.345) -> 32.541455 | AM16: 0.89 | AN16: 233
A17: 45790 | B17: 10031163 | C17: =IF(ISBLANK(B17),"0",B17-B16) -> 2266 | D17: 24414365 | E17: =IF(ISBLANK(D17),"0",D17-D16) -> 5648 | F17: =E17*0.9438 -> 5330.5824 | G17: 15800906 | H17: =IF(ISBLANK(G17),"0",G17-G16) -> 2695 | I17: =H17*0.6536 -> 1761.452 | J17: 3829147 | K17: =IF(ISBLANK(J17),"0",J17-J16) -> 772 | L17: 1762 | M17: =IF(ISBLANK(L17),"0",L17-L16) -> 0 | N17: =M17*0.5 -> 0 | O17: 1028 | P17: =IF(ISBLANK(O17),"0",O17-O16) -> 0 | Q17: =P17*0.5 -> 0 | R17: =C17+F17+I17+K17+N17+Q17 -> 10130.034 | S17: =R17*0.2 -> 2026.0069 | T17: 88518 | U17: =IF(ISBLANK(T17),"0",T17-T16) -> 42 | V17: 38018 | W17: =IF(ISBLANK(V17),"0",V17-V16) -> 15 | X17: =U17-W17 -> 27 | Y17: =X17*7.84 -> 211.68 | Z17: 1 | AA17: =Z17*22.6796*1.96 -> 44.452016 | AB17: =AA17*2.7659 -> 122.94983 | AC17: 0 | AD17: 83443 | AE17: =AL17*0.66 -> 20.576764 | AF17: =IF(ISBLANK(AD17),"0 ",AE17*284.345) -> 5850.9 | AG17: =AF17*0.3449 -> 2017.9754 | AH17: =IF(ISBLANK(AD17),"0",1754*1608.73/12/31*0.66) -> 5006.264 | AI17: =AG17+AH17 -> 7024.2394 | AJ17: 3102869 | AK17: =IF(ISBLANK(AJ17),"0",AJ17-AJ16) -> 8865 | AL17: =IF(ISBLANK(AK17),"0 ",AK17/284.345) -> 31.176915 | AM17: 0.9459 | AN17: 273
... A27: 45800 | B27: 10055680 | C27: =IF(ISBLANK(B27),"0",B27-B26) -> 2422 | D27: 24471141 | E27: =IF(ISBLANK(D27),"0",D27-D26) -> 5969 | F27: =E27*0.9438 -> 5633.5422 | G27: 15830580 | H27: =IF(ISBLANK(G27),"0",G27-G26) -> 3005 | I27: =H27*0.6536 -> 1964.068 | J27: 3837797 | K27: =IF(ISBLANK(J27),"0",J27-J26) -> 859 | L27: 1784 | M27: =IF(ISBLANK(L27),"0",L27-L26) -> 0 | N27: =M27*0.5 -> 0 | O27: 1042 | P27: =IF(ISBLANK(O27),"0",O27-O26) -> 0 | Q27: =P27*0.5 -> 0 | R27: =C27+F27+I27+K27+N27+Q27 -> 10878.61 | S27: =R27*0.2 -> 2175.722 | T27: 89308 | U27: =IF(ISBLANK(T27),"0",T27-T26) -> 84 | V27: 38163 | W27: =IF(ISBLANK(V27),"0",V27-V26) -> 21 | X27: =U27-W27 -> 63 | Y27: =X27*7.84 -> 493.92 | Z27: 2 | AA27: =Z27*22.6796*1.96 -> 88.904032 | AB27: =AA27*2.7659 -> 245.89966 | AC27: 0 | AD27: 83563 | AE27: =AL27*0.66 -> 24.689796 | AF27: =IF(ISBLANK(AD27),"0 ",AE27*284.345) -> 7020.42 | AG27: =AF27*0.3449 -> 2421.3429 | AH27: =IF(ISBLANK(AD27),"0",1754*1608.73/12/31*0.66) -> 5006.264 | AI27: =AG27+AH27 -> 7427.6068 | AJ27: 3202146 | AK27: =IF(ISBLANK(AJ27),"0",AJ27-AJ26) -> 10637 | AL27: =IF(ISBLANK(AK27),"0 ",AK27/284.345) -> 37.408782 | AM27: 0.89 | AN27: 231
A28: 45801 | B28: 10058173 | C28: =IF(ISBLANK(B28),"0",B28-B27) -> 2493 | D28: 24476979 | E28: =IF(ISBLANK(D28),"0",D28-D27) -> 5838 | F28: =E28*0.9438 -> 5509.9044 | G28: 15833494 | H28: =IF(ISBLANK(G28),"0",G28-G27) -> 2914 | I28: =H28*0.6536 -> 1904.5904 | J28: 3838635 | K28: =IF(ISBLANK(J28),"0",J28-J27) -> 838 | L28: 1809 | M28: 0 | N28: =M28*0.5 -> 0 | O28: 1054 | P28: =IF(ISBLANK(O28),"0",O28-O27) -> 12 | Q28: =P28*0.5 -> 6 | R28: =C28+F28+I28+K28+N28+Q28 -> 10751.495 | S28: =R28*0.2 -> 2150.299 | T28: 89367 | U28: =IF(ISBLANK(T28),"0",T28-T27) -> 59 | V28: 38176 | W28: =IF(ISBLANK(V28),"0",V28-V27) -> 13 | X28: =U28-W28 -> 46 | Y28: =X28*7.84 -> 360.64 | Z28: 1 | AA28: =Z28*22.6796*1.96 -> 44.452016 | AB28: =AA28*2.7659 -> 122.94983 | AC28: 0 | AD28: 83575 | AE28: =AL28*0.66 -> 22.795759 | AF28: =IF(ISBLANK(AD28),"0 ",AE28*284.345) -> 6481.86 | AG28: =AF28*0.3449 -> 2235.5935 | AH28: =IF(ISBLANK(AD28),"0",1754*1608.73/12/31*0.66) -> 5006.264 | AI28: =AG28+AH28 -> 7241.8575 | AJ28: 3211967 | AK28: =IF(ISBLANK(AJ28),"0",AJ28-AJ27) -> 9821 | AL28: =IF(ISBLANK(AK28),"0 ",AK28/284.345) -> 34.539028 | AM28: 0.96 | AN28: 250
A29: 45802 | B29: 10060676 | C29: =IF(ISBLANK(B29),"0",B29-B28) -> 2503 | D29: 24482753 | E29: =IF(ISBLANK(D29),"0",D29-D28) -> 5774 | F29: =E29*0.9438 -> 5449.5012 | G29: 15836448 | H29: =IF(ISBLANK(G29),"0",G29-G28) -> 2954 | I29: =H29*0.6536 -> 1930.7344 | J29: 3839435 | K29: =IF(ISBLANK(J29),"0",J29-J28) -> 800 | L29: 1809 | M29: =IF(ISBLANK(L29),"0",L29-L28) -> 0 | N29: =M29*0.5 -> 0 | O29: 1054 | P29: =IF(ISBLANK(O29),"0",O29-O28) -> 0 | Q29: =P29*0.5 -> 0 | R29: =C29+F29+I29+K29+N29+Q29 -> 10683.236 | S29: =R29*0.2 -> 2136.6471 | T29: 89488 | U29: =IF(ISBLANK(T29),"0",T29-T28) -> 121 | V29: 38198 | W29: =IF(ISBLANK(V29),"0",V29-V28) -> 22 | X29: =U29-W29 -> 99 | Y29: =X29*7.84 -> 776.16 | Z29: 1 | AA29: =Z29*22.6796*1.96 -> 44.452016 | AB29: =AA29*2.7659 -> 122.94983 | AC29: 4 | AD29: 83587 | AE29: =AL29*0.66 -> 22.705235 | AF29: =IF(ISBLANK(AD29),"0 ",AE29*284.345) -> 6456.12 | AG29: =AF29*0.3449 -> 2226.7158 | AH29: =IF(ISBLANK(AD29),"0",1754*1608.73/12/31*0.66) -> 5006.264 | AI29: =AG29+AH29 -> 7232.9798 | AJ29: 3221749 | AK29: =IF(ISBLANK(AJ29),"0",AJ29-AJ28) -> 9782 | AL29: =IF(ISBLANK(AK29),"0 ",AK29/284.345) -> 34.401871 | AM29: 0.91 | AN29: 238
A30: 45803 | B30: 10063173 | C30: =IF(ISBLANK(B30),"0",B30-B29) -> 2497 | D30: 24488329 | E30: =IF(ISBLANK(D30),"0",D30-D29) -> 5576 | F30: =E30*0.9438 -> 5262.6288 | G30: 15839514 | H30: =IF(ISBLANK(G30),"0",G30-G29) -> 3066 | I30: =H30*0.6536 -> 2003.9376 | J30: 3840299 | K30: =IF(ISBLANK(J30),"0",J30-J29) -> 864 | L30: 1809 | M30: =IF(ISBLANK(L30),"0",L30-L29) -> 0 | N30: =M30*0.5 -> 0 | O30: 1054 | P30: =IF(ISBLANK(O30),"0",O30-O29) -> 0 | Q30: =P30*0.5 -> 0 | R30: =C30+F30+I30+K30+N30+Q30 -> 10627.566 | S30: =R30*0.2 -> 2125.5133 | T30: 89540 | U30: =IF(ISBLANK(T30),"0",T30-T29) -> 52 | V30: 38211 | W30: =IF(ISBLANK(V30),"0",V30-V29) -> 13 | X30: =U30-W30 -> 39 | Y30: =X30*7.84 -> 305.76 | Z30: 2 | AA30: =Z30*22.6796*1.96 -> 88.904032 | AB30: =AA30*2.7659 -> 245.89966 | AC30: 0 | AD30: 83059 | AE30: =AL30*0.66 -> 25.348995 | AF30: =IF(ISBLANK(AD30),"0 ",AE30*284.345) -> 7207.86 | AG30: =AF30*0.3449 -> 2485.9909 | AH30: =IF(ISBLANK(AD30),"0",1754*1608.73/12/31*0.66) -> 5006.264 | AI30: =AG30+AH30 -> 7492.2549 | AJ30: 3232670 | AK30: =IF(ISBLANK(AJ30),"0",AJ30-AJ29) -> 10921 | AL30: =IF(ISBLANK(AK30),"0 ",AK30/284.345) -> 38.407568 | AM30: 0.88 | AN30: 254
A31: 45804 | B31: 10065533 | C31: =IF(ISBLANK(B31),"0",B31-B30) -> 2360 | D31: 24493952 | E31: =IF(ISBLANK(D31),"0",D31-D30) -> 5623 | F31: =E31*0.9438 -> 5306.9874 | G31: 15842494 | H31: =IF(ISBLANK(G31),"0",G31-G30) -> 2980 | I31: =H31*0.6536 -> 1947.728 | J31: 3841162 | K31: =IF(ISBLANK(J31),"0",J31-J30) -> 863 | L31: 1809 | M31: =IF(ISBLANK(L31),"0",L31-L30) -> 0 | N31: =M31*0.5 -> 0 | O31: 1054 | P31: =IF(ISBLANK(O31),"0",O31-O30) -> 0 | Q31: =P31*0.5 -> 0 | R31: =C31+F31+I31+K31+N31+Q31 -> 10477.715 | S31: =R31*0.2 -> 2095.5431 | T31: 89612 | U31: =IF(ISBLANK(T31),"0",T31-T30) -> 72 | V31: 38223 | W31: =IF(ISBLANK(V31),"0",V31-V30) -> 12 | X31: =U31-W31 -> 60 | Y31: =X31*7.84 -> 470.4 | Z31: 1 | AA31: =Z31*22.6796*1.96 -> 44.452016 | AB31: =AA31*2.7659 -> 122.94983 | AC31: 0 | AD31: 83080 | AE31: =AL31*0.66 -> 23.009302 | AF31: =IF(ISBLANK(AD31),"0 ",AE31*284.345) -> 6542.58 | AG31: =AF31*0.3449 -> 2256.5358 | AH31: =IF(ISBLANK(AD31),"0",1754*1608.73/12/31*0.66) -> 5006.264 | AI31: =AG31+AH31 -> 7262.7998 | AJ31: 3242583 | AK31: =IF(ISBLANK(AJ31),"0",AJ31-AJ30) -> 9913 | AL31: =IF(ISBLANK(AK31),"0 ",AK31/284.345) -> 34.862579 | AM31: 0.89 | AN31: 256
A32: 45805 | B32: 10067944 | C32: =IF(ISBLANK(B32),"0",B32-B31) -> 2411 | D32: 24499449 | E32: =IF(ISBLANK(D32),"0",D32-D31) -> 5497 | F32: =E32*0.9438 -> 5188.0686 | G32: 15845472 | H32: =IF(ISBLANK(G32),"0",G32-G31) -> 2978 | I32: =H32*0.6536 -> 1946.4208 | J32: 3842013 | K32: =IF(ISBLANK(J32),"0",J32-J31) -> 851 | L32: 1809 | M32: =IF(ISBLANK(L32),"0",L32-L31) -> 0 | N32: =M32*0.5 -> 0 | O32: 1054 | P32: =IF(ISBLANK(O32),"0",O32-O31) -> 0 | Q32: =P32*0.5 -> 0 | R32: =C32+F32+I32+K32+N32+Q32 -> 10396.489 | S32: =R32*0.2 -> 2079.2979 | T32: 89697 | U32: =IF(ISBLANK(T32),"0",T32-T31) -> 85 | V32: 38241 | W32: =IF(ISBLANK(V32),"0",V32-V31) -> 18 | X32: =U32-W32 -> 67 | Y32: =X32*7.84 -> 525.28 | Z32: 1 | AA32: =Z32*22.6796*1.96 -> 44.452016 | AB32: =AA32*2.7659 -> 122.94983 | AC32: 0 | AD32: 83103 | AE32: =AL32*0.66 -> 24.392692 | AF32: =IF(ISBLANK(AD32),"0 ",AE32*284.345) -> 6935.94 | AG32: =AF32*0.3449 -> 2392.2057 | AH32: =IF(ISBLANK(AD32),"0",1754*1608.73/12/31*0.66) -> 5006.264 | AI32: =AG32+AH32 -> 7398.4697 | AJ32: 3253092 | AK32: =IF(ISBLANK(AJ32),"0",AJ32-AJ31) -> 10509 | AL32: =IF(ISBLANK(AK32),"0 ",AK32/284.345) -> 36.958624 | AM32: 0.8888 | AN32: 230
A33: 45806 | B33: 10070295 | C33: =IF(ISBLANK(B33),"0",B33-B32) -> 2351 | D33: 24504826 | E33: =IF(ISBLANK(D33),"0",D33-D32) -> 5377 | F33: =E33*0.9438 -> 5074.8126 | G33: 15848373 | H33: =IF(ISBLANK(G33),"0",G33-G32) -> 2901 | I33: =H33*0.6536 -> 1896.0936 | J33: 3842833 | K33: =IF(ISBLANK(J33),"0",J33-J32) -> 820 | L33: 1809 | M33: =IF(ISBLANK(L33),"0",L33-L32) -> 0 | N33: =M33*0.5 -> 0 | O33: 1054 | P33: =IF(ISBLANK(O33),"0",O33-O32) -> 0 | Q33: =P33*0.5 -> 0 | R33: =C33+F33+I33+K33+N33+Q33 -> 10141.906 | S33: =R33*0.2 -> 2028.3812 | T33: 89759 | U33: =IF(ISBLANK(T33),"0",T33-T32) -> 62 | V33: 38254 | W33: =IF(ISBLANK(V33),"0",V33-V32) -> 13 | X33: =U33-W33 -> 49 | Y33: =X33*7.84 -> 384.16 | Z33: 1 | AA33: =Z33*22.6796*1.96 -> 44.452016 | AB33: =AA33*2.7659 -> 122.94983 | AC33: 4 | AD33: 83126 | AE33: =AL33*0.66 -> 24.420545 | AF33: =IF(ISBLANK(AD33),"0 ",AE33*284.345) -> 6943.86 | AG33: =AF33*0.3449 -> 2394.9373 | AH33: =IF(ISBLANK(AD33),"0",1754*1608.73/12/31*0.66) -> 5006.264 | AI33: =AG33+AH33 -> 7401.2013 | AJ33: 3263613 | AK33: =IF(ISBLANK(AJ33),"0",AJ33-AJ32) -> 10521 | AL33: =IF(ISBLANK(AK33),"0 ",AK33/284.345) -> 37.000826 | AM33: 0.7954 | AN33: 236
A34: 45807 | B34: 10072673 | C34: =IF(ISBLANK(B34),"0",B34-B33) -> 2378 | D34: 24510290 | E34: =IF(ISBLANK(D34),"0",D34-D33) -> 5464 | F34: =E34*0.9438 -> 5156.9232 | G34: 15851447 | H34: =IF(ISBLANK(G34),"0",G34-G33) -> 3074 | I34: =H34*0.6536 -> 2009.1664 | J34: 3843626 | K34: =IF(ISBLANK(J34),"0",J34-J33) -> 793 | L34: 1809 | M34: =IF(ISBLANK(L34),"0",L34-L33) -> 0 | N34: =M34*0.5 -> 0 | O34: 1054 | P34: =IF(ISBLANK(O34),"0",O34-O33) -> 0 | Q34: =P34*0.5 -> 0 | R34: =C34+F34+I34+K34+N34+Q34 -> 10337.09 | S34: =R34*0.2 -> 2067.4179 | T34: 89835 | U34: =IF(ISBLANK(T34),"0",T34-T33) -> 76 | V34: 38271 | W34: =IF(ISBLANK(V34),"0",V34-V33) -> 17 | X34: =U34-W34 -> 59 | Y34: =X34*7.84 -> 462.56 | Z34: 1 | AA34: =Z34*22.6796*1.96 -> 44.452016 | AB34: =AA34*2.7659 -> 122.94983 | AC34: 0 | AD34: 83148 | AE34: =AL34*0.66 -> 23.842586 | AF34: =IF(ISBLANK(AD34),"0 ",AE34*284.345) -> 6779.52 | AG34: =AF34*0.3449 -> 2338.2564 | AH34: =IF(ISBLANK(AD34),"0",1754*1608.73/12/31*0.66) -> 5006.264 | AI34: =AG34+AH34 -> 7344.5204 | AJ34: 3273885 | AK34: =IF(ISBLANK(AJ34),"0",AJ34-AJ33) -> 10272 | AL34: =IF(ISBLANK(AK34),"0 ",AK34/284.345) -> 36.12513 | AM34: 0.7992 | AN34: 207
A35: 45808 | B35: 10075080 | C35: =IF(ISBLANK(B35),"0",B35-B34) -> 2407 | D35: 24515606 | E35: =IF(ISBLANK(D35),"0",D35-D34) -> 5316 | F35: =E35*0.9438 -> 5017.2408 | G35: 15854348 | H35: =IF(ISBLANK(G35),"0",G35-G34) -> 2901 | I35: =H35*0.6536 -> 1896.0936 | J35: 3844401 | K35: =IF(ISBLANK(J35),"0",J35-J34) -> 775 | L35: 1834 | M35: =IF(ISBLANK(L35),"0",L35-L34) -> 25 | N35: =M35*0.5 -> 12.5 | O35: 1063 | P35: =IF(ISBLANK(O35),"0",O35-O34) -> 9 | Q35: =P35*0.5 -> 4.5 | R35: =C35+F35+I35+K35+N35+Q35 -> 10112.334 | S35: =R35*0.2 -> 2022.4669 | T35: 89894 | U35: =IF(ISBLANK(T35),"0",T35-T34) -> 59 | V35: 38284 | W35: =IF(ISBLANK(V35),"0",V35-V34) -> 13 | X35: =U35-W35 -> 46 | Y35: =X35*7.84 -> 360.64 | Z35: 2 | AA35: =Z35*22.6796*1.96 -> 88.904032 | AB35: =AA35*2.7659 -> 245.89966 | AC35: 0 | AD35: 83171 | AE35: =AL35*0.66 -> 23.571014 | AF35: =IF(ISBLANK(AD35),"0 ",AE35*284.345) -> 6702.3 | AG35: =AF35*0.3449 -> 2311.6233 | AH35: =IF(ISBLANK(AD35),"0",1754*1608.73/12/31*0.66) -> 5006.264 | AI35: =AG35+AH35 -> 7317.8872 | AJ35: 3284040 | AK35: =IF(ISBLANK(AJ35),"0",AJ35-AJ34) -> 10155 | AL35: =IF(ISBLANK(AK35),"0 ",AK35/284.345) -> 35.713658 | AM35: 0.861 | AN35: 223
C36: =SUM(C5:C35) -> 74983 | F36: =SUM(F5:F35) -> 167451.83 | I36: =SUM(I5:I35) -> 62909.654 | K36: =SUM(K5:K35) -> 26055 | N36: =SUM(N5:N35) -> 37.5 | Q36: =SUM(Q5:Q35) -> 26.5 | R36: =SUM(R5:R35) -> 331463.48 | S36: =R36*0.2 -> 66292.696 | U36: =SUM(U5:U35) -> 2298 | W36: =SUM(W5:W35) -> 461 | X36: =SUM(X5:X35) -> 1837 | Y36: =SUM(Y5:Y35) -> 14402.08 | Z36: =SUM(Z5:Z35) -> 35 | AA36: =SUM(AA5:AA35) -> 1555.8206 | AB36: =SUM(AB5:AB35) -> 4303.2441 | AC36: =SUM(AC5:AC35) -> 36 | AE36: =SUM(AE5:AE35) -> 702.98025 | AF36: =SUM(AF5:AF35) -> 199888.92 | AG36: =SUM(AG5:AG35) -> 68941.689 | AH36: =SUM(AH5:AH35) -> 155194.18 | AI36: =SUM(AI5:AI35) -> 224135.87 | AK36: =SUM(AK5:AK35) -> 302862 | AL36: =SUM(AL5:AL35) -> 1065.1216 | AM36: =AVERAGE(AM5:AM35) -> 0.91437419 | AN36: =SUM(AN5:AN35) -> 8158
AD37: AVT Charges should be Zero in the DC invoice - Please notify if not
B38: Electricity | G38: AED | K38: KW | T38: Water | V38: AED | X38: M3 | Z38: Gas | AA38: AED | AB38: Litres | AD38: District Cooling | AF38: AED | AH38: Ton Hour
B39: Actual May 2025 | G39: =S36 -> 66292.696 | K39: =G39/0.2 -> 331463.48 | T39: =B39 -> Actual May 2025 | V39: =Y36 -> 14402.08 | X39: =X36 -> 1837 | Z39: =T39 -> Actual May 2025 | AA39: =AB36 -> 4303.2441 | AB39: =AA39/1.2551 -> 3428.6066 | AD39: =T39 -> Actual May 2025 | AF39: =AI36 -> 224135.87 | AH39: =AF36 -> 199888.92 | AI39: =(AD39-#REF!)/0.3428 -> #VALUE! | AP39: 149225.58
B40: Budget May 2025 | G40: 78253.452 | K40: =G40/0.2 -> 391267.26 | T40: =B40 -> Budget May 2025 | V40: 16955.39 | X40: =V40/7.84 -> 2162.6773 | Z40: =T40 -> Budget May 2025 | AA40: 5099.2305 | AB40: =AA40/1.2551 -> 4062.8081 | AD40: =T40 -> Budget May 2025 | AF40: 231114.47 | AH40: =AP40/0.3449 -> 220122.62 | AI40: =(AD40-AF36)/0.3428 -> #VALUE! | AP40: =AF40-AH36 -> 75920.291 | AQ40: CHW Consumption Charges (Budget 2025 MTD)
B41: Actual YTD 2025 | G41: =G39+280292.91 -> 346585.61 | K41: =G41/0.2 -> 1732928 | T41: =B41 -> Actual YTD 2025 | V41: =V39+55624.8 -> 70026.88 | X41: =V41/7.84 -> 8932 | Z41: =T41 -> Actual YTD 2025 | AA41: =AA39+17588.97 -> 21892.214 | AB41: =AA41/1.2551 -> 17442.605 | AD41: =T41 -> Actual YTD 2025 | AF41: =AF39+755427.67 -> 979563.54 | AH41: =AP41/0.3449 -> 2390169.2 | AP41: =AF41-AP46 -> 824369.36 | AQ41: CHW Consumption Charges (Actual 2025 YTD)
B42: Budget YTD 2025 | G42: =295196.16+G40 -> 373449.61 | K42: =G42/0.2 -> 1867248.1 | T42: =B42 -> Budget YTD 2025 | V42: =58693.57+V40 -> 75648.96 | X42: =V42/7.84 -> 9649.1021 | Z42: =T42 -> Budget YTD 2025 | AA42: =18132.72+AA40 -> 23231.95 | AB42: =AA42/1.2551 -> 18510.039 | AD42: =T42 -> Budget YTD 2025 | AF42: =778108.83+AF40 -> 1009223.3 | AH42: =AP42/0.3449 -> 2476164.5 | AI42: =(AD42-AF38)/0.3428 -> #VALUE! | AP42: =AF42-AP46 -> 854029.12 | AQ42: CHW Consumption Charges (Budget 2025 YTD)
B43: Actual May 2024 | G43: 72456.9 | K43: =G43/0.2 -> 362284.5 | T43: =B43 -> Actual May 2024 | V43: 15860.32 | X43: =V43/7.84 -> 2023 | Z43: =T43 -> Actual May 2024 | AA43: 3023.96 | AB43: =AA43/0.8571 -> 3528.1297 | AD43: =T43 -> Actual May 2024 | AF43: 215752.87 | AH43: =AP43/0.3442 -> 209957.18 | AI43: =(AD43-AF39)/0.3428 -> #VALUE! | AP43: =AF43-AP48 -> 72267.26 | AQ43: CHW Consumption Charges (Actual 2024 MTD)
B44: Actual YTD 2024 | G44: 361897.74 | K44: =G44/0.2 -> 1809488.7 | T44: =B44 -> Actual YTD 2024 | V44: 69195.84 | X44: =V44/7.84 -> 8826 | Z44: =T44 -> Actual YTD 2024 | AA44: 16443.03 | AB44: =AA44/0.8571 -> 19184.494 | AD44: =T44 -> Actual YTD 2024 | AF44: 954652.99 | AH44: =AP44/0.3442 -> 2339998.3 | AI44: =(AD44-AF40)/0.3428 -> #VALUE! | AP44: =AF44-AP47 -> 805427.41 | AQ44: CHW Consumption Charges (Actual 2024 YTD)
G45: 45778 | I45: =TODAY() -> 45811 | J45: 31
A46: Monthly Budget | D46: Daily Budget | I46: MTD Average | N46: MTD Budget | U46: MTD Actual | Y46: YTD Budget | AD46: YTD Actual | AG46: Savings | AH46: Exceeds | AP46: =155194.18 -> 155194.18 | AQ46: CHW Fixed Charges YTD 2025
A47: Electricity | B47: =G40 -> 78253.452 | D47: Electricity | G47: =B47/31 -> 2524.3049 | I47: Electricity | L47: =S36/J45 -> 2138.4741 | N47: Electricity | S47: =G47*J45 -> 78253.452 | U47: Electricity | W47: =S36 -> 66292.696 | X47: =S47-W47 -> 11960.756 | Y47: Electricity | AA47: =S47+G42 -> 451703.06 | AD47: Electricity | AF47: =W47+G41 -> 412878.3 | AG47: =AA47-AF47 -> 38824.762 | AH47: =AF47-AA47 -> -38824.762 | AP47: =149225.58 -> 149225.58 | AQ47: CHW Fixed Charges YTD 2024
A48: Water | B48: =V40 -> 16955.39 | D48: Water | G48: =B48/30 -> 565.17968 | I48: Water | L48: =Y36/J45 -> 464.58323 | N48: Water | S48: =G48*J45 -> 17520.57 | U48: Water | W48: =Y36 -> 14402.08 | X48: =S48-W48 -> 3118.49 | Y48: Water | AA48: =S48+V42 -> 93169.53 | AD48: Water | AF48: =W48+V41 -> 84428.96 | AG48: =AA48-AF48 -> 8740.5704 | AH48: =AF48-AA48 -> -8740.5704 | AP48: =143485.61 -> 143485.61
A49: Gas | B49: =AA40 -> 5099.2305 | D49: Gas | G49: =B49/31 -> 164.49131 | I49: Gas | L49: =AB36/J45 -> 138.81433 | N49: Gas | S49: =G49*J45 -> 5099.2305 | U49: Gas | W49: =AB36 -> 4303.2441 | X49: =S49-W49 -> 795.9864 | Y49: Gas | AA49: =S49+AA42 -> 28331.181 | AD49: Gas | AF49: =W49+AA41 -> 26195.458 | AG49: =AA49-AF49 -> 2135.7228 | AH49: =AF49-AA49 -> -2135.7228
...

Sheet Daily Consumption
A1: DATE | B1: ='May 2025'!A5 -> 45778 | C1: ='May 2025'!A6 -> 45779 | D1: ='May 2025'!A7 -> 45780 | E1: ='May 2025'!$A8 -> 45781 | F1: ='May 2025'!$A9 -> 45782 | G1: ='May 2025'!$A10 -> 45783 | H1: ='May 2025'!$A11 -> 45784 | I1: ='May 2025'!$A12 -> 45785 | J1: ='May 2025'!$A13 -> 45786 | K1: ='May 2025'!$A14 -> 45787 | L1: ='May 2025'!$A15 -> 45788 | M1: ='May 2025'!$A16 -> 45789 | N1: ='May 2025'!$A17 -> 45790 | O1: ='May 2025'!$A18 -> 45791 | P1: ='May 2025'!$A19 -> 45792 | Q1: ='May 2025'!$A20 -> 45793 | R1: ='May 2025'!$A21 -> 45794 | S1: ='May 2025'!$A22 -> 45795 | T1: ='May 2025'!$A23 -> 45796 | U1: ='May 2025'!$A24 -> 45797 | V1: ='May 2025'!$A25 -> 45798 | W1: ='May 2025'!$A26 -> 45799 | X1: ='May 2025'!$A27 -> 45800 | Y1: ='May 2025'!$A28 -> 45801 | Z1: ='May 2025'!$A29 -> 45802 | AA1: ='May 2025'!$A30 -> 45803 | AB1: ='May 2025'!$A31 -> 45804 | AC1: ='May 2025'!$A32 -> 45805 | AD1: ='May 2025'!$A33 -> 45806 | AE1: ='May 2025'!$A34 -> 45807 | AF1: ='May 2025'!$A35 -> 45808
A2: Electricity | B2: =VLOOKUP(B1,'May 2025'!A5:AJ35,19,FALSE) -> 2200.1654 | C2: =VLOOKUP(C1,'May 2025'!$A$5:$AM$35,19,FALSE) -> 2222.9396 | D2: =VLOOKUP(D1,'May 2025'!$A$5:$AM$35,19,FALSE) -> 2165.0465 | E2: =VLOOKUP(E1,'May 2025'!$A$5:$AM$35,19,FALSE) -> 2232.9628 | F2: =VLOOKUP(F1,'May 2025'!$A$5:$AM$35,19,FALSE) -> 2192.7374 | G2: =VLOOKUP(G1,'May 2025'!$A$5:$AM$35,19,FALSE) -> 2155.9002 | H2: =VLOOKUP(H1,'May 2025'!$A$5:$AM$35,19,FALSE) -> 2225.5584 | I2: =VLOOKUP(I1,'May 2025'!$A$5:$AM$35,19,FALSE) -> 2264.9044 | J2: =VLOOKUP(J1,'May 2025'!$A$5:$AM$35,19,FALSE) -> 2222.7902 | ... X2: =VLOOKUP(X1,'May 2025'!$A$5:$AM$35,19,FALSE) -> 2175.722 | Y2: =VLOOKUP(Z1,'May 2025'!$A$5:$AM$35,19,FALSE) -> 2136.6471 | Z2: =VLOOKUP(AA1,'May 2025'!$A$5:$AM$35,19,FALSE) -> 2125.5133 | AA2: =VLOOKUP(AA1,'May 2025'!$A$5:$AM$35,19,FALSE) -> 2125.5133 | AB2: =VLOOKUP(AB1,'May 2025'!$A$5:$AM$35,19,FALSE) -> 2095.5431 | AC2: =VLOOKUP(AC1,'May 2025'!$A$5:$AM$35,19,FALSE) -> 2079.2979 | AD2: =VLOOKUP(AD1,'May 2025'!$A$5:$AM$35,19,FALSE) -> 2028.3812 | AE2: =VLOOKUP(AE1,'May 2025'!$A$5:$AM$35,19,FALSE) -> 2067.4179 | AF2: =VLOOKUP(AF1,'May 2025'!$A$5:$AM$35,19,FALSE) -> 2022.4669
A3: Water | B3: =VLOOKUP(B1,'May 2025'!$A$5:$AJ$36,25,FALSE) -> 548.8 | C3: =VLOOKUP(C1,'May 2025'!$A$5:$AJ$36,25,FALSE) -> 415.52 | D3: =VLOOKUP(D1,'May 2025'!$A$5:$AJ$36,25,FALSE) -> 595.84 | E3: =VLOOKUP(E1,'May 2025'!$A$5:$AJ$36,25,FALSE) -> 548.8 | F3: =VLOOKUP(F1,'May 2025'!$A$5:$AJ$36,25,FALSE) -> 415.52 | G3: =VLOOKUP(G1,'May 2025'!$A$5:$AJ$36,25,FALSE) -> 446.88 | H3: =VLOOKUP(H1,'May 2025'!$A$5:$AJ$36,25,FALSE) -> 313.6 | I3: =VLOOKUP(I1,'May 2025'!$A$5:$AJ$36,25,FALSE) -> 470.4 | ... X3: =VLOOKUP(X1,'May 2025'!$A$5:$AJ$36,25,FALSE) -> 493.92 | Y3: =VLOOKUP(Z1,'May 2025'!$A$5:$AJ$36,25,FALSE) -> 776.16 | Z3: =VLOOKUP(AA1,'May 2025'!$A$5:$AJ$36,25,FALSE) -> 305.76 | AA3: =VLOOKUP(AA1,'May 2025'!$A$5:$AJ$36,25,FALSE) -> 305.76 | AB3: =VLOOKUP(AB1,'May 2025'!$A$5:$AJ$36,25,FALSE) -> 470.4 | AC3: =VLOOKUP(AC1,'May 2025'!$A$5:$AJ$36,25,FALSE) -> 525.28 | AD3: =VLOOKUP(AD1,'May 2025'!$A$5:$AJ$36,25,FALSE) -> 384.16 | AE3: =VLOOKUP(AE1,'May 2025'!$A$5:$AJ$36,25,FALSE) -> 462.56 | AF3: =VLOOKUP(AF1,'May 2025'!$A$5:$AJ$36,25,FALSE) -> 360.64
A4: Gas | B4: =VLOOKUP(B1,'May 2025'!$A$5:$AJ$36,28,FALSE) -> 122.94983 | C4: =VLOOKUP(C1,'May 2025'!$A$5:$AJ$36,28,FALSE) -> 122.94983 | D4: =VLOOKUP(D1,'May 2025'!$A$5:$AJ$36,28,FALSE) -> 122.94983 | E4: =VLOOKUP(E1,'May 2025'!$A$5:$AJ$36,28,FALSE) -> 122.94983 | F4: =VLOOKUP(F1,'May 2025'!$A$5:$AJ$36,28,FALSE) -> 122.94983 | G4: =VLOOKUP(G1,'May 2025'!$A$5:$AJ$36,28,FALSE) -> 122.94983 | H4: =VLOOKUP(H1,'May 2025'!$A$5:$AJ$36,28,FALSE) -> 122.94983 | I4: =VLOOKUP(I1,'May 2025'!$A$5:$AJ$36,28,FALSE) -> 122.94983 | ... X4: =VLOOKUP(X1,'May 2025'!$A$5:$AJ$36,28,FALSE) -> 245.89966 | Y4: =VLOOKUP(Z1,'May 2025'!$A$5:$AJ$36,28,FALSE) -> 122.94983 | Z4: =VLOOKUP(AA1,'May 2025'!$A$5:$AJ$36,28,FALSE) -> 245.89966 | AA4: =VLOOKUP(AA1,'May 2025'!$A$5:$AJ$36,28,FALSE) -> 245.89966 | AB4: =VLOOKUP(AB1,'May 2025'!$A$5:$AJ$36,28,FALSE) -> 122.94983 | AC4: =VLOOKUP(AC1,'May 2025'!$A$5:$AJ$36,28,FALSE) -> 122.94983 | AD4: =VLOOKUP(AD1,'May 2025'!$A$5:$AJ$36,28,FALSE) -> 122.94983 | AE4: =VLOOKUP(AE1,'May 2025'!$A$5:$AJ$36,28,FALSE) -> 122.94983 | AF4: =VLOOKUP(AF1,'May 2025'!$A$5:$AJ$36,28,FALSE) -> 245.89966
A5: D Cooling | B5: =VLOOKUP(B1,'May 2025'!$A$5:$AJ$36,35,FALSE) -> 7270.3117 | C5: =VLOOKUP(C1,'May 2025'!$A$5:$AJ$36,35,FALSE) -> 7253.0116 | D5: =VLOOKUP(D1,'May 2025'!$A$5:$AJ$36,35,FALSE) -> 7097.9928 | E5: =VLOOKUP(E1,'May 2025'!$A$5:$AJ$36,35,FALSE) -> 7182.2174 | F5: =VLOOKUP(F1,'May 2025'!$A$5:$AJ$36,35,FALSE) -> 7269.8565 | G5: =VLOOKUP(G1,'May 2025'!$A$5:$AJ$36,35,FALSE) -> 7432.6148 | H5: =VLOOKUP(H1,'May 2025'!$A$5:$AJ$36,35,FALSE) -> 7024.2394 | I5: =VLOOKUP(I1,'May 2025'!$A$5:$AJ$36,35,FALSE) -> 6917.7067 | ... X5: =VLOOKUP(X1,'May 2025'!$A$5:$AJ$36,35,FALSE) -> 7427.6068 | Y5: =VLOOKUP(Z1,'May 2025'!$A$5:$AJ$36,35,FALSE) -> 7232.9798 | Z5: =VLOOKUP(AA1,'May 2025'!$A$5:$AJ$36,35,FALSE) -> 7492.2549 | AA5: =VLOOKUP(AA1,'May 2025'!$A$5:$AJ$36,35,FALSE) -> 7492.2549 | AB5: =VLOOKUP(AB1,'May 2025'!$A$5:$AJ$36,35,FALSE) -> 7262.7998 | AC5: =VLOOKUP(AC1,'May 2025'!$A$5:$AJ$36,35,FALSE) -> 7398.4697 | AD5: =VLOOKUP(AD1,'May 2025'!$A$5:$AJ$36,35,FALSE) -> 7401.2013 | AE5: =VLOOKUP(AE1,'May 2025'!$A$5:$AJ$36,35,FALSE) -> 7344.5204 | AF5: =VLOOKUP(AF1,'May 2025'!$A$5:$AJ$36,35,FALSE) -> 7317.8872
